Workbook
Name DATES: '[1]FAI Growth by sector'!$C$4:$AX$4
Name DES: '[1]FAI Growth by sector'!$A$6:$A$76
Name IDS: '[1]FAI Growth by sector'!#REF!
Name OBS: '[1]FAI Growth by sector'!$C$6:$AX$76
Name UNITS: '[1]FAI Growth by sector'!#REF!

Sheet Sector Top picks
Q1: Source: Bloomberg, Wind, CICC Research
D2: A-share and H-share Sector Top Picks：February 2026
B4: Sector | C4: Stock name | D4: Ticker | E4: Price | F4: Chg. YTD (%) | G4: TP | H4: Turnover Avg | I4: Up/ down (%) | J4: Earnings growth (%) | L4: P/E (x) | N4: P/B (x) | P4: Div. Yield （%）
H5: 3M, mn | J5: 26E | K5: 27E | L5: 26E | M5: 27E | N5: 26E | O5: 27E | P5: 26E | Q5: 27E
A6: 1 | B6: Food, Beverage & Tobacco | C6: KWEICHOW MOUTAI | D6: 600519.SH | E6: 1555 | F6: 12.911892 | G6: 1860 | H6: 5982.4907 | I6: 19.614148 | J6: 0.049272017 | K6: 0.069356588 | L6: 20.495855 | M6: 19.201561 | N6: 7.0152486 | O6: 6.4113665 | P6: 3.7153055 | Q6: 3.8142122
A7: 2 | B7: Food, Beverage & Tobacco | C7: WLY | D7: 000858.SZ | E7: 108.89 | F7: 2.7845951 | G7: 128 | H7: 2333.2573 | I7: 17.549821 | J7: 0.024531501 | K7: 0.08459084 | L7: 16.079445 | M7: 14.780779 | N7: 2.8328737 | O7: 2.6324824 | P7: 4.4512811 | Q7: 4.733217
A8: 3 | B8: Food, Beverage & Tobacco | C8: SHANXI FEN WINE | D8: 600809.SH | E8: 180.21 | F8: 4.9563192 | G8: 228 | H8: 1091.9437 | I8: 26.519061 | J8: 0.062324402 | K8: 0.098764928 | L8: 16.997736 | M8: 15.479299 | N8: 4.7900165 | O8: 4.1827593 | P8: 3.5003607 | Q8: 3.8149936
A9: 4 | B9: Food, Beverage & Tobacco | C9: ANJOY FOOD | D9: 603345.SH | E9: 90.39 | F9: 14.013623 | G9: 100 | H9: 450.05614 | I9: 10.631707 | J9: 0.12229718 | K9: 0.11231323 | L9: 18.906087 | M9: 17.070822 | N9: 1.9814547 | O9: 1.903308 | P9: 2.9848435 | Q9: 3.1618542
A10: 5 | B10: Media & Entertainment | C10: CENTURY HUATONG | D10: 002602.SZ | E10: 19.42 | F10: 13.833529 | G10: 26.5 | H10: 3252.7971 | I10: 36.457261 | J10: 0.4875999 | K10: 0.2263865 | L10: 16.598291 | M10: 13.551989 | N10: 3.785575 | O10: 3.0136561 | P10: 0.30895984 | Q10: 0.28321318
A11: 6 | B11: Elec EQPT, Grid | C11: FIRST | D11: 603806.SH | E11: 18.6 | F11: 33.237822 | G11: 23.2 | H11: 607.10945 | I11: 24.731183 | J11: 0.44838373 | K11: 0.32354212 | L11: 28.181818 | M11: 21.453287 | N11: 2.6878613 | O11: 2.5074144 | P11: 1.5913978 | Q11: 1.9516129
A12: 7 | B12: Elec EQPT, Grid | C12: GINLONG TECHNOLOGIES | D12: 300763.SZ | E12: 80.8 | F12: 13.149419 | G12: 102.6 | H12: 1103.4249 | I12: 26.980198 | J12: 0.30828352 | K12: 0.14099217 | L12: 21.003379 | M12: 17.283422 | N12: 2.9607915 | O12: - | P12: 0.55693069 | Q12: -
A13: 8 | B13: Elec EQPT, Grid | C13: DKEM | D13: 300842.SZ | E13: 107.71 | F13: 81.727687 | G13: - | H13: 852.57306 | I13: - | J13: 2.1608857 | K13: 0.49490799 | L13: 36.474771 | M13: 24.385329 | N13: 6.4885542 | O13: 5.2058966 | P13: 0.31566243 | Q13: 0.46420945
A14: 9 | B14: Mechanical Equipment | C14: CHINT POWER | D14: 002150.SZ | E14: 23.39 | F14: 16.368159 | G14: 28 | H14: 545.43216 | I14: 19.709277 | J14: 0.38023212 | K14: 0.40648576 | L14: 21.399817 | M14: 15.287582 | N14: 3.3083451 | O14: 2.7071759 | P14: 0.72680633 | Q14: -
A15: 10 | B15: Elec EQPT, Grid | C15: MEGMEET | D15: 002851.SZ | E15: 117.6 | F15: 30.565116 | G15: - | H15: 1967.0426 | I15: - | J15: 1.9381503 | K15: 0.58601101 | L15: 69.014085 | M15: 40.692042 | N15: 8.4928143 | O15: 7.006673 | P15: 0.23979592 | Q15: 0.15306122
A16: 11 | B16: Elec EQPT, Grid | C16: NARI-TECH | D16: 600406.SH | E16: 25.24 | F16: 12.27758 | G16: 29.2 | H16: 1818.2427 | I16: 15.689382 | J16: 0.12762595 | K16: 0.11641546 | L16: 21.499148 | M16: 19.106737 | N16: 3.4349483 | O16: 3.1129748 | P16: 2.3652932 | Q16: 2.5515055
A17: 12 | B17: Elec EQPT, Grid | C17: CATL | D17: 300750.SZ | E17: 362.94 | F17: -1.1762784 | G17: 445 | H17: 10541.293 | I17: 22.609798 | J17: 0.26340254 | K17: 0.21693317 | L17: 18.951491 | M17: 15.673691 | N17: 4.4242631 | O17: 3.7557821 | P17: 2.283022 | Q17: 2.6453408
A18: 13 | B18: Non-ferrous Metals | C18: CMOC | D18: 603993.SH | E18: 22.17 | F18: 10.85 | G18: 35 | H18: 5272.3032 | I18: 57.870997 | J18: 0.33324918 | K18: 0.070007754 | L18: 18.383085 | M18: 16.569507 | N18: 4.6565848 | O18: 3.9504633 | P18: 2.2868742 | Q18: 2.5078935
A19: 14 | B19: Non-ferrous Metals | C19: XINGYE SILVER&TIN | D19: 000426.SZ | E19: 50.02 | F19: 40.505618 | G19: 85 | H19: 3288.3885 | I19: 69.932027 | J19: 0.27045358 | K19: 0.17755182 | L19: 34.736111 | M19: 29.545186 | N19: 7.4070783 | O19: 6.0461743 | P19: 0.40983607 | Q19: 0.46981208
A20: 15 | B20: Communication | C20: ZHONGJI INNOLIGHT | D20: 300308.SZ | E20: 561.99 | F20: -7.8704918 | G20: 830 | H20: 19010.014 | I20: 47.689461 | J20: 1.1335218 | K20: 0.29975577 | L20: 28.458072 | M20: 21.2875 | N20: 12.228073 | O20: 7.9884861 | P20: 0.51566754 | Q20: 0.74449723
A21: 16 | B21: Electronics | C21: FII | D21: 601138.SH | E21: 53.88 | F21: -12.692887 | G21: 79 | H21: 11288.077 | I21: 46.622123 | J21: 0.81222013 | K21: 0.26628977 | L21: 16.964736 | M21: 13.402985 | N21: 5.0018567 | O21: 4.1123493 | P21: 2.9008909 | Q21: 3.6247216
A22: 17 | B22: Electronics | C22: AMEC | D22: 688012.SH | E22: 356.88 | F22: 30.85949 | G22: 480 | H22: 4532.7343 | I22: 34.498991 | J22: 0.53482864 | K22: 0.3586761 | L22: 68.71005 | M22: 50.578231 | N22: 8.911529 | O22: 7.6586978 | P22: 0.12833445 | Q22: 0.29757902
A23: 18 | B23: Electronics | C23: ACCOTEST | D23: 688200.SH | E23: 272.9 | F23: 43.480547 | G23: 368 | H23: 558.02002 | I23: 34.84793 | J23: 0.25989881 | K23: 0.23554214 | L23: 55.979487 | M23: 44.482478 | N23: 8.2701982 | O23: 7.2516143 | P23: 0.50311469 | Q23: 0.6112129
A24: 19 | B24: Electronics | C24: JCET | D24: 600584.SH | E24: 44.66 | F24: 21.424687 | G24: 83 | H24: 2986.0818 | I24: 85.848634 | J24: 0.48751128 | K24: 0.26311574 | L24: 34.40678 | M24: 27.115968 | N24: 2.5999884 | O24: 2.4063797 | P24: 0.45006717 | Q24: 0.62024183
A25: 20 | B25: Mechanical Equipment | C25: JEREH GROUP | D25: 002353.SZ | E25: 87 | F25: 22.82931 | G25: 100 | H25: 1458.2178 | I25: 14.942529 | J25: 0.23791352 | K25: 0.1822608 | L25: 23.268254 | M25: 19.638826 | N25: 3.3385778 | O25: 2.9415742 | P25: 1.0678161 | Q25: 1.2448276
A26: 21 | B26: Communication | C26: CICT MOBILE | D26: 688387.SH | E26: 16.67 | F26: 29.224806 | G26: 22.61 | H26: 1859.4751 | I26: 35.632873 | J26: -2.3135314 | K26: 1.0596194 | L26: 595.35714 | M26: 264.60317 | N26: 9.1342466 | O26: 8.6822917 | P26: - | Q26: -
A27: 22 | B27: National Defense | C27: AVIC HI-TECH | D27: 600862.SH | E27: 25.81 | F27: 9.2255607 | G27: 27.61 | H27: 824.86172 | I27: 6.9740411 | J27: 0.1674777 | K27: 0.14183189 | L27: 24.937198 | M27: 21.872881 | N27: 3.8407738 | O27: 3.3333333 | P27: 1.0461062 | Q27: 1.1623402
B29: Sector | C29: Stock name | D29: Ticker | E29: Price | F29: Chg. YTD (%) | G29: TP | H29: Turnover Avg | I29: Up/ down (%) | J29: Earnings growth (%) | L29: P/E (x) | N29: P/B (x) | P29: Div. Yield （%）
H30: 3M, mn | J30: 26E | K30: 27E | L30: 26E | M30: 27E | N30: 26E | O30: 27E | P30: 26E | Q30: 27E
A31: 1 | B31: Information Technology | C31: NETEASE-S | D31: 9999.HK | E31: 192.6 | F31: -10.251631 | G31: 275 | H31: 1231.3437 | I31: 42.78297 | J31: 0.059719423 | K31: 0.10463082 | L31: 13.249085 | M31: 11.986472 | N31: 2.86723 | O31: 2.5002037 | P31: 2.5482445 | Q31: 2.9633061
A32: 2 | B32: Consumer Discretionary | C32: KUAISHOU-W | D32: 1024.HK | E32: 73 | F32: 14.151681 | G32: 89 | H32: 2502.5486 | I32: 21.917808 | J32: 0.12951113 | K32: 0.16184041 | L32: 11.944625 | M32: 10.289704 | N32: 2.7376356 | O32: 2.1935725 | P32: 0 | Q32: 0
A33: 3 | B33: Consumer Discretionary | C33: ALIBABA-W | D33: 9988.HK | E33: 159.6 | F33: 11.764706 | G33: 197 | H33: 14055.417 | I33: 23.433584 | J33: -0.34751305 | K33: 0.40574861 | L33: 26.30354 | M33: 18.409062 | N33: 2.4002197 | O33: 2.3695655 | P33: 0.6560857 | Q33: 0.76402238
A34: 4 | B34: Information Technology | C34: TENCENT | D34: 0700.HK | E34: 558.5 | F34: -6.7612688 | G34: 700 | H34: 12088.018 | I34: 25.335721 | J34: 0.12580609 | K34: 0.10838203 | L34: 15.69335 | M34: 14.109552 | N34: 3.2605378 | O34: 2.7732235 | P34: 1.1460876 | Q34: 1.281965
A35: 5 | B35: Industrials | C35: GOLDWIND | D35: 2208.HK | E35: 13.12 | F35: -2.1625652 | G35: 21.8 | H35: 638.33021 | I35: 66.158537 | J35: 0.34964021 | K35: 0.19037273 | L35: 11.108306 | M35: 9.3896963 | N35: 1.1121028 | O35: 1.0268429 | P35: 2.7719104 | Q35: 3.2524894
A36: 6 | B36: Materials | C36: NANSHAN AL INTL | D36: 2610.HK | E36: 61.7 | F36: 27.374071 | G36: 100 | H36: 159.91573 | I36: 62.074554 | J36: 0.3368984 | K36: - | L36: 9.2910565 | M36: - | N36: 1.9842709 | O36: - | P36: 2.1526077 | Q36: -
A37: 7 | B37: Materials | C37: ZIJIN GOLD INTL | D37: 2259.HK | E37: 205.8 | F37: 40.958904 | G37: 300 | H37: 842.59944 | I37: 45.772595 | J37: 1.1766383 | K37: 0.10729446 | L37: 22.399427 | M37: 20.278465 | N37: 7.7339185 | O37: 5.8982818 | P37: 0.70610406 | Q37: 0.88452821
A38: 8 | B38: Materials | C38: LYGEND RESOURCE | D38: 2245.HK | E38: 25.58 | F38: 11.996497 | G38: 30 | H38: 117.38818 | I38: 17.279124 | J38: 0.55620053 | K38: 0.21125805 | L38: 9.3494004 | M38: 8.5409936 | N38: 2.0375823 | O38: 1.4685871 | P38: 6.5583749 | Q38: -
A39: 9 | B39: Information Technology | C39: YOFC | D39: 6869.HK | E39: 86.5 | F39: 67.311412 | G39: 97 | H39: 1410.2525 | I39: 12.138728 | J39: 0.75309754 | K39: 0.39360062 | L39: 38.032444 | M39: 27.379022 | N39: 4.2258271 | O39: 3.7543633 | P39: 0.70289129 | Q39: 1.0699567
A40: 10 | B40: Industrials | C40: SANY INT'L | D40: 0631.HK | E40: 12.9 | F40: 48.960739 | G40: 14.7 | H40: 99.659225 | I40: 13.953488 | J40: 0.26421053 | K40: 0.24612823 | L40: 12.975333 | M40: 10.638086 | N40: 2.3382079 | O40: 2.0441068 | P40: 4.1894985 | Q40: 5.6732792

Sheet Summary-A share
B1: Updated | C1: 46062
B2: Sector | C2: Market cap （Rmb bn） | D2: Weight of market cap | E2: Free-float market value （Rmb bn） | F2: Weight of free-float market value | G2: Number of covered companies | H2: Proportion | I2: P/E (x) | O2: P/B(x) | U2: Dividend yield | AA2: ROE | AG2: Income (YoY) | AL2: Net profit(YoY)
I3: 2023A | J3: 2024A | K3: 2025E | L3: 2026E | M3: 2027E | N3: 2028E | O3: 2023A | P3: 2024A | Q3: 2025E | R3: 2026E | S3: 2027E | T3: 2028E | U3: 2023A | V3: 2024A | W3: 2025E | X3: 2026E | Y3: 2027E | Z3: 2028E | AA3: 2023A | AB3: 2024A | AC3: 2025E | AD3: 2026E | AE3: 2027E | AF3: 2028E | AG3: 2024A | AH3: 2025E | AI3: 2026E | AJ3: 2027E | AK3: 2028E | AL3: 2024A | AM3: 2025E | AN3: 2026E | AO3: 2027E | AP3: 2028E
B5: CICC covered companies-A share | C5: 69057.772 | D5: 1 | E5: 53653.958 | F5: 1 | G5: 1081 | H5: 1 | I5: 17.109596 | J5: 16.57237 | K5: 15.532857 | L5: 13.831363 | M5: 16.074216 | N5: 93.107388 | O5: 1.5208479 | P5: 1.4353903 | Q5: 1.4919398 | R5: 1.4064272 | S5: 1.5670892 | T5: 12.551605 | U5: 0.022913534 | V5: 0.024297942 | W5: 0.024947912 | X5: 0.027192556 | Y5: 0.022395327 | Z5: 0.0044931625 | AA5: 0.088888591 | AB5: 0.08661346 | AC5: 0.096050569 | AD5: 0.10168392 | AE5: 0.097490864 | AF5: 0.12257694 | AG5: 0.0081662946 | AH5: -0.081592504 | AI5: 0.036907714 | AJ5: -0.20874729 | AK5: -0.68088213 | AL5: 0.032416982 | AM5: 0.066923429 | AN5: 0.1230171 | AO5: -0.13953106 | AP5: =SUMIFS('A share covered list'!AC4:AC9640,'A share covered list'!AC4:AC9640,"<>0",'A share covered list'!AB4:AB9640,"<>0")/SUMIFS('A share covered list'!AB4:AB9640,'A share covered list'!AC4:AC9640,"<>0",'A share covered list'!AB4:AB9640,"<>0")-1 -> -0.82735832
B6: Financials | C6: 19429.734 | D6: 0.28135478 | E6: 13285.502 | F6: 0.24761458 | G6: 45 | H6: 0.041628122 | I6: 8.8843216 | J6: 8.0161494 | K6: 7.7500798 | L6: 7.2170522 | M6: 7.1937952 | N6: - | O6: 0.79054011 | P6: 0.73773443 | Q6: 0.69377519 | R6: 0.64823661 | S6: 0.61710183 | T6: - | U6: 0.034763445 | V6: 0.036729716 | W6: 0.038941667 | X6: 0.040301306 | Y6: 0.041234162 | Z6: 0.00013180055 | AA6: 0.088981483 | AB6: 0.092031023 | AC6: 0.089518458 | AD6: 0.089820136 | AE6: 0.085782513 | AF6: - | AG6: 0.0031817869 | AH6: -0.11256208 | AI6: 0.034339873 | AJ6: 0.03260908 | AK6: - | AL6: 0.10830289 | AM6: 0.03433121 | AN6: 0.073856686 | AO6: 0.0032329233 | AP6: -
B7: Non-financials | C7: 49628.038 | D7: 0.71864522 | E7: 40368.455 | F7: 0.75238542 | G7: 1036 | H7: 0.95837188 | I7: 26.80126 | J7: 28.421204 | K7: 25.557308 | L7: 21.543039 | M7: 31.040978 | N7: 67.253269 | O7: 2.3793994 | P7: 2.2761106 | Q7: 2.7094462 | R7: 2.5893312 | S7: 3.9303168 | T7: 9.0975577 | U7: 0.018285121 | V7: 0.019442261 | W7: 0.019482143 | X7: 0.022072458 | Y7: 0.015037136 | Z7: 0.0061967071 | AA7: 0.088779388 | AB7: 0.080084946 | AC7: 0.10601454 | AD7: 0.1201934 | AE7: 0.12661704 | AF7: 0.13527309 | AG7: 0.0095223859 | AH7: -0.073219803 | AI7: 0.037572466 | AJ7: -0.27103397 | AK7: -0.56454941 | AL7: -0.056997752 | AM7: 0.11205782 | AN7: 0.18633718 | AO7: -0.30598067 | AP7: =(SUMIFS('A share covered list'!AC4:AC9640,'A share covered list'!AC4:AC9640,"<>0",'A share covered list'!AB4:AB9640,"<>0")-SUMIFS('A share covered list'!AC$4:AC$9640,'A share covered list'!$E$4:$E$9640,'Summary-A share'!$B23,'A share covered list'!AC$4:AC$9640,"<>0",'A share covered list'!AB$4:AB$9640,"<>0")-SUMIFS('A share covered list'!AC$4:AC$9640,'A share covered list'!$E$4:$E$9640,'Summary-A share'!$B24,'A share covered list'!AC$4:AC$9640,"<>0",'A share covered list'!AB$4:AB$9640,"<>0")-SUMIFS('A share covered list'!AC$4:AC$9640,'A share covered list'!$E$4:$E$9640,'Summary-A share'!$B25,'A share covered list'!AC$4:AC$9640,"<>0",'A share covered list'!AB$4:AB$9640,"<>0"))/(SUMIFS('A share covered list'!AB4:AB9640,'A share covered list'!AC4:AC9640,"<>0",'A share covered list'!AB4:AB9640,"<>0")-(SUMIFS('A share covered list'!AB$4:AB$9640,'A share covered list'!$E$4:$E$9640,'Summary-A share'!$B23,'A share covered list'!AC$4:AC$9640,"<>0",'A share covered list'!AB$4:AB$9640,"<>0")+SUMIFS('A share covered list'!AB$4:AB$9640,'A share covered list'!$E$4:$E$9640,'Summary-A share'!$B24,'A share covered list'!AC$4:AC$9640,"<>0",'A share covered list'!AB$4:AB$9640,"<>0")+SUMIFS('A share covered list'!AB$4:AB$9640,'A share covered list'!$E$4:$E$9640,'Summary-A share'!$B25,'A share covered list'!AC$4:AC$9640,"<>0",'A share covered list'!AB$4:AB$9640,"<>0")))-1 -> -0.53844655
B8: Main board | C8: 56870.87 | D8: 0.82352599 | E8: 44152.059 | F8: 0.82290405 | G8: 720 | H8: 0.66604995 | I8: 14.841383 | J8: 14.269502 | K8: 13.599091 | L8: 12.207929 | M8: 14.129822 | N8: 107.96956 | O8: 1.3248433 | P8: 1.2502298 | Q8: 1.30299 | R8: 1.2264618 | S8: 1.3437893 | T8: 13.025527 | U8: 0.0263325 | V8: 0.027930561 | W8: 0.028567686 | X8: 0.030867819 | Y8: 0.025302342 | Z8: 0.0037486945 | AA8: 0.08926684 | AB8: 0.087615517 | AC8: 0.095814492 | AD8: 0.10046436 | AE8: 0.095103064 | AF8: 0.12064073 | AG8: 0.0088224964 | AH8: -0.09753299 | AI8: 0.031168125 | AJ8: -0.20198356 | AK8: -0.70930329 | AL8: 0.040077104 | AM8: 0.049298253 | AN8: 0.11395563 | AO8: -0.13601677 | AP8: =IFERROR(SUMIFS('A share covered list'!AC$4:AC$9640,'A share covered list'!$C$4:$C$9640,'Summary-A share'!$B8,'A share covered list'!AC$4:AC$9640,"<>0",'A share covered list'!AB$4:AB$9640,"<>0")/SUMIFS('A share covered list'!AB$4:AB$9640,'A share covered list'!$C$4:$C$9640,'Summary-A share'!$B8,'A share covered list'!AC$4:AC$9640,"<>0",'A share covered list'!AB$4:AB$9640,"<>0"),"-")-1 -> -0.86913144
B9: ChiNext Board | C9: 6975.7353 | D9: 0.10101304 | E9: 5854.8854 | F9: 0.10912309 | G9: 203 | H9: 0.18778908 | I9: 43.379169 | J9: 42.100341 | K9: 32.37862 | L9: 27.388485 | M9: 30.445906 | N9: 39.515821 | O9: 4.5600909 | P9: 4.2250628 | Q9: 4.0241043 | R9: 3.8432223 | S9: 4.9405468 | T9: 7.9657108 | U9: 0.009738444 | V9: 0.010927378 | W9: 0.012006274 | X9: 0.014762933 | Y9: 0.013396408 | Z9: 0.012053498 | AA9: 0.10512167 | AB9: 0.10035697 | AC9: 0.12428276 | AD9: 0.14032256 | AE9: 0.16227294 | AF9: 0.20158283 | AG9: 0.0086459811 | AH9: 0.13053457 | AI9: 0.080482844 | AJ9: -0.2060675 | AK9: -0.34813846 | AL9: 0.030375721 | AM9: 0.30025125 | AN9: 0.18219829 | AO9: -0.10042144 | AP9: =IFERROR(SUMIFS('A share covered list'!AC$4:AC$9640,'A share covered list'!$C$4:$C$9640,'Summary-A share'!$B9,'A share covered list'!AC$4:AC$9640,"<>0",'A share covered list'!AB$4:AB$9640,"<>0")/SUMIFS('A share covered list'!AB$4:AB$9640,'A share covered list'!$C$4:$C$9640,'Summary-A share'!$B9,'A share covered list'!AC$4:AC$9640,"<>0",'A share covered list'!AB$4:AB$9640,"<>0"),"-")-1 -> #VALUE!
B10: SSE STAR Market | C10: 5211.1666 | D10: 0.075460972 | E10: 3647.0133 | F10: 0.067972867 | G10: 158 | H10: 0.14616096 | I10: 108.97746 | J10: 246.58431 | K10: 99.006501 | L10: 61.432022 | M10: 106.08977 | N10: 131.76478 | O10: 5.1580773 | P10: 5.0412999 | Q10: 5.4077011 | R10: 5.317531 | S10: 12.857487 | T10: 19.418123 | U10: 0.0036123627 | V10: 0.0029943371 | W10: 0.0032735549 | X10: 0.0042757182 | Y10: 0.0032129389 | Z10: 0.0025982666 | AA10: 0.047331597 | AB10: 0.020444528 | AC10: 0.054619656 | AD10: 0.086559596 | AE10: 0.12119441 | AF10: 0.1473696 | AG10: -0.024844881 | AH10: 0.15901736 | AI10: 0.15917445 | AJ10: -0.45067627 | AK10: -0.39067091 | AL10: -0.55805193 | AM10: 1.4905871 | AN10: 0.61164322 | AO10: -0.42094302 | AP10: =IFERROR(SUMIFS('A share covered list'!AC$4:AC$9640,'A share covered list'!$C$4:$C$9640,'Summary-A share'!$B10,'A share covered list'!AC$4:AC$9640,"<>0",'A share covered list'!AB$4:AB$9640,"<>0")/SUMIFS('A share covered list'!AB$4:AB$9640,'A share covered list'!$C$4:$C$9640,'Summary-A share'!$B10,'A share covered list'!AC$4:AC$9640,"<>0",'A share covered list'!AB$4:AB$9640,"<>0"),"-")-1 -> -0.19485488
B11: Oil & gas | C11: 3231.2096 | D11: 0.046710804 | E11: 1461.3131 | F11: 0.027193271 | G11: 14 | H11: 0.012738854 | I11: 15.901428 | J11: 15.593672 | K11: 20.465644 | L11: 18.515026 | M11: 113.40196 | N11: 729.74026 | O11: 1.5861838 | P11: 1.4970662 | Q11: 2.7086909 | R11: 2.4868846 | S11: 13.179308 | T11: 57.943005 | U11: 0.032625993 | V11: 0.032329123 | W11: 0.021528885 | X11: 0.023823954 | Y11: 0.0026339579 | Z11: 0.00047962224 | AA11: 0.099751029 | AB11: 0.096004727 | AC11: 0.13235307 | AD11: 0.1343171 | AE11: 0.11621764 | AF11: 0.079402231 | AG11: -0.022814055 | AH11: -0.66150383 | AI11: 0.072093047 | AJ11: -0.53433868 | AK11: -0.92969642 | AL11: 0.019735943 | AM11: -0.23805612 | AN11: 0.10535323 | AO11: -0.83673098 | AP11: =IFERROR(SUMIFS('A share covered list'!AC$4:AC$9640,'A share covered list'!$E$4:$E$9640,'Summary-A share'!$B11,'A share covered list'!AC$4:AC$9640,"<>0",'A share covered list'!AB$4:AB$9640,"<>0")/SUMIFS('A share covered list'!AB$4:AB$9640,'A share covered list'!$E$4:$E$9640,'Summary-A share'!$B11,'A share covered list'!AC$4:AC$9640,"<>0",'A share covered list'!AB$4:AB$9640,"<>0")-1,"-") -> -0.84459956
B12: Non-ferrous metals | C12: 3387.5699 | D12: 0.04897117 | E12: 2885.7354 | F12: 0.053700049 | G12: 31 | H12: 0.028207461 | I12: 45.273441 | J12: 35.939361 | K12: 27.079972 | L12: 18.816756 | M12: 26.492578 | N12: 389.45957 | O12: 4.2971973 | P12: 3.8353598 | Q12: 4.6852834 | R12: 3.9414839 | S12: 5.8241488 | T12: 87.381427 | U12: 0.0080912876 | V12: 0.010361195 | W12: 0.012211653 | X12: 0.017386699 | Y12: 0.011958682 | Z12: 0.00041280329 | AA12: 0.094916518 | AB12: 0.10671753 | AC12: 0.17301655 | AD12: 0.2094667 | AE12: 0.21984077 | AF12: 0.16046519 | AG12: 0.0330362 | AH12: -0.021420413 | AI12: 0.12300225 | AJ12: -0.39794899 | AK12: -0.84970009 | AL12: 0.25971748 | AM12: 0.32715648 | AN12: 0.43914135 | AO12: -0.2897348 | AP12: =IFERROR(SUMIFS('A share covered list'!AC$4:AC$9640,'A share covered list'!$E$4:$E$9640,'Summary-A share'!$B12,'A share covered list'!AC$4:AC$9640,"<>0",'A share covered list'!AB$4:AB$9640,"<>0")/SUMIFS('A share covered list'!AB$4:AB$9640,'A share covered list'!$E$4:$E$9640,'Summary-A share'!$B12,'A share covered list'!AC$4:AC$9640,"<>0",'A share covered list'!AB$4:AB$9640,"<>0")-1,"-") -> -0.93197605
B13: Coal | C13: 639.07978 | D13: 0.0092386239 | E13: 516.79903 | F13: 0.0096170053 | G13: 6 | H13: 0.0054595086 | I13: 8.5851017 | J13: 9.6653331 | K13: 13.310374 | L13: 12.051706 | M13: 316.74776 | N13: - | O13: 1.2284673 | P13: 1.1478266 | Q13: 1.3609775 | R13: 1.282166 | S13: 30.184555 | T13: - | U13: 0.059550338 | V13: 0.049838326 | W13: 0.037811633 | X13: 0.041507869 | Y13: 0.0014207146 | Z13: 0 | AA13: 0.14309293 | AB13: 0.11875706 | AC13: 0.10224938 | AD13: 0.10638876 | AE13: 0.095295245 | AF13: - | AG13: -0.016461975 | AH13: -0.10480736 | AI13: 0.019096156 | AJ13: -0.9765278 | AK13: -1 | AL13: -0.11176349 | AM13: -0.27384963 | AN13: 0.10443903 | AO13: -0.96195173 | AP13: =IFERROR(SUMIFS('A share covered list'!AC$4:AC$9640,'A share covered list'!$E$4:$E$9640,'Summary-A share'!$B13,'A share covered list'!AC$4:AC$9640,"<>0",'A share covered list'!AB$4:AB$9640,"<>0")/SUMIFS('A share covered list'!AB$4:AB$9640,'A share covered list'!$E$4:$E$9640,'Summary-A share'!$B13,'A share covered list'!AC$4:AC$9640,"<>0",'A share covered list'!AB$4:AB$9640,"<>0")-1,"-") -> -1
B14: Construction materials | C14: 551.1975 | D14: 0.0079681858 | E14: 485.18694 | F14: 0.0090287425 | G14: 19 | H14: 0.017288444 | I14: 19.329198 | J14: 33.82873 | K14: 21.251512 | L14: 17.371176 | M14: 18.259971 | N14: 375.38052 | O14: 1.073516 | P14: 1.0766238 | Q14: 1.1604991 | R14: 1.1147308 | S14: 1.5161251 | T14: 43.656926 | U14: 0.026634419 | V14: 0.025151076 | W14: 0.022187111 | X14: 0.026748053 | Y14: 0.026586169 | Z14: 0.0023324308 | AA14: 0.055538568 | AB14: 0.031825723 | AC14: 0.054607837 | AD14: 0.06417129 | AE14: 0.083029981 | AF14: 0.11630045 | AG14: -0.1361507 | AH14: 0.026540257 | AI14: 0.041441724 | AJ14: -0.43140181 | AK14: -0.9638647 | AL14: -0.4286159 | AM14: 0.59182695 | AN14: 0.22337785 | AO14: -0.048674496 | AP14: =IFERROR(SUMIFS('A share covered list'!AC$4:AC$9640,'A share covered list'!$E$4:$E$9640,'Summary-A share'!$B14,'A share covered list'!AC$4:AC$9640,"<>0",'A share covered list'!AB$4:AB$9640,"<>0")/SUMIFS('A share covered list'!AB$4:AB$9640,'A share covered list'!$E$4:$E$9640,'Summary-A share'!$B14,'A share covered list'!AC$4:AC$9640,"<>0",'A share covered list'!AB$4:AB$9640,"<>0")-1,"-") -> -0.9513561
B15: Steel | C15: 119.48396 | D15: 0.0017272763 | E15: 111.93292 | F15: 0.0020829364 | G15: 5 | H15: 0.0045495905 | I15: 33.208728 | J15: -29.840254 | K15: 17.511195 | L15: 13.664836 | M15: 118.93448 | N15: 98.236407 | O15: 0.61280482 | P15: 0.62988582 | Q15: 0.69136808 | R15: 0.66459922 | S15: 11.770369 | T15: 10.836987 | U15: 0.018676148 | V15: 0.0094654616 | W15: 0.016111284 | X15: 0.025961895 | Y15: 0.0028620578 | Z15: 0.003455945 | AA15: 0.018453125 | AB15: -0.021108594 | AC15: 0.039481491 | AD15: 0.048635726 | AE15: 0.098965152 | AF15: 0.081627591 | AG15: -0.072008687 | AH15: 0.052995998 | AI15: 0.016374368 | AJ15: -0.96497257 | AK15: 0.12562725 | AL15: -2.1128836 | AM15: -2.7040673 | AN15: 0.28147858 | AO15: -0.88510619 | AP15: =IFERROR(SUMIFS('A share covered list'!AC$4:AC$9640,'A share covered list'!$E$4:$E$9640,'Summary-A share'!$B15,'A share covered list'!AC$4:AC$9640,"<>0",'A share covered list'!AB$4:AB$9640,"<>0")/SUMIFS('A share covered list'!AB$4:AB$9640,'A share covered list'!$E$4:$E$9640,'Summary-A share'!$B15,'A share covered list'!AC$4:AC$9640,"<>0",'A share covered list'!AB$4:AB$9640,"<>0")-1,"-") -> 0.21069658
B16: Chemicals | C16: 2289.0039 | D16: 0.033090151 | E16: 2156.7935 | F16: 0.04013532 | G16: 88 | H16: 0.080072793 | I16: 28.516359 | J16: 31.284165 | K16: 22.63943 | L16: 19.063974 | M16: 28.437809 | N16: 148.75581 | O16: 2.6355826 | P16: 2.5032707 | Q16: 2.4532587 | R16: 2.3957313 | S16: 4.1251177 | T16: 18.709133 | U16: 0.013651799 | V16: 0.014796977 | W16: 0.016738228 | X16: 0.021000759 | Y16: 0.013807268 | Z16: 0.0024597686 | AA16: 0.092423534 | AB16: 0.080017183 | AC16: 0.10836221 | AD16: 0.12566799 | AE16: 0.14505751 | AF16: 0.12651499 | AG16: 0.00026561483 | AH16: 0.087484878 | AI16: 0.040307516 | AJ16: -0.43917056 | AK16: -0.8032559 | AL16: -0.088473065 | AM16: 0.3818442 | AN16: 0.18755039 | AO16: -0.32962579 | AP16: =IFERROR(SUMIFS('A share covered list'!AC$4:AC$9640,'A share covered list'!$E$4:$E$9640,'Summary-A share'!$B16,'A share covered list'!AC$4:AC$9640,"<>0",'A share covered list'!AB$4:AB$9640,"<>0")/SUMIFS('A share covered list'!AB$4:AB$9640,'A share covered list'!$E$4:$E$9640,'Summary-A share'!$B16,'A share covered list'!AC$4:AC$9640,"<>0",'A share covered list'!AB$4:AB$9640,"<>0")-1,"-") -> -0.80882892
B17: Construction | C17: 533.58727 | D17: 0.0077136099 | E17: 486.80914 | F17: 0.0090589297 | G17: 15 | H17: 0.013648772 | I17: 6.0026216 | J17: 6.8139812 | K17: 9.1797639 | L17: 9.50859 | M17: 9.5962547 | N17: - | O17: 0.40125782 | P17: 0.38492516 | Q17: 0.8515732 | R17: 0.86147625 | S17: 0.85760648 | T17: - | U17: 0.03568134 | V17: 0.03556412 | W17: 0.027626577 | X17: 0.028162216 | Y17: 0.028071491 | Z17: 0 | AA17: 0.066847096 | AB17: 0.056490493 | AC17: 0.092766351 | AD17: 0.09059979 | AE17: 0.089368874 | AF17: - | AG17: -0.020348002 | AH17: -0.23787276 | AI17: -0.025483081 | AJ17: 0.029783801 | AK17: -1 | AL17: -0.11907277 | AM17: -0.25771716 | AN17: -0.034582007 | AO17: -0.0091353071 | AP17: =IFERROR(SUMIFS('A share covered list'!AC$4:AC$9640,'A share covered list'!$E$4:$E$9640,'Summary-A share'!$B17,'A share covered list'!AC$4:AC$9640,"<>0",'A share covered list'!AB$4:AB$9640,"<>0")/SUMIFS('A share covered list'!AB$4:AB$9640,'A share covered list'!$E$4:$E$9640,'Summary-A share'!$B17,'A share covered list'!AC$4:AC$9640,"<>0",'A share covered list'!AB$4:AB$9640,"<>0")-1,"-") -> -1
B18: Electricity and utilities | C18: 1676.0872 | D18: 0.024229744 | E18: 1565.2093 | F18: 0.029126653 | G18: 20 | H18: 0.018198362 | I18: 18.319936 | J18: 15.99587 | K18: 17.996598 | L18: 17.698773 | M18: 23.085653 | N18: 139.83334 | O18: 1.4986515 | P18: 1.3740206 | Q18: 2.3452058 | R18: 2.2201827 | S18: 3.0923956 | T18: 11.640094 | U18: 0.028175168 | V18: 0.032499005 | W18: 0.03016287 | X18: 0.031769528 | Y18: 0.026422569 | Z18: 0.0031868688 | AA18: 0.08180441 | AB18: 0.085898461 | AC18: 0.13031384 | AD18: 0.12544275 | AE18: 0.13395313 | AF18: - | AG18: -0.0090949627 | AH18: -0.20874799 | AI18: 0.007549803 | AJ18: -0.15674241 | AK18: -0.841832 | AL18: 0.14529164 | AM18: -0.11117257 | AN18: 0.016827447 | AO18: -0.23334322 | AP18: =IFERROR(SUMIFS('A share covered list'!AC$4:AC$9640,'A share covered list'!$E$4:$E$9640,'Summary-A share'!$B18,'A share covered list'!AC$4:AC$9640,"<>0",'A share covered list'!AB$4:AB$9640,"<>0")/SUMIFS('A share covered list'!AB$4:AB$9640,'A share covered list'!$E$4:$E$9640,'Summary-A share'!$B18,'A share covered list'!AC$4:AC$9640,"<>0",'A share covered list'!AB$4:AB$9640,"<>0")-1,"-") -> -0.83490595
B19: Electrical equipment and new energy | C19: 4522.7235 | D19: 0.065381104 | E19: 4117.9211 | F19: 0.076629535 | G19: 85 | H19: 0.077343039 | I19: 31.639604 | J19: 46.731455 | K19: 34.334637 | L19: 22.884536 | M19: 27.82912 | N19: 32.143301 | O19: 3.6470891 | P19: 3.4610145 | Q19: 3.6423226 | R19: 3.2922689 | S19: 5.2501975 | T19: 7.418759 | U19: 0.011892738 | V19: 0.011040997 | W19: 0.013172154 | X19: 0.017233335 | Y19: 0.01502224 | Z19: 0.015093823 | AA19: 0.11526974 | AB19: 0.074061774 | AC19: 0.10608304 | AD19: 0.14386435 | AE19: 0.18865841 | AF19: 0.13007907 | AG19: -0.058948696 | AH19: 0.052041834 | AI19: 0.20596972 | AJ19: -0.31294418 | AK19: -0.40317064 | AL19: -0.32294845 | AM19: 0.36105868 | AN19: 0.50034227 | AO19: -0.17767662 | AP19: =IFERROR(SUMIFS('A share covered list'!AC$4:AC$9640,'A share covered list'!$E$4:$E$9640,'Summary-A share'!$B19,'A share covered list'!AC$4:AC$9640,"<>0",'A share covered list'!AB$4:AB$9640,"<>0")/SUMIFS('A share covered list'!AB$4:AB$9640,'A share covered list'!$E$4:$E$9640,'Summary-A share'!$B19,'A share covered list'!AC$4:AC$9640,"<>0",'A share covered list'!AB$4:AB$9640,"<>0")-1,"-") -> -0.13421711
B20: Machinery | C20: 2730.3633 | D20: 0.039470502 | E20: 2414.7927 | F20: 0.044936373 | G20: 97 | H20: 0.088262056 | I20: 39.908997 | J20: 39.687874 | K20: 28.886082 | L20: 24.424531 | M20: 98.451464 | N20: 300.76275 | O20: 3.8740224 | P20: 3.6351558 | Q20: 3.506824 | R20: 3.3277478 | S20: 14.081867 | T20: 59.967155 | U20: 0.0092597898 | V20: 0.010400562 | W20: 0.012490924 | X20: 0.014643132 | Y20: 0.003327363 | Z20: 0.0014550078 | AA20: 0.097071406 | AB20: 0.091593613 | AC20: 0.12140186 | AD20: 0.13624613 | AE20: 0.1430336 | AF20: 0.19938358 | AG20: 0.054794719 | AH20: 0.1898947 | AI20: 0.10913677 | AJ20: -0.77314637 | AK20: -0.64184289 | AL20: 0.0055715259 | AM20: 0.37394453 | AN20: 0.18266683 | AO20: -0.75191298 | AP20: =IFERROR(SUMIFS('A share covered list'!AC$4:AC$9640,'A share covered list'!$E$4:$E$9640,'Summary-A share'!$B20,'A share covered list'!AC$4:AC$9640,"<>0",'A share covered list'!AB$4:AB$9640,"<>0")/SUMIFS('A share covered list'!AB$4:AB$9640,'A share covered list'!$E$4:$E$9640,'Summary-A share'!$B20,'A share covered list'!AC$4:AC$9640,"<>0",'A share covered list'!AB$4:AB$9640,"<>0")-1,"-") -> -0.67266071
B21: High-end equipment | C21: 1461.564 | D21: 0.021128567 | E21: 1409.5377 | F21: 0.026229793 | G21: 36 | H21: 0.032757052 | I21: 54.674724 | J21: 74.832901 | K21: 56.046313 | L21: 49.247836 | M21: 53.179979 | N21: 49.326502 | O21: 4.1034573 | P21: 3.8314233 | Q21: 3.9291572 | R21: 3.8609614 | S21: 4.278827 | T21: 4.2796936 | U21: 0.006519679 | V21: 0.0053441929 | W21: 0.00711143 | X21: 0.0097595043 | Y21: 0.0063371978 | Z21: 0.0067897883 | AA21: 0.075052181 | AB21: 0.051199715 | AC21: 0.070105544 | AD21: 0.078398601 | AE21: 0.080459358 | AF21: 0.081721663 | AG21: -0.035329157 | AH21: 0.11571677 | AI21: 0.10212887 | AJ21: -0.019982022 | AK21: 0.078289516 | AL21: -0.26937587 | AM21: 0.33519758 | AN21: 0.13804621 | AO21: -0.073940291 | AP21: =IFERROR(SUMIFS('A share covered list'!AC$4:AC$9640,'A share covered list'!$E$4:$E$9640,'Summary-A share'!$B21,'A share covered list'!AC$4:AC$9640,"<>0",'A share covered list'!AB$4:AB$9640,"<>0")/SUMIFS('A share covered list'!AB$4:AB$9640,'A share covered list'!$E$4:$E$9640,'Summary-A share'!$B21,'A share covered list'!AC$4:AC$9640,"<>0",'A share covered list'!AB$4:AB$9640,"<>0")-1,"-") -> 0.078121845
B22: Transportation and logistics | C22: 1512.4005 | D22: 0.021863466 | E22: 1354.8599 | F22: 0.025212306 | G22: 32 | H22: 0.029117379 | I22: 16.206947 | J22: 13.135002 | K22: 13.172316 | L22: 14.806722 | M22: 26.363266 | N22: 59.73266 | O22: 1.1150977 | P22: 1.0317878 | Q22: 1.2406855 | R22: 1.2757373 | S22: 1.9480398 | T22: 7.7142335 | U22: 0.029491674 | V22: 0.038463208 | W22: 0.035069613 | X22: 0.032194151 | Y22: 0.019125873 | Z22: 0.0087280784 | AA22: 0.06880369 | AB22: 0.078552539 | AC22: 0.094188865 | AD22: 0.086159334 | AE22: 0.073892203 | AF22: 0.12765412 | AG22: 0.041305483 | AH22: 0.31219025 | AI22: -0.54200608 | AJ22: -0.34991176 | AK22: -0.56538234 | AL22: 0.23387468 | AM22: -0.0028327002 | AN22: -0.11038273 | AO22: -0.43835784 | AP22: =IFERROR(SUMIFS('A share covered list'!AC$4:AC$9640,'A share covered list'!$E$4:$E$9640,'Summary-A share'!$B22,'A share covered list'!AC$4:AC$9640,"<>0",'A share covered list'!AB$4:AB$9640,"<>0")/SUMIFS('A share covered list'!AB$4:AB$9640,'A share covered list'!$E$4:$E$9640,'Summary-A share'!$B22,'A share covered list'!AC$4:AC$9640,"<>0",'A share covered list'!AB$4:AB$9640,"<>0")-1,"-") -> -0.5586457
B23: Banks | C23: 13519.8 | D23: 0.19544407 | E23: 8874.5526 | F23: 0.1651447 | G23: 22 | H23: 0.020018198 | I23: 6.9991547 | J23: 6.8559872 | K23: 6.7646664 | L23: 6.6391243 | M23: 6.5560644 | N23: - | O23: 0.65285819 | P23: 0.60987679 | Q23: 0.5619214 | R23: 0.52986573 | S23: 0.50862287 | T23: - | U23: 0.042285839 | V23: 0.043298417 | W23: 0.044129861 | X23: 0.044970108 | Y23: 0.045292185 | Z23: 0 | AA23: 0.093276719 | AB23: 0.088955357 | AC23: 0.083067127 | AD23: 0.079809582 | AE23: 0.077580518 | AF23: - | AG23: -0.0028779803 | AH23: 0.0089901987 | AI23: 0.024227601 | AJ23: 0.022587788 | AK23: -1 | AL23: 0.020882111 | AM23: 0.013499677 | AN23: 0.018909443 | AO23: 0.012669168 | AP23: =IFERROR(SUMIFS('A share covered list'!AC$4:AC$9640,'A share covered list'!$E$4:$E$9640,'Summary-A share'!$B23,'A share covered list'!AC$4:AC$9640,"<>0",'A share covered list'!AB$4:AB$9640,"<>0")/SUMIFS('A share covered list'!AB$4:AB$9640,'A share covered list'!$E$4:$E$9640,'Summary-A share'!$B23,'A share covered list'!AC$4:AC$9640,"<>0",'A share covered list'!AB$4:AB$9640,"<>0")-1,"-") -> -1
B24: Non-bank financials | C24: 5888.692 | D24: 0.08512773 | E24: 4390.8597 | F24: 0.081708592 | G24: 22 | H24: 0.020018198 | I24: 23.103979 | J24: 13.042428 | K24: 11.600651 | L24: 8.9911923 | M24: 9.2195293 | N24: 1790.0882 | O24: 1.5234308 | P24: 1.4136635 | Q24: 1.49428 | R24: 1.3227721 | S24: 1.2007276 | T24: 136.07991 | U24: 0.017550313 | V24: 0.021700072 | W24: 0.027170604 | X24: 0.029727617 | Y24: 0.032066119 | Z24: 0.00043440037 | AA24: 0.06593803 | AB24: 0.1083896 | AC24: 0.12881001 | AD24: 0.14711865 | AE24: 0.1302374 | AF24: 0.07601855 | AG24: 0.013755465 | AH24: -0.32028193 | AI24: 0.059705609 | AJ24: 0.06044195 | AK24: -0.99700627 | AL24: 0.77144773 | AM24: 0.12428411 | AN24: 0.29022387 | AO24: -0.024766663 | AP24: =IFERROR(SUMIFS('A share covered list'!AC$4:AC$9640,'A share covered list'!$E$4:$E$9640,'Summary-A share'!$B24,'A share covered list'!AC$4:AC$9640,"<>0",'A share covered list'!AB$4:AB$9640,"<>0")/SUMIFS('A share covered list'!AB$4:AB$9640,'A share covered list'!$E$4:$E$9640,'Summary-A share'!$B24,'A share covered list'!AC$4:AC$9640,"<>0",'A share covered list'!AB$4:AB$9640,"<>0")-1,"-") -> -0.99484968
B25: Diversified financials | C25: 21.24179 | D25: 0.0003070742 | E25: 20.09016 | F25: 0.0003738536 | G25: 1 | H25: 0.00090991811 | I25: 46.413604 | J25: 60.483693 | K25: 25.64102 | L25: 24.278274 | M25: - | N25: - | O25: 5.6654141 | P25: 6.2637584 | Q25: 4.2183487 | R25: 3.5939075 | S25: - | T25: - | U25: 0.018831274 | V25: 0.022485133 | W25: 0 | X25: 0 | Y25: 0 | Z25: 0 | AA25: 0.12206365 | AB25: 0.10356111 | AC25: 0.16451564 | AD25: 0.14802978 | AE25: - | AF25: - | AG25: -0.029630731 | AH25: 0.0919392 | AI25: 0.11241428 | AJ25: -1 | AK25: - | AL25: -0.23262616 | AM25: 1.3588646 | AN25: 0.056130271 | AO25: -1 | AP25: =IFERROR(SUMIFS('A share covered list'!AC$4:AC$9640,'A share covered list'!$E$4:$E$9640,'Summary-A share'!$B25,'A share covered list'!AC$4:AC$9640,"<>0",'A share covered list'!AB$4:AB$9640,"<>0")/SUMIFS('A share covered list'!AB$4:AB$9640,'A share covered list'!$E$4:$E$9640,'Summary-A share'!$B25,'A share covered list'!AC$4:AC$9640,"<>0",'A share covered list'!AB$4:AB$9640,"<>0")-1,"-") -> -
B26: Real estate | C26: 406.19472 | D26: 0.0058720059 | E26: 365.39004 | F26: 0.006799467 | G26: 15 | H26: 0.013648772 | I26: 29.744087 | J26: -5.6173573 | K26: -5.7437524 | L26: -11.113134 | M26: -22.357197 | N26: - | O26: 0.29386311 | P26: 0.32585799 | Q26: 0.61748601 | R26: 0.65942503 | S26: 0.72478357 | T26: - | U26: 0.016352589 | V26: 0.011360322 | W26: 0.013265067 | X26: 0.012776286 | Y26: 0.011319226 | Z26: 0 | AA26: 0.0098797153 | AB26: -0.058009127 | AC26: -0.10750568 | AD26: -0.059337449 | AE26: -0.032418356 | AF26: - | AG26: -0.16470524 | AH26: 0.0047049731 | AI26: -0.17635951 | AJ26: -0.21820717 | AK26: -1 | AL26: -6.295032 | AM26: -0.022005659 | AN26: -0.48315639 | AO26: -0.50292811 | AP26: =IFERROR(SUMIFS('A share covered list'!AC$4:AC$9640,'A share covered list'!$E$4:$E$9640,'Summary-A share'!$B26,'A share covered list'!AC$4:AC$9640,"<>0",'A share covered list'!AB$4:AB$9640,"<>0")/SUMIFS('A share covered list'!AB$4:AB$9640,'A share covered list'!$E$4:$E$9640,'Summary-A share'!$B26,'A share covered list'!AC$4:AC$9640,"<>0",'A share covered list'!AB$4:AB$9640,"<>0")-1,"-") -> -1
B27: Auto | C27: 2827.5237 | D27: 0.040875067 | E27: 2093.9544 | F27: 0.038965961 | G27: 60 | H27: 0.054595086 | I27: 27.155352 | J27: 24.115138 | K27: 21.341229 | L27: 16.05317 | M27: 15.446375 | N27: 14.844609 | O27: 2.7116152 | P27: 2.4553154 | Q27: 2.4040297 | R27: 2.1518765 | S27: 2.1333374 | T27: 1.9790357 | U27: 0.013332259 | V27: 0.016108556 | W27: 0.015687822 | X27: 0.021373935 | Y27: 0.020198557 | Z27: 0.021385437 | AA27: 0.099855646 | AB27: 0.10181635 | AC27: 0.1126472 | AD27: 0.13404683 | AE27: 0.13811249 | AF27: 0.13357733 | AG27: 0.11083313 | AH27: 0.10747442 | AI27: 0.16253904 | AJ27: 0.015706285 | AK27: 0.034420687 | AL27: 0.12607075 | AM27: 0.12997889 | AN27: 0.32940905 | AO27: 0.039283919 | AP27: =IFERROR(SUMIFS('A share covered list'!AC$4:AC$9640,'A share covered list'!$E$4:$E$9640,'Summary-A share'!$B27,'A share covered list'!AC$4:AC$9640,"<>0",'A share covered list'!AB$4:AB$9640,"<>0")/SUMIFS('A share covered list'!AB$4:AB$9640,'A share covered list'!$E$4:$E$9640,'Summary-A share'!$B27,'A share covered list'!AC$4:AC$9640,"<>0",'A share covered list'!AB$4:AB$9640,"<>0")-1,"-") -> 0.040537723
B28: Home appliances | C28: 850.89584 | D28: 0.012300666 | E28: 738.84027 | F28: 0.013748924 | G28: 30 | H28: 0.027297543 | I28: 12.440665 | J28: 11.646432 | K28: 11.44306 | L28: 10.479479 | M28: 157.40628 | N28: - | O28: 2.227483 | P28: 2.0293225 | Q28: 1.9815596 | R28: 1.8071958 | S28: 19.60416 | T28: - | U28: 0.040476815 | V28: 0.046555569 | W28: 0.04720123 | X28: 0.051457144 | Y28: 0.0028380559 | Z28: 0 | AA28: 0.17904855 | AB28: 0.17424413 | AC28: 0.17316693 | AD28: 0.17245093 | AE28: 0.12454497 | AF28: - | AG28: 0.035122723 | AH28: 0.029022693 | AI28: 0.066391838 | AJ28: -0.8755884 | AK28: -1 | AL28: 0.068195363 | AM28: 0.017772587 | AN28: 0.091949313 | AO28: -0.93342401 | AP28: =IFERROR(SUMIFS('A share covered list'!AC$4:AC$9640,'A share covered list'!$E$4:$E$9640,'Summary-A share'!$B28,'A share covered list'!AC$4:AC$9640,"<>0",'A share covered list'!AB$4:AB$9640,"<>0")/SUMIFS('A share covered list'!AB$4:AB$9640,'A share covered list'!$E$4:$E$9640,'Summary-A share'!$B28,'A share covered list'!AC$4:AC$9640,"<>0",'A share covered list'!AB$4:AB$9640,"<>0")-1,"-") -> -1
B29: Light manufacturing | C29: 515.03201 | D29: 0.0074453725 | E29: 461.25356 | F29: 0.0085833713 | G29: 48 | H29: 0.043676069 | I29: 21.929061 | J29: 25.322061 | K29: 18.075852 | L29: 18.13882 | M29: 27.866682 | N29: 67.494727 | O29: 2.2183231 | P29: 2.1306859 | Q29: 2.0299858 | R29: 2.1293929 | S29: 3.4359767 | T29: 8.8606286 | U29: 0.022216523 | V29: 0.023123981 | W29: 0.026370147 | X29: 0.026217108 | Y29: 0.015957998 | Z29: 0.007537182 | AA29: 0.10115906 | AB29: 0.084143461 | AC29: 0.11230374 | AD29: 0.11739424 | AE29: 0.12330053 | AF29: 0.12363505 | AG29: 0.011660835 | AH29: 0.13350954 | AI29: -0.074022897 | AJ29: -0.5054451 | AK29: -0.66042474 | AL29: -0.13399384 | AM29: 0.40087783 | AN29: -0.0034714009 | AO29: -0.34908577 | AP29: =IFERROR(SUMIFS('A share covered list'!AC$4:AC$9640,'A share covered list'!$E$4:$E$9640,'Summary-A share'!$B29,'A share covered list'!AC$4:AC$9640,"<>0",'A share covered list'!AB$4:AB$9640,"<>0")/SUMIFS('A share covered list'!AB$4:AB$9640,'A share covered list'!$E$4:$E$9640,'Summary-A share'!$B29,'A share covered list'!AC$4:AC$9640,"<>0",'A share covered list'!AB$4:AB$9640,"<>0")-1,"-") -> -0.58712802
B30: Textiles & apparel | C30: 268.5528 | D30: 0.0038822357 | E30: 251.14984 | F30: 0.004673595 | G30: 24 | H30: 0.021838035 | I30: 17.458926 | J30: 18.649305 | K30: 17.183805 | L30: 15.22674 | M30: 27.371116 | N30: 36.313983 | O30: 1.9442158 | P30: 1.887956 | Q30: 1.845143 | R30: 1.7903793 | S30: 3.5899983 | T30: 6.5471923 | U30: 0.037098354 | V30: 0.037736227 | W30: 0.035637424 | X30: 0.039385477 | Y30: 0.022044976 | Z30: 0.01524069 | AA30: 0.11135942 | AB30: 0.10123465 | AC30: 0.10737686 | AD30: 0.11758126 | AE30: 0.1311601 | AF30: 0.16904274 | AG30: 0.054680422 | AH30: 0.052858824 | AI30: 0.066580021 | AJ30: -0.520728 | AK30: -0.42724716 | AL30: -0.06382969 | AM30: 0.085283803 | AN30: 0.12852815 | AO30: -0.44369312 | AP30: =IFERROR(SUMIFS('A share covered list'!AC$4:AC$9640,'A share covered list'!$E$4:$E$9640,'Summary-A share'!$B30,'A share covered list'!AC$4:AC$9640,"<>0",'A share covered list'!AB$4:AB$9640,"<>0")/SUMIFS('A share covered list'!AB$4:AB$9640,'A share covered list'!$E$4:$E$9640,'Summary-A share'!$B30,'A share covered list'!AC$4:AC$9640,"<>0",'A share covered list'!AB$4:AB$9640,"<>0")-1,"-") -> -0.24626511
B31: Retail | C31: 371.91888 | D31: 0.0053765097 | E31: 339.59726 | F31: 0.0063194946 | G31: 22 | H31: 0.020018198 | I31: 25.691323 | J31: 30.800484 | K31: 25.850337 | L31: 19.723947 | M31: 127.77819 | N31: - | O31: 1.653194 | P31: 1.6085527 | Q31: 1.6837869 | R31: 1.6072629 | S31: 11.230659 | T31: - | U31: 0.01882656 | V31: 0.020887737 | W31: 0.023750959 | X31: 0.027368576 | Y31: 0.0037171278 | Z31: 0 | AA31: 0.064348342 | AB31: 0.052224917 | AC31: 0.065135976 | AD31: 0.081487895 | AE31: 0.087891826 | AF31: - | AG31: -0.091390958 | AH31: -0.050308418 | AI31: 0.058008816 | AJ31: -0.89266001 | AK31: -1 | AL31: -0.16587925 | AM31: 0.19149256 | AN31: 0.31060672 | AO31: -0.84563918 | AP31: =IFERROR(SUMIFS('A share covered list'!AC$4:AC$9640,'A share covered list'!$E$4:$E$9640,'Summary-A share'!$B31,'A share covered list'!AC$4:AC$9640,"<>0",'A share covered list'!AB$4:AB$9640,"<>0")/SUMIFS('A share covered list'!AB$4:AB$9640,'A share covered list'!$E$4:$E$9640,'Summary-A share'!$B31,'A share covered list'!AC$4:AC$9640,"<>0",'A share covered list'!AB$4:AB$9640,"<>0")-1,"-") -> -1
B32: Consumer services | C32: 317.36023 | D32: 0.0045878025 | E32: 285.27637 | F32: 0.0053086485 | G32: 13 | H32: 0.011828935 | I32: 30.138988 | J32: 32.422044 | K32: 35.450173 | L32: 27.965738 | M32: 50.10835 | N32: - | O32: 2.8638494 | P32: 2.7193524 | Q32: 2.8353739 | R32: 2.6285577 | S32: 4.6384545 | T32: - | U32: 0.015786158 | V32: 0.014369427 | W32: 0.013685804 | X32: 0.019194812 | Y32: 0.011405682 | Z32: 0 | AA32: 0.09502142 | AB32: 0.083873562 | AC32: 0.079981949 | AD32: 0.093992074 | AE32: 0.092568496 | AF32: - | AG32: 0.017759919 | AH32: 0.042910606 | AI32: 0.092314578 | AJ32: -0.61387842 | AK32: -1 | AL32: -0.070416792 | AM32: -0.08541929 | AN32: 0.26762873 | AO32: -0.44189465 | AP32: =IFERROR(SUMIFS('A share covered list'!AC$4:AC$9640,'A share covered list'!$E$4:$E$9640,'Summary-A share'!$B32,'A share covered list'!AC$4:AC$9640,"<>0",'A share covered list'!AB$4:AB$9640,"<>0")/SUMIFS('A share covered list'!AB$4:AB$9640,'A share covered list'!$E$4:$E$9640,'Summary-A share'!$B32,'A share covered list'!AC$4:AC$9640,"<>0",'A share covered list'!AB$4:AB$9640,"<>0")-1,"-") -> -1
B33: Food and beverage | C33: 4007.1283 | D33: 0.057927591 | E33: 3898.0271 | F33: 0.072537574 | G33: 59 | H33: 0.053685168 | I33: 20.558496 | J33: 19.627768 | K33: 19.968358 | L33: 19.929691 | M33: 26.67147 | N33: 169.58447 | O33: 4.7270454 | P33: 4.4678425 | Q33: 4.3617606 | R33: 4.2340655 | S33: 6.1891486 | T33: 27.554597 | U33: 0.033937257 | V33: 0.036736666 | W33: 0.03740124 | X33: 0.037673166 | Y33: 0.02269272 | Z33: 0.0038446161 | AA33: 0.22993148 | AB33: 0.22762866 | AC33: 0.21843361 | AD33: 0.21245014 | AE33: 0.23205127 | AF33: 0.16271026 | AG33: 0.027476382 | AH33: -0.024506584 | AI33: 0.013241586 | AJ33: -0.3501412 | AK33: -0.70537932 | AL33: 0.047418954 | AM33: -0.0170565 | AN33: 0.0019402125 | AO33: -0.25277121 | AP33: =IFERROR(SUMIFS('A share covered list'!AC$4:AC$9640,'A share covered list'!$E$4:$E$9640,'Summary-A share'!$B33,'A share covered list'!AC$4:AC$9640,"<>0",'A share covered list'!AB$4:AB$9640,"<>0")/SUMIFS('A share covered list'!AB$4:AB$9640,'A share covered list'!$E$4:$E$9640,'Summary-A share'!$B33,'A share covered list'!AC$4:AC$9640,"<>0",'A share covered list'!AB$4:AB$9640,"<>0")-1,"-") -> -0.84272457
B34: Agriculture | C34: 592.69352 | D34: 0.0085680579 | E34: 410.3423 | F34: 0.0076359743 | G34: 23 | H34: 0.020928116 | I34: 319.04081 | J34: 25.091358 | K34: 25.409747 | L34: 22.289253 | M34: 18.785342 | N34: 199.10023 | O34: 2.2950659 | P34: 2.170212 | Q34: 2.1810628 | R34: 2.0463612 | S34: 2.097011 | T34: 63.805612 | U34: 0.0086359407 | V34: 0.014127479 | W34: 0.014684453 | X34: 0.016317219 | Y34: 0.01978191 | Z34: 0.0011560612 | AA34: 0.0071936438 | AB34: 0.08649241 | AC34: 0.085835677 | AD34: 0.091809325 | AE34: 0.11163017 | AF34: 0.3204698 | AG34: -0.0057550846 | AH34: 0.062703766 | AI34: 0.060131846 | AJ34: 0.030636832 | AK34: -0.97783125 | AL34: 11.715167 | AM34: -0.012530196 | AN34: 0.13999993 | AO34: 0.18652364 | AP34: =IFERROR(SUMIFS('A share covered list'!AC$4:AC$9640,'A share covered list'!$E$4:$E$9640,'Summary-A share'!$B34,'A share covered list'!AC$4:AC$9640,"<>0",'A share covered list'!AB$4:AB$9640,"<>0")/SUMIFS('A share covered list'!AB$4:AB$9640,'A share covered list'!$E$4:$E$9640,'Summary-A share'!$B34,'A share covered list'!AC$4:AC$9640,"<>0",'A share covered list'!AB$4:AB$9640,"<>0")-1,"-") -> -0.90564882
B35: Pharmaceuticals | C35: 3562.4671 | D35: 0.051499507 | E35: 2835.078 | F35: 0.052757375 | G35: 91 | H35: 0.082802548 | I35: 34.576603 | J35: 37.613702 | K35: 28.661066 | L35: 25.580126 | M35: 33.508795 | N35: 45.525375 | O35: 3.4716149 | P35: 3.3368894 | Q35: 3.2973094 | R35: 3.052136 | S35: 4.0158556 | T35: 5.3249414 | U35: 0.013306391 | V35: 0.014047762 | W35: 0.014334982 | X35: 0.015936403 | Y35: 0.011652512 | Z35: 0.009168138 | AA35: 0.10040358 | AB35: 0.088714731 | AC35: 0.11504489 | AD35: 0.11931669 | AE35: 0.11984482 | AF35: 0.11697793 | AG35: 0.0081160667 | AH35: 0.071216676 | AI35: 0.079073659 | AJ35: -0.23119851 | AK35: -0.084520584 | AL35: -0.080744466 | AM35: 0.31236225 | AN35: 0.12044276 | AO35: -0.23661458 | AP35: =IFERROR(SUMIFS('A share covered list'!AC$4:AC$9640,'A share covered list'!$E$4:$E$9640,'Summary-A share'!$B35,'A share covered list'!AC$4:AC$9640,"<>0",'A share covered list'!AB$4:AB$9640,"<>0")/SUMIFS('A share covered list'!AB$4:AB$9640,'A share covered list'!$E$4:$E$9640,'Summary-A share'!$B35,'A share covered list'!AC$4:AC$9640,"<>0",'A share covered list'!AB$4:AB$9640,"<>0")-1,"-") -> -0.26395345
B36: Electronics | C36: 5708.7729 | D36: 0.082526795 | E36: 4646.4802 | F36: 0.086465381 | G36: 95 | H36: 0.08644222 | I36: 76.723279 | J36: 85.81219 | K36: 53.981555 | L36: 46.440101 | M36: 101.69868 | N36: 107.56612 | O36: 4.1350484 | P36: 4.0096845 | Q36: 4.8696042 | R36: 5.091011 | S36: 14.375037 | T36: 15.581873 | U36: 0.0048862778 | V36: 0.0046291062 | W36: 0.0056141715 | X36: 0.006525842 | Y36: 0.0033050746 | Z36: 0.003227233 | AA36: 0.053895616 | AB36: 0.046726281 | AC36: 0.090208669 | AD36: 0.10962532 | AE36: 0.1413493 | AF36: 0.14716852 | AG36: 0.1305826 | AH36: 0.075948171 | AI36: -0.07993593 | AJ36: -0.64180775 | AK36: -0.23867225 | AL36: -0.10591631 | AM36: 0.58965762 | AN36: 0.16239099 | AO36: -0.54335591 | AP36: =IFERROR(SUMIFS('A share covered list'!AC$4:AC$9640,'A share covered list'!$E$4:$E$9640,'Summary-A share'!$B36,'A share covered list'!AC$4:AC$9640,"<>0",'A share covered list'!AB$4:AB$9640,"<>0")/SUMIFS('A share covered list'!AB$4:AB$9640,'A share covered list'!$E$4:$E$9640,'Summary-A share'!$B36,'A share covered list'!AC$4:AC$9640,"<>0",'A share covered list'!AB$4:AB$9640,"<>0")-1,"-") -> -0.054547327
B37: Media | C37: 1057.1261 | D37: 0.015281958 | E37: 981.8994 | F37: 0.018271961 | G37: 33 | H37: 0.030027298 | I37: 36.586253 | J37: 54.683797 | K37: 31.851326 | L37: 22.853 | M37: 21.360393 | N37: 27.704607 | O37: 3.3819567 | P37: 3.388246 | Q37: 3.3154652 | R37: 3.0615481 | S37: 2.9559729 | T37: 4.7559294 | U37: 0.015243921 | V37: 0.015465391 | W37: 0.016227014 | X37: 0.019415698 | Y37: 0.022252824 | Z37: 0.017475465 | AA37: 0.092437907 | AB37: 0.061960694 | AC37: 0.10409191 | AD37: 0.13396701 | AE37: 0.1383857 | AF37: 0.17874605 | AG37: 0.039157245 | AH37: 0.098148311 | AI37: 0.10163819 | AJ37: 0.0098451344 | AK37: -0.22914936 | AL37: -0.33094892 | AM37: 0.71684524 | AN37: 0.39374812 | AO37: 0.069877307 | AP37: =IFERROR(SUMIFS('A share covered list'!AC$4:AC$9640,'A share covered list'!$E$4:$E$9640,'Summary-A share'!$B37,'A share covered list'!AC$4:AC$9640,"<>0",'A share covered list'!AB$4:AB$9640,"<>0")/SUMIFS('A share covered list'!AB$4:AB$9640,'A share covered list'!$E$4:$E$9640,'Summary-A share'!$B37,'A share covered list'!AC$4:AC$9640,"<>0",'A share covered list'!AB$4:AB$9640,"<>0")-1,"-") -> -0.2289949
B38: Computers | C38: 3278.8767 | D38: 0.047399887 | E38: 3015.8882 | F38: 0.056122034 | G38: 74 | H38: 0.06733394 | I38: 75.468545 | J38: 84.232749 | K38: 46.409225 | L38: 27.618103 | M38: 27.156497 | N38: 140.81728 | O38: 5.6331502 | P38: 5.6880429 | Q38: 5.5082232 | R38: 5.1030256 | S38: 6.2041811 | T38: 16.196973 | U38: 0.007079585 | V38: 0.0072946081 | W38: 0.0098511419 | X38: 0.017253921 | Y38: 0.018190269 | Z38: 0.0015289901 | AA38: 0.074642358 | AB38: 0.067527689 | AC38: 0.11868811 | AD38: 0.18477104 | AE38: 0.22846029 | AF38: 0.11479284 | AG38: 0.20252631 | AH38: 0.37920037 | AI38: 0.59879638 | AJ38: 0.15008889 | AK38: -0.8220386 | AL38: -0.10404746 | AM38: 0.81500011 | AN38: 0.68039147 | AO38: 0.016998028 | AP38: =IFERROR(SUMIFS('A share covered list'!AC$4:AC$9640,'A share covered list'!$E$4:$E$9640,'Summary-A share'!$B38,'A share covered list'!AC$4:AC$9640,"<>0",'A share covered list'!AB$4:AB$9640,"<>0")/SUMIFS('A share covered list'!AB$4:AB$9640,'A share covered list'!$E$4:$E$9640,'Summary-A share'!$B38,'A share covered list'!AC$4:AC$9640,"<>0",'A share covered list'!AB$4:AB$9640,"<>0")-1,"-") -> -0.80715082
B39: Telecommunications | C39: 3326.2327 | D39: 0.04808447 | E39: 1162.471 | F39: 0.021632181 | G39: 19 | H39: 0.017288444 | I39: 18.193484 | J39: 17.323126 | K39: 16.493594 | L39: 16.877674 | M39: 16.077216 | N39: 49.736824 | O39: 1.6987811 | P39: 1.6380931 | Q39: 1.592868 | R39: 1.5580842 | S39: 1.521057 | T39: 4.446797 | U39: 0.037022412 | V39: 0.03987938 | W39: 0.042624998 | X39: 0.041789816 | Y39: 0.04435712 | Z39: 0.011475247 | AA39: 0.09337305 | AB39: 0.094561056 | AC39: 0.096574952 | AD39: 0.092316287 | AE39: 0.094609481 | AF39: 0.085388335 | AG39: 0.037243019 | AH39: 0.035437828 | AI39: 0.0088122898 | AJ39: 0.012519869 | AK39: -0.50480275 | AL39: 0.050242514 | AM39: 0.050294242 | AN39: -0.022756741 | AO39: 0.049788397 | AP39: =IFERROR(SUMIFS('A share covered list'!AC$4:AC$9640,'A share covered list'!$E$4:$E$9640,'Summary-A share'!$B39,'A share covered list'!AC$4:AC$9640,"<>0",'A share covered list'!AB$4:AB$9640,"<>0")/SUMIFS('A share covered list'!AB$4:AB$9640,'A share covered list'!$E$4:$E$9640,'Summary-A share'!$B39,'A share covered list'!AC$4:AC$9640,"<>0",'A share covered list'!AB$4:AB$9640,"<>0")-1,"-") -> -0.67675428

Sheet A share covered list
A1: Updated | B1: 46062 | E1: 0
A2: Ticker | B2: Bloomberg ticker | C2: Listed Sector | D2: Name | E2: Sector | F2: Analyst | G2: Analyst | H2: Restricted list | I2: Ranking | J2: Target Price | K2: Closed price （Rmb） | L2: Price change （Week） | M2: Price change （since 2024） | N2: Share （mn） | O2: Free-float share (mn) | P2: Market cap （Rmb mn） | Q2: Free-float market value （Rmb mn） | R2: Income（Rmb mn） | X2: Net profit（Rmb mn） | AD2: Market cap（Rmb mn） | AJ2: Owner's equity(Rmb mn) | AP2: Market cap（Rmb mn） | AV2: Dividend(Rmb mn) | BB2: Market cap（Rmb mn） | BH2: OCF（Rmb mn） | BN2: EPS（Rmb） | BT2: BPS | BZ2: DPS | CF2: OCF per share | CL2: PE（X） | CR2: PB（X） | CX2: Dividend yield | DD2: ROE | DJ2: Income (YoY) | DO2: Net profit（YoY）
C3: 上市板 | R3: 2023A | S3: 2024A | T3: 2025E | U3: 2026E | V3: 2027E | W3: 2028E | X3: 2023A | Y3: 2024A | Z3: 2025E | AA3: 2026E | AB3: 2027E | AC3: 2028E | AD3: 2023A | AE3: 2024A | AF3: 2025E | AG3: 2026E | AH3: 2027E | AI3: 2028E | AJ3: 2023A | AK3: 2024A | AL3: 2025E | AM3: 2026E | AN3: 2027E | AO3: 2028E | AP3: 2023A | AQ3: 2024A | AR3: 2025E | AS3: 2026E | AT3: 2027E | AU3: 2028E | AV3: 2023A | AW3: 2024A | AX3: 2025E | AY3: 2026E | AZ3: 2027E | BA3: 2028E | BB3: 2023A | BC3: 2024A | BD3: 2025E | BE3: 2026E | BF3: 2027E | BG3: 2028E | BH3: 2023A | BI3: 2024A | BJ3: 2025E | BK3: 2026E | BL3: 2027E | BM3: 2028E | BN3: 2023A | BO3: 2024A | BP3: 2025E | BQ3: 2026E | BR3: 2027E | BS3: 2028E | BT3: 2023A | BU3: 2024A | BV3: 2025E | BW3: 2026E | BX3: 2027E | BY3: 2028E | BZ3: 2023A | CA3: 2024A | CB3: 2025E | CC3: 2026E | CD3: 2027E | CE3: 2028E | CF3: 2023A | CG3: 2024A | CH3: 2025E | CI3: 2026E | CJ3: 2027E | CK3: 2028E | CL3: 2023A | CM3: 2024A | CN3: 2025E | CO3: 2026E | CP3: 2027E | CQ3: 2028E | CR3: 2023A | CS3: 2024A | CT3: 2025E | CU3: 2026E | CV3: 2027E | CW3: 2028E | CX3: 2023A | CY3: 2024A | CZ3: 2025E | DA3: 2026E | DB3: 2027E | DC3: 2028E | DD3: 2023A | DE3: 2024A | DF3: 2025E | DG3: 2026E | DH3: 2027E | DI3: 2028E | DJ3: 2024A | DK3: 2025E | DL3: 2026E | DM3: 2027E | DN3: 2028E | DO3: 2024A | DP3: 2025E | DQ3: 2026E | DR3: 2027E | DS3: 2028E
A4: 920026.BJ | B4: 920026 CH Equity | C4: Beijing Stock Exchange | D4: Zhuozhao Dispensing Technology | E4: Machinery | F4: 刘中玉 | G4: Zhongyu LIU | H4: N | I4: Outperform | K4: 36.66 | L4: -0.0416 | M4: 0.0327 | N4: 82.08 | O4: 37.21 | P4: 3008.95 | Q4: 1364.29 | R4: 262.57085 | S4: 125.11995 | T4: 313.7 | U4: 355.37 | X4: 63.932682 | Y4: -20.750805 | Z4: 72.3 | AA4: 78.4 | AD4: 3008.95 | AE4: 3008.95 | AF4: 3008.95 | AG4: 3008.95 | AH4: 3008.95 | AI4: 3008.95 | AJ4: 616.75193 | AK4: 569.54798 | AL4: 633.24 | AM4: 668.26 | AP4: 3008.95 | AQ4: 3008.95 | AR4: 3008.95 | AS4: 3008.95 | AT4: 3008.95 | AU4: 3008.95 | AV4: 55.812527 | AX4: 43.38 | AY4: 47.04 | BB4: 3008.95 | BC4: 3008.95 | BD4: 3008.95 | BE4: 3008.95 | BF4: 3008.95 | BG4: 3008.95 | BH4: 150.66521 | BI4: 34.991339 | BJ4: 30.21 | BK4: 68.96 | BN4: 0.77890694 | BO4: -0.25281196 | BP4: 0.88084795 | BQ4: 0.95516569 | BT4: 7.5140342 | BU4: 6.9389373 | BV4: 7.7149123 | BW4: 8.1415692 | BZ4: 0.67997718 | CB4: 0.52850877 | CC4: 0.57309942 | CF4: 1.8355898 | CG4: 0.42630774 | CH4: 0.36805556 | CI4: 0.84015595 | CL4: 47.064348 | CM4: -145.00401 | CN4: 41.617566 | CO4: 38.379464 | CR4: 4.8787038 | CS4: 5.2830492 | CT4: 4.7516739 | CU4: 4.5026636 | CX4: 0.018548838 | CZ4: 0.014416989 | DA4: 0.01563336 | DD4: 10.366029 | DE4: -3.6433814 | DF4: 11.417472 | DG4: 11.731961 | DJ4: -0.5234812 | DK4: 1.5071942 | DL4: 0.13283392 | DO4: -1.3245727 | DP4: -4.4842021 | DQ4: 0.084370678
A5: 920077.BJ | B5: 920077 CH Equity | C5: Beijing Stock Exchange | D5: Jilin Tangu Carbon Fiber | E5: Chemicals | F5: 严蓓娜 | G5: Beina YAN | H5: N | I5: Outperform | J5: 18.8 | K5: 17.43 | L5: -0.0219 | M5: 0.0241 | N5: 587.68 | O5: 316.96 | P5: 10243.29 | Q5: 5524.56 | R5: 2049.237 | S5: 1603.2355 | T5: 1603.24 | U5: 2463.64 | V5: 2745.52 | X5: 231.38924 | Y5: 93.870517 | Z5: 93.87 | AA5: 164.72 | AB5: 217.61 | AD5: 10243.29 | AE5: 10243.29 | AF5: 10243.29 | AG5: 10243.29 | AH5: 10243.29 | AI5: 10243.29 | AJ5: 2427.8498 | AK5: 2454.5516 | AL5: 2446.3 | AM5: 2611.02 | AN5: 2803.93 | AP5: 10243.29 | AQ5: 10243.29 | AR5: 10243.29 | AS5: 10243.29 | AT5: 10243.29 | AU5: 10243.29 | AV5: 58.768182 | AY5: 24.71 | AZ5: 32.64 | BB5: 10243.29 | BC5: 10243.29 | BD5: 10243.29 | BE5: 10243.29 | BF5: 10243.29 | BG5: 10243.29 | BH5: -595.17996 | BI5: -317.66138 | BJ5: -317.66 | BK5: 192.21 | BL5: 482.13 | BN5: 0.39373339 | BO5: 0.15973066 | BP5: 0.15972978 | BQ5: 0.28028859 | BR5: 0.37028655 | BT5: 4.1312445 | BU5: 4.1766805 | BV5: 4.1626395 | BW5: 4.4429281 | BX5: 4.771185 | BZ5: 0.10000031 | CC5: 0.042046692 | CD5: 0.05554043 | CF5: -1.012762 | CG5: -0.54053461 | CH5: -0.54053226 | CI5: 0.32706575 | CJ5: 0.82039545 | CL5: 44.268653 | CM5: 109.12148 | CN5: 109.12208 | CO5: 62.186073 | CP5: 47.07178 | CR5: 4.219079 | CS5: 4.1731818 | CT5: 4.1872583 | CU5: 3.923099 | CV5: 3.6531903 | CX5: 0.0057372369 | DA5: 0.0024123109 | DB5: 0.0031864762 | DD5: 9.5306243 | DE5: 3.8243448 | DF5: 3.8372236 | DG5: 6.3086457 | DH5: 7.7608927 | DJ5: -0.21764273 | DK5: 2.8070673e-06 | DL5: 0.53666326 | DM5: 0.11441607 | DO5: -0.59431771 | DP5: -5.5096106e-06 | DQ5: 0.75476723 | DR5: 0.32109034
A6: 920139.BJ | B6: 920139 CH Equity | C6: Beijing Stock Exchange | D6: Sino IC Technology | E6: Electronics | F6: 于新彦 | G6: Xinyan YU | H6: N | I6: Outperform | K6: 21.16 | L6: -0.0117 | M6: 0.0124 | N6: 269.51 | O6: 258.32 | P6: 5702.78 | Q6: 5466.1 | R6: 315.48963 | S6: 276.27555 | T6: 367.52 | U6: 439.5 | X6: 74.862559 | Y6: -14.983229 | Z6: 57.61 | AA6: 75.03 | AD6: 5702.78 | AE6: 5702.78 | AF6: 5702.78 | AG6: 5702.78 | AH6: 5702.78 | AI6: 5702.78 | AJ6: 1115.6817 | AK6: 1099.682 | AL6: 1157.56 | AM6: 1223.94 | AP6: 5702.78 | AQ6: 5702.78 | AR6: 5702.78 | AS6: 5702.78 | AT6: 5702.78 | AU6: 5702.78 | AV6: 15.7412 | AX6: 8.64 | AY6: 11.25 | BB6: 5702.78 | BC6: 5702.78 | BD6: 5702.78 | BE6: 5702.78 | BF6: 5702.78 | BG6: 5702.78 | BH6: 172.36836 | BI6: 143.88133 | BJ6: 205.48 | BK6: 225.59 | BN6: 0.27777284 | BO6: -0.055594334 | BP6: 0.2137583 | BQ6: 0.27839412 | BT6: 4.139667 | BU6: 4.0803014 | BV6: 4.295054 | BW6: 4.5413528 | BZ6: 0.058406738 | CB6: 0.03205818 | CC6: 0.041742421 | CF6: 0.63956201 | CG6: 0.53386269 | CH6: 0.76242069 | CI6: 0.83703759 | CL6: 76.176664 | CM6: -380.61088 | CN6: 98.989412 | CO6: 76.006664 | CR6: 5.111476 | CS6: 5.1858445 | CT6: 4.9265524 | CU6: 4.6593624 | CX6: 0.0027602678 | CZ6: 0.0015150506 | DA6: 0.0019727221 | DD6: 6.7100287 | DE6: -1.3625056 | DF6: 4.9768479 | DG6: 6.1302025 | DJ6: -0.12429592 | DK6: 0.3302661 | DL6: 0.19585329 | DO6: -1.2001432 | DP6: -4.8449656 | DQ6: 0.30237806
A7: 920368.BJ | B7: 920368 CH Equity | C7: Beijing Stock Exchange | D7: LINTON Technologies Group | E7: Machinery | F7: 张梓丁 | G7: Ziding ZHANG | H7: N | I7: Outperform | J7: 25 | K7: 58.86 | L7: 0.0096 | M7: 1.3629 | N7: 234.78 | O7: 223.36 | P7: 13819.18 | Q7: 13147.1 | R7: 6001.5771 | S7: 5669.2786 | T7: 7052.35 | X7: 681.48159 | Y7: 340.49299 | Z7: 787.44 | AD7: 13819.18 | AE7: 13819.18 | AF7: 13819.18 | AG7: 13819.18 | AH7: 13819.18 | AI7: 13819.18 | AJ7: 3991.1548 | AK7: 4332.2163 | AL7: 5226.01 | AP7: 13819.18 | AQ7: 13819.18 | AR7: 13819.18 | AS7: 13819.18 | AT7: 13819.18 | AU7: 13819.18 | AV7: 70.049892 | AW7: 35.217066 | AX7: 39.37 | BB7: 13819.18 | BC7: 13819.18 | BD7: 13819.18 | BE7: 13819.18 | BF7: 13819.18 | BG7: 13819.18 | BH7: 463.4203 | BI7: -493.75486 | BJ7: 1809.34 | BN7: 2.902639 | BO7: 1.450264 | BP7: 3.3539484 | BT7: 16.999552 | BU7: 18.452237 | BV7: 22.259179 | BZ7: 0.29836397 | CA7: 0.15000028 | CB7: 0.1676889 | CF7: 1.9738491 | CG7: -2.1030533 | CH7: 7.7065338 | CL7: 20.278141 | CM7: 40.585799 | CN7: 17.549502 | CR7: 3.4624515 | CS7: 3.1898638 | CT7: 2.644308 | CX7: 0.0050690339 | CY7: 0.0025484194 | CZ7: 0.0028489389 | DD7: 17.074797 | DE7: 7.8595565 | DF7: 15.067709 | DJ7: -0.055368524 | DK7: 0.24395897 | DO7: -0.50036363 | DP7: 1.3126468
A8: 920394.BJ | B8: 920394 CH Equity | C8: Beijing Stock Exchange | D8: Metastar Special Paper | E8: Light manufacturing | F8: 徐贇妍 | G8: Yunyan XU | H8: N | I8: Outperform | J8: 18 | K8: 57.59 | L8: 0.0016 | M8: 0.4074 | N8: 146.25 | O8: 145.17 | P8: 8422.54 | Q8: 8360.5 | R8: 340.47177 | S8: 407.9459 | T8: 527.37 | U8: 634.83 | X8: 81.633867 | Y8: 100.52256 | Z8: 115.74 | AA8: 138.05 | AD8: 8422.54 | AE8: 8422.54 | AF8: 8422.54 | AG8: 8422.54 | AH8: 8422.54 | AI8: 8422.54 | AJ8: 666.41081 | AK8: 735.19118 | AL8: 769.93 | AM8: 907.98 | AP8: 8422.54 | AQ8: 8422.54 | AR8: 8422.54 | AS8: 8422.54 | AT8: 8422.54 | AU8: 8422.54 | AV8: 29.25 | AW8: 29.25 | BB8: 8422.54 | BC8: 8422.54 | BD8: 8422.54 | BE8: 8422.54 | BF8: 8422.54 | BG8: 8422.54 | BH8: 35.168225 | BI8: 42.481697 | BJ8: 140.06 | BK8: 155.08 | BN8: 0.55818029 | BO8: 0.68733373 | BP8: 0.79138462 | BQ8: 0.94393162 | BT8: 4.5566551 | BU8: 5.0269483 | BV8: 5.2644786 | BW8: 6.2084103 | BZ8: 0.2 | CA8: 0.2 | CF8: 0.2404665 | CG8: 0.29047314 | CH8: 0.95767521 | CI8: 1.0603761 | CL8: 103.17458 | CM8: 83.787561 | CN8: 72.771211 | CO8: 61.010793 | CR8: 12.638661 | CS8: 11.456258 | CT8: 10.939358 | CU8: 9.2761294 | CX8: 0.0034728241 | CY8: 0.0034728241 | DD8: 12.249781 | DE8: 13.672982 | DF8: 15.032535 | DG8: 15.204079 | DJ8: 0.19817833 | DK8: 0.29274495 | DL8: 0.20376586 | DO8: 0.23138303 | DP8: 0.15138335 | DQ8: 0.19275963
