Workbook
Name comp1: OFFSET(data!$A$3,1,1,data!$O$4,1)
Name comp2: OFFSET(data!$A$3,1,2,data!$O$4,1)
Name pd: OFFSET(data!$A$3,1,9,data!$O$4,1)
Name timeseries: OFFSET(data!$A$3,1,0,data!$O$4,1)

Sheet 价差分析
E1: 价差分析
D4: Wind代码1： | E4: 000002.SZ | G4: Wind代码2： | H4: 600048.SH | J4: Wind代码3： | K4: 600895.SH | M4: Wind代码4： | N4: 600383.SH | P4: Wind代码5： | Q4: 001979.SZ | S4: 起始日期: | T4: =TODAY()-365 -> 44900 | V4: 行情周期： | W4: 日
D5: 公司简称： | E5: =[1]!s_info_name(E4) -> 万科A | G5: 公司简称： | H5: =[1]!s_info_name(H4) -> 保利发展 | J5: 公司简称： | K5: =[1]!s_info_name(K4) -> 张江高科 | M5: 公司简称： | N5: =[1]!s_info_name(N4) -> 金地集团 | P5: 公司简称： | Q5: =[1]!s_info_name(Q4) -> 招商蛇口 | S5: 截止日期: | T5: =[1]!TDaysOffset(TODAY(),"Offset=-1") -> 45264 | V5: 复权选择： | W5: 不复权
D7: 实时行情 | N7: 价格走势
C8: =E4 -> 000002.SZ | D8: =E5 -> 万科A | E8: =IF(RTD("wdf.rtq",,E4,26)>0,"↑",IF(RTD("wdf.rtq",,E4,26)=0,"--","↓"))&" 收盘:"&RTD("wdf.rtq",,E4,5)&"︱"&"最高:"&RTD("wdf.rtq",,E4,3)&"︱"&"最低:"&RTD("wdf.rtq",,E4,4)&"︱"&"涨跌幅:"&TRUNC(RTD("wdf.rtq",,E4,27),2)&"%︱"&"前收盘:"&RTD("wdf.rtq",,E4,1)&"︱"&"成交额:"&TRUNC(RTD("wdf.rtq",,E4,29)/100000000,2)&"亿︱" -> ↓ 收盘:10.79︱最高:11.16︱最低:10.78︱涨跌幅:-3.49%︱前收盘:11.18︱成交额:10.38亿︱
C9: =H4 -> 600048.SH | D9: =H5 -> 保利发展 | E9: =IF(RTD("wdf.rtq",,H4,26)>0,"↑",IF(RTD("wdf.rtq",,H4,26)=0,"--","↓"))&" 收盘:"&RTD("wdf.rtq",,H4,5)&"︱"&"最高:"&RTD("wdf.rtq",,H4,3)&"︱"&"最低:"&RTD("wdf.rtq",,H4,4)&"︱"&"涨跌幅:"&TRUNC(RTD("wdf.rtq",,H4,27),2)&"%︱"&"前收盘:"&RTD("wdf.rtq",,H4,1)&"︱"&"成交额:"&TRUNC(RTD("wdf.rtq",,H4,29)/100000000,2)&"亿︱" -> ↓ 收盘:9.66︱最高:9.97︱最低:9.64︱涨跌幅:-3.01%︱前收盘:9.96︱成交额:7.46亿︱
C10: =K4 -> 600895.SH | D10: =K5 -> 张江高科 | E10: =IF(RTD("wdf.rtq",,K4,26)>0,"↑",IF(RTD("wdf.rtq",,K4,26)=0,"--","↓"))&" 收盘:"&RTD("wdf.rtq",,K4,5)&"︱"&"最高:"&RTD("wdf.rtq",,K4,3)&"︱"&"最低:"&RTD("wdf.rtq",,K4,4)&"︱"&"涨跌幅:"&TRUNC(RTD("wdf.rtq",,K4,27),2)&"%︱"&"前收盘:"&RTD("wdf.rtq",,K4,1)&"︱"&"成交额:"&TRUNC(RTD("wdf.rtq",,K4,29)/100000000,2)&"亿︱" -> ↓ 收盘:21.74︱最高:22.98︱最低:21.68︱涨跌幅:-5.4%︱前收盘:22.98︱成交额:15.31亿︱
C11: =N4 -> 600383.SH | D11: =N5 -> 金地集团 | E11: =IF(RTD("wdf.rtq",,N4,26)>0,"↑",IF(RTD("wdf.rtq",,N4,26)=0,"--","↓"))&" 收盘:"&RTD("wdf.rtq",,N4,5)&"︱"&"最高:"&RTD("wdf.rtq",,N4,3)&"︱"&"最低:"&RTD("wdf.rtq",,N4,4)&"︱"&"涨跌幅:"&TRUNC(RTD("wdf.rtq",,N4,27),2)&"%︱"&"前收盘:"&RTD("wdf.rtq",,N4,1)&"︱"&"成交额:"&TRUNC(RTD("wdf.rtq",,N4,29)/100000000,2)&"亿︱" -> ↓ 收盘:4.97︱最高:5.1︱最低:4.97︱涨跌幅:-2.93%︱前收盘:5.12︱成交额:3.84亿︱
C12: =Q4 -> 001979.SZ | D12: =Q5 -> 招商蛇口 | E12: =IF(RTD("wdf.rtq",,Q4,26)>0,"↑",IF(RTD("wdf.rtq",,Q4,26)=0,"--","↓"))&" 收盘:"&RTD("wdf.rtq",,Q4,5)&"︱"&"最高:"&RTD("wdf.rtq",,Q4,3)&"︱"&"最低:"&RTD("wdf.rtq",,Q4,4)&"︱"&"涨跌幅:"&TRUNC(RTD("wdf.rtq",,Q4,27),2)&"%︱"&"前收盘:"&RTD("wdf.rtq",,Q4,1)&"︱"&"成交额:"&TRUNC(RTD("wdf.rtq",,Q4,29)/100000000,2)&"亿︱" -> ↓ 收盘:9.62︱最高:9.96︱最低:9.6︱涨跌幅:-3.51%︱前收盘:9.97︱成交额:5.39亿︱
D15: 价差参数
D16: 多头代码： | E16: 000002.SZ | G16: 空头代码： | H16: 001979.SZ
D17: 公司简称： | E17: =[1]!s_info_name(E16) -> 万科A | G17: 公司简称： | H17: =[1]!s_info_name(H16) -> 招商蛇口
D20: 价差走势 | N20: 价差统计
N24: 最新 | P24: =data!J4 -> 1.21
N25: 平均值 | P25: =AVERAGE(pd) -> 1.7578926
N26: 与均值差 | P26: =P24-P25 -> -0.54789256
N27: 最新价差出现概率 | P27: =1-FREQUENCY(pd,P24)/data!N6 -> 0.52479339
N28: 标准偏差 | P28: =STDEV(pd) -> 1.5295108
N29: 与均值差/标准偏差 | P29: =P26/P28 -> -0.35821424
N30: 中间值 | P30: =MEDIAN(pd) -> 1.31
N31: 最高 | P31: =MAX(pd) -> 5.84
N32: 最低 | P32: =MIN(pd) -> -0.61

Sheet data
B1: =价差分析!E4 -> 000002.SZ | C1: =价差分析!H4 -> 600048.SH | D1: =价差分析!$K$4 -> 600895.SH | E1: =价差分析!$N$4 -> 600383.SH | F1: =价差分析!$Q$4 -> 001979.SZ | H1: =价差分析!E16 -> 000002.SZ | I1: =价差分析!H16 -> 001979.SZ
B2: Wind代码1 | C2: Wind代码2 | D2: Wind代码3 | E2: Wind代码4 | F2: Wind代码5
A3: 日期 | B3: =[1]!s_info_name(B1) -> 万科A | C3: =[1]!s_info_name(C1) -> 保利发展 | D3: =[1]!s_info_name(D1) -> 张江高科 | E3: =[1]!s_info_name(E1) -> 金地集团 | F3: =[1]!s_info_name(F1) -> 招商蛇口 | H3: =[1]!s_info_name(H1) -> 万科A | I3: =[1]!s_info_name(I1) -> 招商蛇口 | J3: 价差
A4: =--[1]!td(价差分析!T5) -> 45264 | B4: =IF($A4="","",[1]!s_dq_close(B$1,$A4,$M$4)) -> 11.18 | C4: =IF($A4="","",[1]!s_dq_close(C$1,$A4,$M$4)) -> 9.96 | D4: =IF($A4="","",[1]!s_dq_close(D$1,$A4,$M$4)) -> 22.98 | E4: =IF($A4="","",[1]!s_dq_close(E$1,$A4,$M$4)) -> 5.12 | F4: =IF($A4="","",[1]!s_dq_close(F$1,$A4,$M$4)) -> 9.97 | H4: =IF($A4="","",[1]!s_dq_close(H$1,$A4,$M$4)) -> 11.18 | I4: =IF($A4="","",[1]!s_dq_close(I$1,$A4,$M$4)) -> 9.97 | J4: =IF(H4="","",H4-I4) -> 1.21 | M4: =IF(价差分析!$W$5="不复权",1,IF(价差分析!$W$5="后复权",2,3)) -> 1 | N4: =MIN(A4:A1504) -> 44901 | O4: =MATCH(N4,A3:A1503,-1)-1 -> 242
A5: =IF(A4="","",IF(IF(价差分析!$W$4="日",--[1]!td(A4-1),IF(价差分析!$W$4="周",--[1]!td(A4-7),--[1]!td(A4-30)))-价差分析!$T$4>0,IF(价差分析!$W$4="日",--[1]!td(A4-1),IF(价差分析!$W$4="周",--[1]!td(A4-7),--[1]!td(A4-30))),"")) -> 45261 | B5: =IF($A5="","",[1]!s_dq_close(B$1,$A5,$M$4)) -> 11.4 | C5: =IF($A5="","",[1]!s_dq_close(C$1,$A5,$M$4)) -> 10.25 | D5: =IF($A5="","",[1]!s_dq_close(D$1,$A5,$M$4)) -> 22.92 | E5: =IF($A5="","",[1]!s_dq_close(E$1,$A5,$M$4)) -> 5.26 | F5: =IF($A5="","",[1]!s_dq_close(F$1,$A5,$M$4)) -> 10.26 | H5: =IF($A5="","",[1]!s_dq_close(H$1,$A5,$M$4)) -> 11.4 | I5: =IF($A5="","",[1]!s_dq_close(I$1,$A5,$M$4)) -> 10.26 | J5: =IF(H5="","",H5-I5) -> 1.14 | M5: 价差 | N5: 分布数 | O5: 价差统计
A6: =IF(A5="","",IF(IF(价差分析!$W$4="日",--[1]!td(A5-1),IF(价差分析!$W$4="周",--[1]!td(A5-7),--[1]!td(A5-30)))-价差分析!$T$4>0,IF(价差分析!$W$4="日",--[1]!td(A5-1),IF(价差分析!$W$4="周",--[1]!td(A5-7),--[1]!td(A5-30))),"")) -> 45260 | B6: =IF($A6="","",[1]!s_dq_close(B$1,$A6,$M$4)) -> 11.44 | C6: =IF($A6="","",[1]!s_dq_close(C$1,$A6,$M$4)) -> 10.26 | D6: =IF($A6="","",[1]!s_dq_close(D$1,$A6,$M$4)) -> 22.75 | E6: =IF($A6="","",[1]!s_dq_close(E$1,$A6,$M$4)) -> 5.12 | F6: =IF($A6="","",[1]!s_dq_close(F$1,$A6,$M$4)) -> 10.42 | H6: =IF($A6="","",[1]!s_dq_close(H$1,$A6,$M$4)) -> 11.44 | I6: =IF($A6="","",[1]!s_dq_close(I$1,$A6,$M$4)) -> 10.42 | J6: =IF(H6="","",H6-I6) -> 1.02 | M6: =MIN(pd) -> -0.61 | N6: =SUM(N7:N16) -> 242
A7: =IF(A6="","",IF(IF(价差分析!$W$4="日",--[1]!td(A6-1),IF(价差分析!$W$4="周",--[1]!td(A6-7),--[1]!td(A6-30)))-价差分析!$T$4>0,IF(价差分析!$W$4="日",--[1]!td(A6-1),IF(价差分析!$W$4="周",--[1]!td(A6-7),--[1]!td(A6-30))),"")) -> 45259 | B7: =IF($A7="","",[1]!s_dq_close(B$1,$A7,$M$4)) -> 11.46 | C7: =IF($A7="","",[1]!s_dq_close(C$1,$A7,$M$4)) -> 10.35 | D7: =IF($A7="","",[1]!s_dq_close(D$1,$A7,$M$4)) -> 23.32 | E7: =IF($A7="","",[1]!s_dq_close(E$1,$A7,$M$4)) -> 5.14 | F7: =IF($A7="","",[1]!s_dq_close(F$1,$A7,$M$4)) -> 10.48 | H7: =IF($A7="","",[1]!s_dq_close(H$1,$A7,$M$4)) -> 11.46 | I7: =IF($A7="","",[1]!s_dq_close(I$1,$A7,$M$4)) -> 10.48 | J7: =IF(H7="","",H7-I7) -> 0.98 | M7: =(价差分析!$P$31-价差分析!$P$32)/10+M6 -> 0.035 | N7: {=FREQUENCY(pd,M7:M16)} -> 12 | O7: =N7/$N$6 -> 0.049586777
A8: =IF(A7="","",IF(IF(价差分析!$W$4="日",--[1]!td(A7-1),IF(价差分析!$W$4="周",--[1]!td(A7-7),--[1]!td(A7-30)))-价差分析!$T$4>0,IF(价差分析!$W$4="日",--[1]!td(A7-1),IF(价差分析!$W$4="周",--[1]!td(A7-7),--[1]!td(A7-30))),"")) -> 45258 | B8: =IF($A8="","",[1]!s_dq_close(B$1,$A8,$M$4)) -> 11.75 | C8: =IF($A8="","",[1]!s_dq_close(C$1,$A8,$M$4)) -> 10.77 | D8: =IF($A8="","",[1]!s_dq_close(D$1,$A8,$M$4)) -> 23.7 | E8: =IF($A8="","",[1]!s_dq_close(E$1,$A8,$M$4)) -> 5.37 | F8: =IF($A8="","",[1]!s_dq_close(F$1,$A8,$M$4)) -> 10.88 | H8: =IF($A8="","",[1]!s_dq_close(H$1,$A8,$M$4)) -> 11.75 | I8: =IF($A8="","",[1]!s_dq_close(I$1,$A8,$M$4)) -> 10.88 | J8: =IF(H8="","",H8-I8) -> 0.87 | M8: =(价差分析!$P$31-价差分析!$P$32)/10+M7 -> 0.68 | N8: 35 | O8: =N8/$N$6 -> 0.1446281
A9: =IF(A8="","",IF(IF(价差分析!$W$4="日",--[1]!td(A8-1),IF(价差分析!$W$4="周",--[1]!td(A8-7),--[1]!td(A8-30)))-价差分析!$T$4>0,IF(价差分析!$W$4="日",--[1]!td(A8-1),IF(价差分析!$W$4="周",--[1]!td(A8-7),--[1]!td(A8-30))),"")) -> 45257 | B9: =IF($A9="","",[1]!s_dq_close(B$1,$A9,$M$4)) -> 11.8 | C9: =IF($A9="","",[1]!s_dq_close(C$1,$A9,$M$4)) -> 10.91 | D9: =IF($A9="","",[1]!s_dq_close(D$1,$A9,$M$4)) -> 25.31 | E9: =IF($A9="","",[1]!s_dq_close(E$1,$A9,$M$4)) -> 5.46 | F9: =IF($A9="","",[1]!s_dq_close(F$1,$A9,$M$4)) -> 11.04 | H9: =IF($A9="","",[1]!s_dq_close(H$1,$A9,$M$4)) -> 11.8 | I9: =IF($A9="","",[1]!s_dq_close(I$1,$A9,$M$4)) -> 11.04 | J9: =IF(H9="","",H9-I9) -> 0.76 | M9: =(价差分析!$P$31-价差分析!$P$32)/10+M8 -> 1.325 | N9: 77 | O9: =N9/$N$6 -> 0.31818182
A10: =IF(A9="","",IF(IF(价差分析!$W$4="日",--[1]!td(A9-1),IF(价差分析!$W$4="周",--[1]!td(A9-7),--[1]!td(A9-30)))-价差分析!$T$4>0,IF(价差分析!$W$4="日",--[1]!td(A9-1),IF(价差分析!$W$4="周",--[1]!td(A9-7),--[1]!td(A9-30))),"")) -> 45254 | B10: =IF($A10="","",[1]!s_dq_close(B$1,$A10,$M$4)) -> 12.12 | C10: =IF($A10="","",[1]!s_dq_close(C$1,$A10,$M$4)) -> 11.19 | D10: =IF($A10="","",[1]!s_dq_close(D$1,$A10,$M$4)) -> 23.41 | E10: =IF($A10="","",[1]!s_dq_close(E$1,$A10,$M$4)) -> 5.71 | F10: =IF($A10="","",[1]!s_dq_close(F$1,$A10,$M$4)) -> 11.13 | H10: =IF($A10="","",[1]!s_dq_close(H$1,$A10,$M$4)) -> 12.12 | I10: =IF($A10="","",[1]!s_dq_close(I$1,$A10,$M$4)) -> 11.13 | J10: =IF(H10="","",H10-I10) -> 0.99 | M10: =(价差分析!$P$31-价差分析!$P$32)/10+M9 -> 1.97 | N10: 50 | O10: =N10/$N$6 -> 0.20661157
A11: =IF(A10="","",IF(IF(价差分析!$W$4="日",--[1]!td(A10-1),IF(价差分析!$W$4="周",--[1]!td(A10-7),--[1]!td(A10-30)))-价差分析!$T$4>0,IF(价差分析!$W$4="日",--[1]!td(A10-1),IF(价差分析!$W$4="周",--[1]!td(A10-7),--[1]!td(A10-30))),"")) -> 45253 | B11: =IF($A11="","",[1]!s_dq_close(B$1,$A11,$M$4)) -> 12.17 | C11: =IF($A11="","",[1]!s_dq_close(C$1,$A11,$M$4)) -> 11.2 | D11: =IF($A11="","",[1]!s_dq_close(D$1,$A11,$M$4)) -> 22.73 | E11: =IF($A11="","",[1]!s_dq_close(E$1,$A11,$M$4)) -> 5.76 | F11: =IF($A11="","",[1]!s_dq_close(F$1,$A11,$M$4)) -> 11.1 | H11: =IF($A11="","",[1]!s_dq_close(H$1,$A11,$M$4)) -> 12.17 | I11: =IF($A11="","",[1]!s_dq_close(I$1,$A11,$M$4)) -> 11.1 | J11: =IF(H11="","",H11-I11) -> 1.07 | M11: =(价差分析!$P$31-价差分析!$P$32)/10+M10 -> 2.615 | N11: 17 | O11: =N11/$N$6 -> 0.070247934
A12: =IF(A11="","",IF(IF(价差分析!$W$4="日",--[1]!td(A11-1),IF(价差分析!$W$4="周",--[1]!td(A11-7),--[1]!td(A11-30)))-价差分析!$T$4>0,IF(价差分析!$W$4="日",--[1]!td(A11-1),IF(价差分析!$W$4="周",--[1]!td(A11-7),--[1]!td(A11-30))),"")) -> 45252 | B12: =IF($A12="","",[1]!s_dq_close(B$1,$A12,$M$4)) -> 11.84 | C12: =IF($A12="","",[1]!s_dq_close(C$1,$A12,$M$4)) -> 10.85 | D12: =IF($A12="","",[1]!s_dq_close(D$1,$A12,$M$4)) -> 22.37 | E12: =IF($A12="","",[1]!s_dq_close(E$1,$A12,$M$4)) -> 5.5 | F12: =IF($A12="","",[1]!s_dq_close(F$1,$A12,$M$4)) -> 10.67 | H12: =IF($A12="","",[1]!s_dq_close(H$1,$A12,$M$4)) -> 11.84 | I12: =IF($A12="","",[1]!s_dq_close(I$1,$A12,$M$4)) -> 10.67 | J12: =IF(H12="","",H12-I12) -> 1.17 | M12: =(价差分析!$P$31-价差分析!$P$32)/10+M11 -> 3.26 | N12: 10 | O12: =N12/$N$6 -> 0.041322314
A13: =IF(A12="","",IF(IF(价差分析!$W$4="日",--[1]!td(A12-1),IF(价差分析!$W$4="周",--[1]!td(A12-7),--[1]!td(A12-30)))-价差分析!$T$4>0,IF(价差分析!$W$4="日",--[1]!td(A12-1),IF(价差分析!$W$4="周",--[1]!td(A12-7),--[1]!td(A12-30))),"")) -> 45251 | B13: =IF($A13="","",[1]!s_dq_close(B$1,$A13,$M$4)) -> 11.92 | C13: =IF($A13="","",[1]!s_dq_close(C$1,$A13,$M$4)) -> 10.97 | D13: =IF($A13="","",[1]!s_dq_close(D$1,$A13,$M$4)) -> 23.19 | E13: =IF($A13="","",[1]!s_dq_close(E$1,$A13,$M$4)) -> 5.61 | F13: =IF($A13="","",[1]!s_dq_close(F$1,$A13,$M$4)) -> 10.86 | H13: =IF($A13="","",[1]!s_dq_close(H$1,$A13,$M$4)) -> 11.92 | I13: =IF($A13="","",[1]!s_dq_close(I$1,$A13,$M$4)) -> 10.86 | J13: =IF(H13="","",H13-I13) -> 1.06 | M13: =(价差分析!$P$31-价差分析!$P$32)/10+M12 -> 3.905 | N13: 8 | O13: =N13/$N$6 -> 0.033057851
A14: =IF(A13="","",IF(IF(价差分析!$W$4="日",--[1]!td(A13-1),IF(价差分析!$W$4="周",--[1]!td(A13-7),--[1]!td(A13-30)))-价差分析!$T$4>0,IF(价差分析!$W$4="日",--[1]!td(A13-1),IF(价差分析!$W$4="周",--[1]!td(A13-7),--[1]!td(A13-30))),"")) -> 45250 | B14: =IF($A14="","",[1]!s_dq_close(B$1,$A14,$M$4)) -> 11.57 | C14: =IF($A14="","",[1]!s_dq_close(C$1,$A14,$M$4)) -> 10.78 | D14: =IF($A14="","",[1]!s_dq_close(D$1,$A14,$M$4)) -> 23.86 | E14: =IF($A14="","",[1]!s_dq_close(E$1,$A14,$M$4)) -> 5.42 | F14: =IF($A14="","",[1]!s_dq_close(F$1,$A14,$M$4)) -> 10.65 | H14: =IF($A14="","",[1]!s_dq_close(H$1,$A14,$M$4)) -> 11.57 | I14: =IF($A14="","",[1]!s_dq_close(I$1,$A14,$M$4)) -> 10.65 | J14: =IF(H14="","",H14-I14) -> 0.92 | M14: =(价差分析!$P$31-价差分析!$P$32)/10+M13 -> 4.55 | N14: 9 | O14: =N14/$N$6 -> 0.037190083
A15: =IF(A14="","",IF(IF(价差分析!$W$4="日",--[1]!td(A14-1),IF(价差分析!$W$4="周",--[1]!td(A14-7),--[1]!td(A14-30)))-价差分析!$T$4>0,IF(价差分析!$W$4="日",--[1]!td(A14-1),IF(价差分析!$W$4="周",--[1]!td(A14-7),--[1]!td(A14-30))),"")) -> 45247 | B15: =IF($A15="","",[1]!s_dq_close(B$1,$A15,$M$4)) -> 11.62 | C15: =IF($A15="","",[1]!s_dq_close(C$1,$A15,$M$4)) -> 10.84 | D15: =IF($A15="","",[1]!s_dq_close(D$1,$A15,$M$4)) -> 23.97 | E15: =IF($A15="","",[1]!s_dq_close(E$1,$A15,$M$4)) -> 5.46 | F15: =IF($A15="","",[1]!s_dq_close(F$1,$A15,$M$4)) -> 10.8 | H15: =IF($A15="","",[1]!s_dq_close(H$1,$A15,$M$4)) -> 11.62 | I15: =IF($A15="","",[1]!s_dq_close(I$1,$A15,$M$4)) -> 10.8 | J15: =IF(H15="","",H15-I15) -> 0.82 | M15: =(价差分析!$P$31-价差分析!$P$32)/10+M14 -> 5.195 | N15: 10 | O15: =N15/$N$6 -> 0.041322314
A16: =IF(A15="","",IF(IF(价差分析!$W$4="日",--[1]!td(A15-1),IF(价差分析!$W$4="周",--[1]!td(A15-7),--[1]!td(A15-30)))-价差分析!$T$4>0,IF(价差分析!$W$4="日",--[1]!td(A15-1),IF(价差分析!$W$4="周",--[1]!td(A15-7),--[1]!td(A15-30))),"")) -> 45246 | B16: =IF($A16="","",[1]!s_dq_close(B$1,$A16,$M$4)) -> 11.8 | C16: =IF($A16="","",[1]!s_dq_close(C$1,$A16,$M$4)) -> 10.94 | D16: =IF($A16="","",[1]!s_dq_close(D$1,$A16,$M$4)) -> 24.53 | E16: =IF($A16="","",[1]!s_dq_close(E$1,$A16,$M$4)) -> 5.52 | F16: =IF($A16="","",[1]!s_dq_close(F$1,$A16,$M$4)) -> 10.78 | H16: =IF($A16="","",[1]!s_dq_close(H$1,$A16,$M$4)) -> 11.8 | I16: =IF($A16="","",[1]!s_dq_close(I$1,$A16,$M$4)) -> 10.78 | J16: =IF(H16="","",H16-I16) -> 1.02 | M16: =MAX(pd) -> 5.84 | N16: 14
A17: =IF(A16="","",IF(IF(价差分析!$W$4="日",--[1]!td(A16-1),IF(价差分析!$W$4="周",--[1]!td(A16-7),--[1]!td(A16-30)))-价差分析!$T$4>0,IF(价差分析!$W$4="日",--[1]!td(A16-1),IF(价差分析!$W$4="周",--[1]!td(A16-7),--[1]!td(A16-30))),"")) -> 45245 | B17: =IF($A17="","",[1]!s_dq_close(B$1,$A17,$M$4)) -> 11.89 | C17: =IF($A17="","",[1]!s_dq_close(C$1,$A17,$M$4)) -> 11.03 | D17: =IF($A17="","",[1]!s_dq_close(D$1,$A17,$M$4)) -> 23.37 | E17: =IF($A17="","",[1]!s_dq_close(E$1,$A17,$M$4)) -> 5.54 | F17: =IF($A17="","",[1]!s_dq_close(F$1,$A17,$M$4)) -> 10.81 | H17: =IF($A17="","",[1]!s_dq_close(H$1,$A17,$M$4)) -> 11.89 | I17: =IF($A17="","",[1]!s_dq_close(I$1,$A17,$M$4)) -> 10.81 | J17: =IF(H17="","",H17-I17) -> 1.08
A18: =IF(A17="","",IF(IF(价差分析!$W$4="日",--[1]!td(A17-1),IF(价差分析!$W$4="周",--[1]!td(A17-7),--[1]!td(A17-30)))-价差分析!$T$4>0,IF(价差分析!$W$4="日",--[1]!td(A17-1),IF(价差分析!$W$4="周",--[1]!td(A17-7),--[1]!td(A17-30))),"")) -> 45244 | B18: =IF($A18="","",[1]!s_dq_close(B$1,$A18,$M$4)) -> 11.78 | C18: =IF($A18="","",[1]!s_dq_close(C$1,$A18,$M$4)) -> 11.11 | D18: =IF($A18="","",[1]!s_dq_close(D$1,$A18,$M$4)) -> 23.98 | E18: =IF($A18="","",[1]!s_dq_close(E$1,$A18,$M$4)) -> 5.55 | F18: =IF($A18="","",[1]!s_dq_close(F$1,$A18,$M$4)) -> 10.98 | H18: =IF($A18="","",[1]!s_dq_close(H$1,$A18,$M$4)) -> 11.78 | I18: =IF($A18="","",[1]!s_dq_close(I$1,$A18,$M$4)) -> 10.98 | J18: =IF(H18="","",H18-I18) -> 0.8
A19: =IF(A18="","",IF(IF(价差分析!$W$4="日",--[1]!td(A18-1),IF(价差分析!$W$4="周",--[1]!td(A18-7),--[1]!td(A18-30)))-价差分析!$T$4>0,IF(价差分析!$W$4="日",--[1]!td(A18-1),IF(价差分析!$W$4="周",--[1]!td(A18-7),--[1]!td(A18-30))),"")) -> 45243 | B19: =IF($A19="","",[1]!s_dq_close(B$1,$A19,$M$4)) -> 11.72 | C19: =IF($A19="","",[1]!s_dq_close(C$1,$A19,$M$4)) -> 11.03 | D19: =IF($A19="","",[1]!s_dq_close(D$1,$A19,$M$4)) -> 23.15 | E19: =IF($A19="","",[1]!s_dq_close(E$1,$A19,$M$4)) -> 5.43 | F19: =IF($A19="","",[1]!s_dq_close(F$1,$A19,$M$4)) -> 10.88 | H19: =IF($A19="","",[1]!s_dq_close(H$1,$A19,$M$4)) -> 11.72 | I19: =IF($A19="","",[1]!s_dq_close(I$1,$A19,$M$4)) -> 10.88 | J19: =IF(H19="","",H19-I19) -> 0.84
A20: =IF(A19="","",IF(IF(价差分析!$W$4="日",--[1]!td(A19-1),IF(价差分析!$W$4="周",--[1]!td(A19-7),--[1]!td(A19-30)))-价差分析!$T$4>0,IF(价差分析!$W$4="日",--[1]!td(A19-1),IF(价差分析!$W$4="周",--[1]!td(A19-7),--[1]!td(A19-30))),"")) -> 45240 | B20: =IF($A20="","",[1]!s_dq_close(B$1,$A20,$M$4)) -> 11.89 | C20: =IF($A20="","",[1]!s_dq_close(C$1,$A20,$M$4)) -> 11.1 | D20: =IF($A20="","",[1]!s_dq_close(D$1,$A20,$M$4)) -> 22.5 | E20: =IF($A20="","",[1]!s_dq_close(E$1,$A20,$M$4)) -> 5.46 | F20: =IF($A20="","",[1]!s_dq_close(F$1,$A20,$M$4)) -> 10.88 | H20: =IF($A20="","",[1]!s_dq_close(H$1,$A20,$M$4)) -> 11.89 | I20: =IF($A20="","",[1]!s_dq_close(I$1,$A20,$M$4)) -> 10.88 | J20: =IF(H20="","",H20-I20) -> 1.01
A21: =IF(A20="","",IF(IF(价差分析!$W$4="日",--[1]!td(A20-1),IF(价差分析!$W$4="周",--[1]!td(A20-7),--[1]!td(A20-30)))-价差分析!$T$4>0,IF(价差分析!$W$4="日",--[1]!td(A20-1),IF(价差分析!$W$4="周",--[1]!td(A20-7),--[1]!td(A20-30))),"")) -> 45239 | B21: =IF($A21="","",[1]!s_dq_close(B$1,$A21,$M$4)) -> 11.96 | C21: =IF($A21="","",[1]!s_dq_close(C$1,$A21,$M$4)) -> 11.2 | D21: =IF($A21="","",[1]!s_dq_close(D$1,$A21,$M$4)) -> 24.23 | E21: =IF($A21="","",[1]!s_dq_close(E$1,$A21,$M$4)) -> 5.45 | F21: =IF($A21="","",[1]!s_dq_close(F$1,$A21,$M$4)) -> 11.08 | H21: =IF($A21="","",[1]!s_dq_close(H$1,$A21,$M$4)) -> 11.96 | I21: =IF($A21="","",[1]!s_dq_close(I$1,$A21,$M$4)) -> 11.08 | J21: =IF(H21="","",H21-I21) -> 0.88
A22: =IF(A21="","",IF(IF(价差分析!$W$4="日",--[1]!td(A21-1),IF(价差分析!$W$4="周",--[1]!td(A21-7),--[1]!td(A21-30)))-价差分析!$T$4>0,IF(价差分析!$W$4="日",--[1]!td(A21-1),IF(价差分析!$W$4="周",--[1]!td(A21-7),--[1]!td(A21-30))),"")) -> 45238 | B22: =IF($A22="","",[1]!s_dq_close(B$1,$A22,$M$4)) -> 12.13 | C22: =IF($A22="","",[1]!s_dq_close(C$1,$A22,$M$4)) -> 11.16 | D22: =IF($A22="","",[1]!s_dq_close(D$1,$A22,$M$4)) -> 24.51 | E22: =IF($A22="","",[1]!s_dq_close(E$1,$A22,$M$4)) -> 5.41 | F22: =IF($A22="","",[1]!s_dq_close(F$1,$A22,$M$4)) -> 11.08 | H22: =IF($A22="","",[1]!s_dq_close(H$1,$A22,$M$4)) -> 12.13 | I22: =IF($A22="","",[1]!s_dq_close(I$1,$A22,$M$4)) -> 11.08 | J22: =IF(H22="","",H22-I22) -> 1.05
A23: =IF(A22="","",IF(IF(价差分析!$W$4="日",--[1]!td(A22-1),IF(价差分析!$W$4="周",--[1]!td(A22-7),--[1]!td(A22-30)))-价差分析!$T$4>0,IF(价差分析!$W$4="日",--[1]!td(A22-1),IF(价差分析!$W$4="周",--[1]!td(A22-7),--[1]!td(A22-30))),"")) -> 45237 | B23: =IF($A23="","",[1]!s_dq_close(B$1,$A23,$M$4)) -> 11.93 | C23: =IF($A23="","",[1]!s_dq_close(C$1,$A23,$M$4)) -> 11.11 | D23: =IF($A23="","",[1]!s_dq_close(D$1,$A23,$M$4)) -> 23.66 | E23: =IF($A23="","",[1]!s_dq_close(E$1,$A23,$M$4)) -> 5.21 | F23: =IF($A23="","",[1]!s_dq_close(F$1,$A23,$M$4)) -> 10.98 | H23: =IF($A23="","",[1]!s_dq_close(H$1,$A23,$M$4)) -> 11.93 | I23: =IF($A23="","",[1]!s_dq_close(I$1,$A23,$M$4)) -> 10.98 | J23: =IF(H23="","",H23-I23) -> 0.95
A24: =IF(A23="","",IF(IF(价差分析!$W$4="日",--[1]!td(A23-1),IF(价差分析!$W$4="周",--[1]!td(A23-7),--[1]!td(A23-30)))-价差分析!$T$4>0,IF(价差分析!$W$4="日",--[1]!td(A23-1),IF(价差分析!$W$4="周",--[1]!td(A23-7),--[1]!td(A23-30))),"")) -> 45236 | B24: =IF($A24="","",[1]!s_dq_close(B$1,$A24,$M$4)) -> 11.97 | C24: =IF($A24="","",[1]!s_dq_close(C$1,$A24,$M$4)) -> 11.12 | D24: =IF($A24="","",[1]!s_dq_close(D$1,$A24,$M$4)) -> 22.68 | E24: =IF($A24="","",[1]!s_dq_close(E$1,$A24,$M$4)) -> 5.27 | F24: =IF($A24="","",[1]!s_dq_close(F$1,$A24,$M$4)) -> 11.05 | H24: =IF($A24="","",[1]!s_dq_close(H$1,$A24,$M$4)) -> 11.97 | I24: =IF($A24="","",[1]!s_dq_close(I$1,$A24,$M$4)) -> 11.05 | J24: =IF(H24="","",H24-I24) -> 0.92
A25: =IF(A24="","",IF(IF(价差分析!$W$4="日",--[1]!td(A24-1),IF(价差分析!$W$4="周",--[1]!td(A24-7),--[1]!td(A24-30)))-价差分析!$T$4>0,IF(价差分析!$W$4="日",--[1]!td(A24-1),IF(价差分析!$W$4="周",--[1]!td(A24-7),--[1]!td(A24-30))),"")) -> 45233 | B25: =IF($A25="","",[1]!s_dq_close(B$1,$A25,$M$4)) -> 11.27 | C25: =IF($A25="","",[1]!s_dq_close(C$1,$A25,$M$4)) -> 10.8 | D25: =IF($A25="","",[1]!s_dq_close(D$1,$A25,$M$4)) -> 22.3 | E25: =IF($A25="","",[1]!s_dq_close(E$1,$A25,$M$4)) -> 5.02 | F25: =IF($A25="","",[1]!s_dq_close(F$1,$A25,$M$4)) -> 10.77 | H25: =IF($A25="","",[1]!s_dq_close(H$1,$A25,$M$4)) -> 11.27 | I25: =IF($A25="","",[1]!s_dq_close(I$1,$A25,$M$4)) -> 10.77 | J25: =IF(H25="","",H25-I25) -> 0.5
A26: =IF(A25="","",IF(IF(价差分析!$W$4="日",--[1]!td(A25-1),IF(价差分析!$W$4="周",--[1]!td(A25-7),--[1]!td(A25-30)))-价差分析!$T$4>0,IF(价差分析!$W$4="日",--[1]!td(A25-1),IF(价差分析!$W$4="周",--[1]!td(A25-7),--[1]!td(A25-30))),"")) -> 45232 | B26: =IF($A26="","",[1]!s_dq_close(B$1,$A26,$M$4)) -> 11.22 | C26: =IF($A26="","",[1]!s_dq_close(C$1,$A26,$M$4)) -> 10.89 | D26: =IF($A26="","",[1]!s_dq_close(D$1,$A26,$M$4)) -> 22.24 | E26: =IF($A26="","",[1]!s_dq_close(E$1,$A26,$M$4)) -> 5.02 | F26: =IF($A26="","",[1]!s_dq_close(F$1,$A26,$M$4)) -> 10.86 | H26: =IF($A26="","",[1]!s_dq_close(H$1,$A26,$M$4)) -> 11.22 | I26: =IF($A26="","",[1]!s_dq_close(I$1,$A26,$M$4)) -> 10.86 | J26: =IF(H26="","",H26-I26) -> 0.36
A27: =IF(A26="","",IF(IF(价差分析!$W$4="日",--[1]!td(A26-1),IF(价差分析!$W$4="周",--[1]!td(A26-7),--[1]!td(A26-30)))-价差分析!$T$4>0,IF(价差分析!$W$4="日",--[1]!td(A26-1),IF(价差分析!$W$4="周",--[1]!td(A26-7),--[1]!td(A26-30))),"")) -> 45231 | B27: =IF($A27="","",[1]!s_dq_close(B$1,$A27,$M$4)) -> 11.34 | C27: =IF($A27="","",[1]!s_dq_close(C$1,$A27,$M$4)) -> 10.94 | D27: =IF($A27="","",[1]!s_dq_close(D$1,$A27,$M$4)) -> 22.47 | E27: =IF($A27="","",[1]!s_dq_close(E$1,$A27,$M$4)) -> 5.08 | F27: =IF($A27="","",[1]!s_dq_close(F$1,$A27,$M$4)) -> 11 | H27: =IF($A27="","",[1]!s_dq_close(H$1,$A27,$M$4)) -> 11.34 | I27: =IF($A27="","",[1]!s_dq_close(I$1,$A27,$M$4)) -> 11 | J27: =IF(H27="","",H27-I27) -> 0.34
A28: =IF(A27="","",IF(IF(价差分析!$W$4="日",--[1]!td(A27-1),IF(价差分析!$W$4="周",--[1]!td(A27-7),--[1]!td(A27-30)))-价差分析!$T$4>0,IF(价差分析!$W$4="日",--[1]!td(A27-1),IF(价差分析!$W$4="周",--[1]!td(A27-7),--[1]!td(A27-30))),"")) -> 45230 | B28: =IF($A28="","",[1]!s_dq_close(B$1,$A28,$M$4)) -> 11.33 | C28: =IF($A28="","",[1]!s_dq_close(C$1,$A28,$M$4)) -> 11.02 | D28: =IF($A28="","",[1]!s_dq_close(D$1,$A28,$M$4)) -> 23.95 | E28: =IF($A28="","",[1]!s_dq_close(E$1,$A28,$M$4)) -> 5.17 | F28: =IF($A28="","",[1]!s_dq_close(F$1,$A28,$M$4)) -> 11.04 | H28: =IF($A28="","",[1]!s_dq_close(H$1,$A28,$M$4)) -> 11.33 | I28: =IF($A28="","",[1]!s_dq_close(I$1,$A28,$M$4)) -> 11.04 | J28: =IF(H28="","",H28-I28) -> 0.29
... A246: =IF(A245="","",IF(IF(价差分析!$W$4="日",--[1]!td(A245-1),IF(价差分析!$W$4="周",--[1]!td(A245-7),--[1]!td(A245-30)))-价差分析!$T$4>0,IF(价差分析!$W$4="日",--[1]!td(A245-1),IF(价差分析!$W$4="周",--[1]!td(A245-7),--[1]!td(A245-30))),"")) | B246: =IF($A246="","",[1]!s_dq_close(B$1,$A246,$M$4)) | C246: =IF($A246="","",[1]!s_dq_close(C$1,$A246,$M$4)) | D246: =IF($A246="","",[1]!s_dq_close(D$1,$A246,$M$4)) | E246: =IF($A246="","",[1]!s_dq_close(E$1,$A246,$M$4)) | F246: =IF($A246="","",[1]!s_dq_close(F$1,$A246,$M$4)) | H246: =IF($A246="","",[1]!s_dq_close(H$1,$A246,$M$4)) | I246: =IF($A246="","",[1]!s_dq_close(I$1,$A246,$M$4)) | J246: =IF(H246="","",H246-I246)
A247: =IF(A246="","",IF(IF(价差分析!$W$4="日",--[1]!td(A246-1),IF(价差分析!$W$4="周",--[1]!td(A246-7),--[1]!td(A246-30)))-价差分析!$T$4>0,IF(价差分析!$W$4="日",--[1]!td(A246-1),IF(价差分析!$W$4="周",--[1]!td(A246-7),--[1]!td(A246-30))),"")) | B247: =IF(A247="","",[1]!s_dq_close($B$1,A247,$M$4)) | C247: =IF(A247="","",[1]!s_dq_close($C$1,A247,$M$4)) | D247: =IF($A247="","",[1]!s_dq_close(D$1,$A247,$M$4)) | E247: =IF($A247="","",[1]!s_dq_close(E$1,$A247,$M$4)) | F247: =IF($A247="","",[1]!s_dq_close(F$1,$A247,$M$4)) | H247: =IF($A247="","",[1]!s_dq_close(H$1,$A247,$M$4)) | I247: =IF($A247="","",[1]!s_dq_close(I$1,$A247,$M$4)) | J247: =IF(H247="","",H247-I247)
A248: =IF(A247="","",IF(IF(价差分析!$W$4="日",--[1]!td(A247-1),IF(价差分析!$W$4="周",--[1]!td(A247-7),--[1]!td(A247-30)))-价差分析!$T$4>0,IF(价差分析!$W$4="日",--[1]!td(A247-1),IF(价差分析!$W$4="周",--[1]!td(A247-7),--[1]!td(A247-30))),"")) | B248: =IF(A248="","",[1]!s_dq_close($B$1,A248,$M$4)) | C248: =IF(A248="","",[1]!s_dq_close($C$1,A248,$M$4)) | D248: =IF($A248="","",[1]!s_dq_close(D$1,$A248,$M$4)) | E248: =IF($A248="","",[1]!s_dq_close(E$1,$A248,$M$4)) | F248: =IF($A248="","",[1]!s_dq_close(F$1,$A248,$M$4)) | H248: =IF($A248="","",[1]!s_dq_close(H$1,$A248,$M$4)) | I248: =IF($A248="","",[1]!s_dq_close(I$1,$A248,$M$4)) | J248: =IF(H248="","",H248-I248)
A249: =IF(A248="","",IF(IF(价差分析!$W$4="日",--[1]!td(A248-1),IF(价差分析!$W$4="周",--[1]!td(A248-7),--[1]!td(A248-30)))-价差分析!$T$4>0,IF(价差分析!$W$4="日",--[1]!td(A248-1),IF(价差分析!$W$4="周",--[1]!td(A248-7),--[1]!td(A248-30))),"")) | B249: =IF(A249="","",[1]!s_dq_close($B$1,A249,$M$4)) | C249: =IF(A249="","",[1]!s_dq_close($C$1,A249,$M$4)) | D249: =IF($A249="","",[1]!s_dq_close(D$1,$A249,$M$4)) | E249: =IF($A249="","",[1]!s_dq_close(E$1,$A249,$M$4)) | F249: =IF($A249="","",[1]!s_dq_close(F$1,$A249,$M$4)) | H249: =IF($A249="","",[1]!s_dq_close(H$1,$A249,$M$4)) | I249: =IF($A249="","",[1]!s_dq_close(I$1,$A249,$M$4)) | J249: =IF(H249="","",H249-I249)
A250: =IF(A249="","",IF(IF(价差分析!$W$4="日",--[1]!td(A249-1),IF(价差分析!$W$4="周",--[1]!td(A249-7),--[1]!td(A249-30)))-价差分析!$T$4>0,IF(价差分析!$W$4="日",--[1]!td(A249-1),IF(价差分析!$W$4="周",--[1]!td(A249-7),--[1]!td(A249-30))),"")) | B250: =IF(A250="","",[1]!s_dq_close($B$1,A250,$M$4)) | C250: =IF(A250="","",[1]!s_dq_close($C$1,A250,$M$4)) | D250: =IF($A250="","",[1]!s_dq_close(D$1,$A250,$M$4)) | E250: =IF($A250="","",[1]!s_dq_close(E$1,$A250,$M$4)) | F250: =IF($A250="","",[1]!s_dq_close(F$1,$A250,$M$4)) | H250: =IF($A250="","",[1]!s_dq_close(H$1,$A250,$M$4)) | I250: =IF($A250="","",[1]!s_dq_close(I$1,$A250,$M$4)) | J250: =IF(H250="","",H250-I250)
A251: =IF(A250="","",IF(IF(价差分析!$W$4="日",--[1]!td(A250-1),IF(价差分析!$W$4="周",--[1]!td(A250-7),--[1]!td(A250-30)))-价差分析!$T$4>0,IF(价差分析!$W$4="日",--[1]!td(A250-1),IF(价差分析!$W$4="周",--[1]!td(A250-7),--[1]!td(A250-30))),"")) | B251: =IF(A251="","",[1]!s_dq_close($B$1,A251,$M$4)) | C251: =IF(A251="","",[1]!s_dq_close($C$1,A251,$M$4)) | D251: =IF($A251="","",[1]!s_dq_close(D$1,$A251,$M$4)) | E251: =IF($A251="","",[1]!s_dq_close(E$1,$A251,$M$4)) | F251: =IF($A251="","",[1]!s_dq_close(F$1,$A251,$M$4)) | H251: =IF($A251="","",[1]!s_dq_close(H$1,$A251,$M$4)) | I251: =IF($A251="","",[1]!s_dq_close(I$1,$A251,$M$4)) | J251: =IF(H251="","",H251-I251)
A252: =IF(A251="","",IF(IF(价差分析!$W$4="日",--[1]!td(A251-1),IF(价差分析!$W$4="周",--[1]!td(A251-7),--[1]!td(A251-30)))-价差分析!$T$4>0,IF(价差分析!$W$4="日",--[1]!td(A251-1),IF(价差分析!$W$4="周",--[1]!td(A251-7),--[1]!td(A251-30))),"")) | B252: =IF(A252="","",[1]!s_dq_close($B$1,A252,$M$4)) | C252: =IF(A252="","",[1]!s_dq_close($C$1,A252,$M$4)) | D252: =IF($A252="","",[1]!s_dq_close(D$1,$A252,$M$4)) | E252: =IF($A252="","",[1]!s_dq_close(E$1,$A252,$M$4)) | F252: =IF($A252="","",[1]!s_dq_close(F$1,$A252,$M$4)) | H252: =IF($A252="","",[1]!s_dq_close(H$1,$A252,$M$4)) | I252: =IF($A252="","",[1]!s_dq_close(I$1,$A252,$M$4)) | J252: =IF(H252="","",H252-I252)
A253: =IF(A252="","",IF(IF(价差分析!$W$4="日",--[1]!td(A252-1),IF(价差分析!$W$4="周",--[1]!td(A252-7),--[1]!td(A252-30)))-价差分析!$T$4>0,IF(价差分析!$W$4="日",--[1]!td(A252-1),IF(价差分析!$W$4="周",--[1]!td(A252-7),--[1]!td(A252-30))),"")) | B253: =IF(A253="","",[1]!s_dq_close($B$1,A253,$M$4)) | C253: =IF(A253="","",[1]!s_dq_close($C$1,A253,$M$4)) | D253: =IF($A253="","",[1]!s_dq_close(D$1,$A253,$M$4)) | E253: =IF($A253="","",[1]!s_dq_close(E$1,$A253,$M$4)) | F253: =IF($A253="","",[1]!s_dq_close(F$1,$A253,$M$4)) | H253: =IF($A253="","",[1]!s_dq_close(H$1,$A253,$M$4)) | I253: =IF($A253="","",[1]!s_dq_close(I$1,$A253,$M$4)) | J253: =IF(H253="","",H253-I253)
A254: =IF(A253="","",IF(IF(价差分析!$W$4="日",--[1]!td(A253-1),IF(价差分析!$W$4="周",--[1]!td(A253-7),--[1]!td(A253-30)))-价差分析!$T$4>0,IF(价差分析!$W$4="日",--[1]!td(A253-1),IF(价差分析!$W$4="周",--[1]!td(A253-7),--[1]!td(A253-30))),"")) | B254: =IF(A254="","",[1]!s_dq_close($B$1,A254,$M$4)) | C254: =IF(A254="","",[1]!s_dq_close($C$1,A254,$M$4)) | D254: =IF($A254="","",[1]!s_dq_close(D$1,$A254,$M$4)) | E254: =IF($A254="","",[1]!s_dq_close(E$1,$A254,$M$4)) | F254: =IF($A254="","",[1]!s_dq_close(F$1,$A254,$M$4)) | H254: =IF($A254="","",[1]!s_dq_close(H$1,$A254,$M$4)) | I254: =IF($A254="","",[1]!s_dq_close(I$1,$A254,$M$4)) | J254: =IF(H254="","",H254-I254)
A255: =IF(A254="","",IF(IF(价差分析!$W$4="日",--[1]!td(A254-1),IF(价差分析!$W$4="周",--[1]!td(A254-7),--[1]!td(A254-30)))-价差分析!$T$4>0,IF(价差分析!$W$4="日",--[1]!td(A254-1),IF(价差分析!$W$4="周",--[1]!td(A254-7),--[1]!td(A254-30))),"")) | B255: =IF(A255="","",[1]!s_dq_close($B$1,A255,$M$4)) | C255: =IF(A255="","",[1]!s_dq_close($C$1,A255,$M$4)) | D255: =IF($A255="","",[1]!s_dq_close(D$1,$A255,$M$4)) | E255: =IF($A255="","",[1]!s_dq_close(E$1,$A255,$M$4)) | F255: =IF($A255="","",[1]!s_dq_close(F$1,$A255,$M$4)) | H255: =IF($A255="","",[1]!s_dq_close(H$1,$A255,$M$4)) | I255: =IF($A255="","",[1]!s_dq_close(I$1,$A255,$M$4)) | J255: =IF(H255="","",H255-I255)
A256: =IF(A255="","",IF(IF(价差分析!$W$4="日",--[1]!td(A255-1),IF(价差分析!$W$4="周",--[1]!td(A255-7),--[1]!td(A255-30)))-价差分析!$T$4>0,IF(价差分析!$W$4="日",--[1]!td(A255-1),IF(价差分析!$W$4="周",--[1]!td(A255-7),--[1]!td(A255-30))),"")) | B256: =IF(A256="","",[1]!s_dq_close($B$1,A256,$M$4)) | C256: =IF(A256="","",[1]!s_dq_close($C$1,A256,$M$4)) | D256: =IF($A256="","",[1]!s_dq_close(D$1,$A256,$M$4)) | E256: =IF($A256="","",[1]!s_dq_close(E$1,$A256,$M$4)) | F256: =IF($A256="","",[1]!s_dq_close(F$1,$A256,$M$4)) | H256: =IF($A256="","",[1]!s_dq_close(H$1,$A256,$M$4)) | I256: =IF($A256="","",[1]!s_dq_close(I$1,$A256,$M$4)) | J256: =IF(H256="","",H256-I256)
A257: =IF(A256="","",IF(IF(价差分析!$W$4="日",--[1]!td(A256-1),IF(价差分析!$W$4="周",--[1]!td(A256-7),--[1]!td(A256-30)))-价差分析!$T$4>0,IF(价差分析!$W$4="日",--[1]!td(A256-1),IF(价差分析!$W$4="周",--[1]!td(A256-7),--[1]!td(A256-30))),"")) | B257: =IF(A257="","",[1]!s_dq_close($B$1,A257,$M$4)) | C257: =IF(A257="","",[1]!s_dq_close($C$1,A257,$M$4)) | D257: =IF($A257="","",[1]!s_dq_close(D$1,$A257,$M$4)) | E257: =IF($A257="","",[1]!s_dq_close(E$1,$A257,$M$4)) | F257: =IF($A257="","",[1]!s_dq_close(F$1,$A257,$M$4)) | H257: =IF($A257="","",[1]!s_dq_close(H$1,$A257,$M$4)) | I257: =IF($A257="","",[1]!s_dq_close(I$1,$A257,$M$4)) | J257: =IF(H257="","",H257-I257)
...

Sheet Wind模板
A1: 价差分析
