Workbook

Sheet 目录
A1: 【华泰策略】新兴产业链景气指数
A3: 组合回测
A4: 面板-总览
A5: 面板-景气指数
A6: 面板-细分环节景气分位数
A7: 面板-细分环节景气指标
A8: 附录-指标体系
A9: 附录-数据来源
A11: 前瞻指标-分产业链
A12: 锂电-领先
A13: 光伏-领先
A14: 风电-领先
... A34: Email: wangyi012893@htsc.com

Sheet 组合回测
L1: 截至11.04
C2: 44562 | D2: 44593 | E2: 44621 | F2: 44652 | G2: 44682 | H2: 44713 | I2: 44743 | J2: 44774 | K2: 44805 | L2: 44835 | Q2: 1月 | R2: 2月 | S2: 3月 | T2: 4月 | U2: 5月 | V2: 6月 | W2: 7月 | X2: 8月 | Y2: 9月 | Z2: 10月 | AA2: 年初至今 | AB2: 5月以来
A3: 884790.WI | B3: 储能指数 | C3: -14.842353 | D3: 4.7821384 | E3: -13.586805 | F3: -18.740445 | G3: 20.826636 | H3: 26.753549 | I3: 6.4962536 | J3: -3.9431589 | K3: -9.0113701 | L3: 13.773565 | O3: 战略配置 奇点时刻组合 | P3: 储能 | T3: 1 | U3: 1 | V3: 1 | W3: 1 | X3: 1 | Y3: 1 | Z3: 1
A4: CI005138.WI | B4: 汽车零部件 | C4: -7.8922957 | D4: -1.4783535 | E4: -13.321728 | F4: -11.900319 | G4: 14.904159 | H4: 14.603652 | I4: 16.386087 | J4: -13.951797 | K4: -8.3148218 | L4: 12.529314 | P4: 智能汽车 | Q4: 1 | R4: 1 | T4: 1 | U4: 1 | V4: 1 | W4: 1 | X4: 1 | Y4: 1 | Z4: 1
A5: CI005459.WI | B5: 光伏设备(中信) | C5: -23.631112 | D5: 9.0565249 | E5: -9.4110188 | F5: -12.600209 | G5: 15.595733 | H5: 23.567465 | I5: 14.20303 | J5: -0.020584896 | K5: -8.1152643 | L5: 14.801592 | P5: N型电池（光伏生产设备） | T5: 1 | U5: 1 | V5: 1 | W5: 1 | X5: 1 | Y5: 1 | Z5: 1
A6: 688234.SH | B6: 半导体材料(中信) | C6: -20.444444 | D6: 0.57336078 | E6: -20.333285 | F6: -19.633028 | G6: 22.60274 | H6: 24.767225 | I6: 26.716418 | J6: 11.943463 | K6: 13.331229 | L6: 13.527063 | P6: 碳化硅 | T6: 1 | U6: 1 | V6: 1 | W6: 1 | X6: 1 | Y6: 1 | Z6: 1
A7: 884039.WI | B7: 锂电池指数 | C7: -13.242191 | D7: 7.9342773 | E7: -13.065676 | F7: -18.556395 | G7: 13.994052 | H7: 21.365571 | I7: 1.7138715 | J7: -8.1280516 | K7: -12.856294 | L7: 9.0694591 | O7: 战术轮动 月度调仓 | P7: 锂电 | U7: 1 | V7: 1
A8: 801735.SI | B8: 光伏设备(申万) | C8: -16.305612 | D8: 10.182547 | E8: -8.9640184 | F8: -12.028803 | G8: 17.036714 | H8: 21.041816 | I8: 0.87399785 | J8: -9.2103286 | K8: -7.0420092 | L8: 11.884095 | P8: 光伏 | S8: 1 | T8: 1 | U8: 1 | V8: 1
A9: 801736.SI | B9: 风电设备(申万) | C9: -6.6124316 | D9: -0.26139898 | E9: -18.69151 | F9: -16.656714 | G9: 22.015123 | H9: 21.23236 | I9: 2.8146597 | J9: -12.770029 | K9: -9.5966238 | L9: 8.5179495 | P9: 风电 | S9: 1 | T9: 1
A10: 801081.SI | B10: 半导体(申万) | C10: -14.967512 | D10: 4.921552 | E10: -12.781501 | F10: -14.929056 | G10: 9.148123 | H10: 8.70857 | I10: -8.9711692 | J10: -1.252863 | K10: -12.338245 | L10: 9.8627402 | P10: 半导体
A11: 8841291.WI | B11: IGBT指数 | C11: -10.946424 | D11: 7.8725006 | E11: -8.9973117 | F11: -12.258814 | G11: 12.062682 | H11: 13.740869 | I11: -7.8405204 | J11: -5.0237391 | K11: -12.767571 | L11: 11.492063 | P11: 功率半导体 | U11: 1
A12: 8841279.WI | B12: IDC指数 | C12: -5.5868098 | D12: 16.500487 | E12: -10.979524 | F12: -21.250942 | G12: 8.8510415 | H12: 9.4994234 | I12: 2.5542209 | J12: -5.3109646 | K12: -9.352536 | L12: 17.743989 | P12: 数字基建 | Q12: 1 | R12: 1 | U12: 1 | V12: 1
A13: 801085.SI | B13: 消费电子(申万) | C13: -12.120337 | D13: -3.4057449 | E13: -21.035115 | F13: -9.8813899 | G13: 10.822486 | H13: 3.877343 | I13: 1.3552766 | J13: 1.1547995 | K13: -15.921452 | L13: 8.0854065 | P13: 消费电子-元宇宙
A14: 884030.WI | B14: 物联网指数 | C14: -13.613309 | D14: 5.1548406 | E14: -11.448574 | F14: -19.825328 | G14: 9.0394367 | H14: 11.313892 | I14: 0.96865663 | J14: -5.2799466 | K14: -13.758684 | L14: 13.276966 | P14: 物联网 | Y14: 1 | Z14: 1
A15: CI005466.WI | B15: 工业机器人及工控系统(中信) | C15: -10.053328 | D15: 2.7083904 | E15: -10.996613 | F15: -17.87975 | G15: 10.555662 | H15: 26.866753 | I15: 14.373185 | J15: -14.647936 | K15: -10.682204 | L15: 13.50082 | P15: 工业机器人 | U15: 1 | V15: 1 | W15: 1 | Z15: 1
A16: 884766.WI | B16: 工业母机指数 | C16: -17.335223 | D16: 7.4520923 | E16: -15.798113 | F16: -15.845991 | G16: 14.084892 | H16: 14.965217 | I16: 10.788018 | J16: -11.31861 | K16: -8.2903343 | L16: 27.516358 | P16: 机床 | Z16: 1
A17: 801742.SI | B17: 航空装备Ⅱ(申万) | C17: -22.353158 | D17: 6.5202169 | E17: -10.154664 | F17: -15.221852 | G17: 11.425438 | H17: 10.826611 | I17: 1.8630868 | J17: -5.7520315 | K17: -1.5676678 | L17: 10.176835 | P17: 航空装备 | Q17: 1 | R17: 1 | U17: 1 | V17: 1
A18: 003230.CJ | B18: CRO/CMO(长江) | C18: -16.47365 | D18: 1.965621 | E18: 7.4020601 | F18: -11.908194 | G18: -4.4213125 | H18: 14.127386 | I18: -11.590546 | J18: -2.6953947 | K18: -19.05756 | L18: 13.480533 | P18: CXO | W18: 1
A19: 801980.SI | B19: 美容护理(申万) | C19: -14.092645 | D19: 4.2863431 | E19: -4.3002614 | F19: -1.7492441 | G19: 5.4233625 | H19: 10.5642 | I19: -2.1863018 | J19: -4.3630745 | K19: -7.9570961 | L19: 2.8041794 | P19: 医美-化妆品 | X19: 1 | Y19: 1 | Z19: 1
A20: 399001.SZ | B20: 创业板指 | C20: -10.293154 | D20: 0.95795892 | E20: -9.9398441 | F20: -9.0509654 | G20: 4.5927367 | H20: 11.872209 | I20: -4.8796057 | J20: -3.677593 | K20: -8.7778977 | L20: 3.7928372 | O20: 华泰策略新兴产业组合 | Q20: =SUMPRODUCT(Q3:Q19,C3:C19)/SUM(Q3:Q19)/100 -> -0.11944088 | R20: =SUMPRODUCT(R3:R19,D3:D19)/SUM(R3:R19)/100 -> 0.071807835 | S20: =SUMPRODUCT(S3:S19,E3:E19)/SUM(S3:S19)/100 -> -0.13827764 | T20: =SUMPRODUCT(T3:T19,F3:F19)/SUM(T3:T19)/100 -> -0.1525992 | U20: =SUMPRODUCT(U3:U19,G3:G19)/SUM(U3:U19)/100 -> 0.14785486 | V20: =SUMPRODUCT(V3:V19,H3:H19)/SUM(V3:V19)/100 -> 0.19921341 | W20: =SUMPRODUCT(W3:W19,I3:I19)/SUM(W3:W19)/100 -> 0.11097405 | X20: =SUMPRODUCT(X3:X19,J3:J19)/SUM(X3:X19)/100 -> -0.020670305 | ... Z20: =SUMPRODUCT(Z3:Z19,L3:L19)/SUM(Z3:Z19)/100 -> 0.13966232 | AA20: {=SUMPRODUCT(PRODUCT(1+Q20:Y20)-1)} -> -0.026027635 | AB20: =SUM(U20:Y20) -> 0.38099533
O21: 战略配置组合 | Q21: =IFERROR(SUMPRODUCT(Q3:Q6,C3:C6)/SUM(Q3:Q6)/100,0) -> -0.078922957 | R21: =IFERROR(SUMPRODUCT(R3:R6,D3:D6)/SUM(R3:R6)/100,0) -> -0.014783535 | S21: =IFERROR(SUMPRODUCT(S3:S6,E3:E6)/SUM(S3:S6)/100,0) -> 0 | T21: =IFERROR(SUMPRODUCT(T3:T6,F3:F6)/SUM(T3:T6)/100,0) -> -0.157185 | U21: =IFERROR(SUMPRODUCT(U3:U6,G3:G6)/SUM(U3:U6)/100,0) -> 0.18482317 | V21: =IFERROR(SUMPRODUCT(V3:V6,H3:H6)/SUM(V3:V6)/100,0) -> 0.22422973 | W21: =IFERROR(SUMPRODUCT(W3:W6,I3:I6)/SUM(W3:W6)/100,0) -> 0.15950447 | X21: =IFERROR(SUMPRODUCT(X3:X6,J3:J6)/SUM(X3:X6)/100,0) -> -0.014930195 | ... Z21: =IFERROR(SUMPRODUCT(Z3:Z6,L3:L6)/SUM(Z3:Z6)/100,0) -> 0.13657884 | AA21: {=SUMPRODUCT(PRODUCT(1+Q21:Y21)-1)} -> 0.22875163 | AB21: =SUM(U21:Y21) -> 0.52335161
O22: 战术配置组合 | Q22: =IFERROR(SUMPRODUCT(Q7:Q19,C7:C19)/SUM(Q7:Q19)/100,0) -> -0.13969984 | R22: =IFERROR(SUMPRODUCT(R7:R19,D7:D19)/SUM(R7:R19)/100,0) -> 0.11510352 | S22: =IFERROR(SUMPRODUCT(S7:S19,E7:E19)/SUM(S7:S19)/100,0) -> -0.13827764 | T22: =IFERROR(SUMPRODUCT(T7:T19,F7:F19)/SUM(T7:T19)/100,0) -> -0.14342758 | U22: =IFERROR(SUMPRODUCT(U7:U19,G7:G19)/SUM(U7:U19)/100,0) -> 0.12320932 | V22: =IFERROR(SUMPRODUCT(V7:V19,H7:H19)/SUM(V7:V19)/100,0) -> 0.17920035 | W22: =IFERROR(SUMPRODUCT(W7:W19,I7:I19)/SUM(W7:W19)/100,0) -> 0.013913195 | X22: =IFERROR(SUMPRODUCT(X7:X19,J7:J19)/SUM(X7:X19)/100,0) -> -0.043630745 | ... Z22: =IFERROR(SUMPRODUCT(Z7:Z19,L7:L19)/SUM(Z7:Z19)/100,0) -> 0.14274581 | AA22: {=SUMPRODUCT(PRODUCT(1+Q22:Y22)-1)} -> -0.18931111 | AB22: =SUM(U22:Y22) -> 0.16411321
O23: 创业板指 | Q23: =C20/100 -> -0.10293154 | R23: =D20/100 -> 0.0095795892 | S23: =E20/100 -> -0.099398441 | T23: =F20/100 -> -0.090509654 | U23: =G20/100 -> 0.045927367 | V23: =H20/100 -> 0.11872209 | W23: =I20/100 -> -0.048796057 | X23: =J20/100 -> -0.03677593 | ... Z23: =L20/100 -> 0.037928372 | AA23: {=SUMPRODUCT(PRODUCT(1+Q23:Y23)-1)} -> -0.27452622 | AB23: =SUM(U23:Y23) -> -0.0087015107
O24: 超额收益 | Q24: =Q20-Q23 -> -0.016509341 | R24: =R20-R23 -> 0.062228246 | S24: =S20-S23 -> -0.038879201 | T24: =T20-T23 -> -0.062089542 | U24: =U20-U23 -> 0.10192749 | V24: =V20-V23 -> 0.080491319 | W24: =W20-W23 -> 0.1597701 | X24: =X20-X23 -> 0.016105625 | ... AA24: =AA20-AA23 -> 0.24849858 | AB24: =SUM(U24:Y24) -> 0.38969684
O25: 来自战略配置部分 | Q25: =Q21-Q23 -> 0.024008581 | R25: =R21-R23 -> -0.024363124 | S25: =S21-S23 -> 0.099398441 | T25: =T21-T23 -> -0.066675348 | U25: =U21-U23 -> 0.1388958 | V25: =V21-V23 -> 0.10550764 | W25: =W21-W23 -> 0.20830053 | X25: =X21-X23 -> 0.021845735 | ... AB25: =AB21-AB23 -> 0.53205312
O26: 来自战术配置部分 | Q26: =Q22-Q23 -> -0.036768301 | R26: =R22-R23 -> 0.10552393 | S26: =S22-S23 -> -0.038879201 | T26: =T22-T23 -> -0.05291793 | U26: =U22-U23 -> 0.077281949 | V26: =V22-V23 -> 0.060478261 | W26: =W22-W23 -> 0.062709251 | X26: =X22-X23 -> -0.0068548145 | ... AB26: =AB22-AB23 -> 0.17281472

Sheet 面板-总览
A2: 景气指数 | B2: 44500 | C2: 44530 | D2: 44561 | E2: 44592 | F2: 44620 | G2: 44651 | H2: 44681 | I2: 44712 | J2: 44742 | K2: 44773 | L2: 44804 | M2: 44834 | N2: 44865 | O2: 2M变化 | Q2: 4Q22预判 | T2: 景气指数 | U2: 44500 | V2: 44530 | W2: 44561 | X2: 44592 | Y2: 44620 | Z2: 44651 | AA2: 44681 | AB2: 44712 | AC2: 44742 | AD2: 44773 | AE2: 44804 | AF2: 44834 | AG2: 44865 | AH2: 2M变化 | AJ2: 趋势图
A3: 锂电 | B3: =INDEX('面板-景气指数'!$33:$45,MATCH('面板-总览'!$A3,'面板-景气指数'!$J$33:$J$45,0),MATCH('面板-总览'!B$2,'面板-景气指数'!$32:$32,0)) -> 0.80168421 | C3: =INDEX('面板-景气指数'!$33:$45,MATCH('面板-总览'!$A3,'面板-景气指数'!$J$33:$J$45,0),MATCH('面板-总览'!C$2,'面板-景气指数'!$32:$32,0)) -> 0.73826316 | D3: =INDEX('面板-景气指数'!$33:$45,MATCH('面板-总览'!$A3,'面板-景气指数'!$J$33:$J$45,0),MATCH('面板-总览'!D$2,'面板-景气指数'!$32:$32,0)) -> 0.73242105 | E3: =INDEX('面板-景气指数'!$33:$45,MATCH('面板-总览'!$A3,'面板-景气指数'!$J$33:$J$45,0),MATCH('面板-总览'!E$2,'面板-景气指数'!$32:$32,0)) -> 0.76571053 | F3: =INDEX('面板-景气指数'!$33:$45,MATCH('面板-总览'!$A3,'面板-景气指数'!$J$33:$J$45,0),MATCH('面板-总览'!F$2,'面板-景气指数'!$32:$32,0)) -> 0.80694737 | G3: =INDEX('面板-景气指数'!$33:$45,MATCH('面板-总览'!$A3,'面板-景气指数'!$J$33:$J$45,0),MATCH('面板-总览'!G$2,'面板-景气指数'!$32:$32,0)) -> 0.82213158 | H3: =INDEX('面板-景气指数'!$33:$45,MATCH('面板-总览'!$A3,'面板-景气指数'!$J$33:$J$45,0),MATCH('面板-总览'!H$2,'面板-景气指数'!$32:$32,0)) -> 0.70592105 | I3: =INDEX('面板-景气指数'!$33:$45,MATCH('面板-总览'!$A3,'面板-景气指数'!$J$33:$J$45,0),MATCH('面板-总览'!I$2,'面板-景气指数'!$32:$32,0)) -> 0.613 | ... K3: =INDEX('面板-景气指数'!$33:$45,MATCH('面板-总览'!$A3,'面板-景气指数'!$J$33:$J$45,0),MATCH('面板-总览'!K$2,'面板-景气指数'!$32:$32,0)) -> 0.68705263 | L3: =INDEX('面板-景气指数'!$33:$46,MATCH('面板-总览'!$A3,'面板-景气指数'!$J$33:$J$46,0),MATCH('面板-总览'!L$2,'面板-景气指数'!$32:$32,0)) -> 0.65971053 | M3: =INDEX('面板-景气指数'!$33:$46,MATCH('面板-总览'!$A3,'面板-景气指数'!$J$33:$J$46,0),MATCH('面板-总览'!M$2,'面板-景气指数'!$32:$32,0)) -> 0.60428947 | N3: =INDEX('面板-景气指数'!$33:$46,MATCH('面板-总览'!$A3,'面板-景气指数'!$J$33:$J$46,0),MATCH('面板-总览'!N$2,'面板-景气指数'!$32:$32,0)) -> 0.60357895 | P3: =N3-L3 -> -0.056131579 | R3: -10 | T3: 锂电上游 | U3: =INDEX('面板-景气指数'!$48:$84,MATCH('面板-总览'!$T3,'面板-景气指数'!$J$48:$J$84,0),MATCH('面板-总览'!U$2,'面板-景气指数'!$32:$32,0)) -> 0.827 | V3: =INDEX('面板-景气指数'!$48:$84,MATCH('面板-总览'!$T3,'面板-景气指数'!$J$48:$J$84,0),MATCH('面板-总览'!V$2,'面板-景气指数'!$32:$32,0)) -> 0.85116667 | W3: =INDEX('面板-景气指数'!$48:$84,MATCH('面板-总览'!$T3,'面板-景气指数'!$J$48:$J$84,0),MATCH('面板-总览'!W$2,'面板-景气指数'!$32:$32,0)) -> 0.83916667 | X3: =INDEX('面板-景气指数'!$48:$84,MATCH('面板-总览'!$T3,'面板-景气指数'!$J$48:$J$84,0),MATCH('面板-总览'!X$2,'面板-景气指数'!$32:$32,0)) -> 0.83666667 | Y3: =INDEX('面板-景气指数'!$48:$84,MATCH('面板-总览'!$T3,'面板-景气指数'!$J$48:$J$84,0),MATCH('面板-总览'!Y$2,'面板-景气指数'!$32:$32,0)) -> 0.88033333 | Z3: =INDEX('面板-景气指数'!$48:$84,MATCH('面板-总览'!$T3,'面板-景气指数'!$J$48:$J$84,0),MATCH('面板-总览'!Z$2,'面板-景气指数'!$32:$32,0)) -> 0.91433333 | AA3: =INDEX('面板-景气指数'!$48:$84,MATCH('面板-总览'!$T3,'面板-景气指数'!$J$48:$J$84,0),MATCH('面板-总览'!AA$2,'面板-景气指数'!$32:$32,0)) -> 0.939 | AB3: =INDEX('面板-景气指数'!$48:$84,MATCH('面板-总览'!$T3,'面板-景气指数'!$J$48:$J$84,0),MATCH('面板-总览'!AB$2,'面板-景气指数'!$32:$32,0)) -> 0.864 | ... AG3: =INDEX('面板-景气指数'!$48:$84,MATCH('面板-总览'!$T3,'面板-景气指数'!$J$48:$J$84,0),MATCH('面板-总览'!AG$2,'面板-景气指数'!$32:$32,0)) -> 0.69533333 | AI3: =AG3-AE3 -> -0.0091666667
A4: 机器人 | B4: =INDEX('面板-景气指数'!$33:$45,MATCH('面板-总览'!$A4,'面板-景气指数'!$J$33:$J$45,0),MATCH('面板-总览'!B$2,'面板-景气指数'!$32:$32,0)) -> 0.51808333 | C4: =INDEX('面板-景气指数'!$33:$45,MATCH('面板-总览'!$A4,'面板-景气指数'!$J$33:$J$45,0),MATCH('面板-总览'!C$2,'面板-景气指数'!$32:$32,0)) -> 0.49891667 | D4: =INDEX('面板-景气指数'!$33:$45,MATCH('面板-总览'!$A4,'面板-景气指数'!$J$33:$J$45,0),MATCH('面板-总览'!D$2,'面板-景气指数'!$32:$32,0)) -> 0.51425 | E4: =INDEX('面板-景气指数'!$33:$45,MATCH('面板-总览'!$A4,'面板-景气指数'!$J$33:$J$45,0),MATCH('面板-总览'!E$2,'面板-景气指数'!$32:$32,0)) -> 0.50825 | F4: =INDEX('面板-景气指数'!$33:$45,MATCH('面板-总览'!$A4,'面板-景气指数'!$J$33:$J$45,0),MATCH('面板-总览'!F$2,'面板-景气指数'!$32:$32,0)) -> 0.64966667 | G4: =INDEX('面板-景气指数'!$33:$45,MATCH('面板-总览'!$A4,'面板-景气指数'!$J$33:$J$45,0),MATCH('面板-总览'!G$2,'面板-景气指数'!$32:$32,0)) -> 0.58466667 | H4: =INDEX('面板-景气指数'!$33:$45,MATCH('面板-总览'!$A4,'面板-景气指数'!$J$33:$J$45,0),MATCH('面板-总览'!H$2,'面板-景气指数'!$32:$32,0)) -> 0.36208333 | I4: =INDEX('面板-景气指数'!$33:$45,MATCH('面板-总览'!$A4,'面板-景气指数'!$J$33:$J$45,0),MATCH('面板-总览'!I$2,'面板-景气指数'!$32:$32,0)) -> 0.1995 | ... K4: =INDEX('面板-景气指数'!$33:$45,MATCH('面板-总览'!$A4,'面板-景气指数'!$J$33:$J$45,0),MATCH('面板-总览'!K$2,'面板-景气指数'!$32:$32,0)) -> 0.42275 | L4: =INDEX('面板-景气指数'!$33:$46,MATCH('面板-总览'!$A4,'面板-景气指数'!$J$33:$J$46,0),MATCH('面板-总览'!L$2,'面板-景气指数'!$32:$32,0)) -> 0.36825 | M4: =INDEX('面板-景气指数'!$33:$46,MATCH('面板-总览'!$A4,'面板-景气指数'!$J$33:$J$46,0),MATCH('面板-总览'!M$2,'面板-景气指数'!$32:$32,0)) -> 0.36575 | N4: =INDEX('面板-景气指数'!$33:$46,MATCH('面板-总览'!$A4,'面板-景气指数'!$J$33:$J$46,0),MATCH('面板-总览'!N$2,'面板-景气指数'!$32:$32,0)) -> 0.3645 | P4: =N4-L4 -> -0.00375 | R4: 10 | T4: 锂电中游 | U4: =INDEX('面板-景气指数'!$48:$84,MATCH('面板-总览'!$T4,'面板-景气指数'!$J$48:$J$84,0),MATCH('面板-总览'!U$2,'面板-景气指数'!$32:$32,0)) -> 0.71207692 | V4: =INDEX('面板-景气指数'!$48:$84,MATCH('面板-总览'!$T4,'面板-景气指数'!$J$48:$J$84,0),MATCH('面板-总览'!V$2,'面板-景气指数'!$32:$32,0)) -> 0.707 | W4: =INDEX('面板-景气指数'!$48:$84,MATCH('面板-总览'!$T4,'面板-景气指数'!$J$48:$J$84,0),MATCH('面板-总览'!W$2,'面板-景气指数'!$32:$32,0)) -> 0.73784615 | X4: =INDEX('面板-景气指数'!$48:$84,MATCH('面板-总览'!$T4,'面板-景气指数'!$J$48:$J$84,0),MATCH('面板-总览'!X$2,'面板-景气指数'!$32:$32,0)) -> 0.772 | Y4: =INDEX('面板-景气指数'!$48:$84,MATCH('面板-总览'!$T4,'面板-景气指数'!$J$48:$J$84,0),MATCH('面板-总览'!Y$2,'面板-景气指数'!$32:$32,0)) -> 0.78761538 | Z4: =INDEX('面板-景气指数'!$48:$84,MATCH('面板-总览'!$T4,'面板-景气指数'!$J$48:$J$84,0),MATCH('面板-总览'!Z$2,'面板-景气指数'!$32:$32,0)) -> 0.79584615 | AA4: =INDEX('面板-景气指数'!$48:$84,MATCH('面板-总览'!$T4,'面板-景气指数'!$J$48:$J$84,0),MATCH('面板-总览'!AA$2,'面板-景气指数'!$32:$32,0)) -> 0.74146154 | AB4: =INDEX('面板-景气指数'!$48:$84,MATCH('面板-总览'!$T4,'面板-景气指数'!$J$48:$J$84,0),MATCH('面板-总览'!AB$2,'面板-景气指数'!$32:$32,0)) -> 0.69446154 | ... AG4: =INDEX('面板-景气指数'!$48:$84,MATCH('面板-总览'!$T4,'面板-景气指数'!$J$48:$J$84,0),MATCH('面板-总览'!AG$2,'面板-景气指数'!$32:$32,0)) -> 0.66 | AI4: =AG4-AE4 -> -0.012230769
A5: 机床 | B5: =INDEX('面板-景气指数'!$33:$45,MATCH('面板-总览'!$A5,'面板-景气指数'!$J$33:$J$45,0),MATCH('面板-总览'!B$2,'面板-景气指数'!$32:$32,0)) -> 0.69716667 | C5: =INDEX('面板-景气指数'!$33:$45,MATCH('面板-总览'!$A5,'面板-景气指数'!$J$33:$J$45,0),MATCH('面板-总览'!C$2,'面板-景气指数'!$32:$32,0)) -> 0.60016667 | D5: =INDEX('面板-景气指数'!$33:$45,MATCH('面板-总览'!$A5,'面板-景气指数'!$J$33:$J$45,0),MATCH('面板-总览'!D$2,'面板-景气指数'!$32:$32,0)) -> 0.52633333 | E5: =INDEX('面板-景气指数'!$33:$45,MATCH('面板-总览'!$A5,'面板-景气指数'!$J$33:$J$45,0),MATCH('面板-总览'!E$2,'面板-景气指数'!$32:$32,0)) -> 0.6005 | F5: =INDEX('面板-景气指数'!$33:$45,MATCH('面板-总览'!$A5,'面板-景气指数'!$J$33:$J$45,0),MATCH('面板-总览'!F$2,'面板-景气指数'!$32:$32,0)) -> 0.74125 | G5: =INDEX('面板-景气指数'!$33:$45,MATCH('面板-总览'!$A5,'面板-景气指数'!$J$33:$J$45,0),MATCH('面板-总览'!G$2,'面板-景气指数'!$32:$32,0)) -> 0.60166667 | H5: =INDEX('面板-景气指数'!$33:$45,MATCH('面板-总览'!$A5,'面板-景气指数'!$J$33:$J$45,0),MATCH('面板-总览'!H$2,'面板-景气指数'!$32:$32,0)) -> 0.431 | I5: =INDEX('面板-景气指数'!$33:$45,MATCH('面板-总览'!$A5,'面板-景气指数'!$J$33:$J$45,0),MATCH('面板-总览'!I$2,'面板-景气指数'!$32:$32,0)) -> 0.44725 | ... K5: =INDEX('面板-景气指数'!$33:$45,MATCH('面板-总览'!$A5,'面板-景气指数'!$J$33:$J$45,0),MATCH('面板-总览'!K$2,'面板-景气指数'!$32:$32,0)) -> 0.32616667 | L5: =INDEX('面板-景气指数'!$33:$46,MATCH('面板-总览'!$A5,'面板-景气指数'!$J$33:$J$46,0),MATCH('面板-总览'!L$2,'面板-景气指数'!$32:$32,0)) -> 0.38966667 | M5: =INDEX('面板-景气指数'!$33:$46,MATCH('面板-总览'!$A5,'面板-景气指数'!$J$33:$J$46,0),MATCH('面板-总览'!M$2,'面板-景气指数'!$32:$32,0)) -> 0.43658333 | N5: =INDEX('面板-景气指数'!$33:$46,MATCH('面板-总览'!$A5,'面板-景气指数'!$J$33:$J$46,0),MATCH('面板-总览'!N$2,'面板-景气指数'!$32:$32,0)) -> 0.43658333 | P5: =N5-L5 -> 0.046916667 | R5: 10 | T5: 锂电下游 | U5: =INDEX('面板-景气指数'!$48:$84,MATCH('面板-总览'!$T5,'面板-景气指数'!$J$48:$J$84,0),MATCH('面板-总览'!U$2,'面板-景气指数'!$32:$32,0)) -> 0.855 | V5: =INDEX('面板-景气指数'!$48:$84,MATCH('面板-总览'!$T5,'面板-景气指数'!$J$48:$J$84,0),MATCH('面板-总览'!V$2,'面板-景气指数'!$32:$32,0)) -> 0.724 | W5: =INDEX('面板-景气指数'!$48:$84,MATCH('面板-总览'!$T5,'面板-景气指数'!$J$48:$J$84,0),MATCH('面板-总览'!W$2,'面板-景气指数'!$32:$32,0)) -> 0.695 | X5: =INDEX('面板-景气指数'!$48:$84,MATCH('面板-总览'!$T5,'面板-景气指数'!$J$48:$J$84,0),MATCH('面板-总览'!X$2,'面板-景气指数'!$32:$32,0)) -> 0.739 | Y5: =INDEX('面板-景气指数'!$48:$84,MATCH('面板-总览'!$T5,'面板-景气指数'!$J$48:$J$84,0),MATCH('面板-总览'!Y$2,'面板-景气指数'!$32:$32,0)) -> 0.797 | Z5: =INDEX('面板-景气指数'!$48:$84,MATCH('面板-总览'!$T5,'面板-景气指数'!$J$48:$J$84,0),MATCH('面板-总览'!Z$2,'面板-景气指数'!$32:$32,0)) -> 0.811 | AA5: =INDEX('面板-景气指数'!$48:$84,MATCH('面板-总览'!$T5,'面板-景气指数'!$J$48:$J$84,0),MATCH('面板-总览'!AA$2,'面板-景气指数'!$32:$32,0)) -> 0.608 | AB5: =INDEX('面板-景气指数'!$48:$84,MATCH('面板-总览'!$T5,'面板-景气指数'!$J$48:$J$84,0),MATCH('面板-总览'!AB$2,'面板-景气指数'!$32:$32,0)) -> 0.478 | ... AG5: =INDEX('面板-景气指数'!$48:$84,MATCH('面板-总览'!$T5,'面板-景气指数'!$J$48:$J$84,0),MATCH('面板-总览'!AG$2,'面板-景气指数'!$32:$32,0)) -> 0.536 | AI5: =AG5-AE5 -> -0.101
A6: 元宇宙 | B6: =INDEX('面板-景气指数'!$33:$45,MATCH('面板-总览'!$A6,'面板-景气指数'!$J$33:$J$45,0),MATCH('面板-总览'!B$2,'面板-景气指数'!$32:$32,0)) -> 0.76025 | C6: =INDEX('面板-景气指数'!$33:$45,MATCH('面板-总览'!$A6,'面板-景气指数'!$J$33:$J$45,0),MATCH('面板-总览'!C$2,'面板-景气指数'!$32:$32,0)) -> 0.710375 | D6: =INDEX('面板-景气指数'!$33:$45,MATCH('面板-总览'!$A6,'面板-景气指数'!$J$33:$J$45,0),MATCH('面板-总览'!D$2,'面板-景气指数'!$32:$32,0)) -> 0.419125 | E6: =INDEX('面板-景气指数'!$33:$45,MATCH('面板-总览'!$A6,'面板-景气指数'!$J$33:$J$45,0),MATCH('面板-总览'!E$2,'面板-景气指数'!$32:$32,0)) -> 0.493375 | F6: =INDEX('面板-景气指数'!$33:$45,MATCH('面板-总览'!$A6,'面板-景气指数'!$J$33:$J$45,0),MATCH('面板-总览'!F$2,'面板-景气指数'!$32:$32,0)) -> 0.4595 | G6: =INDEX('面板-景气指数'!$33:$45,MATCH('面板-总览'!$A6,'面板-景气指数'!$J$33:$J$45,0),MATCH('面板-总览'!G$2,'面板-景气指数'!$32:$32,0)) -> 0.464 | H6: =INDEX('面板-景气指数'!$33:$45,MATCH('面板-总览'!$A6,'面板-景气指数'!$J$33:$J$45,0),MATCH('面板-总览'!H$2,'面板-景气指数'!$32:$32,0)) -> 0.449875 | I6: =INDEX('面板-景气指数'!$33:$45,MATCH('面板-总览'!$A6,'面板-景气指数'!$J$33:$J$45,0),MATCH('面板-总览'!I$2,'面板-景气指数'!$32:$32,0)) -> 0.468375 | ... K6: =INDEX('面板-景气指数'!$33:$45,MATCH('面板-总览'!$A6,'面板-景气指数'!$J$33:$J$45,0),MATCH('面板-总览'!K$2,'面板-景气指数'!$32:$32,0)) -> 0.685875 | L6: =INDEX('面板-景气指数'!$33:$46,MATCH('面板-总览'!$A6,'面板-景气指数'!$J$33:$J$46,0),MATCH('面板-总览'!L$2,'面板-景气指数'!$32:$32,0)) -> 0.672 | M6: =INDEX('面板-景气指数'!$33:$46,MATCH('面板-总览'!$A6,'面板-景气指数'!$J$33:$J$46,0),MATCH('面板-总览'!M$2,'面板-景气指数'!$32:$32,0)) -> 0.199875 | N6: =INDEX('面板-景气指数'!$33:$46,MATCH('面板-总览'!$A6,'面板-景气指数'!$J$33:$J$46,0),MATCH('面板-总览'!N$2,'面板-景气指数'!$32:$32,0)) -> 0.185625 | P6: =N6-L6 -> -0.486375 | R6: 10 | T6: 机器人上游 | U6: =INDEX('面板-景气指数'!$48:$84,MATCH('面板-总览'!$T6,'面板-景气指数'!$J$48:$J$84,0),MATCH('面板-总览'!U$2,'面板-景气指数'!$32:$32,0)) -> 0.826 | V6: =INDEX('面板-景气指数'!$48:$84,MATCH('面板-总览'!$T6,'面板-景气指数'!$J$48:$J$84,0),MATCH('面板-总览'!V$2,'面板-景气指数'!$32:$32,0)) -> 0.869 | W6: =INDEX('面板-景气指数'!$48:$84,MATCH('面板-总览'!$T6,'面板-景气指数'!$J$48:$J$84,0),MATCH('面板-总览'!W$2,'面板-景气指数'!$32:$32,0)) -> 0.898 | X6: =INDEX('面板-景气指数'!$48:$84,MATCH('面板-总览'!$T6,'面板-景气指数'!$J$48:$J$84,0),MATCH('面板-总览'!X$2,'面板-景气指数'!$32:$32,0)) -> 0.913 | Y6: =INDEX('面板-景气指数'!$48:$84,MATCH('面板-总览'!$T6,'面板-景气指数'!$J$48:$J$84,0),MATCH('面板-总览'!Y$2,'面板-景气指数'!$32:$32,0)) -> 0.985 | Z6: =INDEX('面板-景气指数'!$48:$84,MATCH('面板-总览'!$T6,'面板-景气指数'!$J$48:$J$84,0),MATCH('面板-总览'!Z$2,'面板-景气指数'!$32:$32,0)) -> 1 | AA6: =INDEX('面板-景气指数'!$48:$84,MATCH('面板-总览'!$T6,'面板-景气指数'!$J$48:$J$84,0),MATCH('面板-总览'!AA$2,'面板-景气指数'!$32:$32,0)) -> 0.971 | AB6: =INDEX('面板-景气指数'!$48:$84,MATCH('面板-总览'!$T6,'面板-景气指数'!$J$48:$J$84,0),MATCH('面板-总览'!AB$2,'面板-景气指数'!$32:$32,0)) -> 0.927 | ... AG6: =INDEX('面板-景气指数'!$48:$84,MATCH('面板-总览'!$T6,'面板-景气指数'!$J$48:$J$84,0),MATCH('面板-总览'!AG$2,'面板-景气指数'!$32:$32,0)) -> 0.84 | AI6: =AG6-AE6 -> -0.044
A7: 光伏 | B7: =INDEX('面板-景气指数'!$33:$45,MATCH('面板-总览'!$A7,'面板-景气指数'!$J$33:$J$45,0),MATCH('面板-总览'!B$2,'面板-景气指数'!$32:$32,0)) -> 0.60390625 | C7: =INDEX('面板-景气指数'!$33:$45,MATCH('面板-总览'!$A7,'面板-景气指数'!$J$33:$J$45,0),MATCH('面板-总览'!C$2,'面板-景气指数'!$32:$32,0)) -> 0.57996875 | D7: =INDEX('面板-景气指数'!$33:$45,MATCH('面板-总览'!$A7,'面板-景气指数'!$J$33:$J$45,0),MATCH('面板-总览'!D$2,'面板-景气指数'!$32:$32,0)) -> 0.5445 | E7: =INDEX('面板-景气指数'!$33:$45,MATCH('面板-总览'!$A7,'面板-景气指数'!$J$33:$J$45,0),MATCH('面板-总览'!E$2,'面板-景气指数'!$32:$32,0)) -> 0.55065625 | F7: =INDEX('面板-景气指数'!$33:$45,MATCH('面板-总览'!$A7,'面板-景气指数'!$J$33:$J$45,0),MATCH('面板-总览'!F$2,'面板-景气指数'!$32:$32,0)) -> 0.8061875 | G7: =INDEX('面板-景气指数'!$33:$45,MATCH('面板-总览'!$A7,'面板-景气指数'!$J$33:$J$45,0),MATCH('面板-总览'!G$2,'面板-景气指数'!$32:$32,0)) -> 0.78153125 | H7: =INDEX('面板-景气指数'!$33:$45,MATCH('面板-总览'!$A7,'面板-景气指数'!$J$33:$J$45,0),MATCH('面板-总览'!H$2,'面板-景气指数'!$32:$32,0)) -> 0.80559375 | I7: =INDEX('面板-景气指数'!$33:$45,MATCH('面板-总览'!$A7,'面板-景气指数'!$J$33:$J$45,0),MATCH('面板-总览'!I$2,'面板-景气指数'!$32:$32,0)) -> 0.825375 | ... K7: =INDEX('面板-景气指数'!$33:$45,MATCH('面板-总览'!$A7,'面板-景气指数'!$J$33:$J$45,0),MATCH('面板-总览'!K$2,'面板-景气指数'!$32:$32,0)) -> 0.811875 | L7: =INDEX('面板-景气指数'!$33:$46,MATCH('面板-总览'!$A7,'面板-景气指数'!$J$33:$J$46,0),MATCH('面板-总览'!L$2,'面板-景气指数'!$32:$32,0)) -> 0.7890625 | M7: =INDEX('面板-景气指数'!$33:$46,MATCH('面板-总览'!$A7,'面板-景气指数'!$J$33:$J$46,0),MATCH('面板-总览'!M$2,'面板-景气指数'!$32:$32,0)) -> 0.7465 | N7: =INDEX('面板-景气指数'!$33:$46,MATCH('面板-总览'!$A7,'面板-景气指数'!$J$33:$J$46,0),MATCH('面板-总览'!N$2,'面板-景气指数'!$32:$32,0)) -> 0.745375 | P7: =N7-L7 -> -0.0436875 | R7: -10 | T7: 机器人中游 | U7: =INDEX('面板-景气指数'!$48:$84,MATCH('面板-总览'!$T7,'面板-景气指数'!$J$48:$J$84,0),MATCH('面板-总览'!U$2,'面板-景气指数'!$32:$32,0)) -> 0.49009091 | V7: =INDEX('面板-景气指数'!$48:$84,MATCH('面板-总览'!$T7,'面板-景气指数'!$J$48:$J$84,0),MATCH('面板-总览'!V$2,'面板-景气指数'!$32:$32,0)) -> 0.46527273 | W7: =INDEX('面板-景气指数'!$48:$84,MATCH('面板-总览'!$T7,'面板-景气指数'!$J$48:$J$84,0),MATCH('面板-总览'!W$2,'面板-景气指数'!$32:$32,0)) -> 0.47936364 | X7: =INDEX('面板-景气指数'!$48:$84,MATCH('面板-总览'!$T7,'面板-景气指数'!$J$48:$J$84,0),MATCH('面板-总览'!X$2,'面板-景气指数'!$32:$32,0)) -> 0.47145455 | Y7: =INDEX('面板-景气指数'!$48:$84,MATCH('面板-总览'!$T7,'面板-景气指数'!$J$48:$J$84,0),MATCH('面板-总览'!Y$2,'面板-景气指数'!$32:$32,0)) -> 0.61918182 | Z7: =INDEX('面板-景气指数'!$48:$84,MATCH('面板-总览'!$T7,'面板-景气指数'!$J$48:$J$84,0),MATCH('面板-总览'!Z$2,'面板-景气指数'!$32:$32,0)) -> 0.54690909 | AA7: =INDEX('面板-景气指数'!$48:$84,MATCH('面板-总览'!$T7,'面板-景气指数'!$J$48:$J$84,0),MATCH('面板-总览'!AA$2,'面板-景气指数'!$32:$32,0)) -> 0.30672727 | AB7: =INDEX('面板-景气指数'!$48:$84,MATCH('面板-总览'!$T7,'面板-景气指数'!$J$48:$J$84,0),MATCH('面板-总览'!AB$2,'面板-景气指数'!$32:$32,0)) -> 0.13336364 | ... AG7: =INDEX('面板-景气指数'!$48:$84,MATCH('面板-总览'!$T7,'面板-景气指数'!$J$48:$J$84,0),MATCH('面板-总览'!AG$2,'面板-景气指数'!$32:$32,0)) -> 0.32127273 | AI7: =AG7-AE7 -> -9.0909091e-05
A8: 风电 | B8: =INDEX('面板-景气指数'!$33:$45,MATCH('面板-总览'!$A8,'面板-景气指数'!$J$33:$J$45,0),MATCH('面板-总览'!B$2,'面板-景气指数'!$32:$32,0)) -> 0.46971154 | C8: =INDEX('面板-景气指数'!$33:$45,MATCH('面板-总览'!$A8,'面板-景气指数'!$J$33:$J$45,0),MATCH('面板-总览'!C$2,'面板-景气指数'!$32:$32,0)) -> 0.42417308 | D8: =INDEX('面板-景气指数'!$33:$45,MATCH('面板-总览'!$A8,'面板-景气指数'!$J$33:$J$45,0),MATCH('面板-总览'!D$2,'面板-景气指数'!$32:$32,0)) -> 0.35930769 | E8: =INDEX('面板-景气指数'!$33:$45,MATCH('面板-总览'!$A8,'面板-景气指数'!$J$33:$J$45,0),MATCH('面板-总览'!E$2,'面板-景气指数'!$32:$32,0)) -> 0.35619231 | F8: =INDEX('面板-景气指数'!$33:$45,MATCH('面板-总览'!$A8,'面板-景气指数'!$J$33:$J$45,0),MATCH('面板-总览'!F$2,'面板-景气指数'!$32:$32,0)) -> 0.49707692 | G8: =INDEX('面板-景气指数'!$33:$45,MATCH('面板-总览'!$A8,'面板-景气指数'!$J$33:$J$45,0),MATCH('面板-总览'!G$2,'面板-景气指数'!$32:$32,0)) -> 0.421 | H8: =INDEX('面板-景气指数'!$33:$45,MATCH('面板-总览'!$A8,'面板-景气指数'!$J$33:$J$45,0),MATCH('面板-总览'!H$2,'面板-景气指数'!$32:$32,0)) -> 0.40128846 | I8: =INDEX('面板-景气指数'!$33:$45,MATCH('面板-总览'!$A8,'面板-景气指数'!$J$33:$J$45,0),MATCH('面板-总览'!I$2,'面板-景气指数'!$32:$32,0)) -> 0.42980769 | ... K8: =INDEX('面板-景气指数'!$33:$45,MATCH('面板-总览'!$A8,'面板-景气指数'!$J$33:$J$45,0),MATCH('面板-总览'!K$2,'面板-景气指数'!$32:$32,0)) -> 0.37986538 | L8: =INDEX('面板-景气指数'!$33:$46,MATCH('面板-总览'!$A8,'面板-景气指数'!$J$33:$J$46,0),MATCH('面板-总览'!L$2,'面板-景气指数'!$32:$32,0)) -> 0.41230769 | M8: =INDEX('面板-景气指数'!$33:$46,MATCH('面板-总览'!$A8,'面板-景气指数'!$J$33:$J$46,0),MATCH('面板-总览'!M$2,'面板-景气指数'!$32:$32,0)) -> 0.41907692 | N8: =INDEX('面板-景气指数'!$33:$46,MATCH('面板-总览'!$A8,'面板-景气指数'!$J$33:$J$46,0),MATCH('面板-总览'!N$2,'面板-景气指数'!$32:$32,0)) -> 0.42663462 | P8: =N8-L8 -> 0.014326923 | R8: 10 | T8: 机床中游 | U8: =INDEX('面板-景气指数'!$48:$84,MATCH('面板-总览'!$T8,'面板-景气指数'!$J$48:$J$84,0),MATCH('面板-总览'!U$2,'面板-景气指数'!$32:$32,0)) -> 0.69716667 | V8: =INDEX('面板-景气指数'!$48:$84,MATCH('面板-总览'!$T8,'面板-景气指数'!$J$48:$J$84,0),MATCH('面板-总览'!V$2,'面板-景气指数'!$32:$32,0)) -> 0.60016667 | W8: =INDEX('面板-景气指数'!$48:$84,MATCH('面板-总览'!$T8,'面板-景气指数'!$J$48:$J$84,0),MATCH('面板-总览'!W$2,'面板-景气指数'!$32:$32,0)) -> 0.52633333 | X8: =INDEX('面板-景气指数'!$48:$84,MATCH('面板-总览'!$T8,'面板-景气指数'!$J$48:$J$84,0),MATCH('面板-总览'!X$2,'面板-景气指数'!$32:$32,0)) -> 0.6005 | Y8: =INDEX('面板-景气指数'!$48:$84,MATCH('面板-总览'!$T8,'面板-景气指数'!$J$48:$J$84,0),MATCH('面板-总览'!Y$2,'面板-景气指数'!$32:$32,0)) -> 0.74125 | Z8: =INDEX('面板-景气指数'!$48:$84,MATCH('面板-总览'!$T8,'面板-景气指数'!$J$48:$J$84,0),MATCH('面板-总览'!Z$2,'面板-景气指数'!$32:$32,0)) -> 0.60166667 | AA8: =INDEX('面板-景气指数'!$48:$84,MATCH('面板-总览'!$T8,'面板-景气指数'!$J$48:$J$84,0),MATCH('面板-总览'!AA$2,'面板-景气指数'!$32:$32,0)) -> 0.431 | AB8: =INDEX('面板-景气指数'!$48:$84,MATCH('面板-总览'!$T8,'面板-景气指数'!$J$48:$J$84,0),MATCH('面板-总览'!AB$2,'面板-景气指数'!$32:$32,0)) -> 0.44725 | ... AG8: =INDEX('面板-景气指数'!$48:$84,MATCH('面板-总览'!$T8,'面板-景气指数'!$J$48:$J$84,0),MATCH('面板-总览'!AG$2,'面板-景气指数'!$32:$32,0)) -> 0.43658333 | AI8: =AG8-AE8 -> 0.046916667
A9: 半导体 | B9: =INDEX('面板-景气指数'!$33:$45,MATCH('面板-总览'!$A9,'面板-景气指数'!$J$33:$J$45,0),MATCH('面板-总览'!B$2,'面板-景气指数'!$32:$32,0)) -> 0.66088043 | C9: =INDEX('面板-景气指数'!$33:$45,MATCH('面板-总览'!$A9,'面板-景气指数'!$J$33:$J$45,0),MATCH('面板-总览'!C$2,'面板-景气指数'!$32:$32,0)) -> 0.65001087 | D9: =INDEX('面板-景气指数'!$33:$45,MATCH('面板-总览'!$A9,'面板-景气指数'!$J$33:$J$45,0),MATCH('面板-总览'!D$2,'面板-景气指数'!$32:$32,0)) -> 0.61475 | E9: =INDEX('面板-景气指数'!$33:$45,MATCH('面板-总览'!$A9,'面板-景气指数'!$J$33:$J$45,0),MATCH('面板-总览'!E$2,'面板-景气指数'!$32:$32,0)) -> 0.60363043 | F9: =INDEX('面板-景气指数'!$33:$45,MATCH('面板-总览'!$A9,'面板-景气指数'!$J$33:$J$45,0),MATCH('面板-总览'!F$2,'面板-景气指数'!$32:$32,0)) -> 0.57363043 | G9: =INDEX('面板-景气指数'!$33:$45,MATCH('面板-总览'!$A9,'面板-景气指数'!$J$33:$J$45,0),MATCH('面板-总览'!G$2,'面板-景气指数'!$32:$32,0)) -> 0.519 | H9: =INDEX('面板-景气指数'!$33:$45,MATCH('面板-总览'!$A9,'面板-景气指数'!$J$33:$J$45,0),MATCH('面板-总览'!H$2,'面板-景气指数'!$32:$32,0)) -> 0.41781522 | I9: =INDEX('面板-景气指数'!$33:$45,MATCH('面板-总览'!$A9,'面板-景气指数'!$J$33:$J$45,0),MATCH('面板-总览'!I$2,'面板-景气指数'!$32:$32,0)) -> 0.39575 | ... K9: =INDEX('面板-景气指数'!$33:$45,MATCH('面板-总览'!$A9,'面板-景气指数'!$J$33:$J$45,0),MATCH('面板-总览'!K$2,'面板-景气指数'!$32:$32,0)) -> 0.30642391 | L9: =INDEX('面板-景气指数'!$33:$46,MATCH('面板-总览'!$A9,'面板-景气指数'!$J$33:$J$46,0),MATCH('面板-总览'!L$2,'面板-景气指数'!$32:$32,0)) -> 0.26147826 | M9: =INDEX('面板-景气指数'!$33:$46,MATCH('面板-总览'!$A9,'面板-景气指数'!$J$33:$J$46,0),MATCH('面板-总览'!M$2,'面板-景气指数'!$32:$32,0)) -> 0.19802174 | N9: =INDEX('面板-景气指数'!$33:$46,MATCH('面板-总览'!$A9,'面板-景气指数'!$J$33:$J$46,0),MATCH('面板-总览'!N$2,'面板-景气指数'!$32:$32,0)) -> 0.19676087 | P9: =N9-L9 -> -0.064717391 | R9: -10 | T9: 元宇宙中游 | U9: =INDEX('面板-景气指数'!$48:$84,MATCH('面板-总览'!$T9,'面板-景气指数'!$J$48:$J$84,0),MATCH('面板-总览'!U$2,'面板-景气指数'!$32:$32,0)) -> 0.90133333 | V9: =INDEX('面板-景气指数'!$48:$84,MATCH('面板-总览'!$T9,'面板-景气指数'!$J$48:$J$84,0),MATCH('面板-总览'!V$2,'面板-景气指数'!$32:$32,0)) -> 0.86366667 | W9: =INDEX('面板-景气指数'!$48:$84,MATCH('面板-总览'!$T9,'面板-景气指数'!$J$48:$J$84,0),MATCH('面板-总览'!W$2,'面板-景气指数'!$32:$32,0)) -> 0.45733333 | X9: =INDEX('面板-景气指数'!$48:$84,MATCH('面板-总览'!$T9,'面板-景气指数'!$J$48:$J$84,0),MATCH('面板-总览'!X$2,'面板-景气指数'!$32:$32,0)) -> 0.48266667 | Y9: =INDEX('面板-景气指数'!$48:$84,MATCH('面板-总览'!$T9,'面板-景气指数'!$J$48:$J$84,0),MATCH('面板-总览'!Y$2,'面板-景气指数'!$32:$32,0)) -> 0.48366667 | Z9: =INDEX('面板-景气指数'!$48:$84,MATCH('面板-总览'!$T9,'面板-景气指数'!$J$48:$J$84,0),MATCH('面板-总览'!Z$2,'面板-景气指数'!$32:$32,0)) -> 0.55816667 | AA9: =INDEX('面板-景气指数'!$48:$84,MATCH('面板-总览'!$T9,'面板-景气指数'!$J$48:$J$84,0),MATCH('面板-总览'!AA$2,'面板-景气指数'!$32:$32,0)) -> 0.56016667 | AB9: =INDEX('面板-景气指数'!$48:$84,MATCH('面板-总览'!$T9,'面板-景气指数'!$J$48:$J$84,0),MATCH('面板-总览'!AB$2,'面板-景气指数'!$32:$32,0)) -> 0.5265 | ... AG9: =INDEX('面板-景气指数'!$48:$84,MATCH('面板-总览'!$T9,'面板-景气指数'!$J$48:$J$84,0),MATCH('面板-总览'!AG$2,'面板-景气指数'!$32:$32,0)) -> 0.16683333 | AI9: =AG9-AE9 -> -0.54666667
A10: 数字基建 | B10: =INDEX('面板-景气指数'!$33:$45,MATCH('面板-总览'!$A10,'面板-景气指数'!$J$33:$J$45,0),MATCH('面板-总览'!B$2,'面板-景气指数'!$32:$32,0)) -> 0.56195833 | C10: =INDEX('面板-景气指数'!$33:$45,MATCH('面板-总览'!$A10,'面板-景气指数'!$J$33:$J$45,0),MATCH('面板-总览'!C$2,'面板-景气指数'!$32:$32,0)) -> 0.49430833 | D10: =INDEX('面板-景气指数'!$33:$45,MATCH('面板-总览'!$A10,'面板-景气指数'!$J$33:$J$45,0),MATCH('面板-总览'!D$2,'面板-景气指数'!$32:$32,0)) -> 0.66258333 | E10: =INDEX('面板-景气指数'!$33:$45,MATCH('面板-总览'!$A10,'面板-景气指数'!$J$33:$J$45,0),MATCH('面板-总览'!E$2,'面板-景气指数'!$32:$32,0)) -> 0.66975 | F10: =INDEX('面板-景气指数'!$33:$45,MATCH('面板-总览'!$A10,'面板-景气指数'!$J$33:$J$45,0),MATCH('面板-总览'!F$2,'面板-景气指数'!$32:$32,0)) -> 0.68066667 | G10: =INDEX('面板-景气指数'!$33:$45,MATCH('面板-总览'!$A10,'面板-景气指数'!$J$33:$J$45,0),MATCH('面板-总览'!G$2,'面板-景气指数'!$32:$32,0)) -> 0.70129167 | H10: =INDEX('面板-景气指数'!$33:$45,MATCH('面板-总览'!$A10,'面板-景气指数'!$J$33:$J$45,0),MATCH('面板-总览'!H$2,'面板-景气指数'!$32:$32,0)) -> 0.65024167 | I10: =INDEX('面板-景气指数'!$33:$45,MATCH('面板-总览'!$A10,'面板-景气指数'!$J$33:$J$45,0),MATCH('面板-总览'!I$2,'面板-景气指数'!$32:$32,0)) -> 0.66549167 | ... K10: =INDEX('面板-景气指数'!$33:$45,MATCH('面板-总览'!$A10,'面板-景气指数'!$J$33:$J$45,0),MATCH('面板-总览'!K$2,'面板-景气指数'!$32:$32,0)) -> 0.47654167 | L10: =INDEX('面板-景气指数'!$33:$46,MATCH('面板-总览'!$A10,'面板-景气指数'!$J$33:$J$46,0),MATCH('面板-总览'!L$2,'面板-景气指数'!$32:$32,0)) -> 0.46844167 | M10: =INDEX('面板-景气指数'!$33:$46,MATCH('面板-总览'!$A10,'面板-景气指数'!$J$33:$J$46,0),MATCH('面板-总览'!M$2,'面板-景气指数'!$32:$32,0)) -> 0.52689167 | N10: =INDEX('面板-景气指数'!$33:$46,MATCH('面板-总览'!$A10,'面板-景气指数'!$J$33:$J$46,0),MATCH('面板-总览'!N$2,'面板-景气指数'!$32:$32,0)) -> 0.51389167 | P10: =N10-L10 -> 0.04545 | R10: 10 | T10: 元宇宙下游 | U10: =INDEX('面板-景气指数'!$48:$84,MATCH('面板-总览'!$T10,'面板-景气指数'!$J$48:$J$84,0),MATCH('面板-总览'!U$2,'面板-景气指数'!$32:$32,0)) -> 0.337 | V10: =INDEX('面板-景气指数'!$48:$84,MATCH('面板-总览'!$T10,'面板-景气指数'!$J$48:$J$84,0),MATCH('面板-总览'!V$2,'面板-景气指数'!$32:$32,0)) -> 0.2505 | W10: =INDEX('面板-景气指数'!$48:$84,MATCH('面板-总览'!$T10,'面板-景气指数'!$J$48:$J$84,0),MATCH('面板-总览'!W$2,'面板-景气指数'!$32:$32,0)) -> 0.3045 | X10: =INDEX('面板-景气指数'!$48:$84,MATCH('面板-总览'!$T10,'面板-景气指数'!$J$48:$J$84,0),MATCH('面板-总览'!X$2,'面板-景气指数'!$32:$32,0)) -> 0.5255 | Y10: =INDEX('面板-景气指数'!$48:$84,MATCH('面板-总览'!$T10,'面板-景气指数'!$J$48:$J$84,0),MATCH('面板-总览'!Y$2,'面板-景气指数'!$32:$32,0)) -> 0.387 | Z10: =INDEX('面板-景气指数'!$48:$84,MATCH('面板-总览'!$T10,'面板-景气指数'!$J$48:$J$84,0),MATCH('面板-总览'!Z$2,'面板-景气指数'!$32:$32,0)) -> 0.1815 | AA10: =INDEX('面板-景气指数'!$48:$84,MATCH('面板-总览'!$T10,'面板-景气指数'!$J$48:$J$84,0),MATCH('面板-总览'!AA$2,'面板-景气指数'!$32:$32,0)) -> 0.119 | AB10: =INDEX('面板-景气指数'!$48:$84,MATCH('面板-总览'!$T10,'面板-景气指数'!$J$48:$J$84,0),MATCH('面板-总览'!AB$2,'面板-景气指数'!$32:$32,0)) -> 0.294 | ... AG10: =INDEX('面板-景气指数'!$48:$84,MATCH('面板-总览'!$T10,'面板-景气指数'!$J$48:$J$84,0),MATCH('面板-总览'!AG$2,'面板-景气指数'!$32:$32,0)) -> 0.242 | AI10: =AG10-AE10 -> -0.3055
A11: CXO | B11: =INDEX('面板-景气指数'!$33:$45,MATCH('面板-总览'!$A11,'面板-景气指数'!$J$33:$J$45,0),MATCH('面板-总览'!B$2,'面板-景气指数'!$32:$32,0)) -> 0.434375 | C11: =INDEX('面板-景气指数'!$33:$45,MATCH('面板-总览'!$A11,'面板-景气指数'!$J$33:$J$45,0),MATCH('面板-总览'!C$2,'面板-景气指数'!$32:$32,0)) -> 0.42325 | D11: =INDEX('面板-景气指数'!$33:$45,MATCH('面板-总览'!$A11,'面板-景气指数'!$J$33:$J$45,0),MATCH('面板-总览'!D$2,'面板-景气指数'!$32:$32,0)) -> 0.493875 | E11: =INDEX('面板-景气指数'!$33:$45,MATCH('面板-总览'!$A11,'面板-景气指数'!$J$33:$J$45,0),MATCH('面板-总览'!E$2,'面板-景气指数'!$32:$32,0)) -> 0.56425 | F11: =INDEX('面板-景气指数'!$33:$45,MATCH('面板-总览'!$A11,'面板-景气指数'!$J$33:$J$45,0),MATCH('面板-总览'!F$2,'面板-景气指数'!$32:$32,0)) -> 0.671875 | G11: =INDEX('面板-景气指数'!$33:$45,MATCH('面板-总览'!$A11,'面板-景气指数'!$J$33:$J$45,0),MATCH('面板-总览'!G$2,'面板-景气指数'!$32:$32,0)) -> 0.65925 | H11: =INDEX('面板-景气指数'!$33:$45,MATCH('面板-总览'!$A11,'面板-景气指数'!$J$33:$J$45,0),MATCH('面板-总览'!H$2,'面板-景气指数'!$32:$32,0)) -> 0.46825 | I11: =INDEX('面板-景气指数'!$33:$45,MATCH('面板-总览'!$A11,'面板-景气指数'!$J$33:$J$45,0),MATCH('面板-总览'!I$2,'面板-景气指数'!$32:$32,0)) -> 0.401875 | ... K11: =INDEX('面板-景气指数'!$33:$45,MATCH('面板-总览'!$A11,'面板-景气指数'!$J$33:$J$45,0),MATCH('面板-总览'!K$2,'面板-景气指数'!$32:$32,0)) -> 0.513 | L11: =INDEX('面板-景气指数'!$33:$46,MATCH('面板-总览'!$A11,'面板-景气指数'!$J$33:$J$46,0),MATCH('面板-总览'!L$2,'面板-景气指数'!$32:$32,0)) -> 0.701875 | M11: =INDEX('面板-景气指数'!$33:$46,MATCH('面板-总览'!$A11,'面板-景气指数'!$J$33:$J$46,0),MATCH('面板-总览'!M$2,'面板-景气指数'!$32:$32,0)) -> 0.736625 | N11: =INDEX('面板-景气指数'!$33:$46,MATCH('面板-总览'!$A11,'面板-景气指数'!$J$33:$J$46,0),MATCH('面板-总览'!N$2,'面板-景气指数'!$32:$32,0)) -> 0.748625 | P11: =N11-L11 -> 0.04675 | R11: -5 | T11: 光伏上游 | U11: =INDEX('面板-景气指数'!$48:$84,MATCH('面板-总览'!$T11,'面板-景气指数'!$J$48:$J$84,0),MATCH('面板-总览'!U$2,'面板-景气指数'!$32:$32,0)) -> 0.902 | V11: =INDEX('面板-景气指数'!$48:$84,MATCH('面板-总览'!$T11,'面板-景气指数'!$J$48:$J$84,0),MATCH('面板-总览'!V$2,'面板-景气指数'!$32:$32,0)) -> 0.91866667 | W11: =INDEX('面板-景气指数'!$48:$84,MATCH('面板-总览'!$T11,'面板-景气指数'!$J$48:$J$84,0),MATCH('面板-总览'!W$2,'面板-景气指数'!$32:$32,0)) -> 0.85283333 | X11: =INDEX('面板-景气指数'!$48:$84,MATCH('面板-总览'!$T11,'面板-景气指数'!$J$48:$J$84,0),MATCH('面板-总览'!X$2,'面板-景气指数'!$32:$32,0)) -> 0.80466667 | Y11: =INDEX('面板-景气指数'!$48:$84,MATCH('面板-总览'!$T11,'面板-景气指数'!$J$48:$J$84,0),MATCH('面板-总览'!Y$2,'面板-景气指数'!$32:$32,0)) -> 0.82633333 | Z11: =INDEX('面板-景气指数'!$48:$84,MATCH('面板-总览'!$T11,'面板-景气指数'!$J$48:$J$84,0),MATCH('面板-总览'!Z$2,'面板-景气指数'!$32:$32,0)) -> 0.77816667 | AA11: =INDEX('面板-景气指数'!$48:$84,MATCH('面板-总览'!$T11,'面板-景气指数'!$J$48:$J$84,0),MATCH('面板-总览'!AA$2,'面板-景气指数'!$32:$32,0)) -> 0.80233333 | AB11: =INDEX('面板-景气指数'!$48:$84,MATCH('面板-总览'!$T11,'面板-景气指数'!$J$48:$J$84,0),MATCH('面板-总览'!AB$2,'面板-景气指数'!$32:$32,0)) -> 0.79516667 | ... AG11: =INDEX('面板-景气指数'!$48:$84,MATCH('面板-总览'!$T11,'面板-景气指数'!$J$48:$J$84,0),MATCH('面板-总览'!AG$2,'面板-景气指数'!$32:$32,0)) -> 0.72233333 | AI11: =AG11-AE11 -> -0.065
A12: 智能汽车 | B12: =INDEX('面板-景气指数'!$33:$45,MATCH('面板-总览'!$A12,'面板-景气指数'!$J$33:$J$45,0),MATCH('面板-总览'!B$2,'面板-景气指数'!$32:$32,0)) -> 0.39216667 | C12: =INDEX('面板-景气指数'!$33:$45,MATCH('面板-总览'!$A12,'面板-景气指数'!$J$33:$J$45,0),MATCH('面板-总览'!C$2,'面板-景气指数'!$32:$32,0)) -> 0.5083 | D12: =INDEX('面板-景气指数'!$33:$45,MATCH('面板-总览'!$A12,'面板-景气指数'!$J$33:$J$45,0),MATCH('面板-总览'!D$2,'面板-景气指数'!$32:$32,0)) -> 0.47723333 | E12: =INDEX('面板-景气指数'!$33:$45,MATCH('面板-总览'!$A12,'面板-景气指数'!$J$33:$J$45,0),MATCH('面板-总览'!E$2,'面板-景气指数'!$32:$32,0)) -> 0.3686 | F12: =INDEX('面板-景气指数'!$33:$45,MATCH('面板-总览'!$A12,'面板-景气指数'!$J$33:$J$45,0),MATCH('面板-总览'!F$2,'面板-景气指数'!$32:$32,0)) -> 0.35543333 | G12: =INDEX('面板-景气指数'!$33:$45,MATCH('面板-总览'!$A12,'面板-景气指数'!$J$33:$J$45,0),MATCH('面板-总览'!G$2,'面板-景气指数'!$32:$32,0)) -> 0.3482 | H12: =INDEX('面板-景气指数'!$33:$45,MATCH('面板-总览'!$A12,'面板-景气指数'!$J$33:$J$45,0),MATCH('面板-总览'!H$2,'面板-景气指数'!$32:$32,0)) -> 0.2021 | I12: =INDEX('面板-景气指数'!$33:$45,MATCH('面板-总览'!$A12,'面板-景气指数'!$J$33:$J$45,0),MATCH('面板-总览'!I$2,'面板-景气指数'!$32:$32,0)) -> 0.14446667 | ... K12: =INDEX('面板-景气指数'!$33:$45,MATCH('面板-总览'!$A12,'面板-景气指数'!$J$33:$J$45,0),MATCH('面板-总览'!K$2,'面板-景气指数'!$32:$32,0)) -> 0.33976667 | L12: =INDEX('面板-景气指数'!$33:$46,MATCH('面板-总览'!$A12,'面板-景气指数'!$J$33:$J$46,0),MATCH('面板-总览'!L$2,'面板-景气指数'!$32:$32,0)) -> 0.40193333 | M12: =INDEX('面板-景气指数'!$33:$46,MATCH('面板-总览'!$A12,'面板-景气指数'!$J$33:$J$46,0),MATCH('面板-总览'!M$2,'面板-景气指数'!$32:$32,0)) -> 0.4704 | N12: =INDEX('面板-景气指数'!$33:$46,MATCH('面板-总览'!$A12,'面板-景气指数'!$J$33:$J$46,0),MATCH('面板-总览'!N$2,'面板-景气指数'!$32:$32,0)) -> 0.4704 | P12: =N12-L12 -> 0.068466667 | R12: 10 | T12: 光伏中游 | U12: =INDEX('面板-景气指数'!$48:$84,MATCH('面板-总览'!$T12,'面板-景气指数'!$J$48:$J$84,0),MATCH('面板-总览'!U$2,'面板-景气指数'!$32:$32,0)) -> 0.55925 | V12: =INDEX('面板-景气指数'!$48:$84,MATCH('面板-总览'!$T12,'面板-景气指数'!$J$48:$J$84,0),MATCH('面板-总览'!V$2,'面板-景气指数'!$32:$32,0)) -> 0.52233333 | W12: =INDEX('面板-景气指数'!$48:$84,MATCH('面板-总览'!$T12,'面板-景气指数'!$J$48:$J$84,0),MATCH('面板-总览'!W$2,'面板-景气指数'!$32:$32,0)) -> 0.48779167 | X12: =INDEX('面板-景气指数'!$48:$84,MATCH('面板-总览'!$T12,'面板-景气指数'!$J$48:$J$84,0),MATCH('面板-总览'!X$2,'面板-景气指数'!$32:$32,0)) -> 0.50804167 | Y12: =INDEX('面板-景气指数'!$48:$84,MATCH('面板-总览'!$T12,'面板-景气指数'!$J$48:$J$84,0),MATCH('面板-总览'!Y$2,'面板-景气指数'!$32:$32,0)) -> 0.857 | Z12: =INDEX('面板-景气指数'!$48:$84,MATCH('面板-总览'!$T12,'面板-景气指数'!$J$48:$J$84,0),MATCH('面板-总览'!Z$2,'面板-景气指数'!$32:$32,0)) -> 0.84108333 | AA12: =INDEX('面板-景气指数'!$48:$84,MATCH('面板-总览'!$T12,'面板-景气指数'!$J$48:$J$84,0),MATCH('面板-总览'!AA$2,'面板-景气指数'!$32:$32,0)) -> 0.84333333 | AB12: =INDEX('面板-景气指数'!$48:$84,MATCH('面板-总览'!$T12,'面板-景气指数'!$J$48:$J$84,0),MATCH('面板-总览'!AB$2,'面板-景气指数'!$32:$32,0)) -> 0.85270833 | ... AG12: =INDEX('面板-景气指数'!$48:$84,MATCH('面板-总览'!$T12,'面板-景气指数'!$J$48:$J$84,0),MATCH('面板-总览'!AG$2,'面板-景气指数'!$32:$32,0)) -> 0.756875 | AI12: =AG12-AE12 -> -0.045041667
A13: 航空装备 | B13: =INDEX('面板-景气指数'!$33:$45,MATCH('面板-总览'!$A13,'面板-景气指数'!$J$33:$J$45,0),MATCH('面板-总览'!B$2,'面板-景气指数'!$32:$32,0)) -> 0.83333333 | C13: =INDEX('面板-景气指数'!$33:$45,MATCH('面板-总览'!$A13,'面板-景气指数'!$J$33:$J$45,0),MATCH('面板-总览'!C$2,'面板-景气指数'!$32:$32,0)) -> 0.83988889 | D13: =INDEX('面板-景气指数'!$33:$45,MATCH('面板-总览'!$A13,'面板-景气指数'!$J$33:$J$45,0),MATCH('面板-总览'!D$2,'面板-景气指数'!$32:$32,0)) -> 0.68911111 | E13: =INDEX('面板-景气指数'!$33:$45,MATCH('面板-总览'!$A13,'面板-景气指数'!$J$33:$J$45,0),MATCH('面板-总览'!E$2,'面板-景气指数'!$32:$32,0)) -> 0.74377778 | F13: =INDEX('面板-景气指数'!$33:$45,MATCH('面板-总览'!$A13,'面板-景气指数'!$J$33:$J$45,0),MATCH('面板-总览'!F$2,'面板-景气指数'!$32:$32,0)) -> 0.77933333 | G13: =INDEX('面板-景气指数'!$33:$45,MATCH('面板-总览'!$A13,'面板-景气指数'!$J$33:$J$45,0),MATCH('面板-总览'!G$2,'面板-景气指数'!$32:$32,0)) -> 0.77088889 | H13: =INDEX('面板-景气指数'!$33:$45,MATCH('面板-总览'!$A13,'面板-景气指数'!$J$33:$J$45,0),MATCH('面板-总览'!H$2,'面板-景气指数'!$32:$32,0)) -> 0.74355556 | I13: =INDEX('面板-景气指数'!$33:$45,MATCH('面板-总览'!$A13,'面板-景气指数'!$J$33:$J$45,0),MATCH('面板-总览'!I$2,'面板-景气指数'!$32:$32,0)) -> 0.76122222 | ... K13: =INDEX('面板-景气指数'!$33:$45,MATCH('面板-总览'!$A13,'面板-景气指数'!$J$33:$J$45,0),MATCH('面板-总览'!K$2,'面板-景气指数'!$32:$32,0)) -> 0.69877778 | L13: =INDEX('面板-景气指数'!$33:$46,MATCH('面板-总览'!$A13,'面板-景气指数'!$J$33:$J$46,0),MATCH('面板-总览'!L$2,'面板-景气指数'!$32:$32,0)) -> 0.70188889 | M13: =INDEX('面板-景气指数'!$33:$46,MATCH('面板-总览'!$A13,'面板-景气指数'!$J$33:$J$46,0),MATCH('面板-总览'!M$2,'面板-景气指数'!$32:$32,0)) -> 0.65577778 | N13: =INDEX('面板-景气指数'!$33:$46,MATCH('面板-总览'!$A13,'面板-景气指数'!$J$33:$J$46,0),MATCH('面板-总览'!N$2,'面板-景气指数'!$32:$32,0)) -> 0.64288889 | P13: =N13-L13 -> -0.059 | R13: -5 | T13: 光伏下游 | U13: =INDEX('面板-景气指数'!$48:$84,MATCH('面板-总览'!$T13,'面板-景气指数'!$J$48:$J$84,0),MATCH('面板-总览'!U$2,'面板-景气指数'!$32:$32,0)) -> 0.2455 | V13: =INDEX('面板-景气指数'!$48:$84,MATCH('面板-总览'!$T13,'面板-景气指数'!$J$48:$J$84,0),MATCH('面板-总览'!V$2,'面板-景气指数'!$32:$32,0)) -> 0.2555 | W13: =INDEX('面板-景气指数'!$48:$84,MATCH('面板-总览'!$T13,'面板-景气指数'!$J$48:$J$84,0),MATCH('面板-总览'!W$2,'面板-景气指数'!$32:$32,0)) -> 0.3 | X13: =INDEX('面板-景气指数'!$48:$84,MATCH('面板-总览'!$T13,'面板-景气指数'!$J$48:$J$84,0),MATCH('面板-总览'!X$2,'面板-景气指数'!$32:$32,0)) -> 0.3 | Y13: =INDEX('面板-景气指数'!$48:$84,MATCH('面板-总览'!$T13,'面板-景气指数'!$J$48:$J$84,0),MATCH('面板-总览'!Y$2,'面板-景气指数'!$32:$32,0)) -> 0.136 | Z13: =INDEX('面板-景气指数'!$48:$84,MATCH('面板-总览'!$T13,'面板-景气指数'!$J$48:$J$84,0),MATCH('面板-总览'!Z$2,'面板-景气指数'!$32:$32,0)) -> 0.077 | AA13: =INDEX('面板-景气指数'!$48:$84,MATCH('面板-总览'!$T13,'面板-景气指数'!$J$48:$J$84,0),MATCH('面板-总览'!AA$2,'面板-景气指数'!$32:$32,0)) -> 0.3625 | AB13: =INDEX('面板-景气指数'!$48:$84,MATCH('面板-总览'!$T13,'面板-景气指数'!$J$48:$J$84,0),MATCH('面板-总览'!AB$2,'面板-景气指数'!$32:$32,0)) -> 0.588 | ... AG13: =INDEX('面板-景气指数'!$48:$84,MATCH('面板-总览'!$T13,'面板-景气指数'!$J$48:$J$84,0),MATCH('面板-总览'!AG$2,'面板-景气指数'!$32:$32,0)) -> 0.6765 | AI13: =AG13-AE13 -> 0.0365
A14: 物联网 | B14: =INDEX('面板-景气指数'!$33:$45,MATCH('面板-总览'!$A14,'面板-景气指数'!$J$33:$J$45,0),MATCH('面板-总览'!B$2,'面板-景气指数'!$32:$32,0)) -> 0.59146429 | C14: =INDEX('面板-景气指数'!$33:$45,MATCH('面板-总览'!$A14,'面板-景气指数'!$J$33:$J$45,0),MATCH('面板-总览'!C$2,'面板-景气指数'!$32:$32,0)) -> 0.56239286 | D14: =INDEX('面板-景气指数'!$33:$45,MATCH('面板-总览'!$A14,'面板-景气指数'!$J$33:$J$45,0),MATCH('面板-总览'!D$2,'面板-景气指数'!$32:$32,0)) -> 0.54221429 | E14: =INDEX('面板-景气指数'!$33:$45,MATCH('面板-总览'!$A14,'面板-景气指数'!$J$33:$J$45,0),MATCH('面板-总览'!E$2,'面板-景气指数'!$32:$32,0)) -> 0.52757143 | F14: =INDEX('面板-景气指数'!$33:$45,MATCH('面板-总览'!$A14,'面板-景气指数'!$J$33:$J$45,0),MATCH('面板-总览'!F$2,'面板-景气指数'!$32:$32,0)) -> 0.51010714 | G14: =INDEX('面板-景气指数'!$33:$45,MATCH('面板-总览'!$A14,'面板-景气指数'!$J$33:$J$45,0),MATCH('面板-总览'!G$2,'面板-景气指数'!$32:$32,0)) -> 0.44432143 | H14: =INDEX('面板-景气指数'!$33:$45,MATCH('面板-总览'!$A14,'面板-景气指数'!$J$33:$J$45,0),MATCH('面板-总览'!H$2,'面板-景气指数'!$32:$32,0)) -> 0.42064286 | I14: =INDEX('面板-景气指数'!$33:$45,MATCH('面板-总览'!$A14,'面板-景气指数'!$J$33:$J$45,0),MATCH('面板-总览'!I$2,'面板-景气指数'!$32:$32,0)) -> 0.39935714 | ... K14: =INDEX('面板-景气指数'!$33:$45,MATCH('面板-总览'!$A14,'面板-景气指数'!$J$33:$J$45,0),MATCH('面板-总览'!K$2,'面板-景气指数'!$32:$32,0)) -> 0.50096429 | L14: =INDEX('面板-景气指数'!$33:$46,MATCH('面板-总览'!$A14,'面板-景气指数'!$J$33:$J$46,0),MATCH('面板-总览'!L$2,'面板-景气指数'!$32:$32,0)) -> 0.54610714 | M14: =INDEX('面板-景气指数'!$33:$46,MATCH('面板-总览'!$A14,'面板-景气指数'!$J$33:$J$46,0),MATCH('面板-总览'!M$2,'面板-景气指数'!$32:$32,0)) -> 0.41403571 | N14: =INDEX('面板-景气指数'!$33:$46,MATCH('面板-总览'!$A14,'面板-景气指数'!$J$33:$J$46,0),MATCH('面板-总览'!N$2,'面板-景气指数'!$32:$32,0)) -> 0.46982143 | P14: =N14-L14 -> -0.076285714 | R14: 10 | T14: 风电上游 | U14: =INDEX('面板-景气指数'!$48:$84,MATCH('面板-总览'!$T14,'面板-景气指数'!$J$48:$J$84,0),MATCH('面板-总览'!U$2,'面板-景气指数'!$32:$32,0)) -> 0.86733333 | V14: =INDEX('面板-景气指数'!$48:$84,MATCH('面板-总览'!$T14,'面板-景气指数'!$J$48:$J$84,0),MATCH('面板-总览'!V$2,'面板-景气指数'!$32:$32,0)) -> 0.82466667 | W14: =INDEX('面板-景气指数'!$48:$84,MATCH('面板-总览'!$T14,'面板-景气指数'!$J$48:$J$84,0),MATCH('面板-总览'!W$2,'面板-景气指数'!$32:$32,0)) -> 0.549 | X14: =INDEX('面板-景气指数'!$48:$84,MATCH('面板-总览'!$T14,'面板-景气指数'!$J$48:$J$84,0),MATCH('面板-总览'!X$2,'面板-景气指数'!$32:$32,0)) -> 0.63733333 | Y14: =INDEX('面板-景气指数'!$48:$84,MATCH('面板-总览'!$T14,'面板-景气指数'!$J$48:$J$84,0),MATCH('面板-总览'!Y$2,'面板-景气指数'!$32:$32,0)) -> 0.71366667 | Z14: =INDEX('面板-景气指数'!$48:$84,MATCH('面板-总览'!$T14,'面板-景气指数'!$J$48:$J$84,0),MATCH('面板-总览'!Z$2,'面板-景气指数'!$32:$32,0)) -> 0.69266667 | AA14: =INDEX('面板-景气指数'!$48:$84,MATCH('面板-总览'!$T14,'面板-景气指数'!$J$48:$J$84,0),MATCH('面板-总览'!AA$2,'面板-景气指数'!$32:$32,0)) -> 0.64933333 | AB14: =INDEX('面板-景气指数'!$48:$84,MATCH('面板-总览'!$T14,'面板-景气指数'!$J$48:$J$84,0),MATCH('面板-总览'!AB$2,'面板-景气指数'!$32:$32,0)) -> 0.628 | ... AG14: =INDEX('面板-景气指数'!$48:$84,MATCH('面板-总览'!$T14,'面板-景气指数'!$J$48:$J$84,0),MATCH('面板-总览'!AG$2,'面板-景气指数'!$32:$32,0)) -> 0.55433333 | AI14: =AG14-AE14 -> -0.061333333
A15: 医美-化妆品 | B15: =INDEX('面板-景气指数'!$33:$45,MATCH('面板-总览'!$A15,'面板-景气指数'!$J$33:$J$45,0),MATCH('面板-总览'!B$2,'面板-景气指数'!$32:$32,0)) -> 0.436375 | C15: =INDEX('面板-景气指数'!$33:$45,MATCH('面板-总览'!$A15,'面板-景气指数'!$J$33:$J$45,0),MATCH('面板-总览'!C$2,'面板-景气指数'!$32:$32,0)) -> 0.37 | D15: =INDEX('面板-景气指数'!$33:$45,MATCH('面板-总览'!$A15,'面板-景气指数'!$J$33:$J$45,0),MATCH('面板-总览'!D$2,'面板-景气指数'!$32:$32,0)) -> 0.33175 | E15: =INDEX('面板-景气指数'!$33:$45,MATCH('面板-总览'!$A15,'面板-景气指数'!$J$33:$J$45,0),MATCH('面板-总览'!E$2,'面板-景气指数'!$32:$32,0)) -> 0.320875 | F15: =INDEX('面板-景气指数'!$33:$45,MATCH('面板-总览'!$A15,'面板-景气指数'!$J$33:$J$45,0),MATCH('面板-总览'!F$2,'面板-景气指数'!$32:$32,0)) -> 0.31925 | G15: =INDEX('面板-景气指数'!$33:$45,MATCH('面板-总览'!$A15,'面板-景气指数'!$J$33:$J$45,0),MATCH('面板-总览'!G$2,'面板-景气指数'!$32:$32,0)) -> 0.332125 | H15: =INDEX('面板-景气指数'!$33:$45,MATCH('面板-总览'!$A15,'面板-景气指数'!$J$33:$J$45,0),MATCH('面板-总览'!H$2,'面板-景气指数'!$32:$32,0)) -> 0.258 | I15: =INDEX('面板-景气指数'!$33:$45,MATCH('面板-总览'!$A15,'面板-景气指数'!$J$33:$J$45,0),MATCH('面板-总览'!I$2,'面板-景气指数'!$32:$32,0)) -> 0.231375 | ... K15: =INDEX('面板-景气指数'!$33:$45,MATCH('面板-总览'!$A15,'面板-景气指数'!$J$33:$J$45,0),MATCH('面板-总览'!K$2,'面板-景气指数'!$32:$32,0)) -> 0.223375 | L15: =INDEX('面板-景气指数'!$33:$46,MATCH('面板-总览'!$A15,'面板-景气指数'!$J$33:$J$46,0),MATCH('面板-总览'!L$2,'面板-景气指数'!$32:$32,0)) -> 0.248625 | M15: =INDEX('面板-景气指数'!$33:$46,MATCH('面板-总览'!$A15,'面板-景气指数'!$J$33:$J$46,0),MATCH('面板-总览'!M$2,'面板-景气指数'!$32:$32,0)) -> 0.281125 | N15: =INDEX('面板-景气指数'!$33:$46,MATCH('面板-总览'!$A15,'面板-景气指数'!$J$33:$J$46,0),MATCH('面板-总览'!N$2,'面板-景气指数'!$32:$32,0)) -> 0.288625 | P15: =N15-L15 -> 0.04 | R15: 10 | T15: 风电中游 | U15: =INDEX('面板-景气指数'!$48:$84,MATCH('面板-总览'!$T15,'面板-景气指数'!$J$48:$J$84,0),MATCH('面板-总览'!U$2,'面板-景气指数'!$32:$32,0)) -> 0.34011765 | V15: =INDEX('面板-景气指数'!$48:$84,MATCH('面板-总览'!$T15,'面板-景气指数'!$J$48:$J$84,0),MATCH('面板-总览'!V$2,'面板-景气指数'!$32:$32,0)) -> 0.25608824 | W15: =INDEX('面板-景气指数'!$48:$84,MATCH('面板-总览'!$T15,'面板-景气指数'!$J$48:$J$84,0),MATCH('面板-总览'!W$2,'面板-景气指数'!$32:$32,0)) -> 0.22852941 | X15: =INDEX('面板-景气指数'!$48:$84,MATCH('面板-总览'!$T15,'面板-景气指数'!$J$48:$J$84,0),MATCH('面板-总览'!X$2,'面板-景气指数'!$32:$32,0)) -> 0.23620588 | Y15: =INDEX('面板-景气指数'!$48:$84,MATCH('面板-总览'!$T15,'面板-景气指数'!$J$48:$J$84,0),MATCH('面板-总览'!Y$2,'面板-景气指数'!$32:$32,0)) -> 0.51326471 | Z15: =INDEX('面板-景气指数'!$48:$84,MATCH('面板-总览'!$T15,'面板-景气指数'!$J$48:$J$84,0),MATCH('面板-总览'!Z$2,'面板-景气指数'!$32:$32,0)) -> 0.44270588 | AA15: =INDEX('面板-景气指数'!$48:$84,MATCH('面板-总览'!$T15,'面板-景气指数'!$J$48:$J$84,0),MATCH('面板-总览'!AA$2,'面板-景气指数'!$32:$32,0)) -> 0.42023529 | AB15: =INDEX('面板-景气指数'!$48:$84,MATCH('面板-总览'!$T15,'面板-景气指数'!$J$48:$J$84,0),MATCH('面板-总览'!AB$2,'面板-景气指数'!$32:$32,0)) -> 0.41682353 | ... AG15: =INDEX('面板-景气指数'!$48:$84,MATCH('面板-总览'!$T15,'面板-景气指数'!$J$48:$J$84,0),MATCH('面板-总览'!AG$2,'面板-景气指数'!$32:$32,0)) -> 0.36176471 | AI15: =AG15-AE15 -> 0.016176471
A16: 储能 | B16: =INDEX('面板-景气指数'!$33:$46,MATCH('面板-总览'!$A16,'面板-景气指数'!$J$33:$J$46,0),MATCH('面板-总览'!B$2,'面板-景气指数'!$32:$32,0)) -> 0.562625 | C16: =INDEX('面板-景气指数'!$33:$46,MATCH('面板-总览'!$A16,'面板-景气指数'!$J$33:$J$46,0),MATCH('面板-总览'!C$2,'面板-景气指数'!$32:$32,0)) -> 0.52458333 | D16: =INDEX('面板-景气指数'!$33:$46,MATCH('面板-总览'!$A16,'面板-景气指数'!$J$33:$J$46,0),MATCH('面板-总览'!D$2,'面板-景气指数'!$32:$32,0)) -> 0.41141667 | E16: =INDEX('面板-景气指数'!$33:$46,MATCH('面板-总览'!$A16,'面板-景气指数'!$J$33:$J$46,0),MATCH('面板-总览'!E$2,'面板-景气指数'!$32:$32,0)) -> 0.43079167 | F16: =INDEX('面板-景气指数'!$33:$46,MATCH('面板-总览'!$A16,'面板-景气指数'!$J$33:$J$46,0),MATCH('面板-总览'!F$2,'面板-景气指数'!$32:$32,0)) -> 0.601 | G16: =INDEX('面板-景气指数'!$33:$46,MATCH('面板-总览'!$A16,'面板-景气指数'!$J$33:$J$46,0),MATCH('面板-总览'!G$2,'面板-景气指数'!$32:$32,0)) -> 0.77683333 | H16: =INDEX('面板-景气指数'!$33:$46,MATCH('面板-总览'!$A16,'面板-景气指数'!$J$33:$J$46,0),MATCH('面板-总览'!H$2,'面板-景气指数'!$32:$32,0)) -> 0.749875 | I16: =INDEX('面板-景气指数'!$33:$46,MATCH('面板-总览'!$A16,'面板-景气指数'!$J$33:$J$46,0),MATCH('面板-总览'!I$2,'面板-景气指数'!$32:$32,0)) -> 0.71775 | ... N16: =INDEX('面板-景气指数'!$33:$46,MATCH('面板-总览'!$A16,'面板-景气指数'!$J$33:$J$46,0),MATCH('面板-总览'!N$2,'面板-景气指数'!$32:$32,0)) -> 0.61483333 | P16: =N16-L16 -> -0.01025 | R16: 10 | T16: 风电下游 | U16: =INDEX('面板-景气指数'!$48:$84,MATCH('面板-总览'!$T16,'面板-景气指数'!$J$48:$J$84,0),MATCH('面板-总览'!U$2,'面板-景气指数'!$32:$32,0)) -> 0.56166667 | V16: =INDEX('面板-景气指数'!$48:$84,MATCH('面板-总览'!$T16,'面板-景气指数'!$J$48:$J$84,0),MATCH('面板-总览'!V$2,'面板-景气指数'!$32:$32,0)) -> 0.65866667 | W16: =INDEX('面板-景气指数'!$48:$84,MATCH('面板-总览'!$T16,'面板-景气指数'!$J$48:$J$84,0),MATCH('面板-总览'!W$2,'面板-景气指数'!$32:$32,0)) -> 0.66366667 | X16: =INDEX('面板-景气指数'!$48:$84,MATCH('面板-总览'!$T16,'面板-景气指数'!$J$48:$J$84,0),MATCH('面板-总览'!X$2,'面板-景气指数'!$32:$32,0)) -> 0.52833333 | Y16: =INDEX('面板-景气指数'!$48:$84,MATCH('面板-总览'!$T16,'面板-景气指数'!$J$48:$J$84,0),MATCH('面板-总览'!Y$2,'面板-景气指数'!$32:$32,0)) -> 0.21933333 | Z16: =INDEX('面板-景气指数'!$48:$84,MATCH('面板-总览'!$T16,'面板-景气指数'!$J$48:$J$84,0),MATCH('面板-总览'!Z$2,'面板-景气指数'!$32:$32,0)) -> 0.067333333 | AA16: =INDEX('面板-景气指数'!$48:$84,MATCH('面板-总览'!$T16,'面板-景气指数'!$J$48:$J$84,0),MATCH('面板-总览'!AA$2,'面板-景气指数'!$32:$32,0)) -> 0.081666667 | AB16: =INDEX('面板-景气指数'!$48:$84,MATCH('面板-总览'!$T16,'面板-景气指数'!$J$48:$J$84,0),MATCH('面板-总览'!AB$2,'面板-景气指数'!$32:$32,0)) -> 0.28066667 | ... AG16: =INDEX('面板-景气指数'!$48:$84,MATCH('面板-总览'!$T16,'面板-景气指数'!$J$48:$J$84,0),MATCH('面板-总览'!AG$2,'面板-景气指数'!$32:$32,0)) -> 0.544 | AI16: =AG16-AE16 -> 0.083
T17: 半导体上游 | U17: =INDEX('面板-景气指数'!$48:$84,MATCH('面板-总览'!$T17,'面板-景气指数'!$J$48:$J$84,0),MATCH('面板-总览'!U$2,'面板-景气指数'!$32:$32,0)) -> 0.47341667 | V17: =INDEX('面板-景气指数'!$48:$84,MATCH('面板-总览'!$T17,'面板-景气指数'!$J$48:$J$84,0),MATCH('面板-总览'!V$2,'面板-景气指数'!$32:$32,0)) -> 0.59825 | W17: =INDEX('面板-景气指数'!$48:$84,MATCH('面板-总览'!$T17,'面板-景气指数'!$J$48:$J$84,0),MATCH('面板-总览'!W$2,'面板-景气指数'!$32:$32,0)) -> 0.61925 | X17: =INDEX('面板-景气指数'!$48:$84,MATCH('面板-总览'!$T17,'面板-景气指数'!$J$48:$J$84,0),MATCH('面板-总览'!X$2,'面板-景气指数'!$32:$32,0)) -> 0.58883333 | Y17: =INDEX('面板-景气指数'!$48:$84,MATCH('面板-总览'!$T17,'面板-景气指数'!$J$48:$J$84,0),MATCH('面板-总览'!Y$2,'面板-景气指数'!$32:$32,0)) -> 0.53241667 | Z17: =INDEX('面板-景气指数'!$48:$84,MATCH('面板-总览'!$T17,'面板-景气指数'!$J$48:$J$84,0),MATCH('面板-总览'!Z$2,'面板-景气指数'!$32:$32,0)) -> 0.41233333 | AA17: =INDEX('面板-景气指数'!$48:$84,MATCH('面板-总览'!$T17,'面板-景气指数'!$J$48:$J$84,0),MATCH('面板-总览'!AA$2,'面板-景气指数'!$32:$32,0)) -> 0.32883333 | AB17: =INDEX('面板-景气指数'!$48:$84,MATCH('面板-总览'!$T17,'面板-景气指数'!$J$48:$J$84,0),MATCH('面板-总览'!AB$2,'面板-景气指数'!$32:$32,0)) -> 0.45666667 | ... AG17: =INDEX('面板-景气指数'!$48:$84,MATCH('面板-总览'!$T17,'面板-景气指数'!$J$48:$J$84,0),MATCH('面板-总览'!AG$2,'面板-景气指数'!$32:$32,0)) -> 0.359 | AI17: =AG17-AE17 -> -0.1835
T18: 半导体中游 | U18: =INDEX('面板-景气指数'!$48:$84,MATCH('面板-总览'!$T18,'面板-景气指数'!$J$48:$J$84,0),MATCH('面板-总览'!U$2,'面板-景气指数'!$32:$32,0)) -> 0.586 | V18: =INDEX('面板-景气指数'!$48:$84,MATCH('面板-总览'!$T18,'面板-景气指数'!$J$48:$J$84,0),MATCH('面板-总览'!V$2,'面板-景气指数'!$32:$32,0)) -> 0.603 | W18: =INDEX('面板-景气指数'!$48:$84,MATCH('面板-总览'!$T18,'面板-景气指数'!$J$48:$J$84,0),MATCH('面板-总览'!W$2,'面板-景气指数'!$32:$32,0)) -> 0.61872727 | X18: =INDEX('面板-景气指数'!$48:$84,MATCH('面板-总览'!$T18,'面板-景气指数'!$J$48:$J$84,0),MATCH('面板-总览'!X$2,'面板-景气指数'!$32:$32,0)) -> 0.58972727 | Y18: =INDEX('面板-景气指数'!$48:$84,MATCH('面板-总览'!$T18,'面板-景气指数'!$J$48:$J$84,0),MATCH('面板-总览'!Y$2,'面板-景气指数'!$32:$32,0)) -> 0.58854545 | Z18: =INDEX('面板-景气指数'!$48:$84,MATCH('面板-总览'!$T18,'面板-景气指数'!$J$48:$J$84,0),MATCH('面板-总览'!Z$2,'面板-景气指数'!$32:$32,0)) -> 0.59772727 | AA18: =INDEX('面板-景气指数'!$48:$84,MATCH('面板-总览'!$T18,'面板-景气指数'!$J$48:$J$84,0),MATCH('面板-总览'!AA$2,'面板-景气指数'!$32:$32,0)) -> 0.46327273 | AB18: =INDEX('面板-景气指数'!$48:$84,MATCH('面板-总览'!$T18,'面板-景气指数'!$J$48:$J$84,0),MATCH('面板-总览'!AB$2,'面板-景气指数'!$32:$32,0)) -> 0.44481818 | ... AG18: =INDEX('面板-景气指数'!$48:$84,MATCH('面板-总览'!$T18,'面板-景气指数'!$J$48:$J$84,0),MATCH('面板-总览'!AG$2,'面板-景气指数'!$32:$32,0)) -> 0.20536364 | AI18: =AG18-AE18 -> -0.085090909
T19: 数字基建上游 | U19: =INDEX('面板-景气指数'!$48:$84,MATCH('面板-总览'!$T19,'面板-景气指数'!$J$48:$J$84,0),MATCH('面板-总览'!U$2,'面板-景气指数'!$32:$32,0)) -> 0.65182051 | V19: =INDEX('面板-景气指数'!$48:$84,MATCH('面板-总览'!$T19,'面板-景气指数'!$J$48:$J$84,0),MATCH('面板-总览'!V$2,'面板-景气指数'!$32:$32,0)) -> 0.64751282 | W19: =INDEX('面板-景气指数'!$48:$84,MATCH('面板-总览'!$T19,'面板-景气指数'!$J$48:$J$84,0),MATCH('面板-总览'!W$2,'面板-景气指数'!$32:$32,0)) -> 0.66633333 | X19: =INDEX('面板-景气指数'!$48:$84,MATCH('面板-总览'!$T19,'面板-景气指数'!$J$48:$J$84,0),MATCH('面板-总览'!X$2,'面板-景气指数'!$32:$32,0)) -> 0.68838462 | Y19: =INDEX('面板-景气指数'!$48:$84,MATCH('面板-总览'!$T19,'面板-景气指数'!$J$48:$J$84,0),MATCH('面板-总览'!Y$2,'面板-景气指数'!$32:$32,0)) -> 0.67658974 | Z19: =INDEX('面板-景气指数'!$48:$84,MATCH('面板-总览'!$T19,'面板-景气指数'!$J$48:$J$84,0),MATCH('面板-总览'!Z$2,'面板-景气指数'!$32:$32,0)) -> 0.7125641 | AA19: =INDEX('面板-景气指数'!$48:$84,MATCH('面板-总览'!$T19,'面板-景气指数'!$J$48:$J$84,0),MATCH('面板-总览'!AA$2,'面板-景气指数'!$32:$32,0)) -> 0.64548718 | AB19: =INDEX('面板-景气指数'!$48:$84,MATCH('面板-总览'!$T19,'面板-景气指数'!$J$48:$J$84,0),MATCH('面板-总览'!AB$2,'面板-景气指数'!$32:$32,0)) -> 0.67010256 | ... AG19: =INDEX('面板-景气指数'!$48:$84,MATCH('面板-总览'!$T19,'面板-景气指数'!$J$48:$J$84,0),MATCH('面板-总览'!AG$2,'面板-景气指数'!$32:$32,0)) -> 0.33579487 | AI19: =AG19-AE19 -> -0.037871795
T20: 数字基建中游 | U20: =INDEX('面板-景气指数'!$48:$84,MATCH('面板-总览'!$T20,'面板-景气指数'!$J$48:$J$84,0),MATCH('面板-总览'!U$2,'面板-景气指数'!$32:$32,0)) -> 0.52733333 | V20: =INDEX('面板-景气指数'!$48:$84,MATCH('面板-总览'!$T20,'面板-景气指数'!$J$48:$J$84,0),MATCH('面板-总览'!V$2,'面板-景气指数'!$32:$32,0)) -> 0.35066667 | W20: =INDEX('面板-景气指数'!$48:$84,MATCH('面板-总览'!$T20,'面板-景气指数'!$J$48:$J$84,0),MATCH('面板-总览'!W$2,'面板-景气指数'!$32:$32,0)) -> 0.775 | X20: =INDEX('面板-景气指数'!$48:$84,MATCH('面板-总览'!$T20,'面板-景气指数'!$J$48:$J$84,0),MATCH('面板-总览'!X$2,'面板-景气指数'!$32:$32,0)) -> 0.775 | Y20: =INDEX('面板-景气指数'!$48:$84,MATCH('面板-总览'!$T20,'面板-景气指数'!$J$48:$J$84,0),MATCH('面板-总览'!Y$2,'面板-景气指数'!$32:$32,0)) -> 0.81433333 | Z20: =INDEX('面板-景气指数'!$48:$84,MATCH('面板-总览'!$T20,'面板-景气指数'!$J$48:$J$84,0),MATCH('面板-总览'!Z$2,'面板-景气指数'!$32:$32,0)) -> 0.833 | AA20: =INDEX('面板-景气指数'!$48:$84,MATCH('面板-总览'!$T20,'面板-景气指数'!$J$48:$J$84,0),MATCH('面板-总览'!AA$2,'面板-景气指数'!$32:$32,0)) -> 0.755 | AB20: =INDEX('面板-景气指数'!$48:$84,MATCH('面板-总览'!$T20,'面板-景气指数'!$J$48:$J$84,0),MATCH('面板-总览'!AB$2,'面板-景气指数'!$32:$32,0)) -> 0.77433333 | ... AG20: =INDEX('面板-景气指数'!$48:$84,MATCH('面板-总览'!$T20,'面板-景气指数'!$J$48:$J$84,0),MATCH('面板-总览'!AG$2,'面板-景气指数'!$32:$32,0)) -> 0.779 | AI20: =AG20-AE20 -> 0.199
T21: 数字基建下游 | U21: =INDEX('面板-景气指数'!$48:$84,MATCH('面板-总览'!$T21,'面板-景气指数'!$J$48:$J$84,0),MATCH('面板-总览'!U$2,'面板-景气指数'!$32:$32,0)) -> 0.50788889 | V21: =INDEX('面板-景气指数'!$48:$84,MATCH('面板-总览'!$T21,'面板-景气指数'!$J$48:$J$84,0),MATCH('面板-总览'!V$2,'面板-景气指数'!$32:$32,0)) -> 0.50788889 | W21: =INDEX('面板-景气指数'!$48:$84,MATCH('面板-总览'!$T21,'面板-景气指数'!$J$48:$J$84,0),MATCH('面板-总览'!W$2,'面板-景气指数'!$32:$32,0)) -> 0.518 | X21: =INDEX('面板-景气指数'!$48:$84,MATCH('面板-总览'!$T21,'面板-景气指数'!$J$48:$J$84,0),MATCH('面板-总览'!X$2,'面板-景气指数'!$32:$32,0)) -> 0.518 | Y21: =INDEX('面板-景气指数'!$48:$84,MATCH('面板-总览'!$T21,'面板-景气指数'!$J$48:$J$84,0),MATCH('面板-总览'!Y$2,'面板-景气指数'!$32:$32,0)) -> 0.518 | Z21: =INDEX('面板-景气指数'!$48:$84,MATCH('面板-总览'!$T21,'面板-景气指数'!$J$48:$J$84,0),MATCH('面板-总览'!Z$2,'面板-景气指数'!$32:$32,0)) -> 0.52444444 | AA21: =INDEX('面板-景气指数'!$48:$84,MATCH('面板-总览'!$T21,'面板-景气指数'!$J$48:$J$84,0),MATCH('面板-总览'!AA$2,'面板-景气指数'!$32:$32,0)) -> 0.52444444 | AB21: =INDEX('面板-景气指数'!$48:$84,MATCH('面板-总览'!$T21,'面板-景气指数'!$J$48:$J$84,0),MATCH('面板-总览'!AB$2,'面板-景气指数'!$32:$32,0)) -> 0.52444444 | ... AG21: =INDEX('面板-景气指数'!$48:$84,MATCH('面板-总览'!$T21,'面板-景气指数'!$J$48:$J$84,0),MATCH('面板-总览'!AG$2,'面板-景气指数'!$32:$32,0)) -> 0.37544444 | AI21: =AG21-AE21 -> -0.056222222
T22: CXO上游 | U22: =INDEX('面板-景气指数'!$48:$84,MATCH('面板-总览'!$T22,'面板-景气指数'!$J$48:$J$84,0),MATCH('面板-总览'!U$2,'面板-景气指数'!$32:$32,0)) -> 0.3042 | V22: =INDEX('面板-景气指数'!$48:$84,MATCH('面板-总览'!$T22,'面板-景气指数'!$J$48:$J$84,0),MATCH('面板-总览'!V$2,'面板-景气指数'!$32:$32,0)) -> 0.2864 | W22: =INDEX('面板-景气指数'!$48:$84,MATCH('面板-总览'!$T22,'面板-景气指数'!$J$48:$J$84,0),MATCH('面板-总览'!W$2,'面板-景气指数'!$32:$32,0)) -> 0.3904 | X22: =INDEX('面板-景气指数'!$48:$84,MATCH('面板-总览'!$T22,'面板-景气指数'!$J$48:$J$84,0),MATCH('面板-总览'!X$2,'面板-景气指数'!$32:$32,0)) -> 0.503 | Y22: =INDEX('面板-景气指数'!$48:$84,MATCH('面板-总览'!$T22,'面板-景气指数'!$J$48:$J$84,0),MATCH('面板-总览'!Y$2,'面板-景气指数'!$32:$32,0)) -> 0.6752 | Z22: =INDEX('面板-景气指数'!$48:$84,MATCH('面板-总览'!$T22,'面板-景气指数'!$J$48:$J$84,0),MATCH('面板-总览'!Z$2,'面板-景气指数'!$32:$32,0)) -> 0.649 | AA22: =INDEX('面板-景气指数'!$48:$84,MATCH('面板-总览'!$T22,'面板-景气指数'!$J$48:$J$84,0),MATCH('面板-总览'!AA$2,'面板-景气指数'!$32:$32,0)) -> 0.3434 | AB22: =INDEX('面板-景气指数'!$48:$84,MATCH('面板-总览'!$T22,'面板-景气指数'!$J$48:$J$84,0),MATCH('面板-总览'!AB$2,'面板-景气指数'!$32:$32,0)) -> 0.2372 | ... AG22: =INDEX('面板-景气指数'!$48:$84,MATCH('面板-总览'!$T22,'面板-景气指数'!$J$48:$J$84,0),MATCH('面板-总览'!AG$2,'面板-景气指数'!$32:$32,0)) -> 0.822 | AI22: =AG22-AE22 -> 0.078
T23: CXO中游 | U23: =INDEX('面板-景气指数'!$48:$84,MATCH('面板-总览'!$T23,'面板-景气指数'!$J$48:$J$84,0),MATCH('面板-总览'!U$2,'面板-景气指数'!$32:$32,0)) -> 0.65133333 | V23: =INDEX('面板-景气指数'!$48:$84,MATCH('面板-总览'!$T23,'面板-景气指数'!$J$48:$J$84,0),MATCH('面板-总览'!V$2,'面板-景气指数'!$32:$32,0)) -> 0.65133333 | W23: =INDEX('面板-景气指数'!$48:$84,MATCH('面板-总览'!$T23,'面板-景气指数'!$J$48:$J$84,0),MATCH('面板-总览'!W$2,'面板-景气指数'!$32:$32,0)) -> 0.66633333 | X23: =INDEX('面板-景气指数'!$48:$84,MATCH('面板-总览'!$T23,'面板-景气指数'!$J$48:$J$84,0),MATCH('面板-总览'!X$2,'面板-景气指数'!$32:$32,0)) -> 0.66633333 | Y23: =INDEX('面板-景气指数'!$48:$84,MATCH('面板-总览'!$T23,'面板-景气指数'!$J$48:$J$84,0),MATCH('面板-总览'!Y$2,'面板-景气指数'!$32:$32,0)) -> 0.66633333 | Z23: =INDEX('面板-景气指数'!$48:$84,MATCH('面板-总览'!$T23,'面板-景气指数'!$J$48:$J$84,0),MATCH('面板-总览'!Z$2,'面板-景气指数'!$32:$32,0)) -> 0.67633333 | AA23: =INDEX('面板-景气指数'!$48:$84,MATCH('面板-总览'!$T23,'面板-景气指数'!$J$48:$J$84,0),MATCH('面板-总览'!AA$2,'面板-景气指数'!$32:$32,0)) -> 0.67633333 | AB23: =INDEX('面板-景气指数'!$48:$84,MATCH('面板-总览'!$T23,'面板-景气指数'!$J$48:$J$84,0),MATCH('面板-总览'!AB$2,'面板-景气指数'!$32:$32,0)) -> 0.67633333 | ... AG23: =INDEX('面板-景气指数'!$48:$84,MATCH('面板-总览'!$T23,'面板-景气指数'!$J$48:$J$84,0),MATCH('面板-总览'!AG$2,'面板-景气指数'!$32:$32,0)) -> 0.62633333 | AI23: =AG23-AE23 -> -0.0053333333
T24: 智能汽车上游 | U24: =INDEX('面板-景气指数'!$48:$84,MATCH('面板-总览'!$T24,'面板-景气指数'!$J$48:$J$84,0),MATCH('面板-总览'!U$2,'面板-景气指数'!$32:$32,0)) -> 0.44925 | V24: =INDEX('面板-景气指数'!$48:$84,MATCH('面板-总览'!$T24,'面板-景气指数'!$J$48:$J$84,0),MATCH('面板-总览'!V$2,'面板-景气指数'!$32:$32,0)) -> 0.45875 | W24: =INDEX('面板-景气指数'!$48:$84,MATCH('面板-总览'!$T24,'面板-景气指数'!$J$48:$J$84,0),MATCH('面板-总览'!W$2,'面板-景气指数'!$32:$32,0)) -> 0.44575 | X24: =INDEX('面板-景气指数'!$48:$84,MATCH('面板-总览'!$T24,'面板-景气指数'!$J$48:$J$84,0),MATCH('面板-总览'!X$2,'面板-景气指数'!$32:$32,0)) -> 0.4695 | Y24: =INDEX('面板-景气指数'!$48:$84,MATCH('面板-总览'!$T24,'面板-景气指数'!$J$48:$J$84,0),MATCH('面板-总览'!Y$2,'面板-景气指数'!$32:$32,0)) -> 0.5085 | Z24: =INDEX('面板-景气指数'!$48:$84,MATCH('面板-总览'!$T24,'面板-景气指数'!$J$48:$J$84,0),MATCH('面板-总览'!Z$2,'面板-景气指数'!$32:$32,0)) -> 0.51475 | AA24: =INDEX('面板-景气指数'!$48:$84,MATCH('面板-总览'!$T24,'面板-景气指数'!$J$48:$J$84,0),MATCH('面板-总览'!AA$2,'面板-景气指数'!$32:$32,0)) -> 0.472 | AB24: =INDEX('面板-景气指数'!$48:$84,MATCH('面板-总览'!$T24,'面板-景气指数'!$J$48:$J$84,0),MATCH('面板-总览'!AB$2,'面板-景气指数'!$32:$32,0)) -> 0.50175 | ... AG24: =INDEX('面板-景气指数'!$48:$84,MATCH('面板-总览'!$T24,'面板-景气指数'!$J$48:$J$84,0),MATCH('面板-总览'!AG$2,'面板-景气指数'!$32:$32,0)) -> 0.56625 | AI24: =AG24-AE24 -> 0.08075
T25: 智能汽车中游 | U25: =INDEX('面板-景气指数'!$48:$84,MATCH('面板-总览'!$T25,'面板-景气指数'!$J$48:$J$84,0),MATCH('面板-总览'!U$2,'面板-景气指数'!$32:$32,0)) -> 0.41118182 | V25: =INDEX('面板-景气指数'!$48:$84,MATCH('面板-总览'!$T25,'面板-景气指数'!$J$48:$J$84,0),MATCH('面板-总览'!V$2,'面板-景气指数'!$32:$32,0)) -> 0.43536364 | W25: =INDEX('面板-景气指数'!$48:$84,MATCH('面板-总览'!$T25,'面板-景气指数'!$J$48:$J$84,0),MATCH('面板-总览'!W$2,'面板-景气指数'!$32:$32,0)) -> 0.56127273 | X25: =INDEX('面板-景气指数'!$48:$84,MATCH('面板-总览'!$T25,'面板-景气指数'!$J$48:$J$84,0),MATCH('面板-总览'!X$2,'面板-景气指数'!$32:$32,0)) -> 0.62863636 | Y25: =INDEX('面板-景气指数'!$48:$84,MATCH('面板-总览'!$T25,'面板-景气指数'!$J$48:$J$84,0),MATCH('面板-总览'!Y$2,'面板-景气指数'!$32:$32,0)) -> 0.66172727 | Z25: =INDEX('面板-景气指数'!$48:$84,MATCH('面板-总览'!$T25,'面板-景气指数'!$J$48:$J$84,0),MATCH('面板-总览'!Z$2,'面板-景气指数'!$32:$32,0)) -> 0.59745455 | AA25: =INDEX('面板-景气指数'!$48:$84,MATCH('面板-总览'!$T25,'面板-景气指数'!$J$48:$J$84,0),MATCH('面板-总览'!AA$2,'面板-景气指数'!$32:$32,0)) -> 0.33863636 | AB25: =INDEX('面板-景气指数'!$48:$84,MATCH('面板-总览'!$T25,'面板-景气指数'!$J$48:$J$84,0),MATCH('面板-总览'!AB$2,'面板-景气指数'!$32:$32,0)) -> 0.21154545 | ... AG25: =INDEX('面板-景气指数'!$48:$84,MATCH('面板-总览'!$T25,'面板-景气指数'!$J$48:$J$84,0),MATCH('面板-总览'!AG$2,'面板-景气指数'!$32:$32,0)) -> 0.37472727 | AI25: =AG25-AE25 -> -0.090818182
T26: 智能汽车下游 | U26: =INDEX('面板-景气指数'!$48:$84,MATCH('面板-总览'!$T26,'面板-景气指数'!$J$48:$J$84,0),MATCH('面板-总览'!U$2,'面板-景气指数'!$32:$32,0)) -> 0.363 | V26: =INDEX('面板-景气指数'!$48:$84,MATCH('面板-总览'!$T26,'面板-景气指数'!$J$48:$J$84,0),MATCH('面板-总览'!V$2,'面板-景气指数'!$32:$32,0)) -> 0.575 | W26: =INDEX('面板-景气指数'!$48:$84,MATCH('面板-总览'!$T26,'面板-景气指数'!$J$48:$J$84,0),MATCH('面板-总览'!W$2,'面板-景气指数'!$32:$32,0)) -> 0.424 | X26: =INDEX('面板-景气指数'!$48:$84,MATCH('面板-总览'!$T26,'面板-景气指数'!$J$48:$J$84,0),MATCH('面板-总览'!X$2,'面板-景气指数'!$32:$32,0)) -> 0.151 | Y26: =INDEX('面板-景气指数'!$48:$84,MATCH('面板-总览'!$T26,'面板-景气指数'!$J$48:$J$84,0),MATCH('面板-总览'!Y$2,'面板-景气指数'!$32:$32,0)) -> 0.09 | Z26: =INDEX('面板-景气指数'!$48:$84,MATCH('面板-总览'!$T26,'面板-景气指数'!$J$48:$J$84,0),MATCH('面板-总览'!Z$2,'面板-景气指数'!$32:$32,0)) -> 0.121 | AA26: =INDEX('面板-景气指数'!$48:$84,MATCH('面板-总览'!$T26,'面板-景气指数'!$J$48:$J$84,0),MATCH('面板-总览'!AA$2,'面板-景气指数'!$32:$32,0)) -> 0.03 | AB26: =INDEX('面板-景气指数'!$48:$84,MATCH('面板-总览'!$T26,'面板-景气指数'!$J$48:$J$84,0),MATCH('面板-总览'!AB$2,'面板-景气指数'!$32:$32,0)) -> 0 | ... AG26: =INDEX('面板-景气指数'!$48:$84,MATCH('面板-总览'!$T26,'面板-景气指数'!$J$48:$J$84,0),MATCH('面板-总览'!AG$2,'面板-景气指数'!$32:$32,0)) -> 0.515 | AI26: =AG26-AE26 -> 0.182
