Workbook

Sheet 目录
A1: 华泰电新－维科技术数据库目录
C4: 华泰电新研究团队
C5: 联系人：申建国/陈爽19514630775
B7: 1 | C7: 业绩相关 | D7: 业绩汇总 | E7: 业绩拆分
B8: 2 | C8: 行业相关 | D8: 行业概况&方案对比 | E8: 行业空间 | F8: 材料环节情况及布局
B9: 2 | C9: 财务信息 | D9: 公司简介 | E9: 年度财务数据 | F9: 季度财务数据 | G9: 费用分析 | H9: 资本开支 | I9: 股权激励
B10: 3 | C10: 其他信息 | D10: 人事 | E10: 参股公司 | F10: 客户与供应商

Sheet 1.1业绩汇总
A1: 华泰电新－业绩拆分
A4: 单位：百万元 | G4: 预测-假设数据
A5: 纺织业务 | B5: 2017年 | C5: 2018年 | D5: 2019年 | E5: 2020年 | F5: 2021年 | G5: 2022E | H5: 2023E | I5: 2024E
A6: 收入 | B6: ='1.2业绩拆分'!B7 -> 368.10171 | C6: ='1.2业绩拆分'!C7 -> 261.05578
A7: YOY | C7: ='1.2业绩拆分'!C8 -> -0.2908053
A8: 成本 | B8: ='1.2业绩拆分'!B9 -> 307.71567 | C8: ='1.2业绩拆分'!C9 -> 205.94779
A9: 毛利 | B9: ='1.2业绩拆分'!B10 -> 60.386036 | C9: ='1.2业绩拆分'!C10 -> 55.10799
A10: 毛利率（%） | B10: ='1.2业绩拆分'!B11 -> 0.16404715 | C10: ='1.2业绩拆分'!C11 -> 0.21109661
A11: 聚合物类电池 | B11: 2017年 | C11: 2018年 | D11: 2019年 | E11: 2020年 | F11: 2021年 | G11: 2022E | H11: 2023E | I11: 2024E
A12: 收入 | B12: ='1.2业绩拆分'!B14 -> 855.1663 | C12: ='1.2业绩拆分'!C14 -> 870.29286 | D12: ='1.2业绩拆分'!D14 -> 907.40549 | E12: ='1.2业绩拆分'!E14 -> 1018.0323 | F12: ='1.2业绩拆分'!F14 -> 1377.3243 | G12: ='1.2业绩拆分'!G14 -> 1652.7891 | H12: ='1.2业绩拆分'!H14 -> 2479.1837 | I12: ='1.2业绩拆分'!I14 -> 2851.0612
A13: YOY | B13: ='1.2业绩拆分'!B15 -> -0.1199 | C13: ='1.2业绩拆分'!C15 -> 0.017688446 | D13: ='1.2业绩拆分'!D15 -> 0.042643845 | E13: ='1.2业绩拆分'!E15 -> 0.12191549 | F13: ='1.2业绩拆分'!F15 -> 0.35292787 | G13: ='1.2业绩拆分'!G15 -> 0.2 | H13: ='1.2业绩拆分'!H15 -> 0.5 | I13: ='1.2业绩拆分'!I15 -> 0.15
A14: 成本 | B14: ='1.2业绩拆分'!B16 -> 910.71166 | C14: ='1.2业绩拆分'!C16 -> 758.05756 | D14: ='1.2业绩拆分'!D16 -> 787.79836 | E14: ='1.2业绩拆分'!E16 -> 822.77126 | F14: ='1.2业绩拆分'!F16 -> 1180.2485 | G14: ='1.2业绩拆分'!G16 -> 1487.5102 | H14: ='1.2业绩拆分'!H16 -> 2107.3061 | I14: ='1.2业绩拆分'!I16 -> 2423.402
A15: 毛利 | B15: ='1.2业绩拆分'!B17 -> -55.545364 | C15: ='1.2业绩拆分'!C17 -> 112.2353 | D15: ='1.2业绩拆分'!D17 -> 119.60714 | E15: ='1.2业绩拆分'!E17 -> 195.26102 | F15: ='1.2业绩拆分'!F17 -> 197.07574 | G15: ='1.2业绩拆分'!G17 -> 165.27891 | H15: ='1.2业绩拆分'!H17 -> 371.87755 | I15: ='1.2业绩拆分'!I17 -> 427.65918
A16: 毛利率（%） | B16: ='1.2业绩拆分'!B18 -> -0.064952705 | C16: ='1.2业绩拆分'!C18 -> 0.12896268 | D16: ='1.2业绩拆分'!D18 -> 0.13181222 | E16: ='1.2业绩拆分'!E18 -> 0.19180239 | F16: ='1.2业绩拆分'!F18 -> 0.14308594 | G16: ='1.2业绩拆分'!G18 -> 0.1 | H16: ='1.2业绩拆分'!H18 -> 0.15 | I16: ='1.2业绩拆分'!I18 -> 0.15
A17: 铝壳电池 | B17: 2017年 | C17: 2018年 | D17: 2019年 | E17: 2020年 | F17: 2021年 | G17: 2022E | H17: 2023E | I17: 2024E
A18: 收入 | B18: ='1.2业绩拆分'!B25 -> 244.94238 | C18: ='1.2业绩拆分'!C25 -> 255.54095 | D18: ='1.2业绩拆分'!D25 -> 278.48122 | E18: ='1.2业绩拆分'!E25 -> 184.35147 | F18: ='1.2业绩拆分'!F25 -> 186.3351 | G18: ='1.2业绩拆分'!G25 -> 251.55239 | H18: ='1.2业绩拆分'!H25 -> 377.32858 | I18: ='1.2业绩拆分'!I25 -> 433.92787
A19: YOY | B19: ='1.2业绩拆分'!B26 -> 0.0129 | C19: ='1.2业绩拆分'!C26 -> 0.043269629 | D19: ='1.2业绩拆分'!D26 -> 0.08977142 | E19: ='1.2业绩拆分'!E26 -> -0.33801113 | F19: ='1.2业绩拆分'!F26 -> 0.010760055 | G19: ='1.2业绩拆分'!G26 -> 0.35 | H19: ='1.2业绩拆分'!H26 -> 0.5 | I19: ='1.2业绩拆分'!I26 -> 0.15
A20: 成本 | B20: ='1.2业绩拆分'!B27 -> 254.94993 | C20: ='1.2业绩拆分'!C27 -> 234.23834 | D20: ='1.2业绩拆分'!D27 -> 228.82622 | E20: ='1.2业绩拆分'!E27 -> 178.79846 | F20: ='1.2业绩拆分'!F27 -> 171.23338 | G20: ='1.2业绩拆分'!G27 -> 231.4282 | H20: ='1.2业绩拆分'!H27 -> 347.1423 | I20: ='1.2业绩拆分'!I27 -> 399.21364
A21: 毛利 | B21: ='1.2业绩拆分'!B28 -> -10.007546 | C21: ='1.2业绩拆分'!C28 -> 21.302615 | D21: ='1.2业绩拆分'!D28 -> 49.655002 | E21: ='1.2业绩拆分'!E28 -> 5.553008 | F21: ='1.2业绩拆分'!F28 -> 15.101724 | G21: ='1.2业绩拆分'!G28 -> 20.124191 | H21: ='1.2业绩拆分'!H28 -> 30.186287 | I21: ='1.2业绩拆分'!I28 -> 34.71423
A22: 毛利率（%） | B22: ='1.2业绩拆分'!B29 -> -0.040856735 | C22: ='1.2业绩拆分'!C29 -> 0.083362823 | D22: ='1.2业绩拆分'!D29 -> 0.17830646 | E22: ='1.2业绩拆分'!E29 -> 0.030121854 | F22: ='1.2业绩拆分'!F29 -> 0.08104605 | G22: ='1.2业绩拆分'!G29 -> 0.08 | H22: ='1.2业绩拆分'!H29 -> 0.08 | I22: ='1.2业绩拆分'!I29 -> 0.08
A23: 小动力电池 | B23: 2017年 | C23: 2018年 | D23: 2019年 | E23: 2020年 | F23: 2021年 | G23: 2022E | H23: 2023E | I23: 2024E
A24: 收入 | B24: ='1.2业绩拆分'!B36 -> 6.843832 | C24: ='1.2业绩拆分'!C36 -> 32.403003 | D24: ='1.2业绩拆分'!D36 -> 350.32363 | E24: ='1.2业绩拆分'!E36 -> 310.54286 | F24: ='1.2业绩拆分'!F36 -> 357.14899 | G24: ='1.2业绩拆分'!G36 -> 589.29584 | H24: ='1.2业绩拆分'!H36 -> 972.33814 | I24: ='1.2业绩拆分'!I36 -> 1166.8058
A25: YOY | B25: ='1.2业绩拆分'!B37 -> -0.9606 | C25: ='1.2业绩拆分'!C37 -> 3.7346286 | D25: ='1.2业绩拆分'!D37 -> 9.8114556 | E25: ='1.2业绩拆分'!E37 -> -0.11355434 | F25: ='1.2业绩拆分'!F37 -> 0.15007956 | G25: ='1.2业绩拆分'!G37 -> 0.65 | H25: ='1.2业绩拆分'!H37 -> 0.65 | I25: ='1.2业绩拆分'!I37 -> 0.2
A26: 成本 | B26: ='1.2业绩拆分'!B38 -> 7.949091 | C26: ='1.2业绩拆分'!C38 -> 41.093003 | D26: ='1.2业绩拆分'!D38 -> 322.83485 | E26: ='1.2业绩拆分'!E38 -> 239.29145 | F26: ='1.2业绩拆分'!F38 -> 350.49385 | G26: ='1.2业绩拆分'!G38 -> 536.25921 | H26: ='1.2业绩拆分'!H38 -> 826.48742 | I26: ='1.2业绩拆分'!I38 -> 991.7849
A27: 毛利 | B27: ='1.2业绩拆分'!B39 -> -1.105259 | C27: ='1.2业绩拆分'!C39 -> -8.69 | D27: ='1.2业绩拆分'!D39 -> 27.488781 | E27: ='1.2业绩拆分'!E39 -> 71.251405 | F27: ='1.2业绩拆分'!F39 -> 6.65514 | G27: ='1.2业绩拆分'!G39 -> 53.036626 | H27: ='1.2业绩拆分'!H39 -> 145.85072 | I27: ='1.2业绩拆分'!I39 -> 175.02086
A28: 毛利率（%） | B28: ='1.2业绩拆分'!B40 -> -0.1614971 | C28: ='1.2业绩拆分'!C40 -> -0.26818502 | D28: ='1.2业绩拆分'!D40 -> 0.07846682 | E28: ='1.2业绩拆分'!E40 -> 0.22944145 | F28: ='1.2业绩拆分'!F40 -> 0.018634072 | G28: ='1.2业绩拆分'!G40 -> 0.09 | H28: ='1.2业绩拆分'!H40 -> 0.15 | I28: ='1.2业绩拆分'!I40 -> 0.15
A29: 其他业务 | B29: 2017年 | C29: 2018年 | D29: 2019年 | E29: 2020年 | F29: 2021年 | G29: 2022E | H29: 2023E | I29: 2024E
A30: 收入 | B30: =B42-B24-B18-B12-B6 -> 122.16578 | C30: =C42-C24-C18-C12-C6 -> 183.38741 | D30: =D42-D24-D18-D12-D6 -> 108.78965 | E30: =E42-E24-E18-E12-E6 -> 232.05339 | F30: =F42-F24-F18-F12-F6 -> 154.63165 | G30: =F30*(1+G31) -> 170.09482 | H30: =G30*(1+H31) -> 187.1043 | I30: =H30*(1+I31) -> 205.81473
A31: YOY | C31: =C30/B30-1 -> 0.50113566 | D31: =D30/C30-1 -> -0.40677686 | E31: =E30/D30-1 -> 1.1330465 | F31: =F30/E30-1 -> -0.33363761 | G31: 0.1 | H31: 0.1 | I31: 0.1
A32: 成本 | B32: 89.81 | C32: =C44-C26-C20-C14-C8 -> 135.69331 | D32: =D44-D26-D20-D14-D8 -> 75.760573 | E32: =E44-E26-E20-E14-E8 -> 189.69882 | F32: =F44-F26-F20-F14-F8 -> 116.72425 | G32: =G30-G33 -> 110.56163 | H32: =H30-H33 -> 121.61779 | I32: =I30-I33 -> 133.77957
A33: 毛利 | B33: =B30-B32 -> 32.355778 | C33: =C30-C32 -> 47.694093 | D33: =D30-D32 -> 33.02908 | E33: =E30-E32 -> 42.354564 | F33: =F30-F32 -> 37.907399 | G33: =G30*G34 -> 59.533186 | H33: =H30*H34 -> 65.486504 | I33: =I30*I34 -> 72.035155
A34: 毛利率（%） | B34: =B33/B30 -> 0.26485141 | C34: =C33/C30 -> 0.26007289 | D34: =D33/D30 -> 0.30360498 | E34: =E33/E30 -> 0.18252077 | F34: =F33/F30 -> 0.24514644 | G34: 0.35 | H34: 0.35 | I34: 0.35
A35: 钠离子电池业务 | B35: 2017年 | C35: 2018年 | D35: 2019年 | E35: 2020年 | F35: 2021年 | G35: 2022E | H35: 2023E | I35: 2024E
A36: 收入 | H36: ='1.2业绩拆分'!H47 -> 936 | I36: ='1.2业绩拆分'!I47 -> 5360
A37: YOY | I37: ='1.2业绩拆分'!I48 -> 4.7264957
A38: 成本 | H38: ='1.2业绩拆分'!H51 -> 720.72 | I38: ='1.2业绩拆分'!I51 -> 4020
A39: 毛利 | H39: ='1.2业绩拆分'!H53 -> 215.28 | I39: ='1.2业绩拆分'!I53 -> 1340
A40: 毛利率（%） | H40: ='1.2业绩拆分'!H55 -> 0.23 | I40: ='1.2业绩拆分'!I55 -> 0.25
B41: 2017年 | C41: 2018年 | D41: 2019年 | E41: 2020年 | F41: 2021年 | G41: 2022E | H41: 2023E | I41: 2024E
A42: 营业收入 | B42: =利润表!B4 -> 1597.22 | C42: =利润表!C4 -> 1602.68 | D42: =利润表!D4 -> 1645 | E42: =利润表!E4 -> 1744.98 | F42: =利润表!F4 -> 2075.44 | G42: =G6+G12+G18+G24+G36+G30 -> 2663.7321 | H42: =H6+H12+H18+H24+H36+H30 -> 4951.9547 | I42: =I6+I12+I18+I24+I36+I30 -> 10017.61
...

Sheet 1.2业绩拆分
A1: 华泰电新-业务拆分
A4: 单位：百万元,万支
A6: 纺织业务 | B6: 2017 | C6: 2018
A7: 营业收入 | B7: 368.10171 | C7: 261.05578
A8: YOY | C8: =C7/B7-1 -> -0.2908053
A9: 营业成本 | B9: 307.71567 | C9: 205.94779 | D9: 备注：2019年报告期內纺织业务完成剥离
A10: 毛利 | B10: =B7-B9 -> 60.386036 | C10: =C7-C9 -> 55.10799
A11: 毛利率 | B11: =B10/B7 -> 0.16404715 | C11: =C10/C7 -> 0.21109661 | G11: =G14+G25+G36 -> 2493.6373 | H11: =H14+H25+H36 -> 3828.8504 | I11: =I14+I25+I36 -> 4451.7948
G12: 预测-假设数据 | K12: 能源业务成本分析 | L12: 2017 | M12: 2018 | N12: 2019 | O12: 2020 | P12: 2021 | Q12: 2022E | R12: 2023E | S12: 2024E
A13: 聚合物电池 | B13: 2017 | C13: 2018 | D13: 2019 | E13: 2020 | F13: 2021 | G13: 2022E | H13: 2023E | I13: 2024E | K13: 聚合物电池成本分析 | L13: 2019 | M13: 2020 | N13: 2021 | O13: 2022E | P13: 2023E | Q13: 2024E
A14: 营业收入 | B14: 855.1663 | C14: 870.29286 | D14: 907.40549 | E14: 1018.0323 | F14: 1377.3243 | G14: =F14*(1+G15) -> 1652.7891 | H14: =G14*(1+H15) -> 2479.1837 | I14: =H14*(1+I15) -> 2851.0612 | K14: 材料 | L14: 868.448 | M14: 711.5444 | N14: 919.59536
A15: YOY | B15: -0.1199 | C15: =C14/B14-1 -> 0.017688446 | D15: =D14/C14-1 -> 0.042643845 | E15: =E14/D14-1 -> 0.12191549 | F15: =F14/E14-1 -> 0.35292787 | G15: 0.2 | H15: 0.5 | I15: 0.15 | K15: 人工 | L15: 139.15823 | M15: 159.52928 | N15: 182.13959
A16: 营业成本 | B16: 910.71166 | C16: 758.05756 | D16: 787.79836 | E16: 822.77126 | F16: 1180.2485 | G16: =G14-G17 -> 1487.5102 | H16: =H14-H17 -> 2107.3061 | I16: =I14-I17 -> 2423.402 | K16: 折旧 | L16: 32.722192 | M16: 41.209576 | N16: 50.572958
A17: 毛利 | B17: =B14-B16 -> -55.545364 | C17: =C14-C16 -> 112.2353 | D17: =D14-D16 -> 119.60714 | E17: =E14-E16 -> 195.26102 | F17: =F14-F16 -> 197.07574 | G17: =G14*G18 -> 165.27891 | H17: =H14*H18 -> 371.87755 | I17: =I14*I18 -> 427.65918 | K17: 能源 | L17: 29.822473 | M17: 33.193128 | N17: 39.195107
A18: 毛利率 | B18: =B17/B14 -> -0.064952705 | C18: =C17/C14 -> 0.12896268 | D18: =D17/D14 -> 0.13181222 | E18: =E17/E14 -> 0.19180239 | F18: =F17/F14 -> 0.14308594 | G18: 0.1 | H18: 0.15 | I18: 0.15 | K18: 制造 | L18: 51.728412 | M18: 63.750816 | N18: 111.62873
A19: 产量 | C19: 4297.85 | D19: 5927.17 | E19: 6351.85 | F19: 6830.99 | K19: 合计 | L19: 1121.9393 | M19: =SUM(M14:M18) -> 1009.2272 | N19: =SUM(N14:N18) -> 1303.1318
A20: YOY | C20: - | D20: =D19/C19-1 -> 0.37910118 | E20: =E19/D19-1 -> 0.071649708 | F20: =F19/E19-1 -> 0.075433142
A21: 销量 | C21: 4439.5 | D21: 5428.62 | E21: 6042.67 | F21: 6768.22
A22: YOY | C22: - | D22: =D21/C21-1 -> 0.22279986 | E22: =E21/D21-1 -> 0.11311346 | F22: =F21/E21-1 -> 0.12007109
A24: 铝壳电池 | B24: 2017 | C24: 2018 | D24: 2019 | E24: 2020 | F24: 2021 | G24: 2022E | H24: 2023E | I24: 2024E | K24: 铝壳电池成本分析 | L24: 2019 | M24: 2020 | N24: 2021 | O24: 2022E | P24: 2023E | Q24: 2024E
A25: 营业收入 | B25: 244.94238 | C25: 255.54095 | D25: 278.48122 | E25: 184.35147 | F25: 186.3351 | G25: =F25*(1+G26) -> 251.55239 | H25: =G25*(1+H26) -> 377.32858 | I25: =H25*(1+I26) -> 433.92787 | K25: 材料 | L25: 288.32949 | M25: 127.60137 | N25: 119.11377
A26: YOY | B26: 0.0129 | C26: =C25/B25-1 -> 0.043269629 | D26: =D25/C25-1 -> 0.08977142 | E26: =E25/D25-1 -> -0.33801113 | F26: =F25/E25-1 -> 0.010760055 | G26: 0.35 | H26: 0.5 | I26: 0.15 | K26: 人工 | L26: 36.532148 | M26: 35.836196 | N26: 36.449249
A27: 营业成本 | B27: 254.94993 | C27: 234.23834 | D27: 228.82622 | E27: 178.79846 | F27: 171.23338 | G27: =G25-G28 -> 231.4282 | H27: =H25-H28 -> 347.1423 | I27: =I25-I28 -> 399.21364 | K27: 折旧 | L27: 6.631432 | M27: 7.11759 | N27: 8.228717
A28: 毛利 | B28: =B25-B27 -> -10.007546 | C28: =C25-C27 -> 21.302615 | D28: =D25-D27 -> 49.655002 | E28: =E25-E27 -> 5.553008 | F28: =F25-F27 -> 15.101724 | G28: =G25*G29 -> 20.124191 | H28: =H25*H29 -> 30.186287 | I28: =I25*I29 -> 34.71423 | K28: 能源 | L28: 8.377614 | M28: 9.499653 | N28: 9.887825
A29: 毛利率 | B29: =B28/B25 -> -0.040856735 | C29: =C28/C25 -> 0.083362823 | D29: =D28/D25 -> 0.17830646 | E29: =E28/E25 -> 0.030121854 | F29: =F28/F25 -> 0.08104605 | G29: 0.08 | H29: 0.08 | I29: 0.08 | K29: 制造 | L29: 14.017121 | M29: 11.109457 | N29: 15.047315
A30: 产量 | C30: 2386.92 | D30: 2715.13 | E30: 2429.55 | F30: 2051.58 | K30: 合计 | L30: 293.88781 | M30: =SUM(M25:M29) -> 191.16427 | N30: =SUM(N25:N29) -> 188.72687
A31: YOY | C31: - | D31: =D30/C30-1 -> 0.13750356 | E31: =E30/D30-1 -> -0.10518097 | F31: =F30/E30-1 -> -0.15557202
A32: 销量 | C32: 2418.07 | D32: 2628.2 | E32: 2393.68 | F32: 2051.58
A33: YOY | C33: - | D33: =D32/C32-1 -> 0.086899883 | E33: =E32/D32-1 -> -0.089232174 | F33: =F32/E32-1 -> -0.14291802
A35: 小动力电池 | B35: 2017 | C35: 2018 | D35: 2019 | E35: 2020 | F35: 2021 | G35: 2022E | H35: 2023E | I35: 2024E | K35: 小动力电池成本分析 | L35: 2019 | M35: 2020 | N35: 2021 | O35: 2022E | P35: 2023E | Q35: 2024E
A36: 营业收入 | B36: 6.843832 | C36: 32.403003 | D36: 350.32363 | E36: 310.54286 | F36: 357.14899 | G36: =F36*(1+G37) -> 589.29584 | H36: =G36*(1+H37) -> 972.33814 | I36: =H36*(1+I37) -> 1166.8058 | K36: 材料 | L36: 65.052594 | M36: 104.45213 | N36: 206.96821
A37: YOY | B37: -0.9606 | C37: =C36/B36-1 -> 3.7346286 | D37: =D36/C36-1 -> 9.8114556 | E37: =E36/D36-1 -> -0.11355434 | F37: =F36/E36-1 -> 0.15007956 | G37: 0.65 | H37: 0.65 | I37: 0.2 | K37: 人工 | L37: 5.128603 | M37: 6.758478 | N37: 14.394039
A38: 营业成本 | B38: 7.949091 | C38: 41.093003 | D38: 322.83485 | E38: 239.29145 | F38: 350.49385 | G38: =G36-G39 -> 536.25921 | H38: =H36-H39 -> 826.48742 | I38: =I36-I39 -> 991.7849 | K38: 折旧 | L38: 0.243191 | M38: 1.617277 | N38: 4.348534
A39: 毛利 | B39: =B36-B38 -> -1.105259 | C39: =C36-C38 -> -8.69 | D39: =D36-D38 -> 27.488781 | E39: =E36-E38 -> 71.251405 | F39: =F36-F38 -> 6.65514 | G39: =G36*G40 -> 53.036626 | H39: =H36*H40 -> 145.85072 | I39: =I36*I40 -> 175.02086 | K39: 能源 | L39: 0.29639 | M39: 0.445213 | N39: 0.865163
A40: 毛利率 | B40: =B39/B36 -> -0.1614971 | C40: =C39/C36 -> -0.26818502 | D40: =D39/D36 -> 0.07846682 | E40: =E39/E36 -> 0.22944145 | F40: =F39/F36 -> 0.018634072 | G40: 0.09 | H40: 0.15 | I40: 0.15 | K40: 制造 | L40: 2.320928 | M40: 5.301721 | N40: 7.134121
A41: 产量 | C41: 87.826026 | D41: 619.01 | E41: 1067.47 | F41: 1585.14 | K41: 合计 | L41: 73.041707 | M41: =SUM(M36:M40) -> 118.57482 | N41: =SUM(N36:N40) -> 233.71007
A42: YOY | C42: - | D42: =D41/C41-1 -> 6.0481385 | E42: =E41/D41-1 -> 0.72447941 | F42: =F41/E41-1 -> 0.4849504
A43: 销量 | C43: 86.120037 | D43: 600.36 | E43: 957.51 | F43: 1426.76
A44: YOY | C44: - | D44: =D43/C43-1 -> 5.9712 | E44: =E43/D43-1 -> 0.59489306 | F44: =F43/E43-1 -> 0.49007321
A46: 钠离子电池 | B46: 2017 | C46: 2018 | D46: 2019 | E46: 2020 | F46: 2021 | G46: 2022E | H46: 2023E | I46: 2024E
...

Sheet 利润表
A1: 维科技术[600152.SH] - 利润表 (单位 : 百万元 , CNY ) | B1: 2017-12-31 | C1: 2018-12-31 | D1: 2019-12-31 | E1: 2020-12-31 | F1: 2021-12-31 | G1: 2022-06-30
A2: 报告期 | B2: 年报 | C2: 年报 | D2: 年报 | E2: 年报 | F2: 年报 | G2: 中报
A3: 报表类型 | B3: 合并报表 | C3: 合并报表 | D3: 合并报表 | E3: 合并报表 | F3: 合并报表 | G3: 合并报表
A4: 营业总收入 | B4: 1597.22 | C4: 1602.68 | D4: 1645 | E4: 1744.98 | F4: 2075.44 | G4: 1183.58
A5: 营业收入 | B5: 1597.22 | C5: 1602.68 | D5: 1645 | E5: 1744.98 | F5: 2075.44 | G5: 1183.58
A6: 其他类金融业务收入
A7: 营业总成本 | B7: 1685.77 | C7: 1736.28 | D7: 1675.05 | E7: 1674.27 | F7: 2142.87 | G7: 1162.38
A8: 营业成本 | B8: 1309.66 | C8: 1375.03 | D8: 1415.22 | E8: 1430.56 | F8: 1818.7 | G8: 1063.34
A9: 税金及附加 | B9: 15.84 | C9: 17.66 | D9: 10.77 | E9: 14.11 | F9: 11.98 | G9: 4.11
A10: 销售费用 | B10: 55.8 | C10: 52.09 | D10: 38.4 | E10: 34.61 | F10: 50.57 | G10: 15.55
A11: 管理费用 | B11: 177.79 | C11: 136.9 | D11: 130.05 | E11: 97.39 | F11: 136.7 | G11: 40.23
A12: 研发费用 | C12: 63.98 | D12: 68.53 | E12: 84.53 | F12: 101.47 | G12: 36.7
A13: 财务费用 | B13: 17.59 | C13: 7.99 | D13: 12.08 | E13: 13.07 | F13: 23.46 | G13: 2.45
A14: 其中：利息费用 | C14: 19.63 | D14: 15.33 | E14: 11.2 | F14: 27.25 | G14: 13.69
A15: 减：利息收入 | C15: 7.1 | D15: 2.09 | E15: 3.84 | F15: 6.59 | G15: 3.82
A16: 其他业务成本(金融类)
A17: 加：其他收益 | B17: 14.65 | C17: 21.14 | D17: 12.88 | E17: 22.04 | F17: 25.77 | G17: 12.68
A18: 投资净收益 | B18: 89.17 | C18: 70 | D18: 23.13 | E18: 8.38 | F18: -15.73 | G18: -16.59
A19: 其中：对联营企业和合营企业的投资收益 | B19: 3.6 | C19: -0.16 | D19: -1.17 | E19: -5.35 | F19: -24.2 | G19: -22.63
A20: 以摊余成本计量的金融资产终止确认收益
A21: 净敞口套期收益
A22: 公允价值变动净收益 | D22: -11.61 | E22: -5.13 | F22: 15.85 | G22: 1.05
A23: 资产减值损失 | B23: 109.08 | C23: 82.63 | D23: -32.05 | E23: -8.12 | F23: -30.38 | G23: -15.37
A24: 信用减值损失 | D24: -22.57 | E24: -63.73 | F24: -25.85 | G24: -1.29
A25: 资产处置收益 | B25: -2.11 | C25: 108.5 | D25: -6.32 | E25: 23.42 | F25: -10.32 | G25: 0.42
A26: 汇兑净收益
A27: 加：营业利润差额(特殊报表科目)
A28: 营业利润差额(合计平衡项目)
A29: 营业利润 | B29: 13.17 | C29: 66.04 | D29: -66.58 | E29: 47.56 | F29: -108.08 | G29: 2.1
A30: 加：营业外收入 | B30: 4.45 | C30: 2.21 | D30: 4.88 | E30: 13.12 | F30: 2.3 | G30: 0.38
A31: 减：营业外支出 | B31: 1.05 | C31: 1.81 | D31: 9.46 | E31: 13 | F31: 10.84 | G31: 0.37
A32: 其中：非流动资产处置净损失
A33: 加：利润总额差额(特殊报表科目)
A34: 利润总额差额(合计平衡项目)
A35: 利润总额 | B35: 16.58 | C35: 66.44 | D35: -71.16 | E35: 47.68 | F35: -116.62 | G35: 2.1
A36: 减：所得税 | B36: 6.36 | C36: 10.03 | D36: -6.77 | E36: -0.52 | F36: 12.39 | G36: -4.96
A37: 加：未确认的投资损失
A38: 加：净利润差额(特殊报表科目)
A39: 净利润差额(合计平衡项目)
A40: 净利润 | B40: 10.22 | C40: 56.41 | D40: -64.39 | E40: 48.2 | F40: -129.01 | G40: 7.06
...

Sheet 2.1 概况&方案对比
A1: 华泰电新－行业概况&方案对比
A5: 产业链
A23: 钠电池与锂电、铅酸电池对比
B24: 铅酸电池 | C24: 钠离子电池 （铜基氧化物/煤基碳体系） | D24: 锂离子电池 （磷酸铁锂/石墨体系）
A25: 能量密度（Wh/kg） | B25: 30-50 | C25: 100-150 | D25: 120-180
A26: 循环寿命（次） | B26: 300-500 | C26: 2000次以上 | D26: 3000次以上
A27: 工作电压（V） | B27: 2 | C27: 3.2 | D27: 3.2
A28: -20℃容量保持率 | B28: 小于60% | C28: 88%以上 | D28: 小于70%
A29: 耐过放电 | B29: 差 | C29: 可放电至0V | D29: 差
A30: 安全性 | B30: 优 | C30: 有潜力达到最优 | D30: 优
A31: 环保性 | B31: 差 | C31: 最优 | D31: 优
A32: 自放电率（每月） | B32: 0.05 | C32: 0.05 | D32: 0.3
A35: 钠电池与液流、铅酸电池对比
B36: 钠离子电池 | C36: 全钒液流电池 | D36: 铅酸蓄电池
A37: 工作原理 | B37: 利用钠离子在正负极之间嵌脱过程实现充放电的摇椅式二次电池 | C37: 以钒为活性物质呈循环流动液态的氧化还原电池 | D37: 利用阳极(PbO2)，阴极(Pb)在电解液(稀硫酸)中的电势差实现充放电的二次电池
A38: 优点 | B38: 1.能量密度70-200Wh/kg；2.高低温性能好，-20℃容量保持率>88%；3.钠离子电池相关金属资源丰富 | C38: 1.设计灵活，功率和容积可以独立设计构思；2.充、放电性能好，可深度放电而不损坏电池，循环寿命长,适用于长时储能；3.安全性高，活性物质存在于电解液中，无爆炸、短路风险 | D38: 1..成本低，价格低廉；2.储存性能好，电压稳定；3.安全性高；4.铅回收的产业链完善
A39: 缺点 | B39: 1.循环次数目前相对较低，远期可能高；2.目前产业链还不够完整,成本较高 | C39: 1.能量密度低，仅为锂电的1/10，占地面积大；2.成本高仍处在示范到商业化前期，集装箱方舱形态钒电池价格在3元/Wh左右；3.能量损耗较高，能量损失在25%-30%左右；4.电池系统复杂，有管道、泵、阀、换热器等辅助部件，核心零部件隔膜和泵有待突破；5. 要求温和的温度环境，工作温度5-40℃ | D39: 1.能量密度低,只有30-50Wh/kg；2.使用寿命短300-500次；3.低温性能差-20℃放电保持率＜60%；4.环保差，对环境腐蚀性强
A41: 钠离子电池与现有电池体系特性对比
A59: 钠电池与锂电池成本对比
B60: 正极材料 | C60: 负极材料 | D60: 电解液 | E60: 隔膜 | F60: 集流体 | G60: 其他
A61: 钠离子电池成本 | B61: 0.26 | C61: 0.16 | D61: 0.26 | E61: 0.18 | F61: 0.04 | G61: 0.1 | H61: 0.7
A62: 锂离子电池成本 | B62: 0.43 | C62: 0.11 | D62: 0.15 | E62: 0.13 | F62: 0.13 | G62: 0.05 | H62: 1
A63: 钠离子电池成本 | B63: 0.182 | C63: 0.112 | D63: 0.182 | E63: 0.126 | F63: 0.028 | G63: 0.07 | H63: 0.7
A64: 锂离子电池成本 | B64: 0.43 | C64: 0.11 | D64: 0.15 | E64: 0.13 | F64: 0.13 | G64: 0.05 | H64: 1

Sheet 2.2 行业空间
A1: 华泰电新－行业空间
A5: 钠离子电池市场空间：2027年国内市场将达到582亿元
B6: 2021 | C6: 2022E | D6: 2023E | E6: 2024E | F6: 2025E | G6: 2026E | H6: 2027E
A7: 低能量密度电动乘用车
A8: 中国乘用车销量（万辆） | B8: 2627.5 | C8: 2837.7 | D8: 2985 | E8: 3075 | F8: 3136 | G8: 3198.7 | H8: 3262.7
A9: 新能源车渗透率 | B9: 0.148 | C9: 0.22 | D9: 0.23 | E9: 0.24 | F9: 0.25 | G9: 0.26 | H9: 0.27
A10: 磷酸铁锂占比 | B10: 0.6 | C10: 0.57 | D10: 0.54 | E10: 0.51 | F10: 0.5 | G10: 0.5 | H10: 0.5
A11: 平均单车带电（KWh） | B11: 39 | C11: 41 | D11: 43 | E11: 44 | F11: 45 | G11: 46 | H11: 47
A12: 总带电量（GWh） | B12: 91 | C12: 145.9 | D12: 159.4 | E12: 165.6 | F12: 176.4 | G12: 191.3 | H12: 207
A13: 钠电池渗透率 | F13: 0.01 | G13: 0.03 | H13: 0.05
A14: 钠电池装机量（GWh） | F14: 1.8 | G14: 5.7 | H14: 10.4
A15: 单价（元/Wh） | F15: 0.5 | G15: 0.5 | H15: 0.5
A16: 钠电池对应市场空间（亿元） | F16: 8.8 | G16: 28.7 | H16: 51.8
A17: 电动两轮车
A18: 国内电动两轮车销量（万辆） | B18: 4100 | C18: 4510 | D18: 4961 | E18: 5457.1 | F18: 6002.8 | G18: 6603.1 | H18: 7263.4
A19: 平均单车带电（KWh） | B19: 0.72 | C19: 0.72 | D19: 0.72 | E19: 0.72 | F19: 0.72 | G19: 0.72 | H19: 0.72
A20: 总带电量（GWh） | B20: 29.5 | C20: 32.5 | D20: 35.7 | E20: 39.3 | F20: 43.2 | G20: 47.5 | H20: 52.3
A21: 钠电池渗透率 | C21: 0.01 | D21: 0.03 | E21: 0.05 | F21: 0.15 | G21: 0.3 | H21: 0.5
A22: 钠电池装机量（GWh） | C22: 0.3 | D22: 1.1 | E22: 2 | F22: 6.5 | G22: 14.3 | H22: 26.1
A23: 单价（元/Wh） | C23: 0.8 | D23: 0.7 | E23: 0.6 | F23: 0.5 | G23: 0.5 | H23: 0.5
A24: 钠电池对应市场空间（亿元） | C24: 2.6 | D24: 7.5 | E24: 11.8 | F24: 32.4 | G24: 71.3 | H24: 130.7
A25: 储能电池
A26: 风光配储电池需求（GWh） | B26: 22.8 | C26: 21.8 | D26: 26.7 | E26: 36 | F26: 52.1 | G26: 75.6 | H26: 109.6
A27: 电网侧和用户侧储能电池需求（GWh） | B27: 1.23 | C27: 1.82 | D27: 2.61 | E27: 3.84 | F27: 5.74 | G27: 8.61 | H27: 12.915
A28: 5G基站储能需求（GWh） | B28: 7 | C28: 6 | D28: 8 | E28: 11 | F28: 15 | G28: 21 | H28: 29.4
A29: 储能总需求量（GWh） | B29: 31 | C29: 29.6 | D29: 37.3 | E29: 50.8 | F29: 72.9 | G29: 105.2 | H29: 151.9
A30: 钠电池渗透率 | C30: 0.01 | D30: 0.03 | E30: 0.05 | F30: 0.15 | G30: 0.3 | H30: 0.45
A31: 钠电池装机量（GWh） | C31: 0.3 | D31: 1.1 | E31: 2.5 | F31: 10.9 | G31: 31.6 | H31: 68.3
A32: 单价（元/Wh） | C32: 0.8 | D32: 0.7 | E32: 0.6 | F32: 0.5 | G32: 0.5 | H32: 0.5
A33: 钠电池对应市场空间（亿元） | C33: 2.4 | D33: 7.8 | E33: 15.2 | F33: 54.6 | G33: 157.8 | H33: 341.7
A34: 电动工具
A35: 电动工具装机量（GWh） | B35: 22 | C35: 24.2 | D35: 26.6 | E35: 29.3 | F35: 32.2 | G35: 35.4 | H35: 39
A36: 钠电池渗透率 | D36: 0.01 | E36: 0.03 | F36: 0.05 | G36: 0.15 | H36: 0.3
A37: 钠电池装机量（GWh） | D37: 0.27 | E37: 0.88 | F37: 1.61 | G37: 5.31 | H37: 11.69
A38: 单价（元/Wh） | D38: 0.7 | E38: 0.6 | F38: 0.5 | G38: 0.5 | H38: 0.5
A39: 钠电池对应市场空间（亿元） | D39: 1.9 | E39: 5.3 | F39: 8.1 | G39: 26.6 | H39: 58.5
A40: 总计 | C40: 5 | D40: 17.2 | E40: 32.3 | F40: 103.9 | G40: 284.3 | H40: 582.7

Sheet 2.3 材料环节情况及布局
A1: 华泰电新－材料环节情况及布局
A5: 结构构成
A6: 部件 | B6: 材料 | C6: 说明
A7: 正极 | B7: 钠过渡金属氧化物 | C7: 可分为层状和隧道状过渡金属氧化物，通常用NaxMO2(M=Co、Fe、Mn 和 Ni 等)表示。层状金属氧化物是当前主流的正极材料
B10: 聚阴离子类化合物 | C10: 聚阴离子类化合物NaxMy[(XOm)n-]z(M为具有可变价态的金属离子；X 为 P、S 和 V 等元素)主要分为：橄榄石结构磷酸盐、NASCICON(钠离子快离子导体)化合物和磷酸盐化合物
B14: 普鲁士蓝类似物（PBA） | C14: 普鲁士蓝类化合物 NaxMA[MB(CN)6]·zH2O(MA 和MB 为过渡金属离子)，晶体结构为面心立方，过渡金属离子与氰化根形成六配位，碱金属离子处于三维通道结构和配位孔隙中
B18: 非晶态材料 | C18: 也叫无定形或玻璃态材料，是固体中的原子不按照一定的空间顺序排列的固体，原子排布上表现为长程无序、短程有序
A21: 负极 | B21: 硬碳或软性无定形碳，合金 类（Sn、Sb 等）、过渡金属氧化物（Na0.66Li0.22Ti0.78O2 等）、钠-过渡金属磷酸盐 （NaTiOPO4）等 | C21: 高能量密度钠离子电池负极材料中，无定型碳材料（包括软碳、硬碳）是目前最有希望走向商业化的，其可逆容量和循环性能均已接近应用要求，但主要瓶颈在于成本较高。基于此，目前开发的无烟煤基无定型碳材料是性价比最高的钠离子电池负极材料
A27: 电解液 | B27: 溶质为六氟磷酸钠 | C27: 由于 Na 和 Al 在低电位不会发生合金化反应，钠离子电池正极和负极的集流体都可使用廉价的铝箔，同等容量的钠离子电池中 Al 集流体成本是锂离子电池 Al 和 Cu 集流体的 1/3
A31: 隔膜 | B31: 与锂电池相同 | C31: —
A32: 集流体 | B32: 铝箔 | C32: 成本比锂电池中的铜箔成本更低
A33: 资料来源：《钠离子电池正极材料的研究现状》
A36: 钠离子电池与锂离子电池最大的区别在于正极材料。
A37: 钠离子电池正极材料主要路线
A38: 材料 | B38: 说明 | C38: 代表企业 | D38: 优势 | E38: 劣势
A39: 过渡金属氧化物 | B39: 可分为层状和隧道状过渡金属氧化物，通常用NaxMO2（M=Co、Fe、Mn和Ni等）表示，层状金属氧化物是当前主流的正极材料 | C39: 宁德时代、中科海钠、钠创新能源、传艺科技 | D39: 能量密度高 | E39: 循环性能差
A40: 普鲁士蓝类似物 | B40: 普鲁士蓝类化合物NaxMA[MB(CN)6]zH2O（MA和MB为过渡金属离子），晶体结构为面心立方，过渡金属离子与氰化根形成六配位，碱金属离子处于三位通道结构和配位孔隙中 | C40: 宁德时代、钠创新能源 | D40: 较好的电化学性能，成本低，稳定性好 | E40: 生产对水敏感
A41: 聚阴离子类化合物 | B41: 聚阴离子类化合物NaxMy[(XOm)n-]z（M为具有可变价态的金属离子；X为P、S和V等元素）主要分为橄榄石结构磷酸盐、NASCICON（钠离子快离子导体）化合物和磷酸盐化合物 | C41: 鹏辉能源、众钠能源 | D41: 热稳定性好，循环寿命好 | E41: 能量密度低，导电性差
A42: 非晶态材料 | B42: 也叫无定形或玻璃态材料，是固体中的原子不按照一定的空间顺序排列的固体，原子排不上表现为长程无序，短程有序 | D42: 循环性能好，能量密度好 | E42: 电导率低，稳定性和耐酸碱性差
A44: 钠离子电池正极企业布局情况
A45: 公司名称 | B45: 正极技术路线 | C45: 布局情况 | D45: 产品性能情况
A46: 容百科技 | B46: 锰铁普鲁士白、层状氧化物体系、聚阴离子体系均有布局 | C46: 规划2023年层状氧化物正极材料产能3.6万吨/年；2025年规划10万吨；普鲁士白供货宁德时代 | D46: 能量密度:>110Wh/kg；循环次数:> 6000次；倍率性能: 优于3C
A47: 振华新材 | B47: 层状金属氧化物体系 | C47: 钠离子电池正极材料处于吨级送样阶段，生产线与现有三元材料兼容，深度合作宁德时代 | D47: 能量密度: 120-130Wh/kg；循环次数:2-4k次；温和放电倍率0.2-0.3C
A48: 湖南邦普 | B48: 未披露 | C48: 已进入磷酸铁锂生产线改产钠离子电池中试产线环评阶段(年产钠电正极600吨)建成后该产线可切换生产磷酸铁 | D48: 未披露
A49: 中伟股份 | B49: 未披露 | C49: 钠系前驱有2-3家客户，今年产量能达到千吨级，预计2023年上半年实现批量供货 | D49: 未披露
A50: 格林美 | B50: 层状金属氧化物体系、普鲁士蓝体系 | C50: 拥有钠离子电池补钠的方法、钠离子电池及其制备方法等多项专利；在普鲁士蓝和层状氧化物等钠离子电池材料两大技术路线均已积累了相关产业技术并和多家下游客户正在认证 | D50: 未披露
A51: 圣阳股份 | B51: 普鲁士白 | C51: 开发高环保、高循环性钠离子电池，已通过实验阶段；收购星空钠电 | D51: 能量密度达160Wh/kg；常温下充电15分钟，电量可达80%以上；在-20℃低温环境中，拥有90%以上的放电保持率；系统集成效率达80%以上
A55: 钠离子电池负极技术路线
A56: 材料 | C56: 性质
A57: 碳基材料 | B57: 软碳 | C57: 嵌钠平台低、容量高、循环寿命长、制备简单等突出优势，硬碳具有高可逆比容量、低电压等突出优势，软碳具有缺陷少、结晶度高、电导率高等特点
B58: 硬碳
A59: 金属化合物 | C59: 成本低、具有较高的比容量和钠储存电势而有潜力作为钠离子电池的阳极材料，其反应机理主要是可逆的氧化还原反应，但金属氧化物自身导电性较差以及在循环过程中会产生体积膨胀, 通常导致电极材料表现出较差的循环稳定性和倍率性能
A60: 合金材料 | C60: 具有较高的比容量、良好的导电性，可在过充电后防止产生枝晶，延长了钠离子电池的使用寿命，为了减轻体积膨胀，提高合金阳极的性能，人们主要集中于材料纳米化、引入碳基体复合、优化粘结剂和电解质添加剂等方面来进行研究
A61: 非金属单质 | C61: 与碳同族的元素，磷和硅成为近年兴起的方向，研究成熟度还不高。其中黑磷有皱褶的层状结构，高导电等特点，但制备较难
A63: 钠离子电池负极企业布局情况
A64: 公司名称 | B64: 负极技术路线 | C64: 布局情况
A65: 贝特瑞 | B65: 软碳 、硬碳均有 | C65: 已有量产硬碳、软碳
A66: 紫宸科技 | B66: 硬碳为主 | C66: 已积极进行钠离子电池产业的相关研发和布局工作
A67: 杉杉股份 | B67: 硬碳为主 | C67: 2021年在钠离子电池硬碳方面也已向相关电池企业进行了百公斤级的供货
A68: 中科电气 | B68: 硬碳 | C68: 新型碳材料硬碳正在研发中
...

Sheet 3.1公司简介
A1: 华泰电新－公司简介
A5: 公司基本信息介绍
A6: 维科技术股份有限公司，成立于1993年7月28日，旗下拥有17家子公司。公司曾是以纺织为主业，地产开发、资本投资、能源新材料综合发展的大型企业集团上市公司，2019年业务期内完成纺织业务剥离。2017 年，公司通过重大资产重组，直接及间接方式合计持有维科电池100%的股权，并直接持有维科新能源100%的股权，公司主营业务转为锂电池制造业务，维科技术锂电池业务以3C数码电池为核心、积极拓展动力和储能电池市场。维科电池是国内排名前五的3C数码电池供应商，客户包括国内主流手机品牌、欧美主要通讯运营商等，并大量应用于笔记本电脑、平板电脑、教育电脑、个人穿戴等电子产品，被评为浙江省名牌产品。维科动力电池以维科电池十余年的锂电池生产技术为依托，可生产软包动力电池、铝壳动力电池等电芯产品，应用领域覆盖特种车辆电池、家电用电池、储能电池等。
A8: 发展历程
A9: 时间 | B9: 发展历程
A10: 1993年-2003年 | B10: 1993年公司由宁波线带集团公司独家发起成立并于1998年6月29日在上海证券交易所挂牌交易，股票代码600152。1999年维科集团收购4025.96万股国家股成为第一大股东，2000年公司更名为维科精华。期间公司主营业务为纺织业务，建立自有品牌并多年实现盈利。
A11: 2003年-2018年 | B11: 2003年公司与宁波维科集团股份有限公司共同出资成立宁波维科能源科技投资有限公司。并于2004年出资成立宁波维科电池有限公司，正式进军锂电池生产业务，开始向新能源电池业务转型。2005年4月首只产品线建成，首批1万只电池产品下线。其后公司于2006年-2011年逐步扩大铝壳电池产能，达到20万只/日。2012年公司成功开拓聚合物电池生产业务，2013年成立宁波第一家院士工作站。2015年公司重新淘汰整合一部分铝壳电池产能并扩大聚合物电池产能。2016年公司开启动力电池项目建设。2018年公司完全剥离纺织业务，并设立东莞维科电池有限公本公司，开拓华南市场业务。
A12: 2019年-至今 | B12: 2019年10月与LG化学公司开辟南昌建设项目，12月宁波维科电池有限公司上榜工信部第四批符合《锂离子电池行业规范条件》企业名单。
A14: 主要产品
A15: 序号 | B15: 产品名称 | C15: 产品简介 | D15: 性能参数或应用场景 | E15: 主要应用情况或客户
A16: 1 | B16: 720Wh/L高能量密度手机电池 | C16: 使用维科自主研发的第三代高能量密度比体系，产品能量密度达720Wh/L，较上一代产品提升了8%，处于行业领先水平。 | D16: 额定容量：4050mAh 电压平台：3.85，充电截止电压4.4V 最大充电电流：0.7C 最大放电电流：1.0C 倍率性能：1.0C放电时间≥54min 循环寿命：0.5C/0.5C,循环500次，容量保持率≧80% 高温性能：55度1.0C放电时间≧51min | E16: 应用在A客户的高端智能手机中。
A17: 2 | B17: 700Wh/L高能量密度手机电池 | C17: 使用维科技术第三代LiCoO2高能量密度体系，能量密度700Wh/L。高温性能优异，同时满足1.2C阶梯快充。 | D17: 额定容量：4120mAh 电压平台：3.85V 最大充电电流：0.7C 最大放电电流：1.0C 倍率性能：1.0C放电时间大于等于54min 循环寿命：0.7C/0.7C,循环500次，容量保持率≥80%，厚度膨胀率≤8% 高温性能：55℃，1.0C放电时间≥51min | E17: 此产品应用于B公司高端智能手机上。
A18: 3 | B18: 680Wh/L高能量密度快充电池 | C18: 使用维科快充体系，能量密度达680Wh/L, 支持1.3C直充； 30分钟充电60%以上电量。 | D18: 额定容量：4050mAh 电压平台：3.85V 最大充电电流：1.3C 最大放电电流：1.0C 循环寿命：0.5C/0.5C,循环500次，容量保持率≥80%，厚度膨胀率≤8% 高温性能：55℃，1.0C放电时间≥51min | E18: 此产品应用于C客户的快充智能手机上。
A19: 4 | B19: 670Wh/L高能量密度平板和笔记本电池 | C19: 笔记本电池主要出口海外客户，能量密度达到670Wh/L,循环寿命为1000次。容量、电压、内阻一致性高。且支持1.0C阶梯快充。 | D19: 额定容量：4210mAh 电压平台：3.85，充电截止电压4.4V 最大充电电流：0.7C 最大放电电流：1.0C 倍率性能：1.0C放电时间大于等于54min 循环寿命：0.5C/0.5C,循环1000次，容量保持率>=60% 高温性能：55度1.0C放电时间>=51min | E19: 此产品应用于H客户笔记本电池上。
A20: 5 | B20: 低速车&叉车（23Kwh低速车锂电池组、6Kwh低速车锂电池组、2.6Kwh清洁车锂电池组、960wh保洁车锂电池组） | C20: 锂离子电动叉车电动系统及低速车电动系统动力输出强，可接受快速充电与大电流放电，一致性好；锂电池配置独立的管理系统，无需维护，环保节能；具有长寿命、高效率、可快充、免维护、无污染的特点。 | D20: 维科叉车及低速车电池系统主要应用在电动叉车、电动低速电动车动力系统上；主要是为整车提供充足的动力，满足整车对于经济性、动力性、安全性、舒适性等要求。每一套电池PACK中都有一套完整的BMS。实现对锂电池的智能管理，过充保护、过放保护、短路保护、过压保护、负载保护、高温保护、过功率保护。 | E20: 广州白云清洁、广州京成轩保洁车、广州朗晴电动车、华信三轮车、宁波海迈克动力有限公司、山东特朗斯新能源有限公司、苏州新欣电动车等客户。
A21: 6 | B21: AGV（1.4Kwh AGV小车锂电池包） | C21: AGV锂离子动力系统具有高寿命，轻质量，能适应浅充浅放和深度循环2种工作环境,配备专用接插件，可提供485、232、CAN口各类通讯功能。可按要求定制，容量50-300AH，三元和铁锂各类AGV动力系统成熟设计方案。 | D21: 维科AGV动力系统主要应用在AGV智能搬运系统。 | E21: 主要客户有杭州同筑、浙江国自机器人有限公司等
A22: 7 | B22: 工业机器人电池 | C22: 机器人锂电池是专为移动机器测仪设计的高效、便携、轻便、充足的大容量锂电池组，机器人监测仪启动瞬间电流要求较大，对电池连续工作时间要求较高。 | D22: 应用于电动机器人，主要从事维护保养、修理、运输、清洗、保安、救援、监护等工作。 | E22: 苏州爱普电器、北京臻迪机器人、浙江国自机器人有限公司、北京猎户星空等。
A23: 8 | B23: 储能（691wh路灯储能锂电池、电池组） | C23: 使用业界成熟的三元18650 2200mAh/2600mAh电芯。电池模块能够串联和并联使用以满足电压和容量的要求。电池模块的热管理机制和电池管理系统提供高度的安全性。每一个电池模块包含了专用的和集成化的电池管理系统，有效的监控电压、电流、温度，SOC，电芯的均衡。 | D23: 可应用场景不间断电源 (UPS)，社区储能系统 (CES)集装箱储能系统，并网储能系统，离网储能系统，微网系统。 | E23: -
A24: 9 | B24: 电动自行车电池（161wh助力自行车锂电池组、236wh助力自行车平衡车锂电池组、智能头盔锂电池组） | C24: 助力自行车锂离子电池组具有高寿命，轻质量，能适应浅充浅放和深度循环的工作模式,配备专用接插件，可提供485、232通讯功能。可按要求定制，能提供功率100-350W，容量2-20AH，三元材料成熟设计方案。 | D24: - | E24: 绿康车业、麦思动力、名泰机械制造有限公司、金华雅玛珈电动车、金华绿骑士等。
A25: 10 | B25: 吸尘器电池（162wh吸尘器锂电池组、360wh吸尘器锂电池组、移动冰箱锂电池组） | C25: 电动智能吸尘器的刷子是用来提高吸尘器效率的，与吸口及垃圾盒是两个独立的单元。吸尘器的电机转速非常高，一般超过13000转，因此电池采用环保锂离子电池组。 | D25: 可应用于家用智能吸尘器以及扫地机器人等智能家居电器中。 | E25: 苏州爱普电器等。
A27: 核心竞争力
A28: 生产优势 | B28: 公司以自动化生产线和数据化生产追溯系统为支撑，公司智能化生产水平较高。同时，公司具有先进的生产管理理念，实现项目开发、原料检验、生产工序的可追溯、无缝隙品质管控体系，保障了生产体系的高效运转。此外，公司强大的设计研发能力、稳定可靠的原材料供应体系、良好的生产协调能力、灵活的生产组织管理体系，实现了锂离子电池业务从锂电芯业务向锂电池封装业务延伸，有效缩短了多批次产品转线生产的切换时间，增强了对各类订单的承接能力，使公司能够快速响应客户需求，根据订单快速组织生产并及时交货，并有效降低公司的整体生产成本。
A29: 产品优势 | B29: 公司产品生产过程严格遵循国家标准，产品本身质量过硬，公司锂电池产品技术指标均符合国标要求，并且与目前国内锂电池第一梯队厂商水平相当，在研的锂电芯最高能量密度达到750Wh/L，处于国内行业前列。
A30: 研发优势 | B30: 公司拥有国家级示范院士专家工作站、国家CNAS实验室、省级工程技术中心等科研平台以及广东省高安全性高能量密度锂离子电池工程技术研究开发中心，并和中国科学院材料所、上海纳米技术及应用国家工程研究中心、中国科学技术大学等国内著名科研院所建立了密切的技术合作关系。截至2021年12月31日，公司共拥有专利165项，其中发明专利42项、实用新型专利117项、外观设计专利6项。公司目前的研发方向主要为高能量密度及快充类锂电池，已完成750Wh/L高能量密度锂电池和720Wh/L高能量密度锂电池快充的研发，并实现小批量中试，处于行业前列水平。
A31: 客户优势 | B31: 目前公司已进入TCL、飞毛腿、传音、神基科技、中兴、海信等知名下游客户的供应商名单，产品广泛应用于各类产品线。目前，公司正在推动国内外一线智能终端产品品牌厂商审核，有望进入一流消费类锂离子电池产品市场，完善公司在消费类锂离子产品领域中的战略定位与布局。此外，公司也在拓展智能穿戴设备、智能家居、POS机、门铃、无人机等新兴消费电子产品市场和两轮自动车、吸尘器、电动工具等小动力锂电池以及家用储能系统领域，并与爱玛电动车、哈喽换电、大疆、小米生态链等客户建立了合作关系。
A32: 人才优势 | B32: 在管理人才方面，公司拥有一支经验丰富、稳定高效的职业经理人团队。同时公司不断完善用人机制，通过绩效奖金、专项奖金以及限制性股票激励等方面构建了长中短期相结合的激励体系，以制度留住和培养人才。公司分管业务的总经理、生产副总经理均有生产管理经验超过10年。在技术人才方面，截至2021年12月31日，公司研发人员共计610名。研发团队成员专业背景涵盖材料化学、电化学、化学工程以及机械设计等领域，人员结构合理、分工明确并具有丰富的研发经验。

Sheet 3.2 年度财务数据
A1: 华泰电新－年度财务数据
A5: 600152.SH | B5: 注：1.减值损失2019年符号变化
A6: =[7]!s_info_name(A5) -> 维科技术 | B6: 43100 | C6: 43465 | D6: 43830 | E6: 44196 | F6: 44561
A7: 单位：亿元 | B7: 2017年 | C7: 2018年 | D7: 2019年 | E7: 2020年 | F7: 2021年
A8: 主要财务数据
A9: 营业总收入 | B9: =[7]!s_stm07_is($A$5,"W16498900",B6,1,1)/100000000 -> 15.97221 | C9: =[7]!s_stm07_is($A$5,"W16498900",C6,1,1)/100000000 -> 16.026789 | D9: =[7]!s_stm07_is($A$5,"W16498900",D6,1,1)/100000000 -> 16.450011 | E9: =[7]!s_stm07_is($A$5,"W16498900",E6,1,1)/100000000 -> 17.449795 | F9: =[7]!s_stm07_is($A$5,"W16498900",F6,1,1)/100000000 -> 20.754382
A10: YoY | C10: =(C9-B9)/B9 -> 0.0034171771 | D10: =(D9-C9)/C9 -> 0.026407147 | E10: =(E9-D9)/D9 -> 0.060777099 | F10: =(F9-E9)/E9 -> 0.18937683
A11: 归母利润 | B11: =[7]!s_stm07_is($A$5,"W16602333",B6,1)/100000000 -> 0.16628209 | C11: =[7]!s_stm07_is($A$5,"W16602333",C6,1)/100000000 -> 0.54579586 | D11: =[7]!s_stm07_is($A$5,"W16602333",D6,1)/100000000 -> -0.64080937 | E11: =[7]!s_stm07_is($A$5,"W16602333",E6,1)/100000000 -> 0.49142739 | F11: =[7]!s_stm07_is($A$5,"W16602333",F6,1)/100000000 -> -1.2717628
A12: YoY | C12: =(C11-B11)/B11 -> 2.282349 | D12: =(D11-C11)/C11 -> -2.1740825 | E12: =(E11-D11)/D11 -> -1.7668855 | F12: =(F11-E11)/E11 -> -3.5878957
A13: 非经常性损益 | B13: =B11-B14 -> 1.0343592 | C13: =C11-C14 -> 2.1741021 | D13: =D11-D14 -> 0.11863217 | E13: =E11-E14 -> 1.1256988 | F13: =F11-F14 -> 0.33985546
A14: 扣非利润 | B14: =[7]!s_fa_deductedprofit($A$5,B6,1)/100000000 -> -0.86807714 | C14: =[7]!s_fa_deductedprofit($A$5,C6,1)/100000000 -> -1.6283062 | D14: =[7]!s_fa_deductedprofit($A$5,D6,1)/100000000 -> -0.75944154 | E14: =[7]!s_fa_deductedprofit($A$5,E6,1)/100000000 -> -0.63427141 | F14: =[7]!s_fa_deductedprofit($A$5,F6,1)/100000000 -> -1.6116183
A15: YoY | C15: =(C14-B14)/B14 -> 0.87576215 | D15: =(D14-C14)/C14 -> -0.5336003 | E15: =(E14-D14)/D14 -> -0.16481864 | F15: =(F14-E14)/E14 -> 1.5408969
A16: 经营活动现金净流量 | B16: =[7]!s_fa_operatecashflow_ttm2($A$5,B6,1)/100000000 -> -0.55406861 | C16: =[7]!s_fa_operatecashflow_ttm2($A$5,C6,1)/100000000 -> -0.17225793 | D16: =[7]!s_fa_operatecashflow_ttm2($A$5,D6,1)/100000000 -> -0.60375775 | E16: =[7]!s_fa_operatecashflow_ttm2($A$5,E6,1)/100000000 -> 0.29606383 | F16: =[7]!s_fa_operatecashflow_ttm2($A$5,F6,1)/100000000 -> -2.3577236
A17: YoY | C17: =(C16-B16)/B16 -> -0.68910362 | D17: =(D16-C16)/C16 -> 2.5049635 | E17: =(E16-D16)/D16 -> -1.4903686 | F17: =(F16-E16)/E16 -> -8.9635653
A18: 经营活动现金净流量/归母净利润(%) | B18: =[7]!s_fa_netprofitcashcover($A$5,B6) -> -333.21003 | C18: =[7]!s_fa_netprofitcashcover($A$5,C6) -> -31.560871 | D18: =[7]!s_fa_netprofitcashcover($A$5,D6) -> 94.217997 | E18: =[7]!s_fa_netprofitcashcover($A$5,E6) -> 60.245691 | F18: =[7]!s_fa_netprofitcashcover($A$5,F6) -> 185.3902
A20: 盈利能力
A21: ROE(摊薄)(%) | B21: =[7]!s_fa_roe_diluted($A$5,B6) -> 1.182 | C21: =[7]!s_fa_roe_diluted($A$5,C6) -> 3.9035 | D21: =[7]!s_fa_roe_diluted($A$5,D6) -> -4.7133 | E21: =[7]!s_fa_roe_diluted($A$5,E6) -> 3.4533 | F21: =[7]!s_fa_roe_diluted($A$5,F6) -> -6.4041
A22: ROE(扣非摊薄)(%) | B22: =[7]!s_fa_roe_exdiluted($A5,B6) -> -6.1709 | C22: =[7]!s_fa_roe_exdiluted($A5,C6) -> -11.6456 | D22: =[7]!s_fa_roe_exdiluted($A5,D6) -> -5.5859 | E22: =[7]!s_fa_roe_exdiluted($A5,E6) -> -4.457 | F22: =[7]!s_fa_roe_exdiluted($A5,F6) -> -8.1155
A23: 综合毛利率（%） | B23: =[7]!S_FA_GROSSPROFITMARGIN($A$5,B6) -> 18.004 | C23: =[7]!S_FA_GROSSPROFITMARGIN($A$5,C6) -> 14.2041 | D23: =[7]!S_FA_GROSSPROFITMARGIN($A$5,D6) -> 13.9683 | E23: =[7]!S_FA_GROSSPROFITMARGIN($A$5,E6) -> 18.0188 | F23: =[7]!S_FA_GROSSPROFITMARGIN($A$5,F6) -> 12.3705
A24: 销售净利率（%） | B24: =[7]!s_fa_netprofitmargin($A$5,B6) -> 0.6396 | C24: =[7]!s_fa_netprofitmargin($A$5,C6) -> 3.5194 | D24: =[7]!s_fa_netprofitmargin($A$5,D6) -> -3.9144 | E24: =[7]!s_fa_netprofitmargin($A$5,E6) -> 2.7622 | F24: =[7]!s_fa_netprofitmargin($A$5,F6) -> -6.2158
A25: 扣非净利率（%） | B25: =[7]!s_fa_netprofitmargin_deducted($A5,B6) -> -5.4349221 | C25: =[7]!s_fa_netprofitmargin_deducted($A5,C6) -> -10.159903 | D25: =[7]!s_fa_netprofitmargin_deducted($A5,D6) -> -4.6166627 | E25: =[7]!s_fa_netprofitmargin_deducted($A5,E6) -> -3.6348359 | F25: =[7]!s_fa_netprofitmargin_deducted($A5,F6) -> -7.7651953
A26: ROIC（%） | B26: =[7]!s_fa_roic($A5,B6) -> 1.5223 | C26: =[7]!s_fa_roic($A5,C6) -> 3.9978 | D26: =[7]!s_fa_roic($A5,D6) -> -3.5564 | E26: =[7]!s_fa_roic($A5,E6) -> 3.0493 | F26: =[7]!s_fa_roic($A5,F6) -> -4.8139
A27: ROA（%） | B27: =[7]!s_fa_roa($A5,B6) -> 0.5417 | C27: =[7]!s_fa_roa($A5,C6) -> 2.1738 | D27: =[7]!s_fa_roa($A5,D6) -> -2.4803 | E27: =[7]!s_fa_roa($A5,E6) -> 1.636 | F27: =[7]!s_fa_roa($A5,F6) -> -3.5812
A28: EBITDA margin（%） | B28: =[7]!s_fa_ebitda2($A5,B6,1)/B9/100000000*100 -> 1.2226933 | C28: =[7]!s_fa_ebitda2($A5,C6,1)/C9/100000000*100 -> -0.20116664 | D28: =[7]!s_fa_ebitda2($A5,D6,1)/D9/100000000*100 -> 1.9648818 | E28: =[7]!s_fa_ebitda2($A5,E6,1)/E9/100000000*100 -> 6.422669 | F28: =[7]!s_fa_ebitda2($A5,F6,1)/F9/100000000*100 -> 2.2290424
A29: 期间费用
A30: 销售费用 | B30: =[7]!s_stm07_is($A$5,"W16644425",B6,1)/100000000 -> 0.55802653 | C30: =[7]!s_stm07_is($A$5,"W16644425",C6,1)/100000000 -> 0.52090118 | D30: =[7]!s_stm07_is($A$5,"W16644425",D6,1)/100000000 -> 0.38404519 | E30: =[7]!s_stm07_is($A$5,"W16644425",E6,1)/100000000 -> 0.3460808 | F30: =[7]!s_stm07_is($A$5,"W16644425",F6,1)/100000000 -> 0.50566413
A31: 管理费用 | B31: =[7]!s_stm07_is($A$5,"W17691551",B6,1)/100000000 -> 1.777883 | C31: =[7]!s_stm07_is($A$5,"W17691551",C6,1)/100000000 -> 1.3689743 | D31: =[7]!s_stm07_is($A$5,"W17691551",D6,1)/100000000 -> 1.3004555 | E31: =[7]!s_stm07_is($A$5,"W17691551",E6,1)/100000000 -> 0.97394553 | F31: =[7]!s_stm07_is($A$5,"W17691551",F6,1)/100000000 -> 1.3669584
A32: 研发费用 | C32: =[7]!s_stm07_is_103($A$5,C6,1)/100000000 -> 0.63975738 | D32: =[7]!s_stm07_is_103($A$5,D6,1)/100000000 -> 0.68533597 | E32: =[7]!s_stm07_is_103($A$5,E6,1)/100000000 -> 0.84530735 | F32: =[7]!s_stm07_is_103($A$5,F6,1)/100000000 -> 1.0147031
A33: 财务费用 | B33: =[7]!s_stm07_is($A$5,"W10733478",B6,1)/100000000 -> 0.17590407 | C33: =[7]!s_stm07_is($A$5,"W10733478",C6,1)/100000000 -> 0.079910713 | D33: =[7]!s_stm07_is($A$5,"W10733478",D6,1)/100000000 -> 0.12075075 | E33: =[7]!s_stm07_is($A$5,"W10733478",E6,1)/100000000 -> 0.13068225 | F33: =[7]!s_stm07_is($A$5,"W10733478",F6,1)/100000000 -> 0.2346468
A34: 期间费用 | B34: =SUM(B30:B33) -> 2.5118137 | C34: =SUM(C30:C33) -> 2.6095436 | D34: =SUM(D30:D33) -> 2.4905874 | E34: =SUM(E30:E33) -> 2.2960159 | F34: =SUM(F30:F33) -> 3.1219724
A35: 销售费用率 | B35: =B30/B$9 -> 0.034937341 | C35: =C30/C$9 -> 0.032501904 | D35: =D30/D$9 -> 0.023346196 | E35: =E30/E$9 -> 0.019832944 | F35: =F30/F$9 -> 0.02436421
A36: 管理费用率 | B36: =B31/B$9 -> 0.11131103 | C36: =C31/C$9 -> 0.085417875 | D36: =D31/D$9 -> 0.079054989 | E36: =E31/E$9 -> 0.055814153 | F36: =F31/F$9 -> 0.065863603
A37: 研发费用率 | B37: =B32/B$9 -> 0 | C37: =C32/C$9 -> 0.039918 | D37: =D32/D$9 -> 0.041661733 | E37: =E32/E$9 -> 0.04844225 | F37: =F32/F$9 -> 0.048891028
A38: 财务费用率 | B38: =B33/B$9 -> 0.011013133 | C38: =C33/C$9 -> 0.0049860712 | D38: =D33/D$9 -> 0.0073404663 | E38: =E33/E$9 -> 0.0074890419 | F38: =F33/F$9 -> 0.011305892
A39: 期间费用率 | B39: =B34/B$9 -> 0.1572615 | C39: =C34/C$9 -> 0.16282385 | D39: =D34/D$9 -> 0.15140338 | E39: =E34/E$9 -> 0.13157839 | F39: =F34/F$9 -> 0.15042473
A40: 资本开支
A41: 资本开支 | B41: =[7]!s_stm07_cs($A$5,"W17905498",B6,1)/100000000 -> 0.6233565 | C41: =[7]!s_stm07_cs($A$5,"W17905498",C6,1)/100000000 -> 3.4604857 | D41: =[7]!s_stm07_cs($A$5,"W17905498",D6,1)/100000000 -> 1.3674125 | E41: =[7]!s_stm07_cs($A$5,"W17905498",E6,1)/100000000 -> 3.4404786 | F41: =[7]!s_stm07_cs($A$5,"W17905498",F6,1)/100000000 -> 3.1689054
A42: 在建工程 | B42: =IF(ISTEXT([7]!s_stm07_bs_178($A$5,B6,1)),0,[7]!s_stm07_bs_178($A$5,B6,1)/100000000) -> 0.48976404 | C42: =IF(ISTEXT([7]!s_stm07_bs_178($A$5,C6,1)),0,[7]!s_stm07_bs_178($A$5,C6,1)/100000000) -> 1.1002289 | D42: =IF(ISTEXT([7]!s_stm07_bs_178($A$5,D6,1)),0,[7]!s_stm07_bs_178($A$5,D6,1)/100000000) -> 0.97863147 | E42: =IF(ISTEXT([7]!s_stm07_bs_178($A$5,E6,1)),0,[7]!s_stm07_bs_178($A$5,E6,1)/100000000) -> 3.534012 | F42: =IF(ISTEXT([7]!s_stm07_bs_178($A$5,F6,1)),0,[7]!s_stm07_bs_178($A$5,F6,1)/100000000) -> 4.4045841
A43: 固定资产 | B43: =[7]!s_stm07_bs_177($A$5,B6,1)/100000000 -> 3.750412 | C43: =[7]!s_stm07_bs_177($A$5,C6,1)/100000000 -> 4.2474193 | D43: =[7]!s_stm07_bs_177($A$5,D6,1)/100000000 -> 4.6761257 | E43: =[7]!s_stm07_bs_177($A$5,E6,1)/100000000 -> 5.4162511 | F43: =[7]!s_stm07_bs_177($A$5,F6,1)/100000000 -> 6.2531254
A44: 折旧与摊销 | B44: =[7]!s_fa_da($A$5,B6,1)/100000000 -> 0.71017754 | C44: =[7]!s_fa_da($A$5,C6,1)/100000000 -> 0.71513412 | D44: =[7]!s_fa_da($A$5,D6,1)/100000000 -> 0.79084413 | E44: =[7]!s_fa_da($A$5,E6,1)/100000000 -> 0.7810468 | F44: =[7]!s_fa_da($A$5,F6,1)/100000000 -> 1.0590707
...

Sheet 3.3 季度财务数据 
A1: 华泰电新－季度财务数据
A5: 600152.SH | R5: 后置列可忽略
A6: =[7]!s_info_name(A5) -> 维科技术 | B6: 43465 | C6: 43555 | D6: 43646 | E6: 43738 | F6: 43830 | G6: 43921 | H6: 44012 | I6: 44104 | J6: 44196 | K6: 44286 | L6: 44377 | M6: 44469 | N6: 44561 | O6: 44651 | P6: 44742 | Q6: 后置列可忽略
A7: 单位：亿元 | B7: 4Q18 | C7: 1Q19 | D7: 2Q19 | E7: 3Q19 | F7: 4Q19 | G7: 1Q20 | H7: 2Q20 | I7: 3Q20 | J7: 4Q20 | K7: 1Q21 | L7: 2Q21 | M7: 3Q21 | N7: 4Q21 | O7: 1Q22 | P7: 2Q22 | Q7: =DATE(YEAR(#REF!)-1,MONTH(#REF!),DAY(#REF!)) -> #REF!
A8: 主要财务数据
A9: 营业收入 | B9: =[7]!s_qstm07_is($A5,"W11730589",B6,1)/100000000 -> 4.8059007 | C9: =[7]!s_qstm07_is($A5,"W11730589",C6,1)/100000000 -> 2.0683073 | D9: =[7]!s_qstm07_is($A5,"W11730589",D6,1)/100000000 -> 3.3572145 | E9: =[7]!s_qstm07_is($A5,"W11730589",E6,1)/100000000 -> 4.9677957 | F9: =[7]!s_qstm07_is($A5,"W11730589",F6,1)/100000000 -> 6.0566938 | G9: =[7]!s_qstm07_is($A5,"W11730589",G6,1)/100000000 -> 1.9963734 | H9: =[7]!s_qstm07_is($A5,"W11730589",H6,1)/100000000 -> 4.2802181 | I9: =[7]!s_qstm07_is($A5,"W11730589",I6,1)/100000000 -> 4.2317597 | ... P9: =[7]!s_qstm07_is($A5,"W11730589",P6,1)/100000000 -> 7.1622782
A10: YoY | J10: =(J9-I9)/I9 -> 0.64032093 | K10: =(K9-J9)/J9 -> -0.37840407 | L10: =(L9-K9)/K9 -> 0.14546907 | M10: =(M9-I9)/I9 -> 0.36395734 | N10: =(N9-J9)/J9 -> -0.17521056 | O10: =(O9-K9)/K9 -> 0.083133775 | P10: =(P9-L9)/L9 -> 0.44913829 | Q10: =[7]!s_stm07_is($A$5,"W16498900",Q7,1,1)/100000000 -> 0
A11: 归母利润 | B11: =[7]!s_qstm07_is($A5,"W10727047",B6,1)/100000000 -> -0.41961353 | C11: =[7]!s_qstm07_is($A5,"W10727047",C6,1)/100000000 -> -0.21584445 | D11: =[7]!s_qstm07_is($A5,"W10727047",D6,1)/100000000 -> -0.2696994 | E11: =[7]!s_qstm07_is($A5,"W10727047",E6,1)/100000000 -> 0.01623364 | F11: =[7]!s_qstm07_is($A5,"W10727047",F6,1)/100000000 -> -0.17149915 | G11: =[7]!s_qstm07_is($A5,"W10727047",G6,1)/100000000 -> -0.16254326 | H11: =[7]!s_qstm07_is($A5,"W10727047",H6,1)/100000000 -> 0.5041913 | I11: =[7]!s_qstm07_is($A5,"W10727047",I6,1)/100000000 -> 0.082485241 | ... P11: =[7]!s_qstm07_is($A5,"W10727047",P6,1)/100000000 -> 0.13612012
A12: YoY | J12: =(J11-I11)/I11 -> -0.18416784 | K12: =(K11-J11)/J11 -> -0.63292052 | L12: =(L11-K11)/K11 -> 0.67114435 | M12: =(M11-I11)/I11 -> -7.2001879 | N12: =(N11-J11)/J11 -> -13.279265 | O12: =(O11-K11)/K11 -> -3.6507931 | P12: =(P11-L11)/L11 -> 2.2973965 | Q12: =[7]!s_qstm07_is($A$5,"W12244963",Q7,1,1)/100000000 -> 0
A13: 非经常性损益 | B13: =B11-B14 -> 0.56083642 | C13: =C11-C14 -> 0.15493831 | D13: =D11-D14 -> 0.06140794 | E13: =E11-E14 -> 0.15349247 | F13: =F11-F14 -> -0.25120655 | G13: =G11-G14 -> 0.1775688 | H13: =H11-H14 -> 0.70160465 | I13: =I11-I14 -> 0.10173538 | ... P13: =P11-P14 -> 0.12985806
A14: 扣非利润 | B14: =[7]!s_qfa_deductedprofit($A$5,B6,1)/100000000 -> -0.98044995 | C14: =[7]!s_qfa_deductedprofit($A$5,C6,1)/100000000 -> -0.37078276 | D14: =[7]!s_qfa_deductedprofit($A$5,D6,1)/100000000 -> -0.33110734 | E14: =[7]!s_qfa_deductedprofit($A$5,E6,1)/100000000 -> -0.13725883 | F14: =[7]!s_qfa_deductedprofit($A$5,F6,1)/100000000 -> 0.079707391 | G14: =[7]!s_qfa_deductedprofit($A$5,G6,1)/100000000 -> -0.34011205 | H14: =[7]!s_qfa_deductedprofit($A$5,H6,1)/100000000 -> -0.19741336 | I14: =[7]!s_qfa_deductedprofit($A$5,I6,1)/100000000 -> -0.019250136 | ... P14: =[7]!s_qfa_deductedprofit($A$5,P6,1)/100000000 -> 0.0062620519
A15: YoY | J15: =(J14-I14)/I14 -> 3.0257308 | K15: =(K14-J14)/J14 -> -1.3923798 | L15: =(L14-K14)/K14 -> -5.7325333 | M15: =(M14-I14)/I14 -> 24.930834 | N15: =(N14-J14)/J14 -> 11.89034 | O15: =(O14-K14)/K14 -> -5.282493 | P15: =(P14-L14)/L14 -> -1.0435149 | Q15: =[7]!s_qfa_deductedprofit($A$5,Q7,1)/100000000 -> 0
A16: 经营活动现金净流量 | B16: =[7]!s_qstm07_cs($A5,"W13116090",B6,1)/100000000 -> 0.80020988 | C16: =[7]!s_qstm07_cs($A5,"W13116090",C6,1)/100000000 -> -0.21679807 | D16: =[7]!s_qstm07_cs($A5,"W13116090",D6,1)/100000000 -> -0.66070572 | E16: =[7]!s_qstm07_cs($A5,"W13116090",E6,1)/100000000 -> -0.067800745 | F16: =[7]!s_qstm07_cs($A5,"W13116090",F6,1)/100000000 -> 0.34154679 | G16: =[7]!s_qstm07_cs($A5,"W13116090",G6,1)/100000000 -> 0.099111391 | H16: =[7]!s_qstm07_cs($A5,"W13116090",H6,1)/100000000 -> 0.088057139 | I16: =[7]!s_qstm07_cs($A5,"W13116090",I6,1)/100000000 -> -0.57871014 | ... P16: =[7]!s_qstm07_cs($A5,"W13116090",P6,1)/100000000 -> 0.38885616
A17: YoY | J17: =(J16-I16)/I16 -> -2.188169 | K17: =(K16-J16)/J16 -> -1.0349764 | L17: =(L16-K16)/K16 -> -6.0016056 | M17: =(M16-I16)/I16 -> 0.98288554 | N17: =(N16-J16)/J16 -> -2.8999939 | O17: =(O16-K16)/K16 -> 64.533321 | P17: =(P16-L16)/L16 -> 2.2326988 | Q17: =[7]!s_qstm07_cs($A$5,"W16360213",Q7,1,1)/100000000 -> 0
A18: 经营活动现金净流量/归母净利润(%) | B18: =B16/B11*100 -> -190.70164 | C18: =C16/C11*100 -> 100.44181 | D18: =D16/D11*100 -> 244.97856 | E18: =E16/E11*100 -> -417.65584 | F18: =F16/F11*100 -> -199.15363 | G18: =G16/G11*100 -> -60.975394 | H18: =H16/H11*100 -> 17.465026 | I18: =I16/I11*100 -> -701.59235 | ... P18: =P16/P11*100 -> 285.67134
A20: 盈利能力
A21: ROE(%) | B21: =[7]!s_qfa_roe($A$5,B6) -> -2.912322 | C21: =[7]!s_qfa_roe($A$5,C6) -> -1.553446 | D21: =[7]!s_qfa_roe($A$5,D6) -> -1.976815 | E21: =[7]!s_qfa_roe($A$5,E6) -> 0.118863 | F21: =[7]!s_qfa_roe($A$5,F6) -> -1.250392 | G21: =[7]!s_qfa_roe($A$5,G6) -> -1.200741 | H21: =[7]!s_qfa_roe($A$5,H6) -> 3.673064 | I21: =[7]!s_qfa_roe($A$5,I6) -> 0.587857 | ... P21: =[7]!s_qfa_roe($A$5,P6) -> 0.68538
A22: ROE(扣非)(%) | B22: =[7]!s_qfa_roe_deducted($A5,B6) -> -6.8048 | C22: =[7]!s_qfa_roe_deducted($A5,C6) -> -2.668546 | D22: =[7]!s_qfa_roe_deducted($A5,D6) -> -2.426916 | E22: =[7]!s_qfa_roe_deducted($A5,E6) -> -1.005016 | F22: =[7]!s_qfa_roe_deducted($A5,F6) -> 0.581143 | G22: =[7]!s_qfa_roe_deducted($A5,G6) -> -2.512478 | H22: =[7]!s_qfa_roe_deducted($A5,H6) -> -1.438168 | I22: =[7]!s_qfa_roe_deducted($A5,I6) -> -0.137192 | ... P22: =[7]!s_qfa_roe_deducted($A5,P6) -> 0.03153
A23: 综合毛利率（%） | B23: =[7]!s_qfa_grossprofitmargin($A$5,B6) -> 8.7276 | C23: =[7]!s_qfa_grossprofitmargin($A$5,C6) -> 3.6556 | D23: =[7]!s_qfa_grossprofitmargin($A$5,D6) -> 11.6517 | E23: =[7]!s_qfa_grossprofitmargin($A$5,E6) -> 17.3045 | F23: =[7]!s_qfa_grossprofitmargin($A$5,F6) -> 16.0377 | G23: =[7]!s_qfa_grossprofitmargin($A$5,G6) -> 8.4137 | H23: =[7]!s_qfa_grossprofitmargin($A$5,H6) -> 23.6741 | I23: =[7]!s_qfa_grossprofitmargin($A$5,I6) -> 15.7979 | ... P23: =[7]!s_qfa_grossprofitmargin($A$5,P6) -> 9.7475
A24: 销售净利率（%） | B24: =[7]!s_qfa_netprofitmargin($A$5,B6) -> -7.8357 | C24: =[7]!s_qfa_netprofitmargin($A$5,C6) -> -10.7938 | D24: =[7]!s_qfa_netprofitmargin($A$5,D6) -> -8.2789 | E24: =[7]!s_qfa_netprofitmargin($A$5,E6) -> 0.2106 | F24: =[7]!s_qfa_netprofitmargin($A$5,F6) -> -2.5293 | G24: =[7]!s_qfa_netprofitmargin($A$5,G6) -> -8.1622 | H24: =[7]!s_qfa_netprofitmargin($A$5,H6) -> 11.748 | I24: =[7]!s_qfa_netprofitmargin($A$5,I6) -> 1.8892 | ... P24: =[7]!s_qfa_netprofitmargin($A$5,P6) -> 1.9005
A25: 扣非净利率（%） | B25: =[7]!s_qfa_deductedprofit($A5,B6)/B9/100000000*100 -> -20.400961 | C25: =[7]!s_qfa_deductedprofit($A5,C6)/C9/100000000*100 -> -17.92687 | D25: =[7]!s_qfa_deductedprofit($A5,D6)/D9/100000000*100 -> -9.8625614 | E25: =[7]!s_qfa_deductedprofit($A5,E6)/E9/100000000*100 -> -2.7629725 | F25: =[7]!s_qfa_deductedprofit($A5,F6)/F9/100000000*100 -> 1.3160215 | G25: =[7]!s_qfa_deductedprofit($A5,G6)/G9/100000000*100 -> -17.036495 | H25: =[7]!s_qfa_deductedprofit($A5,H6)/H9/100000000*100 -> -4.6122266 | I25: =[7]!s_qfa_deductedprofit($A5,I6)/I9/100000000*100 -> -0.45489672 | ... P25: =[7]!s_qfa_deductedprofit($A5,P6)/P9/100000000*100 -> 0.087431006
A26: ROA（%） | B26: =[7]!s_qfa_roa($A5,B6) -> -1.4638 | C26: =[7]!s_qfa_roa($A5,C6) -> -0.8882 | D26: =[7]!s_qfa_roa($A5,D6) -> -1.0576 | E26: =[7]!s_qfa_roa($A5,E6) -> 0.0384 | F26: =[7]!s_qfa_roa($A5,F6) -> -0.5594 | G26: =[7]!s_qfa_roa($A5,G6) -> -0.6217 | H26: =[7]!s_qfa_roa($A5,H6) -> 1.98 | I26: =[7]!s_qfa_roa($A5,I6) -> 0.299 | ... P26: =[7]!s_qfa_roa($A5,P6) -> 0.3185
A27: EBITDA margin（%） | B27: =IF(MONTH(B6)=3,[7]!s_fa_ebitda2_ttm($A5,B6),[7]!s_fa_ebitda2_ttm($A5,B6)-[7]!s_fa_ebitda2_ttm($A5,#REF!))/B9/100000000*100 -> -0.67085351 | C27: =IF(MONTH(C6)=3,[7]!s_fa_ebitda2_ttm($A5,C6),[7]!s_fa_ebitda2_ttm($A5,C6)-[7]!s_fa_ebitda2_ttm($A5,#REF!))/C9/100000000*100 -> -1.5587893 | D27: =IF(MONTH(D6)=3,[7]!s_fa_ebitda2_ttm($A5,D6),[7]!s_fa_ebitda2_ttm($A5,D6)-[7]!s_fa_ebitda2_ttm($A5,#REF!))/D9/100000000*100 -> -14.548527 | E27: =IF(MONTH(E6)=3,[7]!s_fa_ebitda2_ttm($A5,E6),[7]!s_fa_ebitda2_ttm($A5,E6)-[7]!s_fa_ebitda2_ttm($A5,#REF!))/E9/100000000*100 -> -0.64899113 | F27: =IF(MONTH(F6)=3,[7]!s_fa_ebitda2_ttm($A5,F6),[7]!s_fa_ebitda2_ttm($A5,F6)-[7]!s_fa_ebitda2_ttm($A5,#REF!))/F9/100000000*100 -> 5.336629 | G27: =IF(MONTH(G6)=3,[7]!s_fa_ebitda2_ttm($A5,G6),[7]!s_fa_ebitda2_ttm($A5,G6)-[7]!s_fa_ebitda2_ttm($A5,#REF!))/G9/100000000*100 -> 16.190522 | H27: =IF(MONTH(H6)=3,[7]!s_fa_ebitda2_ttm($A5,H6),[7]!s_fa_ebitda2_ttm($A5,H6)-[7]!s_fa_ebitda2_ttm($A5,#REF!))/H9/100000000*100 -> 30.138887 | I27: =IF(MONTH(I6)=3,[7]!s_fa_ebitda2_ttm($A5,I6),[7]!s_fa_ebitda2_ttm($A5,I6)-[7]!s_fa_ebitda2_ttm($A5,#REF!))/I9/100000000*100 -> 7.6380348 | J27: =IF(MONTH(J6)=3,[7]!s_fa_ebitda2_ttm($A5,J6),[7]!s_fa_ebitda2_ttm($A5,J6)-[7]!s_fa_ebitda2_ttm($A5,I6))/J9/100000000*100 -> 11.489242 | K27: =IF(MONTH(K6)=3,[7]!s_fa_ebitda2_ttm($A5,K6),[7]!s_fa_ebitda2_ttm($A5,K6)-[7]!s_fa_ebitda2_ttm($A5,J6))/K9/100000000*100 -> 25.974541 | L27: =IF(MONTH(L6)=3,[7]!s_fa_ebitda2_ttm($A5,L6),[7]!s_fa_ebitda2_ttm($A5,L6)-[7]!s_fa_ebitda2_ttm($A5,K6))/L9/100000000*100 -> -3.6739953 | M27: =IF(MONTH(M6)=3,[7]!s_fa_ebitda2_ttm($A5,M6),[7]!s_fa_ebitda2_ttm($A5,M6)-[7]!s_fa_ebitda2_ttm($A5,L6))/M9/100000000*100 -> 3.145996 | N27: =IF(MONTH(N6)=3,[7]!s_fa_ebitda2_ttm($A5,N6),[7]!s_fa_ebitda2_ttm($A5,N6)-[7]!s_fa_ebitda2_ttm($A5,M6))/N9/100000000*100 -> -11.49506 | O27: =IF(MONTH(O6)=3,[7]!s_fa_ebitda2_ttm($A5,O6),[7]!s_fa_ebitda2_ttm($A5,O6)-[7]!s_fa_ebitda2_ttm($A5,N6))/O9/100000000*100 -> 9.8989256 | P27: =IF(MONTH(P6)=3,[7]!s_fa_ebitda2_ttm($A5,P6),[7]!s_fa_ebitda2_ttm($A5,P6)-[7]!s_fa_ebitda2_ttm($A5,O6))/P9/100000000*100 -> 1.6616058
A28: 期间费用
A29: 销售费用 | B29: =[7]!s_qstm07_is($A5,"W17952062",B6,1)/100000000 -> 0.1097106 | C29: =[7]!s_qstm07_is($A5,"W17952062",C6,1)/100000000 -> 0.062724369 | D29: =[7]!s_qstm07_is($A5,"W17952062",D6,1)/100000000 -> 0.094250675 | E29: =[7]!s_qstm07_is($A5,"W17952062",E6,1)/100000000 -> 0.095475898 | F29: =[7]!s_qstm07_is($A5,"W17952062",F6,1)/100000000 -> 0.13159425 | G29: =[7]!s_qstm07_is($A5,"W17952062",G6,1)/100000000 -> 0.070924726 | H29: =[7]!s_qstm07_is($A5,"W17952062",H6,1)/100000000 -> 0.084086707 | I29: =[7]!s_qstm07_is($A5,"W17952062",I6,1)/100000000 -> 0.10562286 | ... P29: =[7]!s_qstm07_is($A5,"W17952062",P6,1)/100000000 -> 0.086830632
A30: 管理费用 | B30: =[7]!s_qstm07_is($A$5,"W10628433",B6,1)/100000000 -> 0.40799178 | C30: =[7]!s_qstm07_is($A$5,"W10628433",C6,1)/100000000 -> 0.24547237 | D30: =[7]!s_qstm07_is($A$5,"W10628433",D6,1)/100000000 -> 0.27800328 | E30: =[7]!s_qstm07_is($A$5,"W10628433",E6,1)/100000000 -> 0.33247397 | F30: =[7]!s_qstm07_is($A$5,"W10628433",F6,1)/100000000 -> 0.44450584 | G30: =[7]!s_qstm07_is($A$5,"W10628433",G6,1)/100000000 -> 0.24009665 | H30: =[7]!s_qstm07_is($A$5,"W10628433",H6,1)/100000000 -> 0.237787 | I30: =[7]!s_qstm07_is($A$5,"W10628433",I6,1)/100000000 -> 0.23505026 | ... P30: =[7]!s_qstm07_is($A$5,"W10628433",P6,1)/100000000 -> 0.20363809
A31: 研发费用 | B31: =[7]!s_qstm07_is_103($A$5,B6,1)/100000000 -> 0.17255886 | C31: =[7]!s_qstm07_is_103($A$5,C6,1)/100000000 -> 0.14957483 | D31: =[7]!s_qstm07_is_103($A$5,D6,1)/100000000 -> 0.17084515 | E31: =[7]!s_qstm07_is_103($A$5,E6,1)/100000000 -> 0.2048937 | F31: =[7]!s_qstm07_is_103($A$5,F6,1)/100000000 -> 0.16002229 | G31: =[7]!s_qstm07_is_103($A$5,G6,1)/100000000 -> 0.17829533 | H31: =[7]!s_qstm07_is_103($A$5,H6,1)/100000000 -> 0.22593237 | I31: =[7]!s_qstm07_is_103($A$5,I6,1)/100000000 -> 0.23258013 | ... P31: =[7]!s_qstm07_is_103($A$5,P6,1)/100000000 -> 0.19851073
A32: 财务费用 | B32: =[7]!s_qstm07_is($A$5,"W13069920",B6,1)/100000000 -> -0.0057045138 | C32: =[7]!s_qstm07_is($A$5,"W13069920",C6,1)/100000000 -> 0.027669689 | D32: =[7]!s_qstm07_is($A$5,"W13069920",D6,1)/100000000 -> 0.0115992 | E32: =[7]!s_qstm07_is($A$5,"W13069920",E6,1)/100000000 -> 0.0021866825 | F32: =[7]!s_qstm07_is($A$5,"W13069920",F6,1)/100000000 -> 0.079295181 | G32: =[7]!s_qstm07_is($A$5,"W13069920",G6,1)/100000000 -> 0.022595247 | H32: =[7]!s_qstm07_is($A$5,"W13069920",H6,1)/100000000 -> 0.010713079 | I32: =[7]!s_qstm07_is($A$5,"W13069920",I6,1)/100000000 -> 0.04646728 | ... P32: =[7]!s_qstm07_is($A$5,"W13069920",P6,1)/100000000 -> -0.021582926
A33: 期间费用 | B33: =SUM(B29:B32) -> 0.68455673 | C33: =SUM(C29:C32) -> 0.48544126 | D33: =SUM(D29:D32) -> 0.5546983 | E33: =SUM(E29:E32) -> 0.63503025 | F33: =SUM(F29:F32) -> 0.81541756 | G33: =SUM(G29:G32) -> 0.51191195 | H33: =SUM(H29:H32) -> 0.55851915 | I33: =SUM(I29:I32) -> 0.61972053 | ... P33: =SUM(P29:P32) -> 0.46739653
A34: 销售费用率 | B34: =B29/B$9 -> 0.022828312 | C34: =C29/C$9 -> 0.030326427 | D34: =D29/D$9 -> 0.02807407 | E34: =E29/E$9 -> 0.019218966 | F34: =F29/F$9 -> 0.021727076 | G34: =G29/G$9 -> 0.035526784 | H34: =H29/H$9 -> 0.019645426 | I34: =I29/I$9 -> 0.02495956 | ... P34: =P29/P$9 -> 0.012123326
A35: 管理费用率 | B35: =B30/B$9 -> 0.084893927 | C35: =C30/C$9 -> 0.11868274 | D35: =D30/D$9 -> 0.082807719 | E35: =E30/E$9 -> 0.066925854 | F35: =F30/F$9 -> 0.073390839 | G35: =G30/G$9 -> 0.1202664 | H35: =H30/H$9 -> 0.055554878 | I35: =I30/I$9 -> 0.055544332 | ... P35: =P30/P$9 -> 0.028432028
A36: 研发费用率 | B36: =B31/B$9 -> 0.035905623 | C36: =C31/C$9 -> 0.072317508 | D36: =D31/D$9 -> 0.05088896 | E36: =E31/E$9 -> 0.04124439 | F36: =F31/F$9 -> 0.026420733 | G36: =G31/G$9 -> 0.089309612 | H36: =H31/H$9 -> 0.052785247 | I36: =I31/I$9 -> 0.054960619 | ... P36: =P31/P$9 -> 0.027716144
A37: 财务费用率 | B37: =B32/B$9 -> -0.0011869812 | C37: =C32/C$9 -> 0.013377939 | D37: =D32/D$9 -> 0.0034550071 | E37: =E32/E$9 -> 0.00044017158 | F37: =F32/F$9 -> 0.013092156 | G37: =G32/G$9 -> 0.011318147 | H37: =H32/H$9 -> 0.0025029284 | I37: =I32/I$9 -> 0.010980605 | ... P37: =P32/P$9 -> -0.0030134164
A38: 期间费用率 | B38: =B33/B$9 -> 0.14244088 | C38: =C33/C$9 -> 0.23470461 | D38: =D33/D$9 -> 0.16522576 | E38: =E33/E$9 -> 0.12782938 | F38: =F33/F$9 -> 0.1346308 | G38: =G33/G$9 -> 0.25642095 | H38: =H33/H$9 -> 0.13048848 | I38: =I33/I$9 -> 0.14644512 | ... P38: =P33/P$9 -> 0.065258081
A39: 减值相关
A40: 减值损失 | B40: =B41+B42 -> 0.2947772 | C40: =C41+C42 -> 0.0013699969 | D40: =D41+D42 -> -0.094225532 | E40: =E41+E42 -> -0.20229164 | F40: =F41+F42 -> -0.24826459 | G40: =G41+G42 -> 0.0049892538 | H40: =H41+H42 -> -0.0026445878 | I40: =I41+I42 -> -0.062073319 | ... P40: =P41+P42 -> -0.12766731
A41: 资产减值损失 | B41: =IF(ISTEXT([7]!s_qstm07_is($A$5,"W17476836",B6,1)),0,[7]!s_qstm07_is($A$5,"W17476836",B6,1))/100000000 -> 0.2947772 | C41: =IF(ISTEXT([7]!s_qstm07_is($A$5,"W17476836",C6,1)),0,[7]!s_qstm07_is($A$5,"W17476836",C6,1))/100000000 -> 0.0089585929 | D41: =IF(ISTEXT([7]!s_qstm07_is($A$5,"W17476836",D6,1)),0,[7]!s_qstm07_is($A$5,"W17476836",D6,1))/100000000 -> -0.032804287 | E41: =IF(ISTEXT([7]!s_qstm07_is($A$5,"W17476836",E6,1)),0,[7]!s_qstm07_is($A$5,"W17476836",E6,1))/100000000 -> -0.14825943 | F41: =IF(ISTEXT([7]!s_qstm07_is($A$5,"W17476836",F6,1)),0,[7]!s_qstm07_is($A$5,"W17476836",F6,1))/100000000 -> -0.1304631 | G41: =IF(ISTEXT([7]!s_qstm07_is($A$5,"W17476836",G6,1)),0,[7]!s_qstm07_is($A$5,"W17476836",G6,1))/100000000 -> -0.0021797698 | H41: =IF(ISTEXT([7]!s_qstm07_is($A$5,"W17476836",H6,1)),0,[7]!s_qstm07_is($A$5,"W17476836",H6,1))/100000000 -> -0.0092240572 | I41: =IF(ISTEXT([7]!s_qstm07_is($A$5,"W17476836",I6,1)),0,[7]!s_qstm07_is($A$5,"W17476836",I6,1))/100000000 -> 0.00489559 | ... P41: =IF(ISTEXT([7]!s_qstm07_is($A$5,"W17476836",P6,1)),0,[7]!s_qstm07_is($A$5,"W17476836",P6,1))/100000000 -> -0.10967506
A42: 信用减值损失 | B42: =[7]!s_qstm07_is_101($A$5,B6,1)/100000000 -> 0 | C42: =[7]!s_qstm07_is_101($A$5,C6,1)/100000000 -> -0.007588596 | D42: =[7]!s_qstm07_is_101($A$5,D6,1)/100000000 -> -0.061421245 | E42: =[7]!s_qstm07_is_101($A$5,E6,1)/100000000 -> -0.054032216 | F42: =[7]!s_qstm07_is_101($A$5,F6,1)/100000000 -> -0.11780149 | G42: =[7]!s_qstm07_is_101($A$5,G6,1)/100000000 -> 0.0071690236 | H42: =[7]!s_qstm07_is_101($A$5,H6,1)/100000000 -> 0.0065794694 | I42: =[7]!s_qstm07_is_101($A$5,I6,1)/100000000 -> -0.066968909 | ... P42: =[7]!s_qstm07_is_101($A$5,P6,1)/100000000 -> -0.017992253
A43: 资产结构
A44: 总资产 | B44: =[7]!s_stm07_bs($A$5,"W15273164",B6,1,1)/100000000 -> 24.712578 | C44: =[7]!s_stm07_bs($A$5,"W15273164",C6,1,1)/100000000 -> 25.559412 | D44: =[7]!s_stm07_bs($A$5,"W15273164",D6,1,1)/100000000 -> 27.003283 | E44: =[7]!s_stm07_bs($A$5,"W15273164",E6,1,1)/100000000 -> 27.559243 | F44: =[7]!s_stm07_bs($A$5,"W15273164",F6,1,1)/100000000 -> 27.209424 | G44: =[7]!s_stm07_bs($A$5,"W15273164",G6,1,1)/100000000 -> 25.210233 | H44: =[7]!s_stm07_bs($A$5,"W15273164",H6,1,1)/100000000 -> 25.581862 | I44: =[7]!s_stm07_bs($A$5,"W15273164",I6,1,1)/100000000 -> 27.886119 | ... P44: =[7]!s_stm07_bs($A$5,"W15273164",P6,1,1)/100000000 -> 42.303539
...

Sheet 3.4费用分析
A1: 华泰电新－费用分析
A4: 单位：万元
A5: 销售费用 | I5: 销售费用
B6: 2019 | C6: 2020 | D6: 2021 | E6: 2022E | F6: 2023E | G6: 2024E | J6: 2019 | K6: 2020 | L6: 2021 | M6: 2022E | N6: 2023E | O6: 2024E
A7: 工资薪酬 | B7: 1547.2902 | C7: 2045.7487 | D7: 1083.73 | I7: 工资薪酬 | J7: =B7/'1.1业绩汇总'!D$42/100 -> 0.0094060195 | K7: =C7/'1.1业绩汇总'!E$42/100 -> 0.011723623 | L7: =D7/'1.1业绩汇总'!F$42/100 -> 0.0052216879
A8: 运输费 | B8: 1111.5294 | I8: 运输费 | J8: =B8/'1.1业绩汇总'!D$42/100 -> 0.0067570176 | K8: =C8/'1.1业绩汇总'!E$42/100 -> 0 | L8: =D8/'1.1业绩汇总'!F$42/100 -> 0
A9: 办公、差旅、业务招待 | B9: 495.7215 | C9: 568.74608 | D9: 741.10678 | I9: 办公、差旅、业务招待 | J9: =B9/'1.1业绩汇总'!D$42/100 -> 0.0030135046 | K9: =C9/'1.1业绩汇总'!E$42/100 -> 0.0032593272 | L9: =D9/'1.1业绩汇总'!F$42/100 -> 0.0035708418
A10: 广告展览策划 | B10: 164.2775 | C10: 75.526419 | D10: 370.82909 | I10: 广告展览策划 | J10: =B10/'1.1业绩汇总'!D$42/100 -> 0.00099864742 | K10: =C10/'1.1业绩汇总'!E$42/100 -> 0.00043282112 | L10: =D10/'1.1业绩汇总'!F$42/100 -> 0.0017867493
A11: 租赁 | B11: 3.1002 | I11: 租赁 | J11: =B11/'1.1业绩汇总'!D$42/100 -> 1.8846201e-05 | K11: =C11/'1.1业绩汇总'!E$42/100 -> 0 | L11: =D11/'1.1业绩汇总'!F$42/100 -> 0
A12: 商场、专柜费用 | B12: 9.0254 | I12: 商场、专柜费用 | J12: =B12/'1.1业绩汇总'!D$42/100 -> 5.4865653e-05 | K12: =C12/'1.1业绩汇总'!E$42/100 -> 0 | L12: =D12/'1.1业绩汇总'!F$42/100 -> 0
A13: 维修费用 | B13: 41.8769 | C13: 56.756034 | D13: 52.420588 | I13: 维修费用 | J13: =B13/'1.1业绩汇总'!D$42/100 -> 0.00025457082 | K13: =C13/'1.1业绩汇总'!E$42/100 -> 0.00032525321 | L13: =D13/'1.1业绩汇总'!F$42/100 -> 0.00025257578
A14: 检验检疫费用 | B14: 233.2022 | C14: 82.6341 | D14: 244.79257 | I14: 检验检疫费用 | J14: =B14/'1.1业绩汇总'!D$42/100 -> 0.0014176426 | K14: =C14/'1.1业绩汇总'!E$42/100 -> 0.00047355328 | L14: =D14/'1.1业绩汇总'!F$42/100 -> 0.0011794731
A15: 折旧及其他 | B15: 10.998312 | C15: 33.300569 | D15: 55.433841 | I15: 折旧及其他 | J15: =B15/'1.1业绩汇总'!D$42/100 -> 6.685904e-05 | K15: =C15/'1.1业绩汇总'!E$42/100 -> 0.00019083639 | L15: =D15/'1.1业绩汇总'!F$42/100 -> 0.0002670944
A16: 保险 | B16: 17.783019 | C16: 133.74082 | D16: 160.56555 | J16: =B16/'1.1业绩汇总'!D$42/100 -> 0.00010810346 | K16: =C16/'1.1业绩汇总'!E$42/100 -> 0.00076643182 | L16: =D16/'1.1业绩汇总'!F$42/100 -> 0.00077364584
A17: 中介服务 | B17: 81.440075 | C17: 371.76652 | D17: 489.43218 | J17: =B17/'1.1业绩汇总'!D$42/100 -> 0.00049507644 | K17: =C17/'1.1业绩汇总'!E$42/100 -> 0.0021304916 | L17: =D17/'1.1业绩汇总'!F$42/100 -> 0.0023582092
A18: 其他 | B18: 124.20668 | C18: 92.588708 | D18: 236.14998 | I18: 其他 | J18: =B18/'1.1业绩汇总'!D$42/100 -> 0.00075505578 | K18: =C18/'1.1业绩汇总'!E42/100 -> 0.0005306004 | L18: =D18/'1.1业绩汇总'!F42/100 -> 0.0011378309
A19: 合计 | B19: =SUM(B7:B18) -> 3840.4514 | C19: =SUM(C7:C18) -> 3460.808 | D19: =SUM(D7:D18) -> 3434.4606 | I19: 合计 | J19: =SUM(J7:J18) -> 0.023346209 | K19: =SUM(K7:K18) -> 0.019832938 | L19: =SUM(L7:L18) -> 0.016548108
A21: 管理费用 | I21: 管理费用
B22: 2019 | C22: 2020 | D22: 2021 | E22: 2022E | F22: 2023E | G22: 2024E | J22: 2019 | K22: 2020 | L22: 2021 | M22: 2022E | N22: 2023E | O22: 2024E
A25: 工资薪酬 | B25: 7164.8885 | C25: 5722.758 | D25: 8068.8539 | I25: 工资薪酬 | J25: =B25/'1.1业绩汇总'!D42/100 -> 0.043555553 | K25: =C25/'1.1业绩汇总'!E42/100 -> 0.032795551 | L25: =D25/'1.1业绩汇总'!F42/100 -> 0.038877799
A26: 办公差旅 | B26: 772.0277 | C26: 601.86452 | D26: 737.82938 | I26: 办公差旅 | J26: =B26/'1.1业绩汇总'!D42/100 -> 0.0046931775 | K26: =C26/'1.1业绩汇总'!E42/100 -> 0.0034491199 | L26: =D26/'1.1业绩汇总'!F42/100 -> 0.0035550504
A27: 修理、物料 | B27: 165.6894 | C27: 81.486431 | D27: 320.39662 | I27: 修理物料 | J27: =B27/'1.1业绩汇总'!D42/100 -> 0.0010072304 | K27: =C27/'1.1业绩汇总'!E42/100 -> 0.0004669763 | L27: =D27/'1.1业绩汇总'!F42/100 -> 0.0015437528
A28: 检测认证 | B28: 11.8758 | C28: 68.40792 | D28: 16.780879 | I28: 检测认证 | J28: =B28/'1.1业绩汇总'!D42/100 -> 7.2193313e-05 | K28: =C28/'1.1业绩汇总'!E42/100 -> 0.00039202696 | L28: =D28/'1.1业绩汇总'!F42/100 -> 8.0854561e-05
A29: 安全生产 | B29: 459.6914 | C29: 423.48763 | D29: 471.94819 | I29: 安全生产 | J29: =B29/'1.1业绩汇总'!D42/100 -> 0.0027944766 | K29: =C29/'1.1业绩汇总'!E42/100 -> 0.002426891 | L29: =D29/'1.1业绩汇总'!F42/100 -> 0.0022739669
A30: 物业租赁 | B30: 498.9496 | C30: 404.10046 | D30: 406.37238 | I30: 物业租赁 | J30: =B30/'1.1业绩汇总'!D42/100 -> 0.0030331283 | K30: =C30/'1.1业绩汇总'!E42/100 -> 0.0023157885 | L30: =D30/'1.1业绩汇总'!F42/100 -> 0.0019580059
A31: 折旧摊销 | B31: 1419.7497 | C31: 1223.2756 | D31: 2009.3624 | I31: 折旧摊销 | J31: =B31/'1.1业绩汇总'!D42/100 -> 0.0086306973 | K31: =C31/'1.1业绩汇总'!E42/100 -> 0.0070102558 | L31: =D31/'1.1业绩汇总'!F42/100 -> 0.0096816214
A32: 排污 | B32: 57.4416 | C32: 37.156364 | D32: 137.26891 | I32: 排污 | J32: =B32/'1.1业绩汇总'!D42/100 -> 0.00034918906 | K32: =C32/'1.1业绩汇总'!E42/100 -> 0.00021293289 | L32: =D32/'1.1业绩汇总'!F42/100 -> 0.00066139668
A33: 中介服务 | B33: 1096.7127 | C33: 350.00573 | D33: 607.50427 | I33: 中介服务 | J33: =B33/'1.1业绩汇总'!D42/100 -> 0.0066669465 | K33: =C33/'1.1业绩汇总'!E42/100 -> 0.0020057865 | L33: =D33/'1.1业绩汇总'!F42/100 -> 0.0029271107
A34: 运输、汽车 | B34: 117.8131 | C34: 81.772695 | D34: 96.314109 | I34: 运输、汽车 | J34: =B34/'1.1业绩汇总'!D42/100 -> 0.00071618906 | K34: =C34/'1.1业绩汇总'!E42/100 -> 0.0004686168 | L34: =D34/'1.1业绩汇总'!F42/100 -> 0.00046406598
