Workbook
Name Date1: OFFSET(沪深两市历史成交!$F$4,1,0,沪深两市历史成交!$J$3,1)
Name Ind1_1: OFFSET(沪深两市历史成交!$G$4,1,0,沪深两市历史成交!$J$3,1)
Name Ind1_2: OFFSET(沪深两市历史成交!$H$4,1,0,沪深两市历史成交!$J$3,1)

Sheet Wind模板
A1: 沪深两市成交分析

Sheet 沪深两市成交分析
E1: 沪深两市成交分析 V1.6 | N1: 最近更新： | O1: =[1]!TDaysOffset(TODAY(),"Offset=-1") -> 45565
D3: 实时成交额（每分钟刷新）
D4: 沪深两市总成交额 | E4: =沪深两市实时成交明细!B3+沪深两市实时成交明细!E3 -> 3451939042200 | G4: 沪市成交额 | I4: =沪深两市实时成交明细!B3 -> 1510513250800 | K4: 深市成交额 | M4: =沪深两市实时成交明细!E3 -> 1941425791400
D7: 查询日期: | E7: =TODAY() -> 45573
D9: 沪深两市总成交额 | E9: =IF(E7=TODAY(),(沪深两市实时成交明细!B3+沪深两市实时成交明细!E3)/100000000,LOOKUP(2,1/(沪深两市成交汇总!E:E<>0),沪深两市成交汇总!E:E)) -> 34519.39 | G9: 较前一日同期变化 | I9: =LOOKUP(2,1/(沪深两市成交汇总!F:F<>0),沪深两市成交汇总!F:F) -> 8589.024 | J9: =IF(I9>0,1,IF(I9=0,0,-1)) -> 1
D11: ="实时买入额(亿元）" -> 实时买入额(亿元）
D23: 每小时成交统计 | E23: 9:30-10:30 | F23: 同比 | G23: 10:31-11:30 | H23: 同比 | I23: 13:00-14:00 | J23: 同比 | K23: 14:01-15:00 | L23: 同比
D24: 今日 | E24: =IF(E7=TODAY(),IF(NOW()-TODAY()>TIME(10,30,0),SUM(沪深两市成交汇总!C2:C62),"--"),SUM(沪深两市成交汇总!C2:C62)) -> 1650326809100 | F24: =IF(E24="--","",E24/E25-1) -> 0.30497203 | G24: =IF(E7=TODAY(),IF(NOW()-TODAY()>TIME(11,30,0),SUM(沪深两市成交汇总!C63:C122),"--"),SUM(沪深两市成交汇总!C63:C122)) -> 829754997600 | H24: =IF(G24="--","",G24/G25-1) -> 1.1036717 | I24: =IF(E7=TODAY(),IF(NOW()-TODAY()>TIME(11,30,0),SUM(沪深两市成交汇总!C123:'沪深两市成交汇总'!C183),"--"),SUM(沪深两市成交汇总!C123:'沪深两市成交汇总'!C183)) -> 449393337000 | J24: =IF(I24="--","",I24/I25-1) -> -0.053117598 | K24: =IF(E7=TODAY(),IF(NOW()-TODAY()>TIME(11,30,0),SUM(沪深两市成交汇总!C184:C243),"--"),SUM(沪深两市成交汇总!C184:C243)) -> 522463898500 | L24: =IF(K24="--","",K24/K25-1) -> 0.13738245
D25: 前一日 | E25: =SUM(沪深两市成交汇总!B2:B62) -> 1264645351600 | G25: =SUM(沪深两市成交汇总!B63:B122) -> 394431785400 | I25: =SUM(沪深两市成交汇总!B123:'沪深两市成交汇总'!B183) -> 474603114500 | K25: =SUM(沪深两市成交汇总!B184:B243) -> 459356390000
D29: 统计开始日期: | E29: =O1-720 -> 44845
D31: ="日均（周度）成交额及同比变化" -> 日均（周度）成交额及同比变化

Sheet 沪深两市实时成交明细
A1: 代码 | B1: 000001.SH | D1: 代码 | E1: 399001.SZ
A2: 简称 | B2: 上证指数 | D2: 简称 | E2: 深证成指
A3: 成交额 | B3: =RTD("wdf.rtq", ,"000001.SH", "rt_amt","RT_Price") -> 1510513250800 | D3: 成交额 | E3: =RTD("wdf.rtq", ,"399001.SZ", "rt_amt","RT_Price") -> 1941425791400

Sheet 沪深两市历史成交
B1: 成交额 [单位]亿元
B2: amt
A3: Date | B3: 000001.SH | C3: 399001.SZ | F3: Date | J3: =COUNT(F:F)-2 -> 99
A4: 日期 | B4: =[1]!S_Info_Name(B3) -> 上证指数 | C4: =[1]!S_Info_Name(C3) -> 深证成指 | D4: 两市合计 | E4: 区间交易天数 | F4: 日期 | G4: 日均成交额 | H4: 环比变化
A5: 45565 | B5: =[1]!WSD(B3:C3,B2,沪深两市成交分析!E29,沪深两市成交分析!O1,"unit=100000000","Per=W","TradingCalendar=SSE","Sort=D","rptType=1","ShowParams=Y","cols=2;rows=101") -> 11677.726 | C5: 14252.641 | D5: =IF(B5+C5=0,"",B5+C5) -> 25930.366 | E5: =IF(D5="","",[1]!i_pq_tradedays($B$3,A6,A5)-1) -> 1 | F5: =IF(D5="","",A5) -> 45565 | G5: =IF(D5="","",D5/E5) -> 25930.366 | H5: =IF(D5="","",G5/G6-1) -> 1.4517399
A6: 45562 | B6: 21999.895 | C6: 30881.665 | D6: =IF(B6+C6=0,"",B6+C6) -> 52881.56 | E6: =IF(D6="","",[1]!i_pq_tradedays($B$3,A7,A6)-1) -> 5 | F6: =IF(D6="","",A6) -> 45562 | G6: =IF(D6="","",D6/E6) -> 10576.312 | H6: =IF(D6="","",G6/G7-1) -> 0.88741679
A7: 45555 | B7: 7490.5996 | C7: 9320.1737 | D7: =IF(B7+C7=0,"",B7+C7) -> 16810.773 | E7: =IF(D7="","",[1]!i_pq_tradedays($B$3,A8,A7)-1) -> 3 | F7: =IF(D7="","",A7) -> 45555 | G7: =IF(D7="","",D7/E7) -> 5603.5911 | H7: =IF(D7="","",G7/G8-1) -> 0.083377428
A8: 45548 | B8: 11291.602 | C8: 14570.074 | D8: =IF(B8+C8=0,"",B8+C8) -> 25861.676 | E8: =IF(D8="","",[1]!i_pq_tradedays($B$3,A9,A8)-1) -> 5 | F8: =IF(D8="","",A8) -> 45548 | G8: =IF(D8="","",D8/E8) -> 5172.3351 | H8: =IF(D8="","",G8/G9-1) -> -0.11529095
A9: 45541 | B9: 12583.919 | C9: 16647.924 | D9: =IF(B9+C9=0,"",B9+C9) -> 29231.842 | E9: =IF(D9="","",[1]!i_pq_tradedays($B$3,A10,A9)-1) -> 5 | F9: =IF(D9="","",A9) -> 45541 | G9: =IF(D9="","",D9/E9) -> 5846.3685 | H9: =IF(D9="","",G9/G10-1) -> -0.031553359
A10: 45534 | B10: 12880.925 | C10: 17303.332 | D10: =IF(B10+C10=0,"",B10+C10) -> 30184.257 | E10: =IF(D10="","",[1]!i_pq_tradedays($B$3,A11,A10)-1) -> 5 | F10: =IF(D10="","",A10) -> 45534 | G10: =IF(D10="","",D10/E10) -> 6036.8514 | H10: =IF(D10="","",G10/G11-1) -> 0.11904075
A11: 45527 | B11: 11349.179 | C11: 15624.153 | D11: =IF(B11+C11=0,"",B11+C11) -> 26973.332 | E11: =IF(D11="","",[1]!i_pq_tradedays($B$3,A12,A11)-1) -> 5 | F11: =IF(D11="","",A11) -> 45527 | G11: =IF(D11="","",D11/E11) -> 5394.6663 | H11: =IF(D11="","",G11/G12-1) -> 0.024302351
A12: 45520 | B12: 11345.881 | C12: 14987.488 | D12: =IF(B12+C12=0,"",B12+C12) -> 26333.369 | E12: =IF(D12="","",[1]!i_pq_tradedays($B$3,A13,A12)-1) -> 5 | F12: =IF(D12="","",A12) -> 45520 | G12: =IF(D12="","",D12/E12) -> 5266.6738 | H12: =IF(D12="","",G12/G13-1) -> -0.18210704
A13: 45513 | B13: 14404.842 | C13: 17791.754 | D13: =IF(B13+C13=0,"",B13+C13) -> 32196.595 | E13: =IF(D13="","",[1]!i_pq_tradedays($B$3,A14,A13)-1) -> 5 | F13: =IF(D13="","",A13) -> 45513 | G13: =IF(D13="","",D13/E13) -> 6439.3191 | H13: =IF(D13="","",G13/G14-1) -> -0.10398953
A14: 45506 | B14: 16159.482 | C14: 19773.798 | D14: =IF(B14+C14=0,"",B14+C14) -> 35933.28 | E14: =IF(D14="","",[1]!i_pq_tradedays($B$3,A15,A14)-1) -> 5 | F14: =IF(D14="","",A14) -> 45506 | G14: =IF(D14="","",D14/E14) -> 7186.6561 | H14: =IF(D14="","",G14/G15-1) -> 0.14414213
A15: 45499 | B15: 14609.949 | C15: 16796.359 | D15: =IF(B15+C15=0,"",B15+C15) -> 31406.308 | E15: =IF(D15="","",[1]!i_pq_tradedays($B$3,A16,A15)-1) -> 5 | F15: =IF(D15="","",A15) -> 45499 | G15: =IF(D15="","",D15/E15) -> 6281.2616 | H15: =IF(D15="","",G15/G16-1) -> -0.036617331
A16: 45492 | B16: 14737.2 | C16: 17862.834 | D16: =IF(B16+C16=0,"",B16+C16) -> 32600.034 | E16: =IF(D16="","",[1]!i_pq_tradedays($B$3,A17,A16)-1) -> 5 | F16: =IF(D16="","",A16) -> 45492 | G16: =IF(D16="","",D16/E16) -> 6520.0069 | H16: =IF(D16="","",G16/G17-1) -> -0.05723912
A17: 45485 | B17: 15375.031 | C17: 19204.293 | D17: =IF(B17+C17=0,"",B17+C17) -> 34579.325 | E17: =IF(D17="","",[1]!i_pq_tradedays($B$3,A18,A17)-1) -> 5 | F17: =IF(D17="","",A17) -> 45485 | G17: =IF(D17="","",D17/E17) -> 6915.8649 | H17: =IF(D17="","",G17/G18-1) -> 0.13711559
... A105: 44848 | B105: 15335.225 | C105: 19576.482 | D105: =IF(B105+C105=0,"",B105+C105) -> 34911.706 | E105: =IF(D105="","",[1]!i_pq_tradedays($B$3,A106,A105)-1) -> -1 | F105: =IF(D105="","",A105) -> 44848 | G105: =IF(D105="","",D105/E105) -> -34911.706 | H105: =IF(D105="","",G105/G106-1) -> #VALUE!
D106: =IF(B106+C106=0,"",B106+C106) | E106: =IF(D106="","",[1]!i_pq_tradedays($B$3,A107,A106)-1) | F106: =IF(D106="","",A106) | G106: =IF(D106="","",D106/E106) | H106: =IF(D106="","",G106/G107-1)
D107: =IF(B107+C107=0,"",B107+C107) | E107: =IF(D107="","",[1]!i_pq_tradedays($B$3,A108,A107)-1) | F107: =IF(D107="","",A107) | G107: =IF(D107="","",D107/E107) | H107: =IF(D107="","",G107/G108-1)
D108: =IF(B108+C108=0,"",B108+C108) | E108: =IF(D108="","",[1]!i_pq_tradedays($B$3,A109,A108)-1) | F108: =IF(D108="","",A108) | G108: =IF(D108="","",D108/E108) | H108: =IF(D108="","",G108/G109-1)
D109: =IF(B109+C109=0,"",B109+C109) | E109: =IF(D109="","",[1]!i_pq_tradedays($B$3,A110,A109)-1) | F109: =IF(D109="","",A109) | G109: =IF(D109="","",D109/E109) | H109: =IF(D109="","",G109/G110-1)
D110: =IF(B110+C110=0,"",B110+C110) | E110: =IF(D110="","",[1]!i_pq_tradedays($B$3,A111,A110)-1) | F110: =IF(D110="","",A110) | G110: =IF(D110="","",D110/E110) | H110: =IF(D110="","",G110/G111-1)
D111: =IF(B111+C111=0,"",B111+C111) | E111: =IF(D111="","",[1]!i_pq_tradedays($B$3,A112,A111)-1) | F111: =IF(D111="","",A111) | G111: =IF(D111="","",D111/E111) | H111: =IF(D111="","",G111/G112-1)
D112: =IF(B112+C112=0,"",B112+C112) | E112: =IF(D112="","",[1]!i_pq_tradedays($B$3,A113,A112)-1) | F112: =IF(D112="","",A112) | G112: =IF(D112="","",D112/E112) | H112: =IF(D112="","",G112/G113-1)
D113: =IF(B113+C113=0,"",B113+C113) | E113: =IF(D113="","",[1]!i_pq_tradedays($B$3,A114,A113)-1) | F113: =IF(D113="","",A113) | G113: =IF(D113="","",D113/E113) | H113: =IF(D113="","",G113/G114-1)
D114: =IF(B114+C114=0,"",B114+C114) | E114: =IF(D114="","",[1]!i_pq_tradedays($B$3,A115,A114)-1) | F114: =IF(D114="","",A114) | G114: =IF(D114="","",D114/E114) | H114: =IF(D114="","",G114/G115-1)
D115: =IF(B115+C115=0,"",B115+C115) | E115: =IF(D115="","",[1]!i_pq_tradedays($B$3,A116,A115)-1) | F115: =IF(D115="","",A115) | G115: =IF(D115="","",D115/E115) | H115: =IF(D115="","",G115/G116-1)
D116: =IF(B116+C116=0,"",B116+C116) | E116: =IF(D116="","",[1]!i_pq_tradedays($B$3,A117,A116)-1) | F116: =IF(D116="","",A116) | G116: =IF(D116="","",D116/E116) | H116: =IF(D116="","",G116/G117-1)
D117: =IF(B117+C117=0,"",B117+C117) | E117: =IF(D117="","",[1]!i_pq_tradedays($B$3,A118,A117)-1) | F117: =IF(D117="","",A117) | G117: =IF(D117="","",D117/E117) | H117: =IF(D117="","",G117/G118-1)
... D500: =IF(B500+C500=0,"",B500+C500) | E500: =IF(D500="","",[1]!i_pq_tradedays($B$3,A501,A500)-1) | F500: =IF(D500="","",A500) | G500: =IF(D500="","",D500/E500) | H500: =IF(D500="","",G500/G501-1)
E501: =IF(LEN(D501)=0,"",[1]!i_pq_tradedays($B$3,A502,A501)-1) | G501: =IF(LEN(D501)=0,"",D501/E501) | H501: =IF(LEN(D501)=0,"",G501/G502-1)
E502: =IF(LEN(D502)=0,"",[1]!i_pq_tradedays($B$3,A503,A502)-1) | G502: =IF(LEN(D502)=0,"",D502/E502) | H502: =IF(LEN(D502)=0,"",G502/G503-1)
E503: =IF(LEN(D503)=0,"",[1]!i_pq_tradedays($B$3,A504,A503)-1) | G503: =IF(LEN(D503)=0,"",D503/E503) | H503: =IF(LEN(D503)=0,"",G503/G504-1)
E504: =IF(LEN(D504)=0,"",[1]!i_pq_tradedays($B$3,A505,A504)-1) | G504: =IF(LEN(D504)=0,"",D504/E504) | H504: =IF(LEN(D504)=0,"",G504/G505-1)
E505: =IF(LEN(D505)=0,"",[1]!i_pq_tradedays($B$3,A506,A505)-1) | G505: =IF(LEN(D505)=0,"",D505/E505) | H505: =IF(LEN(D505)=0,"",G505/G506-1)
E506: =IF(LEN(D506)=0,"",[1]!i_pq_tradedays($B$3,A507,A506)-1) | G506: =IF(LEN(D506)=0,"",D506/E506) | H506: =IF(LEN(D506)=0,"",G506/G507-1)
E507: =IF(LEN(D507)=0,"",[1]!i_pq_tradedays($B$3,A508,A507)-1) | G507: =IF(LEN(D507)=0,"",D507/E507) | H507: =IF(LEN(D507)=0,"",G507/G508-1)
E508: =IF(LEN(D508)=0,"",[1]!i_pq_tradedays($B$3,A509,A508)-1) | G508: =IF(LEN(D508)=0,"",D508/E508) | H508: =IF(LEN(D508)=0,"",G508/G509-1)
E509: =IF(LEN(D509)=0,"",[1]!i_pq_tradedays($B$3,A510,A509)-1) | G509: =IF(LEN(D509)=0,"",D509/E509) | H509: =IF(LEN(D509)=0,"",G509/G510-1)
...

Sheet 沪深两市成交汇总
A1: 时间 | B1: 昨日两市合计 | C1: 今日两市合计 | D1: 昨日累计成交 | E1: 今日累计成交 | F1: 暂无
A2: 0.39583333 | B2: =沪市成交情况!B4+深市成交情况!B4 -> 130046348100 | C2: =IF(沪深两市成交分析!$E$7<>TODAY(),沪市成交情况!D4+深市成交情况!D4,IF(NOW()-TODAY()-A2>0.0007,沪市成交情况!D4+深市成交情况!D4,0)) -> 222592675100 | D2: =SUM(B$2:B2)/100000000 -> 1300.4635 | E2: =IF(C2=0,NA(),SUM(C$2:C2)/100000000) -> 2225.9268 | F2: =IF(C2=0,0,E2-D2) -> 925.46327
A3: 0.39652778 | B3: =沪市成交情况!B5+深市成交情况!B5 -> 59453842500 | C3: =IF(沪深两市成交分析!$E$7<>TODAY(),沪市成交情况!D5+深市成交情况!D5,IF(NOW()-TODAY()-A3>0.0007,沪市成交情况!D5+深市成交情况!D5,0)) -> 67912915700 | D3: =SUM(B$2:B3)/100000000 -> 1895.0019 | E3: =IF(C3=0,NA(),SUM(C$2:C3)/100000000) -> 2905.0559 | F3: =IF(C3=0,0,E3-D3) -> 1010.054
A4: 0.39722222 | B4: =沪市成交情况!B6+深市成交情况!B6 -> 45667410300 | C4: =IF(沪深两市成交分析!$E$7<>TODAY(),沪市成交情况!D6+深市成交情况!D6,IF(NOW()-TODAY()-A4>0.0007,沪市成交情况!D6+深市成交情况!D6,0)) -> 54204303400 | D4: =SUM(B$2:B4)/100000000 -> 2351.676 | E4: =IF(C4=0,NA(),SUM(C$2:C4)/100000000) -> 3447.0989 | F4: =IF(C4=0,0,E4-D4) -> 1095.4229
A5: 0.39791667 | B5: =沪市成交情况!B7+深市成交情况!B7 -> 40411378600 | C5: =IF(沪深两市成交分析!$E$7<>TODAY(),沪市成交情况!D7+深市成交情况!D7,IF(NOW()-TODAY()-A5>0.0007,沪市成交情况!D7+深市成交情况!D7,0)) -> 50646606500 | D5: =SUM(B$2:B5)/100000000 -> 2755.7898 | E5: =IF(C5=0,NA(),SUM(C$2:C5)/100000000) -> 3953.565 | F5: =IF(C5=0,0,E5-D5) -> 1197.7752
A6: 0.39861111 | B6: =沪市成交情况!B8+深市成交情况!B8 -> 38990879900 | C6: =IF(沪深两市成交分析!$E$7<>TODAY(),沪市成交情况!D8+深市成交情况!D8,IF(NOW()-TODAY()-A6>0.0007,沪市成交情况!D8+深市成交情况!D8,0)) -> 46264056800 | D6: =SUM(B$2:B6)/100000000 -> 3145.6986 | E6: =IF(C6=0,NA(),SUM(C$2:C6)/100000000) -> 4416.2056 | F6: =IF(C6=0,0,E6-D6) -> 1270.507
A7: 0.39930556 | B7: =沪市成交情况!B9+深市成交情况!B9 -> 35530323900 | C7: =IF(沪深两市成交分析!$E$7<>TODAY(),沪市成交情况!D9+深市成交情况!D9,IF(NOW()-TODAY()-A7>0.0007,沪市成交情况!D9+深市成交情况!D9,0)) -> 44429552300 | D7: =SUM(B$2:B7)/100000000 -> 3501.0018 | E7: =IF(C7=0,NA(),SUM(C$2:C7)/100000000) -> 4860.5011 | F7: =IF(C7=0,0,E7-D7) -> 1359.4993
A8: 0.4 | B8: =沪市成交情况!B10+深市成交情况!B10 -> 33437907800 | C8: =IF(沪深两市成交分析!$E$7<>TODAY(),沪市成交情况!D10+深市成交情况!D10,IF(NOW()-TODAY()-A8>0.0007,沪市成交情况!D10+深市成交情况!D10,0)) -> 39461889600 | D8: =SUM(B$2:B8)/100000000 -> 3835.3809 | E8: =IF(C8=0,NA(),SUM(C$2:C8)/100000000) -> 5255.12 | F8: =IF(C8=0,0,E8-D8) -> 1419.7391
A9: 0.40069444 | B9: =沪市成交情况!B11+深市成交情况!B11 -> 30179651300 | C9: =IF(沪深两市成交分析!$E$7<>TODAY(),沪市成交情况!D11+深市成交情况!D11,IF(NOW()-TODAY()-A9>0.0007,沪市成交情况!D11+深市成交情况!D11,0)) -> 37627257300 | D9: =SUM(B$2:B9)/100000000 -> 4137.1774 | E9: =IF(C9=0,NA(),SUM(C$2:C9)/100000000) -> 5631.3926 | F9: =IF(C9=0,0,E9-D9) -> 1494.2151
A10: 0.40138889 | B10: =沪市成交情况!B12+深市成交情况!B12 -> 30923059200 | C10: =IF(沪深两市成交分析!$E$7<>TODAY(),沪市成交情况!D12+深市成交情况!D12,IF(NOW()-TODAY()-A10>0.0007,沪市成交情况!D12+深市成交情况!D12,0)) -> 36585759900 | D10: =SUM(B$2:B10)/100000000 -> 4446.408 | E10: =IF(C10=0,NA(),SUM(C$2:C10)/100000000) -> 5997.2502 | F10: =IF(C10=0,0,E10-D10) -> 1550.8421
A11: 0.40208333 | B11: =沪市成交情况!B13+深市成交情况!B13 -> 32669457000 | C11: =IF(沪深两市成交分析!$E$7<>TODAY(),沪市成交情况!D13+深市成交情况!D13,IF(NOW()-TODAY()-A11>0.0007,沪市成交情况!D13+深市成交情况!D13,0)) -> 38715426300 | D11: =SUM(B$2:B11)/100000000 -> 4773.1026 | E11: =IF(C11=0,NA(),SUM(C$2:C11)/100000000) -> 6384.4044 | F11: =IF(C11=0,0,E11-D11) -> 1611.3018
A12: 0.40277778 | B12: =沪市成交情况!B14+深市成交情况!B14 -> 35779855400 | C12: =IF(沪深两市成交分析!$E$7<>TODAY(),沪市成交情况!D14+深市成交情况!D14,IF(NOW()-TODAY()-A12>0.0007,沪市成交情况!D14+深市成交情况!D14,0)) -> 41132595100 | D12: =SUM(B$2:B12)/100000000 -> 5130.9011 | E12: =IF(C12=0,NA(),SUM(C$2:C12)/100000000) -> 6795.7304 | F12: =IF(C12=0,0,E12-D12) -> 1664.8292
A13: 0.40347222 | B13: =沪市成交情况!B15+深市成交情况!B15 -> 31093196600 | C13: =IF(沪深两市成交分析!$E$7<>TODAY(),沪市成交情况!D15+深市成交情况!D15,IF(NOW()-TODAY()-A13>0.0007,沪市成交情况!D15+深市成交情况!D15,0)) -> 36220022700 | D13: =SUM(B$2:B13)/100000000 -> 5441.8331 | E13: =IF(C13=0,NA(),SUM(C$2:C13)/100000000) -> 7157.9306 | F13: =IF(C13=0,0,E13-D13) -> 1716.0975
... A243: 0.625 | B243: =沪市成交情况!B245+深市成交情况!B245 -> 18591619500 | C243: =IF(沪深两市成交分析!$E$7<>TODAY(),沪市成交情况!D245+深市成交情况!D245,IF(NOW()-TODAY()-A243>0.0007,沪市成交情况!D245+深市成交情况!D245,0)) -> 24534199400 | D243: =SUM(B$2:B243)/100000000 -> 25930.366 | E243: =IF(C243=0,NA(),SUM(C$2:C243)/100000000) -> 34519.39 | F243: =IF(C243=0,0,E243-D243) -> 8589.024

Sheet 沪市成交情况
A1: 000001.SH | B1: =[1]!S_Info_Name($A$1) -> 上证指数 | C1: 000001.SH | D1: =[1]!S_Info_Name($A$1) -> 上证指数
A2: 时间 | B2: 成交额 | C2: 时间 | D2: 成交额 | F2: =TEXT(G9,"yyyy-mm-dd")&" 9:29:00" -> 2024-09-30 9:29:00 | G2: =TEXT(G9,"yyyy-mm-dd")&" 15:00:00" -> 2024-09-30 15:00:00
A3: time | B3: amt | C3: time | D3: amt | F3: =TEXT(G10,"yyyy-mm-dd")&" 9:29:00" -> 2024-10-08 9:29:00 | G3: =IF(G10<>TODAY(),TEXT(G10,"yyyy-mm-dd")&" 15:00:00",TEXT(G10,"yyyy-mm-dd")&" "& G5) -> 2024-10-08 15:00:00
A4: =[1]!WSI(A1,B3,F2,G2,"cols=2;rows=242") -> 2024-09-30 09:30 | B4: 52148147900 | C4: =[1]!WSI(C1,D3,F3,G3,"cols=2;rows=242") -> 2024-10-08 09:30 | D4: 93434101300
A5: 45565.397 | B5: 26213087900 | C5: 45573.397 | D5: 29434234500 | F5: 行情刷新分钟 | G5: =LEFT(G6,6)&"00" -> 15:00:00
A6: 45565.397 | B6: 20046799200 | C6: 45573.397 | D6: 22817497300 | F6: 行情刷新时间 | G6: =RTD("wdf.rtq", , A1, "rt_time","RT_Price") -> 15:00:03
A7: 45565.398 | B7: 18349949500 | C7: 45573.398 | D7: 21636107100
A8: 45565.399 | B8: 18156624600 | C8: 45573.399 | D8: 21315144700
A9: 45565.399 | B9: 15754509600 | C9: 45573.399 | D9: 20319539100 | F9: 前一工作日 | G9: =[1]!TDaysOffset(G10,"Offset=-1") -> 45565
A10: 45565.4 | B10: 15158221300 | C10: 45573.4 | D10: 16451688300 | F10: 查询日期 | G10: =沪深两市成交分析!E7 -> 45573
A11: 45565.401 | B11: 13661465100 | C11: 45573.401 | D11: 16689933100
A12: 45565.401 | B12: 13609328700 | C12: 45573.401 | D12: 15507442100
A13: 45565.402 | B13: 14275606000 | C13: 45573.402 | D13: 16907939600
A14: 45565.403 | B14: 15578249600 | C14: 45573.403 | D14: 16921891000
A15: 45565.403 | B15: 13492874600 | C15: 45573.403 | D15: 15019093300
A16: 45565.404 | B16: 11603648900 | C16: 45573.404 | D16: 15070553000
A17: 45565.405 | B17: 9380303600 | C17: 45573.405 | D17: 16953828100
A18: 45565.406 | B18: 11330900200 | C18: 45573.406 | D18: 15618280100
A19: 45565.406 | B19: 11214908500 | C19: 45573.406 | D19: 17528395600
A20: 45565.407 | B20: 10096701200 | C20: 45573.407 | D20: 15903247300
A21: 45565.408 | B21: 10385941000 | C21: 45573.408 | D21: 13803676000
A22: 45565.408 | B22: 11038036800 | C22: 45573.408 | D22: 13071603000
... A245: 45565.625 | B245: 8130581400 | C245: 45573.625 | D245: 10749302200

Sheet 深市成交情况
A1: 399001.SZ | B1: =[1]!S_Info_Name(A1) -> 深证成指 | C1: 399001.SZ | D1: =[1]!S_Info_Name(C1) -> 深证成指
A2: 时间 | B2: 成交额 | C2: 时间 | D2: 成交额 | F2: =TEXT(G9,"yyyy-mm-dd")&" 9:29:00" -> 2024-09-30 9:29:00 | G2: =TEXT(G9,"yyyy-mm-dd")&" 15:00:00" -> 2024-09-30 15:00:00
A3: time | B3: amt | C3: time | D3: amt | F3: =TEXT(G10,"yyyy-mm-dd")&" 9:29:00" -> 2024-10-08 9:29:00 | G3: =IF(G10<>TODAY(),TEXT(G10,"yyyy-mm-dd")&" 15:00:00",TEXT(G10,"yyyy-mm-dd")&" "& G5) -> 2024-10-08 15:00:00
A4: =[1]!WSI(A1,B3,F2,G2,"cols=2;rows=242") -> 2024-09-30 09:30 | B4: 77898200200 | C4: =[1]!WSI(C1,D3,F3,G3,"cols=2;rows=242") -> 2024-10-08 09:30 | D4: 129158573800
A5: 45565.397 | B5: 33240754600 | C5: 45573.397 | D5: 38478681200 | F5: 行情刷新分钟 | G5: =LEFT(G6,6)&"00" -> 15:00:00
A6: 45565.397 | B6: 25620611100 | C6: 45573.397 | D6: 31386806100 | F6: 行情刷新时间 | G6: =RTD("wdf.rtq", , A1, "rt_time","RT_Price") -> 15:00:03
A7: 45565.398 | B7: 22061429100 | C7: 45573.398 | D7: 29010499400
A8: 45565.399 | B8: 20834255300 | C8: 45573.399 | D8: 24948912100
A9: 45565.399 | B9: 19775814300 | C9: 45573.399 | D9: 24110013200 | F9: 前一工作日 | G9: =[1]!TDaysOffset(G10,"Offset=-1") -> 45565
A10: 45565.4 | B10: 18279686500 | C10: 45573.4 | D10: 23010201300 | F10: 查询日期 | G10: =沪深两市成交分析!E7 -> 45573
A11: 45565.401 | B11: 16518186200 | C11: 45573.401 | D11: 20937324200
A12: 45565.401 | B12: 17313730500 | C12: 45573.401 | D12: 21078317800
A13: 45565.402 | B13: 18393851000 | C13: 45573.402 | D13: 21807486700
A14: 45565.403 | B14: 20201605800 | C14: 45573.403 | D14: 24210704100
A15: 45565.403 | B15: 17600322000 | C15: 45573.403 | D15: 21200929400
A16: 45565.404 | B16: 13794214000 | C16: 45573.404 | D16: 20742824000
A17: 45565.405 | B17: 12482400300 | C17: 45573.405 | D17: 21049437300
A18: 45565.406 | B18: 13173098900 | C18: 45573.406 | D18: 22465978800
A19: 45565.406 | B19: 13795926400 | C19: 45573.406 | D19: 23828812500
A20: 45565.407 | B20: 11817699900 | C20: 45573.407 | D20: 21024563900
A21: 45565.408 | B21: 13928305400 | C21: 45573.408 | D21: 17496530600
A22: 45565.408 | B22: 14942746000 | C22: 45573.408 | D22: 17032728400
... A245: 45565.625 | B245: 10461038100 | C245: 45573.625 | D245: 13784897200
