Workbook
Name 主力净流入: IF(COUNT(资金流向数据!$I:$I) > 0,OFFSET(资金流向数据!$I$6,0,0,COUNT(资金流向数据!$I:$I)),0)

Sheet Wind模板
A1: 行业资金流向

Sheet 行业资金流向
E1: 行业资金流向 V1.1 | K1: 最近更新： | L1: =[1]!TDaysOffset(TODAY(),"Offset=-1") -> 46101
D4: 行业板块： | E4: wind行业二级
D6: 实时行业资金流向（亿元）
D21: 行业板块： | E21: wind行业二级 | G21: 查询日期: | H21: =[1]!TDaysOffset(TODAY(),"Offset=-1") -> 46101 | J21: 统计区间（天）： | K21: 5
D23: 行业资金流向统计（亿元）

Sheet 资金流向数据
B1: 数据集名称 | C1: 板块成分 | K1: 板块名称 | L1: 板块ID | O1: 数据集名称 | P1: 行业资金流向
B2: 日期 | C2: =TEXT(行业资金流向!L1,"YYYYMMDD") -> 20260320 | K2: wind行业一级 | L2: a39901011p000000 | O2: 截止日期 | P2: =TEXT(行业资金流向!H21,"YYYYMMDD") -> 20260320
B3: 板块ID | C3: =VLOOKUP(行业资金流向!E4,资金流向数据!K:L,2,0) -> a39901011q000000 | K3: wind行业二级 | L3: a39901011q000000 | O3: 统计区间 | P3: =行业资金流向!K21&"日" -> 5日
B4: date | C4: wind_code | D4: sec_name | K4: 申万行业一级 | L4: a39901011g000000 | O4: 行业分类 | P4: =行业资金流向!E21 -> wind行业二级
A5: 主力净流入(降序) | B5: 最新调整日期 | C5: Wind代码 | D5: 证券名称 | E5: 主力净流入 | G5: 序列 | H5: 证券名称 | I5: 主力净流入(亿元) | K5: 申万行业二级 | L5: a39901011h000000 | O5: industryName | P5: mainInflowMoney | Q5: swapNumber | R5: continuousInflowDays | T5: 序列 | V5: 主力净流入额(万元) | W5: 成交额(万元) | X5: 连续流入天数
A6: =IFERROR(RANK(E6,$E$6:$E$129),"") -> 10 | B6: =[1]!wset("sectorconstituent","date="&C2,"sectorId="&C3,"field=date,wind_code,sec_name","cols=3;rows=35") -> 46101 | C6: 882100.WI | D6: 石油石化 | E6: =IF(C6="","",RTD("wdf.rtq", ,C6, "rt_mf_amt","RT_Price")) -> 391409012 | G6: 1 | H6: =IF(D6="","",VLOOKUP(G6,A:E,4,0)) -> 化工 | I6: =IF(D6="","",VLOOKUP(G6,A:E,5,0)) -> 4849838049 | K6: Wind主题行业 | L6: a39901012d000000 | N6: 主力净流入(降序) | O6: 行业 | P6: 主力净流入额(万元) | Q6: 成交额(万元) | R6: 连续流入天数 | T6: 1 | U6: =IF(O7="","",VLOOKUP(T6,N:R,2,0)) -> Wind资本货物 | V6: =IF(O7="","",VLOOKUP(T6,N:R,3,0)) -> -3397499.7 | W6: =IF(O7="","",VLOOKUP(T6,N:R,4,0)) -> 2.2589787e+08 | X6: =IF(O7="","",VLOOKUP(T6,N:R,5,0)) -> -2
A7: =IFERROR(RANK(E7,$E$6:$E$129),"") -> 1 | B7: 46101 | C7: 882101.WI | D7: 化工 | E7: =IF(C7="","",RTD("wdf.rtq", ,C7, "rt_mf_amt","RT_Price")) -> 4849838049 | G7: 2 | H7: =IF(D7="","",VLOOKUP(G7,A:E,4,0)) -> 汽车与零配件 | I7: =IF(D7="","",VLOOKUP(G7,A:E,5,0)) -> 4189815323 | K7: Wind省级指数 | L7: 1000047025000000 | N7: =IFERROR(RANK(Q7,$Q$7:$Q$129),"") -> 18 | O7: =[1]!wset("industrymoneyflow","endDate="&P2,"span="&P3,"sectorIndex="&P4,"field=industryName,mainInflowMoney,swapNumber,continuousInflowDays,","cols=4;rows=24") -> Wind房地产Ⅱ | P7: -143499.16 | Q7: 9522565.2 | R7: -3 | T7: 2 | U7: =IF(O8="","",VLOOKUP(T7,N:R,2,0)) -> Wind材料Ⅱ | V7: =IF(O8="","",VLOOKUP(T7,N:R,3,0)) -> -5631205.3 | W7: =IF(O8="","",VLOOKUP(T7,N:R,4,0)) -> 2.0426828e+08 | X7: =IF(O8="","",VLOOKUP(T7,N:R,5,0)) -> -5
A8: =IFERROR(RANK(E8,$E$6:$E$129),"") -> 8 | B8: 46101 | C8: 882102.WI | D8: 国防军工 | E8: =IF(C8="","",RTD("wdf.rtq", ,C8, "rt_mf_amt","RT_Price")) -> 857296014 | G8: 3 | H8: =IF(D8="","",VLOOKUP(G8,A:E,4,0)) -> 电气设备 | I8: =IF(D8="","",VLOOKUP(G8,A:E,5,0)) -> 3741169640 | N8: =IFERROR(RANK(Q8,$Q$7:$Q$129),"") -> 9 | O8: Wind能源Ⅱ | P8: -289197.9 | Q8: 29339739 | R8: -1 | T8: 3 | U8: =IF(O9="","",VLOOKUP(T8,N:R,2,0)) -> Wind技术硬件与设备 | V8: =IF(O9="","",VLOOKUP(T8,N:R,3,0)) -> -2159957.8 | W8: =IF(O9="","",VLOOKUP(T8,N:R,4,0)) -> 2.0285558e+08 | X8: =IF(O9="","",VLOOKUP(T8,N:R,5,0)) -> -2
A9: =IFERROR(RANK(E9,$E$6:$E$129),"") -> 12 | B9: 46101 | C9: 882103.WI | D9: 企业服务 | E9: =IF(C9="","",RTD("wdf.rtq", ,C9, "rt_mf_amt","RT_Price")) -> 120592756 | G9: 4 | H9: =IF(D9="","",VLOOKUP(G9,A:E,4,0)) -> 有色金属 | I9: =IF(D9="","",VLOOKUP(G9,A:E,5,0)) -> 3687179869 | N9: =IFERROR(RANK(Q9,$Q$7:$Q$129),"") -> 14 | O9: Wind商业和专业服务 | P9: -310943.94 | Q9: 14537807 | R9: -2 | T9: 4 | U9: =IF(O10="","",VLOOKUP(T9,N:R,2,0)) -> Wind半导体与半导体生产设备 | V9: =IF(O10="","",VLOOKUP(T9,N:R,3,0)) -> -545632.77 | W9: =IF(O10="","",VLOOKUP(T9,N:R,4,0)) -> 97959539 | X9: =IF(O10="","",VLOOKUP(T9,N:R,5,0)) -> 1
A10: =IFERROR(RANK(E10,$E$6:$E$129),"") -> 29 | B10: 46101 | C10: 882104.WI | D10: 交通运输 | E10: =IF(C10="","",RTD("wdf.rtq", ,C10, "rt_mf_amt","RT_Price")) -> -1647711971 | G10: 5 | H10: =IF(D10="","",VLOOKUP(G10,A:E,4,0)) -> 造纸与包装 | I10: =IF(D10="","",VLOOKUP(G10,A:E,5,0)) -> 3327513353 | N10: =IFERROR(RANK(Q10,$Q$7:$Q$129),"") -> 21 | O10: Wind消费者服务Ⅱ | P10: -105631.15 | Q10: 2962036.3 | R10: -5 | T10: 5 | U10: =IF(O11="","",VLOOKUP(T10,N:R,2,0)) -> Wind软件与服务 | V10: =IF(O11="","",VLOOKUP(T10,N:R,3,0)) -> -1526151.6 | W10: =IF(O11="","",VLOOKUP(T10,N:R,4,0)) -> 77243017 | X10: =IF(O11="","",VLOOKUP(T10,N:R,5,0)) -> -2
A11: =IFERROR(RANK(E11,$E$6:$E$129),"") -> 2 | B11: 46101 | C11: 882105.WI | D11: 汽车与零配件 | E11: =IF(C11="","",RTD("wdf.rtq", ,C11, "rt_mf_amt","RT_Price")) -> 4189815323 | G11: 6 | H11: =IF(D11="","",VLOOKUP(G11,A:E,4,0)) -> 公用事业Ⅱ | I11: =IF(D11="","",VLOOKUP(G11,A:E,5,0)) -> 1903448658 | N11: =IFERROR(RANK(Q11,$Q$7:$Q$129),"") -> 17 | O11: Wind媒体Ⅱ | P11: -466916.21 | Q11: 12726187 | R11: -2 | T11: 6 | U11: =IF(O12="","",VLOOKUP(T11,N:R,2,0)) -> Wind公用事业Ⅱ | V11: =IF(O12="","",VLOOKUP(T11,N:R,3,0)) -> -204223.55 | W11: =IF(O12="","",VLOOKUP(T11,N:R,4,0)) -> 44421153 | X11: =IF(O12="","",VLOOKUP(T11,N:R,5,0)) -> -1
A12: =IFERROR(RANK(E12,$E$6:$E$129),"") -> 16 | B12: 46101 | C12: 882106.WI | D12: 耐用消费品 | E12: =IF(C12="","",RTD("wdf.rtq", ,C12, "rt_mf_amt","RT_Price")) -> -63477959 | G12: 7 | H12: =IF(D12="","",VLOOKUP(G12,A:E,4,0)) -> 煤炭Ⅱ | I12: =IF(D12="","",VLOOKUP(G12,A:E,5,0)) -> 1573061315 | N12: =IFERROR(RANK(Q12,$Q$7:$Q$129),"") -> 19 | O12: Wind零售业 | P12: -108327.81 | Q12: 4648291 | R12: -5 | T12: 7 | U12: =IF(O13="","",VLOOKUP(T12,N:R,2,0)) -> Wind汽车与汽车零部件 | V12: =IF(O13="","",VLOOKUP(T12,N:R,3,0)) -> -571931 | W12: =IF(O13="","",VLOOKUP(T12,N:R,4,0)) -> 33979793 | X12: =IF(O13="","",VLOOKUP(T12,N:R,5,0)) -> -3
A13: =IFERROR(RANK(E13,$E$6:$E$129),"") -> 22 | B13: 46101 | C13: 882107.WI | D13: 消费者服务 | E13: =IF(C13="","",RTD("wdf.rtq", ,C13, "rt_mf_amt","RT_Price")) -> -343005931 | G13: 8 | H13: =IF(D13="","",VLOOKUP(G13,A:E,4,0)) -> 国防军工 | I13: =IF(D13="","",VLOOKUP(G13,A:E,5,0)) -> 857296014 | N13: =IFERROR(RANK(Q13,$Q$7:$Q$129),"") -> 23 | O13: Wind食品与主要用品零售Ⅱ | P13: -46972.328 | Q13: 1380343.3 | R13: -5 | T13: 8 | U13: =IF(O14="","",VLOOKUP(T13,N:R,2,0)) -> Wind制药、生物科技与生命科学 | V13: =IF(O14="","",VLOOKUP(T13,N:R,3,0)) -> -569254.69 | W13: =IF(O14="","",VLOOKUP(T13,N:R,4,0)) -> 30209882 | X13: =IF(O14="","",VLOOKUP(T13,N:R,5,0)) -> -5
A14: =IFERROR(RANK(E14,$E$6:$E$129),"") -> 13 | B14: 46101 | C14: 882108.WI | D14: 媒体娱乐 | E14: =IF(C14="","",RTD("wdf.rtq", ,C14, "rt_mf_amt","RT_Price")) -> 37102254 | G14: 9 | H14: =IF(D14="","",VLOOKUP(G14,A:E,4,0)) -> 非银金融 | I14: =IF(D14="","",VLOOKUP(G14,A:E,5,0)) -> 599458641 | N14: =IFERROR(RANK(Q14,$Q$7:$Q$129),"") -> 10 | O14: Wind食品、饮料与烟草 | P14: -528621.33 | Q14: 25354520 | R14: -4 | T14: 9 | U14: =IF(O15="","",VLOOKUP(T14,N:R,2,0)) -> Wind能源Ⅱ | V14: =IF(O15="","",VLOOKUP(T14,N:R,3,0)) -> -289197.9 | W14: =IF(O15="","",VLOOKUP(T14,N:R,4,0)) -> 29339739 | X14: =IF(O15="","",VLOOKUP(T14,N:R,5,0)) -> -1
A15: =IFERROR(RANK(E15,$E$6:$E$129),"") -> 17 | B15: 46101 | C15: 882109.WI | D15: 可选消费零售 | E15: =IF(C15="","",RTD("wdf.rtq", ,C15, "rt_mf_amt","RT_Price")) -> -88213333 | G15: 10 | H15: =IF(D15="","",VLOOKUP(G15,A:E,4,0)) -> 石油石化 | I15: =IF(D15="","",VLOOKUP(G15,A:E,5,0)) -> 391409012 | N15: =IFERROR(RANK(Q15,$Q$7:$Q$129),"") -> 24 | O15: Wind家庭与个人用品 | P15: -16538.054 | Q15: 910668.06 | R15: -5 | T15: 10 | U15: =IF(O16="","",VLOOKUP(T15,N:R,2,0)) -> Wind食品、饮料与烟草 | V15: =IF(O16="","",VLOOKUP(T15,N:R,3,0)) -> -528621.33 | W15: =IF(O16="","",VLOOKUP(T15,N:R,4,0)) -> 25354520 | X15: =IF(O16="","",VLOOKUP(T15,N:R,5,0)) -> -4
A16: =IFERROR(RANK(E16,$E$6:$E$129),"") -> 15 | B16: 46101 | C16: 882110.WI | D16: 日常消费零售 | E16: =IF(C16="","",RTD("wdf.rtq", ,C16, "rt_mf_amt","RT_Price")) -> -55820831 | G16: 11 | H16: =IF(D16="","",VLOOKUP(G16,A:E,4,0)) -> 机械 | I16: =IF(D16="","",VLOOKUP(G16,A:E,5,0)) -> 228825481 | N16: =IFERROR(RANK(Q16,$Q$7:$Q$129),"") -> 15 | O16: Wind医疗保健设备与服务 | P16: -455425.97 | Q16: 13933338 | R16: -5 | T16: 11 | U16: =IF(O17="","",VLOOKUP(T16,N:R,2,0)) -> Wind多元金融 | V16: =IF(O17="","",VLOOKUP(T16,N:R,3,0)) -> -216725.26 | W16: =IF(O17="","",VLOOKUP(T16,N:R,4,0)) -> 19539075 | X16: =IF(O17="","",VLOOKUP(T16,N:R,5,0)) -> -1
A17: =IFERROR(RANK(E17,$E$6:$E$129),"") -> 32 | B17: 46101 | C17: 882111.WI | D17: 食品饮料 | E17: =IF(C17="","",RTD("wdf.rtq", ,C17, "rt_mf_amt","RT_Price")) -> -2541667312 | G17: 12 | H17: =IF(D17="","",VLOOKUP(G17,A:E,4,0)) -> 企业服务 | I17: =IF(D17="","",VLOOKUP(G17,A:E,5,0)) -> 120592756 | N17: =IFERROR(RANK(Q17,$Q$7:$Q$129),"") -> 13 | O17: Wind运输 | P17: -85217.279 | Q17: 15247159 | R17: -2 | T17: 12 | U17: =IF(O18="","",VLOOKUP(T17,N:R,2,0)) -> Wind耐用消费品与服装 | V17: =IF(O18="","",VLOOKUP(T17,N:R,3,0)) -> -537319.43 | W17: =IF(O18="","",VLOOKUP(T17,N:R,4,0)) -> 18164622 | X17: =IF(O18="","",VLOOKUP(T17,N:R,5,0)) -> -5
A18: =IFERROR(RANK(E18,$E$6:$E$129),"") -> 18 | B18: 46101 | C18: 882112.WI | D18: 家庭用品 | E18: =IF(C18="","",RTD("wdf.rtq", ,C18, "rt_mf_amt","RT_Price")) -> -96327989 | G18: 13 | H18: =IF(D18="","",VLOOKUP(G18,A:E,4,0)) -> 媒体娱乐 | I18: =IF(D18="","",VLOOKUP(G18,A:E,5,0)) -> 37102254 | N18: =IFERROR(RANK(Q18,$Q$7:$Q$129),"") -> 7 | O18: Wind汽车与汽车零部件 | P18: -571931 | Q18: 33979793 | R18: -3 | T18: 13 | U18: =IF(O19="","",VLOOKUP(T18,N:R,2,0)) -> Wind运输 | V18: =IF(O19="","",VLOOKUP(T18,N:R,3,0)) -> -85217.279 | W18: =IF(O19="","",VLOOKUP(T18,N:R,4,0)) -> 15247159 | X18: =IF(O19="","",VLOOKUP(T18,N:R,5,0)) -> -2
A19: =IFERROR(RANK(E19,$E$6:$E$129),"") -> 25 | B19: 46101 | C19: 882113.WI | D19: 医疗设备与服务 | E19: =IF(C19="","",RTD("wdf.rtq", ,C19, "rt_mf_amt","RT_Price")) -> -420982719 | G19: 14 | H19: =IF(D19="","",VLOOKUP(G19,A:E,4,0)) -> 电信服务 | I19: =IF(D19="","",VLOOKUP(G19,A:E,5,0)) -> -36815674 | N19: =IFERROR(RANK(Q19,$Q$7:$Q$129),"") -> 12 | O19: Wind耐用消费品与服装 | P19: -537319.43 | Q19: 18164622 | R19: -5 | T19: 14 | U19: =IF(O20="","",VLOOKUP(T19,N:R,2,0)) -> Wind商业和专业服务 | V19: =IF(O20="","",VLOOKUP(T19,N:R,3,0)) -> -310943.94 | W19: =IF(O20="","",VLOOKUP(T19,N:R,4,0)) -> 14537807 | X19: =IF(O20="","",VLOOKUP(T19,N:R,5,0)) -> -2
... A30: =IFERROR(RANK(E30,$E$6:$E$129),"") -> 26 | B30: 46101 | C30: 882126.WI | D30: 钢铁Ⅱ | E30: =IF(C30="","",RTD("wdf.rtq", ,C30, "rt_mf_amt","RT_Price")) -> -442455875 | G30: 25 | H30: =IF(D30="","",VLOOKUP(G30,A:E,4,0)) -> 医疗设备与服务 | I30: =IF(D30="","",VLOOKUP(G30,A:E,5,0)) -> -420982719 | N30: =IFERROR(RANK(Q30,$Q$7:$Q$129),"") -> 3 | O30: Wind技术硬件与设备 | P30: -2159957.8 | Q30: 2.0285558e+08 | R30: -2 | T30: 25 | U30: =IF(O31="","",VLOOKUP(T30,N:R,2,0)) | V30: =IF(O31="","",VLOOKUP(T30,N:R,3,0)) | W30: =IF(O31="","",VLOOKUP(T30,N:R,4,0)) | X30: =IF(O31="","",VLOOKUP(T30,N:R,5,0))
A31: =IFERROR(RANK(E31,$E$6:$E$129),"") -> 4 | B31: 46101 | C31: 882127.WI | D31: 有色金属 | E31: =IF(C31="","",RTD("wdf.rtq", ,C31, "rt_mf_amt","RT_Price")) -> 3687179869 | G31: 26 | H31: =IF(D31="","",VLOOKUP(G31,A:E,4,0)) -> 钢铁Ⅱ | I31: =IF(D31="","",VLOOKUP(G31,A:E,5,0)) -> -442455875 | N31: =IFERROR(RANK(Q31,$Q$7:$Q$129),"") | T31: 26 | U31: =IF(O32="","",VLOOKUP(T31,N:R,2,0)) | V31: =IF(O32="","",VLOOKUP(T31,N:R,3,0)) | W31: =IF(O32="","",VLOOKUP(T31,N:R,4,0)) | X31: =IF(O32="","",VLOOKUP(T31,N:R,5,0))
A32: =IFERROR(RANK(E32,$E$6:$E$129),"") -> 5 | B32: 46101 | C32: 882128.WI | D32: 造纸与包装 | E32: =IF(C32="","",RTD("wdf.rtq", ,C32, "rt_mf_amt","RT_Price")) -> 3327513353 | G32: 27 | H32: =IF(D32="","",VLOOKUP(G32,A:E,4,0)) -> 房地产Ⅱ | I32: =IF(D32="","",VLOOKUP(G32,A:E,5,0)) -> -523579297 | N32: =IFERROR(RANK(Q32,$Q$7:$Q$129),"") | T32: 27 | U32: =IF(O33="","",VLOOKUP(T32,N:R,2,0)) | V32: =IF(O33="","",VLOOKUP(T32,N:R,3,0)) | W32: =IF(O33="","",VLOOKUP(T32,N:R,4,0)) | X32: =IF(O33="","",VLOOKUP(T32,N:R,5,0))
A33: =IFERROR(RANK(E33,$E$6:$E$129),"") -> 30 | B33: 46101 | C33: 882129.WI | D33: 建筑 | E33: =IF(C33="","",RTD("wdf.rtq", ,C33, "rt_mf_amt","RT_Price")) -> -1693398194 | G33: 28 | H33: =IF(D33="","",VLOOKUP(G33,A:E,4,0)) -> 软件服务 | I33: =IF(D33="","",VLOOKUP(G33,A:E,5,0)) -> -547516320 | N33: =IFERROR(RANK(Q33,$Q$7:$Q$129),"") | T33: 28 | U33: =IF(O34="","",VLOOKUP(T33,N:R,2,0)) | V33: =IF(O34="","",VLOOKUP(T33,N:R,3,0)) | W33: =IF(O34="","",VLOOKUP(T33,N:R,4,0)) | X33: =IF(O34="","",VLOOKUP(T33,N:R,5,0))
A34: =IFERROR(RANK(E34,$E$6:$E$129),"") -> 3 | B34: 46101 | C34: 882130.WI | D34: 电气设备 | E34: =IF(C34="","",RTD("wdf.rtq", ,C34, "rt_mf_amt","RT_Price")) -> 3741169640 | G34: 29 | H34: =IF(D34="","",VLOOKUP(G34,A:E,4,0)) -> 交通运输 | I34: =IF(D34="","",VLOOKUP(G34,A:E,5,0)) -> -1647711971 | N34: =IFERROR(RANK(Q34,$Q$7:$Q$129),"") | T34: 29 | U34: =IF(O35="","",VLOOKUP(T34,N:R,2,0)) | V34: =IF(O35="","",VLOOKUP(T34,N:R,3,0)) | W34: =IF(O35="","",VLOOKUP(T34,N:R,4,0)) | X34: =IF(O35="","",VLOOKUP(T34,N:R,5,0))
A35: =IFERROR(RANK(E35,$E$6:$E$129),"") -> 11 | B35: 46101 | C35: 882131.WI | D35: 机械 | E35: =IF(C35="","",RTD("wdf.rtq", ,C35, "rt_mf_amt","RT_Price")) -> 228825481 | G35: 30 | H35: =IF(D35="","",VLOOKUP(G35,A:E,4,0)) -> 建筑 | I35: =IF(D35="","",VLOOKUP(G35,A:E,5,0)) -> -1693398194 | N35: =IFERROR(RANK(Q35,$Q$7:$Q$129),"") | T35: 30 | U35: =IF(O36="","",VLOOKUP(T35,N:R,2,0)) | V35: =IF(O36="","",VLOOKUP(T35,N:R,3,0)) | W35: =IF(O36="","",VLOOKUP(T35,N:R,4,0)) | X35: =IF(O36="","",VLOOKUP(T35,N:R,5,0))
A36: =IFERROR(RANK(E36,$E$6:$E$129),"") -> 21 | B36: 46101 | C36: 882132.WI | D36: 工业贸易与综合 | E36: =IF(C36="","",RTD("wdf.rtq", ,C36, "rt_mf_amt","RT_Price")) -> -241376788 | G36: 31 | H36: =IF(D36="","",VLOOKUP(G36,A:E,4,0)) -> 医药生物 | I36: =IF(D36="","",VLOOKUP(G36,A:E,5,0)) -> -1979422049 | N36: =IFERROR(RANK(Q36,$Q$7:$Q$129),"") | T36: 31 | U36: =IF(O37="","",VLOOKUP(T36,N:R,2,0)) | V36: =IF(O37="","",VLOOKUP(T36,N:R,3,0)) | W36: =IF(O37="","",VLOOKUP(T36,N:R,4,0)) | X36: =IF(O37="","",VLOOKUP(T36,N:R,5,0))
A37: =IFERROR(RANK(E37,$E$6:$E$129),"") -> 19 | B37: 46101 | C37: 882133.WI | D37: 环保Ⅱ | E37: =IF(C37="","",RTD("wdf.rtq", ,C37, "rt_mf_amt","RT_Price")) -> -193852137 | G37: 32 | H37: =IF(D37="","",VLOOKUP(G37,A:E,4,0)) -> 食品饮料 | I37: =IF(D37="","",VLOOKUP(G37,A:E,5,0)) -> -2541667312 | N37: =IFERROR(RANK(Q37,$Q$7:$Q$129),"") | T37: 32 | U37: =IF(O38="","",VLOOKUP(T37,N:R,2,0)) | V37: =IF(O38="","",VLOOKUP(T37,N:R,3,0)) | W37: =IF(O38="","",VLOOKUP(T37,N:R,4,0)) | X37: =IF(O38="","",VLOOKUP(T37,N:R,5,0))
A38: =IFERROR(RANK(E38,$E$6:$E$129),"") -> 23 | B38: 46101 | C38: 882134.WI | D38: 家电Ⅱ | E38: =IF(C38="","",RTD("wdf.rtq", ,C38, "rt_mf_amt","RT_Price")) -> -350557159 | G38: 33 | H38: =IF(D38="","",VLOOKUP(G38,A:E,4,0)) -> 银行 | I38: =IF(D38="","",VLOOKUP(G38,A:E,5,0)) -> -3775281840 | N38: =IFERROR(RANK(Q38,$Q$7:$Q$129),"") | T38: 33 | U38: =IF(O39="","",VLOOKUP(T38,N:R,2,0)) | V38: =IF(O39="","",VLOOKUP(T38,N:R,3,0)) | W38: =IF(O39="","",VLOOKUP(T38,N:R,4,0)) | X38: =IF(O39="","",VLOOKUP(T38,N:R,5,0))
A39: =IFERROR(RANK(E39,$E$6:$E$129),"") -> 24 | B39: 46101 | C39: 882135.WI | D39: 纺织服装Ⅱ | E39: =IF(C39="","",RTD("wdf.rtq", ,C39, "rt_mf_amt","RT_Price")) -> -376950193 | G39: 34 | H39: =IF(D39="","",VLOOKUP(G39,A:E,4,0)) -> 半导体 | I39: =IF(D39="","",VLOOKUP(G39,A:E,5,0)) -> -7350586062 | N39: =IFERROR(RANK(Q39,$Q$7:$Q$129),"") | T39: 34 | U39: =IF(O40="","",VLOOKUP(T39,N:R,2,0)) | V39: =IF(O40="","",VLOOKUP(T39,N:R,3,0)) | W39: =IF(O40="","",VLOOKUP(T39,N:R,4,0)) | X39: =IF(O40="","",VLOOKUP(T39,N:R,5,0))
A40: =IFERROR(RANK(E40,$E$6:$E$129),"") -> 27 | B40: 46101 | C40: 882136.WI | D40: 房地产Ⅱ | E40: =IF(C40="","",RTD("wdf.rtq", ,C40, "rt_mf_amt","RT_Price")) -> -523579297 | G40: 35 | H40: =IF(D40="","",VLOOKUP(G40,A:E,4,0)) -> 硬件设备 | I40: =IF(D40="","",VLOOKUP(G40,A:E,5,0)) -> -8966055614 | N40: =IFERROR(RANK(Q40,$Q$7:$Q$129),"") | T40: 35 | U40: =IF(O41="","",VLOOKUP(T40,N:R,2,0)) | V40: =IF(O41="","",VLOOKUP(T40,N:R,3,0)) | W40: =IF(O41="","",VLOOKUP(T40,N:R,4,0)) | X40: =IF(O41="","",VLOOKUP(T40,N:R,5,0))
A41: =IFERROR(RANK(E41,$E$6:$E$129),"") | E41: =IF(C41="","",RTD("wdf.rtq", ,C41, "rt_mf_amt","RT_Price")) | G41: 36 | H41: =IF(D41="","",VLOOKUP(G41,A:E,4,0)) | I41: =IF(D41="","",VLOOKUP(G41,A:E,5,0)) | N41: =IFERROR(RANK(Q41,$Q$7:$Q$129),"") | T41: 36 | U41: =IF(O42="","",VLOOKUP(T41,N:R,2,0)) | V41: =IF(O42="","",VLOOKUP(T41,N:R,3,0)) | W41: =IF(O42="","",VLOOKUP(T41,N:R,4,0)) | X41: =IF(O42="","",VLOOKUP(T41,N:R,5,0))
A42: =IFERROR(RANK(E42,$E$6:$E$129),"") | E42: =IF(C42="","",RTD("wdf.rtq", ,C42, "rt_mf_amt","RT_Price")) | G42: 37 | H42: =IF(D42="","",VLOOKUP(G42,A:E,4,0)) | I42: =IF(D42="","",VLOOKUP(G42,A:E,5,0)) | N42: =IFERROR(RANK(Q42,$Q$7:$Q$129),"") | T42: 37 | U42: =IF(O43="","",VLOOKUP(T42,N:R,2,0)) | V42: =IF(O43="","",VLOOKUP(T42,N:R,3,0)) | W42: =IF(O43="","",VLOOKUP(T42,N:R,4,0)) | X42: =IF(O43="","",VLOOKUP(T42,N:R,5,0))
A43: =IFERROR(RANK(E43,$E$6:$E$129),"") | E43: =IF(C43="","",RTD("wdf.rtq", ,C43, "rt_mf_amt","RT_Price")) | G43: 38 | H43: =IF(D43="","",VLOOKUP(G43,A:E,4,0)) | I43: =IF(D43="","",VLOOKUP(G43,A:E,5,0)) | N43: =IFERROR(RANK(Q43,$Q$7:$Q$129),"") | T43: 38 | U43: =IF(O44="","",VLOOKUP(T43,N:R,2,0)) | V43: =IF(O44="","",VLOOKUP(T43,N:R,3,0)) | W43: =IF(O44="","",VLOOKUP(T43,N:R,4,0)) | X43: =IF(O44="","",VLOOKUP(T43,N:R,5,0))
A44: =IFERROR(RANK(E44,$E$6:$E$129),"") | E44: =IF(C44="","",RTD("wdf.rtq", ,C44, "rt_mf_amt","RT_Price")) | G44: 39 | H44: =IF(D44="","",VLOOKUP(G44,A:E,4,0)) | I44: =IF(D44="","",VLOOKUP(G44,A:E,5,0)) | N44: =IFERROR(RANK(Q44,$Q$7:$Q$129),"") | T44: 39 | U44: =IF(O45="","",VLOOKUP(T44,N:R,2,0)) | V44: =IF(O45="","",VLOOKUP(T44,N:R,3,0)) | W44: =IF(O45="","",VLOOKUP(T44,N:R,4,0)) | X44: =IF(O45="","",VLOOKUP(T44,N:R,5,0))
A45: =IFERROR(RANK(E45,$E$6:$E$129),"") | E45: =IF(C45="","",RTD("wdf.rtq", ,C45, "rt_mf_amt","RT_Price")) | G45: 40 | H45: =IF(D45="","",VLOOKUP(G45,A:E,4,0)) | I45: =IF(D45="","",VLOOKUP(G45,A:E,5,0)) | N45: =IFERROR(RANK(Q45,$Q$7:$Q$129),"") | T45: 40 | U45: =IF(O46="","",VLOOKUP(T45,N:R,2,0)) | V45: =IF(O46="","",VLOOKUP(T45,N:R,3,0)) | W45: =IF(O46="","",VLOOKUP(T45,N:R,4,0)) | X45: =IF(O46="","",VLOOKUP(T45,N:R,5,0))
A46: =IFERROR(RANK(E46,$E$6:$E$129),"") | E46: =IF(C46="","",RTD("wdf.rtq", ,C46, "rt_mf_amt","RT_Price")) | G46: 41 | H46: =IF(D46="","",VLOOKUP(G46,A:E,4,0)) | I46: =IF(D46="","",VLOOKUP(G46,A:E,5,0)) | N46: =IFERROR(RANK(Q46,$Q$7:$Q$129),"") | T46: 41 | U46: =IF(O47="","",VLOOKUP(T46,N:R,2,0)) | V46: =IF(O47="","",VLOOKUP(T46,N:R,3,0)) | W46: =IF(O47="","",VLOOKUP(T46,N:R,4,0)) | X46: =IF(O47="","",VLOOKUP(T46,N:R,5,0))
A47: =IFERROR(RANK(E47,$E$6:$E$129),"") | E47: =IF(C47="","",RTD("wdf.rtq", ,C47, "rt_mf_amt","RT_Price")) | G47: 42 | H47: =IF(D47="","",VLOOKUP(G47,A:E,4,0)) | I47: =IF(D47="","",VLOOKUP(G47,A:E,5,0)) | N47: =IFERROR(RANK(Q47,$Q$7:$Q$129),"") | T47: 42 | U47: =IF(O48="","",VLOOKUP(T47,N:R,2,0)) | V47: =IF(O48="","",VLOOKUP(T47,N:R,3,0)) | W47: =IF(O48="","",VLOOKUP(T47,N:R,4,0)) | X47: =IF(O48="","",VLOOKUP(T47,N:R,5,0))
A48: =IFERROR(RANK(E48,$E$6:$E$129),"") | E48: =IF(C48="","",RTD("wdf.rtq", ,C48, "rt_mf_amt","RT_Price")) | G48: 43 | H48: =IF(D48="","",VLOOKUP(G48,A:E,4,0)) | I48: =IF(D48="","",VLOOKUP(G48,A:E,5,0)) | N48: =IFERROR(RANK(Q48,$Q$7:$Q$129),"") | T48: 43 | U48: =IF(O49="","",VLOOKUP(T48,N:R,2,0)) | V48: =IF(O49="","",VLOOKUP(T48,N:R,3,0)) | W48: =IF(O49="","",VLOOKUP(T48,N:R,4,0)) | X48: =IF(O49="","",VLOOKUP(T48,N:R,5,0))
A49: =IFERROR(RANK(E49,$E$6:$E$129),"") | E49: =IF(C49="","",RTD("wdf.rtq", ,C49, "rt_mf_amt","RT_Price")) | G49: 44 | H49: =IF(D49="","",VLOOKUP(G49,A:E,4,0)) | I49: =IF(D49="","",VLOOKUP(G49,A:E,5,0)) | N49: =IFERROR(RANK(Q49,$Q$7:$Q$129),"") | T49: 44 | U49: =IF(O50="","",VLOOKUP(T49,N:R,2,0)) | V49: =IF(O50="","",VLOOKUP(T49,N:R,3,0)) | W49: =IF(O50="","",VLOOKUP(T49,N:R,4,0)) | X49: =IF(O50="","",VLOOKUP(T49,N:R,5,0))
A50: =IFERROR(RANK(E50,$E$6:$E$129),"") | E50: =IF(C50="","",RTD("wdf.rtq", ,C50, "rt_mf_amt","RT_Price")) | G50: 45 | H50: =IF(D50="","",VLOOKUP(G50,A:E,4,0)) | I50: =IF(D50="","",VLOOKUP(G50,A:E,5,0)) | N50: =IFERROR(RANK(Q50,$Q$7:$Q$129),"") | T50: 45 | U50: =IF(O51="","",VLOOKUP(T50,N:R,2,0)) | V50: =IF(O51="","",VLOOKUP(T50,N:R,3,0)) | W50: =IF(O51="","",VLOOKUP(T50,N:R,4,0)) | X50: =IF(O51="","",VLOOKUP(T50,N:R,5,0))
...
