Workbook
Name benchmark: 参数设置!$P$4:$P$48
Name comparlastrep: 参数设置!$D$6
Name comppool: 参数设置!$V:$Y
Name currencyunit: 盈利预测!$E$10
Name CurrencyUnit: 参数设置!$G$3
Name gross_items: 主营构成!$J$27:$N$31
Name holdertime: 参数设置!$G$9
Name holdertimetype: 参数设置!$C$9:$F$9
Name industrytype: 参数设置!$U$6:$U$9
Name Institutionlist: 参数设置!$B$16:$C$108
Name pricetype: 参数设置!$C$8:$E$8
Name quantity: 盈利预测!$Q$15:$Q$83
Name recentreportdate: 参数设置!$D$4
Name reporttype: 参数设置!$C$10:$F$10
Name rev_items: 主营构成!$J$20:$N$24
Name rptype: 参数设置!$G$10
Name rptype2: 参数设置!$G$11
Name rptype3: 参数设置!$G$12
Name rptype4: 参数设置!$G$13
Name rptype5: 参数设置!$G$14
Name series: 参数设置!$V:$V
Name timetype: 参数设置!$C$5:$E$5
Name Unit: 参数设置!$C$3:$F$3

Sheet 公司分析
D1: 股票速览-公司分析(港股)
C4: 交易代码 | D4: 9626.HK | E4: 证券简称 | F4: =[1]!s_info_name(D4) -> 哔哩哔哩-W
C5: 日期 | D5: =TODAY()-1 -> 45466 | E5: 单位 | F5: 亿
C7: 说明：《公司分析》提供上市公司速览、盈利预测、行业比较等内容。通过本模板，可以快速浏览上市公司的基本信息，股价、股本、股东及财务经营状况；机构的预测明细和进行相关行业的比较，了解公司在行业中的地位。
C8: 公司概况
C10: 公司名称 | D10: =[1]!s_info_compname(D4) -> 哔哩哔哩股份有限公司 | M10: EPS(摊薄) | N10: =[1]!hks_fa_eps_ttm2(D4,YEAR(行业比较!G5)-1&"-12-31",0) -> -20.230138 | O10: 现价 | P10: =RTD("wdf.rtq",,D4,5) -> 137.3 | T10: 前收盘价 | U10: =[1]!s_dq_close(D4,D5,1) -> 136.8
C11: 首发上市日期 | D11: =[1]!s_ipo_listeddate(D4) -> 2021-03-29 | M11: BPS | N11: =[1]!hks_fa_bps(D4,YEAR(行业比较!G5)-1&"-12-31") -> 38.102437 | O11: 开盘价 | P11: =RTD("wdf.rtq",,D4,2) -> 140.6 | T11: 涨跌 | U11: =RTD("wdf.rtq",,D4,26) -> 0.5
C12: 公司电话 | D12: =[1]!s_info_phone(D4) -> 0 | M12: 市盈率 | N12: =[1]!s_val_pe(D4,D5,1) -> -10.829672 | O12: 最高价 | P12: =RTD("wdf.rtq",,D4,3) -> 141.4 | T12: 涨跌幅 | U12: =RTD("wdf.rtq",,D4,27)/100 -> 0.0037
C13: 公司传真 | D13: =[1]!s_info_fax(D4) -> 0 | M13: 市净率 | N13: =[1]!s_val_pb(D4,D5,1) -> 3.6287186 | O13: 最低价 | P13: =RTD("wdf.rtq",,D4,4) -> 136.3 | T13: 成交量(万) | U13: =RTD("wdf.rtq",,D4,29)/10000 -> 40442.286
C14: 行业(SW/GICS) | D14: =[1]!s_info_industry_sw_2021(D4,D5,1)&"/"&[1]!s_info_industry_gics(D4) -> 传媒/信息技术 | M14: ="总股本"&"("&F5&")" -> 总股本(亿) | N14: =[1]!s_share_total(D4,D5)/CurrencyUnit -> 4.2126142 | O14: 均价 | P14: =RTD("wdf.rtq",,D4,28) -> 138.602 | T14: 成交额(万) | U14: =RTD("wdf.rtq",,D4,30)/10000 -> 291.7872
C15: 员工总数 | D15: =[1]!s_info_employee(D4,YEAR(行业比较!G5)-1&"-12-31") -> 11092 | M15: ="总市值"&"("&F5&")" -> 总市值(亿) | N15: =[1]!s_val_mv(D4,D5)/CurrencyUnit -> 576.28562 | O15: 60日最高/最低 | P15: =[1]!s_pq_high(D4,D5-60,D5,1)&"/"&[1]!s_pq_low(D4,D5-60,D5,1) -> 145.6/90.55
C16: 年度审计意见 | D16: =[1]!s_stmnote_audit_category(D4,YEAR(行业比较!G5)-1&"-12-31",2) -> 标准无保留意见
C20: 市场表现 | D20: 不复权 | E20: 周 | F20: PE Band | G20: =LEFT(F20,2)&"最小值=8" -> PE最小值=8 | H20: =LEFT(F20,2)&"间距="&H29 -> PE间距=12 | M20: 指数基准 | V20: 恒生科技指数
H29: 12
C37: 主要股东分析 | V37: ="单位:("&F5&")" -> 单位:(亿)
C38: 前10大股东 | F38: =D5 -> 45466 | M38: 半年前 | V38: =holdertime -> 45286
C39: 股东名称 | F39: 持股数量 | G39: 持股比例 | H39: ="较"&M38&"变动" -> 较半年前变动 | M39: 股东名称 | V39: 持股数量
C40: =[1]!s_holder_name($D$4,F$38,1) -> Deutsche Bank Aktiengesellschaft | F40: =[1]!s_holder_quantity($D$4,F$38,1)/CurrencyUnit -> 1.1022008 | G40: =[1]!s_holder_pct($D$4,F$38,1)/100 -> 0.2616 | H40: =IF(ISNA(VLOOKUP(C40,$M$40:$V$50,4,FALSE)),F40,F40-VLOOKUP(C40,$M$40:$V$50,4,FALSE)) -> 1.1022008 | M40: =[1]!s_holder_name($D$4,V$38,1) -> Vanship Limited | V40: =[1]!s_holder_quantity($D$4,V$38,1)/CurrencyUnit -> 0.49299006
C41: =[1]!s_holder_name($D$4,F$38,2) -> Vanship Limited | F41: =[1]!s_holder_quantity($D$4,F$38,2)/CurrencyUnit -> 0.49824531 | G41: =[1]!s_holder_pct($D$4,F$38,2)/100 -> 0.1183 | H41: =IF(ISNA(VLOOKUP(C41,$M$40:$V$50,4,FALSE)),F41,F41-VLOOKUP(C41,$M$40:$V$50,4,FALSE)) -> 0.49824531 | M41: =[1]!s_holder_name($D$4,V$38,2) -> Tencent Mobility Limited | V41: =[1]!s_holder_quantity($D$4,V$38,2)/CurrencyUnit -> 0.32795161
C42: =[1]!s_holder_name($D$4,F$38,3) -> Tencent Mobility Limited | F42: =[1]!s_holder_quantity($D$4,F$38,3)/CurrencyUnit -> 0.32795161 | G42: =[1]!s_holder_pct($D$4,F$38,3)/100 -> 0.077800002 | H42: =IF(ISNA(VLOOKUP(C42,$M$40:$V$50,4,FALSE)),F42,F42-VLOOKUP(C42,$M$40:$V$50,4,FALSE)) -> 0.32795161 | M42: =[1]!s_holder_name($D$4,V$38,3) -> 淘宝中国控股有限公司 | V42: =[1]!s_holder_quantity($D$4,V$38,3)/CurrencyUnit -> 0.30845657
C43: =[1]!s_holder_name($D$4,F$38,4) -> Kami Sama Limited | F43: =[1]!s_holder_quantity($D$4,F$38,4)/CurrencyUnit -> 0.27367208 | G43: =[1]!s_holder_pct($D$4,F$38,4)/100 -> 0.065 | H43: =IF(ISNA(VLOOKUP(C43,$M$40:$V$50,4,FALSE)),F43,F43-VLOOKUP(C43,$M$40:$V$50,4,FALSE)) -> 0.27367208 | M43: =[1]!s_holder_name($D$4,V$38,4) -> Kami Sama Limited | V43: =[1]!s_holder_quantity($D$4,V$38,4)/CurrencyUnit -> 0.27216108
C44: =[1]!s_holder_name($D$4,F$38,5) -> 黄河投资有限公司 | F44: =[1]!s_holder_quantity($D$4,F$38,5)/CurrencyUnit -> 0.10954357 | G44: =[1]!s_holder_pct($D$4,F$38,5)/100 -> 0.025999999 | H44: =IF(ISNA(VLOOKUP(C44,$M$40:$V$50,4,FALSE)),F44,F44-VLOOKUP(C44,$M$40:$V$50,4,FALSE)) -> 0.10954357 | M44: =[1]!s_holder_name($D$4,V$38,5) -> OPH B Limited | V44: =[1]!s_holder_quantity($D$4,V$38,5)/CurrencyUnit -> 0.10954357
C45: =[1]!s_holder_name($D$4,F$38,6) -> Saber Lily Limited | F45: =[1]!s_holder_quantity($D$4,F$38,6)/CurrencyUnit -> 0.081083 | G45: =[1]!s_holder_pct($D$4,F$38,6)/100 -> 0.0192 | H45: =IF(ISNA(VLOOKUP(C45,$M$40:$V$50,4,FALSE)),F45,F45-VLOOKUP(C45,$M$40:$V$50,4,FALSE)) -> 0.081083 | M45: =[1]!s_holder_name($D$4,V$38,6) -> Saber Lily Limited | V45: =[1]!s_holder_quantity($D$4,V$38,6)/CurrencyUnit -> 0.072
C46: =[1]!s_holder_name($D$4,F$38,7) -> 陈睿 | F46: =[1]!s_holder_quantity($D$4,F$38,7)/CurrencyUnit -> 0.05 | G46: =[1]!s_holder_pct($D$4,F$38,7)/100 -> 0.011900001 | H46: =IF(ISNA(VLOOKUP(C46,$M$40:$V$50,4,FALSE)),F46,F46-VLOOKUP(C46,$M$40:$V$50,4,FALSE)) -> 0.05 | M46: =[1]!s_holder_name($D$4,V$38,7) -> 陈睿 | V46: =[1]!s_holder_quantity($D$4,V$38,7)/CurrencyUnit -> 0.05
C47: =[1]!s_holder_name($D$4,F$38,8) -> 李旎 | F47: =[1]!s_holder_quantity($D$4,F$38,8)/CurrencyUnit -> 0.03 | G47: =[1]!s_holder_pct($D$4,F$38,8)/100 -> 0.0070999998 | H47: =IF(ISNA(VLOOKUP(C47,$M$40:$V$50,4,FALSE)),F47,F47-VLOOKUP(C47,$M$40:$V$50,4,FALSE)) -> 0.03 | M47: =[1]!s_holder_name($D$4,V$38,8) -> 李旎 | V47: =[1]!s_holder_quantity($D$4,V$38,8)/CurrencyUnit -> 0.03
C48: =[1]!s_holder_name($D$4,F$38,9) -> 徐逸 | F48: =[1]!s_holder_quantity($D$4,F$38,9)/CurrencyUnit -> 0.00045 | G48: =[1]!s_holder_pct($D$4,F$38,9)/100 -> 9.9999998e-05 | H48: =IF(ISNA(VLOOKUP(C48,$M$40:$V$50,4,FALSE)),F48,F48-VLOOKUP(C48,$M$40:$V$50,4,FALSE)) -> 0.00045 | M48: =[1]!s_holder_name($D$4,V$38,9) -> 徐逸 | V48: =[1]!s_holder_quantity($D$4,V$38,9)/CurrencyUnit -> 0.00045
C49: =[1]!s_holder_name($D$4,F$38,10) -> 0 | F49: =[1]!s_holder_quantity($D$4,F$38,10)/CurrencyUnit -> 0 | G49: =[1]!s_holder_pct($D$4,F$38,10)/100 -> 0 | H49: =IF(ISNA(VLOOKUP(C49,$M$40:$V$50,4,FALSE)),F49,F49-VLOOKUP(C49,$M$40:$V$50,4,FALSE)) -> 0 | M49: =[1]!s_holder_name($D$4,V$38,10) -> 0 | V49: =[1]!s_holder_quantity($D$4,$F38,10)/CurrencyUnit -> 0
C50: 合计 | F50: =SUM(F40:F49) -> 2.4731464 | G50: =SUM(G40:G49) -> 0.587 | H50: =IF(ISNA(VLOOKUP(C50,$M$40:$V$50,4,FALSE)),F50,F50-VLOOKUP(C50,$M$40:$V$50,4,FALSE)) -> 2.4731464 | M50: 合计 | V50: =SUM(V40:V49) -> 1.6635529
C53: 股本结构
C55: 总股本(亿） | D55: =N14 -> 4.2126142
C56: 流通A股 | D56: =[1]!S_SHARE_LIQA(D4,D5)/CurrencyUnit -> 0
C57: 流通B股 | D57: =[1]!s_share_liqb(D4,D5)/CurrencyUnit -> 0
C58: 香港上市股 | D58: =[1]!s_share_h(D4,D5)/CurrencyUnit -> 3.375463
C59: 海外上市股 | D59: =[1]!s_share_oversea(D4,D5)/CurrencyUnit -> 0
C60: 流通股合计 | D60: =[1]!s_share_totaltradable(D4,D5)/CurrencyUnit -> 0
C61: 限售股 | D61: =[1]!s_share_totalrestricted(D4,D5)/CurrencyUnit -> 0
C64: 收入与毛利分析 | H64: 年度
C66: 按行业分类 | D66: =IF($H$64="年度",YEAR(E66)-1&"/12/31",IF(MONTH(E66)=6,YEAR(E66)-1&"/12/31",YEAR(E66)&"/6/30")) -> 2019/12/31 | E66: =IF($H$64="年度",YEAR(F66)-1&"/12/31",IF(MONTH(F66)=6,YEAR(F66)-1&"/12-31",YEAR(F66)&"/6/30")) -> 2020/12/31 | F66: =IF($H$64="年度",YEAR(G66)-1&"/12/31",IF(MONTH(G66)=6,YEAR(G66)-1&"/12/31",YEAR(G66)&"/6/30")) -> 2021/12/31 | G66: =IF($H$64="年度",YEAR(H66)-1&"/12/31",IF(MONTH(H66)=6,YEAR(H66)-1&"/12/31",YEAR(H66)&"/6/30")) -> 2022/12/31 | H66: =IF(H64="年度",YEAR(TODAY())-1&"/12/31",IF(MONTH(TODAY())<9,YEAR(TODAY())-1&"/12/31",YEAR(TODAY())&"/06/30")) -> 2023/12/31
C67: 收入[合并报表] | D67: =[1]!S_STM07_IS($D$4,9,D66,1)/CurrencyUnit -> 67.77922 | E67: =[1]!S_STM07_IS($D$4,9,E66,1)/CurrencyUnit -> 119.98976 | F67: =[1]!S_STM07_IS($D$4,9,F66,1)/CurrencyUnit -> 193.83684 | G67: =[1]!S_STM07_IS($D$4,9,G66,1)/CurrencyUnit -> 218.99167 | H67: =[1]!S_STM07_IS($D$4,9,H66,1)/CurrencyUnit -> 225.27987
C68: =主营构成!C19 -> 收入[按产品分类] | D68: =SUM(D70:D74) -> 44.14825 | E68: =SUM(E70:E74) -> 66.46154 | F68: =SUM(F70:F74) -> 96.14347 | G68: =SUM(G70:G74) -> 188.02672 | H68: =SUM(H70:H74) -> 225.27987
...

Sheet 行业比较
D1: 股票速览-行业比较
C4: 交易代码 | D4: =公司分析!D4 -> 9626.HK | E4: =[1]!s_info_name(D4) -> 哔哩哔哩-W | F4: 行业排名 | G4: =VLOOKUP(E4,E14:R20003,14,FALSE)&"/"&MAX(series) -> 4/44 | H4: ="("&"按"&R12&")" -> (按总市值)
C5: 单位 | D5: 百万 | E5: =IF(D5="千",1000,IF(D5="百万",1000000,1000000000)) -> 1000000 | F5: 最新年报 | G5: =[1]!s_fa_lyr_bt(D4,公司分析!D5) -> 2023-12-31
C6: 行业属性 | D6: wind四级行业 | E6: =IF($D$6="申万一级行业",[1]!s_info_industry_sw_2021(D4,公司分析!D$5,1),IF($D$6="申万二级行业",[1]!s_info_industry_sw_2021(D4,公司分析!D$5,2),IF($D$6="申万三级行业",[1]!s_info_industry_sw_2021(D4,公司分析!D$5,3),IF($D$6="wind一级行业",[1]!s_info_industry_gics(D4,1),IF($D$6="wind二级行业",[1]!s_info_industry_gics(D4,2),IF($D$6="wind三级行业",[1]!s_info_industry_gics(D4,3),IF($D$6="wind四级行业",[1]!s_info_industry_gics(D4,4),IF($D$6="证监会门类行业",[1]!s_info_industry_csrc12_n(D4,公司分析!D$5,1),IF([1]!s_info_industry_csrc12_n(D4,公司分析!D$5,1)="制造业",[1]!s_info_industry_csrc12_n(D4,公司分析!D$5,2),[1]!s_info_industry_csrc12_n(D4,公司分析!D$5,1)))))))))) -> 互联网软件与服务 | F6: 分析类型 | G6: 财务摘要
C9: 行业比较
C11: 序号 | D11: 证券代码 | E11: 证券简称 | F11: 收盘价 | G11: 涨跌%[N日] | H11: =IF($G$6="财务摘要",参数设置!AC3,IF($G$6="估值分析",参数设置!AC4,参数设置!AC5)) -> 收入 | I11: =IF($G$6="财务摘要",参数设置!AD3,IF($G$6="估值分析",参数设置!AD4,参数设置!AD5)) -> 毛利率 | J11: =IF($G$6="财务摘要",参数设置!AF3,IF($G$6="估值分析",参数设置!AF4,参数设置!AF5)) -> 净利润率 | K11: =IF($G$6="财务摘要",参数设置!AG3,IF(G6="估值分析",参数设置!AG4,参数设置!AG5)) -> ROA | L11: =IF($G$6="财务摘要",参数设置!AH3,IF(G6="估值分析",参数设置!AH4,参数设置!AH5)) -> ROE | M11: =IF($G$6="财务摘要",参数设置!AI3,IF($G$6="估值分析",参数设置!AI4,参数设置!AI5)) -> EPS | N11: =IF($G$6="财务摘要",参数设置!AL3,IF(G6="估值分析",参数设置!AL4,参数设置!AL5)) -> PE | O11: =IF($G$6="财务摘要",参数设置!AN3,IF(G6="估值分析",参数设置!AN4,参数设置!AN5)) -> 总股本 | P11: =IF($G$6="财务摘要",参数设置!AO3,IF(G6="估值分析",参数设置!AO4,参数设置!AO5)) -> 总市值 | R11: 排名
G12: 20 | H12: 合并报表 | R12: 总市值
H13: =IF(H12="合并报表",1,IF(H12="母公司报表",2,IF(H12="合并报表(调整)",3,4))) -> 1
C14: =IF(ROW()-13<=MAX(series),ROW()-13,"") -> 1 | D14: =IF(C14="","",VLOOKUP(C14,comppool,2,FALSE)) -> 0484.HK | E14: =IF(C14="","",VLOOKUP(C14,comppool,3,FALSE)) -> 云游控股 | F14: =IF(C14="","",[1]!s_dq_close(D14,TODAY(),1)) -> 0.79 | G14: =IF(C14="","",[1]!s_pq_pctchange(D14,TODAY()-$G$12,TODAY())/100) -> -0.048192771 | H14: =IF(C14="","",IF($H$11="收入",[1]!S_STM07_IS(D14,9,$G$5,$H$13)/$E$5,[1]!S_STM07_IS(D14,48,$G$5,$H$13)/$E$5)) -> 60.172 | I14: =IF(C14="","",IF($I$11="毛利率",([1]!S_STM07_IS(D14,9,$G$5,$H$13)-[1]!S_STM07_IS(D14,10,$G$5,$H$13))/[1]!S_STM07_IS(D14,9,$G$5,$H$13),[1]!S_STM07_IS(D14,14,$G$5,$H$13)/$E$5)) -> 0.15025261 | J14: =IF(C14="","",IF($J$11="净利润率",[1]!S_STM07_IS(D14,61,$G$5,$H$13)/[1]!S_STM07_IS(D14,9,$G$5,$H$13),[1]!S_STM07_IS(D14,55,$G$5,$H$13)/$E$5)) -> -0.29277737 | K14: =IF(C14="","",[1]!hks_fa_roa2(D14,$G$5)) -> -2.9793 | L14: =IF(C14="","",[1]!hks_fa_roe(D14,$G$5)) -> -2.8565 | M14: =IF(C14="","",IF($M$11="EPS",[1]!S_STM07_IS(D14,61,$G$5,$H$13)/IF([1]!s_share_total(D14,$G$5)=0,[1]!s_share_total(D14,[1]!s_ipo_listeddate(D14)),[1]!s_share_total(D14,$G$5)),([1]!s_stm07_bs(D14,75,$G$5,$H$13)+[1]!s_stm07_bs(D14,88,$G$5,$H$13)+[1]!s_stm07_bs(D14,94,$G$5,$H$13)+[1]!s_stm07_bs(D14,95,$G$5,$H$13))/$E$5)) -> -0.12006808 | N14: =IF(C14="","",F14/([1]!S_STM07_IS(D14,61,$G$5,$H$13)/IF([1]!s_share_total(D14,$G$5)=0,[1]!s_share_total(D14,[1]!s_ipo_listeddate(D14)),[1]!s_share_total(D14,$G$5)))) -> -6.5796004 | O14: =IF(C14="","",[1]!s_share_total(D14,TODAY())/$E$5) -> 146.72509 | P14: =IF(C14="","",F14*O14) -> 115.91282 | Q14: =IF(C14="","",HLOOKUP($R$12,$G$11:$P$20003,ROW()-ROW($G$11)+1,FALSE)) -> 115.91282 | R14: =IF(C14="","",RANK(Q14,Q:Q,0)) -> 37
C15: =IF(ROW()-13<=MAX(series),ROW()-13,"") -> 2 | D15: =IF(C15="","",VLOOKUP(C15,comppool,2,FALSE)) -> 0700.HK | E15: =IF(C15="","",VLOOKUP(C15,comppool,3,FALSE)) -> 腾讯控股 | F15: =IF(C15="","",[1]!s_dq_close(D15,TODAY(),1)) -> 381.4 | G15: =IF(C15="","",[1]!s_pq_pctchange(D15,TODAY()-$G$12,TODAY())/100) -> 0.017066667 | H15: =IF(C15="","",IF($H$11="收入",[1]!S_STM07_IS(D15,9,$G$5,$H$13)/$E$5,[1]!S_STM07_IS(D15,48,$G$5,$H$13)/$E$5)) -> 609015 | I15: =IF(C15="","",IF($I$11="毛利率",([1]!S_STM07_IS(D15,9,$G$5,$H$13)-[1]!S_STM07_IS(D15,10,$G$5,$H$13))/[1]!S_STM07_IS(D15,9,$G$5,$H$13),[1]!S_STM07_IS(D15,14,$G$5,$H$13)/$E$5)) -> 0.48128371 | J15: =IF(C15="","",IF($J$11="净利润率",[1]!S_STM07_IS(D15,61,$G$5,$H$13)/[1]!S_STM07_IS(D15,9,$G$5,$H$13),[1]!S_STM07_IS(D15,55,$G$5,$H$13)/$E$5)) -> 0.18918417 | K15: =IF(C15="","",[1]!hks_fa_roa2(D15,$G$5)) -> 10.1035 | L15: =IF(C15="","",[1]!hks_fa_roe(D15,$G$5)) -> 15.0611 | M15: =IF(C15="","",IF($M$11="EPS",[1]!S_STM07_IS(D15,61,$G$5,$H$13)/IF([1]!s_share_total(D15,$G$5)=0,[1]!s_share_total(D15,[1]!s_ipo_listeddate(D15)),[1]!s_share_total(D15,$G$5)),([1]!s_stm07_bs(D15,75,$G$5,$H$13)+[1]!s_stm07_bs(D15,88,$G$5,$H$13)+[1]!s_stm07_bs(D15,94,$G$5,$H$13)+[1]!s_stm07_bs(D15,95,$G$5,$H$13))/$E$5)) -> 12.149751 | N15: =IF(C15="","",F15/([1]!S_STM07_IS(D15,61,$G$5,$H$13)/IF([1]!s_share_total(D15,$G$5)=0,[1]!s_share_total(D15,[1]!s_ipo_listeddate(D15)),[1]!s_share_total(D15,$G$5)))) -> 31.39159 | O15: =IF(C15="","",[1]!s_share_total(D15,TODAY())/$E$5) -> 9407.4572 | P15: =IF(C15="","",F15*O15) -> 3588004.2 | Q15: =IF(C15="","",HLOOKUP($R$12,$G$11:$P$20003,ROW()-ROW($G$11)+1,FALSE)) -> 3588004.2 | R15: =IF(C15="","",RANK(Q15,Q:Q,0)) -> 1
C16: =IF(ROW()-13<=MAX(series),ROW()-13,"") -> 3 | D16: =IF(C16="","",VLOOKUP(C16,comppool,2,FALSE)) -> 0802.HK | E16: =IF(C16="","",VLOOKUP(C16,comppool,3,FALSE)) -> 中国钱包 | F16: =IF(C16="","",[1]!s_dq_close(D16,TODAY(),1)) -> 0.045 | G16: =IF(C16="","",[1]!s_pq_pctchange(D16,TODAY()-$G$12,TODAY())/100) -> 0 | H16: =IF(C16="","",IF($H$11="收入",[1]!S_STM07_IS(D16,9,$G$5,$H$13)/$E$5,[1]!S_STM07_IS(D16,48,$G$5,$H$13)/$E$5)) -> 70.959 | I16: =IF(C16="","",IF($I$11="毛利率",([1]!S_STM07_IS(D16,9,$G$5,$H$13)-[1]!S_STM07_IS(D16,10,$G$5,$H$13))/[1]!S_STM07_IS(D16,9,$G$5,$H$13),[1]!S_STM07_IS(D16,14,$G$5,$H$13)/$E$5)) -> 0.35516284 | J16: =IF(C16="","",IF($J$11="净利润率",[1]!S_STM07_IS(D16,61,$G$5,$H$13)/[1]!S_STM07_IS(D16,9,$G$5,$H$13),[1]!S_STM07_IS(D16,55,$G$5,$H$13)/$E$5)) -> -0.45262757 | K16: =IF(C16="","",[1]!hks_fa_roa2(D16,$G$5)) -> -7.9941 | L16: =IF(C16="","",[1]!hks_fa_roe(D16,$G$5)) -> -9.2285 | M16: =IF(C16="","",IF($M$11="EPS",[1]!S_STM07_IS(D16,61,$G$5,$H$13)/IF([1]!s_share_total(D16,$G$5)=0,[1]!s_share_total(D16,[1]!s_ipo_listeddate(D16)),[1]!s_share_total(D16,$G$5)),([1]!s_stm07_bs(D16,75,$G$5,$H$13)+[1]!s_stm07_bs(D16,88,$G$5,$H$13)+[1]!s_stm07_bs(D16,94,$G$5,$H$13)+[1]!s_stm07_bs(D16,95,$G$5,$H$13))/$E$5)) -> -0.053215501 | N16: =IF(C16="","",F16/([1]!S_STM07_IS(D16,61,$G$5,$H$13)/IF([1]!s_share_total(D16,$G$5)=0,[1]!s_share_total(D16,[1]!s_ipo_listeddate(D16)),[1]!s_share_total(D16,$G$5)))) -> -0.84561827 | O16: =IF(C16="","",[1]!s_share_total(D16,TODAY())/$E$5) -> 603.54595 | P16: =IF(C16="","",F16*O16) -> 27.159568 | Q16: =IF(C16="","",HLOOKUP($R$12,$G$11:$P$20003,ROW()-ROW($G$11)+1,FALSE)) -> 27.159568 | R16: =IF(C16="","",RANK(Q16,Q:Q,0)) -> 42
C17: =IF(ROW()-13<=MAX(series),ROW()-13,"") -> 4 | D17: =IF(C17="","",VLOOKUP(C17,comppool,2,FALSE)) -> 0856.HK | E17: =IF(C17="","",VLOOKUP(C17,comppool,3,FALSE)) -> 伟仕佳杰 | F17: =IF(C17="","",[1]!s_dq_close(D17,TODAY(),1)) -> 4.47 | G17: =IF(C17="","",[1]!s_pq_pctchange(D17,TODAY()-$G$12,TODAY())/100) -> -0.0096460161 | H17: =IF(C17="","",IF($H$11="收入",[1]!S_STM07_IS(D17,9,$G$5,$H$13)/$E$5,[1]!S_STM07_IS(D17,48,$G$5,$H$13)/$E$5)) -> 73891.296 | I17: =IF(C17="","",IF($I$11="毛利率",([1]!S_STM07_IS(D17,9,$G$5,$H$13)-[1]!S_STM07_IS(D17,10,$G$5,$H$13))/[1]!S_STM07_IS(D17,9,$G$5,$H$13),[1]!S_STM07_IS(D17,14,$G$5,$H$13)/$E$5)) -> 0.047319728 | J17: =IF(C17="","",IF($J$11="净利润率",[1]!S_STM07_IS(D17,61,$G$5,$H$13)/[1]!S_STM07_IS(D17,9,$G$5,$H$13),[1]!S_STM07_IS(D17,55,$G$5,$H$13)/$E$5)) -> 0.012478236 | K17: =IF(C17="","",[1]!hks_fa_roa2(D17,$G$5)) -> 4.2214 | L17: =IF(C17="","",[1]!hks_fa_roe(D17,$G$5)) -> 11.6121 | M17: =IF(C17="","",IF($M$11="EPS",[1]!S_STM07_IS(D17,61,$G$5,$H$13)/IF([1]!s_share_total(D17,$G$5)=0,[1]!s_share_total(D17,[1]!s_ipo_listeddate(D17)),[1]!s_share_total(D17,$G$5)),([1]!s_stm07_bs(D17,75,$G$5,$H$13)+[1]!s_stm07_bs(D17,88,$G$5,$H$13)+[1]!s_stm07_bs(D17,94,$G$5,$H$13)+[1]!s_stm07_bs(D17,95,$G$5,$H$13))/$E$5)) -> 0.64038341 | N17: =IF(C17="","",F17/([1]!S_STM07_IS(D17,61,$G$5,$H$13)/IF([1]!s_share_total(D17,$G$5)=0,[1]!s_share_total(D17,[1]!s_ipo_listeddate(D17)),[1]!s_share_total(D17,$G$5)))) -> 6.9801933 | O17: =IF(C17="","",[1]!s_share_total(D17,TODAY())/$E$5) -> 1436.89 | P17: =IF(C17="","",F17*O17) -> 6422.8983 | Q17: =IF(C17="","",HLOOKUP($R$12,$G$11:$P$20003,ROW()-ROW($G$11)+1,FALSE)) -> 6422.8983 | R17: =IF(C17="","",RANK(Q17,Q:Q,0)) -> 12
C18: =IF(ROW()-13<=MAX(series),ROW()-13,"") -> 5 | D18: =IF(C18="","",VLOOKUP(C18,comppool,2,FALSE)) -> 0909.HK | E18: =IF(C18="","",VLOOKUP(C18,comppool,3,FALSE)) -> 明源云 | F18: =IF(C18="","",[1]!s_dq_close(D18,TODAY(),1)) -> 2.03 | G18: =IF(C18="","",[1]!s_pq_pctchange(D18,TODAY()-$G$12,TODAY())/100) -> -0.14345992 | H18: =IF(C18="","",IF($H$11="收入",[1]!S_STM07_IS(D18,9,$G$5,$H$13)/$E$5,[1]!S_STM07_IS(D18,48,$G$5,$H$13)/$E$5)) -> 1639.644 | I18: =IF(C18="","",IF($I$11="毛利率",([1]!S_STM07_IS(D18,9,$G$5,$H$13)-[1]!S_STM07_IS(D18,10,$G$5,$H$13))/[1]!S_STM07_IS(D18,9,$G$5,$H$13),[1]!S_STM07_IS(D18,14,$G$5,$H$13)/$E$5)) -> 0.79482314 | J18: =IF(C18="","",IF($J$11="净利润率",[1]!S_STM07_IS(D18,61,$G$5,$H$13)/[1]!S_STM07_IS(D18,9,$G$5,$H$13),[1]!S_STM07_IS(D18,55,$G$5,$H$13)/$E$5)) -> -0.35717143 | K18: =IF(C18="","",[1]!hks_fa_roa2(D18,$G$5)) -> -12.71 | L18: =IF(C18="","",[1]!hks_fa_roe(D18,$G$5)) -> -11.6698 | M18: =IF(C18="","",IF($M$11="EPS",[1]!S_STM07_IS(D18,61,$G$5,$H$13)/IF([1]!s_share_total(D18,$G$5)=0,[1]!s_share_total(D18,[1]!s_ipo_listeddate(D18)),[1]!s_share_total(D18,$G$5)),([1]!s_stm07_bs(D18,75,$G$5,$H$13)+[1]!s_stm07_bs(D18,88,$G$5,$H$13)+[1]!s_stm07_bs(D18,94,$G$5,$H$13)+[1]!s_stm07_bs(D18,95,$G$5,$H$13))/$E$5)) -> -0.30151328 | N18: =IF(C18="","",F18/([1]!S_STM07_IS(D18,61,$G$5,$H$13)/IF([1]!s_share_total(D18,$G$5)=0,[1]!s_share_total(D18,[1]!s_ipo_listeddate(D18)),[1]!s_share_total(D18,$G$5)))) -> -6.732705 | O18: =IF(C18="","",[1]!s_share_total(D18,TODAY())/$E$5) -> 1958.784 | P18: =IF(C18="","",F18*O18) -> 3976.3316 | Q18: =IF(C18="","",HLOOKUP($R$12,$G$11:$P$20003,ROW()-ROW($G$11)+1,FALSE)) -> 3976.3316 | R18: =IF(C18="","",RANK(Q18,Q:Q,0)) -> 16
C19: =IF(ROW()-13<=MAX(series),ROW()-13,"") -> 6 | D19: =IF(C19="","",VLOOKUP(C19,comppool,2,FALSE)) -> 0917.HK | E19: =IF(C19="","",VLOOKUP(C19,comppool,3,FALSE)) -> 趣致集团 | F19: =IF(C19="","",[1]!s_dq_close(D19,TODAY(),1)) -> 48.75 | G19: =IF(C19="","",[1]!s_pq_pctchange(D19,TODAY()-$G$12,TODAY())/100) -> 0.2279597 | H19: =IF(C19="","",IF($H$11="收入",[1]!S_STM07_IS(D19,9,$G$5,$H$13)/$E$5,[1]!S_STM07_IS(D19,48,$G$5,$H$13)/$E$5)) -> 1006.697 | I19: =IF(C19="","",IF($I$11="毛利率",([1]!S_STM07_IS(D19,9,$G$5,$H$13)-[1]!S_STM07_IS(D19,10,$G$5,$H$13))/[1]!S_STM07_IS(D19,9,$G$5,$H$13),[1]!S_STM07_IS(D19,14,$G$5,$H$13)/$E$5)) -> 0.53170616 | J19: =IF(C19="","",IF($J$11="净利润率",[1]!S_STM07_IS(D19,61,$G$5,$H$13)/[1]!S_STM07_IS(D19,9,$G$5,$H$13),[1]!S_STM07_IS(D19,55,$G$5,$H$13)/$E$5)) -> 0.13007092 | K19: =IF(C19="","",[1]!hks_fa_roa2(D19,$G$5)) -> 16.7331 | L19: =IF(C19="","",[1]!hks_fa_roe(D19,$G$5)) -> 0 | M19: =IF(C19="","",IF($M$11="EPS",[1]!S_STM07_IS(D19,61,$G$5,$H$13)/IF([1]!s_share_total(D19,$G$5)=0,[1]!s_share_total(D19,[1]!s_ipo_listeddate(D19)),[1]!s_share_total(D19,$G$5)),([1]!s_stm07_bs(D19,75,$G$5,$H$13)+[1]!s_stm07_bs(D19,88,$G$5,$H$13)+[1]!s_stm07_bs(D19,94,$G$5,$H$13)+[1]!s_stm07_bs(D19,95,$G$5,$H$13))/$E$5)) -> #DIV/0! | N19: =IF(C19="","",F19/([1]!S_STM07_IS(D19,61,$G$5,$H$13)/IF([1]!s_share_total(D19,$G$5)=0,[1]!s_share_total(D19,[1]!s_ipo_listeddate(D19)),[1]!s_share_total(D19,$G$5)))) -> #DIV/0! | O19: =IF(C19="","",[1]!s_share_total(D19,TODAY())/$E$5) -> 262.70545 | P19: =IF(C19="","",F19*O19) -> 12806.89 | Q19: =IF(C19="","",HLOOKUP($R$12,$G$11:$P$20003,ROW()-ROW($G$11)+1,FALSE)) -> 12806.89 | R19: =IF(C19="","",RANK(Q19,Q:Q,0)) -> 10
C20: =IF(ROW()-13<=MAX(series),ROW()-13,"") -> 7 | D20: =IF(C20="","",VLOOKUP(C20,comppool,2,FALSE)) -> 1020.HK | E20: =IF(C20="","",VLOOKUP(C20,comppool,3,FALSE)) -> 赛伯乐国际控股 | F20: =IF(C20="","",[1]!s_dq_close(D20,TODAY(),1)) -> 0.074 | G20: =IF(C20="","",[1]!s_pq_pctchange(D20,TODAY()-$G$12,TODAY())/100) -> -0.075 | H20: =IF(C20="","",IF($H$11="收入",[1]!S_STM07_IS(D20,9,$G$5,$H$13)/$E$5,[1]!S_STM07_IS(D20,48,$G$5,$H$13)/$E$5)) -> 111.544 | I20: =IF(C20="","",IF($I$11="毛利率",([1]!S_STM07_IS(D20,9,$G$5,$H$13)-[1]!S_STM07_IS(D20,10,$G$5,$H$13))/[1]!S_STM07_IS(D20,9,$G$5,$H$13),[1]!S_STM07_IS(D20,14,$G$5,$H$13)/$E$5)) -> 0.20334576 | J20: =IF(C20="","",IF($J$11="净利润率",[1]!S_STM07_IS(D20,61,$G$5,$H$13)/[1]!S_STM07_IS(D20,9,$G$5,$H$13),[1]!S_STM07_IS(D20,55,$G$5,$H$13)/$E$5)) -> -0.15747149 | K20: =IF(C20="","",[1]!hks_fa_roa2(D20,$G$5)) -> 3.9826 | L20: =IF(C20="","",[1]!hks_fa_roe(D20,$G$5)) -> -12.7225 | M20: =IF(C20="","",IF($M$11="EPS",[1]!S_STM07_IS(D20,61,$G$5,$H$13)/IF([1]!s_share_total(D20,$G$5)=0,[1]!s_share_total(D20,[1]!s_ipo_listeddate(D20)),[1]!s_share_total(D20,$G$5)),([1]!s_stm07_bs(D20,75,$G$5,$H$13)+[1]!s_stm07_bs(D20,88,$G$5,$H$13)+[1]!s_stm07_bs(D20,94,$G$5,$H$13)+[1]!s_stm07_bs(D20,95,$G$5,$H$13))/$E$5)) -> -0.0044183699 | N20: =IF(C20="","",F20/([1]!S_STM07_IS(D20,61,$G$5,$H$13)/IF([1]!s_share_total(D20,$G$5)=0,[1]!s_share_total(D20,[1]!s_ipo_listeddate(D20)),[1]!s_share_total(D20,$G$5)))) -> -16.748258 | O20: =IF(C20="","",[1]!s_share_total(D20,TODAY())/$E$5) -> 3975.448 | P20: =IF(C20="","",F20*O20) -> 294.18315 | Q20: =IF(C20="","",HLOOKUP($R$12,$G$11:$P$20003,ROW()-ROW($G$11)+1,FALSE)) -> 294.18315 | R20: =IF(C20="","",RANK(Q20,Q:Q,0)) -> 29
C21: =IF(ROW()-13<=MAX(series),ROW()-13,"") -> 8 | D21: =IF(C21="","",VLOOKUP(C21,comppool,2,FALSE)) -> 1039.HK | E21: =IF(C21="","",VLOOKUP(C21,comppool,3,FALSE)) -> 畅由联盟 | F21: =IF(C21="","",[1]!s_dq_close(D21,TODAY(),1)) -> 0.135 | G21: =IF(C21="","",[1]!s_pq_pctchange(D21,TODAY()-$G$12,TODAY())/100) -> -0.035714286 | H21: =IF(C21="","",IF($H$11="收入",[1]!S_STM07_IS(D21,9,$G$5,$H$13)/$E$5,[1]!S_STM07_IS(D21,48,$G$5,$H$13)/$E$5)) -> 226.751 | I21: =IF(C21="","",IF($I$11="毛利率",([1]!S_STM07_IS(D21,9,$G$5,$H$13)-[1]!S_STM07_IS(D21,10,$G$5,$H$13))/[1]!S_STM07_IS(D21,9,$G$5,$H$13),[1]!S_STM07_IS(D21,14,$G$5,$H$13)/$E$5)) -> 0.17320321 | J21: =IF(C21="","",IF($J$11="净利润率",[1]!S_STM07_IS(D21,61,$G$5,$H$13)/[1]!S_STM07_IS(D21,9,$G$5,$H$13),[1]!S_STM07_IS(D21,55,$G$5,$H$13)/$E$5)) -> -0.16565307 | K21: =IF(C21="","",[1]!hks_fa_roa2(D21,$G$5)) -> -5.2765 | L21: =IF(C21="","",[1]!hks_fa_roe(D21,$G$5)) -> -14.8396 | M21: =IF(C21="","",IF($M$11="EPS",[1]!S_STM07_IS(D21,61,$G$5,$H$13)/IF([1]!s_share_total(D21,$G$5)=0,[1]!s_share_total(D21,[1]!s_ipo_listeddate(D21)),[1]!s_share_total(D21,$G$5)),([1]!s_stm07_bs(D21,75,$G$5,$H$13)+[1]!s_stm07_bs(D21,88,$G$5,$H$13)+[1]!s_stm07_bs(D21,94,$G$5,$H$13)+[1]!s_stm07_bs(D21,95,$G$5,$H$13))/$E$5)) -> -0.020741562 | N21: =IF(C21="","",F21/([1]!S_STM07_IS(D21,61,$G$5,$H$13)/IF([1]!s_share_total(D21,$G$5)=0,[1]!s_share_total(D21,[1]!s_ipo_listeddate(D21)),[1]!s_share_total(D21,$G$5)))) -> -6.5086708 | O21: =IF(C21="","",[1]!s_share_total(D21,TODAY())/$E$5) -> 1810.9533 | P21: =IF(C21="","",F21*O21) -> 244.47869 | Q21: =IF(C21="","",HLOOKUP($R$12,$G$11:$P$20003,ROW()-ROW($G$11)+1,FALSE)) -> 244.47869 | R21: =IF(C21="","",RANK(Q21,Q:Q,0)) -> 32
C22: =IF(ROW()-13<=MAX(series),ROW()-13,"") -> 9 | D22: =IF(C22="","",VLOOKUP(C22,comppool,2,FALSE)) -> 1075.HK | E22: =IF(C22="","",VLOOKUP(C22,comppool,3,FALSE)) -> 首都信息 | F22: =IF(C22="","",[1]!s_dq_close(D22,TODAY(),1)) -> 0.249 | G22: =IF(C22="","",[1]!s_pq_pctchange(D22,TODAY()-$G$12,TODAY())/100) -> 0.016326531 | H22: =IF(C22="","",IF($H$11="收入",[1]!S_STM07_IS(D22,9,$G$5,$H$13)/$E$5,[1]!S_STM07_IS(D22,48,$G$5,$H$13)/$E$5)) -> 1425.5818 | I22: =IF(C22="","",IF($I$11="毛利率",([1]!S_STM07_IS(D22,9,$G$5,$H$13)-[1]!S_STM07_IS(D22,10,$G$5,$H$13))/[1]!S_STM07_IS(D22,9,$G$5,$H$13),[1]!S_STM07_IS(D22,14,$G$5,$H$13)/$E$5)) -> 0.27991651 | J22: =IF(C22="","",IF($J$11="净利润率",[1]!S_STM07_IS(D22,61,$G$5,$H$13)/[1]!S_STM07_IS(D22,9,$G$5,$H$13),[1]!S_STM07_IS(D22,55,$G$5,$H$13)/$E$5)) -> -0.05114153 | K22: =IF(C22="","",[1]!hks_fa_roa2(D22,$G$5)) -> -3.9576 | L22: =IF(C22="","",[1]!hks_fa_roe(D22,$G$5)) -> -6.0566 | M22: =IF(C22="","",IF($M$11="EPS",[1]!S_STM07_IS(D22,61,$G$5,$H$13)/IF([1]!s_share_total(D22,$G$5)=0,[1]!s_share_total(D22,[1]!s_ipo_listeddate(D22)),[1]!s_share_total(D22,$G$5)),([1]!s_stm07_bs(D22,75,$G$5,$H$13)+[1]!s_stm07_bs(D22,88,$G$5,$H$13)+[1]!s_stm07_bs(D22,94,$G$5,$H$13)+[1]!s_stm07_bs(D22,95,$G$5,$H$13))/$E$5)) -> -0.025156752 | N22: =IF(C22="","",F22/([1]!S_STM07_IS(D22,61,$G$5,$H$13)/IF([1]!s_share_total(D22,$G$5)=0,[1]!s_share_total(D22,[1]!s_ipo_listeddate(D22)),[1]!s_share_total(D22,$G$5)))) -> -9.8979391 | O22: =IF(C22="","",[1]!s_share_total(D22,TODAY())/$E$5) -> 2898.0861 | P22: =IF(C22="","",F22*O22) -> 721.62344 | Q22: =IF(C22="","",HLOOKUP($R$12,$G$11:$P$20003,ROW()-ROW($G$11)+1,FALSE)) -> 721.62344 | R22: =IF(C22="","",RANK(Q22,Q:Q,0)) -> 25
C23: =IF(ROW()-13<=MAX(series),ROW()-13,"") -> 10 | D23: =IF(C23="","",VLOOKUP(C23,comppool,2,FALSE)) -> 1274.HK | E23: =IF(C23="","",VLOOKUP(C23,comppool,3,FALSE)) -> 知行汽车科技 | F23: =IF(C23="","",[1]!s_dq_close(D23,TODAY(),1)) -> 69.95 | G23: =IF(C23="","",[1]!s_pq_pctchange(D23,TODAY()-$G$12,TODAY())/100) -> 0.10943695 | H23: =IF(C23="","",IF($H$11="收入",[1]!S_STM07_IS(D23,9,$G$5,$H$13)/$E$5,[1]!S_STM07_IS(D23,48,$G$5,$H$13)/$E$5)) -> 1216.287 | I23: =IF(C23="","",IF($I$11="毛利率",([1]!S_STM07_IS(D23,9,$G$5,$H$13)-[1]!S_STM07_IS(D23,10,$G$5,$H$13))/[1]!S_STM07_IS(D23,9,$G$5,$H$13),[1]!S_STM07_IS(D23,14,$G$5,$H$13)/$E$5)) -> 0.099444457 | J23: =IF(C23="","",IF($J$11="净利润率",[1]!S_STM07_IS(D23,61,$G$5,$H$13)/[1]!S_STM07_IS(D23,9,$G$5,$H$13),[1]!S_STM07_IS(D23,55,$G$5,$H$13)/$E$5)) -> -0.1604128 | K23: =IF(C23="","",[1]!hks_fa_roa2(D23,$G$5)) -> -13.4661 | L23: =IF(C23="","",[1]!hks_fa_roe(D23,$G$5)) -> -21.7976 | M23: =IF(C23="","",IF($M$11="EPS",[1]!S_STM07_IS(D23,61,$G$5,$H$13)/IF([1]!s_share_total(D23,$G$5)=0,[1]!s_share_total(D23,[1]!s_ipo_listeddate(D23)),[1]!s_share_total(D23,$G$5)),([1]!s_stm07_bs(D23,75,$G$5,$H$13)+[1]!s_stm07_bs(D23,88,$G$5,$H$13)+[1]!s_stm07_bs(D23,94,$G$5,$H$13)+[1]!s_stm07_bs(D23,95,$G$5,$H$13))/$E$5)) -> -0.86204969 | N23: =IF(C23="","",F23/([1]!S_STM07_IS(D23,61,$G$5,$H$13)/IF([1]!s_share_total(D23,$G$5)=0,[1]!s_share_total(D23,[1]!s_ipo_listeddate(D23)),[1]!s_share_total(D23,$G$5)))) -> -81.143814 | O23: =IF(C23="","",[1]!s_share_total(D23,TODAY())/$E$5) -> 226.33034 | P23: =IF(C23="","",F23*O23) -> 15831.807 | Q23: =IF(C23="","",HLOOKUP($R$12,$G$11:$P$20003,ROW()-ROW($G$11)+1,FALSE)) -> 15831.807 | R23: =IF(C23="","",RANK(Q23,Q:Q,0)) -> 7
C24: =IF(ROW()-13<=MAX(series),ROW()-13,"") -> 11 | D24: =IF(C24="","",VLOOKUP(C24,comppool,2,FALSE)) -> 1686.HK | E24: =IF(C24="","",VLOOKUP(C24,comppool,3,FALSE)) -> 新意网集团 | F24: =IF(C24="","",[1]!s_dq_close(D24,TODAY(),1)) -> 2.58 | G24: =IF(C24="","",[1]!s_pq_pctchange(D24,TODAY()-$G$12,TODAY())/100) -> -0.054945055 | H24: =IF(C24="","",IF($H$11="收入",[1]!S_STM07_IS(D24,9,$G$5,$H$13)/$E$5,[1]!S_STM07_IS(D24,48,$G$5,$H$13)/$E$5)) -> 2345.903 | I24: =IF(C24="","",IF($I$11="毛利率",([1]!S_STM07_IS(D24,9,$G$5,$H$13)-[1]!S_STM07_IS(D24,10,$G$5,$H$13))/[1]!S_STM07_IS(D24,9,$G$5,$H$13),[1]!S_STM07_IS(D24,14,$G$5,$H$13)/$E$5)) -> 0.56302413 | J24: =IF(C24="","",IF($J$11="净利润率",[1]!S_STM07_IS(D24,61,$G$5,$H$13)/[1]!S_STM07_IS(D24,9,$G$5,$H$13),[1]!S_STM07_IS(D24,55,$G$5,$H$13)/$E$5)) -> 0.38593454 | K24: =IF(C24="","",[1]!hks_fa_roa2(D24,$G$5)) -> 6.0985 | L24: =IF(C24="","",[1]!hks_fa_roe(D24,$G$5)) -> 19.6167 | M24: =IF(C24="","",IF($M$11="EPS",[1]!S_STM07_IS(D24,61,$G$5,$H$13)/IF([1]!s_share_total(D24,$G$5)=0,[1]!s_share_total(D24,[1]!s_ipo_listeddate(D24)),[1]!s_share_total(D24,$G$5)),([1]!s_stm07_bs(D24,75,$G$5,$H$13)+[1]!s_stm07_bs(D24,88,$G$5,$H$13)+[1]!s_stm07_bs(D24,94,$G$5,$H$13)+[1]!s_stm07_bs(D24,95,$G$5,$H$13))/$E$5)) -> 0.38706405 | N24: =IF(C24="","",F24/([1]!S_STM07_IS(D24,61,$G$5,$H$13)/IF([1]!s_share_total(D24,$G$5)=0,[1]!s_share_total(D24,[1]!s_ipo_listeddate(D24)),[1]!s_share_total(D24,$G$5)))) -> 6.6655635 | O24: =IF(C24="","",[1]!s_share_total(D24,TODAY())/$E$5) -> 2339.0573 | P24: =IF(C24="","",F24*O24) -> 6034.7679 | Q24: =IF(C24="","",HLOOKUP($R$12,$G$11:$P$20003,ROW()-ROW($G$11)+1,FALSE)) -> 6034.7679 | R24: =IF(C24="","",RANK(Q24,Q:Q,0)) -> 13
C25: =IF(ROW()-13<=MAX(series),ROW()-13,"") -> 12 | D25: =IF(C25="","",VLOOKUP(C25,comppool,2,FALSE)) -> 1736.HK | E25: =IF(C25="","",VLOOKUP(C25,comppool,3,FALSE)) -> 中国育儿网络 | F25: =IF(C25="","",[1]!s_dq_close(D25,TODAY(),1)) -> 0.072 | G25: =IF(C25="","",[1]!s_pq_pctchange(D25,TODAY()-$G$12,TODAY())/100) -> 0.10769231 | H25: =IF(C25="","",IF($H$11="收入",[1]!S_STM07_IS(D25,9,$G$5,$H$13)/$E$5,[1]!S_STM07_IS(D25,48,$G$5,$H$13)/$E$5)) -> 57.444 | I25: =IF(C25="","",IF($I$11="毛利率",([1]!S_STM07_IS(D25,9,$G$5,$H$13)-[1]!S_STM07_IS(D25,10,$G$5,$H$13))/[1]!S_STM07_IS(D25,9,$G$5,$H$13),[1]!S_STM07_IS(D25,14,$G$5,$H$13)/$E$5)) -> 0.043538054 | J25: =IF(C25="","",IF($J$11="净利润率",[1]!S_STM07_IS(D25,61,$G$5,$H$13)/[1]!S_STM07_IS(D25,9,$G$5,$H$13),[1]!S_STM07_IS(D25,55,$G$5,$H$13)/$E$5)) -> -0.8387473 | K25: =IF(C25="","",[1]!hks_fa_roa2(D25,$G$5)) -> -31.901 | L25: =IF(C25="","",[1]!hks_fa_roe(D25,$G$5)) -> -70.1667 | M25: =IF(C25="","",IF($M$11="EPS",[1]!S_STM07_IS(D25,61,$G$5,$H$13)/IF([1]!s_share_total(D25,$G$5)=0,[1]!s_share_total(D25,[1]!s_ipo_listeddate(D25)),[1]!s_share_total(D25,$G$5)),([1]!s_stm07_bs(D25,75,$G$5,$H$13)+[1]!s_stm07_bs(D25,88,$G$5,$H$13)+[1]!s_stm07_bs(D25,94,$G$5,$H$13)+[1]!s_stm07_bs(D25,95,$G$5,$H$13))/$E$5)) -> -0.16726497 | N25: =IF(C25="","",F25/([1]!S_STM07_IS(D25,61,$G$5,$H$13)/IF([1]!s_share_total(D25,$G$5)=0,[1]!s_share_total(D25,[1]!s_ipo_listeddate(D25)),[1]!s_share_total(D25,$G$5)))) -> -0.43045476 | O25: =IF(C25="","",[1]!s_share_total(D25,TODAY())/$E$5) -> 345.66234 | P25: =IF(C25="","",F25*O25) -> 24.887689 | Q25: =IF(C25="","",HLOOKUP($R$12,$G$11:$P$20003,ROW()-ROW($G$11)+1,FALSE)) -> 24.887689 | R25: =IF(C25="","",RANK(Q25,Q:Q,0)) -> 43
... C1500: =IF(ROW()-13<=MAX(series),ROW()-13,"") | D1500: =IF(C1500="","",VLOOKUP(C1500,comppool,2,FALSE)) | E1500: =IF(C1500="","",VLOOKUP(C1500,comppool,3,FALSE)) | F1500: =IF(C1500="","",[1]!s_dq_close(D1500,TODAY(),1)) | G1500: =IF(C1500="","",[1]!s_pq_pctchange(D1500,TODAY()-$G$12,TODAY())/100) | H1500: =IF(C1500="","",IF($H$11="收入",[1]!S_STM07_IS(D1500,9,$G$5,$H$13)/$E$5,[1]!S_STM07_IS(D1500,48,$G$5,$H$13)/$E$5)) | I1500: =IF(C1500="","",IF($I$11="毛利率",([1]!S_STM07_IS(D1500,9,$G$5,$H$13)-[1]!S_STM07_IS(D1500,10,$G$5,$H$13))/[1]!S_STM07_IS(D1500,9,$G$5,$H$13),[1]!S_STM07_IS(D1500,14,$G$5,$H$13)/$E$5)) | J1500: =IF(C1500="","",IF($J$11="净利润率",[1]!S_STM07_IS(D1500,61,$G$5,$H$13)/[1]!S_STM07_IS(D1500,9,$G$5,$H$13),[1]!S_STM07_IS(D1500,55,$G$5,$H$13)/$E$5)) | K1500: =IF(C1500="","",[1]!hks_fa_roa2(D1500,$G$5)) | L1500: =IF(C1500="","",[1]!hks_fa_roe(D1500,$G$5)) | M1500: =IF(C1500="","",IF($M$11="EPS",[1]!S_STM07_IS(D1500,61,$G$5,$H$13)/IF([1]!s_share_total(D1500,$G$5)=0,[1]!s_share_total(D1500,[1]!s_ipo_listeddate(D1500)),[1]!s_share_total(D1500,$G$5)),([1]!s_stm07_bs(D1500,75,$G$5,$H$13)+[1]!s_stm07_bs(D1500,88,$G$5,$H$13)+[1]!s_stm07_bs(D1500,94,$G$5,$H$13)+[1]!s_stm07_bs(D1500,95,$G$5,$H$13))/$E$5)) | N1500: =IF(C1500="","",F1500/([1]!S_STM07_IS(D1500,61,$G$5,$H$13)/IF([1]!s_share_total(D1500,$G$5)=0,[1]!s_share_total(D1500,[1]!s_ipo_listeddate(D1500)),[1]!s_share_total(D1500,$G$5)))) | O1500: =IF(C1500="","",[1]!s_share_total(D1500,TODAY())/$E$5) | P1500: =IF(C1500="","",F1500*O1500) | Q1500: =IF(C1500="","",HLOOKUP($R$12,$G$11:$P$20003,ROW()-ROW($G$11)+1,FALSE)) | R1500: =IF(C1500="","",RANK(Q1500,Q:Q,0))
C1501: =IF(ROW()-13<=MAX(series),ROW()-13,"")
C1502: =IF(ROW()-13<=MAX(series),ROW()-13,"")
C1503: =IF(ROW()-13<=MAX(series),ROW()-13,"")
C1504: =IF(ROW()-13<=MAX(series),ROW()-13,"")
C1505: =IF(ROW()-13<=MAX(series),ROW()-13,"")
C1506: =IF(ROW()-13<=MAX(series),ROW()-13,"")
C1507: =IF(ROW()-13<=MAX(series),ROW()-13,"")
C1508: =IF(ROW()-13<=MAX(series),ROW()-13,"")
C1509: =IF(ROW()-13<=MAX(series),ROW()-13,"")
C1510: =IF(ROW()-13<=MAX(series),ROW()-13,"")
C1511: =IF(ROW()-13<=MAX(series),ROW()-13,"")
C1512: =IF(ROW()-13<=MAX(series),ROW()-13,"")
... C2172: =IF(ROW()-13<=MAX(series),ROW()-13,"")

Sheet 盈利预测
E1: 股票速览-盈利预测
D2: 预测与评级明细
D4: 机构汇总 | E4: 国泰君安 | F4: =VLOOKUP(E4,参数设置!C16:D108,2,FALSE) -> 2
D6: 公司代码 | E6: =公司分析!D4 -> 9626.HK | H6: 最高/最低/均值 | J6: 评级明细 | K6: =IF(D4="自选机构","评级次数","评级家数") -> 评级家数
D7: 证券简称 | E7: =[1]!s_info_name(E6) -> 哔哩哔哩-W | G7: 预测主营收入 | H7: =DMAX(D14:Q99,H14,R14:S15)&"/"&DMIN(D14:Q99,H14,R14:S15)&"/"&TRUNC(DAVERAGE(D14:Q99,H14,R14:S15),0) -> 26107/25059/25515 | J7: 买入 | K7: =COUNTIFS($O$15:$O$99,J7,$AB$15:$AB$99,1) -> 7 | O7: 评级变动 | P7: =IF(D4="自选机构","次数","家数") -> 家数
D8: 预测年份 | E8: =YEAR(E9) -> 2024 | G8: 预测净利润 | H8: =DMAX(D14:Q99,I14,T14:U15)&"/"&DMIN(D14:Q99,I14,T14:U15)&"/"&TRUNC(DAVERAGE(D14:Q99,I14,T14:U15),0) -> -1403.9946/-2463/-1878 | J8: 增持 | K8: =COUNTIFS($O$15:$O$99,J8,$AB$15:$AB$99,1) -> 2 | O8: 首次评级 | P8: =COUNTIFS($AA$15:$AA$99,O8,$AB$15:$AB$99,1) -> 1
D9: 交易日期 | E9: =公司分析!D5 -> 45466 | G9: 预测每股收益 | H9: =TRUNC(DMAX(D14:Q99,J14,V14:W15),3)&"/"&TRUNC(DMIN(D14:Q99,J14,V14:W15),3)&"/"&TRUNC(DAVERAGE(D14:Q99,J14,V14:W15),3) -> -3.332/-5.846/-4.459 | J9: 中性 | K9: =COUNTIFS($O$15:$O$99,J9,$AB$15:$AB$99,1) -> 0 | O9: 评级上调 | P9: =COUNTIFS($AA$15:$AA$99,O9,$AB$15:$AB$99,1) -> 2
D10: 单位 | E10: 1000000 | F10: =IF(E11="自定义",F11,IF(E11="一个月",E9-30,IF(E11="三个月",E9-90,IF(E11="半年",E9-180,E9-365)))) -> 45376 | G10: =IF(D4="自选机构","预测次数","预测机构家数") -> 预测机构家数 | H10: =DCOUNT(D14:Q99,H14,R14:S15)&"/"&DCOUNT(D14:Q99,I14,T14:U15)&"/"&DCOUNT(D14:Q99,J14,V14:W15) -> 11/11/11 | J10: 减持 | K10: =COUNTIFS($O$15:$O$99,J10,$AB$15:$AB$99,1) -> 0 | O10: 评级不变 | P10: =COUNTIFS($AA$15:$AA$99,O10,$AB$15:$AB$99,1) -> 7
D11: 统计区间 | E11: 三个月 | G11: 最新报告 | H11: =MAX(X15:X99) -> 45463 | J11: 卖出 | K11: =COUNTIFS($O$15:$O$99,J11,$AB$15:$AB$99,1) -> 0 | O11: 评级下调 | P11: =COUNTIFS($AA$15:$AA$99,O11,$AB$15:$AB$99,1) -> 0
C14: 预测时间设置 | D14: 序号 | E14: 机构 | F14: 研究员 | G14: 机构最近预测时间 | H14: 机构预测主营业务收入 | I14: 机构预测净利润 | J14: 机构预测每股收益 | K14: 机构最近评级时间 | L14: 评级研究员 | M14: 机构投资评级(原始) | N14: 标准化得分 | O14: 标准化评级 | P14: 机构首次评级时间 | Q14: =E11&"内预测" -> 三个月内预测 | R14: =Q14 -> 三个月内预测 | S14: 机构预测主营业务收入 | T14: =Q14 -> 三个月内预测 | U14: 机构预测净利润 | V14: =Q14 -> 三个月内预测 | W14: 机构预测每股收益 | X14: 预测时间 | Y14: 评级时间设置 | Z14: 机构上次评级(标准化得分) | AA14: 评级变化 | AB14: =E11&"内评级" -> 三个月内评级 | AC14: 评级变动
C15: =E9 -> 45466 | D15: 1 | E15: =IF($D$4="自选机构",$E$4,VLOOKUP(D15,Institutionlist,2,FALSE)) -> 申银万国 | F15: =IF($D$4="自选机构",[1]!S_EST_ESTANALYST($E$6,$E$8,C15,$F$4),[1]!S_EST_ESTANALYST($E$6,$E$8,$E$9,D15)) -> 0 | G15: =IF($D$4="自选机构",[1]!S_EST_ESTNEWTIME_INST($E$6,$E$8,C15,$F$4),[1]!S_EST_ESTNEWTIME_INST($E$6,$E$8,$E$9,D15)) -> 0 | H15: =IF($D$4="自选机构",[1]!S_EST_SALES_INST($E$6,$E$8,C15,$F$4)/currencyunit,[1]!S_EST_SALES_INST($E$6,$E$8,$E$9,D15)/currencyunit) -> 0 | I15: =IF($D$4="自选机构",[1]!S_EST_NETPROFIT_INST($E$6,$E$8,C15,$F$4)/currencyunit,[1]!S_EST_NETPROFIT_INST($E$6,$E$8,$E$9,D15)/currencyunit) -> 0 | J15: =IF($D$4="自选机构",[1]!S_EST_EPS_INST($E$6,$E$8,C15,$F$4),[1]!S_EST_EPS_INST($E$6,$E$8,$E$9,D15)) -> 0 | K15: =IF($D$4="自选机构",[1]!S_EST_NEWRATINGTIME_INST($E$6,Y15,$F$4),[1]!S_EST_NEWRATINGTIME_INST($E$6,$E$9,D15)) -> 0 | L15: =IF($D$4="自选机构",[1]!S_EST_RATINGANALYST($E$6,Y15,$F$4),[1]!S_EST_RATINGANALYST($E$6,$E$9,D15)) -> 0 | M15: =IF($D$4="自选机构",[1]!S_EST_ORGRATING_INST($E$6,Y15,$F$4),[1]!S_EST_ORGRATING_INST($E$6,$E$9,D15)) -> 0 | N15: =IF($D$4="自选机构",[1]!S_EST_SCORERATING_INST($E$6,Y15,$F$4),[1]!S_EST_SCORERATING_INST($E$6,$E$9,D15)) -> 0 | O15: =IF($D$4="自选机构",[1]!S_EST_STDRATING_INST($E$6,Y15,$F$4),[1]!S_EST_STDRATING_INST($E$6,$E$9,D15)) -> 0 | P15: =IF($D$4="自选机构",[1]!S_EST_FRSTRATINGTIME_INST($E$6,$F$4),[1]!S_EST_FRSTRATINGTIME_INST($E$6,D15)) -> 0 | Q15: =IF(G15-$F$10>=0,1,"") | R15: 1 | S15: <>0 | T15: 1 | U15: <>0 | V15: 1 | W15: <>0 | X15: =--G15 -> 0 | Y15: =E9 -> 45466 | Z15: =IF($D$4="自选机构",[1]!S_EST_SCORERATING_INST($E$6,K15-1,$F$4),[1]!S_EST_SCORERATING_INST($E$6,K15-1,D15)) -> 0 | AA15: =IFERROR(IF(Z15/N15>1,"评级上调",IF(Z15/N15=1,"评级不变",IF(Z15/N15>0,"评级下调","首次评级"))),0) -> 0 | AB15: =IF(K15-$F$10>=0,1,"") | AC15: =IF(ISERROR(AA15),"",IF(AA15="评级不变",0,IF(AA15="评级下调",-1,IF(AA15="评级上调",1,""))))
C16: =G15-1 -> -1 | D16: 2 | E16: =IF($D$4="自选机构",$E$4,VLOOKUP(D16,Institutionlist,2,FALSE)) -> 国泰君安 | F16: =IF($D$4="自选机构",[1]!S_EST_ESTANALYST($E$6,$E$8,C16,$F$4),[1]!S_EST_ESTANALYST($E$6,$E$8,$E$9,D16)) -> 秦和平 | G16: =IF($D$4="自选机构",[1]!S_EST_ESTNEWTIME_INST($E$6,$E$8,C16,$F$4),[1]!S_EST_ESTNEWTIME_INST($E$6,$E$8,$E$9,D16)) -> 2024-03-09 | H16: =IF($D$4="自选机构",[1]!S_EST_SALES_INST($E$6,$E$8,C16,$F$4)/currencyunit,[1]!S_EST_SALES_INST($E$6,$E$8,$E$9,D16)/currencyunit) -> 25440 | I16: =IF($D$4="自选机构",[1]!S_EST_NETPROFIT_INST($E$6,$E$8,C16,$F$4)/currencyunit,[1]!S_EST_NETPROFIT_INST($E$6,$E$8,$E$9,D16)/currencyunit) -> -1851 | J16: =IF($D$4="自选机构",[1]!S_EST_EPS_INST($E$6,$E$8,C16,$F$4),[1]!S_EST_EPS_INST($E$6,$E$8,$E$9,D16)) -> -4.3939 | K16: =IF($D$4="自选机构",[1]!S_EST_NEWRATINGTIME_INST($E$6,Y16,$F$4),[1]!S_EST_NEWRATINGTIME_INST($E$6,$E$9,D16)) -> 2024-03-09 | L16: =IF($D$4="自选机构",[1]!S_EST_RATINGANALYST($E$6,Y16,$F$4),[1]!S_EST_RATINGANALYST($E$6,$E$9,D16)) -> 秦和平 | M16: =IF($D$4="自选机构",[1]!S_EST_ORGRATING_INST($E$6,Y16,$F$4),[1]!S_EST_ORGRATING_INST($E$6,$E$9,D16)) -> 国泰君安_增持 | N16: =IF($D$4="自选机构",[1]!S_EST_SCORERATING_INST($E$6,Y16,$F$4),[1]!S_EST_SCORERATING_INST($E$6,$E$9,D16)) -> 1 | O16: =IF($D$4="自选机构",[1]!S_EST_STDRATING_INST($E$6,Y16,$F$4),[1]!S_EST_STDRATING_INST($E$6,$E$9,D16)) -> 增持 | P16: =IF($D$4="自选机构",[1]!S_EST_FRSTRATINGTIME_INST($E$6,$F$4),[1]!S_EST_FRSTRATINGTIME_INST($E$6,D16)) -> 0 | Q16: =IF(G16-$F$10>=0,1,"") | X16: =--G16 -> 45360 | Y16: =K15-1 -> -1 | Z16: =IF($D$4="自选机构",[1]!S_EST_SCORERATING_INST($E$6,K16-1,$F$4),[1]!S_EST_SCORERATING_INST($E$6,K16-1,D16)) -> 1 | AA16: =IFERROR(IF(Z16/N16>1,"评级上调",IF(Z16/N16=1,"评级不变",IF(Z16/N16>0,"评级下调","首次评级"))),0) -> 评级不变 | AB16: =IF(K16-$F$10>=0,1,"") | AC16: =IF(ISERROR(AA16),"",IF(AA16="评级不变",0,IF(AA16="评级下调",-1,IF(AA16="评级上调",1,"")))) -> 0
C17: =G16-1 -> 45359 | D17: 3 | E17: =IF($D$4="自选机构",$E$4,VLOOKUP(D17,Institutionlist,2,FALSE)) -> 中银国际 | F17: =IF($D$4="自选机构",[1]!S_EST_ESTANALYST($E$6,$E$8,C17,$F$4),[1]!S_EST_ESTANALYST($E$6,$E$8,$E$9,D17)) -> 卢翌 | G17: =IF($D$4="自选机构",[1]!S_EST_ESTNEWTIME_INST($E$6,$E$8,C17,$F$4),[1]!S_EST_ESTNEWTIME_INST($E$6,$E$8,$E$9,D17)) -> 2024-05-24 | H17: =IF($D$4="自选机构",[1]!S_EST_SALES_INST($E$6,$E$8,C17,$F$4)/currencyunit,[1]!S_EST_SALES_INST($E$6,$E$8,$E$9,D17)/currencyunit) -> 25821 | I17: =IF($D$4="自选机构",[1]!S_EST_NETPROFIT_INST($E$6,$E$8,C17,$F$4)/currencyunit,[1]!S_EST_NETPROFIT_INST($E$6,$E$8,$E$9,D17)/currencyunit) -> -1966 | J17: =IF($D$4="自选机构",[1]!S_EST_EPS_INST($E$6,$E$8,C17,$F$4),[1]!S_EST_EPS_INST($E$6,$E$8,$E$9,D17)) -> -4.6669 | K17: =IF($D$4="自选机构",[1]!S_EST_NEWRATINGTIME_INST($E$6,Y17,$F$4),[1]!S_EST_NEWRATINGTIME_INST($E$6,$E$9,D17)) -> 2024-05-24 | L17: =IF($D$4="自选机构",[1]!S_EST_RATINGANALYST($E$6,Y17,$F$4),[1]!S_EST_RATINGANALYST($E$6,$E$9,D17)) -> 卢翌 | M17: =IF($D$4="自选机构",[1]!S_EST_ORGRATING_INST($E$6,Y17,$F$4),[1]!S_EST_ORGRATING_INST($E$6,$E$9,D17)) -> 中银证券_买入 | N17: =IF($D$4="自选机构",[1]!S_EST_SCORERATING_INST($E$6,Y17,$F$4),[1]!S_EST_SCORERATING_INST($E$6,$E$9,D17)) -> 1 | O17: =IF($D$4="自选机构",[1]!S_EST_STDRATING_INST($E$6,Y17,$F$4),[1]!S_EST_STDRATING_INST($E$6,$E$9,D17)) -> 买入 | P17: =IF($D$4="自选机构",[1]!S_EST_FRSTRATINGTIME_INST($E$6,$F$4),[1]!S_EST_FRSTRATINGTIME_INST($E$6,D17)) -> 0 | Q17: =IF(G17-$F$10>=0,1,"") -> 1 | X17: =--G17 -> 45436 | Y17: =K16-1 -> 45359 | Z17: =IF($D$4="自选机构",[1]!S_EST_SCORERATING_INST($E$6,K17-1,$F$4),[1]!S_EST_SCORERATING_INST($E$6,K17-1,D17)) -> 3 | AA17: =IFERROR(IF(Z17/N17>1,"评级上调",IF(Z17/N17=1,"评级不变",IF(Z17/N17>0,"评级下调","首次评级"))),0) -> 评级上调 | AB17: =IF(K17-$F$10>=0,1,"") -> 1 | AC17: =IF(ISERROR(AA17),"",IF(AA17="评级不变",0,IF(AA17="评级下调",-1,IF(AA17="评级上调",1,"")))) -> 1
C18: =G17-1 -> 45435 | D18: 4 | E18: =IF($D$4="自选机构",$E$4,VLOOKUP(D18,Institutionlist,2,FALSE)) -> 国信证券 | F18: =IF($D$4="自选机构",[1]!S_EST_ESTANALYST($E$6,$E$8,C18,$F$4),[1]!S_EST_ESTANALYST($E$6,$E$8,$E$9,D18)) -> 0 | G18: =IF($D$4="自选机构",[1]!S_EST_ESTNEWTIME_INST($E$6,$E$8,C18,$F$4),[1]!S_EST_ESTNEWTIME_INST($E$6,$E$8,$E$9,D18)) -> 0 | H18: =IF($D$4="自选机构",[1]!S_EST_SALES_INST($E$6,$E$8,C18,$F$4)/currencyunit,[1]!S_EST_SALES_INST($E$6,$E$8,$E$9,D18)/currencyunit) -> 0 | I18: =IF($D$4="自选机构",[1]!S_EST_NETPROFIT_INST($E$6,$E$8,C18,$F$4)/currencyunit,[1]!S_EST_NETPROFIT_INST($E$6,$E$8,$E$9,D18)/currencyunit) -> 0 | J18: =IF($D$4="自选机构",[1]!S_EST_EPS_INST($E$6,$E$8,C18,$F$4),[1]!S_EST_EPS_INST($E$6,$E$8,$E$9,D18)) -> 0 | K18: =IF($D$4="自选机构",[1]!S_EST_NEWRATINGTIME_INST($E$6,Y18,$F$4),[1]!S_EST_NEWRATINGTIME_INST($E$6,$E$9,D18)) -> 0 | L18: =IF($D$4="自选机构",[1]!S_EST_RATINGANALYST($E$6,Y18,$F$4),[1]!S_EST_RATINGANALYST($E$6,$E$9,D18)) -> 0 | M18: =IF($D$4="自选机构",[1]!S_EST_ORGRATING_INST($E$6,Y18,$F$4),[1]!S_EST_ORGRATING_INST($E$6,$E$9,D18)) -> 0 | N18: =IF($D$4="自选机构",[1]!S_EST_SCORERATING_INST($E$6,Y18,$F$4),[1]!S_EST_SCORERATING_INST($E$6,$E$9,D18)) -> 0 | O18: =IF($D$4="自选机构",[1]!S_EST_STDRATING_INST($E$6,Y18,$F$4),[1]!S_EST_STDRATING_INST($E$6,$E$9,D18)) -> 0 | P18: =IF($D$4="自选机构",[1]!S_EST_FRSTRATINGTIME_INST($E$6,$F$4),[1]!S_EST_FRSTRATINGTIME_INST($E$6,D18)) -> 0 | Q18: =IF(G18-$F$10>=0,1,"") | X18: =--G18 -> 0 | Y18: =K17-1 -> 45435 | Z18: =IF($D$4="自选机构",[1]!S_EST_SCORERATING_INST($E$6,K18-1,$F$4),[1]!S_EST_SCORERATING_INST($E$6,K18-1,D18)) -> 0 | AA18: =IFERROR(IF(Z18/N18>1,"评级上调",IF(Z18/N18=1,"评级不变",IF(Z18/N18>0,"评级下调","首次评级"))),0) -> 0 | AB18: =IF(K18-$F$10>=0,1,"") | AC18: =IF(ISERROR(AA18),"",IF(AA18="评级不变",0,IF(AA18="评级下调",-1,IF(AA18="评级上调",1,""))))
C19: =G18-1 -> -1 | D19: 5 | E19: =IF($D$4="自选机构",$E$4,VLOOKUP(D19,Institutionlist,2,FALSE)) -> 海通证券 | F19: =IF($D$4="自选机构",[1]!S_EST_ESTANALYST($E$6,$E$8,C19,$F$4),[1]!S_EST_ESTANALYST($E$6,$E$8,$E$9,D19)) -> 0 | G19: =IF($D$4="自选机构",[1]!S_EST_ESTNEWTIME_INST($E$6,$E$8,C19,$F$4),[1]!S_EST_ESTNEWTIME_INST($E$6,$E$8,$E$9,D19)) -> 0 | H19: =IF($D$4="自选机构",[1]!S_EST_SALES_INST($E$6,$E$8,C19,$F$4)/currencyunit,[1]!S_EST_SALES_INST($E$6,$E$8,$E$9,D19)/currencyunit) -> 0 | I19: =IF($D$4="自选机构",[1]!S_EST_NETPROFIT_INST($E$6,$E$8,C19,$F$4)/currencyunit,[1]!S_EST_NETPROFIT_INST($E$6,$E$8,$E$9,D19)/currencyunit) -> 0 | J19: =IF($D$4="自选机构",[1]!S_EST_EPS_INST($E$6,$E$8,C19,$F$4),[1]!S_EST_EPS_INST($E$6,$E$8,$E$9,D19)) -> 0 | K19: =IF($D$4="自选机构",[1]!S_EST_NEWRATINGTIME_INST($E$6,Y19,$F$4),[1]!S_EST_NEWRATINGTIME_INST($E$6,$E$9,D19)) -> 0 | L19: =IF($D$4="自选机构",[1]!S_EST_RATINGANALYST($E$6,Y19,$F$4),[1]!S_EST_RATINGANALYST($E$6,$E$9,D19)) -> 0 | M19: =IF($D$4="自选机构",[1]!S_EST_ORGRATING_INST($E$6,Y19,$F$4),[1]!S_EST_ORGRATING_INST($E$6,$E$9,D19)) -> 0 | N19: =IF($D$4="自选机构",[1]!S_EST_SCORERATING_INST($E$6,Y19,$F$4),[1]!S_EST_SCORERATING_INST($E$6,$E$9,D19)) -> 0 | O19: =IF($D$4="自选机构",[1]!S_EST_STDRATING_INST($E$6,Y19,$F$4),[1]!S_EST_STDRATING_INST($E$6,$E$9,D19)) -> 0 | P19: =IF($D$4="自选机构",[1]!S_EST_FRSTRATINGTIME_INST($E$6,$F$4),[1]!S_EST_FRSTRATINGTIME_INST($E$6,D19)) -> 0 | Q19: =IF(G19-$F$10>=0,1,"") | X19: =--G19 -> 0 | Y19: =K18-1 -> -1 | Z19: =IF($D$4="自选机构",[1]!S_EST_SCORERATING_INST($E$6,K19-1,$F$4),[1]!S_EST_SCORERATING_INST($E$6,K19-1,D19)) -> 0 | AA19: =IFERROR(IF(Z19/N19>1,"评级上调",IF(Z19/N19=1,"评级不变",IF(Z19/N19>0,"评级下调","首次评级"))),0) -> 0 | AB19: =IF(K19-$F$10>=0,1,"") | AC19: =IF(ISERROR(AA19),"",IF(AA19="评级不变",0,IF(AA19="评级下调",-1,IF(AA19="评级上调",1,""))))
C20: =G19-1 -> -1 | D20: 6 | E20: =IF($D$4="自选机构",$E$4,VLOOKUP(D20,Institutionlist,2,FALSE)) -> 招商证券 | F20: =IF($D$4="自选机构",[1]!S_EST_ESTANALYST($E$6,$E$8,C20,$F$4),[1]!S_EST_ESTANALYST($E$6,$E$8,$E$9,D20)) -> 0 | G20: =IF($D$4="自选机构",[1]!S_EST_ESTNEWTIME_INST($E$6,$E$8,C20,$F$4),[1]!S_EST_ESTNEWTIME_INST($E$6,$E$8,$E$9,D20)) -> 0 | H20: =IF($D$4="自选机构",[1]!S_EST_SALES_INST($E$6,$E$8,C20,$F$4)/currencyunit,[1]!S_EST_SALES_INST($E$6,$E$8,$E$9,D20)/currencyunit) -> 0 | I20: =IF($D$4="自选机构",[1]!S_EST_NETPROFIT_INST($E$6,$E$8,C20,$F$4)/currencyunit,[1]!S_EST_NETPROFIT_INST($E$6,$E$8,$E$9,D20)/currencyunit) -> 0 | J20: =IF($D$4="自选机构",[1]!S_EST_EPS_INST($E$6,$E$8,C20,$F$4),[1]!S_EST_EPS_INST($E$6,$E$8,$E$9,D20)) -> 0 | K20: =IF($D$4="自选机构",[1]!S_EST_NEWRATINGTIME_INST($E$6,Y20,$F$4),[1]!S_EST_NEWRATINGTIME_INST($E$6,$E$9,D20)) -> 2024-05-29 | L20: =IF($D$4="自选机构",[1]!S_EST_RATINGANALYST($E$6,Y20,$F$4),[1]!S_EST_RATINGANALYST($E$6,$E$9,D20)) -> 顾佳 | M20: =IF($D$4="自选机构",[1]!S_EST_ORGRATING_INST($E$6,Y20,$F$4),[1]!S_EST_ORGRATING_INST($E$6,$E$9,D20)) -> 招商证券_增持 | N20: =IF($D$4="自选机构",[1]!S_EST_SCORERATING_INST($E$6,Y20,$F$4),[1]!S_EST_SCORERATING_INST($E$6,$E$9,D20)) -> 2 | O20: =IF($D$4="自选机构",[1]!S_EST_STDRATING_INST($E$6,Y20,$F$4),[1]!S_EST_STDRATING_INST($E$6,$E$9,D20)) -> 增持 | P20: =IF($D$4="自选机构",[1]!S_EST_FRSTRATINGTIME_INST($E$6,$F$4),[1]!S_EST_FRSTRATINGTIME_INST($E$6,D20)) -> 0 | Q20: =IF(G20-$F$10>=0,1,"") | X20: =--G20 -> 0 | Y20: =K19-1 -> -1 | Z20: =IF($D$4="自选机构",[1]!S_EST_SCORERATING_INST($E$6,K20-1,$F$4),[1]!S_EST_SCORERATING_INST($E$6,K20-1,D20)) -> 0 | AA20: =IFERROR(IF(Z20/N20>1,"评级上调",IF(Z20/N20=1,"评级不变",IF(Z20/N20>0,"评级下调","首次评级"))),0) -> 首次评级 | AB20: =IF(K20-$F$10>=0,1,"") -> 1 | AC20: =IF(ISERROR(AA20),"",IF(AA20="评级不变",0,IF(AA20="评级下调",-1,IF(AA20="评级上调",1,""))))
C21: =G20-1 -> -1 | D21: 7 | E21: =IF($D$4="自选机构",$E$4,VLOOKUP(D21,Institutionlist,2,FALSE)) -> 光大证券 | F21: =IF($D$4="自选机构",[1]!S_EST_ESTANALYST($E$6,$E$8,C21,$F$4),[1]!S_EST_ESTANALYST($E$6,$E$8,$E$9,D21)) -> 付天姿 | G21: =IF($D$4="自选机构",[1]!S_EST_ESTNEWTIME_INST($E$6,$E$8,C21,$F$4),[1]!S_EST_ESTNEWTIME_INST($E$6,$E$8,$E$9,D21)) -> 2024-06-20 | H21: =IF($D$4="自选机构",[1]!S_EST_SALES_INST($E$6,$E$8,C21,$F$4)/currencyunit,[1]!S_EST_SALES_INST($E$6,$E$8,$E$9,D21)/currencyunit) -> 26107 | I21: =IF($D$4="自选机构",[1]!S_EST_NETPROFIT_INST($E$6,$E$8,C21,$F$4)/currencyunit,[1]!S_EST_NETPROFIT_INST($E$6,$E$8,$E$9,D21)/currencyunit) -> -1558.995 | J21: =IF($D$4="自选机构",[1]!S_EST_EPS_INST($E$6,$E$8,C21,$F$4),[1]!S_EST_EPS_INST($E$6,$E$8,$E$9,D21)) -> -3.7008 | K21: =IF($D$4="自选机构",[1]!S_EST_NEWRATINGTIME_INST($E$6,Y21,$F$4),[1]!S_EST_NEWRATINGTIME_INST($E$6,$E$9,D21)) -> 0 | L21: =IF($D$4="自选机构",[1]!S_EST_RATINGANALYST($E$6,Y21,$F$4),[1]!S_EST_RATINGANALYST($E$6,$E$9,D21)) -> 0 | M21: =IF($D$4="自选机构",[1]!S_EST_ORGRATING_INST($E$6,Y21,$F$4),[1]!S_EST_ORGRATING_INST($E$6,$E$9,D21)) -> 0 | N21: =IF($D$4="自选机构",[1]!S_EST_SCORERATING_INST($E$6,Y21,$F$4),[1]!S_EST_SCORERATING_INST($E$6,$E$9,D21)) -> 0 | O21: =IF($D$4="自选机构",[1]!S_EST_STDRATING_INST($E$6,Y21,$F$4),[1]!S_EST_STDRATING_INST($E$6,$E$9,D21)) -> 0 | P21: =IF($D$4="自选机构",[1]!S_EST_FRSTRATINGTIME_INST($E$6,$F$4),[1]!S_EST_FRSTRATINGTIME_INST($E$6,D21)) -> 0 | Q21: =IF(G21-$F$10>=0,1,"") -> 1 | X21: =--G21 -> 45463 | Y21: =K20-1 -> 45440 | Z21: =IF($D$4="自选机构",[1]!S_EST_SCORERATING_INST($E$6,K21-1,$F$4),[1]!S_EST_SCORERATING_INST($E$6,K21-1,D21)) -> 0 | AA21: =IFERROR(IF(Z21/N21>1,"评级上调",IF(Z21/N21=1,"评级不变",IF(Z21/N21>0,"评级下调","首次评级"))),0) -> 0 | AB21: =IF(K21-$F$10>=0,1,"") | AC21: =IF(ISERROR(AA21),"",IF(AA21="评级不变",0,IF(AA21="评级下调",-1,IF(AA21="评级上调",1,""))))
C22: =G21-1 -> 45462 | D22: 8 | E22: =IF($D$4="自选机构",$E$4,VLOOKUP(D22,Institutionlist,2,FALSE)) -> 中信证券 | F22: =IF($D$4="自选机构",[1]!S_EST_ESTANALYST($E$6,$E$8,C22,$F$4),[1]!S_EST_ESTANALYST($E$6,$E$8,$E$9,D22)) -> 0 | G22: =IF($D$4="自选机构",[1]!S_EST_ESTNEWTIME_INST($E$6,$E$8,C22,$F$4),[1]!S_EST_ESTNEWTIME_INST($E$6,$E$8,$E$9,D22)) -> 0 | H22: =IF($D$4="自选机构",[1]!S_EST_SALES_INST($E$6,$E$8,C22,$F$4)/currencyunit,[1]!S_EST_SALES_INST($E$6,$E$8,$E$9,D22)/currencyunit) -> 0 | I22: =IF($D$4="自选机构",[1]!S_EST_NETPROFIT_INST($E$6,$E$8,C22,$F$4)/currencyunit,[1]!S_EST_NETPROFIT_INST($E$6,$E$8,$E$9,D22)/currencyunit) -> 0 | J22: =IF($D$4="自选机构",[1]!S_EST_EPS_INST($E$6,$E$8,C22,$F$4),[1]!S_EST_EPS_INST($E$6,$E$8,$E$9,D22)) -> 0 | K22: =IF($D$4="自选机构",[1]!S_EST_NEWRATINGTIME_INST($E$6,Y22,$F$4),[1]!S_EST_NEWRATINGTIME_INST($E$6,$E$9,D22)) -> 0 | L22: =IF($D$4="自选机构",[1]!S_EST_RATINGANALYST($E$6,Y22,$F$4),[1]!S_EST_RATINGANALYST($E$6,$E$9,D22)) -> 0 | M22: =IF($D$4="自选机构",[1]!S_EST_ORGRATING_INST($E$6,Y22,$F$4),[1]!S_EST_ORGRATING_INST($E$6,$E$9,D22)) -> 0 | N22: =IF($D$4="自选机构",[1]!S_EST_SCORERATING_INST($E$6,Y22,$F$4),[1]!S_EST_SCORERATING_INST($E$6,$E$9,D22)) -> 0 | O22: =IF($D$4="自选机构",[1]!S_EST_STDRATING_INST($E$6,Y22,$F$4),[1]!S_EST_STDRATING_INST($E$6,$E$9,D22)) -> 0 | P22: =IF($D$4="自选机构",[1]!S_EST_FRSTRATINGTIME_INST($E$6,$F$4),[1]!S_EST_FRSTRATINGTIME_INST($E$6,D22)) -> 0 | Q22: =IF(G22-$F$10>=0,1,"") | X22: =--G22 -> 0 | Y22: =K21-1 -> -1 | Z22: =IF($D$4="自选机构",[1]!S_EST_SCORERATING_INST($E$6,K22-1,$F$4),[1]!S_EST_SCORERATING_INST($E$6,K22-1,D22)) -> 0 | AA22: =IFERROR(IF(Z22/N22>1,"评级上调",IF(Z22/N22=1,"评级不变",IF(Z22/N22>0,"评级下调","首次评级"))),0) -> 0 | AB22: =IF(K22-$F$10>=0,1,"") | AC22: =IF(ISERROR(AA22),"",IF(AA22="评级不变",0,IF(AA22="评级下调",-1,IF(AA22="评级上调",1,""))))
C23: =G22-1 -> -1 | D23: 9 | E23: =IF($D$4="自选机构",$E$4,VLOOKUP(D23,Institutionlist,2,FALSE)) -> 国金证券 | F23: =IF($D$4="自选机构",[1]!S_EST_ESTANALYST($E$6,$E$8,C23,$F$4),[1]!S_EST_ESTANALYST($E$6,$E$8,$E$9,D23)) -> 陈泽敏 | G23: =IF($D$4="自选机构",[1]!S_EST_ESTNEWTIME_INST($E$6,$E$8,C23,$F$4),[1]!S_EST_ESTNEWTIME_INST($E$6,$E$8,$E$9,D23)) -> 2024-03-09 | H23: =IF($D$4="自选机构",[1]!S_EST_SALES_INST($E$6,$E$8,C23,$F$4)/currencyunit,[1]!S_EST_SALES_INST($E$6,$E$8,$E$9,D23)/currencyunit) -> 25667 | I23: =IF($D$4="自选机构",[1]!S_EST_NETPROFIT_INST($E$6,$E$8,C23,$F$4)/currencyunit,[1]!S_EST_NETPROFIT_INST($E$6,$E$8,$E$9,D23)/currencyunit) -> -1767.0179 | J23: =IF($D$4="自选机构",[1]!S_EST_EPS_INST($E$6,$E$8,C23,$F$4),[1]!S_EST_EPS_INST($E$6,$E$8,$E$9,D23)) -> -4.1945 | K23: =IF($D$4="自选机构",[1]!S_EST_NEWRATINGTIME_INST($E$6,Y23,$F$4),[1]!S_EST_NEWRATINGTIME_INST($E$6,$E$9,D23)) -> 2024-03-09 | L23: =IF($D$4="自选机构",[1]!S_EST_RATINGANALYST($E$6,Y23,$F$4),[1]!S_EST_RATINGANALYST($E$6,$E$9,D23)) -> 陈泽敏 | M23: =IF($D$4="自选机构",[1]!S_EST_ORGRATING_INST($E$6,Y23,$F$4),[1]!S_EST_ORGRATING_INST($E$6,$E$9,D23)) -> 国金证券_买入 | N23: =IF($D$4="自选机构",[1]!S_EST_SCORERATING_INST($E$6,Y23,$F$4),[1]!S_EST_SCORERATING_INST($E$6,$E$9,D23)) -> 1 | O23: =IF($D$4="自选机构",[1]!S_EST_STDRATING_INST($E$6,Y23,$F$4),[1]!S_EST_STDRATING_INST($E$6,$E$9,D23)) -> 买入 | P23: =IF($D$4="自选机构",[1]!S_EST_FRSTRATINGTIME_INST($E$6,$F$4),[1]!S_EST_FRSTRATINGTIME_INST($E$6,D23)) -> 0 | Q23: =IF(G23-$F$10>=0,1,"") | X23: =--G23 -> 45360 | Y23: =K22-1 -> -1 | Z23: =IF($D$4="自选机构",[1]!S_EST_SCORERATING_INST($E$6,K23-1,$F$4),[1]!S_EST_SCORERATING_INST($E$6,K23-1,D23)) -> 0 | AA23: =IFERROR(IF(Z23/N23>1,"评级上调",IF(Z23/N23=1,"评级不变",IF(Z23/N23>0,"评级下调","首次评级"))),0) -> 首次评级 | AB23: =IF(K23-$F$10>=0,1,"") | AC23: =IF(ISERROR(AA23),"",IF(AA23="评级不变",0,IF(AA23="评级下调",-1,IF(AA23="评级上调",1,""))))
C24: =G23-1 -> 45359 | D24: 10 | E24: =IF($D$4="自选机构",$E$4,VLOOKUP(D24,Institutionlist,2,FALSE)) -> 兴业证券 | F24: =IF($D$4="自选机构",[1]!S_EST_ESTANALYST($E$6,$E$8,C24,$F$4),[1]!S_EST_ESTANALYST($E$6,$E$8,$E$9,D24)) -> 0 | G24: =IF($D$4="自选机构",[1]!S_EST_ESTNEWTIME_INST($E$6,$E$8,C24,$F$4),[1]!S_EST_ESTNEWTIME_INST($E$6,$E$8,$E$9,D24)) -> 0 | H24: =IF($D$4="自选机构",[1]!S_EST_SALES_INST($E$6,$E$8,C24,$F$4)/currencyunit,[1]!S_EST_SALES_INST($E$6,$E$8,$E$9,D24)/currencyunit) -> 0 | I24: =IF($D$4="自选机构",[1]!S_EST_NETPROFIT_INST($E$6,$E$8,C24,$F$4)/currencyunit,[1]!S_EST_NETPROFIT_INST($E$6,$E$8,$E$9,D24)/currencyunit) -> 0 | J24: =IF($D$4="自选机构",[1]!S_EST_EPS_INST($E$6,$E$8,C24,$F$4),[1]!S_EST_EPS_INST($E$6,$E$8,$E$9,D24)) -> 0 | K24: =IF($D$4="自选机构",[1]!S_EST_NEWRATINGTIME_INST($E$6,Y24,$F$4),[1]!S_EST_NEWRATINGTIME_INST($E$6,$E$9,D24)) -> 0 | L24: =IF($D$4="自选机构",[1]!S_EST_RATINGANALYST($E$6,Y24,$F$4),[1]!S_EST_RATINGANALYST($E$6,$E$9,D24)) -> 0 | M24: =IF($D$4="自选机构",[1]!S_EST_ORGRATING_INST($E$6,Y24,$F$4),[1]!S_EST_ORGRATING_INST($E$6,$E$9,D24)) -> 0 | N24: =IF($D$4="自选机构",[1]!S_EST_SCORERATING_INST($E$6,Y24,$F$4),[1]!S_EST_SCORERATING_INST($E$6,$E$9,D24)) -> 0 | O24: =IF($D$4="自选机构",[1]!S_EST_STDRATING_INST($E$6,Y24,$F$4),[1]!S_EST_STDRATING_INST($E$6,$E$9,D24)) -> 0 | P24: =IF($D$4="自选机构",[1]!S_EST_FRSTRATINGTIME_INST($E$6,$F$4),[1]!S_EST_FRSTRATINGTIME_INST($E$6,D24)) -> 0 | Q24: =IF(G24-$F$10>=0,1,"") | X24: =--G24 -> 0 | Y24: =K23-1 -> 45359 | Z24: =IF($D$4="自选机构",[1]!S_EST_SCORERATING_INST($E$6,K24-1,$F$4),[1]!S_EST_SCORERATING_INST($E$6,K24-1,D24)) -> 0 | AA24: =IFERROR(IF(Z24/N24>1,"评级上调",IF(Z24/N24=1,"评级不变",IF(Z24/N24>0,"评级下调","首次评级"))),0) -> 0 | AB24: =IF(K24-$F$10>=0,1,"") | AC24: =IF(ISERROR(AA24),"",IF(AA24="评级不变",0,IF(AA24="评级下调",-1,IF(AA24="评级上调",1,""))))
C25: =G24-1 -> -1 | D25: 11 | E25: =IF($D$4="自选机构",$E$4,VLOOKUP(D25,Institutionlist,2,FALSE)) -> 东方证券 | F25: =IF($D$4="自选机构",[1]!S_EST_ESTANALYST($E$6,$E$8,C25,$F$4),[1]!S_EST_ESTANALYST($E$6,$E$8,$E$9,D25)) -> 项雯倩 | G25: =IF($D$4="自选机构",[1]!S_EST_ESTNEWTIME_INST($E$6,$E$8,C25,$F$4),[1]!S_EST_ESTNEWTIME_INST($E$6,$E$8,$E$9,D25)) -> 2024-05-26 | H25: =IF($D$4="自选机构",[1]!S_EST_SALES_INST($E$6,$E$8,C25,$F$4)/currencyunit,[1]!S_EST_SALES_INST($E$6,$E$8,$E$9,D25)/currencyunit) -> 25711 | I25: =IF($D$4="自选机构",[1]!S_EST_NETPROFIT_INST($E$6,$E$8,C25,$F$4)/currencyunit,[1]!S_EST_NETPROFIT_INST($E$6,$E$8,$E$9,D25)/currencyunit) -> -1403.9946 | J25: =IF($D$4="自选机构",[1]!S_EST_EPS_INST($E$6,$E$8,C25,$F$4),[1]!S_EST_EPS_INST($E$6,$E$8,$E$9,D25)) -> -3.3328 | K25: =IF($D$4="自选机构",[1]!S_EST_NEWRATINGTIME_INST($E$6,Y25,$F$4),[1]!S_EST_NEWRATINGTIME_INST($E$6,$E$9,D25)) -> 2024-05-26 | L25: =IF($D$4="自选机构",[1]!S_EST_RATINGANALYST($E$6,Y25,$F$4),[1]!S_EST_RATINGANALYST($E$6,$E$9,D25)) -> 项雯倩 | M25: =IF($D$4="自选机构",[1]!S_EST_ORGRATING_INST($E$6,Y25,$F$4),[1]!S_EST_ORGRATING_INST($E$6,$E$9,D25)) -> 东方证券_买入 | N25: =IF($D$4="自选机构",[1]!S_EST_SCORERATING_INST($E$6,Y25,$F$4),[1]!S_EST_SCORERATING_INST($E$6,$E$9,D25)) -> 1 | O25: =IF($D$4="自选机构",[1]!S_EST_STDRATING_INST($E$6,Y25,$F$4),[1]!S_EST_STDRATING_INST($E$6,$E$9,D25)) -> 买入 | P25: =IF($D$4="自选机构",[1]!S_EST_FRSTRATINGTIME_INST($E$6,$F$4),[1]!S_EST_FRSTRATINGTIME_INST($E$6,D25)) -> 0 | Q25: =IF(G25-$F$10>=0,1,"") -> 1 | X25: =--G25 -> 45438 | Y25: =K24-1 -> -1 | Z25: =IF($D$4="自选机构",[1]!S_EST_SCORERATING_INST($E$6,K25-1,$F$4),[1]!S_EST_SCORERATING_INST($E$6,K25-1,D25)) -> 1 | AA25: =IFERROR(IF(Z25/N25>1,"评级上调",IF(Z25/N25=1,"评级不变",IF(Z25/N25>0,"评级下调","首次评级"))),0) -> 评级不变 | AB25: =IF(K25-$F$10>=0,1,"") -> 1 | AC25: =IF(ISERROR(AA25),"",IF(AA25="评级不变",0,IF(AA25="评级下调",-1,IF(AA25="评级上调",1,"")))) -> 0
C26: =G25-1 -> 45437 | D26: 12 | E26: =IF($D$4="自选机构",$E$4,VLOOKUP(D26,Institutionlist,2,FALSE)) -> 长江证券 | F26: =IF($D$4="自选机构",[1]!S_EST_ESTANALYST($E$6,$E$8,C26,$F$4),[1]!S_EST_ESTANALYST($E$6,$E$8,$E$9,D26)) -> 0 | G26: =IF($D$4="自选机构",[1]!S_EST_ESTNEWTIME_INST($E$6,$E$8,C26,$F$4),[1]!S_EST_ESTNEWTIME_INST($E$6,$E$8,$E$9,D26)) -> 0 | H26: =IF($D$4="自选机构",[1]!S_EST_SALES_INST($E$6,$E$8,C26,$F$4)/currencyunit,[1]!S_EST_SALES_INST($E$6,$E$8,$E$9,D26)/currencyunit) -> 0 | I26: =IF($D$4="自选机构",[1]!S_EST_NETPROFIT_INST($E$6,$E$8,C26,$F$4)/currencyunit,[1]!S_EST_NETPROFIT_INST($E$6,$E$8,$E$9,D26)/currencyunit) -> 0 | J26: =IF($D$4="自选机构",[1]!S_EST_EPS_INST($E$6,$E$8,C26,$F$4),[1]!S_EST_EPS_INST($E$6,$E$8,$E$9,D26)) -> 0 | K26: =IF($D$4="自选机构",[1]!S_EST_NEWRATINGTIME_INST($E$6,Y26,$F$4),[1]!S_EST_NEWRATINGTIME_INST($E$6,$E$9,D26)) -> 2024-03-12 | L26: =IF($D$4="自选机构",[1]!S_EST_RATINGANALYST($E$6,Y26,$F$4),[1]!S_EST_RATINGANALYST($E$6,$E$9,D26)) -> 高超 | M26: =IF($D$4="自选机构",[1]!S_EST_ORGRATING_INST($E$6,Y26,$F$4),[1]!S_EST_ORGRATING_INST($E$6,$E$9,D26)) -> 长江证券_买入 | N26: =IF($D$4="自选机构",[1]!S_EST_SCORERATING_INST($E$6,Y26,$F$4),[1]!S_EST_SCORERATING_INST($E$6,$E$9,D26)) -> 1 | O26: =IF($D$4="自选机构",[1]!S_EST_STDRATING_INST($E$6,Y26,$F$4),[1]!S_EST_STDRATING_INST($E$6,$E$9,D26)) -> 买入 | P26: =IF($D$4="自选机构",[1]!S_EST_FRSTRATINGTIME_INST($E$6,$F$4),[1]!S_EST_FRSTRATINGTIME_INST($E$6,D26)) -> 0 | Q26: =IF(G26-$F$10>=0,1,"") | X26: =--G26 -> 0 | Y26: =K25-1 -> 45437 | Z26: =IF($D$4="自选机构",[1]!S_EST_SCORERATING_INST($E$6,K26-1,$F$4),[1]!S_EST_SCORERATING_INST($E$6,K26-1,D26)) -> 1 | AA26: =IFERROR(IF(Z26/N26>1,"评级上调",IF(Z26/N26=1,"评级不变",IF(Z26/N26>0,"评级下调","首次评级"))),0) -> 评级不变 | AB26: =IF(K26-$F$10>=0,1,"") | AC26: =IF(ISERROR(AA26),"",IF(AA26="评级不变",0,IF(AA26="评级下调",-1,IF(AA26="评级上调",1,"")))) -> 0
C27: =G26-1 -> -1 | D27: 13 | E27: =IF($D$4="自选机构",$E$4,VLOOKUP(D27,Institutionlist,2,FALSE)) -> 华泰证券 | F27: =IF($D$4="自选机构",[1]!S_EST_ESTANALYST($E$6,$E$8,C27,$F$4),[1]!S_EST_ESTANALYST($E$6,$E$8,$E$9,D27)) -> 夏路路 | G27: =IF($D$4="自选机构",[1]!S_EST_ESTNEWTIME_INST($E$6,$E$8,C27,$F$4),[1]!S_EST_ESTNEWTIME_INST($E$6,$E$8,$E$9,D27)) -> 2024-05-24 | H27: =IF($D$4="自选机构",[1]!S_EST_SALES_INST($E$6,$E$8,C27,$F$4)/currencyunit,[1]!S_EST_SALES_INST($E$6,$E$8,$E$9,D27)/currencyunit) -> 25693 | I27: =IF($D$4="自选机构",[1]!S_EST_NETPROFIT_INST($E$6,$E$8,C27,$F$4)/currencyunit,[1]!S_EST_NETPROFIT_INST($E$6,$E$8,$E$9,D27)/currencyunit) -> -2090 | J27: =IF($D$4="自选机构",[1]!S_EST_EPS_INST($E$6,$E$8,C27,$F$4),[1]!S_EST_EPS_INST($E$6,$E$8,$E$9,D27)) -> -4.96 | K27: =IF($D$4="自选机构",[1]!S_EST_NEWRATINGTIME_INST($E$6,Y27,$F$4),[1]!S_EST_NEWRATINGTIME_INST($E$6,$E$9,D27)) -> 0 | L27: =IF($D$4="自选机构",[1]!S_EST_RATINGANALYST($E$6,Y27,$F$4),[1]!S_EST_RATINGANALYST($E$6,$E$9,D27)) -> 0 | M27: =IF($D$4="自选机构",[1]!S_EST_ORGRATING_INST($E$6,Y27,$F$4),[1]!S_EST_ORGRATING_INST($E$6,$E$9,D27)) -> 0 | N27: =IF($D$4="自选机构",[1]!S_EST_SCORERATING_INST($E$6,Y27,$F$4),[1]!S_EST_SCORERATING_INST($E$6,$E$9,D27)) -> 0 | O27: =IF($D$4="自选机构",[1]!S_EST_STDRATING_INST($E$6,Y27,$F$4),[1]!S_EST_STDRATING_INST($E$6,$E$9,D27)) -> 0 | P27: =IF($D$4="自选机构",[1]!S_EST_FRSTRATINGTIME_INST($E$6,$F$4),[1]!S_EST_FRSTRATINGTIME_INST($E$6,D27)) -> 0 | Q27: =IF(G27-$F$10>=0,1,"") -> 1 | X27: =--G27 -> 45436 | Y27: =K26-1 -> 45362 | Z27: =IF($D$4="自选机构",[1]!S_EST_SCORERATING_INST($E$6,K27-1,$F$4),[1]!S_EST_SCORERATING_INST($E$6,K27-1,D27)) -> 0 | AA27: =IFERROR(IF(Z27/N27>1,"评级上调",IF(Z27/N27=1,"评级不变",IF(Z27/N27>0,"评级下调","首次评级"))),0) -> 0 | AB27: =IF(K27-$F$10>=0,1,"") | AC27: =IF(ISERROR(AA27),"",IF(AA27="评级不变",0,IF(AA27="评级下调",-1,IF(AA27="评级上调",1,""))))
