Workbook
Name zzz: 数据!$A$1:$A$274

Sheet 计算
B5: 持有时间（月） | C5: 5
B6: 计算日期 | C6: =WORKDAY(TODAY(),-1) -> 45398 | D6: 持有期末日期 | E6: =OFFSET(数据!E270,C5,0) -> 45763
B7: 收益率曲线 | C7: 8
B8: 曲线代码 | C8: =OFFSET(数据!A1,计算!C7-1,1) -> 2122 | D8: 年付息次数 | E8: 1
B11: 持有期收益(%)
B12: 关键年期 | C12: 1y | D12: 2y | E12: 3y | F12: 4y | G12: 5y | H12: 6y | I12: 7y | J12: 10y | K12: 15y | L12: 20y | M12: 30y
B13: =ROUND(B31,0) & "BP" -> -30BP | C13: =C31+C$28/$E$8*OFFSET(数据!$G$270,计算!$C$5,0)-100 -> 2.4928719 | D13: =D31+D$28/$E$8*OFFSET(数据!$G$270,计算!$C$5,0)-100 -> 2.887572 | E13: =E31+E$28/$E$8*OFFSET(数据!$G$270,计算!$C$5,0)-100 -> 3.3840817 | F13: =F31+F$28/$E$8*OFFSET(数据!$G$270,计算!$C$5,0)-100 -> 3.8566452 | G13: =G31+G$28/$E$8*OFFSET(数据!$G$270,计算!$C$5,0)-100 -> 3.9140903 | H13: =H31+H$28/$E$8*OFFSET(数据!$G$270,计算!$C$5,0)-100 -> 4.2516791 | I13: =I31+I$28/$E$8*OFFSET(数据!$G$270,计算!$C$5,0)-100 -> 4.7023557 | J13: =J31+J$28/$E$8*OFFSET(数据!$G$270,计算!$C$5,0)-100 -> 5.2962692 | ... M13: =M31+M$28/$E$8*OFFSET(数据!$G$270,计算!$C$5,0)-100 -> 9.0726964
B14: =ROUND(B32,0) & "BP" -> -20BP | C14: =C32+C$28/$E$8*OFFSET(数据!$G$270,计算!$C$5,0)-100 -> 2.3940905 | D14: =D32+D$28/$E$8*OFFSET(数据!$G$270,计算!$C$5,0)-100 -> 2.6918615 | E14: =E32+E$28/$E$8*OFFSET(数据!$G$270,计算!$C$5,0)-100 -> 3.0930615 | F14: =F32+F$28/$E$8*OFFSET(数据!$G$270,计算!$C$5,0)-100 -> 3.4724541 | G14: =G32+G$28/$E$8*OFFSET(数据!$G$270,计算!$C$5,0)-100 -> 3.440029 | H14: =H32+H$28/$E$8*OFFSET(数据!$G$270,计算!$C$5,0)-100 -> 3.6883079 | I14: =I32+I$28/$E$8*OFFSET(数据!$G$270,计算!$C$5,0)-100 -> 4.0512886 | J14: =J32+J$28/$E$8*OFFSET(数据!$G$270,计算!$C$5,0)-100 -> 4.3973919 | ... M14: =M32+M$28/$E$8*OFFSET(数据!$G$270,计算!$C$5,0)-100 -> 6.8812035
B15: =ROUND(B33,0) & "BP" -> -10BP | C15: =C33+C$28/$E$8*OFFSET(数据!$G$270,计算!$C$5,0)-100 -> 2.2955031 | D15: =D33+D$28/$E$8*OFFSET(数据!$G$270,计算!$C$5,0)-100 -> 2.4967247 | E15: =E33+E$28/$E$8*OFFSET(数据!$G$270,计算!$C$5,0)-100 -> 2.8031728 | F15: =F33+F$28/$E$8*OFFSET(数据!$G$270,计算!$C$5,0)-100 -> 3.0901197 | G15: =G33+G$28/$E$8*OFFSET(数据!$G$270,计算!$C$5,0)-100 -> 2.9687019 | H15: =H33+H$28/$E$8*OFFSET(数据!$G$270,计算!$C$5,0)-100 -> 3.1287086 | I15: =I33+I$28/$E$8*OFFSET(数据!$G$270,计算!$C$5,0)-100 -> 3.4051773 | J15: =J33+J$28/$E$8*OFFSET(数据!$G$270,计算!$C$5,0)-100 -> 3.5077764 | ... M15: =M33+M$28/$E$8*OFFSET(数据!$G$270,计算!$C$5,0)-100 -> 4.7471402
B16: =ROUND(B34,0) & "BP" -> 0BP | C16: =C34+C$28/$E$8*OFFSET(数据!$G$270,计算!$C$5,0)-100 -> 2.1971093 | D16: =D34+D$28/$E$8*OFFSET(数据!$G$270,计算!$C$5,0)-100 -> 2.3021592 | E16: =E34+E$28/$E$8*OFFSET(数据!$G$270,计算!$C$5,0)-100 -> 2.5144101 | F16: =F34+F$28/$E$8*OFFSET(数据!$G$270,计算!$C$5,0)-100 -> 2.7096312 | G16: =G34+G$28/$E$8*OFFSET(数据!$G$270,计算!$C$5,0)-100 -> 2.5000903 | H16: =H34+H$28/$E$8*OFFSET(数据!$G$270,计算!$C$5,0)-100 -> 2.5728523 | I16: =I34+I$28/$E$8*OFFSET(数据!$G$270,计算!$C$5,0)-100 -> 2.763979 | J16: =J34+J$28/$E$8*OFFSET(数据!$G$270,计算!$C$5,0)-100 -> 2.6273169 | ... M16: =M34+M$28/$E$8*OFFSET(数据!$G$270,计算!$C$5,0)-100 -> 2.6688552
B17: =ROUND(B35,0) & "BP" -> 10BP | C17: =C35+C$28/$E$8*OFFSET(数据!$G$270,计算!$C$5,0)-100 -> 2.0989084 | D17: =D35+D$28/$E$8*OFFSET(数据!$G$270,计算!$C$5,0)-100 -> 2.1081629 | E17: =E35+E$28/$E$8*OFFSET(数据!$G$270,计算!$C$5,0)-100 -> 2.2267678 | F17: =F35+F$28/$E$8*OFFSET(数据!$G$270,计算!$C$5,0)-100 -> 2.3309777 | G17: =G35+G$28/$E$8*OFFSET(数据!$G$270,计算!$C$5,0)-100 -> 2.0341758 | H17: =H35+H$28/$E$8*OFFSET(数据!$G$270,计算!$C$5,0)-100 -> 2.0207099 | I17: =I35+I$28/$E$8*OFFSET(数据!$G$270,计算!$C$5,0)-100 -> 2.1276512 | J17: =J35+J$28/$E$8*OFFSET(数据!$G$270,计算!$C$5,0)-100 -> 1.7559087 | ... M17: =M35+M$28/$E$8*OFFSET(数据!$G$270,计算!$C$5,0)-100 -> 0.64474716
B18: =ROUND(B36,0) & "BP" -> 15BP | C18: =C36+C$28/$E$8*OFFSET(数据!$G$270,计算!$C$5,0)-100 -> 2.0498802 | D18: =D36+D$28/$E$8*OFFSET(数据!$G$270,计算!$C$5,0)-100 -> 2.0113774 | E18: =E36+E$28/$E$8*OFFSET(数据!$G$270,计算!$C$5,0)-100 -> 2.0833651 | F18: =F36+F$28/$E$8*OFFSET(数据!$G$270,计算!$C$5,0)-100 -> 2.1423358 | G18: =G36+G$28/$E$8*OFFSET(数据!$G$270,计算!$C$5,0)-100 -> 1.8022243 | H18: =H36+H$28/$E$8*OFFSET(数据!$G$270,计算!$C$5,0)-100 -> 1.7460225 | I18: =I36+I$28/$E$8*OFFSET(数据!$G$270,计算!$C$5,0)-100 -> 1.8113005 | J18: =J36+J$28/$E$8*OFFSET(数据!$G$270,计算!$C$5,0)-100 -> 1.3235665 | ... M18: =M36+M$28/$E$8*OFFSET(数据!$G$270,计算!$C$5,0)-100 -> -0.34747756
B19: =ROUND(B37,0) & "BP" -> 20BP | C19: =C37+C$28/$E$8*OFFSET(数据!$G$270,计算!$C$5,0)-100 -> 2.0008999 | D19: =D37+D$28/$E$8*OFFSET(数据!$G$270,计算!$C$5,0)-100 -> 1.9147335 | E19: =E37+E$28/$E$8*OFFSET(数据!$G$270,计算!$C$5,0)-100 -> 1.9402405 | F19: =F37+F$28/$E$8*OFFSET(数据!$G$270,计算!$C$5,0)-100 -> 1.9541487 | G19: =G37+G$28/$E$8*OFFSET(数据!$G$270,计算!$C$5,0)-100 -> 1.5709402 | H19: =H37+H$28/$E$8*OFFSET(数据!$G$270,计算!$C$5,0)-100 -> 1.4722529 | I19: =I37+I$28/$E$8*OFFSET(数据!$G$270,计算!$C$5,0)-100 -> 1.4961517 | J19: =J37+J$28/$E$8*OFFSET(数据!$G$270,计算!$C$5,0)-100 -> 0.89344845 | ... M19: =M37+M$28/$E$8*OFFSET(数据!$G$270,计算!$C$5,0)-100 -> -1.3267366
B20: =ROUND(B38,0) & "BP" -> 25BP | C20: =C38+C$28/$E$8*OFFSET(数据!$G$270,计算!$C$5,0)-100 -> 1.9519677 | D20: =D38+D$28/$E$8*OFFSET(数据!$G$270,计算!$C$5,0)-100 -> 1.8182307 | E20: =E38+E$28/$E$8*OFFSET(数据!$G$270,计算!$C$5,0)-100 -> 1.7973933 | F20: =F38+F$28/$E$8*OFFSET(数据!$G$270,计算!$C$5,0)-100 -> 1.7664151 | G20: =G38+G$28/$E$8*OFFSET(数据!$G$270,计算!$C$5,0)-100 -> 1.3403214 | H20: =H38+H$28/$E$8*OFFSET(数据!$G$270,计算!$C$5,0)-100 -> 1.1993975 | I20: =I38+I$28/$E$8*OFFSET(数据!$G$270,计算!$C$5,0)-100 -> 1.1821995 | J20: =J38+J$28/$E$8*OFFSET(数据!$G$270,计算!$C$5,0)-100 -> 0.4655419 | ... M20: =M38+M$28/$E$8*OFFSET(数据!$G$270,计算!$C$5,0)-100 -> -2.2932166
B21: =ROUND(B39,0) & "BP" -> 30BP | C21: =C39+C$28/$E$8*OFFSET(数据!$G$270,计算!$C$5,0)-100 -> 1.9030833 | D21: =D39+D$28/$E$8*OFFSET(数据!$G$270,计算!$C$5,0)-100 -> 1.7218688 | E21: =E39+E$28/$E$8*OFFSET(数据!$G$270,计算!$C$5,0)-100 -> 1.6548229 | F21: =F39+F$28/$E$8*OFFSET(数据!$G$270,计算!$C$5,0)-100 -> 1.5791336 | G21: =G39+G$28/$E$8*OFFSET(数据!$G$270,计算!$C$5,0)-100 -> 1.1103655 | H21: =H39+H$28/$E$8*OFFSET(数据!$G$270,计算!$C$5,0)-100 -> 0.92745288 | I21: =I39+I$28/$E$8*OFFSET(数据!$G$270,计算!$C$5,0)-100 -> 0.86943889 | J21: =J39+J$28/$E$8*OFFSET(数据!$G$270,计算!$C$5,0)-100 -> 0.039834183 | ... M21: =M39+M$28/$E$8*OFFSET(数据!$G$270,计算!$C$5,0)-100 -> -3.2471015
B22: =ROUND(B40,0) & "BP" -> 40BP | C22: =C40+C$28/$E$8*OFFSET(数据!$G$270,计算!$C$5,0)-100 -> 1.8054578 | D22: =D40+D$28/$E$8*OFFSET(数据!$G$270,计算!$C$5,0)-100 -> 1.5295667 | E22: =E40+E$28/$E$8*OFFSET(数据!$G$270,计算!$C$5,0)-100 -> 1.3705094 | F22: =F40+F$28/$E$8*OFFSET(数据!$G$270,计算!$C$5,0)-100 -> 1.2059217 | G22: =G40+G$28/$E$8*OFFSET(数据!$G$270,计算!$C$5,0)-100 -> 0.65243357 | H22: =H40+H$28/$E$8*OFFSET(数据!$G$270,计算!$C$5,0)-100 -> 0.38628178 | I22: =I40+I$28/$E$8*OFFSET(数据!$G$270,计算!$C$5,0)-100 -> 0.24747148 | J22: =J40+J$28/$E$8*OFFSET(数据!$G$270,计算!$C$5,0)-100 -> -0.80503489 | ... M22: =M40+M$28/$E$8*OFFSET(数据!$G$270,计算!$C$5,0)-100 -> -5.1178076
B23: =ROUND(B41,0) & "BP" -> 50BP | C23: =C41+C$28/$E$8*OFFSET(数据!$G$270,计算!$C$5,0)-100 -> 1.7080231 | D23: =D41+D$28/$E$8*OFFSET(数据!$G$270,计算!$C$5,0)-100 -> 1.3378249 | E23: =E41+E$28/$E$8*OFFSET(数据!$G$270,计算!$C$5,0)-100 -> 1.0872948 | F23: =F41+F$28/$E$8*OFFSET(数据!$G$270,计算!$C$5,0)-100 -> 0.83450266 | G23: =G41+G$28/$E$8*OFFSET(数据!$G$270,计算!$C$5,0)-100 -> 0.19712674 | H23: =H41+H$28/$E$8*OFFSET(数据!$G$270,计算!$C$5,0)-100 -> -0.1512883 | I23: =I41+I$28/$E$8*OFFSET(数据!$G$270,计算!$C$5,0)-100 -> -0.36979139 | J23: =J41+J$28/$E$8*OFFSET(数据!$G$270,计算!$C$5,0)-100 -> -1.6412583 | ... M23: =M41+M$28/$E$8*OFFSET(数据!$G$270,计算!$C$5,0)-100 -> -6.9402707
B25: 持有期末全价
B26: 关键年期 | C26: 1y | D26: 2y | E26: 3y | F26: 4y | G26: 5y | H26: 6y | I26: 7y | J26: 10y | K26: 15y | L26: 20y | M26: 30y
B27: 虚拟券到期日期 | C27: =(YEAR(C6)+1)&"-"&(MONTH(C6))&"-"&DAY(C6) -> 2025-4-16 | D27: =(YEAR(C6)+2)&"-"&(MONTH(C6))&"-"&DAY(C6) -> 2026-4-16 | E27: =(YEAR(C6)+3)&"-"&(MONTH(C6))&"-"&DAY(C6) -> 2027-4-16 | F27: =(YEAR(C6)+4)&"-"&(MONTH(C6))&"-"&DAY(C6) -> 2028-4-16 | G27: =(YEAR(C6)+5)&"-"&(MONTH(C6))&"-"&DAY(C6) -> 2029-4-16 | H27: =(YEAR(C6)+6)&"-"&(MONTH(C6))&"-"&DAY(C6) -> 2030-4-16 | I27: =(YEAR(C6)+7)&"-"&(MONTH(C6))&"-"&DAY(C6) -> 2031-4-16 | J27: =(YEAR(C6)+10)&"-"&(MONTH(C6))&"-"&DAY(C6) -> 2034-4-16 | K27: =(YEAR(C6)+15)&"-"&(MONTH(C6))&"-"&DAY(C6) -> 2039-4-16 | L27: =(YEAR(C6)+20)&"-"&(MONTH(C6))&"-"&DAY(C6) -> 2044-4-16 | M27: =(YEAR(C6)+30)&"-"&(MONTH(C6))&"-"&DAY(C6) -> 2054-4-16
B28: 虚拟券票面利率 | C28: =IF($C$7<46,[1]!B_CALC_CURVE_CHINABOND($C$8,$C$6,C26),IF($C$7<71,[1]!b_calc_curve_csi($C$8,$C$6,C26),[1]!B_CALC_CURVE($C$8,$C$6,C26))) -> 2.044 | D28: =IF($C$7<46,[1]!B_CALC_CURVE_CHINABOND($C$8,$C$6,D26),IF($C$7<71,[1]!b_calc_curve_csi($C$8,$C$6,D26),[1]!B_CALC_CURVE($C$8,$C$6,D26))) -> 2.1318 | E28: =IF($C$7<46,[1]!B_CALC_CURVE_CHINABOND($C$8,$C$6,E26),IF($C$7<71,[1]!b_calc_curve_csi($C$8,$C$6,E26),[1]!B_CALC_CURVE($C$8,$C$6,E26))) -> 2.2305 | F28: =IF($C$7<46,[1]!B_CALC_CURVE_CHINABOND($C$8,$C$6,F26),IF($C$7<71,[1]!b_calc_curve_csi($C$8,$C$6,F26),[1]!B_CALC_CURVE($C$8,$C$6,F26))) -> 2.3306 | G28: =IF($C$7<46,[1]!B_CALC_CURVE_CHINABOND($C$8,$C$6,G26),IF($C$7<71,[1]!b_calc_curve_csi($C$8,$C$6,G26),[1]!B_CALC_CURVE($C$8,$C$6,G26))) -> 2.3605 | H28: =IF($C$7<46,[1]!B_CALC_CURVE_CHINABOND($C$8,$C$6,H26),IF($C$7<71,[1]!b_calc_curve_csi($C$8,$C$6,H26),[1]!B_CALC_CURVE($C$8,$C$6,H26))) -> 2.393 | I28: =IF($C$7<46,[1]!B_CALC_CURVE_CHINABOND($C$8,$C$6,I26),IF($C$7<71,[1]!b_calc_curve_csi($C$8,$C$6,I26),[1]!B_CALC_CURVE($C$8,$C$6,I26))) -> 2.4433 | J28: =IF($C$7<46,[1]!B_CALC_CURVE_CHINABOND($C$8,$C$6,J26),IF($C$7<71,[1]!b_calc_curve_csi($C$8,$C$6,J26),[1]!B_CALC_CURVE($C$8,$C$6,J26))) -> 2.5109 | ... M28: =IF($C$7<46,[1]!B_CALC_CURVE_CHINABOND($C$8,$C$6,M26),IF($C$7<71,[1]!b_calc_curve_csi($C$8,$C$6,M26),[1]!B_CALC_CURVE($C$8,$C$6,M26))) -> 2.6545
B29: 持有期末剩余期限 | C29: =LEFT(C26,SEARCH("y",C26)-1)-OFFSET(数据!$F$270,计算!$C$5,0)/365 -> 0 | D29: =LEFT(D26,SEARCH("y",D26)-1)-OFFSET(数据!$F$270,计算!$C$5,0)/365 -> 1 | E29: =LEFT(E26,SEARCH("y",E26)-1)-OFFSET(数据!$F$270,计算!$C$5,0)/365 -> 2 | F29: =LEFT(F26,SEARCH("y",F26)-1)-OFFSET(数据!$F$270,计算!$C$5,0)/365 -> 3 | G29: =LEFT(G26,SEARCH("y",G26)-1)-OFFSET(数据!$F$270,计算!$C$5,0)/365 -> 4 | H29: =LEFT(H26,SEARCH("y",H26)-1)-OFFSET(数据!$F$270,计算!$C$5,0)/365 -> 5 | I29: =LEFT(I26,SEARCH("y",I26)-1)-OFFSET(数据!$F$270,计算!$C$5,0)/365 -> 6 | J29: =LEFT(J26,SEARCH("y",J26)-1)-OFFSET(数据!$F$270,计算!$C$5,0)/365 -> 9 | ... M29: =LEFT(M26,SEARCH("y",M26)-1)-OFFSET(数据!$F$270,计算!$C$5,0)/365 -> 29
B30: 持有期末YTM | C30: =IF($C$7<46,[1]!B_CALC_CURVE_CHINABOND($C$8,$C$6,C29),IF($C$7<71,[1]!b_calc_curve_csi($C$8,$C$6,C29),[1]!B_CALC_CURVE($C$8,$C$6,C29))) -> 1.888 | D30: =IF($C$7<46,[1]!B_CALC_CURVE_CHINABOND($C$8,$C$6,D29),IF($C$7<71,[1]!b_calc_curve_csi($C$8,$C$6,D29),[1]!B_CALC_CURVE($C$8,$C$6,D29))) -> 2.044 | E30: =IF($C$7<46,[1]!B_CALC_CURVE_CHINABOND($C$8,$C$6,E29),IF($C$7<71,[1]!b_calc_curve_csi($C$8,$C$6,E29),[1]!B_CALC_CURVE($C$8,$C$6,E29))) -> 2.1318 | F30: =IF($C$7<46,[1]!B_CALC_CURVE_CHINABOND($C$8,$C$6,F29),IF($C$7<71,[1]!b_calc_curve_csi($C$8,$C$6,F29),[1]!B_CALC_CURVE($C$8,$C$6,F29))) -> 2.2305 | G30: =IF($C$7<46,[1]!B_CALC_CURVE_CHINABOND($C$8,$C$6,G29),IF($C$7<71,[1]!b_calc_curve_csi($C$8,$C$6,G29),[1]!B_CALC_CURVE($C$8,$C$6,G29))) -> 2.3306 | H30: =IF($C$7<46,[1]!B_CALC_CURVE_CHINABOND($C$8,$C$6,H29),IF($C$7<71,[1]!b_calc_curve_csi($C$8,$C$6,H29),[1]!B_CALC_CURVE($C$8,$C$6,H29))) -> 2.3605 | I30: =IF($C$7<46,[1]!B_CALC_CURVE_CHINABOND($C$8,$C$6,I29),IF($C$7<71,[1]!b_calc_curve_csi($C$8,$C$6,I29),[1]!B_CALC_CURVE($C$8,$C$6,I29))) -> 2.393 | J30: =IF($C$7<46,[1]!B_CALC_CURVE_CHINABOND($C$8,$C$6,J29),IF($C$7<71,[1]!b_calc_curve_csi($C$8,$C$6,J29),[1]!B_CALC_CURVE($C$8,$C$6,J29))) -> 2.4976 | ... M30: =IF($C$7<46,[1]!B_CALC_CURVE_CHINABOND($C$8,$C$6,M29),IF($C$7<71,[1]!b_calc_curve_csi($C$8,$C$6,M29),[1]!B_CALC_CURVE($C$8,$C$6,M29))) -> 2.6538
B31: -30 | C31: =[1]!B_CALC_PRICE("999999",$C$6,(C$30+$B31/100),2,C$27,$E$8,C$28,100,$C$6) -> 100.44887 | D31: =[1]!B_CALC_PRICE("999999",$C$6,(D$30+$B31/100),2,D$27,$E$8,D$28,100,$C$6) -> 100.75577 | E31: =[1]!B_CALC_PRICE("999999",$C$6,(E$30+$B31/100),2,E$27,$E$8,E$28,100,$C$6) -> 101.15358 | F31: =[1]!B_CALC_PRICE("999999",$C$6,(F$30+$B31/100),2,F$27,$E$8,F$28,100,$C$6) -> 101.52605 | G31: =[1]!B_CALC_PRICE("999999",$C$6,(G$30+$B31/100),2,G$27,$E$8,G$28,100,$C$6) -> 101.55359 | H31: =[1]!B_CALC_PRICE("999999",$C$6,(H$30+$B31/100),2,H$27,$E$8,H$28,100,$C$6) -> 101.85868 | I31: =[1]!B_CALC_PRICE("999999",$C$6,(I$30+$B31/100),2,I$27,$E$8,I$28,100,$C$6) -> 102.25906 | J31: =[1]!B_CALC_PRICE("999999",$C$6,(J$30+$B31/100),2,J$27,$E$8,J$28,100,$C$6) -> 102.78537 | ... M31: =[1]!B_CALC_PRICE("999999",$C$6,(M$30+$B31/100),2,M$27,$E$8,M$28,100,$C$6) -> 106.4182
B32: -20 | C32: =[1]!B_CALC_PRICE("999999",$C$6,(C$30+$B32/100),2,C$27,$E$8,C$28,100,$C$6) -> 100.35009 | D32: =[1]!B_CALC_PRICE("999999",$C$6,(D$30+$B32/100),2,D$27,$E$8,D$28,100,$C$6) -> 100.56006 | E32: =[1]!B_CALC_PRICE("999999",$C$6,(E$30+$B32/100),2,E$27,$E$8,E$28,100,$C$6) -> 100.86256 | F32: =[1]!B_CALC_PRICE("999999",$C$6,(F$30+$B32/100),2,F$27,$E$8,F$28,100,$C$6) -> 101.14185 | G32: =[1]!B_CALC_PRICE("999999",$C$6,(G$30+$B32/100),2,G$27,$E$8,G$28,100,$C$6) -> 101.07953 | H32: =[1]!B_CALC_PRICE("999999",$C$6,(H$30+$B32/100),2,H$27,$E$8,H$28,100,$C$6) -> 101.29531 | I32: =[1]!B_CALC_PRICE("999999",$C$6,(I$30+$B32/100),2,I$27,$E$8,I$28,100,$C$6) -> 101.60799 | J32: =[1]!B_CALC_PRICE("999999",$C$6,(J$30+$B32/100),2,J$27,$E$8,J$28,100,$C$6) -> 101.88649 | ... M32: =[1]!B_CALC_PRICE("999999",$C$6,(M$30+$B32/100),2,M$27,$E$8,M$28,100,$C$6) -> 104.2267
B33: -10 | C33: =[1]!B_CALC_PRICE("999999",$C$6,(C$30+$B33/100),2,C$27,$E$8,C$28,100,$C$6) -> 100.2515 | D33: =[1]!B_CALC_PRICE("999999",$C$6,(D$30+$B33/100),2,D$27,$E$8,D$28,100,$C$6) -> 100.36492 | E33: =[1]!B_CALC_PRICE("999999",$C$6,(E$30+$B33/100),2,E$27,$E$8,E$28,100,$C$6) -> 100.57267 | F33: =[1]!B_CALC_PRICE("999999",$C$6,(F$30+$B33/100),2,F$27,$E$8,F$28,100,$C$6) -> 100.75952 | G33: =[1]!B_CALC_PRICE("999999",$C$6,(G$30+$B33/100),2,G$27,$E$8,G$28,100,$C$6) -> 100.6082 | H33: =[1]!B_CALC_PRICE("999999",$C$6,(H$30+$B33/100),2,H$27,$E$8,H$28,100,$C$6) -> 100.73571 | I33: =[1]!B_CALC_PRICE("999999",$C$6,(I$30+$B33/100),2,I$27,$E$8,I$28,100,$C$6) -> 100.96188 | J33: =[1]!B_CALC_PRICE("999999",$C$6,(J$30+$B33/100),2,J$27,$E$8,J$28,100,$C$6) -> 100.99688 | ... M33: =[1]!B_CALC_PRICE("999999",$C$6,(M$30+$B33/100),2,M$27,$E$8,M$28,100,$C$6) -> 102.09264
B34: 0 | C34: =[1]!B_CALC_PRICE("999999",$C$6,(C$30+$B34/100),2,C$27,$E$8,C$28,100,$C$6) -> 100.15311 | D34: =[1]!B_CALC_PRICE("999999",$C$6,(D$30+$B34/100),2,D$27,$E$8,D$28,100,$C$6) -> 100.17036 | E34: =[1]!B_CALC_PRICE("999999",$C$6,(E$30+$B34/100),2,E$27,$E$8,E$28,100,$C$6) -> 100.28391 | F34: =[1]!B_CALC_PRICE("999999",$C$6,(F$30+$B34/100),2,F$27,$E$8,F$28,100,$C$6) -> 100.37903 | G34: =[1]!B_CALC_PRICE("999999",$C$6,(G$30+$B34/100),2,G$27,$E$8,G$28,100,$C$6) -> 100.13959 | H34: =[1]!B_CALC_PRICE("999999",$C$6,(H$30+$B34/100),2,H$27,$E$8,H$28,100,$C$6) -> 100.17985 | I34: =[1]!B_CALC_PRICE("999999",$C$6,(I$30+$B34/100),2,I$27,$E$8,I$28,100,$C$6) -> 100.32068 | J34: =[1]!B_CALC_PRICE("999999",$C$6,(J$30+$B34/100),2,J$27,$E$8,J$28,100,$C$6) -> 100.11642 | ... M34: =[1]!B_CALC_PRICE("999999",$C$6,(M$30+$B34/100),2,M$27,$E$8,M$28,100,$C$6) -> 100.01436
B35: 10 | C35: =[1]!B_CALC_PRICE("999999",$C$6,(C$30+$B35/100),2,C$27,$E$8,C$28,100,$C$6) -> 100.05491 | D35: =[1]!B_CALC_PRICE("999999",$C$6,(D$30+$B35/100),2,D$27,$E$8,D$28,100,$C$6) -> 99.976363 | E35: =[1]!B_CALC_PRICE("999999",$C$6,(E$30+$B35/100),2,E$27,$E$8,E$28,100,$C$6) -> 99.996268 | F35: =[1]!B_CALC_PRICE("999999",$C$6,(F$30+$B35/100),2,F$27,$E$8,F$28,100,$C$6) -> 100.00038 | G35: =[1]!B_CALC_PRICE("999999",$C$6,(G$30+$B35/100),2,G$27,$E$8,G$28,100,$C$6) -> 99.673676 | H35: =[1]!B_CALC_PRICE("999999",$C$6,(H$30+$B35/100),2,H$27,$E$8,H$28,100,$C$6) -> 99.62771 | I35: =[1]!B_CALC_PRICE("999999",$C$6,(I$30+$B35/100),2,I$27,$E$8,I$28,100,$C$6) -> 99.684351 | J35: =[1]!B_CALC_PRICE("999999",$C$6,(J$30+$B35/100),2,J$27,$E$8,J$28,100,$C$6) -> 99.245009 | ... M35: =[1]!B_CALC_PRICE("999999",$C$6,(M$30+$B35/100),2,M$27,$E$8,M$28,100,$C$6) -> 97.990247
B36: 15 | C36: =[1]!B_CALC_PRICE("999999",$C$6,(C$30+$B36/100),2,C$27,$E$8,C$28,100,$C$6) -> 100.00588 | D36: =[1]!B_CALC_PRICE("999999",$C$6,(D$30+$B36/100),2,D$27,$E$8,D$28,100,$C$6) -> 99.879577 | E36: =[1]!B_CALC_PRICE("999999",$C$6,(E$30+$B36/100),2,E$27,$E$8,E$28,100,$C$6) -> 99.852865 | F36: =[1]!B_CALC_PRICE("999999",$C$6,(F$30+$B36/100),2,F$27,$E$8,F$28,100,$C$6) -> 99.811736 | G36: =[1]!B_CALC_PRICE("999999",$C$6,(G$30+$B36/100),2,G$27,$E$8,G$28,100,$C$6) -> 99.441724 | H36: =[1]!B_CALC_PRICE("999999",$C$6,(H$30+$B36/100),2,H$27,$E$8,H$28,100,$C$6) -> 99.353022 | I36: =[1]!B_CALC_PRICE("999999",$C$6,(I$30+$B36/100),2,I$27,$E$8,I$28,100,$C$6) -> 99.368001 | J36: =[1]!B_CALC_PRICE("999999",$C$6,(J$30+$B36/100),2,J$27,$E$8,J$28,100,$C$6) -> 98.812666 | ... M36: =[1]!B_CALC_PRICE("999999",$C$6,(M$30+$B36/100),2,M$27,$E$8,M$28,100,$C$6) -> 96.998022
B37: 20 | C37: =[1]!B_CALC_PRICE("999999",$C$6,(C$30+$B37/100),2,C$27,$E$8,C$28,100,$C$6) -> 99.9569 | D37: =[1]!B_CALC_PRICE("999999",$C$6,(D$30+$B37/100),2,D$27,$E$8,D$28,100,$C$6) -> 99.782933 | E37: =[1]!B_CALC_PRICE("999999",$C$6,(E$30+$B37/100),2,E$27,$E$8,E$28,100,$C$6) -> 99.709741 | F37: =[1]!B_CALC_PRICE("999999",$C$6,(F$30+$B37/100),2,F$27,$E$8,F$28,100,$C$6) -> 99.623549 | G37: =[1]!B_CALC_PRICE("999999",$C$6,(G$30+$B37/100),2,G$27,$E$8,G$28,100,$C$6) -> 99.21044 | H37: =[1]!B_CALC_PRICE("999999",$C$6,(H$30+$B37/100),2,H$27,$E$8,H$28,100,$C$6) -> 99.079253 | I37: =[1]!B_CALC_PRICE("999999",$C$6,(I$30+$B37/100),2,I$27,$E$8,I$28,100,$C$6) -> 99.052852 | J37: =[1]!B_CALC_PRICE("999999",$C$6,(J$30+$B37/100),2,J$27,$E$8,J$28,100,$C$6) -> 98.382548 | ... M37: =[1]!B_CALC_PRICE("999999",$C$6,(M$30+$B37/100),2,M$27,$E$8,M$28,100,$C$6) -> 96.018763
B38: 25 | C38: =[1]!B_CALC_PRICE("999999",$C$6,(C$30+$B38/100),2,C$27,$E$8,C$28,100,$C$6) -> 99.907968 | D38: =[1]!B_CALC_PRICE("999999",$C$6,(D$30+$B38/100),2,D$27,$E$8,D$28,100,$C$6) -> 99.686431 | E38: =[1]!B_CALC_PRICE("999999",$C$6,(E$30+$B38/100),2,E$27,$E$8,E$28,100,$C$6) -> 99.566893 | F38: =[1]!B_CALC_PRICE("999999",$C$6,(F$30+$B38/100),2,F$27,$E$8,F$28,100,$C$6) -> 99.435815 | G38: =[1]!B_CALC_PRICE("999999",$C$6,(G$30+$B38/100),2,G$27,$E$8,G$28,100,$C$6) -> 98.979821 | H38: =[1]!B_CALC_PRICE("999999",$C$6,(H$30+$B38/100),2,H$27,$E$8,H$28,100,$C$6) -> 98.806398 | I38: =[1]!B_CALC_PRICE("999999",$C$6,(I$30+$B38/100),2,I$27,$E$8,I$28,100,$C$6) -> 98.7389 | J38: =[1]!B_CALC_PRICE("999999",$C$6,(J$30+$B38/100),2,J$27,$E$8,J$28,100,$C$6) -> 97.954642 | ... M38: =[1]!B_CALC_PRICE("999999",$C$6,(M$30+$B38/100),2,M$27,$E$8,M$28,100,$C$6) -> 95.052283
B39: 30 | C39: =[1]!B_CALC_PRICE("999999",$C$6,(C$30+$B39/100),2,C$27,$E$8,C$28,100,$C$6) -> 99.859083 | D39: =[1]!B_CALC_PRICE("999999",$C$6,(D$30+$B39/100),2,D$27,$E$8,D$28,100,$C$6) -> 99.590069 | E39: =[1]!B_CALC_PRICE("999999",$C$6,(E$30+$B39/100),2,E$27,$E$8,E$28,100,$C$6) -> 99.424323 | F39: =[1]!B_CALC_PRICE("999999",$C$6,(F$30+$B39/100),2,F$27,$E$8,F$28,100,$C$6) -> 99.248534 | G39: =[1]!B_CALC_PRICE("999999",$C$6,(G$30+$B39/100),2,G$27,$E$8,G$28,100,$C$6) -> 98.749865 | H39: =[1]!B_CALC_PRICE("999999",$C$6,(H$30+$B39/100),2,H$27,$E$8,H$28,100,$C$6) -> 98.534453 | I39: =[1]!B_CALC_PRICE("999999",$C$6,(I$30+$B39/100),2,I$27,$E$8,I$28,100,$C$6) -> 98.426139 | J39: =[1]!B_CALC_PRICE("999999",$C$6,(J$30+$B39/100),2,J$27,$E$8,J$28,100,$C$6) -> 97.528934 | ... M39: =[1]!B_CALC_PRICE("999999",$C$6,(M$30+$B39/100),2,M$27,$E$8,M$28,100,$C$6) -> 94.098398
B40: 40 | C40: =[1]!B_CALC_PRICE("999999",$C$6,(C$30+$B40/100),2,C$27,$E$8,C$28,100,$C$6) -> 99.761458 | D40: =[1]!B_CALC_PRICE("999999",$C$6,(D$30+$B40/100),2,D$27,$E$8,D$28,100,$C$6) -> 99.397767 | E40: =[1]!B_CALC_PRICE("999999",$C$6,(E$30+$B40/100),2,E$27,$E$8,E$28,100,$C$6) -> 99.140009 | F40: =[1]!B_CALC_PRICE("999999",$C$6,(F$30+$B40/100),2,F$27,$E$8,F$28,100,$C$6) -> 98.875322 | G40: =[1]!B_CALC_PRICE("999999",$C$6,(G$30+$B40/100),2,G$27,$E$8,G$28,100,$C$6) -> 98.291934 | H40: =[1]!B_CALC_PRICE("999999",$C$6,(H$30+$B40/100),2,H$27,$E$8,H$28,100,$C$6) -> 97.993282 | I40: =[1]!B_CALC_PRICE("999999",$C$6,(I$30+$B40/100),2,I$27,$E$8,I$28,100,$C$6) -> 97.804171 | J40: =[1]!B_CALC_PRICE("999999",$C$6,(J$30+$B40/100),2,J$27,$E$8,J$28,100,$C$6) -> 96.684065 | ... M40: =[1]!B_CALC_PRICE("999999",$C$6,(M$30+$B40/100),2,M$27,$E$8,M$28,100,$C$6) -> 92.227692
B41: 50 | C41: =[1]!B_CALC_PRICE("999999",$C$6,(C$30+$B41/100),2,C$27,$E$8,C$28,100,$C$6) -> 99.664023 | D41: =[1]!B_CALC_PRICE("999999",$C$6,(D$30+$B41/100),2,D$27,$E$8,D$28,100,$C$6) -> 99.206025 | E41: =[1]!B_CALC_PRICE("999999",$C$6,(E$30+$B41/100),2,E$27,$E$8,E$28,100,$C$6) -> 98.856795 | F41: =[1]!B_CALC_PRICE("999999",$C$6,(F$30+$B41/100),2,F$27,$E$8,F$28,100,$C$6) -> 98.503903 | G41: =[1]!B_CALC_PRICE("999999",$C$6,(G$30+$B41/100),2,G$27,$E$8,G$28,100,$C$6) -> 97.836627 | H41: =[1]!B_CALC_PRICE("999999",$C$6,(H$30+$B41/100),2,H$27,$E$8,H$28,100,$C$6) -> 97.455712 | I41: =[1]!B_CALC_PRICE("999999",$C$6,(I$30+$B41/100),2,I$27,$E$8,I$28,100,$C$6) -> 97.186909 | J41: =[1]!B_CALC_PRICE("999999",$C$6,(J$30+$B41/100),2,J$27,$E$8,J$28,100,$C$6) -> 95.847842 | ... M41: =[1]!B_CALC_PRICE("999999",$C$6,(M$30+$B41/100),2,M$27,$E$8,M$28,100,$C$6) -> 90.405229

Sheet 使用说明

Sheet 数据
A1: ------------"中债收益率曲线"-----------------------
A2: 中债国债收益率曲线 | B2: 1232
A3: 财政部-中国地方政府债券收益率曲线 | B3: 4202
A4: 中债国开债收益率曲线 | B4: 2142
A5: 中债进出口行债收益率曲线 | B5: 1322
A6: 中债农发行债收益率曲线 | B6: 2352
A7: 中债铁道债收益率曲线 | B7: 1882
A8: 中债铁道债收益率曲线(减税) | B8: 2122
A9: 中债三峡集团债券收益率曲线 | B9: 4172
A10: 中债中短期票据收益率曲线(AAA+) | B10: 2022
A11: 中债中短期票据收益率曲线(AAA) | B11: 1102
A12: 中债中短期票据收益率曲线(AAA-) | B12: 1502
A13: 中债中短期票据收益率曲线(AA+) | B13: 1082
A14: 中债中短期票据收益率曲线(AA) | B14: 1072
A15: 中债中短期票据收益率曲线(AA-) | B15: 1092
A16: 中债中短期票据收益率曲线(A+) | B16: 1052
A17: 中债中短期票据收益率曲线(A) | B17: 1042
A18: 中债中短期票据收益率曲线(A-) | B18: 1062
A19: 中债企业债收益率曲线(AAA) | B19: 1262
A20: 中债企业债收益率曲线(AAA-) | B20: 2242
A21: 中债企业债收益率曲线(AA+) | B21: 1442
A22: 中债企业债收益率曲线(AA) | B22: 1252
A23: 中债企业债收益率曲线(AA-) | B23: 2252
A24: 中债企业债收益率曲线(A+) | B24: 1852
A25: 中债企业债收益率曲线(A) | B25: 1902
A26: 中债企业债收益率曲线(A-) | B26: 2172
A27: 中债企业债收益率曲线(BBB+) | B27: 1912
A28: 中债企业债收益率曲线(BBB) | B28: 2202
A29: 中债企业债收益率曲线(BB) | B29: 2212
A30: 中债企业债收益率曲线(B) | B30: 2222
A31: 中债企业债收益率曲线(CCC) | B31: 2232
A32: 中债企业债收益率曲线(CC) | B32: 2192
A33: 中债城投债收益率曲线(AAA) | B33: 1842
A34: 中债城投债收益率曲线(AA+) | B34: 1832
A35: 中债城投债收益率曲线(AA) | B35: 1872
A36: 中债城投债收益率曲线(AA(2)) | B36: 1482
A37: 中债城投债收益率曲线(AA-) | B37: 1822
A38: 中债商业银行普通债收益率曲线(AAA) | B38: 2032
A39: 中债商业银行普通债收益率曲线(AAA-) | B39: 2262
A40: 中债商业银行普通债收益率曲线(AA+) | B40: 2042
...

Sheet 算法说明

Sheet Wind模板
A1: 不同债券品种持有期收益情景分析
