Workbook

Sheet 美联储利率观测器
G1: 美联储利率观测器 V1.10 | Z1: 最近更新： | AA1: =NOW() -> 46037.779
F5: 最新决议日期 | G5: 目标利率 | H5: 有效利率 | I5: 下次会议时间 | K5: 倒计天数 | O5: 预测单次会议加息降息概率 | X5: 预测利率变动概率
F6: =日历计算!E2 -> 46002.083 | G6: =AG46 -> 3.75 | H6: =AG50 -> 3.64 | I6: =美联储议息会议日历!D4 -> 46051.083 | K6: =美联储议息会议日历!D5 -> 13.303888 | O6: 预测时间间隔（天）： | Q6: 1 | R6: 选择预测会议月份： | T6: 46366.083 | X6: 选择预测月份： | AA6: 46366.083
F9: 隐含隔夜利率&加息/降息次数 | O9: =TEXT(T6,"YY年mm月")&"单月利率变动概率" -> 26年12月单月利率变动概率 | X9: =TEXT(AA6,"YY年mm月")&"累计加息/降息概率" -> 26年12月累计加息/降息概率
C12: 检索代码 | F12: 会议日期 | G12: 加息/降息次数 | H12: 加息/降息概率 | I12: 隐含利率变动 | J12: 隐含利率(%) | K12: 假定利率变动 | O12: 观测时点 | P12: -50bps | Q12: -25bps | R12: 0bps | S12: +25bps | T12: +50bps | X12: 观测时点 | Y12: 降息 | Z12: 保持不变 | AA12: 加息
C13: =日历计算!D3 -> 2601E | F13: =日历计算!E3 -> 46051.083 | G13: =I13/K13 -> -0.04 | H13: =IF(VLOOKUP(C13,加息降息概率计算!C:Y,23,0)>0,1-VLOOKUP(C13,加息降息概率计算!C:Y,22,0),IF(VLOOKUP(C13,加息降息概率计算!C:Y,21,0)>0,VLOOKUP(C13,加息降息概率计算!C:Y,22,0)-1,0)) -> -0.044285714 | I13: =J13-$H$6 -> -0.01 | J13: =VLOOKUP(C13&"E",加息降息概率计算!C:S,9,0) -> 3.63 | K13: 0.25 | O13: =TODAY() -> 46037 | P13: =VLOOKUP(TEXT($T$6,"YYMM")&"E",加息降息概率计算!$C:$S,13,0) -> 0 | Q13: =VLOOKUP(TEXT($T$6,"YYMM")&"E",加息降息概率计算!$C:$S,14,0) -> 0.24 | R13: =VLOOKUP(TEXT($T$6,"YYMM")&"E",加息降息概率计算!$C:$S,15,0) -> 0.76 | S13: =VLOOKUP(TEXT($T$6,"YYMM")&"E",加息降息概率计算!$C:$S,16,0) -> 0 | T13: =VLOOKUP(TEXT($T$6,"YYMM")&"E",加息降息概率计算!$C:$S,17,0) -> 0 | X13: =O13 -> 46037 | Y13: =VLOOKUP(TEXT($AA$6,"YYMM")&"E",加息降息概率计算!$C:$Y,21,0) -> 1 | Z13: =VLOOKUP(TEXT($AA$6,"YYMM")&"E",加息降息概率计算!$C:$Y,22,0) -> 0 | AA13: =VLOOKUP(TEXT($AA$6,"YYMM")&"E",加息降息概率计算!$C:$Y,23,0) -> 0
C14: =日历计算!D4 -> 2603E | F14: =日历计算!E4 -> 46100.083 | G14: =I14/K14 -> -0.27846154 | H14: =IF(VLOOKUP(C14,加息降息概率计算!C:Y,23,0)>0,1-VLOOKUP(C14,加息降息概率计算!C:Y,22,0),IF(VLOOKUP(C14,加息降息概率计算!C:Y,21,0)>0,VLOOKUP(C14,加息降息概率计算!C:Y,22,0)-1,0)) -> -0.28274725 | I14: =J14-$H$6 -> -0.069615385 | J14: =VLOOKUP(C14&"E",加息降息概率计算!C:S,9,0) -> 3.5703846 | K14: 0.25 | O14: =TODAY()-美联储利率观测器!Q6 -> 46036 | P14: =VLOOKUP(TEXT($T$6,"YYMM")&"E",'加息降息概率计算-1P'!$C:$S,13,0) -> 0 | Q14: =VLOOKUP(TEXT($T$6,"YYMM")&"E",'加息降息概率计算-1P'!$C:$S,14,0) -> 0.24 | R14: =VLOOKUP(TEXT($T$6,"YYMM")&"E",'加息降息概率计算-1P'!$C:$S,15,0) -> 0.76 | S14: =VLOOKUP(TEXT($T$6,"YYMM")&"E",'加息降息概率计算-1P'!$C:$S,16,0) -> 0 | T14: =VLOOKUP(TEXT($T$6,"YYMM")&"E",'加息降息概率计算-1P'!$C:$S,17,0) -> 0 | X14: =O14 -> 46036 | Y14: =VLOOKUP(TEXT($AA$6,"YYMM")&"E",'加息降息概率计算-1P'!$C:$Y,21,0) -> 1 | Z14: =VLOOKUP(TEXT($AA$6,"YYMM")&"E",'加息降息概率计算-1P'!$C:$Y,22,0) -> 0 | AA14: =VLOOKUP(TEXT($AA$6,"YYMM")&"E",'加息降息概率计算-1P'!$C:$Y,23,0) -> 0
C15: =日历计算!D5 -> 2604E | F15: =日历计算!E5 -> 46142.083 | G15: =I15/K15 -> -0.46 | H15: =IF(VLOOKUP(C15,加息降息概率计算!C:Y,23,0)>0,1-VLOOKUP(C15,加息降息概率计算!C:Y,22,0),IF(VLOOKUP(C15,加息降息概率计算!C:Y,21,0)>0,VLOOKUP(C15,加息降息概率计算!C:Y,22,0)-1,0)) -> -0.46428571 | I15: =J15-$H$6 -> -0.115 | J15: =VLOOKUP(C15&"E",加息降息概率计算!C:S,9,0) -> 3.525 | K15: 0.25 | O15: =TODAY()-2*美联储利率观测器!Q6 -> 46035 | P15: =VLOOKUP(TEXT($T$6,"YYMM")&"E",'加息降息概率计算-2P'!$C:$S,13,0) -> 0 | Q15: =VLOOKUP(TEXT($T$6,"YYMM")&"E",'加息降息概率计算-2P'!$C:$S,14,0) -> 0.24 | R15: =VLOOKUP(TEXT($T$6,"YYMM")&"E",'加息降息概率计算-2P'!$C:$S,15,0) -> 0.76 | S15: =VLOOKUP(TEXT($T$6,"YYMM")&"E",'加息降息概率计算-2P'!$C:$S,16,0) -> 0 | T15: =VLOOKUP(TEXT($T$6,"YYMM")&"E",'加息降息概率计算-2P'!$C:$S,17,0) -> 0 | X15: =O15 -> 46035 | Y15: =VLOOKUP(TEXT($AA$6,"YYMM")&"E",'加息降息概率计算-2P'!$C:$Y,21,0) -> 1 | Z15: =VLOOKUP(TEXT($AA$6,"YYMM")&"E",'加息降息概率计算-2P'!$C:$Y,22,0) -> 0 | AA15: =VLOOKUP(TEXT($AA$6,"YYMM")&"E",'加息降息概率计算-2P'!$C:$Y,23,0) -> 0
C16: =日历计算!D6 -> 2606E | F16: =日历计算!E6 -> 46191.083 | G16: =I16/K16 -> -0.96769231 | H16: =IF(VLOOKUP(C16,加息降息概率计算!C:Y,23,0)>0,1-VLOOKUP(C16,加息降息概率计算!C:Y,22,0),IF(VLOOKUP(C16,加息降息概率计算!C:Y,21,0)>0,VLOOKUP(C16,加息降息概率计算!C:Y,22,0)-1,0)) -> -0.97197802 | I16: =J16-$H$6 -> -0.24192308 | J16: =VLOOKUP(C16&"E",加息降息概率计算!C:S,9,0) -> 3.3980769 | K16: 0.25 | O16: =TODAY()-3*美联储利率观测器!Q6 -> 46034 | P16: =VLOOKUP(TEXT($T$6,"YYMM")&"E",'加息降息概率计算-3P'!$C:$S,13,0) -> 0 | Q16: =VLOOKUP(TEXT($T$6,"YYMM")&"E",'加息降息概率计算-3P'!$C:$S,14,0) -> 0.22 | R16: =VLOOKUP(TEXT($T$6,"YYMM")&"E",'加息降息概率计算-3P'!$C:$S,15,0) -> 0.78 | S16: =VLOOKUP(TEXT($T$6,"YYMM")&"E",'加息降息概率计算-3P'!$C:$S,16,0) -> 0 | T16: =VLOOKUP(TEXT($T$6,"YYMM")&"E",'加息降息概率计算-3P'!$C:$S,17,0) -> 0 | X16: =O16 -> 46034 | Y16: =VLOOKUP(TEXT($AA$6,"YYMM")&"E",'加息降息概率计算-3P'!$C:$Y,21,0) -> 1 | Z16: =VLOOKUP(TEXT($AA$6,"YYMM")&"E",'加息降息概率计算-3P'!$C:$Y,22,0) -> 0 | AA16: =VLOOKUP(TEXT($AA$6,"YYMM")&"E",'加息降息概率计算-3P'!$C:$Y,23,0) -> 0
C17: =日历计算!D7 -> 2607E | F17: =日历计算!E7 -> 46233.083 | G17: =I17/K17 -> -1.3 | H17: =IF(VLOOKUP(C17,加息降息概率计算!C:Y,23,0)>0,1-VLOOKUP(C17,加息降息概率计算!C:Y,22,0),IF(VLOOKUP(C17,加息降息概率计算!C:Y,21,0)>0,VLOOKUP(C17,加息降息概率计算!C:Y,22,0)-1,0)) -> -1 | I17: =J17-$H$6 -> -0.325 | J17: =VLOOKUP(C17&"E",加息降息概率计算!C:S,9,0) -> 3.315 | K17: 0.25 | O17: =TODAY()-4*美联储利率观测器!Q6 -> 46033 | P17: =VLOOKUP(TEXT($T$6,"YYMM")&"E",'加息降息概率计算-4P'!$C:$S,13,0) -> 0 | Q17: =VLOOKUP(TEXT($T$6,"YYMM")&"E",'加息降息概率计算-4P'!$C:$S,14,0) -> 0.2 | R17: =VLOOKUP(TEXT($T$6,"YYMM")&"E",'加息降息概率计算-4P'!$C:$S,15,0) -> 0.8 | S17: =VLOOKUP(TEXT($T$6,"YYMM")&"E",'加息降息概率计算-4P'!$C:$S,16,0) -> 0 | T17: =VLOOKUP(TEXT($T$6,"YYMM")&"E",'加息降息概率计算-4P'!$C:$S,17,0) -> 0 | X17: =O17 -> 46033 | Y17: =VLOOKUP(TEXT($AA$6,"YYMM")&"E",'加息降息概率计算-4P'!$C:$Y,21,0) -> 1 | Z17: =VLOOKUP(TEXT($AA$6,"YYMM")&"E",'加息降息概率计算-4P'!$C:$Y,22,0) -> 0 | AA17: =VLOOKUP(TEXT($AA$6,"YYMM")&"E",'加息降息概率计算-4P'!$C:$Y,23,0) -> 0
C18: =日历计算!D8 -> 2609E | F18: =日历计算!E8 -> 46282.083 | G18: =I18/K18 -> -1.7285714 | H18: =IF(VLOOKUP(C18,加息降息概率计算!C:Y,23,0)>0,1-VLOOKUP(C18,加息降息概率计算!C:Y,22,0),IF(VLOOKUP(C18,加息降息概率计算!C:Y,21,0)>0,VLOOKUP(C18,加息降息概率计算!C:Y,22,0)-1,0)) -> -1 | I18: =J18-$H$6 -> -0.43214286 | J18: =VLOOKUP(C18&"E",加息降息概率计算!C:S,9,0) -> 3.2078571 | K18: 0.25 | O18: =TODAY()-5*美联储利率观测器!Q6 -> 46032 | P18: =VLOOKUP(TEXT($T$6,"YYMM")&"E",'加息降息概率计算-5P'!$C:$S,13,0) -> 0 | Q18: =VLOOKUP(TEXT($T$6,"YYMM")&"E",'加息降息概率计算-5P'!$C:$S,14,0) -> 0.2 | R18: =VLOOKUP(TEXT($T$6,"YYMM")&"E",'加息降息概率计算-5P'!$C:$S,15,0) -> 0.8 | S18: =VLOOKUP(TEXT($T$6,"YYMM")&"E",'加息降息概率计算-5P'!$C:$S,16,0) -> 0 | T18: =VLOOKUP(TEXT($T$6,"YYMM")&"E",'加息降息概率计算-5P'!$C:$S,17,0) -> 0 | X18: =O18 -> 46032 | Y18: =VLOOKUP(TEXT($AA$6,"YYMM")&"E",'加息降息概率计算-5P'!$C:$Y,21,0) -> 1 | Z18: =VLOOKUP(TEXT($AA$6,"YYMM")&"E",'加息降息概率计算-5P'!$C:$Y,22,0) -> 0 | AA18: =VLOOKUP(TEXT($AA$6,"YYMM")&"E",'加息降息概率计算-5P'!$C:$Y,23,0) -> 0
C19: =日历计算!D9 -> 2610E | F19: =日历计算!E9 -> 46324.083 | G19: =I19/K19 -> -1.96 | H19: =IF(VLOOKUP(C19,加息降息概率计算!C:Y,23,0)>0,1-VLOOKUP(C19,加息降息概率计算!C:Y,22,0),IF(VLOOKUP(C19,加息降息概率计算!C:Y,21,0)>0,VLOOKUP(C19,加息降息概率计算!C:Y,22,0)-1,0)) -> -1 | I19: =J19-$H$6 -> -0.49 | J19: =VLOOKUP(C19&"E",加息降息概率计算!C:S,9,0) -> 3.15 | K19: 0.25 | O19: =TODAY()-6*美联储利率观测器!Q6 -> 46031 | P19: =VLOOKUP(TEXT($T$6,"YYMM")&"E",'加息降息概率计算-6P'!$C:$S,13,0) -> 0 | Q19: =VLOOKUP(TEXT($T$6,"YYMM")&"E",'加息降息概率计算-6P'!$C:$S,14,0) -> 0.2 | R19: =VLOOKUP(TEXT($T$6,"YYMM")&"E",'加息降息概率计算-6P'!$C:$S,15,0) -> 0.8 | S19: =VLOOKUP(TEXT($T$6,"YYMM")&"E",'加息降息概率计算-6P'!$C:$S,16,0) -> 0 | T19: =VLOOKUP(TEXT($T$6,"YYMM")&"E",'加息降息概率计算-6P'!$C:$S,17,0) -> 0 | X19: =O19 -> 46031 | Y19: =VLOOKUP(TEXT($AA$6,"YYMM")&"E",'加息降息概率计算-6P'!$C:$Y,21,0) -> 1 | Z19: =VLOOKUP(TEXT($AA$6,"YYMM")&"E",'加息降息概率计算-6P'!$C:$Y,22,0) -> 0 | AA19: =VLOOKUP(TEXT($AA$6,"YYMM")&"E",'加息降息概率计算-6P'!$C:$Y,23,0) -> 0
C20: =日历计算!D10 -> 2612E | F20: =日历计算!E10 -> 46366.083 | G20: =I20/K20 -> -2.2 | H20: =IF(VLOOKUP(C20,加息降息概率计算!C:Y,23,0)>0,1-VLOOKUP(C20,加息降息概率计算!C:Y,22,0),IF(VLOOKUP(C20,加息降息概率计算!C:Y,21,0)>0,VLOOKUP(C20,加息降息概率计算!C:Y,22,0)-1,0)) -> -1 | I20: =J20-$H$6 -> -0.55 | J20: =VLOOKUP(C20&"E",加息降息概率计算!C:S,9,0) -> 3.09 | K20: 0.25 | O20: =TODAY()-7*美联储利率观测器!Q6 -> 46030 | P20: =VLOOKUP(TEXT($T$6,"YYMM")&"E",'加息降息概率计算-7P'!$C:$S,13,0) -> 0 | Q20: =VLOOKUP(TEXT($T$6,"YYMM")&"E",'加息降息概率计算-7P'!$C:$S,14,0) -> 0.2 | R20: =VLOOKUP(TEXT($T$6,"YYMM")&"E",'加息降息概率计算-7P'!$C:$S,15,0) -> 0.8 | S20: =VLOOKUP(TEXT($T$6,"YYMM")&"E",'加息降息概率计算-7P'!$C:$S,16,0) -> 0 | T20: =VLOOKUP(TEXT($T$6,"YYMM")&"E",'加息降息概率计算-7P'!$C:$S,17,0) -> 0 | X20: =O20 -> 46030 | Y20: =VLOOKUP(TEXT($AA$6,"YYMM")&"E",'加息降息概率计算-7P'!$C:$Y,21,0) -> 1 | Z20: =VLOOKUP(TEXT($AA$6,"YYMM")&"E",'加息降息概率计算-7P'!$C:$Y,22,0) -> 0 | AA20: =VLOOKUP(TEXT($AA$6,"YYMM")&"E",'加息降息概率计算-7P'!$C:$Y,23,0) -> 0
C21: =日历计算!D11 -> 请更新代码 | O21: =TODAY()-8*美联储利率观测器!Q6 -> 46029 | P21: =VLOOKUP(TEXT($T$6,"YYMM")&"E",'加息降息概率计算-8P'!$C:$S,13,0) -> 0 | Q21: =VLOOKUP(TEXT($T$6,"YYMM")&"E",'加息降息概率计算-8P'!$C:$S,14,0) -> 0.22 | R21: =VLOOKUP(TEXT($T$6,"YYMM")&"E",'加息降息概率计算-8P'!$C:$S,15,0) -> 0.78 | S21: =VLOOKUP(TEXT($T$6,"YYMM")&"E",'加息降息概率计算-8P'!$C:$S,16,0) -> 0 | T21: =VLOOKUP(TEXT($T$6,"YYMM")&"E",'加息降息概率计算-8P'!$C:$S,17,0) -> 0 | X21: =O21 -> 46029 | Y21: =VLOOKUP(TEXT($AA$6,"YYMM")&"E",'加息降息概率计算-8P'!$C:$Y,21,0) -> 1 | Z21: =VLOOKUP(TEXT($AA$6,"YYMM")&"E",'加息降息概率计算-8P'!$C:$Y,22,0) -> 0 | AA21: =VLOOKUP(TEXT($AA$6,"YYMM")&"E",'加息降息概率计算-8P'!$C:$Y,23,0) -> 0
C22: =日历计算!D12 -> 请更新代码 | O22: =TODAY()-9*美联储利率观测器!Q6 -> 46028 | P22: =VLOOKUP(TEXT($T$6,"YYMM")&"E",'加息降息概率计算-9P'!$C:$S,13,0) -> 0 | Q22: =VLOOKUP(TEXT($T$6,"YYMM")&"E",'加息降息概率计算-9P'!$C:$S,14,0) -> 0.18 | R22: =VLOOKUP(TEXT($T$6,"YYMM")&"E",'加息降息概率计算-9P'!$C:$S,15,0) -> 0.82 | S22: =VLOOKUP(TEXT($T$6,"YYMM")&"E",'加息降息概率计算-9P'!$C:$S,16,0) -> 0 | T22: =VLOOKUP(TEXT($T$6,"YYMM")&"E",'加息降息概率计算-9P'!$C:$S,17,0) -> 0 | X22: =O22 -> 46028 | Y22: =VLOOKUP(TEXT($AA$6,"YYMM")&"E",'加息降息概率计算-9P'!$C:$Y,21,0) -> 1 | Z22: =VLOOKUP(TEXT($AA$6,"YYMM")&"E",'加息降息概率计算-9P'!$C:$Y,22,0) -> 0 | AA22: =VLOOKUP(TEXT($AA$6,"YYMM")&"E",'加息降息概率计算-9P'!$C:$Y,23,0) -> 0
C23: =日历计算!D13 -> 请更新代码 | O23: =TODAY()-10*美联储利率观测器!Q6 -> 46027 | P23: =VLOOKUP(TEXT($T$6,"YYMM")&"E",'加息降息概率计算-10P'!$C:$S,13,0) -> 0 | Q23: =VLOOKUP(TEXT($T$6,"YYMM")&"E",'加息降息概率计算-10P'!$C:$S,14,0) -> 0.16 | R23: =VLOOKUP(TEXT($T$6,"YYMM")&"E",'加息降息概率计算-10P'!$C:$S,15,0) -> 0.84 | S23: =VLOOKUP(TEXT($T$6,"YYMM")&"E",'加息降息概率计算-10P'!$C:$S,16,0) -> 0 | T23: =VLOOKUP(TEXT($T$6,"YYMM")&"E",'加息降息概率计算-10P'!$C:$S,17,0) -> 0 | X23: =O23 -> 46027 | Y23: =VLOOKUP(TEXT($AA$6,"YYMM")&"E",'加息降息概率计算-10P'!$C:$Y,21,0) -> 1 | Z23: =VLOOKUP(TEXT($AA$6,"YYMM")&"E",'加息降息概率计算-10P'!$C:$Y,22,0) -> 0 | AA23: =VLOOKUP(TEXT($AA$6,"YYMM")&"E",'加息降息概率计算-10P'!$C:$Y,23,0) -> 0
C24: =日历计算!D14 -> 请更新代码 | O24: =TODAY()-11*美联储利率观测器!Q6 -> 46026 | P24: =VLOOKUP(TEXT($T$6,"YYMM")&"E",'加息降息概率计算-11P'!$C:$S,13,0) -> 0 | Q24: =VLOOKUP(TEXT($T$6,"YYMM")&"E",'加息降息概率计算-11P'!$C:$S,14,0) -> 0.14 | R24: =VLOOKUP(TEXT($T$6,"YYMM")&"E",'加息降息概率计算-11P'!$C:$S,15,0) -> 0.86 | S24: =VLOOKUP(TEXT($T$6,"YYMM")&"E",'加息降息概率计算-11P'!$C:$S,16,0) -> 0 | T24: =VLOOKUP(TEXT($T$6,"YYMM")&"E",'加息降息概率计算-11P'!$C:$S,17,0) -> 0 | X24: =O24 -> 46026 | Y24: =VLOOKUP(TEXT($AA$6,"YYMM")&"E",'加息降息概率计算-11P'!$C:$Y,21,0) -> 1 | Z24: =VLOOKUP(TEXT($AA$6,"YYMM")&"E",'加息降息概率计算-11P'!$C:$Y,22,0) -> 0 | AA24: =VLOOKUP(TEXT($AA$6,"YYMM")&"E",'加息降息概率计算-11P'!$C:$Y,23,0) -> 0
C25: =日历计算!D15 -> 请更新代码 | O25: =TODAY()-12*美联储利率观测器!Q6 -> 46025 | P25: =VLOOKUP(TEXT($T$6,"YYMM")&"E",'加息降息概率计算-12P'!$C:$S,13,0) -> 0 | Q25: =VLOOKUP(TEXT($T$6,"YYMM")&"E",'加息降息概率计算-12P'!$C:$S,14,0) -> 0.14 | R25: =VLOOKUP(TEXT($T$6,"YYMM")&"E",'加息降息概率计算-12P'!$C:$S,15,0) -> 0.86 | S25: =VLOOKUP(TEXT($T$6,"YYMM")&"E",'加息降息概率计算-12P'!$C:$S,16,0) -> 0 | T25: =VLOOKUP(TEXT($T$6,"YYMM")&"E",'加息降息概率计算-12P'!$C:$S,17,0) -> 0 | X25: =O25 -> 46025 | Y25: =VLOOKUP(TEXT($AA$6,"YYMM")&"E",'加息降息概率计算-12P'!$C:$Y,21,0) -> 1 | Z25: =VLOOKUP(TEXT($AA$6,"YYMM")&"E",'加息降息概率计算-12P'!$C:$Y,22,0) -> 0 | AA25: =VLOOKUP(TEXT($AA$6,"YYMM")&"E",'加息降息概率计算-12P'!$C:$Y,23,0) -> 0
C26: =日历计算!D16 -> 请更新代码 | O26: =TODAY()-13*美联储利率观测器!Q6 -> 46024 | P26: =VLOOKUP(TEXT($T$6,"YYMM")&"E",'加息降息概率计算-13P'!$C:$S,13,0) -> 0 | Q26: =VLOOKUP(TEXT($T$6,"YYMM")&"E",'加息降息概率计算-13P'!$C:$S,14,0) -> 0.14 | R26: =VLOOKUP(TEXT($T$6,"YYMM")&"E",'加息降息概率计算-13P'!$C:$S,15,0) -> 0.86 | S26: =VLOOKUP(TEXT($T$6,"YYMM")&"E",'加息降息概率计算-13P'!$C:$S,16,0) -> 0 | T26: =VLOOKUP(TEXT($T$6,"YYMM")&"E",'加息降息概率计算-13P'!$C:$S,17,0) -> 0 | X26: =O26 -> 46024 | Y26: =VLOOKUP(TEXT($AA$6,"YYMM")&"E",'加息降息概率计算-13P'!$C:$Y,21,0) -> 1 | Z26: =VLOOKUP(TEXT($AA$6,"YYMM")&"E",'加息降息概率计算-13P'!$C:$Y,22,0) -> 0 | AA26: =VLOOKUP(TEXT($AA$6,"YYMM")&"E",'加息降息概率计算-13P'!$C:$Y,23,0) -> 0
C27: =日历计算!D17 -> 请更新代码 | O27: =TODAY()-14*美联储利率观测器!Q6 -> 46023 | P27: =VLOOKUP(TEXT($T$6,"YYMM")&"E",'加息降息概率计算-14P'!$C:$S,13,0) -> 0 | Q27: =VLOOKUP(TEXT($T$6,"YYMM")&"E",'加息降息概率计算-14P'!$C:$S,14,0) -> 0.16 | R27: =VLOOKUP(TEXT($T$6,"YYMM")&"E",'加息降息概率计算-14P'!$C:$S,15,0) -> 0.84 | S27: =VLOOKUP(TEXT($T$6,"YYMM")&"E",'加息降息概率计算-14P'!$C:$S,16,0) -> 0 | T27: =VLOOKUP(TEXT($T$6,"YYMM")&"E",'加息降息概率计算-14P'!$C:$S,17,0) -> 0 | X27: =O27 -> 46023 | Y27: =VLOOKUP(TEXT($AA$6,"YYMM")&"E",'加息降息概率计算-14P'!$C:$Y,21,0) -> 1 | Z27: =VLOOKUP(TEXT($AA$6,"YYMM")&"E",'加息降息概率计算-14P'!$C:$Y,22,0) -> 0 | AA27: =VLOOKUP(TEXT($AA$6,"YYMM")&"E",'加息降息概率计算-14P'!$C:$Y,23,0) -> 0
C28: =日历计算!D18 -> 请更新代码 | O28: =TODAY()-15*美联储利率观测器!Q6 -> 46022 | P28: =VLOOKUP(TEXT($T$6,"YYMM")&"E",'加息降息概率计算-15P'!$C:$S,13,0) -> 0 | Q28: =VLOOKUP(TEXT($T$6,"YYMM")&"E",'加息降息概率计算-15P'!$C:$S,14,0) -> 0.16 | R28: =VLOOKUP(TEXT($T$6,"YYMM")&"E",'加息降息概率计算-15P'!$C:$S,15,0) -> 0.84 | S28: =VLOOKUP(TEXT($T$6,"YYMM")&"E",'加息降息概率计算-15P'!$C:$S,16,0) -> 0 | T28: =VLOOKUP(TEXT($T$6,"YYMM")&"E",'加息降息概率计算-15P'!$C:$S,17,0) -> 0 | X28: =O28 -> 46022 | Y28: =VLOOKUP(TEXT($AA$6,"YYMM")&"E",'加息降息概率计算-15P'!$C:$Y,21,0) -> 1 | Z28: =VLOOKUP(TEXT($AA$6,"YYMM")&"E",'加息降息概率计算-15P'!$C:$Y,22,0) -> 0 | AA28: =VLOOKUP(TEXT($AA$6,"YYMM")&"E",'加息降息概率计算-15P'!$C:$Y,23,0) -> 0
C29: =日历计算!D19 -> 请更新代码 | O29: =TODAY()-16*美联储利率观测器!Q6 -> 46021 | P29: =VLOOKUP(TEXT($T$6,"YYMM")&"E",'加息降息概率计算-16P'!$C:$S,13,0) -> 0 | Q29: =VLOOKUP(TEXT($T$6,"YYMM")&"E",'加息降息概率计算-16P'!$C:$S,14,0) -> 0.16 | R29: =VLOOKUP(TEXT($T$6,"YYMM")&"E",'加息降息概率计算-16P'!$C:$S,15,0) -> 0.84 | S29: =VLOOKUP(TEXT($T$6,"YYMM")&"E",'加息降息概率计算-16P'!$C:$S,16,0) -> 0 | T29: =VLOOKUP(TEXT($T$6,"YYMM")&"E",'加息降息概率计算-16P'!$C:$S,17,0) -> 0 | X29: =O29 -> 46021 | Y29: =VLOOKUP(TEXT($AA$6,"YYMM")&"E",'加息降息概率计算-16P'!$C:$Y,21,0) -> 1 | Z29: =VLOOKUP(TEXT($AA$6,"YYMM")&"E",'加息降息概率计算-16P'!$C:$Y,22,0) -> 0 | AA29: =VLOOKUP(TEXT($AA$6,"YYMM")&"E",'加息降息概率计算-16P'!$C:$Y,23,0) -> 0
C30: =日历计算!D20 -> 请更新代码 | O30: =TODAY()-17*美联储利率观测器!Q6 -> 46020 | P30: =VLOOKUP(TEXT($T$6,"YYMM")&"E",'加息降息概率计算-17P'!$C:$S,13,0) -> 0 | Q30: =VLOOKUP(TEXT($T$6,"YYMM")&"E",'加息降息概率计算-17P'!$C:$S,14,0) -> 0.14 | R30: =VLOOKUP(TEXT($T$6,"YYMM")&"E",'加息降息概率计算-17P'!$C:$S,15,0) -> 0.86 | S30: =VLOOKUP(TEXT($T$6,"YYMM")&"E",'加息降息概率计算-17P'!$C:$S,16,0) -> 0 | T30: =VLOOKUP(TEXT($T$6,"YYMM")&"E",'加息降息概率计算-17P'!$C:$S,17,0) -> 0 | X30: =O30 -> 46020 | Y30: =VLOOKUP(TEXT($AA$6,"YYMM")&"E",'加息降息概率计算-17P'!$C:$Y,21,0) -> 1 | Z30: =VLOOKUP(TEXT($AA$6,"YYMM")&"E",'加息降息概率计算-17P'!$C:$Y,22,0) -> 0 | AA30: =VLOOKUP(TEXT($AA$6,"YYMM")&"E",'加息降息概率计算-17P'!$C:$Y,23,0) -> 0
C31: =日历计算!D21 -> 请更新代码 | O31: =TODAY()-18*美联储利率观测器!Q6 -> 46019 | P31: =VLOOKUP(TEXT($T$6,"YYMM")&"E",'加息降息概率计算-18P'!$C:$S,13,0) -> 0 | Q31: =VLOOKUP(TEXT($T$6,"YYMM")&"E",'加息降息概率计算-18P'!$C:$S,14,0) -> 0.14 | R31: =VLOOKUP(TEXT($T$6,"YYMM")&"E",'加息降息概率计算-18P'!$C:$S,15,0) -> 0.86 | S31: =VLOOKUP(TEXT($T$6,"YYMM")&"E",'加息降息概率计算-18P'!$C:$S,16,0) -> 0 | T31: =VLOOKUP(TEXT($T$6,"YYMM")&"E",'加息降息概率计算-18P'!$C:$S,17,0) -> 0 | X31: =O31 -> 46019 | Y31: =VLOOKUP(TEXT($AA$6,"YYMM")&"E",'加息降息概率计算-18P'!$C:$Y,21,0) -> 1 | Z31: =VLOOKUP(TEXT($AA$6,"YYMM")&"E",'加息降息概率计算-18P'!$C:$Y,22,0) -> 0 | AA31: =VLOOKUP(TEXT($AA$6,"YYMM")&"E",'加息降息概率计算-18P'!$C:$Y,23,0) -> 0
AF44: =[1]!edb() -> Wind
AF45: 指标名称 | AG45: 美国:联邦基金目标利率
AF46: 46002 | AG46: 3.75
AF48: =[1]!edb() -> Wind
AF49: 指标名称 | AG49: 美国:有效联邦基金利率(EFFR)(日)
AF50: 46035 | AG50: 3.64

Sheet 美联储议息会议日历
F1: 美联储议息会议日历 | K1: 最近更新： | L1: =NOW() -> 46037.779
C4: 日期： | D4: =IFERROR(日历计算!E3,“--”) -> 46051.083 | E4: =IFERROR(日历计算!E4,"--") -> 46100.083 | F4: =IFERROR(日历计算!E5,"--") -> 46142.083 | G4: =IFERROR(日历计算!E6,"--") -> 46191.083 | H4: =IFERROR(日历计算!E7,"--") -> 46233.083 | I4: =IFERROR(日历计算!E8,"--") -> 46282.083 | J4: =IFERROR(日历计算!E9,"--") -> 46324.083 | K4: =IFERROR(日历计算!E10,"--") -> 46366.083 | L4: =IFERROR(日历计算!E11,"--") -> 请更新日历
C5: 倒数（天）： | D5: =IFERROR(D4-$L$1,"--") -> 13.303888 | E5: =IFERROR(E4-$L$1,"--") -> 62.303888 | F5: =IFERROR(F4-$L$1,"--") -> 104.30389 | G5: =IFERROR(G4-$L$1,"--") -> 153.30389 | H5: =IFERROR(H4-$L$1,"--") -> 195.30389 | I5: =IFERROR(I4-$L$1,"--") -> 244.30389 | J5: =IFERROR(J4-$L$1,"--") -> 286.30389 | K5: =IFERROR(K4-$L$1,"--") -> 328.30389 | L5: =IFERROR(L4-$L$1,"--") -> --

Sheet 日历计算
B1: 日历更新区 | E1: 隐含利率日期时点 | G1: 概率计算日期时点 | K1: 连续日历月(含会议日) | N1: 连续日历月(每月1号)
A2: =IF(B2="请更新日历","请更新代码",TEXT(B2,"YYMM")&"E") -> 2408E | B2: 45505.083 | E2: =OFFSET(IF(美联储议息会议日历!L1<B2,B2,IF(美联储议息会议日历!L1<B3,B3,IF(美联储议息会议日历!L1<B4,B4,IF(美联储议息会议日历!L1<B5,B5,IF(美联储议息会议日历!L1<B6,B6,IF(美联储议息会议日历!L1<B7,B7,IF(美联储议息会议日历!L1<B8,B8,IF(美联储议息会议日历!L1<B9,B9,IF(美联储议息会议日历!L1<B10,B10,IF(美联储议息会议日历!L1<B11,B11,IF(美联储议息会议日历!L1<B12,B12,IF(美联储议息会议日历!L1<B13,B13,B14)))))))))))),-1,0) -> 46002.083 | G2: =OFFSET(IF(美联储议息会议日历!L1<=K2,K2,IF(美联储议息会议日历!L1<=K3,K3,IF(美联储议息会议日历!L1<=K4,K4,IF(美联储议息会议日历!L1<=K5,K5,IF(美联储议息会议日历!L1<=K6,K6,IF(美联储议息会议日历!L1<=K7,K7,IF(美联储议息会议日历!L1<=K8,K8,IF(美联储议息会议日历!L1<=K9,K9,IF(美联储议息会议日历!L1<=K10,K10,IF(美联储议息会议日历!L1<=K11,K11,IF(美联储议息会议日历!L1<=K12,K12,IF(美联储议息会议日历!L1<=K13,K13,IF(美联储议息会议日历!L1<=K14,K14,IF(美联储议息会议日历!L1<=K15,K15,IF(美联储议息会议日历!L1<=K16,K16,IF(美联储议息会议日历!L1<=K17,K17,IF(美联储议息会议日历!L1<=K18,K18,IF(美联储议息会议日历!L1<=K19,K19,K20)))))))))))))))))),-1,0) -> 连续日历月(含会议日) | H2: =_xlfn.IFNA(MATCH(G2,$E$3:$E$21,0),0) -> 0 | J2: =IF(K2="请更新日历","请更新代码",TEXT(K2,"YYMM")&"E") -> 2601E | K2: =IF(COUNTIF(A:A,M2)=0,N2,VLOOKUP(M2,A:B,2,0)) -> 46051.083 | M2: =TEXT(N2,"YYMM")&"E" -> 2601E | N2: =DATE(YEAR(TODAY()), 1, 1) + TIME(2, 0, 0) -> 46023.083
A3: =IF(B3="请更新日历","请更新代码",TEXT(B3,"YYMM")&"E") -> 2409E | B3: 45554.083 | D3: =OFFSET(IF(美联储议息会议日历!L1<=B2,B2,IF(美联储议息会议日历!L1<=B3,B3,IF(美联储议息会议日历!L1<=B4,B4,IF(美联储议息会议日历!L1<=B5,B5,IF(美联储议息会议日历!L1<=B6,B6,IF(美联储议息会议日历!L1<=B7,B7,IF(美联储议息会议日历!L1<=B8,B8,IF(美联储议息会议日历!L1<=B9,B9,IF(美联储议息会议日历!L1<=B10,B10,IF(美联储议息会议日历!L1<=B11,B11,IF(美联储议息会议日历!L1<=B12,B12,IF(美联储议息会议日历!L1<=B13,B13,B14)))))))))))),0,-1) -> 2601E | E3: =IF(美联储议息会议日历!L1<B2,B2,IF(美联储议息会议日历!L1<B3,B3,IF(美联储议息会议日历!L1<B4,B4,IF(美联储议息会议日历!L1<B5,B5,IF(美联储议息会议日历!L1<B6,B6,IF(美联储议息会议日历!L1<B7,B7,IF(美联储议息会议日历!L1<B8,B8,IF(美联储议息会议日历!L1<B9,B9,IF(美联储议息会议日历!L1<B10,B10,IF(美联储议息会议日历!L1<B11,B11,IF(美联储议息会议日历!L1<B12,B12,IF(美联储议息会议日历!L1<B13,B13,B14)))))))))))) -> 46051.083 | G3: =IF(美联储议息会议日历!L1<=K2,K2,IF(美联储议息会议日历!L1<=K3,K3,IF(美联储议息会议日历!L1<=K4,K4,IF(美联储议息会议日历!L1<=K5,K5,IF(美联储议息会议日历!L1<=K6,K6,IF(美联储议息会议日历!L1<=K7,K7,IF(美联储议息会议日历!L1<=K8,K8,IF(美联储议息会议日历!L1<=K9,K9,IF(美联储议息会议日历!L1<=K10,K10,IF(美联储议息会议日历!L1<=K11,K11,IF(美联储议息会议日历!L1<=K12,K12,IF(美联储议息会议日历!L1<=K13,K13,IF(美联储议息会议日历!L1<=K14,K14,IF(美联储议息会议日历!L1<=K15,K15,IF(美联储议息会议日历!L1<=K16,K16,IF(美联储议息会议日历!L1<=K17,K17,IF(美联储议息会议日历!L1<=K18,K18,IF(美联储议息会议日历!L1<=K19,K19,K20)))))))))))))))))) -> 46051.083 | H3: =_xlfn.IFNA(MATCH(G3,$E$3:$E$21,0),0) -> 1 | J3: =IF(K3="请更新日历","请更新代码",TEXT(K3,"YYMM")&"E") -> 2602E | K3: =IF(COUNTIF(A:A,M3)=0,N3,VLOOKUP(M3,A:B,2,0)) -> 46054.083 | M3: =TEXT(N3,"YYMM")&"E" -> 2602E | N3: =DATE(YEAR(TODAY()), 2, 1) + TIME(2, 0, 0) -> 46054.083
A4: =IF(B4="请更新日历","请更新代码",TEXT(B4,"YYMM")&"E") -> 2411E | B4: 45604.083 | D4: =OFFSET(IF(美联储议息会议日历!L1<=B2,B2,IF(美联储议息会议日历!L1<=B3,B3,IF(美联储议息会议日历!L1<=B4,B4,IF(美联储议息会议日历!L1<=B5,B5,IF(美联储议息会议日历!L1<=B6,B6,IF(美联储议息会议日历!L1<=B7,B7,IF(美联储议息会议日历!L1<=B8,B8,IF(美联储议息会议日历!L1<=B9,B9,IF(美联储议息会议日历!L1<=B10,B10,IF(美联储议息会议日历!L1<=B11,B11,IF(美联储议息会议日历!L1<=B12,B12,IF(美联储议息会议日历!L1<=B13,B13,B14)))))))))))),1,-1) -> 2603E | E4: =OFFSET(IF(美联储议息会议日历!L1<B2,B2,IF(美联储议息会议日历!L1<B3,B3,IF(美联储议息会议日历!L1<B4,B4,IF(美联储议息会议日历!L1<B5,B5,IF(美联储议息会议日历!L1<B6,B6,IF(美联储议息会议日历!L1<B7,B7,IF(美联储议息会议日历!L1<B8,B8,IF(美联储议息会议日历!L1<B9,B9,IF(美联储议息会议日历!L1<B10,B10,IF(美联储议息会议日历!L1<B11,B11,IF(美联储议息会议日历!L1<B12,B12,IF(美联储议息会议日历!L1<B13,B13,B14)))))))))))),1,0) -> 46100.083 | G4: =OFFSET(IF(美联储议息会议日历!L1<=K2,K2,IF(美联储议息会议日历!L1<=K3,K3,IF(美联储议息会议日历!L1<=K4,K4,IF(美联储议息会议日历!L1<=K5,K5,IF(美联储议息会议日历!L1<=K6,K6,IF(美联储议息会议日历!L1<=K7,K7,IF(美联储议息会议日历!L1<=K8,K8,IF(美联储议息会议日历!L1<=K9,K9,IF(美联储议息会议日历!L1<=K10,K10,IF(美联储议息会议日历!L1<=K11,K11,IF(美联储议息会议日历!L1<=K12,K12,IF(美联储议息会议日历!L1<=K13,K13,IF(美联储议息会议日历!L1<=K14,K14,IF(美联储议息会议日历!L1<=K15,K15,IF(美联储议息会议日历!L1<=K16,K16,IF(美联储议息会议日历!L1<=K17,K17,IF(美联储议息会议日历!L1<=K18,K18,IF(美联储议息会议日历!L1<=K19,K19,K20)))))))))))))))))),1,0) -> 46054.083 | H4: =_xlfn.IFNA(MATCH(G4,$E$3:$E$21,0),0) -> 0 | J4: =IF(K4="请更新日历","请更新代码",TEXT(K4,"YYMM")&"E") -> 2603E | K4: =IF(COUNTIF(A:A,M4)=0,N4,VLOOKUP(M4,A:B,2,0)) -> 46100.083 | M4: =TEXT(N4,"YYMM")&"E" -> 2603E | N4: =DATE(YEAR(TODAY()), 3, 1) + TIME(2, 0, 0) -> 46082.083
A5: =IF(B5="请更新日历","请更新代码",TEXT(B5,"YYMM")&"E") -> 2412E | B5: 45645.083 | D5: =OFFSET(IF(美联储议息会议日历!L1<=B2,B2,IF(美联储议息会议日历!L1<=B3,B3,IF(美联储议息会议日历!L1<=B4,B4,IF(美联储议息会议日历!L1<=B5,B5,IF(美联储议息会议日历!L1<=B6,B6,IF(美联储议息会议日历!L1<=B7,B7,IF(美联储议息会议日历!L1<=B8,B8,IF(美联储议息会议日历!L1<=B9,B9,IF(美联储议息会议日历!L1<=B10,B10,IF(美联储议息会议日历!L1<=B11,B11,IF(美联储议息会议日历!L1<=B12,B12,IF(美联储议息会议日历!L1<=B13,B13,B14)))))))))))),2,-1) -> 2604E | E5: =OFFSET(IF(美联储议息会议日历!L1<B2,B2,IF(美联储议息会议日历!L1<B3,B3,IF(美联储议息会议日历!L1<B4,B4,IF(美联储议息会议日历!L1<B5,B5,IF(美联储议息会议日历!L1<B6,B6,IF(美联储议息会议日历!L1<B7,B7,IF(美联储议息会议日历!L1<B8,B8,IF(美联储议息会议日历!L1<B9,B9,IF(美联储议息会议日历!L1<B10,B10,IF(美联储议息会议日历!L1<B11,B11,IF(美联储议息会议日历!L1<B12,B12,IF(美联储议息会议日历!L1<B13,B13,B14)))))))))))),2,0) -> 46142.083 | G5: =OFFSET(IF(美联储议息会议日历!L1<=K2,K2,IF(美联储议息会议日历!L1<=K3,K3,IF(美联储议息会议日历!L1<=K4,K4,IF(美联储议息会议日历!L1<=K5,K5,IF(美联储议息会议日历!L1<=K6,K6,IF(美联储议息会议日历!L1<=K7,K7,IF(美联储议息会议日历!L1<=K8,K8,IF(美联储议息会议日历!L1<=K9,K9,IF(美联储议息会议日历!L1<=K10,K10,IF(美联储议息会议日历!L1<=K11,K11,IF(美联储议息会议日历!L1<=K12,K12,IF(美联储议息会议日历!L1<=K13,K13,IF(美联储议息会议日历!L1<=K14,K14,IF(美联储议息会议日历!L1<=K15,K15,IF(美联储议息会议日历!L1<=K16,K16,IF(美联储议息会议日历!L1<=K17,K17,IF(美联储议息会议日历!L1<=K18,K18,IF(美联储议息会议日历!L1<=K19,K19,K20)))))))))))))))))),2,0) -> 46100.083 | H5: =_xlfn.IFNA(MATCH(G5,$E$3:$E$21,0),0) -> 2 | J5: =IF(K5="请更新日历","请更新代码",TEXT(K5,"YYMM")&"E") -> 2604E | K5: =IF(COUNTIF(A:A,M5)=0,N5,VLOOKUP(M5,A:B,2,0)) -> 46142.083 | M5: =TEXT(N5,"YYMM")&"E" -> 2604E | N5: =DATE(YEAR(TODAY()), 4, 1) + TIME(2, 0, 0) -> 46113.083
A6: =IF(B6="请更新日历","请更新代码",TEXT(B6,"YYMM")&"E") -> 2501E | B6: 45687.083 | D6: =OFFSET(IF(美联储议息会议日历!L1<=B2,B2,IF(美联储议息会议日历!L1<=B3,B3,IF(美联储议息会议日历!L1<=B4,B4,IF(美联储议息会议日历!L1<=B5,B5,IF(美联储议息会议日历!L1<=B6,B6,IF(美联储议息会议日历!L1<=B7,B7,IF(美联储议息会议日历!L1<=B8,B8,IF(美联储议息会议日历!L1<=B9,B9,IF(美联储议息会议日历!L1<=B10,B10,IF(美联储议息会议日历!L1<=B11,B11,IF(美联储议息会议日历!L1<=B12,B12,IF(美联储议息会议日历!L1<=B13,B13,B14)))))))))))),3,-1) -> 2606E | E6: =OFFSET(IF(美联储议息会议日历!L1<B2,B2,IF(美联储议息会议日历!L1<B3,B3,IF(美联储议息会议日历!L1<B4,B4,IF(美联储议息会议日历!L1<B5,B5,IF(美联储议息会议日历!L1<B6,B6,IF(美联储议息会议日历!L1<B7,B7,IF(美联储议息会议日历!L1<B8,B8,IF(美联储议息会议日历!L1<B9,B9,IF(美联储议息会议日历!L1<B10,B10,IF(美联储议息会议日历!L1<B11,B11,IF(美联储议息会议日历!L1<B12,B12,IF(美联储议息会议日历!L1<B13,B13,B14)))))))))))),3,0) -> 46191.083 | G6: =OFFSET(IF(美联储议息会议日历!L1<=K2,K2,IF(美联储议息会议日历!L1<=K3,K3,IF(美联储议息会议日历!L1<=K4,K4,IF(美联储议息会议日历!L1<=K5,K5,IF(美联储议息会议日历!L1<=K6,K6,IF(美联储议息会议日历!L1<=K7,K7,IF(美联储议息会议日历!L1<=K8,K8,IF(美联储议息会议日历!L1<=K9,K9,IF(美联储议息会议日历!L1<=K10,K10,IF(美联储议息会议日历!L1<=K11,K11,IF(美联储议息会议日历!L1<=K12,K12,IF(美联储议息会议日历!L1<=K13,K13,IF(美联储议息会议日历!L1<=K14,K14,IF(美联储议息会议日历!L1<=K15,K15,IF(美联储议息会议日历!L1<=K16,K16,IF(美联储议息会议日历!L1<=K17,K17,IF(美联储议息会议日历!L1<=K18,K18,IF(美联储议息会议日历!L1<=K19,K19,K20)))))))))))))))))),3,0) -> 46142.083 | H6: =_xlfn.IFNA(MATCH(G6,$E$3:$E$21,0),0) -> 3 | J6: =IF(K6="请更新日历","请更新代码",TEXT(K6,"YYMM")&"E") -> 2605E | K6: =IF(COUNTIF(A:A,M6)=0,N6,VLOOKUP(M6,A:B,2,0)) -> 46143.083 | M6: =TEXT(N6,"YYMM")&"E" -> 2605E | N6: =DATE(YEAR(TODAY()), 5, 1) + TIME(2, 0, 0) -> 46143.083
A7: =IF(B7="请更新日历","请更新代码",TEXT(B7,"YYMM")&"E") -> 2503E | B7: 45736.083 | D7: =OFFSET(IF(美联储议息会议日历!L1<=B2,B2,IF(美联储议息会议日历!L1<=B3,B3,IF(美联储议息会议日历!L1<=B4,B4,IF(美联储议息会议日历!L1<=B5,B5,IF(美联储议息会议日历!L1<=B6,B6,IF(美联储议息会议日历!L1<=B7,B7,IF(美联储议息会议日历!L1<=B8,B8,IF(美联储议息会议日历!L1<=B9,B9,IF(美联储议息会议日历!L1<=B10,B10,IF(美联储议息会议日历!L1<=B11,B11,IF(美联储议息会议日历!L1<=B12,B12,IF(美联储议息会议日历!L1<=B13,B13,B14)))))))))))),4,-1) -> 2607E | E7: =OFFSET(IF(美联储议息会议日历!L1<B2,B2,IF(美联储议息会议日历!L1<B3,B3,IF(美联储议息会议日历!L1<B4,B4,IF(美联储议息会议日历!L1<B5,B5,IF(美联储议息会议日历!L1<B6,B6,IF(美联储议息会议日历!L1<B7,B7,IF(美联储议息会议日历!L1<B8,B8,IF(美联储议息会议日历!L1<B9,B9,IF(美联储议息会议日历!L1<B10,B10,IF(美联储议息会议日历!L1<B11,B11,IF(美联储议息会议日历!L1<B12,B12,IF(美联储议息会议日历!L1<B13,B13,B14)))))))))))),4,0) -> 46233.083 | G7: =OFFSET(IF(美联储议息会议日历!L1<=K2,K2,IF(美联储议息会议日历!L1<=K3,K3,IF(美联储议息会议日历!L1<=K4,K4,IF(美联储议息会议日历!L1<=K5,K5,IF(美联储议息会议日历!L1<=K6,K6,IF(美联储议息会议日历!L1<=K7,K7,IF(美联储议息会议日历!L1<=K8,K8,IF(美联储议息会议日历!L1<=K9,K9,IF(美联储议息会议日历!L1<=K10,K10,IF(美联储议息会议日历!L1<=K11,K11,IF(美联储议息会议日历!L1<=K12,K12,IF(美联储议息会议日历!L1<=K13,K13,IF(美联储议息会议日历!L1<=K14,K14,IF(美联储议息会议日历!L1<=K15,K15,IF(美联储议息会议日历!L1<=K16,K16,IF(美联储议息会议日历!L1<=K17,K17,IF(美联储议息会议日历!L1<=K18,K18,IF(美联储议息会议日历!L1<=K19,K19,K20)))))))))))))))))),4,0) -> 46143.083 | H7: =_xlfn.IFNA(MATCH(G7,$E$3:$E$21,0),0) -> 0 | J7: =IF(K7="请更新日历","请更新代码",TEXT(K7,"YYMM")&"E") -> 2606E | K7: =IF(COUNTIF(A:A,M7)=0,N7,VLOOKUP(M7,A:B,2,0)) -> 46191.083 | M7: =TEXT(N7,"YYMM")&"E" -> 2606E | N7: =DATE(YEAR(TODAY()), 6, 1) + TIME(2, 0, 0) -> 46174.083
A8: =IF(B8="请更新日历","请更新代码",TEXT(B8,"YYMM")&"E") -> 2505E | B8: 45785.083 | D8: =OFFSET(IF(美联储议息会议日历!L1<=B2,B2,IF(美联储议息会议日历!L1<=B3,B3,IF(美联储议息会议日历!L1<=B4,B4,IF(美联储议息会议日历!L1<=B5,B5,IF(美联储议息会议日历!L1<=B6,B6,IF(美联储议息会议日历!L1<=B7,B7,IF(美联储议息会议日历!L1<=B8,B8,IF(美联储议息会议日历!L1<=B9,B9,IF(美联储议息会议日历!L1<=B10,B10,IF(美联储议息会议日历!L1<=B11,B11,IF(美联储议息会议日历!L1<=B12,B12,IF(美联储议息会议日历!L1<=B13,B13,B14)))))))))))),5,-1) -> 2609E | E8: =OFFSET(IF(美联储议息会议日历!L1<B2,B2,IF(美联储议息会议日历!L1<B3,B3,IF(美联储议息会议日历!L1<B4,B4,IF(美联储议息会议日历!L1<B5,B5,IF(美联储议息会议日历!L1<B6,B6,IF(美联储议息会议日历!L1<B7,B7,IF(美联储议息会议日历!L1<B8,B8,IF(美联储议息会议日历!L1<B9,B9,IF(美联储议息会议日历!L1<B10,B10,IF(美联储议息会议日历!L1<B11,B11,IF(美联储议息会议日历!L1<B12,B12,IF(美联储议息会议日历!L1<B13,B13,B14)))))))))))),5,0) -> 46282.083 | G8: =OFFSET(IF(美联储议息会议日历!L1<=K2,K2,IF(美联储议息会议日历!L1<=K3,K3,IF(美联储议息会议日历!L1<=K4,K4,IF(美联储议息会议日历!L1<=K5,K5,IF(美联储议息会议日历!L1<=K6,K6,IF(美联储议息会议日历!L1<=K7,K7,IF(美联储议息会议日历!L1<=K8,K8,IF(美联储议息会议日历!L1<=K9,K9,IF(美联储议息会议日历!L1<=K10,K10,IF(美联储议息会议日历!L1<=K11,K11,IF(美联储议息会议日历!L1<=K12,K12,IF(美联储议息会议日历!L1<=K13,K13,IF(美联储议息会议日历!L1<=K14,K14,IF(美联储议息会议日历!L1<=K15,K15,IF(美联储议息会议日历!L1<=K16,K16,IF(美联储议息会议日历!L1<=K17,K17,IF(美联储议息会议日历!L1<=K18,K18,IF(美联储议息会议日历!L1<=K19,K19,K20)))))))))))))))))),5,0) -> 46191.083 | H8: =_xlfn.IFNA(MATCH(G8,$E$3:$E$21,0),0) -> 4 | J8: =IF(K8="请更新日历","请更新代码",TEXT(K8,"YYMM")&"E") -> 2607E | K8: =IF(COUNTIF(A:A,M8)=0,N8,VLOOKUP(M8,A:B,2,0)) -> 46233.083 | M8: =TEXT(N8,"YYMM")&"E" -> 2607E | N8: =DATE(YEAR(TODAY()), 7, 1) + TIME(2, 0, 0) -> 46204.083
A9: =IF(B9="请更新日历","请更新代码",TEXT(B9,"YYMM")&"E") -> 2506E | B9: 45827.083 | D9: =OFFSET(IF(美联储议息会议日历!L1<=B2,B2,IF(美联储议息会议日历!L1<=B3,B3,IF(美联储议息会议日历!L1<=B4,B4,IF(美联储议息会议日历!L1<=B5,B5,IF(美联储议息会议日历!L1<=B6,B6,IF(美联储议息会议日历!L1<=B7,B7,IF(美联储议息会议日历!L1<=B8,B8,IF(美联储议息会议日历!L1<=B9,B9,IF(美联储议息会议日历!L1<=B10,B10,IF(美联储议息会议日历!L1<=B11,B11,IF(美联储议息会议日历!L1<=B12,B12,IF(美联储议息会议日历!L1<=B13,B13,B14)))))))))))),6,-1) -> 2610E | E9: =OFFSET(IF(美联储议息会议日历!L1<B2,B2,IF(美联储议息会议日历!L1<B3,B3,IF(美联储议息会议日历!L1<B4,B4,IF(美联储议息会议日历!L1<B5,B5,IF(美联储议息会议日历!L1<B6,B6,IF(美联储议息会议日历!L1<B7,B7,IF(美联储议息会议日历!L1<B8,B8,IF(美联储议息会议日历!L1<B9,B9,IF(美联储议息会议日历!L1<B10,B10,IF(美联储议息会议日历!L1<B11,B11,IF(美联储议息会议日历!L1<B12,B12,IF(美联储议息会议日历!L1<B13,B13,B14)))))))))))),6,0) -> 46324.083 | G9: =OFFSET(IF(美联储议息会议日历!L1<=K2,K2,IF(美联储议息会议日历!L1<=K3,K3,IF(美联储议息会议日历!L1<=K4,K4,IF(美联储议息会议日历!L1<=K5,K5,IF(美联储议息会议日历!L1<=K6,K6,IF(美联储议息会议日历!L1<=K7,K7,IF(美联储议息会议日历!L1<=K8,K8,IF(美联储议息会议日历!L1<=K9,K9,IF(美联储议息会议日历!L1<=K10,K10,IF(美联储议息会议日历!L1<=K11,K11,IF(美联储议息会议日历!L1<=K12,K12,IF(美联储议息会议日历!L1<=K13,K13,IF(美联储议息会议日历!L1<=K14,K14,IF(美联储议息会议日历!L1<=K15,K15,IF(美联储议息会议日历!L1<=K16,K16,IF(美联储议息会议日历!L1<=K17,K17,IF(美联储议息会议日历!L1<=K18,K18,IF(美联储议息会议日历!L1<=K19,K19,K20)))))))))))))))))),6,0) -> 46233.083 | H9: =_xlfn.IFNA(MATCH(G9,$E$3:$E$21,0),0) -> 5 | J9: =IF(K9="请更新日历","请更新代码",TEXT(K9,"YYMM")&"E") -> 2608E | K9: =IF(COUNTIF(A:A,M9)=0,N9,VLOOKUP(M9,A:B,2,0)) -> 46235.083 | M9: =TEXT(N9,"YYMM")&"E" -> 2608E | N9: =DATE(YEAR(TODAY()), 8, 1) + TIME(2, 0, 0) -> 46235.083
A10: =IF(B10="请更新日历","请更新代码",TEXT(B10,"YYMM")&"E") -> 2507E | B10: 45869.083 | D10: =OFFSET(IF(美联储议息会议日历!L1<=B2,B2,IF(美联储议息会议日历!L1<=B3,B3,IF(美联储议息会议日历!L1<=B4,B4,IF(美联储议息会议日历!L1<=B5,B5,IF(美联储议息会议日历!L1<=B6,B6,IF(美联储议息会议日历!L1<=B7,B7,IF(美联储议息会议日历!L1<=B8,B8,IF(美联储议息会议日历!L1<=B9,B9,IF(美联储议息会议日历!L1<=B10,B10,IF(美联储议息会议日历!L1<=B11,B11,IF(美联储议息会议日历!L1<=B12,B12,IF(美联储议息会议日历!L1<=B13,B13,B14)))))))))))),7,-1) -> 2612E | E10: =OFFSET(IF(美联储议息会议日历!L1<B2,B2,IF(美联储议息会议日历!L1<B3,B3,IF(美联储议息会议日历!L1<B4,B4,IF(美联储议息会议日历!L1<B5,B5,IF(美联储议息会议日历!L1<B6,B6,IF(美联储议息会议日历!L1<B7,B7,IF(美联储议息会议日历!L1<B8,B8,IF(美联储议息会议日历!L1<B9,B9,IF(美联储议息会议日历!L1<B10,B10,IF(美联储议息会议日历!L1<B11,B11,IF(美联储议息会议日历!L1<B12,B12,IF(美联储议息会议日历!L1<B13,B13,B14)))))))))))),7,0) -> 46366.083 | G10: =OFFSET(IF(美联储议息会议日历!L1<=K2,K2,IF(美联储议息会议日历!L1<=K3,K3,IF(美联储议息会议日历!L1<=K4,K4,IF(美联储议息会议日历!L1<=K5,K5,IF(美联储议息会议日历!L1<=K6,K6,IF(美联储议息会议日历!L1<=K7,K7,IF(美联储议息会议日历!L1<=K8,K8,IF(美联储议息会议日历!L1<=K9,K9,IF(美联储议息会议日历!L1<=K10,K10,IF(美联储议息会议日历!L1<=K11,K11,IF(美联储议息会议日历!L1<=K12,K12,IF(美联储议息会议日历!L1<=K13,K13,IF(美联储议息会议日历!L1<=K14,K14,IF(美联储议息会议日历!L1<=K15,K15,IF(美联储议息会议日历!L1<=K16,K16,IF(美联储议息会议日历!L1<=K17,K17,IF(美联储议息会议日历!L1<=K18,K18,IF(美联储议息会议日历!L1<=K19,K19,K20)))))))))))))))))),7,0) -> 46235.083 | H10: =_xlfn.IFNA(MATCH(G10,$E$3:$E$21,0),0) -> 0 | J10: =IF(K10="请更新日历","请更新代码",TEXT(K10,"YYMM")&"E") -> 2609E | K10: =IF(COUNTIF(A:A,M10)=0,N10,VLOOKUP(M10,A:B,2,0)) -> 46282.083 | M10: =TEXT(N10,"YYMM")&"E" -> 2609E | N10: =DATE(YEAR(TODAY()), 9, 1) + TIME(2, 0, 0) -> 46266.083
A11: =IF(B11="请更新日历","请更新代码",TEXT(B11,"YYMM")&"E") -> 2509E | B11: 45918.083 | D11: =OFFSET(IF(美联储议息会议日历!L1<=B2,B2,IF(美联储议息会议日历!L1<=B3,B3,IF(美联储议息会议日历!L1<=B4,B4,IF(美联储议息会议日历!L1<=B5,B5,IF(美联储议息会议日历!L1<=B6,B6,IF(美联储议息会议日历!L1<=B7,B7,IF(美联储议息会议日历!L1<=B8,B8,IF(美联储议息会议日历!L1<=B9,B9,IF(美联储议息会议日历!L1<=B10,B10,IF(美联储议息会议日历!L1<=B11,B11,IF(美联储议息会议日历!L1<=B12,B12,IF(美联储议息会议日历!L1<=B13,B13,B14)))))))))))),8,-1) -> 请更新代码 | E11: =OFFSET(IF(美联储议息会议日历!L1<B2,B2,IF(美联储议息会议日历!L1<B3,B3,IF(美联储议息会议日历!L1<B4,B4,IF(美联储议息会议日历!L1<B5,B5,IF(美联储议息会议日历!L1<B6,B6,IF(美联储议息会议日历!L1<B7,B7,IF(美联储议息会议日历!L1<B8,B8,IF(美联储议息会议日历!L1<B9,B9,IF(美联储议息会议日历!L1<B10,B10,IF(美联储议息会议日历!L1<B11,B11,IF(美联储议息会议日历!L1<B12,B12,IF(美联储议息会议日历!L1<B13,B13,B14)))))))))))),8,0) -> 请更新日历 | G11: =OFFSET(IF(美联储议息会议日历!L1<=K2,K2,IF(美联储议息会议日历!L1<=K3,K3,IF(美联储议息会议日历!L1<=K4,K4,IF(美联储议息会议日历!L1<=K5,K5,IF(美联储议息会议日历!L1<=K6,K6,IF(美联储议息会议日历!L1<=K7,K7,IF(美联储议息会议日历!L1<=K8,K8,IF(美联储议息会议日历!L1<=K9,K9,IF(美联储议息会议日历!L1<=K10,K10,IF(美联储议息会议日历!L1<=K11,K11,IF(美联储议息会议日历!L1<=K12,K12,IF(美联储议息会议日历!L1<=K13,K13,IF(美联储议息会议日历!L1<=K14,K14,IF(美联储议息会议日历!L1<=K15,K15,IF(美联储议息会议日历!L1<=K16,K16,IF(美联储议息会议日历!L1<=K17,K17,IF(美联储议息会议日历!L1<=K18,K18,IF(美联储议息会议日历!L1<=K19,K19,K20)))))))))))))))))),8,0) -> 46282.083 | H11: =_xlfn.IFNA(MATCH(G11,$E$3:$E$21,0),0) -> 6 | J11: =IF(K11="请更新日历","请更新代码",TEXT(K11,"YYMM")&"E") -> 2610E | K11: =IF(COUNTIF(A:A,M11)=0,N11,VLOOKUP(M11,A:B,2,0)) -> 46324.083 | M11: =TEXT(N11,"YYMM")&"E" -> 2610E | N11: =DATE(YEAR(TODAY()), 10, 1) + TIME(2, 0, 0) -> 46296.083
A12: =IF(B12="请更新日历","请更新代码",TEXT(B12,"YYMM")&"E") -> 2510E | B12: 45960.083 | D12: =OFFSET(IF(美联储议息会议日历!L1<=B2,B2,IF(美联储议息会议日历!L1<=B3,B3,IF(美联储议息会议日历!L1<=B4,B4,IF(美联储议息会议日历!L1<=B5,B5,IF(美联储议息会议日历!L1<=B6,B6,IF(美联储议息会议日历!L1<=B7,B7,IF(美联储议息会议日历!L1<=B8,B8,IF(美联储议息会议日历!L1<=B9,B9,IF(美联储议息会议日历!L1<=B10,B10,IF(美联储议息会议日历!L1<=B11,B11,IF(美联储议息会议日历!L1<=B12,B12,IF(美联储议息会议日历!L1<=B13,B13,B14)))))))))))),9,-1) -> 请更新代码 | E12: =OFFSET(IF(美联储议息会议日历!L1<B2,B2,IF(美联储议息会议日历!L1<B3,B3,IF(美联储议息会议日历!L1<B4,B4,IF(美联储议息会议日历!L1<B5,B5,IF(美联储议息会议日历!L1<B6,B6,IF(美联储议息会议日历!L1<B7,B7,IF(美联储议息会议日历!L1<B8,B8,IF(美联储议息会议日历!L1<B9,B9,IF(美联储议息会议日历!L1<B10,B10,IF(美联储议息会议日历!L1<B11,B11,IF(美联储议息会议日历!L1<B12,B12,IF(美联储议息会议日历!L1<B13,B13,B14)))))))))))),9,0) -> 请更新日历 | G12: =OFFSET(IF(美联储议息会议日历!L1<=K2,K2,IF(美联储议息会议日历!L1<=K3,K3,IF(美联储议息会议日历!L1<=K4,K4,IF(美联储议息会议日历!L1<=K5,K5,IF(美联储议息会议日历!L1<=K6,K6,IF(美联储议息会议日历!L1<=K7,K7,IF(美联储议息会议日历!L1<=K8,K8,IF(美联储议息会议日历!L1<=K9,K9,IF(美联储议息会议日历!L1<=K10,K10,IF(美联储议息会议日历!L1<=K11,K11,IF(美联储议息会议日历!L1<=K12,K12,IF(美联储议息会议日历!L1<=K13,K13,IF(美联储议息会议日历!L1<=K14,K14,IF(美联储议息会议日历!L1<=K15,K15,IF(美联储议息会议日历!L1<=K16,K16,IF(美联储议息会议日历!L1<=K17,K17,IF(美联储议息会议日历!L1<=K18,K18,IF(美联储议息会议日历!L1<=K19,K19,K20)))))))))))))))))),9,0) -> 46324.083 | H12: =_xlfn.IFNA(MATCH(G12,$E$3:$E$21,0),0) -> 7 | J12: =IF(K12="请更新日历","请更新代码",TEXT(K12,"YYMM")&"E") -> 2611E | K12: =IF(COUNTIF(A:A,M12)=0,N12,VLOOKUP(M12,A:B,2,0)) -> 46327.083 | M12: =TEXT(N12,"YYMM")&"E" -> 2611E | N12: =DATE(YEAR(TODAY()), 11, 1) + TIME(2, 0, 0) -> 46327.083
A13: =IF(B13="请更新日历","请更新代码",TEXT(B13,"YYMM")&"E") -> 2512E | B13: 46002.083 | D13: =OFFSET(IF(美联储议息会议日历!L1<=B2,B2,IF(美联储议息会议日历!L1<=B3,B3,IF(美联储议息会议日历!L1<=B4,B4,IF(美联储议息会议日历!L1<=B5,B5,IF(美联储议息会议日历!L1<=B6,B6,IF(美联储议息会议日历!L1<=B7,B7,IF(美联储议息会议日历!L1<=B8,B8,IF(美联储议息会议日历!L1<=B9,B9,IF(美联储议息会议日历!L1<=B10,B10,IF(美联储议息会议日历!L1<=B11,B11,IF(美联储议息会议日历!L1<=B12,B12,IF(美联储议息会议日历!L1<=B13,B13,B14)))))))))))),10,-1) -> 请更新代码 | E13: =OFFSET(IF(美联储议息会议日历!L1<B2,B2,IF(美联储议息会议日历!L1<B3,B3,IF(美联储议息会议日历!L1<B4,B4,IF(美联储议息会议日历!L1<B5,B5,IF(美联储议息会议日历!L1<B6,B6,IF(美联储议息会议日历!L1<B7,B7,IF(美联储议息会议日历!L1<B8,B8,IF(美联储议息会议日历!L1<B9,B9,IF(美联储议息会议日历!L1<B10,B10,IF(美联储议息会议日历!L1<B11,B11,IF(美联储议息会议日历!L1<B12,B12,IF(美联储议息会议日历!L1<B13,B13,B14)))))))))))),10,0) -> 请更新日历 | G13: =OFFSET(IF(美联储议息会议日历!L1<=K2,K2,IF(美联储议息会议日历!L1<=K3,K3,IF(美联储议息会议日历!L1<=K4,K4,IF(美联储议息会议日历!L1<=K5,K5,IF(美联储议息会议日历!L1<=K6,K6,IF(美联储议息会议日历!L1<=K7,K7,IF(美联储议息会议日历!L1<=K8,K8,IF(美联储议息会议日历!L1<=K9,K9,IF(美联储议息会议日历!L1<=K10,K10,IF(美联储议息会议日历!L1<=K11,K11,IF(美联储议息会议日历!L1<=K12,K12,IF(美联储议息会议日历!L1<=K13,K13,IF(美联储议息会议日历!L1<=K14,K14,IF(美联储议息会议日历!L1<=K15,K15,IF(美联储议息会议日历!L1<=K16,K16,IF(美联储议息会议日历!L1<=K17,K17,IF(美联储议息会议日历!L1<=K18,K18,IF(美联储议息会议日历!L1<=K19,K19,K20)))))))))))))))))),10,0) -> 46327.083 | H13: =_xlfn.IFNA(MATCH(G13,$E$3:$E$21,0),0) -> 0 | J13: =IF(K13="请更新日历","请更新代码",TEXT(K13,"YYMM")&"E") -> 2612E | K13: =IF(COUNTIF(A:A,M13)=0,N13,VLOOKUP(M13,A:B,2,0)) -> 46366.083 | M13: =TEXT(N13,"YYMM")&"E" -> 2612E | N13: =DATE(YEAR(TODAY()), 12, 1) + TIME(2, 0, 0) -> 46357.083
A14: =IF(B14="请更新日历","请更新代码",TEXT(B14,"YYMM")&"E") -> 2601E | B14: 46051.083 | D14: =OFFSET(IF(美联储议息会议日历!L1<=B2,B2,IF(美联储议息会议日历!L1<=B3,B3,IF(美联储议息会议日历!L1<=B4,B4,IF(美联储议息会议日历!L1<=B5,B5,IF(美联储议息会议日历!L1<=B6,B6,IF(美联储议息会议日历!L1<=B7,B7,IF(美联储议息会议日历!L1<=B8,B8,IF(美联储议息会议日历!L1<=B9,B9,IF(美联储议息会议日历!L1<=B10,B10,IF(美联储议息会议日历!L1<=B11,B11,IF(美联储议息会议日历!L1<=B12,B12,IF(美联储议息会议日历!L1<=B13,B13,B14)))))))))))),11,-1) -> 请更新代码 | E14: =OFFSET(IF(美联储议息会议日历!L1<B2,B2,IF(美联储议息会议日历!L1<B3,B3,IF(美联储议息会议日历!L1<B4,B4,IF(美联储议息会议日历!L1<B5,B5,IF(美联储议息会议日历!L1<B6,B6,IF(美联储议息会议日历!L1<B7,B7,IF(美联储议息会议日历!L1<B8,B8,IF(美联储议息会议日历!L1<B9,B9,IF(美联储议息会议日历!L1<B10,B10,IF(美联储议息会议日历!L1<B11,B11,IF(美联储议息会议日历!L1<B12,B12,IF(美联储议息会议日历!L1<B13,B13,B14)))))))))))),11,0) -> 请更新日历 | G14: =OFFSET(IF(美联储议息会议日历!L1<=K2,K2,IF(美联储议息会议日历!L1<=K3,K3,IF(美联储议息会议日历!L1<=K4,K4,IF(美联储议息会议日历!L1<=K5,K5,IF(美联储议息会议日历!L1<=K6,K6,IF(美联储议息会议日历!L1<=K7,K7,IF(美联储议息会议日历!L1<=K8,K8,IF(美联储议息会议日历!L1<=K9,K9,IF(美联储议息会议日历!L1<=K10,K10,IF(美联储议息会议日历!L1<=K11,K11,IF(美联储议息会议日历!L1<=K12,K12,IF(美联储议息会议日历!L1<=K13,K13,IF(美联储议息会议日历!L1<=K14,K14,IF(美联储议息会议日历!L1<=K15,K15,IF(美联储议息会议日历!L1<=K16,K16,IF(美联储议息会议日历!L1<=K17,K17,IF(美联储议息会议日历!L1<=K18,K18,IF(美联储议息会议日历!L1<=K19,K19,K20)))))))))))))))))),11,0) -> 46366.083 | H14: =_xlfn.IFNA(MATCH(G14,$E$3:$E$21,0),0) -> 8 | J14: =IF(K14="请更新日历","请更新代码",TEXT(K14,"YYMM")&"E") -> 2701E | K14: =IF(COUNTIF(A:A,M14)=0,N14,VLOOKUP(M14,A:B,2,0)) -> 46388.083 | M14: =TEXT(N14,"YYMM")&"E" -> 2701E | N14: =DATE(YEAR(TODAY())+1, 1, 1) + TIME(2, 0, 0) -> 46388.083
A15: =IF(B15="请更新日历","请更新代码",TEXT(B15,"YYMM")&"E") -> 2603E | B15: 46100.083 | D15: =OFFSET(IF(美联储议息会议日历!L1<=B2,B2,IF(美联储议息会议日历!L1<=B3,B3,IF(美联储议息会议日历!L1<=B4,B4,IF(美联储议息会议日历!L1<=B5,B5,IF(美联储议息会议日历!L1<=B6,B6,IF(美联储议息会议日历!L1<=B7,B7,IF(美联储议息会议日历!L1<=B8,B8,IF(美联储议息会议日历!L1<=B9,B9,IF(美联储议息会议日历!L1<=B10,B10,IF(美联储议息会议日历!L1<=B11,B11,IF(美联储议息会议日历!L1<=B12,B12,IF(美联储议息会议日历!L1<=B13,B13,B14)))))))))))),12,-1) -> 请更新代码 | E15: =OFFSET(IF(美联储议息会议日历!L1<B2,B2,IF(美联储议息会议日历!L1<B3,B3,IF(美联储议息会议日历!L1<B4,B4,IF(美联储议息会议日历!L1<B5,B5,IF(美联储议息会议日历!L1<B6,B6,IF(美联储议息会议日历!L1<B7,B7,IF(美联储议息会议日历!L1<B8,B8,IF(美联储议息会议日历!L1<B9,B9,IF(美联储议息会议日历!L1<B10,B10,IF(美联储议息会议日历!L1<B11,B11,IF(美联储议息会议日历!L1<B12,B12,IF(美联储议息会议日历!L1<B13,B13,B14)))))))))))),12,0) -> 请更新日历 | G15: =OFFSET(IF(美联储议息会议日历!L1<=K2,K2,IF(美联储议息会议日历!L1<=K3,K3,IF(美联储议息会议日历!L1<=K4,K4,IF(美联储议息会议日历!L1<=K5,K5,IF(美联储议息会议日历!L1<=K6,K6,IF(美联储议息会议日历!L1<=K7,K7,IF(美联储议息会议日历!L1<=K8,K8,IF(美联储议息会议日历!L1<=K9,K9,IF(美联储议息会议日历!L1<=K10,K10,IF(美联储议息会议日历!L1<=K11,K11,IF(美联储议息会议日历!L1<=K12,K12,IF(美联储议息会议日历!L1<=K13,K13,IF(美联储议息会议日历!L1<=K14,K14,IF(美联储议息会议日历!L1<=K15,K15,IF(美联储议息会议日历!L1<=K16,K16,IF(美联储议息会议日历!L1<=K17,K17,IF(美联储议息会议日历!L1<=K18,K18,IF(美联储议息会议日历!L1<=K19,K19,K20)))))))))))))))))),12,0) -> 46388.083 | H15: =_xlfn.IFNA(MATCH(G15,$E$3:$E$21,0),0) -> 0 | J15: =IF(K15="请更新日历","请更新代码",TEXT(K15,"YYMM")&"E") -> 2702E | K15: =IF(COUNTIF(A:A,M15)=0,N15,VLOOKUP(M15,A:B,2,0)) -> 46419.083 | M15: =TEXT(N15,"YYMM")&"E" -> 2702E | N15: =DATE(YEAR(TODAY())+1, 2, 1) + TIME(2, 0, 0) -> 46419.083
A16: =IF(B16="请更新日历","请更新代码",TEXT(B16,"YYMM")&"E") -> 2604E | B16: 46142.083 | D16: =OFFSET(IF(美联储议息会议日历!L1<=B2,B2,IF(美联储议息会议日历!L1<=B3,B3,IF(美联储议息会议日历!L1<=B4,B4,IF(美联储议息会议日历!L1<=B5,B5,IF(美联储议息会议日历!L1<=B6,B6,IF(美联储议息会议日历!L1<=B7,B7,IF(美联储议息会议日历!L1<=B8,B8,IF(美联储议息会议日历!L1<=B9,B9,IF(美联储议息会议日历!L1<=B10,B10,IF(美联储议息会议日历!L1<=B11,B11,IF(美联储议息会议日历!L1<=B12,B12,IF(美联储议息会议日历!L1<=B13,B13,B14)))))))))))),13,-1) -> 请更新代码 | E16: =OFFSET(IF(美联储议息会议日历!L1<B2,B2,IF(美联储议息会议日历!L1<B3,B3,IF(美联储议息会议日历!L1<B4,B4,IF(美联储议息会议日历!L1<B5,B5,IF(美联储议息会议日历!L1<B6,B6,IF(美联储议息会议日历!L1<B7,B7,IF(美联储议息会议日历!L1<B8,B8,IF(美联储议息会议日历!L1<B9,B9,IF(美联储议息会议日历!L1<B10,B10,IF(美联储议息会议日历!L1<B11,B11,IF(美联储议息会议日历!L1<B12,B12,IF(美联储议息会议日历!L1<B13,B13,B14)))))))))))),13,0) -> 请更新日历 | G16: =OFFSET(IF(美联储议息会议日历!L1<=K2,K2,IF(美联储议息会议日历!L1<=K3,K3,IF(美联储议息会议日历!L1<=K4,K4,IF(美联储议息会议日历!L1<=K5,K5,IF(美联储议息会议日历!L1<=K6,K6,IF(美联储议息会议日历!L1<=K7,K7,IF(美联储议息会议日历!L1<=K8,K8,IF(美联储议息会议日历!L1<=K9,K9,IF(美联储议息会议日历!L1<=K10,K10,IF(美联储议息会议日历!L1<=K11,K11,IF(美联储议息会议日历!L1<=K12,K12,IF(美联储议息会议日历!L1<=K13,K13,IF(美联储议息会议日历!L1<=K14,K14,IF(美联储议息会议日历!L1<=K15,K15,IF(美联储议息会议日历!L1<=K16,K16,IF(美联储议息会议日历!L1<=K17,K17,IF(美联储议息会议日历!L1<=K18,K18,IF(美联储议息会议日历!L1<=K19,K19,K20)))))))))))))))))),13,0) -> 46419.083 | H16: =_xlfn.IFNA(MATCH(G16,$E$3:$E$21,0),0) -> 0 | J16: =IF(K16="请更新日历","请更新代码",TEXT(K16,"YYMM")&"E") -> 2703E | K16: =IF(COUNTIF(A:A,M16)=0,N16,VLOOKUP(M16,A:B,2,0)) -> 46447.083 | M16: =TEXT(N16,"YYMM")&"E" -> 2703E | N16: =DATE(YEAR(TODAY())+1, 3, 1) + TIME(2, 0, 0) -> 46447.083
A17: =IF(B17="请更新日历","请更新代码",TEXT(B17,"YYMM")&"E") -> 2606E | B17: 46191.083 | D17: =OFFSET(IF(美联储议息会议日历!L1<=B2,B2,IF(美联储议息会议日历!L1<=B3,B3,IF(美联储议息会议日历!L1<=B4,B4,IF(美联储议息会议日历!L1<=B5,B5,IF(美联储议息会议日历!L1<=B6,B6,IF(美联储议息会议日历!L1<=B7,B7,IF(美联储议息会议日历!L1<=B8,B8,IF(美联储议息会议日历!L1<=B9,B9,IF(美联储议息会议日历!L1<=B10,B10,IF(美联储议息会议日历!L1<=B11,B11,IF(美联储议息会议日历!L1<=B12,B12,IF(美联储议息会议日历!L1<=B13,B13,B14)))))))))))),14,-1) -> 请更新代码 | E17: =OFFSET(IF(美联储议息会议日历!L1<B2,B2,IF(美联储议息会议日历!L1<B3,B3,IF(美联储议息会议日历!L1<B4,B4,IF(美联储议息会议日历!L1<B5,B5,IF(美联储议息会议日历!L1<B6,B6,IF(美联储议息会议日历!L1<B7,B7,IF(美联储议息会议日历!L1<B8,B8,IF(美联储议息会议日历!L1<B9,B9,IF(美联储议息会议日历!L1<B10,B10,IF(美联储议息会议日历!L1<B11,B11,IF(美联储议息会议日历!L1<B12,B12,IF(美联储议息会议日历!L1<B13,B13,B14)))))))))))),14,0) -> 请更新日历 | G17: =OFFSET(IF(美联储议息会议日历!L1<=K2,K2,IF(美联储议息会议日历!L1<=K3,K3,IF(美联储议息会议日历!L1<=K4,K4,IF(美联储议息会议日历!L1<=K5,K5,IF(美联储议息会议日历!L1<=K6,K6,IF(美联储议息会议日历!L1<=K7,K7,IF(美联储议息会议日历!L1<=K8,K8,IF(美联储议息会议日历!L1<=K9,K9,IF(美联储议息会议日历!L1<=K10,K10,IF(美联储议息会议日历!L1<=K11,K11,IF(美联储议息会议日历!L1<=K12,K12,IF(美联储议息会议日历!L1<=K13,K13,IF(美联储议息会议日历!L1<=K14,K14,IF(美联储议息会议日历!L1<=K15,K15,IF(美联储议息会议日历!L1<=K16,K16,IF(美联储议息会议日历!L1<=K17,K17,IF(美联储议息会议日历!L1<=K18,K18,IF(美联储议息会议日历!L1<=K19,K19,K20)))))))))))))))))),14,0) -> 46447.083 | H17: =_xlfn.IFNA(MATCH(G17,$E$3:$E$21,0),0) -> 0 | J17: =IF(K17="请更新日历","请更新代码",TEXT(K17,"YYMM")&"E") -> 2704E | K17: =IF(COUNTIF(A:A,M17)=0,N17,VLOOKUP(M17,A:B,2,0)) -> 46478.083 | M17: =TEXT(N17,"YYMM")&"E" -> 2704E | N17: =DATE(YEAR(TODAY())+1, 4, 1) + TIME(2, 0, 0) -> 46478.083
A18: =IF(B18="请更新日历","请更新代码",TEXT(B18,"YYMM")&"E") -> 2607E | B18: 46233.083 | D18: =OFFSET(IF(美联储议息会议日历!L1<=B2,B2,IF(美联储议息会议日历!L1<=B3,B3,IF(美联储议息会议日历!L1<=B4,B4,IF(美联储议息会议日历!L1<=B5,B5,IF(美联储议息会议日历!L1<=B6,B6,IF(美联储议息会议日历!L1<=B7,B7,IF(美联储议息会议日历!L1<=B8,B8,IF(美联储议息会议日历!L1<=B9,B9,IF(美联储议息会议日历!L1<=B10,B10,IF(美联储议息会议日历!L1<=B11,B11,IF(美联储议息会议日历!L1<=B12,B12,IF(美联储议息会议日历!L1<=B13,B13,B14)))))))))))),15,-1) -> 请更新代码 | E18: =OFFSET(IF(美联储议息会议日历!L1<B2,B2,IF(美联储议息会议日历!L1<B3,B3,IF(美联储议息会议日历!L1<B4,B4,IF(美联储议息会议日历!L1<B5,B5,IF(美联储议息会议日历!L1<B6,B6,IF(美联储议息会议日历!L1<B7,B7,IF(美联储议息会议日历!L1<B8,B8,IF(美联储议息会议日历!L1<B9,B9,IF(美联储议息会议日历!L1<B10,B10,IF(美联储议息会议日历!L1<B11,B11,IF(美联储议息会议日历!L1<B12,B12,IF(美联储议息会议日历!L1<B13,B13,B14)))))))))))),15,0) -> 请更新日历 | G18: =OFFSET(IF(美联储议息会议日历!L1<=K2,K2,IF(美联储议息会议日历!L1<=K3,K3,IF(美联储议息会议日历!L1<=K4,K4,IF(美联储议息会议日历!L1<=K5,K5,IF(美联储议息会议日历!L1<=K6,K6,IF(美联储议息会议日历!L1<=K7,K7,IF(美联储议息会议日历!L1<=K8,K8,IF(美联储议息会议日历!L1<=K9,K9,IF(美联储议息会议日历!L1<=K10,K10,IF(美联储议息会议日历!L1<=K11,K11,IF(美联储议息会议日历!L1<=K12,K12,IF(美联储议息会议日历!L1<=K13,K13,IF(美联储议息会议日历!L1<=K14,K14,IF(美联储议息会议日历!L1<=K15,K15,IF(美联储议息会议日历!L1<=K16,K16,IF(美联储议息会议日历!L1<=K17,K17,IF(美联储议息会议日历!L1<=K18,K18,IF(美联储议息会议日历!L1<=K19,K19,K20)))))))))))))))))),15,0) -> 46478.083 | H18: =_xlfn.IFNA(MATCH(G18,$E$3:$E$21,0),0) -> 0 | J18: =IF(K18="请更新日历","请更新代码",TEXT(K18,"YYMM")&"E") -> 2705E | K18: =IF(COUNTIF(A:A,M18)=0,N18,VLOOKUP(M18,A:B,2,0)) -> 46508.083 | M18: =TEXT(N18,"YYMM")&"E" -> 2705E | N18: =DATE(YEAR(TODAY())+1, 5, 1) + TIME(2, 0, 0) -> 46508.083
A19: =IF(B19="请更新日历","请更新代码",TEXT(B19,"YYMM")&"E") -> 2609E | B19: 46282.083 | D19: =OFFSET(IF(美联储议息会议日历!L1<=B2,B2,IF(美联储议息会议日历!L1<=B3,B3,IF(美联储议息会议日历!L1<=B4,B4,IF(美联储议息会议日历!L1<=B5,B5,IF(美联储议息会议日历!L1<=B6,B6,IF(美联储议息会议日历!L1<=B7,B7,IF(美联储议息会议日历!L1<=B8,B8,IF(美联储议息会议日历!L1<=B9,B9,IF(美联储议息会议日历!L1<=B10,B10,IF(美联储议息会议日历!L1<=B11,B11,IF(美联储议息会议日历!L1<=B12,B12,IF(美联储议息会议日历!L1<=B13,B13,B14)))))))))))),16,-1) -> 请更新代码 | E19: =OFFSET(IF(美联储议息会议日历!L1<B2,B2,IF(美联储议息会议日历!L1<B3,B3,IF(美联储议息会议日历!L1<B4,B4,IF(美联储议息会议日历!L1<B5,B5,IF(美联储议息会议日历!L1<B6,B6,IF(美联储议息会议日历!L1<B7,B7,IF(美联储议息会议日历!L1<B8,B8,IF(美联储议息会议日历!L1<B9,B9,IF(美联储议息会议日历!L1<B10,B10,IF(美联储议息会议日历!L1<B11,B11,IF(美联储议息会议日历!L1<B12,B12,IF(美联储议息会议日历!L1<B13,B13,B14)))))))))))),16,0) -> 请更新日历 | G19: =OFFSET(IF(美联储议息会议日历!L1<=K2,K2,IF(美联储议息会议日历!L1<=K3,K3,IF(美联储议息会议日历!L1<=K4,K4,IF(美联储议息会议日历!L1<=K5,K5,IF(美联储议息会议日历!L1<=K6,K6,IF(美联储议息会议日历!L1<=K7,K7,IF(美联储议息会议日历!L1<=K8,K8,IF(美联储议息会议日历!L1<=K9,K9,IF(美联储议息会议日历!L1<=K10,K10,IF(美联储议息会议日历!L1<=K11,K11,IF(美联储议息会议日历!L1<=K12,K12,IF(美联储议息会议日历!L1<=K13,K13,IF(美联储议息会议日历!L1<=K14,K14,IF(美联储议息会议日历!L1<=K15,K15,IF(美联储议息会议日历!L1<=K16,K16,IF(美联储议息会议日历!L1<=K17,K17,IF(美联储议息会议日历!L1<=K18,K18,IF(美联储议息会议日历!L1<=K19,K19,K20)))))))))))))))))),16,0) -> 46508.083 | H19: =_xlfn.IFNA(MATCH(G19,$E$3:$E$21,0),0) -> 0 | J19: =IF(K19="请更新日历","请更新代码",TEXT(K19,"YYMM")&"E") -> 2706E | K19: =IF(COUNTIF(A:A,M19)=0,N19,VLOOKUP(M19,A:B,2,0)) -> 46539.083 | M19: =TEXT(N19,"YYMM")&"E" -> 2706E | N19: =DATE(YEAR(TODAY())+1, 6, 1) + TIME(2, 0, 0) -> 46539.083
A20: =IF(B20="请更新日历","请更新代码",TEXT(B20,"YYMM")&"E") -> 2610E | B20: 46324.083 | D20: =OFFSET(IF(美联储议息会议日历!L1<=B2,B2,IF(美联储议息会议日历!L1<=B3,B3,IF(美联储议息会议日历!L1<=B4,B4,IF(美联储议息会议日历!L1<=B5,B5,IF(美联储议息会议日历!L1<=B6,B6,IF(美联储议息会议日历!L1<=B7,B7,IF(美联储议息会议日历!L1<=B8,B8,IF(美联储议息会议日历!L1<=B9,B9,IF(美联储议息会议日历!L1<=B10,B10,IF(美联储议息会议日历!L1<=B11,B11,IF(美联储议息会议日历!L1<=B12,B12,IF(美联储议息会议日历!L1<=B13,B13,B14)))))))))))),17,-1) -> 请更新代码 | E20: =OFFSET(IF(美联储议息会议日历!L1<B2,B2,IF(美联储议息会议日历!L1<B3,B3,IF(美联储议息会议日历!L1<B4,B4,IF(美联储议息会议日历!L1<B5,B5,IF(美联储议息会议日历!L1<B6,B6,IF(美联储议息会议日历!L1<B7,B7,IF(美联储议息会议日历!L1<B8,B8,IF(美联储议息会议日历!L1<B9,B9,IF(美联储议息会议日历!L1<B10,B10,IF(美联储议息会议日历!L1<B11,B11,IF(美联储议息会议日历!L1<B12,B12,IF(美联储议息会议日历!L1<B13,B13,B14)))))))))))),17,0) -> 请更新日历 | G20: =OFFSET(IF(美联储议息会议日历!L1<=K2,K2,IF(美联储议息会议日历!L1<=K3,K3,IF(美联储议息会议日历!L1<=K4,K4,IF(美联储议息会议日历!L1<=K5,K5,IF(美联储议息会议日历!L1<=K6,K6,IF(美联储议息会议日历!L1<=K7,K7,IF(美联储议息会议日历!L1<=K8,K8,IF(美联储议息会议日历!L1<=K9,K9,IF(美联储议息会议日历!L1<=K10,K10,IF(美联储议息会议日历!L1<=K11,K11,IF(美联储议息会议日历!L1<=K12,K12,IF(美联储议息会议日历!L1<=K13,K13,IF(美联储议息会议日历!L1<=K14,K14,IF(美联储议息会议日历!L1<=K15,K15,IF(美联储议息会议日历!L1<=K16,K16,IF(美联储议息会议日历!L1<=K17,K17,IF(美联储议息会议日历!L1<=K18,K18,IF(美联储议息会议日历!L1<=K19,K19,K20)))))))))))))))))),17,0) -> 46539.083 | H20: =_xlfn.IFNA(MATCH(G20,$E$3:$E$21,0),0) -> 0 | J20: =IF(K20="请更新日历","请更新代码",TEXT(K20,"YYMM")&"E") -> 2707E | K20: =IF(COUNTIF(A:A,M20)=0,N20,VLOOKUP(M20,A:B,2,0)) -> 46569.083 | M20: =TEXT(N20,"YYMM")&"E" -> 2707E | N20: =DATE(YEAR(TODAY())+1, 7, 1) + TIME(2, 0, 0) -> 46569.083
A21: =IF(B21="请更新日历","请更新代码",TEXT(B21,"YYMM")&"E") -> 2612E | B21: 46366.083 | D21: =OFFSET(IF(美联储议息会议日历!L1<=B2,B2,IF(美联储议息会议日历!L1<=B3,B3,IF(美联储议息会议日历!L1<=B4,B4,IF(美联储议息会议日历!L1<=B5,B5,IF(美联储议息会议日历!L1<=B6,B6,IF(美联储议息会议日历!L1<=B7,B7,IF(美联储议息会议日历!L1<=B8,B8,IF(美联储议息会议日历!L1<=B9,B9,IF(美联储议息会议日历!L1<=B10,B10,IF(美联储议息会议日历!L1<=B11,B11,IF(美联储议息会议日历!L1<=B12,B12,IF(美联储议息会议日历!L1<=B13,B13,B14)))))))))))),18,-1) -> 请更新代码 | E21: =OFFSET(IF(美联储议息会议日历!L1<B2,B2,IF(美联储议息会议日历!L1<B3,B3,IF(美联储议息会议日历!L1<B4,B4,IF(美联储议息会议日历!L1<B5,B5,IF(美联储议息会议日历!L1<B6,B6,IF(美联储议息会议日历!L1<B7,B7,IF(美联储议息会议日历!L1<B8,B8,IF(美联储议息会议日历!L1<B9,B9,IF(美联储议息会议日历!L1<B10,B10,IF(美联储议息会议日历!L1<B11,B11,IF(美联储议息会议日历!L1<B12,B12,IF(美联储议息会议日历!L1<B13,B13,B14)))))))))))),18,0) -> 请更新日历 | G21: =OFFSET(IF(美联储议息会议日历!L1<=K2,K2,IF(美联储议息会议日历!L1<=K3,K3,IF(美联储议息会议日历!L1<=K4,K4,IF(美联储议息会议日历!L1<=K5,K5,IF(美联储议息会议日历!L1<=K6,K6,IF(美联储议息会议日历!L1<=K7,K7,IF(美联储议息会议日历!L1<=K8,K8,IF(美联储议息会议日历!L1<=K9,K9,IF(美联储议息会议日历!L1<=K10,K10,IF(美联储议息会议日历!L1<=K11,K11,IF(美联储议息会议日历!L1<=K12,K12,IF(美联储议息会议日历!L1<=K13,K13,IF(美联储议息会议日历!L1<=K14,K14,IF(美联储议息会议日历!L1<=K15,K15,IF(美联储议息会议日历!L1<=K16,K16,IF(美联储议息会议日历!L1<=K17,K17,IF(美联储议息会议日历!L1<=K18,K18,IF(美联储议息会议日历!L1<=K19,K19,K20)))))))))))))))))),18,0) -> 46569.083 | H21: =_xlfn.IFNA(MATCH(G21,$E$3:$E$21,0),0) -> 0 | J21: =IF(K21="请更新日历","请更新代码",TEXT(K21,"YYMM")&"E") -> 2708E | K21: =IF(COUNTIF(A:A,M21)=0,N21,VLOOKUP(M21,A:B,2,0)) -> 46600.083 | M21: =TEXT(N21,"YYMM")&"E" -> 2708E | N21: =DATE(YEAR(TODAY())+1, 8, 1) + TIME(2, 0, 0) -> 46600.083
A22: =IF(B22="请更新日历","请更新代码",TEXT(B22,"YYMM")&"E") -> 请更新代码 | B22: 请更新日历 | D22: =OFFSET(IF(美联储议息会议日历!L1<=B2,B2,IF(美联储议息会议日历!L1<=B3,B3,IF(美联储议息会议日历!L1<=B4,B4,IF(美联储议息会议日历!L1<=B5,B5,IF(美联储议息会议日历!L1<=B6,B6,IF(美联储议息会议日历!L1<=B7,B7,IF(美联储议息会议日历!L1<=B8,B8,IF(美联储议息会议日历!L1<=B9,B9,IF(美联储议息会议日历!L1<=B10,B10,IF(美联储议息会议日历!L1<=B11,B11,IF(美联储议息会议日历!L1<=B12,B12,IF(美联储议息会议日历!L1<=B13,B13,B14)))))))))))),19,-1) -> 请更新代码 | E22: =OFFSET(IF(美联储议息会议日历!L1<B2,B2,IF(美联储议息会议日历!L1<B3,B3,IF(美联储议息会议日历!L1<B4,B4,IF(美联储议息会议日历!L1<B5,B5,IF(美联储议息会议日历!L1<B6,B6,IF(美联储议息会议日历!L1<B7,B7,IF(美联储议息会议日历!L1<B8,B8,IF(美联储议息会议日历!L1<B9,B9,IF(美联储议息会议日历!L1<B10,B10,IF(美联储议息会议日历!L1<B11,B11,IF(美联储议息会议日历!L1<B12,B12,IF(美联储议息会议日历!L1<B13,B13,B14)))))))))))),19,0) -> 请更新日历 | G22: =OFFSET(IF(美联储议息会议日历!L1<=K2,K2,IF(美联储议息会议日历!L1<=K3,K3,IF(美联储议息会议日历!L1<=K4,K4,IF(美联储议息会议日历!L1<=K5,K5,IF(美联储议息会议日历!L1<=K6,K6,IF(美联储议息会议日历!L1<=K7,K7,IF(美联储议息会议日历!L1<=K8,K8,IF(美联储议息会议日历!L1<=K9,K9,IF(美联储议息会议日历!L1<=K10,K10,IF(美联储议息会议日历!L1<=K11,K11,IF(美联储议息会议日历!L1<=K12,K12,IF(美联储议息会议日历!L1<=K13,K13,IF(美联储议息会议日历!L1<=K14,K14,IF(美联储议息会议日历!L1<=K15,K15,IF(美联储议息会议日历!L1<=K16,K16,IF(美联储议息会议日历!L1<=K17,K17,IF(美联储议息会议日历!L1<=K18,K18,IF(美联储议息会议日历!L1<=K19,K19,K20)))))))))))))))))),19,0) -> 46600.083 | H22: =_xlfn.IFNA(MATCH(G22,$E$3:$E$21,0),0) -> 0 | J22: =IF(K22="请更新日历","请更新代码",TEXT(K22,"YYMM")&"E") -> 2709E | K22: =IF(COUNTIF(A:A,M22)=0,N22,VLOOKUP(M22,A:B,2,0)) -> 46631.083 | M22: =TEXT(N22,"YYMM")&"E" -> 2709E | N22: =DATE(YEAR(TODAY())+1, 9, 1) + TIME(2, 0, 0) -> 46631.083
A23: =IF(B23="请更新日历","请更新代码",TEXT(B23,"YYMM")&"E") -> 请更新代码 | B23: 请更新日历 | D23: =OFFSET(IF(美联储议息会议日历!L1<=B2,B2,IF(美联储议息会议日历!L1<=B3,B3,IF(美联储议息会议日历!L1<=B4,B4,IF(美联储议息会议日历!L1<=B5,B5,IF(美联储议息会议日历!L1<=B6,B6,IF(美联储议息会议日历!L1<=B7,B7,IF(美联储议息会议日历!L1<=B8,B8,IF(美联储议息会议日历!L1<=B9,B9,IF(美联储议息会议日历!L1<=B10,B10,IF(美联储议息会议日历!L1<=B11,B11,IF(美联储议息会议日历!L1<=B12,B12,IF(美联储议息会议日历!L1<=B13,B13,B14)))))))))))),20,-1) -> 请更新代码 | E23: =OFFSET(IF(美联储议息会议日历!L1<B2,B2,IF(美联储议息会议日历!L1<B3,B3,IF(美联储议息会议日历!L1<B4,B4,IF(美联储议息会议日历!L1<B5,B5,IF(美联储议息会议日历!L1<B6,B6,IF(美联储议息会议日历!L1<B7,B7,IF(美联储议息会议日历!L1<B8,B8,IF(美联储议息会议日历!L1<B9,B9,IF(美联储议息会议日历!L1<B10,B10,IF(美联储议息会议日历!L1<B11,B11,IF(美联储议息会议日历!L1<B12,B12,IF(美联储议息会议日历!L1<B13,B13,B14)))))))))))),20,0) -> 请更新日历 | G23: =OFFSET(IF(美联储议息会议日历!L1<=K2,K2,IF(美联储议息会议日历!L1<=K3,K3,IF(美联储议息会议日历!L1<=K4,K4,IF(美联储议息会议日历!L1<=K5,K5,IF(美联储议息会议日历!L1<=K6,K6,IF(美联储议息会议日历!L1<=K7,K7,IF(美联储议息会议日历!L1<=K8,K8,IF(美联储议息会议日历!L1<=K9,K9,IF(美联储议息会议日历!L1<=K10,K10,IF(美联储议息会议日历!L1<=K11,K11,IF(美联储议息会议日历!L1<=K12,K12,IF(美联储议息会议日历!L1<=K13,K13,IF(美联储议息会议日历!L1<=K14,K14,IF(美联储议息会议日历!L1<=K15,K15,IF(美联储议息会议日历!L1<=K16,K16,IF(美联储议息会议日历!L1<=K17,K17,IF(美联储议息会议日历!L1<=K18,K18,IF(美联储议息会议日历!L1<=K19,K19,K20)))))))))))))))))),20,0) -> 46631.083 | H23: =_xlfn.IFNA(MATCH(G23,$E$3:$E$21,0),0) -> 0 | J23: =IF(K23="请更新日历","请更新代码",TEXT(K23,"YYMM")&"E") -> 2710E | K23: =IF(COUNTIF(A:A,M23)=0,N23,VLOOKUP(M23,A:B,2,0)) -> 46661.083 | M23: =TEXT(N23,"YYMM")&"E" -> 2710E | N23: =DATE(YEAR(TODAY())+1, 10, 1) + TIME(2, 0, 0) -> 46661.083
A24: =IF(B24="请更新日历","请更新代码",TEXT(B24,"YYMM")&"E") -> 请更新代码 | B24: 请更新日历 | G24: =OFFSET(IF(美联储议息会议日历!L1<=K2,K2,IF(美联储议息会议日历!L1<=K3,K3,IF(美联储议息会议日历!L1<=K4,K4,IF(美联储议息会议日历!L1<=K5,K5,IF(美联储议息会议日历!L1<=K6,K6,IF(美联储议息会议日历!L1<=K7,K7,IF(美联储议息会议日历!L1<=K8,K8,IF(美联储议息会议日历!L1<=K9,K9,IF(美联储议息会议日历!L1<=K10,K10,IF(美联储议息会议日历!L1<=K11,K11,IF(美联储议息会议日历!L1<=K12,K12,IF(美联储议息会议日历!L1<=K13,K13,IF(美联储议息会议日历!L1<=K14,K14,IF(美联储议息会议日历!L1<=K15,K15,IF(美联储议息会议日历!L1<=K16,K16,IF(美联储议息会议日历!L1<=K17,K17,IF(美联储议息会议日历!L1<=K18,K18,IF(美联储议息会议日历!L1<=K19,K19,K20)))))))))))))))))),21,0) -> 46661.083 | H24: =_xlfn.IFNA(MATCH(G24,$E$3:$E$21,0),0) -> 0 | J24: =IF(K24="请更新日历","请更新代码",TEXT(K24,"YYMM")&"E") -> 2711E | K24: =IF(COUNTIF(A:A,M24)=0,N24,VLOOKUP(M24,A:B,2,0)) -> 46692.083 | M24: =TEXT(N24,"YYMM")&"E" -> 2711E | N24: =DATE(YEAR(TODAY())+1, 11, 1) + TIME(2, 0, 0) -> 46692.083
A25: =IF(B25="请更新日历","请更新代码",TEXT(B25,"YYMM")&"E") -> 请更新代码 | B25: 请更新日历 | G25: =OFFSET(IF(美联储议息会议日历!L1<=K2,K2,IF(美联储议息会议日历!L1<=K3,K3,IF(美联储议息会议日历!L1<=K4,K4,IF(美联储议息会议日历!L1<=K5,K5,IF(美联储议息会议日历!L1<=K6,K6,IF(美联储议息会议日历!L1<=K7,K7,IF(美联储议息会议日历!L1<=K8,K8,IF(美联储议息会议日历!L1<=K9,K9,IF(美联储议息会议日历!L1<=K10,K10,IF(美联储议息会议日历!L1<=K11,K11,IF(美联储议息会议日历!L1<=K12,K12,IF(美联储议息会议日历!L1<=K13,K13,IF(美联储议息会议日历!L1<=K14,K14,IF(美联储议息会议日历!L1<=K15,K15,IF(美联储议息会议日历!L1<=K16,K16,IF(美联储议息会议日历!L1<=K17,K17,IF(美联储议息会议日历!L1<=K18,K18,IF(美联储议息会议日历!L1<=K19,K19,K20)))))))))))))))))),22,0) -> 46692.083 | H25: =_xlfn.IFNA(MATCH(G25,$E$3:$E$21,0),0) -> 0 | J25: =IF(K25="请更新日历","请更新代码",TEXT(K25,"YYMM")&"E") -> 2712E | K25: =IF(COUNTIF(A:A,M25)=0,N25,VLOOKUP(M25,A:B,2,0)) -> 46722.083 | M25: =TEXT(N25,"YYMM")&"E" -> 2712E | N25: =DATE(YEAR(TODAY())+1, 12, 1) + TIME(2, 0, 0) -> 46722.083
A26: =IF(B26="请更新日历","请更新代码",TEXT(B26,"YYMM")&"E") -> 请更新代码 | B26: 请更新日历 | G26: =OFFSET(IF(美联储议息会议日历!L1<=K2,K2,IF(美联储议息会议日历!L1<=K3,K3,IF(美联储议息会议日历!L1<=K4,K4,IF(美联储议息会议日历!L1<=K5,K5,IF(美联储议息会议日历!L1<=K6,K6,IF(美联储议息会议日历!L1<=K7,K7,IF(美联储议息会议日历!L1<=K8,K8,IF(美联储议息会议日历!L1<=K9,K9,IF(美联储议息会议日历!L1<=K10,K10,IF(美联储议息会议日历!L1<=K11,K11,IF(美联储议息会议日历!L1<=K12,K12,IF(美联储议息会议日历!L1<=K13,K13,IF(美联储议息会议日历!L1<=K14,K14,IF(美联储议息会议日历!L1<=K15,K15,IF(美联储议息会议日历!L1<=K16,K16,IF(美联储议息会议日历!L1<=K17,K17,IF(美联储议息会议日历!L1<=K18,K18,IF(美联储议息会议日历!L1<=K19,K19,K20)))))))))))))))))),23,0) -> 46722.083 | H26: =_xlfn.IFNA(MATCH(G26,$E$3:$E$21,0),0) -> 0 | J26: =IF(K26="请更新日历","请更新代码",TEXT(K26,"YYMM")&"E") -> 2801E | K26: =IF(COUNTIF(A:A,M26)=0,N26,VLOOKUP(M26,A:B,2,0)) -> 46753.083 | M26: =TEXT(N26,"YYMM")&"E" -> 2801E | N26: =DATE(YEAR(TODAY())+2, 1, 1) + TIME(2, 0, 0) -> 46753.083
A27: =IF(B27="请更新日历","请更新代码",TEXT(B27,"YYMM")&"E") -> 请更新代码 | B27: 请更新日历 | G27: =OFFSET(IF(美联储议息会议日历!L1<=K2,K2,IF(美联储议息会议日历!L1<=K3,K3,IF(美联储议息会议日历!L1<=K4,K4,IF(美联储议息会议日历!L1<=K5,K5,IF(美联储议息会议日历!L1<=K6,K6,IF(美联储议息会议日历!L1<=K7,K7,IF(美联储议息会议日历!L1<=K8,K8,IF(美联储议息会议日历!L1<=K9,K9,IF(美联储议息会议日历!L1<=K10,K10,IF(美联储议息会议日历!L1<=K11,K11,IF(美联储议息会议日历!L1<=K12,K12,IF(美联储议息会议日历!L1<=K13,K13,IF(美联储议息会议日历!L1<=K14,K14,IF(美联储议息会议日历!L1<=K15,K15,IF(美联储议息会议日历!L1<=K16,K16,IF(美联储议息会议日历!L1<=K17,K17,IF(美联储议息会议日历!L1<=K18,K18,IF(美联储议息会议日历!L1<=K19,K19,K20)))))))))))))))))),24,0) -> 46753.083 | H27: =_xlfn.IFNA(MATCH(G27,$E$3:$E$21,0),0) -> 0 | J27: =IF(K27="请更新日历","请更新代码",TEXT(K27,"YYMM")&"E") -> 2802E | K27: =IF(COUNTIF(A:A,M27)=0,N27,VLOOKUP(M27,A:B,2,0)) -> 46784.083 | M27: =TEXT(N27,"YYMM")&"E" -> 2802E | N27: =DATE(YEAR(TODAY())+2, 2, 1) + TIME(2, 0, 0) -> 46784.083
A28: =IF(B28="请更新日历","请更新代码",TEXT(B28,"YYMM")&"E") -> 请更新代码 | B28: 请更新日历 | G28: =OFFSET(IF(美联储议息会议日历!L1<=K2,K2,IF(美联储议息会议日历!L1<=K3,K3,IF(美联储议息会议日历!L1<=K4,K4,IF(美联储议息会议日历!L1<=K5,K5,IF(美联储议息会议日历!L1<=K6,K6,IF(美联储议息会议日历!L1<=K7,K7,IF(美联储议息会议日历!L1<=K8,K8,IF(美联储议息会议日历!L1<=K9,K9,IF(美联储议息会议日历!L1<=K10,K10,IF(美联储议息会议日历!L1<=K11,K11,IF(美联储议息会议日历!L1<=K12,K12,IF(美联储议息会议日历!L1<=K13,K13,IF(美联储议息会议日历!L1<=K14,K14,IF(美联储议息会议日历!L1<=K15,K15,IF(美联储议息会议日历!L1<=K16,K16,IF(美联储议息会议日历!L1<=K17,K17,IF(美联储议息会议日历!L1<=K18,K18,IF(美联储议息会议日历!L1<=K19,K19,K20)))))))))))))))))),25,0) -> 46784.083 | H28: =_xlfn.IFNA(MATCH(G28,$E$3:$E$21,0),0) -> 0 | J28: =IF(K28="请更新日历","请更新代码",TEXT(K28,"YYMM")&"E") -> 2803E | K28: =IF(COUNTIF(A:A,M28)=0,N28,VLOOKUP(M28,A:B,2,0)) -> 46813.083 | M28: =TEXT(N28,"YYMM")&"E" -> 2803E | N28: =DATE(YEAR(TODAY())+2, 3, 1) + TIME(2, 0, 0) -> 46813.083
A29: =IF(B29="请更新日历","请更新代码",TEXT(B29,"YYMM")&"E") -> 请更新代码 | B29: 请更新日历 | G29: =OFFSET(IF(美联储议息会议日历!L1<=K2,K2,IF(美联储议息会议日历!L1<=K3,K3,IF(美联储议息会议日历!L1<=K4,K4,IF(美联储议息会议日历!L1<=K5,K5,IF(美联储议息会议日历!L1<=K6,K6,IF(美联储议息会议日历!L1<=K7,K7,IF(美联储议息会议日历!L1<=K8,K8,IF(美联储议息会议日历!L1<=K9,K9,IF(美联储议息会议日历!L1<=K10,K10,IF(美联储议息会议日历!L1<=K11,K11,IF(美联储议息会议日历!L1<=K12,K12,IF(美联储议息会议日历!L1<=K13,K13,IF(美联储议息会议日历!L1<=K14,K14,IF(美联储议息会议日历!L1<=K15,K15,IF(美联储议息会议日历!L1<=K16,K16,IF(美联储议息会议日历!L1<=K17,K17,IF(美联储议息会议日历!L1<=K18,K18,IF(美联储议息会议日历!L1<=K19,K19,K20)))))))))))))))))),26,0) -> 46813.083 | H29: =_xlfn.IFNA(MATCH(G29,$E$3:$E$21,0),0) -> 0 | J29: =IF(K29="请更新日历","请更新代码",TEXT(K29,"YYMM")&"E") -> 2804E | K29: =IF(COUNTIF(A:A,M29)=0,N29,VLOOKUP(M29,A:B,2,0)) -> 46844.083 | M29: =TEXT(N29,"YYMM")&"E" -> 2804E | N29: =DATE(YEAR(TODAY())+2, 4, 1) + TIME(2, 0, 0) -> 46844.083
A30: =IF(B30="请更新日历","请更新代码",TEXT(B30,"YYMM")&"E") -> 请更新代码 | B30: 请更新日历 | G30: =OFFSET(IF(美联储议息会议日历!L1<=K2,K2,IF(美联储议息会议日历!L1<=K3,K3,IF(美联储议息会议日历!L1<=K4,K4,IF(美联储议息会议日历!L1<=K5,K5,IF(美联储议息会议日历!L1<=K6,K6,IF(美联储议息会议日历!L1<=K7,K7,IF(美联储议息会议日历!L1<=K8,K8,IF(美联储议息会议日历!L1<=K9,K9,IF(美联储议息会议日历!L1<=K10,K10,IF(美联储议息会议日历!L1<=K11,K11,IF(美联储议息会议日历!L1<=K12,K12,IF(美联储议息会议日历!L1<=K13,K13,IF(美联储议息会议日历!L1<=K14,K14,IF(美联储议息会议日历!L1<=K15,K15,IF(美联储议息会议日历!L1<=K16,K16,IF(美联储议息会议日历!L1<=K17,K17,IF(美联储议息会议日历!L1<=K18,K18,IF(美联储议息会议日历!L1<=K19,K19,K20)))))))))))))))))),27,0) -> 46844.083 | H30: =_xlfn.IFNA(MATCH(G30,$E$3:$E$21,0),0) -> 0 | J30: =IF(K30="请更新日历","请更新代码",TEXT(K30,"YYMM")&"E") -> 2805E | K30: =IF(COUNTIF(A:A,M30)=0,N30,VLOOKUP(M30,A:B,2,0)) -> 46874.083 | M30: =TEXT(N30,"YYMM")&"E" -> 2805E | N30: =DATE(YEAR(TODAY())+2, 5, 1) + TIME(2, 0, 0) -> 46874.083
A31: =IF(B31="请更新日历","请更新代码",TEXT(B31,"YYMM")&"E") -> 请更新代码 | B31: 请更新日历 | G31: =OFFSET(IF(美联储议息会议日历!L1<=K2,K2,IF(美联储议息会议日历!L1<=K3,K3,IF(美联储议息会议日历!L1<=K4,K4,IF(美联储议息会议日历!L1<=K5,K5,IF(美联储议息会议日历!L1<=K6,K6,IF(美联储议息会议日历!L1<=K7,K7,IF(美联储议息会议日历!L1<=K8,K8,IF(美联储议息会议日历!L1<=K9,K9,IF(美联储议息会议日历!L1<=K10,K10,IF(美联储议息会议日历!L1<=K11,K11,IF(美联储议息会议日历!L1<=K12,K12,IF(美联储议息会议日历!L1<=K13,K13,IF(美联储议息会议日历!L1<=K14,K14,IF(美联储议息会议日历!L1<=K15,K15,IF(美联储议息会议日历!L1<=K16,K16,IF(美联储议息会议日历!L1<=K17,K17,IF(美联储议息会议日历!L1<=K18,K18,IF(美联储议息会议日历!L1<=K19,K19,K20)))))))))))))))))),28,0) -> 46874.083 | H31: =_xlfn.IFNA(MATCH(G31,$E$3:$E$21,0),0) -> 0 | J31: =IF(K31="请更新日历","请更新代码",TEXT(K31,"YYMM")&"E") -> 2806E | K31: =IF(COUNTIF(A:A,M31)=0,N31,VLOOKUP(M31,A:B,2,0)) -> 46905.083 | M31: =TEXT(N31,"YYMM")&"E" -> 2806E | N31: =DATE(YEAR(TODAY())+2, 6, 1) + TIME(2, 0, 0) -> 46905.083
A32: =IF(B32="请更新日历","请更新代码",TEXT(B32,"YYMM")&"E") -> 请更新代码 | B32: 请更新日历 | J32: =IF(K32="请更新日历","请更新代码",TEXT(K32,"YYMM")&"E") -> 2807E | K32: =IF(COUNTIF(A:A,M32)=0,N32,VLOOKUP(M32,A:B,2,0)) -> 46935.083 | M32: =TEXT(N32,"YYMM")&"E" -> 2807E | N32: =DATE(YEAR(TODAY())+2, 7, 1) + TIME(2, 0, 0) -> 46935.083
A33: =IF(B33="请更新日历","请更新代码",TEXT(B33,"YYMM")&"E") -> 请更新代码 | B33: 请更新日历 | J33: =IF(K33="请更新日历","请更新代码",TEXT(K33,"YYMM")&"E") -> 2808E | K33: =IF(COUNTIF(A:A,M33)=0,N33,VLOOKUP(M33,A:B,2,0)) -> 46966.083 | M33: =TEXT(N33,"YYMM")&"E" -> 2808E | N33: =DATE(YEAR(TODAY())+2, 8, 1) + TIME(2, 0, 0) -> 46966.083
A34: =IF(B34="请更新日历","请更新代码",TEXT(B34,"YYMM")&"E") -> 请更新代码 | B34: 请更新日历 | J34: =IF(K34="请更新日历","请更新代码",TEXT(K34,"YYMM")&"E") -> 2809E | K34: =IF(COUNTIF(A:A,M34)=0,N34,VLOOKUP(M34,A:B,2,0)) -> 46997.083 | M34: =TEXT(N34,"YYMM")&"E" -> 2809E | N34: =DATE(YEAR(TODAY())+2, 9, 1) + TIME(2, 0, 0) -> 46997.083
A35: =IF(B35="请更新日历","请更新代码",TEXT(B35,"YYMM")&"E") -> 请更新代码 | B35: 请更新日历 | J35: =IF(K35="请更新日历","请更新代码",TEXT(K35,"YYMM")&"E") -> 2810E | K35: =IF(COUNTIF(A:A,M35)=0,N35,VLOOKUP(M35,A:B,2,0)) -> 47027.083 | M35: =TEXT(N35,"YYMM")&"E" -> 2810E | N35: =DATE(YEAR(TODAY())+2, 10, 1) + TIME(2, 0, 0) -> 47027.083
A36: =IF(B36="请更新日历","请更新代码",TEXT(B36,"YYMM")&"E") -> 请更新代码 | B36: 请更新日历 | J36: =IF(K36="请更新日历","请更新代码",TEXT(K36,"YYMM")&"E") -> 2811E | K36: =IF(COUNTIF(A:A,M36)=0,N36,VLOOKUP(M36,A:B,2,0)) -> 47058.083 | M36: =TEXT(N36,"YYMM")&"E" -> 2811E | N36: =DATE(YEAR(TODAY())+2, 11, 1) + TIME(2, 0, 0) -> 47058.083
A37: =IF(B37="请更新日历","请更新代码",TEXT(B37,"YYMM")&"E") -> 请更新代码 | B37: 请更新日历 | J37: =IF(K37="请更新日历","请更新代码",TEXT(K37,"YYMM")&"E") -> 2812E | K37: =IF(COUNTIF(A:A,M37)=0,N37,VLOOKUP(M37,A:B,2,0)) -> 47088.083 | M37: =TEXT(N37,"YYMM")&"E" -> 2812E | N37: =DATE(YEAR(TODAY())+2, 12, 1) + TIME(2, 0, 0) -> 47088.083
J38: =IF(K38="请更新日历","请更新代码",TEXT(K38,"YYMM")&"E") -> 2901E | K38: =IF(COUNTIF(A:A,M38)=0,N38,VLOOKUP(M38,A:B,2,0)) -> 47119.083 | M38: =TEXT(N38,"YYMM")&"E" -> 2901E | N38: =DATE(YEAR(TODAY())+3, 1, 1) + TIME(2, 0, 0) -> 47119.083
J39: =IF(K39="请更新日历","请更新代码",TEXT(K39,"YYMM")&"E") -> 2902E | K39: =IF(COUNTIF(A:A,M39)=0,N39,VLOOKUP(M39,A:B,2,0)) -> 47150.083 | M39: =TEXT(N39,"YYMM")&"E" -> 2902E | N39: =DATE(YEAR(TODAY())+3, 2, 1) + TIME(2, 0, 0) -> 47150.083
J40: =IF(K40="请更新日历","请更新代码",TEXT(K40,"YYMM")&"E") -> 2903E | K40: =IF(COUNTIF(A:A,M40)=0,N40,VLOOKUP(M40,A:B,2,0)) -> 47178.083 | M40: =TEXT(N40,"YYMM")&"E" -> 2903E | N40: =DATE(YEAR(TODAY())+3, 3, 1) + TIME(2, 0, 0) -> 47178.083
...

Sheet 使用说明
B1: 美联储利率观测器使用说明

Sheet 加息降息概率计算
G1: 美联储议息会议加息降息概率计算 | X1: 最近更新： | Y1: =TODAY() -> 46037
B3: 2 | O3: 加息/降息概率 | W3: 累计加息/降息概率
C4: 检索代码 | F4: 会议日期 | H4: 距离月初/月末天数 | I4: 距离月初/月末天数% | J4: 价格 | K4: 隐含利率 | L4: 月度价差 | M4: 25bp变动次数 | N4: 达成加减息次数&余数 | O4: -50bps | P4: -25bps | Q4: 0bps | R4: +25bps | S4: +50bps | T4: 和当前月度价差 | U4: 25bp变动次数 | V4: 达成加减息次数&余数 | W4: 降息 | X4: 保持不变 | Y4: 加息
C5: =TEXT(D5,"YYMM")&"EE" -> 2804EE | D5: =D6 -> 46844.083 | E5: 月末 | H5: =DAY(EOMONTH(D5,0))-H7 -> 30 | I5: =H5/(H7+H5) -> 1 | J5: =IF(G6,IF(I7=0,J6,(J6-I7*J7)/I5),J6) -> 96.875 | K5: =100-J5 -> 3.125 | L5: =K5-K7 -> 0 | M5: =L5/25*100 -> 0 | N5: =TRUNC(M5,0)/1 -> 0 | T5: =K5-$K$88 -> -0.51607143 | U5: =T5/25*100 -> -2.0642857 | V5: =TRUNC(U5,0)/1 -> -2
C6: =TEXT(D6,"YYMM")&"E" -> 2804E | D6: =日历计算!G30 -> 46844.083 | E6: 平均 | F6: =IF(日历计算!H30<>0,日历计算!G30,"当月无会议"&"("&TEXT(日历计算!G30,"M")&"月)") -> 当月无会议(4月) | G6: =IF(LEFT(F6,1)="当",FALSE,TRUE) -> FALSE | J6: =VLOOKUP(C6,FF期货结算价!D:Z,$B$3,0) -> 96.875 | K6: =100-J6 -> 3.125 | N6: =IF(M5>0,MOD(M5,1),MOD(M5,-1)) -> 0 | O6: =IF(N5=-2,1-ABS(N6),IF(N5=-1,ABS(N6),0)) -> 0 | P6: =IF(N5=-1,1-ABS(N6),IF(N5=0,IF(N6<0,ABS(N6),0),0)) -> 0 | Q6: =IF(N5=0,1-ABS(N6),0) -> 1 | R6: =IF(N5=0,IF(N6>0,ABS(N6),0),IF(N6=1,1-ABS(N6),0)) -> 0 | S6: =IF(N5=1,ABS(N6),IF(N5=2,1-ABS(N6),0)) -> 0 | V6: =IF(U5>0,MOD(U5,1),MOD(U5,-1)) -> -0.064285714 | W6: =IF(V5<0,100%,IF(V6<0,ABS(V6),0)) -> 1 | X6: =IF(V5=0,1-ABS(V6),0) -> 0 | Y6: =IF(V5>0,100%,IF(V6>0,V6,0)) -> 0
