Workbook

Sheet 业绩披露日期
D1: 业绩披露日期 | H1: 最近更新: | I1: =TODAY() -> 45534
C4: 财报期： | D4: =IF(MONTH(I1)<=3,DATE(YEAR(I1)-1,12,31),IF(MONTH(I1)<=6,DATE(YEAR(I1),3,30),IF(MONTH(I1)<=9,DATE(YEAR(I1),6,30),IF(MONTH(I1)<=12,DATE(YEAR(I1),9,30),"")))) -> 45473
C5: 板块名称： | D5: 美国中国股
C7: 业绩预计披露日期 | D7: =[1]!TDays(I1,I1+5,"Days=Alldays","Direction=H","cols=6;rows=1") -> 45534 | E7: 45535 | F7: 45536 | G7: 45537 | H7: 45538 | I7: 45539
C8: 倒数日 | D8: =D7-TODAY() -> 0 | E8: =E7-TODAY() -> 1 | F8: =F7-TODAY() -> 2 | G8: =G7-TODAY() -> 3 | H8: =H7-TODAY() -> 4 | I8: =I7-TODAY() -> 5
B9: 1 | D9: =_xlfn.IFNA(VLOOKUP(业绩披露日期!B9,内容筛选!$A:$J,7,0)&" "&VLOOKUP(业绩披露日期!B9,内容筛选!$A:$J,8,0),"") -> BTCM.N 比特矿业 | E9: =_xlfn.IFNA(VLOOKUP(业绩披露日期!$B9,内容筛选!$B:$J,6,0)&" "&VLOOKUP(业绩披露日期!$B9,内容筛选!$B:$J,7,0),"") | F9: =_xlfn.IFNA(VLOOKUP(业绩披露日期!$B9,内容筛选!$C:$J,5,0)&" "&VLOOKUP(业绩披露日期!$B9,内容筛选!$C:$J,6,0),"") | G9: =_xlfn.IFNA(VLOOKUP(业绩披露日期!$B9,内容筛选!$D:$J,4,0)&" "&VLOOKUP(业绩披露日期!$B9,内容筛选!$D:$J,5,0),"") -> DOYU.O 斗鱼 | H9: =_xlfn.IFNA(VLOOKUP(业绩披露日期!$B9,内容筛选!$E:$J,3,0)&" "&VLOOKUP(业绩披露日期!$B9,内容筛选!$E:$J,4,0),"") -> HUIZ.O 慧择 | I9: =_xlfn.IFNA(VLOOKUP(业绩披露日期!$B9,内容筛选!$F:$J,2,0)&" "&VLOOKUP(业绩披露日期!$B9,内容筛选!$F:$J,3,0),"") -> MLGO.O MICROALGO
B10: 2 | D10: =_xlfn.IFNA(VLOOKUP(业绩披露日期!B10,内容筛选!$A:$J,7,0)&" "&VLOOKUP(业绩披露日期!B10,内容筛选!$A:$J,8,0),"") -> JKS.N 晶科能源 | E10: =_xlfn.IFNA(VLOOKUP(业绩披露日期!$B10,内容筛选!$B:$J,6,0)&" "&VLOOKUP(业绩披露日期!$B10,内容筛选!$B:$J,7,0),"") | F10: =_xlfn.IFNA(VLOOKUP(业绩披露日期!$B10,内容筛选!$C:$J,5,0)&" "&VLOOKUP(业绩披露日期!$B10,内容筛选!$C:$J,6,0),"") | G10: =_xlfn.IFNA(VLOOKUP(业绩披露日期!$B10,内容筛选!$D:$J,4,0)&" "&VLOOKUP(业绩披露日期!$B10,内容筛选!$D:$J,5,0),"") -> GURE.O 海湾资源 | H10: =_xlfn.IFNA(VLOOKUP(业绩披露日期!$B10,内容筛选!$E:$J,3,0)&" "&VLOOKUP(业绩披露日期!$B10,内容筛选!$E:$J,4,0),"") -> MOMO.O 挚文集团 | I10: =_xlfn.IFNA(VLOOKUP(业绩披露日期!$B10,内容筛选!$F:$J,2,0)&" "&VLOOKUP(业绩披露日期!$B10,内容筛选!$F:$J,3,0),"") -> SJ.O 思享无限
B11: 3 | D11: =_xlfn.IFNA(VLOOKUP(业绩披露日期!B11,内容筛选!$A:$J,7,0)&" "&VLOOKUP(业绩披露日期!B11,内容筛选!$A:$J,8,0),"") -> SPI.O 绿能宝 | E11: =_xlfn.IFNA(VLOOKUP(业绩披露日期!$B11,内容筛选!$B:$J,6,0)&" "&VLOOKUP(业绩披露日期!$B11,内容筛选!$B:$J,7,0),"") | F11: =_xlfn.IFNA(VLOOKUP(业绩披露日期!$B11,内容筛选!$C:$J,5,0)&" "&VLOOKUP(业绩披露日期!$B11,内容筛选!$C:$J,6,0),"") | G11: =_xlfn.IFNA(VLOOKUP(业绩披露日期!$B11,内容筛选!$D:$J,4,0)&" "&VLOOKUP(业绩披露日期!$B11,内容筛选!$D:$J,5,0),"") -> MI.A NFT | H11: =_xlfn.IFNA(VLOOKUP(业绩披露日期!$B11,内容筛选!$E:$J,3,0)&" "&VLOOKUP(业绩披露日期!$B11,内容筛选!$E:$J,4,0),"") -> SOGP.O SOUND | I11: =_xlfn.IFNA(VLOOKUP(业绩披露日期!$B11,内容筛选!$F:$J,2,0)&" "&VLOOKUP(业绩披露日期!$B11,内容筛选!$F:$J,3,0),"") -> WDH.N 水滴公司
B12: 4 | D12: =_xlfn.IFNA(VLOOKUP(业绩披露日期!B12,内容筛选!$A:$J,7,0)&" "&VLOOKUP(业绩披露日期!B12,内容筛选!$A:$J,8,0),"") -> TIGR.O 老虎证券 | E12: =_xlfn.IFNA(VLOOKUP(业绩披露日期!$B12,内容筛选!$B:$J,6,0)&" "&VLOOKUP(业绩披露日期!$B12,内容筛选!$B:$J,7,0),"") | F12: =_xlfn.IFNA(VLOOKUP(业绩披露日期!$B12,内容筛选!$C:$J,5,0)&" "&VLOOKUP(业绩披露日期!$B12,内容筛选!$C:$J,6,0),"") | G12: =_xlfn.IFNA(VLOOKUP(业绩披露日期!$B12,内容筛选!$D:$J,4,0)&" "&VLOOKUP(业绩披露日期!$B12,内容筛选!$D:$J,5,0),"") -> TCTM.O 达内教育 | H12: =_xlfn.IFNA(VLOOKUP(业绩披露日期!$B12,内容筛选!$E:$J,3,0)&" "&VLOOKUP(业绩披露日期!$B12,内容筛选!$E:$J,4,0),"") | I12: =_xlfn.IFNA(VLOOKUP(业绩披露日期!$B12,内容筛选!$F:$J,2,0)&" "&VLOOKUP(业绩披露日期!$B12,内容筛选!$F:$J,3,0),"")
B13: 5 | D13: =_xlfn.IFNA(VLOOKUP(业绩披露日期!B13,内容筛选!$A:$J,7,0)&" "&VLOOKUP(业绩披露日期!B13,内容筛选!$A:$J,8,0),"") | E13: =_xlfn.IFNA(VLOOKUP(业绩披露日期!$B13,内容筛选!$B:$J,6,0)&" "&VLOOKUP(业绩披露日期!$B13,内容筛选!$B:$J,7,0),"") | F13: =_xlfn.IFNA(VLOOKUP(业绩披露日期!$B13,内容筛选!$C:$J,5,0)&" "&VLOOKUP(业绩披露日期!$B13,内容筛选!$C:$J,6,0),"") | G13: =_xlfn.IFNA(VLOOKUP(业绩披露日期!$B13,内容筛选!$D:$J,4,0)&" "&VLOOKUP(业绩披露日期!$B13,内容筛选!$D:$J,5,0),"") -> YQ.O 一起教育科技 | H13: =_xlfn.IFNA(VLOOKUP(业绩披露日期!$B13,内容筛选!$E:$J,3,0)&" "&VLOOKUP(业绩披露日期!$B13,内容筛选!$E:$J,4,0),"") | I13: =_xlfn.IFNA(VLOOKUP(业绩披露日期!$B13,内容筛选!$F:$J,2,0)&" "&VLOOKUP(业绩披露日期!$B13,内容筛选!$F:$J,3,0),"")
B14: 6 | D14: =_xlfn.IFNA(VLOOKUP(业绩披露日期!B14,内容筛选!$A:$J,7,0)&" "&VLOOKUP(业绩披露日期!B14,内容筛选!$A:$J,8,0),"") | E14: =_xlfn.IFNA(VLOOKUP(业绩披露日期!$B14,内容筛选!$B:$J,6,0)&" "&VLOOKUP(业绩披露日期!$B14,内容筛选!$B:$J,7,0),"") | F14: =_xlfn.IFNA(VLOOKUP(业绩披露日期!$B14,内容筛选!$C:$J,5,0)&" "&VLOOKUP(业绩披露日期!$B14,内容筛选!$C:$J,6,0),"") | G14: =_xlfn.IFNA(VLOOKUP(业绩披露日期!$B14,内容筛选!$D:$J,4,0)&" "&VLOOKUP(业绩披露日期!$B14,内容筛选!$D:$J,5,0),"") | H14: =_xlfn.IFNA(VLOOKUP(业绩披露日期!$B14,内容筛选!$E:$J,3,0)&" "&VLOOKUP(业绩披露日期!$B14,内容筛选!$E:$J,4,0),"") | I14: =_xlfn.IFNA(VLOOKUP(业绩披露日期!$B14,内容筛选!$F:$J,2,0)&" "&VLOOKUP(业绩披露日期!$B14,内容筛选!$F:$J,3,0),"")
B15: 7 | D15: =_xlfn.IFNA(VLOOKUP(业绩披露日期!B15,内容筛选!$A:$J,7,0)&" "&VLOOKUP(业绩披露日期!B15,内容筛选!$A:$J,8,0),"") | E15: =_xlfn.IFNA(VLOOKUP(业绩披露日期!$B15,内容筛选!$B:$J,6,0)&" "&VLOOKUP(业绩披露日期!$B15,内容筛选!$B:$J,7,0),"") | F15: =_xlfn.IFNA(VLOOKUP(业绩披露日期!$B15,内容筛选!$C:$J,5,0)&" "&VLOOKUP(业绩披露日期!$B15,内容筛选!$C:$J,6,0),"") | G15: =_xlfn.IFNA(VLOOKUP(业绩披露日期!$B15,内容筛选!$D:$J,4,0)&" "&VLOOKUP(业绩披露日期!$B15,内容筛选!$D:$J,5,0),"") | H15: =_xlfn.IFNA(VLOOKUP(业绩披露日期!$B15,内容筛选!$E:$J,3,0)&" "&VLOOKUP(业绩披露日期!$B15,内容筛选!$E:$J,4,0),"") | I15: =_xlfn.IFNA(VLOOKUP(业绩披露日期!$B15,内容筛选!$F:$J,2,0)&" "&VLOOKUP(业绩披露日期!$B15,内容筛选!$F:$J,3,0),"")
B16: 8 | D16: =_xlfn.IFNA(VLOOKUP(业绩披露日期!B16,内容筛选!$A:$J,7,0)&" "&VLOOKUP(业绩披露日期!B16,内容筛选!$A:$J,8,0),"") | E16: =_xlfn.IFNA(VLOOKUP(业绩披露日期!$B16,内容筛选!$B:$J,6,0)&" "&VLOOKUP(业绩披露日期!$B16,内容筛选!$B:$J,7,0),"") | F16: =_xlfn.IFNA(VLOOKUP(业绩披露日期!$B16,内容筛选!$C:$J,5,0)&" "&VLOOKUP(业绩披露日期!$B16,内容筛选!$C:$J,6,0),"") | G16: =_xlfn.IFNA(VLOOKUP(业绩披露日期!$B16,内容筛选!$D:$J,4,0)&" "&VLOOKUP(业绩披露日期!$B16,内容筛选!$D:$J,5,0),"") | H16: =_xlfn.IFNA(VLOOKUP(业绩披露日期!$B16,内容筛选!$E:$J,3,0)&" "&VLOOKUP(业绩披露日期!$B16,内容筛选!$E:$J,4,0),"") | I16: =_xlfn.IFNA(VLOOKUP(业绩披露日期!$B16,内容筛选!$F:$J,2,0)&" "&VLOOKUP(业绩披露日期!$B16,内容筛选!$F:$J,3,0),"")
B17: 9 | D17: =_xlfn.IFNA(VLOOKUP(业绩披露日期!B17,内容筛选!$A:$J,7,0)&" "&VLOOKUP(业绩披露日期!B17,内容筛选!$A:$J,8,0),"") | E17: =_xlfn.IFNA(VLOOKUP(业绩披露日期!$B17,内容筛选!$B:$J,6,0)&" "&VLOOKUP(业绩披露日期!$B17,内容筛选!$B:$J,7,0),"") | F17: =_xlfn.IFNA(VLOOKUP(业绩披露日期!$B17,内容筛选!$C:$J,5,0)&" "&VLOOKUP(业绩披露日期!$B17,内容筛选!$C:$J,6,0),"") | G17: =_xlfn.IFNA(VLOOKUP(业绩披露日期!$B17,内容筛选!$D:$J,4,0)&" "&VLOOKUP(业绩披露日期!$B17,内容筛选!$D:$J,5,0),"") | H17: =_xlfn.IFNA(VLOOKUP(业绩披露日期!$B17,内容筛选!$E:$J,3,0)&" "&VLOOKUP(业绩披露日期!$B17,内容筛选!$E:$J,4,0),"") | I17: =_xlfn.IFNA(VLOOKUP(业绩披露日期!$B17,内容筛选!$F:$J,2,0)&" "&VLOOKUP(业绩披露日期!$B17,内容筛选!$F:$J,3,0),"")
B18: 10 | D18: =_xlfn.IFNA(VLOOKUP(业绩披露日期!B18,内容筛选!$A:$J,7,0)&" "&VLOOKUP(业绩披露日期!B18,内容筛选!$A:$J,8,0),"") | E18: =_xlfn.IFNA(VLOOKUP(业绩披露日期!$B18,内容筛选!$B:$J,6,0)&" "&VLOOKUP(业绩披露日期!$B18,内容筛选!$B:$J,7,0),"") | F18: =_xlfn.IFNA(VLOOKUP(业绩披露日期!$B18,内容筛选!$C:$J,5,0)&" "&VLOOKUP(业绩披露日期!$B18,内容筛选!$C:$J,6,0),"") | G18: =_xlfn.IFNA(VLOOKUP(业绩披露日期!$B18,内容筛选!$D:$J,4,0)&" "&VLOOKUP(业绩披露日期!$B18,内容筛选!$D:$J,5,0),"") | H18: =_xlfn.IFNA(VLOOKUP(业绩披露日期!$B18,内容筛选!$E:$J,3,0)&" "&VLOOKUP(业绩披露日期!$B18,内容筛选!$E:$J,4,0),"") | I18: =_xlfn.IFNA(VLOOKUP(业绩披露日期!$B18,内容筛选!$F:$J,2,0)&" "&VLOOKUP(业绩披露日期!$B18,内容筛选!$F:$J,3,0),"")
B19: 11 | D19: =_xlfn.IFNA(VLOOKUP(业绩披露日期!B19,内容筛选!$A:$J,7,0)&" "&VLOOKUP(业绩披露日期!B19,内容筛选!$A:$J,8,0),"") | E19: =_xlfn.IFNA(VLOOKUP(业绩披露日期!$B19,内容筛选!$B:$J,6,0)&" "&VLOOKUP(业绩披露日期!$B19,内容筛选!$B:$J,7,0),"") | F19: =_xlfn.IFNA(VLOOKUP(业绩披露日期!$B19,内容筛选!$C:$J,5,0)&" "&VLOOKUP(业绩披露日期!$B19,内容筛选!$C:$J,6,0),"") | G19: =_xlfn.IFNA(VLOOKUP(业绩披露日期!$B19,内容筛选!$D:$J,4,0)&" "&VLOOKUP(业绩披露日期!$B19,内容筛选!$D:$J,5,0),"") | H19: =_xlfn.IFNA(VLOOKUP(业绩披露日期!$B19,内容筛选!$E:$J,3,0)&" "&VLOOKUP(业绩披露日期!$B19,内容筛选!$E:$J,4,0),"") | I19: =_xlfn.IFNA(VLOOKUP(业绩披露日期!$B19,内容筛选!$F:$J,2,0)&" "&VLOOKUP(业绩披露日期!$B19,内容筛选!$F:$J,3,0),"")
B20: 12 | D20: =_xlfn.IFNA(VLOOKUP(业绩披露日期!B20,内容筛选!$A:$J,7,0)&" "&VLOOKUP(业绩披露日期!B20,内容筛选!$A:$J,8,0),"") | E20: =_xlfn.IFNA(VLOOKUP(业绩披露日期!$B20,内容筛选!$B:$J,6,0)&" "&VLOOKUP(业绩披露日期!$B20,内容筛选!$B:$J,7,0),"") | F20: =_xlfn.IFNA(VLOOKUP(业绩披露日期!$B20,内容筛选!$C:$J,5,0)&" "&VLOOKUP(业绩披露日期!$B20,内容筛选!$C:$J,6,0),"") | G20: =_xlfn.IFNA(VLOOKUP(业绩披露日期!$B20,内容筛选!$D:$J,4,0)&" "&VLOOKUP(业绩披露日期!$B20,内容筛选!$D:$J,5,0),"") | H20: =_xlfn.IFNA(VLOOKUP(业绩披露日期!$B20,内容筛选!$E:$J,3,0)&" "&VLOOKUP(业绩披露日期!$B20,内容筛选!$E:$J,4,0),"") | I20: =_xlfn.IFNA(VLOOKUP(业绩披露日期!$B20,内容筛选!$F:$J,2,0)&" "&VLOOKUP(业绩披露日期!$B20,内容筛选!$F:$J,3,0),"")
... B27: 19 | D27: =_xlfn.IFNA(VLOOKUP(业绩披露日期!B27,内容筛选!$A:$J,7,0)&" "&VLOOKUP(业绩披露日期!B27,内容筛选!$A:$J,8,0),"") | E27: =_xlfn.IFNA(VLOOKUP(业绩披露日期!$B27,内容筛选!$B:$J,6,0)&" "&VLOOKUP(业绩披露日期!$B27,内容筛选!$B:$J,7,0),"") | F27: =_xlfn.IFNA(VLOOKUP(业绩披露日期!$B27,内容筛选!$C:$J,5,0)&" "&VLOOKUP(业绩披露日期!$B27,内容筛选!$C:$J,6,0),"") | G27: =_xlfn.IFNA(VLOOKUP(业绩披露日期!$B27,内容筛选!$D:$J,4,0)&" "&VLOOKUP(业绩披露日期!$B27,内容筛选!$D:$J,5,0),"") | H27: =_xlfn.IFNA(VLOOKUP(业绩披露日期!$B27,内容筛选!$E:$J,3,0)&" "&VLOOKUP(业绩披露日期!$B27,内容筛选!$E:$J,4,0),"") | I27: =_xlfn.IFNA(VLOOKUP(业绩披露日期!$B27,内容筛选!$F:$J,2,0)&" "&VLOOKUP(业绩披露日期!$B27,内容筛选!$F:$J,3,0),"")

Sheet 证券列表 
A1: 数据集名称 | B1: 板块成分
A2: 日期 | B2: =TEXT(业绩披露日期!I1-1,"YYYYMMDD") -> 20240829
A3: 板块ID | B3: =IF(业绩披露日期!D5="美国中国股","a005010700000000",IF(业绩披露日期!D5="标普500成分股","a005010800000000","")) -> a005010700000000
A4: date | B4: wind_code | C4: sec_name
A5: 最新调整日期 | B5: Wind代码 | C5: 证券名称
A6: =[1]!wset("sectorconstituent","date="&B2,"sectorId="&B3,"field=date,wind_code,sec_name","cols=3;rows=335") -> 45533 | B6: AACG.O | C6: ATA CREATIVITY GLOBAL
A7: 45533 | B7: ABLV.O | C7: ABLE VIEW GLOBAL
A8: 45533 | B8: ABTS.O | C8: ABITS
A9: 45533 | B9: ACMR.O | C9: 盛美半导体
A10: 45533 | B10: ADAG.O | C10: 天演药业
A11: 45533 | B11: ADD.O | C11: 彩色星球科技
A12: 45533 | B12: AEHL.O | C12: ANTELOPE ENTERPRISE
A13: 45533 | B13: AGBA.O | C13: AGBA
A14: 45533 | B14: AGMH.O | C14: 安高盟
A15: 45533 | B15: AHG.O | C15: AKSO HEALTH
A16: 45533 | B16: AIHS.O | C16: 森淼科技
A17: 45533 | B17: AIXI.O | C17: 小I
A18: 45533 | B18: AMBO.A | C18: 安博教育
... A340: 45533 | B340: ZTO.N | C340: 中通快递

Sheet Wind模板
A1: 业绩披露日期

Sheet 内容筛选
G1: 代码 | H1: 名称 | I1: 定期报告预计披露日期 | J1: 总市值1
G2: Code | H2: Name | I2: stm_predict_issuingdate | J2: ev
A3: =IF(K3="",0,RANK(K3,K:K,1)) -> 0 | B3: =IF(L3="",0,RANK(L3,L:L,1)) -> 0 | C3: =IF(M3="",0,RANK(M3,M:M,1)) -> 0 | D3: =IF(N3="",0,RANK(N3,N:N,1)) -> 0 | E3: =IF(O3="",0,RANK(O3,O:O,1)) -> 0 | F3: =IF(P3="",0,RANK(P3,P:P,1)) -> 0 | G3: =IF('证券列表 '!B6="","",'证券列表 '!B6) -> AACG.O | H3: =[1]!WSS($G$3:$G$510,$I$2:$J$2,"rptDate="&TEXT(业绩披露日期!D4,"YYYYMMDD"),"unit=1","tradeDate="&TEXT(业绩披露日期!I1,"YYYYMMDD"), "UnitMask=2","cols=2;rows=335") -> ATA CREATIVITY GLOBAL | I3: 45511 | J3: 19105185 | K3: =IF($I3=业绩披露日期!D$7,ROW(),"") | L3: =IF($I3=业绩披露日期!E$7,ROW(),"") | M3: =IF($I3=业绩披露日期!F$7,ROW(),"") | N3: =IF($I3=业绩披露日期!G$7,ROW(),"") | O3: =IF($I3=业绩披露日期!H$7,ROW(),"") | P3: =IF($I3=业绩披露日期!I$7,ROW(),"")
A4: =IF(K4="",0,RANK(K4,K:K,1)) -> 0 | B4: =IF(L4="",0,RANK(L4,L:L,1)) -> 0 | C4: =IF(M4="",0,RANK(M4,M:M,1)) -> 0 | D4: =IF(N4="",0,RANK(N4,N:N,1)) -> 0 | E4: =IF(O4="",0,RANK(O4,O:O,1)) -> 0 | F4: =IF(P4="",0,RANK(P4,P:P,1)) -> 0 | G4: =IF('证券列表 '!B7="","",'证券列表 '!B7) -> ABLV.O | H4: ABLE VIEW GLOBAL | J4: 70759611 | K4: =IF($I4=业绩披露日期!D$7,ROW(),"") | L4: =IF($I4=业绩披露日期!E$7,ROW(),"") | M4: =IF($I4=业绩披露日期!F$7,ROW(),"") | N4: =IF($I4=业绩披露日期!G$7,ROW(),"") | O4: =IF($I4=业绩披露日期!H$7,ROW(),"") | P4: =IF($I4=业绩披露日期!I$7,ROW(),"")
A5: =IF(K5="",0,RANK(K5,K:K,1)) -> 0 | B5: =IF(L5="",0,RANK(L5,L:L,1)) -> 0 | C5: =IF(M5="",0,RANK(M5,M:M,1)) -> 0 | D5: =IF(N5="",0,RANK(N5,N:N,1)) -> 0 | E5: =IF(O5="",0,RANK(O5,O:O,1)) -> 0 | F5: =IF(P5="",0,RANK(P5,P:P,1)) -> 0 | G5: =IF('证券列表 '!B8="","",'证券列表 '!B8) -> ABTS.O | H5: ABITS | J5: 17119577 | K5: =IF($I5=业绩披露日期!D$7,ROW(),"") | L5: =IF($I5=业绩披露日期!E$7,ROW(),"") | M5: =IF($I5=业绩披露日期!F$7,ROW(),"") | N5: =IF($I5=业绩披露日期!G$7,ROW(),"") | O5: =IF($I5=业绩披露日期!H$7,ROW(),"") | P5: =IF($I5=业绩披露日期!I$7,ROW(),"")
A6: =IF(K6="",0,RANK(K6,K:K,1)) -> 0 | B6: =IF(L6="",0,RANK(L6,L:L,1)) -> 0 | C6: =IF(M6="",0,RANK(M6,M:M,1)) -> 0 | D6: =IF(N6="",0,RANK(N6,N:N,1)) -> 0 | E6: =IF(O6="",0,RANK(O6,O:O,1)) -> 0 | F6: =IF(P6="",0,RANK(P6,P:P,1)) -> 0 | G6: =IF('证券列表 '!B9="","",'证券列表 '!B9) -> ACMR.O | H6: 盛美半导体 | I6: 45511 | J6: 1.1107313e+09 | K6: =IF($I6=业绩披露日期!D$7,ROW(),"") | L6: =IF($I6=业绩披露日期!E$7,ROW(),"") | M6: =IF($I6=业绩披露日期!F$7,ROW(),"") | N6: =IF($I6=业绩披露日期!G$7,ROW(),"") | O6: =IF($I6=业绩披露日期!H$7,ROW(),"") | P6: =IF($I6=业绩披露日期!I$7,ROW(),"")
A7: =IF(K7="",0,RANK(K7,K:K,1)) -> 0 | B7: =IF(L7="",0,RANK(L7,L:L,1)) -> 0 | C7: =IF(M7="",0,RANK(M7,M:M,1)) -> 0 | D7: =IF(N7="",0,RANK(N7,N:N,1)) -> 0 | E7: =IF(O7="",0,RANK(O7,O:O,1)) -> 0 | F7: =IF(P7="",0,RANK(P7,P:P,1)) -> 0 | G7: =IF('证券列表 '!B10="","",'证券列表 '!B10) -> ADAG.O | H7: 天演药业 | J7: 1.2838527e+08 | K7: =IF($I7=业绩披露日期!D$7,ROW(),"") | L7: =IF($I7=业绩披露日期!E$7,ROW(),"") | M7: =IF($I7=业绩披露日期!F$7,ROW(),"") | N7: =IF($I7=业绩披露日期!G$7,ROW(),"") | O7: =IF($I7=业绩披露日期!H$7,ROW(),"") | P7: =IF($I7=业绩披露日期!I$7,ROW(),"")
A8: =IF(K8="",0,RANK(K8,K:K,1)) -> 0 | B8: =IF(L8="",0,RANK(L8,L:L,1)) -> 0 | C8: =IF(M8="",0,RANK(M8,M:M,1)) -> 0 | D8: =IF(N8="",0,RANK(N8,N:N,1)) -> 0 | E8: =IF(O8="",0,RANK(O8,O:O,1)) -> 0 | F8: =IF(P8="",0,RANK(P8,P:P,1)) -> 0 | G8: =IF('证券列表 '!B11="","",'证券列表 '!B11) -> ADD.O | H8: 彩色星球科技 | J8: 32012004 | K8: =IF($I8=业绩披露日期!D$7,ROW(),"") | L8: =IF($I8=业绩披露日期!E$7,ROW(),"") | M8: =IF($I8=业绩披露日期!F$7,ROW(),"") | N8: =IF($I8=业绩披露日期!G$7,ROW(),"") | O8: =IF($I8=业绩披露日期!H$7,ROW(),"") | P8: =IF($I8=业绩披露日期!I$7,ROW(),"")
A9: =IF(K9="",0,RANK(K9,K:K,1)) -> 0 | B9: =IF(L9="",0,RANK(L9,L:L,1)) -> 0 | C9: =IF(M9="",0,RANK(M9,M:M,1)) -> 0 | D9: =IF(N9="",0,RANK(N9,N:N,1)) -> 0 | E9: =IF(O9="",0,RANK(O9,O:O,1)) -> 0 | F9: =IF(P9="",0,RANK(P9,P:P,1)) -> 0 | G9: =IF('证券列表 '!B12="","",'证券列表 '!B12) -> AEHL.O | H9: ANTELOPE ENTERPRISE | J9: 25210246 | K9: =IF($I9=业绩披露日期!D$7,ROW(),"") | L9: =IF($I9=业绩披露日期!E$7,ROW(),"") | M9: =IF($I9=业绩披露日期!F$7,ROW(),"") | N9: =IF($I9=业绩披露日期!G$7,ROW(),"") | O9: =IF($I9=业绩披露日期!H$7,ROW(),"") | P9: =IF($I9=业绩披露日期!I$7,ROW(),"")
A10: =IF(K10="",0,RANK(K10,K:K,1)) -> 0 | B10: =IF(L10="",0,RANK(L10,L:L,1)) -> 0 | C10: =IF(M10="",0,RANK(M10,M:M,1)) -> 0 | D10: =IF(N10="",0,RANK(N10,N:N,1)) -> 0 | E10: =IF(O10="",0,RANK(O10,O:O,1)) -> 0 | F10: =IF(P10="",0,RANK(P10,P:P,1)) -> 0 | G10: =IF('证券列表 '!B13="","",'证券列表 '!B13) -> AGBA.O | H10: AGBA | I10: 45520 | J10: 2.0861659e+08 | K10: =IF($I10=业绩披露日期!D$7,ROW(),"") | L10: =IF($I10=业绩披露日期!E$7,ROW(),"") | M10: =IF($I10=业绩披露日期!F$7,ROW(),"") | N10: =IF($I10=业绩披露日期!G$7,ROW(),"") | O10: =IF($I10=业绩披露日期!H$7,ROW(),"") | P10: =IF($I10=业绩披露日期!I$7,ROW(),"")
A11: =IF(K11="",0,RANK(K11,K:K,1)) -> 0 | B11: =IF(L11="",0,RANK(L11,L:L,1)) -> 0 | C11: =IF(M11="",0,RANK(M11,M:M,1)) -> 0 | D11: =IF(N11="",0,RANK(N11,N:N,1)) -> 0 | E11: =IF(O11="",0,RANK(O11,O:O,1)) -> 0 | F11: =IF(P11="",0,RANK(P11,P:P,1)) -> 0 | G11: =IF('证券列表 '!B14="","",'证券列表 '!B14) -> AGMH.O | H11: 安高盟 | J11: 28990326 | K11: =IF($I11=业绩披露日期!D$7,ROW(),"") | L11: =IF($I11=业绩披露日期!E$7,ROW(),"") | M11: =IF($I11=业绩披露日期!F$7,ROW(),"") | N11: =IF($I11=业绩披露日期!G$7,ROW(),"") | O11: =IF($I11=业绩披露日期!H$7,ROW(),"") | P11: =IF($I11=业绩披露日期!I$7,ROW(),"")
A12: =IF(K12="",0,RANK(K12,K:K,1)) -> 0 | B12: =IF(L12="",0,RANK(L12,L:L,1)) -> 0 | C12: =IF(M12="",0,RANK(M12,M:M,1)) -> 0 | D12: =IF(N12="",0,RANK(N12,N:N,1)) -> 0 | E12: =IF(O12="",0,RANK(O12,O:O,1)) -> 0 | F12: =IF(P12="",0,RANK(P12,P:P,1)) -> 0 | G12: =IF('证券列表 '!B15="","",'证券列表 '!B15) -> AHG.O | H12: AKSO HEALTH | J12: 1.4718089e+08 | K12: =IF($I12=业绩披露日期!D$7,ROW(),"") | L12: =IF($I12=业绩披露日期!E$7,ROW(),"") | M12: =IF($I12=业绩披露日期!F$7,ROW(),"") | N12: =IF($I12=业绩披露日期!G$7,ROW(),"") | O12: =IF($I12=业绩披露日期!H$7,ROW(),"") | P12: =IF($I12=业绩披露日期!I$7,ROW(),"")
A13: =IF(K13="",0,RANK(K13,K:K,1)) -> 0 | B13: =IF(L13="",0,RANK(L13,L:L,1)) -> 0 | C13: =IF(M13="",0,RANK(M13,M:M,1)) -> 0 | D13: =IF(N13="",0,RANK(N13,N:N,1)) -> 0 | E13: =IF(O13="",0,RANK(O13,O:O,1)) -> 0 | F13: =IF(P13="",0,RANK(P13,P:P,1)) -> 0 | G13: =IF('证券列表 '!B16="","",'证券列表 '!B16) -> AIHS.O | H13: 森淼科技 | J13: 12726828 | K13: =IF($I13=业绩披露日期!D$7,ROW(),"") | L13: =IF($I13=业绩披露日期!E$7,ROW(),"") | M13: =IF($I13=业绩披露日期!F$7,ROW(),"") | N13: =IF($I13=业绩披露日期!G$7,ROW(),"") | O13: =IF($I13=业绩披露日期!H$7,ROW(),"") | P13: =IF($I13=业绩披露日期!I$7,ROW(),"")
A14: =IF(K14="",0,RANK(K14,K:K,1)) -> 0 | B14: =IF(L14="",0,RANK(L14,L:L,1)) -> 0 | C14: =IF(M14="",0,RANK(M14,M:M,1)) -> 0 | D14: =IF(N14="",0,RANK(N14,N:N,1)) -> 0 | E14: =IF(O14="",0,RANK(O14,O:O,1)) -> 0 | F14: =IF(P14="",0,RANK(P14,P:P,1)) -> 0 | G14: =IF('证券列表 '!B17="","",'证券列表 '!B17) -> AIXI.O | H14: 小I | J14: 41707078 | K14: =IF($I14=业绩披露日期!D$7,ROW(),"") | L14: =IF($I14=业绩披露日期!E$7,ROW(),"") | M14: =IF($I14=业绩披露日期!F$7,ROW(),"") | N14: =IF($I14=业绩披露日期!G$7,ROW(),"") | O14: =IF($I14=业绩披露日期!H$7,ROW(),"") | P14: =IF($I14=业绩披露日期!I$7,ROW(),"")
A15: =IF(K15="",0,RANK(K15,K:K,1)) -> 0 | B15: =IF(L15="",0,RANK(L15,L:L,1)) -> 0 | C15: =IF(M15="",0,RANK(M15,M:M,1)) -> 0 | D15: =IF(N15="",0,RANK(N15,N:N,1)) -> 0 | E15: =IF(O15="",0,RANK(O15,O:O,1)) -> 0 | F15: =IF(P15="",0,RANK(P15,P:P,1)) -> 0 | G15: =IF('证券列表 '!B18="","",'证券列表 '!B18) -> AMBO.A | H15: 安博教育 | J15: 3545470.2 | K15: =IF($I15=业绩披露日期!D$7,ROW(),"") | L15: =IF($I15=业绩披露日期!E$7,ROW(),"") | M15: =IF($I15=业绩披露日期!F$7,ROW(),"") | N15: =IF($I15=业绩披露日期!G$7,ROW(),"") | O15: =IF($I15=业绩披露日期!H$7,ROW(),"") | P15: =IF($I15=业绩披露日期!I$7,ROW(),"")
A16: =IF(K16="",0,RANK(K16,K:K,1)) -> 0 | B16: =IF(L16="",0,RANK(L16,L:L,1)) -> 0 | C16: =IF(M16="",0,RANK(M16,M:M,1)) -> 0 | D16: =IF(N16="",0,RANK(N16,N:N,1)) -> 0 | E16: =IF(O16="",0,RANK(O16,O:O,1)) -> 0 | F16: =IF(P16="",0,RANK(P16,P:P,1)) -> 0 | G16: =IF('证券列表 '!B19="","",'证券列表 '!B19) -> AMTD.N | H16: 尚乘IDEA集团 | J16: 1.0795968e+08 | K16: =IF($I16=业绩披露日期!D$7,ROW(),"") | L16: =IF($I16=业绩披露日期!E$7,ROW(),"") | M16: =IF($I16=业绩披露日期!F$7,ROW(),"") | N16: =IF($I16=业绩披露日期!G$7,ROW(),"") | O16: =IF($I16=业绩披露日期!H$7,ROW(),"") | P16: =IF($I16=业绩披露日期!I$7,ROW(),"")
A17: =IF(K17="",0,RANK(K17,K:K,1)) -> 0 | B17: =IF(L17="",0,RANK(L17,L:L,1)) -> 0 | C17: =IF(M17="",0,RANK(M17,M:M,1)) -> 0 | D17: =IF(N17="",0,RANK(N17,N:N,1)) -> 0 | E17: =IF(O17="",0,RANK(O17,O:O,1)) -> 0 | F17: =IF(P17="",0,RANK(P17,P:P,1)) -> 0 | G17: =IF('证券列表 '!B20="","",'证券列表 '!B20) -> ANL.O | H17: 阿诺医药 | J17: 1.0147574e+08 | K17: =IF($I17=业绩披露日期!D$7,ROW(),"") | L17: =IF($I17=业绩披露日期!E$7,ROW(),"") | M17: =IF($I17=业绩披露日期!F$7,ROW(),"") | N17: =IF($I17=业绩披露日期!G$7,ROW(),"") | O17: =IF($I17=业绩披露日期!H$7,ROW(),"") | P17: =IF($I17=业绩披露日期!I$7,ROW(),"")
A18: =IF(K18="",0,RANK(K18,K:K,1)) -> 0 | B18: =IF(L18="",0,RANK(L18,L:L,1)) -> 0 | C18: =IF(M18="",0,RANK(M18,M:M,1)) -> 0 | D18: =IF(N18="",0,RANK(N18,N:N,1)) -> 0 | E18: =IF(O18="",0,RANK(O18,O:O,1)) -> 0 | F18: =IF(P18="",0,RANK(P18,P:P,1)) -> 0 | G18: =IF('证券列表 '!B21="","",'证券列表 '!B21) -> ANTE.O | H18: 悦航阳光 | J18: 3501101.4 | K18: =IF($I18=业绩披露日期!D$7,ROW(),"") | L18: =IF($I18=业绩披露日期!E$7,ROW(),"") | M18: =IF($I18=业绩披露日期!F$7,ROW(),"") | N18: =IF($I18=业绩披露日期!G$7,ROW(),"") | O18: =IF($I18=业绩披露日期!H$7,ROW(),"") | P18: =IF($I18=业绩披露日期!I$7,ROW(),"")
A19: =IF(K19="",0,RANK(K19,K:K,1)) -> 0 | B19: =IF(L19="",0,RANK(L19,L:L,1)) -> 0 | C19: =IF(M19="",0,RANK(M19,M:M,1)) -> 0 | D19: =IF(N19="",0,RANK(N19,N:N,1)) -> 0 | E19: =IF(O19="",0,RANK(O19,O:O,1)) -> 0 | F19: =IF(P19="",0,RANK(P19,P:P,1)) -> 0 | G19: =IF('证券列表 '!B22="","",'证券列表 '!B22) -> API.O | H19: 声网 | I19: 45523 | J19: 1.7982571e+08 | K19: =IF($I19=业绩披露日期!D$7,ROW(),"") | L19: =IF($I19=业绩披露日期!E$7,ROW(),"") | M19: =IF($I19=业绩披露日期!F$7,ROW(),"") | N19: =IF($I19=业绩披露日期!G$7,ROW(),"") | O19: =IF($I19=业绩披露日期!H$7,ROW(),"") | P19: =IF($I19=业绩披露日期!I$7,ROW(),"")
A20: =IF(K20="",0,RANK(K20,K:K,1)) -> 0 | B20: =IF(L20="",0,RANK(L20,L:L,1)) -> 0 | C20: =IF(M20="",0,RANK(M20,M:M,1)) -> 0 | D20: =IF(N20="",0,RANK(N20,N:N,1)) -> 0 | E20: =IF(O20="",0,RANK(O20,O:O,1)) -> 0 | F20: =IF(P20="",0,RANK(P20,P:P,1)) -> 0 | G20: =IF('证券列表 '!B23="","",'证券列表 '!B23) -> APLM.O | H20: 冠科美博 | J20: 14043213 | K20: =IF($I20=业绩披露日期!D$7,ROW(),"") | L20: =IF($I20=业绩披露日期!E$7,ROW(),"") | M20: =IF($I20=业绩披露日期!F$7,ROW(),"") | N20: =IF($I20=业绩披露日期!G$7,ROW(),"") | O20: =IF($I20=业绩披露日期!H$7,ROW(),"") | P20: =IF($I20=业绩披露日期!I$7,ROW(),"")
A21: =IF(K21="",0,RANK(K21,K:K,1)) -> 0 | B21: =IF(L21="",0,RANK(L21,L:L,1)) -> 0 | C21: =IF(M21="",0,RANK(M21,M:M,1)) -> 0 | D21: =IF(N21="",0,RANK(N21,N:N,1)) -> 0 | E21: =IF(O21="",0,RANK(O21,O:O,1)) -> 0 | F21: =IF(P21="",0,RANK(P21,P:P,1)) -> 0 | G21: =IF('证券列表 '!B24="","",'证券列表 '!B24) -> APM.O | H21: 知临集团 | J21: 14923287 | K21: =IF($I21=业绩披露日期!D$7,ROW(),"") | L21: =IF($I21=业绩披露日期!E$7,ROW(),"") | M21: =IF($I21=业绩披露日期!F$7,ROW(),"") | N21: =IF($I21=业绩披露日期!G$7,ROW(),"") | O21: =IF($I21=业绩披露日期!H$7,ROW(),"") | P21: =IF($I21=业绩披露日期!I$7,ROW(),"")
A22: =IF(K22="",0,RANK(K22,K:K,1)) -> 0 | B22: =IF(L22="",0,RANK(L22,L:L,1)) -> 0 | C22: =IF(M22="",0,RANK(M22,M:M,1)) -> 0 | D22: =IF(N22="",0,RANK(N22,N:N,1)) -> 0 | E22: =IF(O22="",0,RANK(O22,O:O,1)) -> 0 | F22: =IF(P22="",0,RANK(P22,P:P,1)) -> 0 | G22: =IF('证券列表 '!B25="","",'证券列表 '!B25) -> AS.N | H22: 亚玛芬体育 | I22: 45524 | J22: 6.7795696e+09 | K22: =IF($I22=业绩披露日期!D$7,ROW(),"") | L22: =IF($I22=业绩披露日期!E$7,ROW(),"") | M22: =IF($I22=业绩披露日期!F$7,ROW(),"") | N22: =IF($I22=业绩披露日期!G$7,ROW(),"") | O22: =IF($I22=业绩披露日期!H$7,ROW(),"") | P22: =IF($I22=业绩披露日期!I$7,ROW(),"")
A23: =IF(K23="",0,RANK(K23,K:K,1)) -> 0 | B23: =IF(L23="",0,RANK(L23,L:L,1)) -> 0 | C23: =IF(M23="",0,RANK(M23,M:M,1)) -> 0 | D23: =IF(N23="",0,RANK(N23,N:N,1)) -> 0 | E23: =IF(O23="",0,RANK(O23,O:O,1)) -> 0 | F23: =IF(P23="",0,RANK(P23,P:P,1)) -> 0 | G23: =IF('证券列表 '!B26="","",'证券列表 '!B26) -> ATAT.O | H23: 亚朵 | I23: 45533 | J23: 2.5757828e+09 | K23: =IF($I23=业绩披露日期!D$7,ROW(),"") | L23: =IF($I23=业绩披露日期!E$7,ROW(),"") | M23: =IF($I23=业绩披露日期!F$7,ROW(),"") | N23: =IF($I23=业绩披露日期!G$7,ROW(),"") | O23: =IF($I23=业绩披露日期!H$7,ROW(),"") | P23: =IF($I23=业绩披露日期!I$7,ROW(),"")
A24: =IF(K24="",0,RANK(K24,K:K,1)) -> 0 | B24: =IF(L24="",0,RANK(L24,L:L,1)) -> 0 | C24: =IF(M24="",0,RANK(M24,M:M,1)) -> 0 | D24: =IF(N24="",0,RANK(N24,N:N,1)) -> 0 | E24: =IF(O24="",0,RANK(O24,O:O,1)) -> 0 | F24: =IF(P24="",0,RANK(P24,P:P,1)) -> 0 | G24: =IF('证券列表 '!B27="","",'证券列表 '!B27) -> ATCO.N | H24: ATLAS(退市) | K24: =IF($I24=业绩披露日期!D$7,ROW(),"") | L24: =IF($I24=业绩披露日期!E$7,ROW(),"") | M24: =IF($I24=业绩披露日期!F$7,ROW(),"") | N24: =IF($I24=业绩披露日期!G$7,ROW(),"") | O24: =IF($I24=业绩披露日期!H$7,ROW(),"") | P24: =IF($I24=业绩披露日期!I$7,ROW(),"")
A25: =IF(K25="",0,RANK(K25,K:K,1)) -> 0 | B25: =IF(L25="",0,RANK(L25,L:L,1)) -> 0 | C25: =IF(M25="",0,RANK(M25,M:M,1)) -> 0 | D25: =IF(N25="",0,RANK(N25,N:N,1)) -> 0 | E25: =IF(O25="",0,RANK(O25,O:O,1)) -> 0 | F25: =IF(P25="",0,RANK(P25,P:P,1)) -> 0 | G25: =IF('证券列表 '!B28="","",'证券列表 '!B28) -> ATGL.O | H25: 阿尔法科技 | J25: 32190139 | K25: =IF($I25=业绩披露日期!D$7,ROW(),"") | L25: =IF($I25=业绩披露日期!E$7,ROW(),"") | M25: =IF($I25=业绩披露日期!F$7,ROW(),"") | N25: =IF($I25=业绩披露日期!G$7,ROW(),"") | O25: =IF($I25=业绩披露日期!H$7,ROW(),"") | P25: =IF($I25=业绩披露日期!I$7,ROW(),"")
A26: =IF(K26="",0,RANK(K26,K:K,1)) -> 0 | B26: =IF(L26="",0,RANK(L26,L:L,1)) -> 0 | C26: =IF(M26="",0,RANK(M26,M:M,1)) -> 0 | D26: =IF(N26="",0,RANK(N26,N:N,1)) -> 0 | E26: =IF(O26="",0,RANK(O26,O:O,1)) -> 0 | F26: =IF(P26="",0,RANK(P26,P:P,1)) -> 0 | G26: =IF('证券列表 '!B29="","",'证券列表 '!B29) -> ATHM.N | H26: 汽车之家 | I26: 45504 | J26: 3.1155791e+09 | K26: =IF($I26=业绩披露日期!D$7,ROW(),"") | L26: =IF($I26=业绩披露日期!E$7,ROW(),"") | M26: =IF($I26=业绩披露日期!F$7,ROW(),"") | N26: =IF($I26=业绩披露日期!G$7,ROW(),"") | O26: =IF($I26=业绩披露日期!H$7,ROW(),"") | P26: =IF($I26=业绩披露日期!I$7,ROW(),"")
A27: =IF(K27="",0,RANK(K27,K:K,1)) -> 0 | B27: =IF(L27="",0,RANK(L27,L:L,1)) -> 0 | C27: =IF(M27="",0,RANK(M27,M:M,1)) -> 0 | D27: =IF(N27="",0,RANK(N27,N:N,1)) -> 0 | E27: =IF(O27="",0,RANK(O27,O:O,1)) -> 0 | F27: =IF(P27="",0,RANK(P27,P:P,1)) -> 0 | G27: =IF('证券列表 '!B30="","",'证券列表 '!B30) -> ATIF.O | H27: 亚洲时代 | I27: 45366 | J27: 8354133.9 | K27: =IF($I27=业绩披露日期!D$7,ROW(),"") | L27: =IF($I27=业绩披露日期!E$7,ROW(),"") | M27: =IF($I27=业绩披露日期!F$7,ROW(),"") | N27: =IF($I27=业绩披露日期!G$7,ROW(),"") | O27: =IF($I27=业绩披露日期!H$7,ROW(),"") | P27: =IF($I27=业绩披露日期!I$7,ROW(),"")
A28: =IF(K28="",0,RANK(K28,K:K,1)) -> 0 | B28: =IF(L28="",0,RANK(L28,L:L,1)) -> 0 | C28: =IF(M28="",0,RANK(M28,M:M,1)) -> 0 | D28: =IF(N28="",0,RANK(N28,N:N,1)) -> 0 | E28: =IF(O28="",0,RANK(O28,O:O,1)) -> 0 | F28: =IF(P28="",0,RANK(P28,P:P,1)) -> 0 | G28: =IF('证券列表 '!B31="","",'证券列表 '!B31) -> ATXG.O | H28: 盈喜集团 | J28: 3444948.3 | K28: =IF($I28=业绩披露日期!D$7,ROW(),"") | L28: =IF($I28=业绩披露日期!E$7,ROW(),"") | M28: =IF($I28=业绩披露日期!F$7,ROW(),"") | N28: =IF($I28=业绩披露日期!G$7,ROW(),"") | O28: =IF($I28=业绩披露日期!H$7,ROW(),"") | P28: =IF($I28=业绩披露日期!I$7,ROW(),"")
A29: =IF(K29="",0,RANK(K29,K:K,1)) -> 0 | B29: =IF(L29="",0,RANK(L29,L:L,1)) -> 0 | C29: =IF(M29="",0,RANK(M29,M:M,1)) -> 0 | D29: =IF(N29="",0,RANK(N29,N:N,1)) -> 0 | E29: =IF(O29="",0,RANK(O29,O:O,1)) -> 0 | F29: =IF(P29="",0,RANK(P29,P:P,1)) -> 0 | G29: =IF('证券列表 '!B32="","",'证券列表 '!B32) -> AZI.O | H29: 中驰车福 | J29: 304445480 | K29: =IF($I29=业绩披露日期!D$7,ROW(),"") | L29: =IF($I29=业绩披露日期!E$7,ROW(),"") | M29: =IF($I29=业绩披露日期!F$7,ROW(),"") | N29: =IF($I29=业绩披露日期!G$7,ROW(),"") | O29: =IF($I29=业绩披露日期!H$7,ROW(),"") | P29: =IF($I29=业绩披露日期!I$7,ROW(),"")
A30: =IF(K30="",0,RANK(K30,K:K,1)) -> 0 | B30: =IF(L30="",0,RANK(L30,L:L,1)) -> 0 | C30: =IF(M30="",0,RANK(M30,M:M,1)) -> 0 | D30: =IF(N30="",0,RANK(N30,N:N,1)) -> 0 | E30: =IF(O30="",0,RANK(O30,O:O,1)) -> 0 | F30: =IF(P30="",0,RANK(P30,P:P,1)) -> 0 | G30: =IF('证券列表 '!B33="","",'证券列表 '!B33) -> BABA.N | H30: 阿里巴巴 | I30: 45245 | J30: 1.9608914e+11 | K30: =IF($I30=业绩披露日期!D$7,ROW(),"") | L30: =IF($I30=业绩披露日期!E$7,ROW(),"") | M30: =IF($I30=业绩披露日期!F$7,ROW(),"") | N30: =IF($I30=业绩披露日期!G$7,ROW(),"") | O30: =IF($I30=业绩披露日期!H$7,ROW(),"") | P30: =IF($I30=业绩披露日期!I$7,ROW(),"")
A31: =IF(K31="",0,RANK(K31,K:K,1)) -> 0 | B31: =IF(L31="",0,RANK(L31,L:L,1)) -> 0 | C31: =IF(M31="",0,RANK(M31,M:M,1)) -> 0 | D31: =IF(N31="",0,RANK(N31,N:N,1)) -> 0 | E31: =IF(O31="",0,RANK(O31,O:O,1)) -> 0 | F31: =IF(P31="",0,RANK(P31,P:P,1)) -> 0 | G31: =IF('证券列表 '!B34="","",'证券列表 '!B34) -> BAOS.O | H31: 宝盛 | J31: 3728803.4 | K31: =IF($I31=业绩披露日期!D$7,ROW(),"") | L31: =IF($I31=业绩披露日期!E$7,ROW(),"") | M31: =IF($I31=业绩披露日期!F$7,ROW(),"") | N31: =IF($I31=业绩披露日期!G$7,ROW(),"") | O31: =IF($I31=业绩披露日期!H$7,ROW(),"") | P31: =IF($I31=业绩披露日期!I$7,ROW(),"")
A32: =IF(K32="",0,RANK(K32,K:K,1)) -> 0 | B32: =IF(L32="",0,RANK(L32,L:L,1)) -> 0 | C32: =IF(M32="",0,RANK(M32,M:M,1)) -> 0 | D32: =IF(N32="",0,RANK(N32,N:N,1)) -> 0 | E32: =IF(O32="",0,RANK(O32,O:O,1)) -> 0 | F32: =IF(P32="",0,RANK(P32,P:P,1)) -> 0 | G32: =IF('证券列表 '!B35="","",'证券列表 '!B35) -> BEDU.N | H32: 博实乐 | J32: 54993478 | K32: =IF($I32=业绩披露日期!D$7,ROW(),"") | L32: =IF($I32=业绩披露日期!E$7,ROW(),"") | M32: =IF($I32=业绩披露日期!F$7,ROW(),"") | N32: =IF($I32=业绩披露日期!G$7,ROW(),"") | O32: =IF($I32=业绩披露日期!H$7,ROW(),"") | P32: =IF($I32=业绩披露日期!I$7,ROW(),"")
A33: =IF(K33="",0,RANK(K33,K:K,1)) -> 0 | B33: =IF(L33="",0,RANK(L33,L:L,1)) -> 0 | C33: =IF(M33="",0,RANK(M33,M:M,1)) -> 0 | D33: =IF(N33="",0,RANK(N33,N:N,1)) -> 0 | E33: =IF(O33="",0,RANK(O33,O:O,1)) -> 0 | F33: =IF(P33="",0,RANK(P33,P:P,1)) -> 0 | G33: =IF('证券列表 '!B36="","",'证券列表 '!B36) -> BEKE.N | H33: 贝壳 | I33: 45516 | J33: 1.7212908e+10 | K33: =IF($I33=业绩披露日期!D$7,ROW(),"") | L33: =IF($I33=业绩披露日期!E$7,ROW(),"") | M33: =IF($I33=业绩披露日期!F$7,ROW(),"") | N33: =IF($I33=业绩披露日期!G$7,ROW(),"") | O33: =IF($I33=业绩披露日期!H$7,ROW(),"") | P33: =IF($I33=业绩披露日期!I$7,ROW(),"")
A34: =IF(K34="",0,RANK(K34,K:K,1)) -> 0 | B34: =IF(L34="",0,RANK(L34,L:L,1)) -> 0 | C34: =IF(M34="",0,RANK(M34,M:M,1)) -> 0 | D34: =IF(N34="",0,RANK(N34,N:N,1)) -> 0 | E34: =IF(O34="",0,RANK(O34,O:O,1)) -> 0 | F34: =IF(P34="",0,RANK(P34,P:P,1)) -> 0 | G34: =IF('证券列表 '!B37="","",'证券列表 '!B37) -> BEST.N | H34: 百世集团 | I34: 45532 | J34: 55060300 | K34: =IF($I34=业绩披露日期!D$7,ROW(),"") | L34: =IF($I34=业绩披露日期!E$7,ROW(),"") | M34: =IF($I34=业绩披露日期!F$7,ROW(),"") | N34: =IF($I34=业绩披露日期!G$7,ROW(),"") | O34: =IF($I34=业绩披露日期!H$7,ROW(),"") | P34: =IF($I34=业绩披露日期!I$7,ROW(),"")
A35: =IF(K35="",0,RANK(K35,K:K,1)) -> 0 | B35: =IF(L35="",0,RANK(L35,L:L,1)) -> 0 | C35: =IF(M35="",0,RANK(M35,M:M,1)) -> 0 | D35: =IF(N35="",0,RANK(N35,N:N,1)) -> 0 | E35: =IF(O35="",0,RANK(O35,O:O,1)) -> 0 | F35: =IF(P35="",0,RANK(P35,P:P,1)) -> 0 | G35: =IF('证券列表 '!B38="","",'证券列表 '!B38) -> BGM.O | H35: 祁连国际 | J35: 47547500 | K35: =IF($I35=业绩披露日期!D$7,ROW(),"") | L35: =IF($I35=业绩披露日期!E$7,ROW(),"") | M35: =IF($I35=业绩披露日期!F$7,ROW(),"") | N35: =IF($I35=业绩披露日期!G$7,ROW(),"") | O35: =IF($I35=业绩披露日期!H$7,ROW(),"") | P35: =IF($I35=业绩披露日期!I$7,ROW(),"")
A36: =IF(K36="",0,RANK(K36,K:K,1)) -> 0 | B36: =IF(L36="",0,RANK(L36,L:L,1)) -> 0 | C36: =IF(M36="",0,RANK(M36,M:M,1)) -> 0 | D36: =IF(N36="",0,RANK(N36,N:N,1)) -> 0 | E36: =IF(O36="",0,RANK(O36,O:O,1)) -> 0 | F36: =IF(P36="",0,RANK(P36,P:P,1)) -> 0 | G36: =IF('证券列表 '!B39="","",'证券列表 '!B39) -> BGNE.O | H36: 百济神州 | I36: 45530 | J36: 2.1613697e+10 | K36: =IF($I36=业绩披露日期!D$7,ROW(),"") | L36: =IF($I36=业绩披露日期!E$7,ROW(),"") | M36: =IF($I36=业绩披露日期!F$7,ROW(),"") | N36: =IF($I36=业绩披露日期!G$7,ROW(),"") | O36: =IF($I36=业绩披露日期!H$7,ROW(),"") | P36: =IF($I36=业绩披露日期!I$7,ROW(),"")
A37: =IF(K37="",0,RANK(K37,K:K,1)) -> 0 | B37: =IF(L37="",0,RANK(L37,L:L,1)) -> 0 | C37: =IF(M37="",0,RANK(M37,M:M,1)) -> 0 | D37: =IF(N37="",0,RANK(N37,N:N,1)) -> 0 | E37: =IF(O37="",0,RANK(O37,O:O,1)) -> 0 | F37: =IF(P37="",0,RANK(P37,P:P,1)) -> 0 | G37: =IF('证券列表 '!B40="","",'证券列表 '!B40) -> BHAT.O | H37: 蓝帽子 | J37: 29327617 | K37: =IF($I37=业绩披露日期!D$7,ROW(),"") | L37: =IF($I37=业绩披露日期!E$7,ROW(),"") | M37: =IF($I37=业绩披露日期!F$7,ROW(),"") | N37: =IF($I37=业绩披露日期!G$7,ROW(),"") | O37: =IF($I37=业绩披露日期!H$7,ROW(),"") | P37: =IF($I37=业绩披露日期!I$7,ROW(),"")
A38: =IF(K38="",0,RANK(K38,K:K,1)) -> 0 | B38: =IF(L38="",0,RANK(L38,L:L,1)) -> 0 | C38: =IF(M38="",0,RANK(M38,M:M,1)) -> 0 | D38: =IF(N38="",0,RANK(N38,N:N,1)) -> 0 | E38: =IF(O38="",0,RANK(O38,O:O,1)) -> 0 | F38: =IF(P38="",0,RANK(P38,P:P,1)) -> 0 | G38: =IF('证券列表 '!B41="","",'证券列表 '!B41) -> BIDU.O | H38: 百度 | I38: 45525 | J38: 2.9297462e+10 | K38: =IF($I38=业绩披露日期!D$7,ROW(),"") | L38: =IF($I38=业绩披露日期!E$7,ROW(),"") | M38: =IF($I38=业绩披露日期!F$7,ROW(),"") | N38: =IF($I38=业绩披露日期!G$7,ROW(),"") | O38: =IF($I38=业绩披露日期!H$7,ROW(),"") | P38: =IF($I38=业绩披露日期!I$7,ROW(),"")
A39: =IF(K39="",0,RANK(K39,K:K,1)) -> 0 | B39: =IF(L39="",0,RANK(L39,L:L,1)) -> 0 | C39: =IF(M39="",0,RANK(M39,M:M,1)) -> 0 | D39: =IF(N39="",0,RANK(N39,N:N,1)) -> 0 | E39: =IF(O39="",0,RANK(O39,O:O,1)) -> 0 | F39: =IF(P39="",0,RANK(P39,P:P,1)) -> 0 | G39: =IF('证券列表 '!B42="","",'证券列表 '!B42) -> BILI.O | H39: 哔哩哔哩 | I39: 45526 | J39: 6.0390068e+09 | K39: =IF($I39=业绩披露日期!D$7,ROW(),"") | L39: =IF($I39=业绩披露日期!E$7,ROW(),"") | M39: =IF($I39=业绩披露日期!F$7,ROW(),"") | N39: =IF($I39=业绩披露日期!G$7,ROW(),"") | O39: =IF($I39=业绩披露日期!H$7,ROW(),"") | P39: =IF($I39=业绩披露日期!I$7,ROW(),"")
A40: =IF(K40="",0,RANK(K40,K:K,1)) -> 0 | B40: =IF(L40="",0,RANK(L40,L:L,1)) -> 0 | C40: =IF(M40="",0,RANK(M40,M:M,1)) -> 0 | D40: =IF(N40="",0,RANK(N40,N:N,1)) -> 0 | E40: =IF(O40="",0,RANK(O40,O:O,1)) -> 0 | F40: =IF(P40="",0,RANK(P40,P:P,1)) -> 0 | G40: =IF('证券列表 '!B43="","",'证券列表 '!B43) -> BNR.O | H40: 燃石医学 | I40: 45533 | J40: 57086733 | K40: =IF($I40=业绩披露日期!D$7,ROW(),"") | L40: =IF($I40=业绩披露日期!E$7,ROW(),"") | M40: =IF($I40=业绩披露日期!F$7,ROW(),"") | N40: =IF($I40=业绩披露日期!G$7,ROW(),"") | O40: =IF($I40=业绩披露日期!H$7,ROW(),"") | P40: =IF($I40=业绩披露日期!I$7,ROW(),"")
...
