Workbook
Name AHMD: 公司名单!$C$1:$E$85
Name BZ: 溢价变动趋势!$G$8
Name company: OFFSET(公司名单!$B$1,溢价变动趋势!$A$5,1)
Name gslb: AH股溢价一览!$A$4:$K$162
Name hcrate1: 溢价变动趋势!$H$19
Name HKS_CNY中间价最新: AH股溢价一览!$P$6
Name hl: 汇率表!$A:$B
Name QJ: 溢价变动趋势!$G$9
Name QJYR: [1]!td(TODAY())
Name wcodea: 溢价变动趋势!$G$6
Name wcodeh: 溢价变动趋势!$G$7
Name windcodea: OFFSET(公司名单!$B$1,溢价变动趋势!$A$5,2)
Name windcodeh: OFFSET(公司名单!$B$1,溢价变动趋势!$A$5,3)

Sheet AH股溢价一览
D1: AH股溢价分析 V1.1
B4: A股涨幅 | C4: A股最新价[CNY] | D4: A股代码 | E4: 公司 | F4: H股代码 | G4: H股最新价[HKD] | H4: H股涨幅 | I4: A-H价差[CNY] | J4: A-H溢价% | K4: A/H
A5: =RANK(J5,$J$5:$J$162)+COUNTIF(J$5:J5,J5)-1 -> 100 | B5: =RTD("wdf.rtq",,D5,27)/100 -> -0.0156 | C5: =RTD("wdf.rtq",,D5,"LastPrice") -> 7.55 | D5: =公司名单!D2 -> 601728.SH | E5: =公司名单!C2 -> 中国电信 | F5: =公司名单!E2 -> 0728.HK | G5: =IF(RTD("wdf.rtq",,F5,5)=0,[1]!s_dq_preclose(F5),RTD("wdf.rtq",,F5,5)) -> 6.14 | H5: =RTD("wdf.rtq",,F5,27)/100 -> -0.0144 | I5: =C5-G5*HKS_CNY中间价最新 -> 1.9585476 | J5: =IF(G5=0,"",(C5/(G5*HKS_CNY中间价最新)-1)) -> 0.35027529 | K5: =IF(G5=0,"",C5/(G5*HKS_CNY中间价最新)) -> 1.3502753 | N5: AH两地上市股票池已更新至： | P5: 45895
A6: =RANK(J6,$J$5:$J$162)+COUNTIF(J$5:J6,J6)-1 -> 67 | B6: =RTD("wdf.rtq",,D6,27)/100 -> 0.0028 | C6: =RTD("wdf.rtq",,D6,"LastPrice") -> 7.21 | D6: =公司名单!D3 -> 601330.SH | E6: =公司名单!C3 -> 绿色动力 | F6: =公司名单!E3 -> 1330.HK | G6: =IF(RTD("wdf.rtq",,F6,5)=0,[1]!s_dq_preclose(F6),RTD("wdf.rtq",,F6,5)) -> 5.11 | H6: =RTD("wdf.rtq",,F6,27)/100 -> 0.0159 | I6: =C6-G6*HKS_CNY中间价最新 -> 2.5565274 | J6: =IF(G6=0,"",(C6/(G6*HKS_CNY中间价最新)-1)) -> 0.54938056 | K6: =IF(G6=0,"",C6/(G6*HKS_CNY中间价最新)) -> 1.5493806 | N6: 最新汇价 | P6: =汇率表!B4 -> 0.91066
A7: =RANK(J7,$J$5:$J$162)+COUNTIF(J$5:J7,J7)-1 -> 131 | B7: =RTD("wdf.rtq",,D7,27)/100 -> -0.0059 | C7: =RTD("wdf.rtq",,D7,"LastPrice") -> 38.87 | D7: =公司名单!D4 -> 601088.SH | E7: =公司名单!C4 -> 中国神华 | F7: =公司名单!E4 -> 1088.HK | G7: =IF(RTD("wdf.rtq",,F7,5)=0,[1]!s_dq_preclose(F7),RTD("wdf.rtq",,F7,5)) -> 35.78 | H7: =RTD("wdf.rtq",,F7,27)/100 -> -0.0039 | I7: =C7-G7*HKS_CNY中间价最新 -> 6.2865852 | J7: =IF(G7=0,"",(C7/(G7*HKS_CNY中间价最新)-1)) -> 0.19293819 | K7: =IF(G7=0,"",C7/(G7*HKS_CNY中间价最新)) -> 1.1929382
A8: =RANK(J8,$J$5:$J$162)+COUNTIF(J$5:J8,J8)-1 -> 8 | B8: =RTD("wdf.rtq",,D8,27)/100 -> 0.0098 | C8: =RTD("wdf.rtq",,D8,"LastPrice") -> 11.33 | D8: =公司名单!D5 -> 600876.SH | E8: =公司名单!C5 -> 凯盛新能 | F8: =公司名单!E5 -> 1108.HK | G8: =IF(RTD("wdf.rtq",,F8,5)=0,[1]!s_dq_preclose(F8),RTD("wdf.rtq",,F8,5)) -> 4.71 | H8: =RTD("wdf.rtq",,F8,27)/100 -> 0.0021 | I8: =C8-G8*HKS_CNY中间价最新 -> 7.0407914 | J8: =IF(G8=0,"",(C8/(G8*HKS_CNY中间价最新)-1)) -> 1.6415129 | K8: =IF(G8=0,"",C8/(G8*HKS_CNY中间价最新)) -> 2.6415129 | M8: 最高溢价
A9: =RANK(J9,$J$5:$J$162)+COUNTIF(J$5:J9,J9)-1 -> 51 | B9: =RTD("wdf.rtq",,D9,27)/100 -> 0.005 | C9: =RTD("wdf.rtq",,D9,"LastPrice") -> 6.09 | D9: =公司名单!D6 -> 600874.SH | E9: =公司名单!C6 -> 创业环保 | F9: =公司名单!E6 -> 1065.HK | G9: =IF(RTD("wdf.rtq",,F9,5)=0,[1]!s_dq_preclose(F9),RTD("wdf.rtq",,F9,5)) -> 4.01 | H9: =RTD("wdf.rtq",,F9,27)/100 -> 0.0025 | I9: =C9-G9*HKS_CNY中间价最新 -> 2.4382534 | J9: =IF(G9=0,"",(C9/(G9*HKS_CNY中间价最新)-1)) -> 0.66769512 | K9: =IF(G9=0,"",C9/(G9*HKS_CNY中间价最新)) -> 1.6676951 | M9: 序号 | N9: 公司名称 | O9: A-H溢价% | P9: A股价格[CNY] | Q9: H股价格[HKD]
A10: =RANK(J10,$J$5:$J$162)+COUNTIF(J$5:J10,J10)-1 -> 1 | B10: =RTD("wdf.rtq",,D10,27)/100 -> 0.0178 | C10: =RTD("wdf.rtq",,D10,"LastPrice") -> 13.16 | D10: =公司名单!D7 -> 001236.SZ | E10: =公司名单!C7 -> 弘业期货 | F10: =公司名单!E7 -> 3678.HK | G10: =IF(RTD("wdf.rtq",,F10,5)=0,[1]!s_dq_preclose(F10),RTD("wdf.rtq",,F10,5)) -> 4.58 | H10: =RTD("wdf.rtq",,F10,27)/100 -> 0.0066 | I10: =C10-G10*HKS_CNY中间价最新 -> 8.9891772 | J10: =IF(G10=0,"",(C10/(G10*HKS_CNY中间价最新)-1)) -> 2.1552527 | K10: =IF(G10=0,"",C10/(G10*HKS_CNY中间价最新)) -> 3.1552527 | M10: 1 | N10: =VLOOKUP(M10,gslb,5,FALSE) -> 弘业期货 | O10: =VLOOKUP(M10,gslb,10,FALSE) -> 2.1552527 | P10: =VLOOKUP(M10,gslb,3,FALSE) -> 13.16 | Q10: =VLOOKUP(M10,gslb,7,FALSE) -> 4.58
A11: =RANK(J11,$J$5:$J$162)+COUNTIF(J$5:J11,J11)-1 -> 25 | B11: =RTD("wdf.rtq",,D11,27)/100 -> 0.0038 | C11: =RTD("wdf.rtq",,D11,"LastPrice") -> 7.98 | D11: =公司名单!D8 -> 600956.SH | E11: =公司名单!C8 -> 新天绿能 | F11: =公司名单!E8 -> 0956.HK | G11: =IF(RTD("wdf.rtq",,F11,5)=0,[1]!s_dq_preclose(F11),RTD("wdf.rtq",,F11,5)) -> 4.28 | H11: =RTD("wdf.rtq",,F11,27)/100 -> 0.0071 | I11: =C11-G11*HKS_CNY中间价最新 -> 4.0823752 | J11: =IF(G11=0,"",(C11/(G11*HKS_CNY中间价最新)-1)) -> 1.0474008 | K11: =IF(G11=0,"",C11/(G11*HKS_CNY中间价最新)) -> 2.0474008 | M11: 2 | N11: =VLOOKUP(M11,gslb,5,FALSE) -> 安德利 | O11: =VLOOKUP(M11,gslb,10,FALSE) -> 2.1469336 | P11: =VLOOKUP(M11,gslb,3,FALSE) -> 52.1 | Q11: =VLOOKUP(M11,gslb,7,FALSE) -> 18.18
A12: =RANK(J12,$J$5:$J$162)+COUNTIF(J$5:J12,J12)-1 -> 76 | B12: =RTD("wdf.rtq",,D12,27)/100 -> -0.0168 | C12: =RTD("wdf.rtq",,D12,"LastPrice") -> 28.64 | D12: =公司名单!D9 -> 600196.SH | E12: =公司名单!C9 -> 复星医药 | F12: =公司名单!E9 -> 2196.HK | G12: =IF(RTD("wdf.rtq",,F12,5)=0,[1]!s_dq_preclose(F12),RTD("wdf.rtq",,F12,5)) -> 21.04 | H12: =RTD("wdf.rtq",,F12,27)/100 -> -0.0232 | I12: =C12-G12*HKS_CNY中间价最新 -> 9.4797136 | J12: =IF(G12=0,"",(C12/(G12*HKS_CNY中间价最新)-1)) -> 0.49475845 | K12: =IF(G12=0,"",C12/(G12*HKS_CNY中间价最新)) -> 1.4947584 | M12: 3 | N12: =VLOOKUP(M12,gslb,5,FALSE) -> 京城股份 | O12: =VLOOKUP(M12,gslb,10,FALSE) -> 1.8762855 | P12: =VLOOKUP(M12,gslb,3,FALSE) -> 13.83 | Q12: =VLOOKUP(M12,gslb,7,FALSE) -> 5.28
A13: =RANK(J13,$J$5:$J$162)+COUNTIF(J$5:J13,J13)-1 -> 42 | B13: =RTD("wdf.rtq",,D13,27)/100 -> -0.0104 | C13: =RTD("wdf.rtq",,D13,"LastPrice") -> 4.76 | D13: =公司名单!D10 -> 601375.SH | E13: =公司名单!C10 -> 中原证券 | F13: =公司名单!E10 -> 1375.HK | G13: =IF(RTD("wdf.rtq",,F13,5)=0,[1]!s_dq_preclose(F13),RTD("wdf.rtq",,F13,5)) -> 2.96 | H13: =RTD("wdf.rtq",,F13,27)/100 -> -0.0133 | I13: =C13-G13*HKS_CNY中间价最新 -> 2.0644464 | J13: =IF(G13=0,"",(C13/(G13*HKS_CNY中间价最新)-1)) -> 0.76587103 | K13: =IF(G13=0,"",C13/(G13*HKS_CNY中间价最新)) -> 1.765871 | M13: 4 | N13: =VLOOKUP(M13,gslb,5,FALSE) -> 复旦张江 | O13: =VLOOKUP(M13,gslb,10,FALSE) -> 1.8691504 | P13: =VLOOKUP(M13,gslb,3,FALSE) -> 10.19 | Q13: =VLOOKUP(M13,gslb,7,FALSE) -> 3.9
A14: =RANK(J14,$J$5:$J$162)+COUNTIF(J$5:J14,J14)-1 -> 60 | B14: =RTD("wdf.rtq",,D14,27)/100 -> -0.0022 | C14: =RTD("wdf.rtq",,D14,"LastPrice") -> 27.53 | D14: =公司名单!D11 -> 600332.SH | E14: =公司名单!C11 -> 白云山 | F14: =公司名单!E11 -> 0874.HK | G14: =IF(RTD("wdf.rtq",,F14,5)=0,[1]!s_dq_preclose(F14),RTD("wdf.rtq",,F14,5)) -> 18.83 | H14: =RTD("wdf.rtq",,F14,27)/100 -> -0.0016 | I14: =C14-G14*HKS_CNY中间价最新 -> 10.382272 | J14: =IF(G14=0,"",(C14/(G14*HKS_CNY中间价最新)-1)) -> 0.60546052 | K14: =IF(G14=0,"",C14/(G14*HKS_CNY中间价最新)) -> 1.6054605 | M14: 5 | N14: =VLOOKUP(M14,gslb,5,FALSE) -> 石化油服 | O14: =VLOOKUP(M14,gslb,10,FALSE) -> 1.8390023 | P14: =VLOOKUP(M14,gslb,3,FALSE) -> 2.12 | Q14: =VLOOKUP(M14,gslb,7,FALSE) -> 0.82
A15: =RANK(J15,$J$5:$J$162)+COUNTIF(J$5:J15,J15)-1 -> 70 | B15: =RTD("wdf.rtq",,D15,27)/100 -> -0.0311 | C15: =RTD("wdf.rtq",,D15,"LastPrice") -> 30.83 | D15: =公司名单!D12 -> 300759.SZ | E15: =公司名单!C12 -> 康龙化成 | F15: =公司名单!E12 -> 3759.HK | G15: =IF(RTD("wdf.rtq",,F15,5)=0,[1]!s_dq_preclose(F15),RTD("wdf.rtq",,F15,5)) -> 22.1 | H15: =RTD("wdf.rtq",,F15,27)/100 -> -0.0383 | I15: =C15-G15*HKS_CNY中间价最新 -> 10.704414 | J15: =IF(G15=0,"",(C15/(G15*HKS_CNY中间价最新)-1)) -> 0.53188086 | K15: =IF(G15=0,"",C15/(G15*HKS_CNY中间价最新)) -> 1.5318809 | M15: 6 | N15: =VLOOKUP(M15,gslb,5,FALSE) -> 龙源电力 | O15: =VLOOKUP(M15,gslb,10,FALSE) -> 1.7227859 | P15: =VLOOKUP(M15,gslb,3,FALSE) -> 16.96 | Q15: =VLOOKUP(M15,gslb,7,FALSE) -> 6.84
A16: =RANK(J16,$J$5:$J$162)+COUNTIF(J$5:J16,J16)-1 -> 65 | B16: =RTD("wdf.rtq",,D16,27)/100 -> -0.022 | C16: =RTD("wdf.rtq",,D16,"LastPrice") -> 11.98 | D16: =公司名单!D13 -> 600958.SH | E16: =公司名单!C13 -> 东方证券 | F16: =公司名单!E13 -> 3958.HK | G16: =IF(RTD("wdf.rtq",,F16,5)=0,[1]!s_dq_preclose(F16),RTD("wdf.rtq",,F16,5)) -> 8.46 | H16: =RTD("wdf.rtq",,F16,27)/100 -> -0.014 | I16: =C16-G16*HKS_CNY中间价最新 -> 4.2758164 | J16: =IF(G16=0,"",(C16/(G16*HKS_CNY中间价最新)-1)) -> 0.55499929 | K16: =IF(G16=0,"",C16/(G16*HKS_CNY中间价最新)) -> 1.5549993 | M16: 7 | N16: =VLOOKUP(M16,gslb,5,FALSE) -> ST晨鸣 | O16: =VLOOKUP(M16,gslb,10,FALSE) -> 1.6603567 | P16: =VLOOKUP(M16,gslb,3,FALSE) -> 2.35 | Q16: =VLOOKUP(M16,gslb,7,FALSE) -> 0.97
A17: =RANK(J17,$J$5:$J$162)+COUNTIF(J$5:J17,J17)-1 -> 13 | B17: =RTD("wdf.rtq",,D17,27)/100 -> -0.0098 | C17: =RTD("wdf.rtq",,D17,"LastPrice") -> 8.05 | D17: =公司名单!D14 -> 601238.SH | E17: =公司名单!C14 -> 广汽集团 | F17: =公司名单!E14 -> 2238.HK | G17: =IF(RTD("wdf.rtq",,F17,5)=0,[1]!s_dq_preclose(F17),RTD("wdf.rtq",,F17,5)) -> 3.75 | H17: =RTD("wdf.rtq",,F17,27)/100 -> 0.0081 | I17: =C17-G17*HKS_CNY中间价最新 -> 4.635025 | J17: =IF(G17=0,"",(C17/(G17*HKS_CNY中间价最新)-1)) -> 1.3572647 | K17: =IF(G17=0,"",C17/(G17*HKS_CNY中间价最新)) -> 2.3572647 | M17: 8 | N17: =VLOOKUP(M17,gslb,5,FALSE) -> 凯盛新能 | O17: =VLOOKUP(M17,gslb,10,FALSE) -> 1.6415129 | P17: =VLOOKUP(M17,gslb,3,FALSE) -> 11.33 | Q17: =VLOOKUP(M17,gslb,7,FALSE) -> 4.71
A18: =RANK(J18,$J$5:$J$162)+COUNTIF(J$5:J18,J18)-1 -> 56 | B18: =RTD("wdf.rtq",,D18,27)/100 -> -0.0046 | C18: =RTD("wdf.rtq",,D18,"LastPrice") -> 10.75 | D18: =公司名单!D15 -> 600026.SH | E18: =公司名单!C15 -> 中远海能 | F18: =公司名单!E15 -> 1138.HK | G18: =IF(RTD("wdf.rtq",,F18,5)=0,[1]!s_dq_preclose(F18),RTD("wdf.rtq",,F18,5)) -> 7.18 | H18: =RTD("wdf.rtq",,F18,27)/100 -> 0.0056 | I18: =C18-G18*HKS_CNY中间价最新 -> 4.2114612 | J18: =IF(G18=0,"",(C18/(G18*HKS_CNY中间价最新)-1)) -> 0.64409822 | K18: =IF(G18=0,"",C18/(G18*HKS_CNY中间价最新)) -> 1.6440982 | M18: 9 | N18: =VLOOKUP(M18,gslb,5,FALSE) -> 上海电气 | O18: =VLOOKUP(M18,gslb,10,FALSE) -> 1.5804026 | P18: =VLOOKUP(M18,gslb,3,FALSE) -> 9 | Q18: =VLOOKUP(M18,gslb,7,FALSE) -> 3.83
A19: =RANK(J19,$J$5:$J$162)+COUNTIF(J$5:J19,J19)-1 -> 77 | B19: =RTD("wdf.rtq",,D19,27)/100 -> -0.0313 | C19: =RTD("wdf.rtq",,D19,"LastPrice") -> 45.16 | D19: =公司名单!D16 -> 688180.SH | E19: =公司名单!C16 -> 君实生物-U | F19: =公司名单!E16 -> 1877.HK | G19: =IF(RTD("wdf.rtq",,F19,5)=0,[1]!s_dq_preclose(F19),RTD("wdf.rtq",,F19,5)) -> 33.32 | H19: =RTD("wdf.rtq",,F19,27)/100 -> -0.0436 | I19: =C19-G19*HKS_CNY中间价最新 -> 14.816809 | J19: =IF(G19=0,"",(C19/(G19*HKS_CNY中间价最新)-1)) -> 0.48830753 | K19: =IF(G19=0,"",C19/(G19*HKS_CNY中间价最新)) -> 1.4883075 | M19: 10 | N19: =VLOOKUP(M19,gslb,5,FALSE) -> 浙江世宝 | O19: =VLOOKUP(M19,gslb,10,FALSE) -> 1.5609299 | P19: =VLOOKUP(M19,gslb,3,FALSE) -> 12.99 | Q19: =VLOOKUP(M19,gslb,7,FALSE) -> 5.57
A20: =RANK(J20,$J$5:$J$162)+COUNTIF(J$5:J20,J20)-1 -> 118 | B20: =RTD("wdf.rtq",,D20,27)/100 -> -0.0121 | C20: =RTD("wdf.rtq",,D20,"LastPrice") -> 22.03 | D20: =公司名单!D17 -> 000776.SZ | E20: =公司名单!C17 -> 广发证券 | F20: =公司名单!E17 -> 1776.HK | G20: =IF(RTD("wdf.rtq",,F20,5)=0,[1]!s_dq_preclose(F20),RTD("wdf.rtq",,F20,5)) -> 19.27 | H20: =RTD("wdf.rtq",,F20,27)/100 -> -0.0057 | I20: =C20-G20*HKS_CNY中间价最新 -> 4.4815818 | J20: =IF(G20=0,"",(C20/(G20*HKS_CNY中间价最新)-1)) -> 0.2553838 | K20: =IF(G20=0,"",C20/(G20*HKS_CNY中间价最新)) -> 1.2553838
A21: =RANK(J21,$J$5:$J$162)+COUNTIF(J$5:J21,J21)-1 -> 47 | B21: =RTD("wdf.rtq",,D21,27)/100 -> 0.1 | C21: =RTD("wdf.rtq",,D21,"LastPrice") -> 71.07 | D21: =公司名单!D18 -> 601869.SH | E21: =公司名单!C18 -> XD长飞光 | F21: =公司名单!E18 -> 6869.HK | G21: =IF(RTD("wdf.rtq",,F21,5)=0,[1]!s_dq_preclose(F21),RTD("wdf.rtq",,F21,5)) -> 45.26 | H21: =RTD("wdf.rtq",,F21,27)/100 -> -0.0329 | I21: =C21-G21*HKS_CNY中间价最新 -> 29.853528 | J21: =IF(G21=0,"",(C21/(G21*HKS_CNY中间价最新)-1)) -> 0.72431063 | K21: =IF(G21=0,"",C21/(G21*HKS_CNY中间价最新)) -> 1.7243106
A22: =RANK(J22,$J$5:$J$162)+COUNTIF(J$5:J22,J22)-1 -> 90 | B22: =RTD("wdf.rtq",,D22,27)/100 -> -0.0373 | C22: =RTD("wdf.rtq",,D22,"LastPrice") -> 66.09 | D22: =公司名单!D19 -> 300347.SZ | E22: =公司名单!C19 -> 泰格医药 | F22: =公司名单!E19 -> 3347.HK | G22: =IF(RTD("wdf.rtq",,F22,5)=0,[1]!s_dq_preclose(F22),RTD("wdf.rtq",,F22,5)) -> 51.45 | H22: =RTD("wdf.rtq",,F22,27)/100 -> -0.0302 | I22: =C22-G22*HKS_CNY中间价最新 -> 19.236543 | J22: =IF(G22=0,"",(C22/(G22*HKS_CNY中间价最新)-1)) -> 0.41056827 | K22: =IF(G22=0,"",C22/(G22*HKS_CNY中间价最新)) -> 1.4105683 | M22: 最低溢价
A23: =RANK(J23,$J$5:$J$162)+COUNTIF(J$5:J23,J23)-1 -> 10 | B23: =RTD("wdf.rtq",,D23,27)/100 -> 0.0062 | C23: =RTD("wdf.rtq",,D23,"LastPrice") -> 12.99 | D23: =公司名单!D20 -> 002703.SZ | E23: =公司名单!C20 -> 浙江世宝 | F23: =公司名单!E20 -> 1057.HK | G23: =IF(RTD("wdf.rtq",,F23,5)=0,[1]!s_dq_preclose(F23),RTD("wdf.rtq",,F23,5)) -> 5.57 | H23: =RTD("wdf.rtq",,F23,27)/100 -> -0.0176 | I23: =C23-G23*HKS_CNY中间价最新 -> 7.9176238 | J23: =IF(G23=0,"",(C23/(G23*HKS_CNY中间价最新)-1)) -> 1.5609299 | K23: =IF(G23=0,"",C23/(G23*HKS_CNY中间价最新)) -> 2.5609299 | M23: 序号 | N23: 公司名称 | O23: A-H溢价% | P23: A股价格[CNY] | Q23: H股价格[HKD]
A24: =RANK(J24,$J$5:$J$162)+COUNTIF(J$5:J24,J24)-1 -> 102 | B24: =RTD("wdf.rtq",,D24,27)/100 -> -0.0018 | C24: =RTD("wdf.rtq",,D24,"LastPrice") -> 5.48 | D24: =公司名单!D21 -> 600027.SH | E24: =公司名单!C21 -> 华电国际 | F24: =公司名单!E21 -> 1071.HK | G24: =IF(RTD("wdf.rtq",,F24,5)=0,[1]!s_dq_preclose(F24),RTD("wdf.rtq",,F24,5)) -> 4.49 | H24: =RTD("wdf.rtq",,F24,27)/100 -> 0 | I24: =C24-G24*HKS_CNY中间价最新 -> 1.3911366 | J24: =IF(G24=0,"",(C24/(G24*HKS_CNY中间价最新)-1)) -> 0.34022575 | K24: =IF(G24=0,"",C24/(G24*HKS_CNY中间价最新)) -> 1.3402257 | M24: 1 | N24: =VLOOKUP(COUNTA($A$5:$A$155)-M24+1,gslb,5,FALSE) -> 荣昌生物 | O24: =VLOOKUP(COUNTA($A$5:$A$155)-M24+1,gslb,10,FALSE) -> 0.035719243 | P24: =VLOOKUP(COUNTA($A$5:$A$155)-M24+1,gslb,3,FALSE) -> 85.5 | Q24: =VLOOKUP(COUNTA($A$5:$A$155)-M24+1,gslb,7,FALSE) -> 90.65
A25: =RANK(J25,$J$5:$J$162)+COUNTIF(J$5:J25,J25)-1 -> 61 | B25: =RTD("wdf.rtq",,D25,27)/100 -> -0.0032 | C25: =RTD("wdf.rtq",,D25,"LastPrice") -> 6.2 | D25: =公司名单!D22 -> 002490.SZ | E25: =公司名单!C22 -> 山东墨龙 | F25: =公司名单!E22 -> 0568.HK | G25: =IF(RTD("wdf.rtq",,F25,5)=0,[1]!s_dq_preclose(F25),RTD("wdf.rtq",,F25,5)) -> 4.29 | H25: =RTD("wdf.rtq",,F25,27)/100 -> 0.0118 | I25: =C25-G25*HKS_CNY中间价最新 -> 2.2932686 | J25: =IF(G25=0,"",(C25/(G25*HKS_CNY中间价最新)-1)) -> 0.58700442 | K25: =IF(G25=0,"",C25/(G25*HKS_CNY中间价最新)) -> 1.5870044 | M25: 2 | N25: =VLOOKUP(COUNTA($A$5:$A$155)-M25+1,gslb,5,FALSE) -> 亿华通-U | O25: =VLOOKUP(COUNTA($A$5:$A$155)-M25+1,gslb,10,FALSE) -> 0.041159615 | P25: =VLOOKUP(COUNTA($A$5:$A$155)-M25+1,gslb,3,FALSE) -> 24.5 | Q25: =VLOOKUP(COUNTA($A$5:$A$155)-M25+1,gslb,7,FALSE) -> 25.84
A26: =RANK(J26,$J$5:$J$162)+COUNTIF(J$5:J26,J26)-1 -> 79 | B26: =RTD("wdf.rtq",,D26,27)/100 -> -0.0033 | C26: =RTD("wdf.rtq",,D26,"LastPrice") -> 67.08 | D26: =公司名单!D23 -> 601336.SH | E26: =公司名单!C23 -> 新华保险 | F26: =公司名单!E23 -> 1336.HK | G26: =IF(RTD("wdf.rtq",,F26,5)=0,[1]!s_dq_preclose(F26),RTD("wdf.rtq",,F26,5)) -> 49.84 | H26: =RTD("wdf.rtq",,F26,27)/100 -> -0.0052 | I26: =C26-G26*HKS_CNY中间价最新 -> 21.692706 | J26: =IF(G26=0,"",(C26/(G26*HKS_CNY中间价最新)-1)) -> 0.47794666 | K26: =IF(G26=0,"",C26/(G26*HKS_CNY中间价最新)) -> 1.4779467 | M26: 3 | N26: =VLOOKUP(COUNTA($A$5:$A$155)-M26+1,gslb,5,FALSE) -> 比亚迪 | O26: =VLOOKUP(COUNTA($A$5:$A$155)-M26+1,gslb,10,FALSE) -> 0.04872681 | P26: =VLOOKUP(COUNTA($A$5:$A$155)-M26+1,gslb,3,FALSE) -> 113.84 | Q26: =VLOOKUP(COUNTA($A$5:$A$155)-M26+1,gslb,7,FALSE) -> 119.2
A27: =RANK(J27,$J$5:$J$162)+COUNTIF(J$5:J27,J27)-1 -> 137 | B27: =RTD("wdf.rtq",,D27,27)/100 -> -0.0004 | C27: =RTD("wdf.rtq",,D27,"LastPrice") -> 22.32 | D27: =公司名单!D24 -> 601688.SH | E27: =公司名单!C24 -> 华泰证券 | F27: =公司名单!E24 -> 6886.HK | G27: =IF(RTD("wdf.rtq",,F27,5)=0,[1]!s_dq_preclose(F27),RTD("wdf.rtq",,F27,5)) -> 21.06 | H27: =RTD("wdf.rtq",,F27,27)/100 -> -0.0028 | I27: =C27-G27*HKS_CNY中间价最新 -> 3.1415004 | J27: =IF(G27=0,"",(C27/(G27*HKS_CNY中间价最新)-1)) -> 0.16380324 | K27: =IF(G27=0,"",C27/(G27*HKS_CNY中间价最新)) -> 1.1638032 | M27: 4 | N27: =VLOOKUP(COUNTA($A$5:$A$155)-M27+1,gslb,5,FALSE) -> 中集集团 | O27: =VLOOKUP(COUNTA($A$5:$A$155)-M27+1,gslb,10,FALSE) -> 0.083724729 | P27: =VLOOKUP(COUNTA($A$5:$A$155)-M27+1,gslb,3,FALSE) -> 8.29 | Q27: =VLOOKUP(COUNTA($A$5:$A$155)-M27+1,gslb,7,FALSE) -> 8.4
A28: =RANK(J28,$J$5:$J$162)+COUNTIF(J$5:J28,J28)-1 -> 31 | B28: =RTD("wdf.rtq",,D28,27)/100 -> 0.0057 | C28: =RTD("wdf.rtq",,D28,"LastPrice") -> 12.29 | D28: =公司名单!D25 -> 601456.SH | E28: =公司名单!C25 -> 国联民生 | F28: =公司名单!E25 -> 1456.HK | G28: =IF(RTD("wdf.rtq",,F28,5)=0,[1]!s_dq_preclose(F28),RTD("wdf.rtq",,F28,5)) -> 6.84 | H28: =RTD("wdf.rtq",,F28,27)/100 -> -0.0229 | I28: =C28-G28*HKS_CNY中间价最新 -> 6.0610856 | J28: =IF(G28=0,"",(C28/(G28*HKS_CNY中间价最新)-1)) -> 0.97305649 | K28: =IF(G28=0,"",C28/(G28*HKS_CNY中间价最新)) -> 1.9730565 | M28: 5 | N28: =VLOOKUP(COUNTA($A$5:$A$155)-M28+1,gslb,5,FALSE) -> 海尔智家 | O28: =VLOOKUP(COUNTA($A$5:$A$155)-M28+1,gslb,10,FALSE) -> 0.096439615 | P28: =VLOOKUP(COUNTA($A$5:$A$155)-M28+1,gslb,3,FALSE) -> 26.34 | Q28: =VLOOKUP(COUNTA($A$5:$A$155)-M28+1,gslb,7,FALSE) -> 26.38
A29: =RANK(J29,$J$5:$J$162)+COUNTIF(J$5:J29,J29)-1 -> 57 | B29: =RTD("wdf.rtq",,D29,27)/100 -> -0.0047 | C29: =RTD("wdf.rtq",,D29,"LastPrice") -> 2.12 | D29: =公司名单!D26 -> 002936.SZ | E29: =公司名单!C26 -> 郑州银行 | F29: =公司名单!E26 -> 6196.HK | G29: =IF(RTD("wdf.rtq",,F29,5)=0,[1]!s_dq_preclose(F29),RTD("wdf.rtq",,F29,5)) -> 1.42 | H29: =RTD("wdf.rtq",,F29,27)/100 -> 0.0071 | I29: =C29-G29*HKS_CNY中间价最新 -> 0.8268628 | J29: =IF(G29=0,"",(C29/(G29*HKS_CNY中间价最新)-1)) -> 0.63942388 | K29: =IF(G29=0,"",C29/(G29*HKS_CNY中间价最新)) -> 1.6394239 | M29: 6 | N29: =VLOOKUP(COUNTA($A$5:$A$155)-M29+1,gslb,5,FALSE) -> 吉宏股份 | O29: =VLOOKUP(COUNTA($A$5:$A$155)-M29+1,gslb,10,FALSE) -> 0.10339533 | P29: =VLOOKUP(COUNTA($A$5:$A$155)-M29+1,gslb,3,FALSE) -> 18.77 | Q29: =VLOOKUP(COUNTA($A$5:$A$155)-M29+1,gslb,7,FALSE) -> 18.68
A30: =RANK(J30,$J$5:$J$162)+COUNTIF(J$5:J30,J30)-1 -> 66 | B30: =RTD("wdf.rtq",,D30,27)/100 -> -0.006 | C30: =RTD("wdf.rtq",,D30,"LastPrice") -> 8.27 | D30: =公司名单!D27 -> 601186.SH | E30: =公司名单!C27 -> 中国铁建 | F30: =公司名单!E27 -> 1186.HK | G30: =IF(RTD("wdf.rtq",,F30,5)=0,[1]!s_dq_preclose(F30),RTD("wdf.rtq",,F30,5)) -> 5.85 | H30: =RTD("wdf.rtq",,F30,27)/100 -> -0.0085 | I30: =C30-G30*HKS_CNY中间价最新 -> 2.942639 | J30: =IF(G30=0,"",(C30/(G30*HKS_CNY中间价最新)-1)) -> 0.55236336 | K30: =IF(G30=0,"",C30/(G30*HKS_CNY中间价最新)) -> 1.5523634 | M30: 7 | N30: =VLOOKUP(COUNTA($A$5:$A$155)-M30+1,gslb,5,FALSE) -> 洛阳钼业 | O30: =VLOOKUP(COUNTA($A$5:$A$155)-M30+1,gslb,10,FALSE) -> 0.10823819 | P30: =VLOOKUP(COUNTA($A$5:$A$155)-M30+1,gslb,3,FALSE) -> 12.03 | Q30: =VLOOKUP(COUNTA($A$5:$A$155)-M30+1,gslb,7,FALSE) -> 11.92
A31: =RANK(J31,$J$5:$J$162)+COUNTIF(J$5:J31,J31)-1 -> 28 | B31: =RTD("wdf.rtq",,D31,27)/100 -> 0.0044 | C31: =RTD("wdf.rtq",,D31,"LastPrice") -> 13.71 | D31: =公司名单!D28 -> 601038.SH | E31: =公司名单!C28 -> 一拖股份 | F31: =公司名单!E28 -> 0038.HK | G31: =IF(RTD("wdf.rtq",,F31,5)=0,[1]!s_dq_preclose(F31),RTD("wdf.rtq",,F31,5)) -> 7.53 | H31: =RTD("wdf.rtq",,F31,27)/100 -> -0.0066 | I31: =C31-G31*HKS_CNY中间价最新 -> 6.8527302 | J31: =IF(G31=0,"",(C31/(G31*HKS_CNY中间价最新)-1)) -> 0.99933799 | K31: =IF(G31=0,"",C31/(G31*HKS_CNY中间价最新)) -> 1.999338 | M31: 8 | N31: =VLOOKUP(COUNTA($A$5:$A$155)-M31+1,gslb,5,FALSE) -> 赤峰黄金 | O31: =VLOOKUP(COUNTA($A$5:$A$155)-M31+1,gslb,10,FALSE) -> 0.11866679 | P31: =VLOOKUP(COUNTA($A$5:$A$155)-M31+1,gslb,3,FALSE) -> 25.57 | Q31: =VLOOKUP(COUNTA($A$5:$A$155)-M31+1,gslb,7,FALSE) -> 25.1
A32: =RANK(J32,$J$5:$J$162)+COUNTIF(J$5:J32,J32)-1 -> 6 | B32: =RTD("wdf.rtq",,D32,27)/100 -> 0.003 | C32: =RTD("wdf.rtq",,D32,"LastPrice") -> 16.96 | D32: =公司名单!D29 -> 001289.SZ | E32: =公司名单!C29 -> 龙源电力 | F32: =公司名单!E29 -> 0916.HK | G32: =IF(RTD("wdf.rtq",,F32,5)=0,[1]!s_dq_preclose(F32),RTD("wdf.rtq",,F32,5)) -> 6.84 | H32: =RTD("wdf.rtq",,F32,27)/100 -> -0.0044 | I32: =C32-G32*HKS_CNY中间价最新 -> 10.731086 | J32: =IF(G32=0,"",(C32/(G32*HKS_CNY中间价最新)-1)) -> 1.7227859 | K32: =IF(G32=0,"",C32/(G32*HKS_CNY中间价最新)) -> 2.7227859 | M32: 9 | N32: =VLOOKUP(COUNTA($A$5:$A$155)-M32+1,gslb,5,FALSE) -> 海螺水泥 | O32: =VLOOKUP(COUNTA($A$5:$A$155)-M32+1,gslb,10,FALSE) -> 0.11988526 | P32: =VLOOKUP(COUNTA($A$5:$A$155)-M32+1,gslb,3,FALSE) -> 24.68 | Q32: =VLOOKUP(COUNTA($A$5:$A$155)-M32+1,gslb,7,FALSE) -> 24.2
A33: =RANK(J33,$J$5:$J$162)+COUNTIF(J$5:J33,J33)-1 -> 151 | B33: =RTD("wdf.rtq",,D33,27)/100 -> 0.0404 | C33: =RTD("wdf.rtq",,D33,"LastPrice") -> 85.5 | D33: =公司名单!D30 -> 688331.SH | E33: =公司名单!C30 -> 荣昌生物 | F33: =公司名单!E30 -> 9995.HK | G33: =IF(RTD("wdf.rtq",,F33,5)=0,[1]!s_dq_preclose(F33),RTD("wdf.rtq",,F33,5)) -> 90.65 | H33: =RTD("wdf.rtq",,F33,27)/100 -> 0.022 | I33: =C33-G33*HKS_CNY中间价最新 -> 2.948671 | J33: =IF(G33=0,"",(C33/(G33*HKS_CNY中间价最新)-1)) -> 0.035719243 | K33: =IF(G33=0,"",C33/(G33*HKS_CNY中间价最新)) -> 1.0357192 | M33: 10 | N33: =VLOOKUP(COUNTA($A$5:$A$155)-M33+1,gslb,5,FALSE) -> 三花智控 | O33: =VLOOKUP(COUNTA($A$5:$A$155)-M33+1,gslb,10,FALSE) -> 0.13304102 | P33: =VLOOKUP(COUNTA($A$5:$A$155)-M33+1,gslb,3,FALSE) -> 30.81 | Q33: =VLOOKUP(COUNTA($A$5:$A$155)-M33+1,gslb,7,FALSE) -> 29.86
A34: =RANK(J34,$J$5:$J$162)+COUNTIF(J$5:J34,J34)-1 -> 92 | B34: =RTD("wdf.rtq",,D34,27)/100 -> -0.0092 | C34: =RTD("wdf.rtq",,D34,"LastPrice") -> 45.42 | D34: =公司名单!D31 -> 000063.SZ | E34: =公司名单!C31 -> 中兴通讯 | F34: =公司名单!E31 -> 0763.HK | G34: =IF(RTD("wdf.rtq",,F34,5)=0,[1]!s_dq_preclose(F34),RTD("wdf.rtq",,F34,5)) -> 35.6 | H34: =RTD("wdf.rtq",,F34,27)/100 -> -0.0404 | I34: =C34-G34*HKS_CNY中间价最新 -> 13.000504 | J34: =IF(G34=0,"",(C34/(G34*HKS_CNY中间价最新)-1)) -> 0.40100883 | K34: =IF(G34=0,"",C34/(G34*HKS_CNY中间价最新)) -> 1.4010088
A35: =RANK(J35,$J$5:$J$162)+COUNTIF(J$5:J35,J35)-1 -> 123 | B35: =RTD("wdf.rtq",,D35,27)/100 -> 0.0116 | C35: =RTD("wdf.rtq",,D35,"LastPrice") -> 32.33 | D35: =公司名单!D32 -> 600547.SH | E35: =公司名单!C32 -> 山东黄金 | F35: =公司名单!E32 -> 1787.HK | G35: =IF(RTD("wdf.rtq",,F35,5)=0,[1]!s_dq_preclose(F35),RTD("wdf.rtq",,F35,5)) -> 28.7 | H35: =RTD("wdf.rtq",,F35,27)/100 -> 0.0368 | I35: =C35-G35*HKS_CNY中间价最新 -> 6.194058 | J35: =IF(G35=0,"",(C35/(G35*HKS_CNY中间价最新)-1)) -> 0.23699387 | K35: =IF(G35=0,"",C35/(G35*HKS_CNY中间价最新)) -> 1.2369939
A36: =RANK(J36,$J$5:$J$162)+COUNTIF(J$5:J36,J36)-1 -> 62 | B36: =RTD("wdf.rtq",,D36,27)/100 -> 0.0081 | C36: =RTD("wdf.rtq",,D36,"LastPrice") -> 14.97 | D36: =公司名单!D33 -> 603906.SH | E36: =公司名单!C33 -> 龙蟠科技 | F36: =公司名单!E33 -> 2465.HK | G36: =IF(RTD("wdf.rtq",,F36,5)=0,[1]!s_dq_preclose(F36),RTD("wdf.rtq",,F36,5)) -> 10.43 | H36: =RTD("wdf.rtq",,F36,27)/100 -> 0.0753 | I36: =C36-G36*HKS_CNY中间价最新 -> 5.4718162 | J36: =IF(G36=0,"",(C36/(G36*HKS_CNY中间价最新)-1)) -> 0.57609079 | K36: =IF(G36=0,"",C36/(G36*HKS_CNY中间价最新)) -> 1.5760908
A37: =RANK(J37,$J$5:$J$162)+COUNTIF(J$5:J37,J37)-1 -> 103 | B37: =RTD("wdf.rtq",,D37,27)/100 -> -0.0026 | C37: =RTD("wdf.rtq",,D37,"LastPrice") -> 3.81 | D37: =公司名单!D34 -> 003816.SZ | E37: =公司名单!C34 -> 中国广核 | F37: =公司名单!E34 -> 1816.HK | G37: =IF(RTD("wdf.rtq",,F37,5)=0,[1]!s_dq_preclose(F37),RTD("wdf.rtq",,F37,5)) -> 3.13 | H37: =RTD("wdf.rtq",,F37,27)/100 -> -0.0063 | I37: =C37-G37*HKS_CNY中间价最新 -> 0.9596342 | J37: =IF(G37=0,"",(C37/(G37*HKS_CNY中间价最新)-1)) -> 0.33667054 | K37: =IF(G37=0,"",C37/(G37*HKS_CNY中间价最新)) -> 1.3366705
A38: =RANK(J38,$J$5:$J$162)+COUNTIF(J$5:J38,J38)-1 -> 101 | B38: =RTD("wdf.rtq",,D38,27)/100 -> -0.0251 | C38: =RTD("wdf.rtq",,D38,"LastPrice") -> 6.98 | D38: =公司名单!D35 -> 000002.SZ | E38: =公司名单!C35 -> 万 科Ａ | F38: =公司名单!E35 -> 2202.HK | G38: =IF(RTD("wdf.rtq",,F38,5)=0,[1]!s_dq_preclose(F38),RTD("wdf.rtq",,F38,5)) -> 5.68 | H38: =RTD("wdf.rtq",,F38,27)/100 -> 0 | I38: =C38-G38*HKS_CNY中间价最新 -> 1.8074512 | J38: =IF(G38=0,"",(C38/(G38*HKS_CNY中间价最新)-1)) -> 0.34943144 | K38: =IF(G38=0,"",C38/(G38*HKS_CNY中间价最新)) -> 1.3494314
A39: =RANK(J39,$J$5:$J$162)+COUNTIF(J$5:J39,J39)-1 -> 69 | B39: =RTD("wdf.rtq",,D39,27)/100 -> 0.0246 | C39: =RTD("wdf.rtq",,D39,"LastPrice") -> 26.29 | D39: =公司名单!D36 -> 601633.SH | E39: =公司名单!C36 -> 长城汽车 | F39: =公司名单!E36 -> 2333.HK | G39: =IF(RTD("wdf.rtq",,F39,5)=0,[1]!s_dq_preclose(F39),RTD("wdf.rtq",,F39,5)) -> 18.8 | H39: =RTD("wdf.rtq",,F39,27)/100 -> 0.0387 | I39: =C39-G39*HKS_CNY中间价最新 -> 9.169592 | J39: =IF(G39=0,"",(C39/(G39*HKS_CNY中间价最新)-1)) -> 0.53559425 | K39: =IF(G39=0,"",C39/(G39*HKS_CNY中间价最新)) -> 1.5355942
A40: =RANK(J40,$J$5:$J$162)+COUNTIF(J$5:J40,J40)-1 -> 81 | B40: =RTD("wdf.rtq",,D40,27)/100 -> 0.0025 | C40: =RTD("wdf.rtq",,D40,"LastPrice") -> 16.11 | D40: =公司名单!D37 -> 601811.SH | E40: =公司名单!C37 -> 新华文轩 | F40: =公司名单!E37 -> 0811.HK | G40: =IF(RTD("wdf.rtq",,F40,5)=0,[1]!s_dq_preclose(F40),RTD("wdf.rtq",,F40,5)) -> 12.16 | H40: =RTD("wdf.rtq",,F40,27)/100 -> -0.0073 | I40: =C40-G40*HKS_CNY中间价最新 -> 5.0363744 | J40: =IF(G40=0,"",(C40/(G40*HKS_CNY中间价最新)-1)) -> 0.45480808 | K40: =IF(G40=0,"",C40/(G40*HKS_CNY中间价最新)) -> 1.4548081
A41: =RANK(J41,$J$5:$J$162)+COUNTIF(J$5:J41,J41)-1 -> 49 | B41: =RTD("wdf.rtq",,D41,27)/100 -> -0.0126 | C41: =RTD("wdf.rtq",,D41,"LastPrice") -> 18.76 | D41: =公司名单!D38 -> 601881.SH | E41: =公司名单!C38 -> 中国银河 | F41: =公司名单!E38 -> 6881.HK | G41: =IF(RTD("wdf.rtq",,F41,5)=0,[1]!s_dq_preclose(F41),RTD("wdf.rtq",,F41,5)) -> 12.23 | H41: =RTD("wdf.rtq",,F41,27)/100 -> -0.0216 | I41: =C41-G41*HKS_CNY中间价最新 -> 7.6226282 | J41: =IF(G41=0,"",(C41/(G41*HKS_CNY中间价最新)-1)) -> 0.68441894 | K41: =IF(G41=0,"",C41/(G41*HKS_CNY中间价最新)) -> 1.6844189
A42: =RANK(J42,$J$5:$J$162)+COUNTIF(J$5:J42,J42)-1 -> 40 | B42: =RTD("wdf.rtq",,D42,27)/100 -> -0.0093 | C42: =RTD("wdf.rtq",,D42,"LastPrice") -> 9.54 | D42: =公司名单!D39 -> 601800.SH | E42: =公司名单!C39 -> 中国交建 | F42: =公司名单!E39 -> 1800.HK | G42: =IF(RTD("wdf.rtq",,F42,5)=0,[1]!s_dq_preclose(F42),RTD("wdf.rtq",,F42,5)) -> 5.83 | H42: =RTD("wdf.rtq",,F42,27)/100 -> -0.0085 | I42: =C42-G42*HKS_CNY中间价最新 -> 4.2308522 | J42: =IF(G42=0,"",(C42/(G42*HKS_CNY中间价最新)-1)) -> 0.79689855 | K42: =IF(G42=0,"",C42/(G42*HKS_CNY中间价最新)) -> 1.7968986
...

Sheet 溢价变动趋势
D1: AH股溢价分析
O4: AH股价格走势
A5: 1
F6: A股代码： | G6: =windcodea -> 601728.SH
F7: H股代码： | G7: =windcodeh -> 0728.HK
F8: 币种： | G8: 人民币
F9: 行情周期： | G9: 周
B16: =company -> 中国电信
B18: 日期 | C18: A股价格 | D18: A股价格 | E18: H股价格 | F18: H股价格 | G18: A-H溢价(%) | H18: 汇率
B19: =--[1]!td(TODAY()-1) -> 45894 | C19: =IF(BZ="港币",D19/H19,D19) -> 7.67 | D19: =[1]!s_dq_close(wcodea,B19,1) -> 7.67 | E19: =IF(BZ="人民币",F19*H19,F19) -> 5.6734118 | F19: =[1]!s_dq_close(wcodeh,B19,1) -> 6.23 | G19: =IF(BZ="人民币",100*(D19/E19-1),100*(C19/E19-1)) -> 35.19202 | H19: =VLOOKUP(B19,hl,2,FALSE) -> 0.91066
B20: =--IF(QJ="日",[1]!td(B19-1),IF(QJ="周",[1]!td(B19-7),[1]!td(B19-30))) -> 45887 | C20: =IF(BZ="港币",D20/H20,D20) -> 7.47 | D20: =[1]!s_dq_close(wcodea,B20,1) -> 7.47 | E20: =IF(BZ="人民币",F20*H20,F20) -> 5.830912 | F20: =[1]!s_dq_close(wcodeh,B20,1) -> 6.4 | G20: =IF(BZ="人民币",100*(D20/E20-1),100*(C20/E20-1)) -> 28.11032 | H20: =VLOOKUP(B20,hl,2,FALSE) -> 0.91108
B21: =--IF(QJ="日",[1]!td(B20-1),IF(QJ="周",[1]!td(B20-7),[1]!td(B20-30))) -> 45880 | C21: =IF(BZ="港币",D21/H21,D21) -> 7.38 | D21: =[1]!s_dq_close(wcodea,B21,1) -> 7.38 | E21: =IF(BZ="人民币",F21*H21,F21) -> 5.639768 | F21: =[1]!s_dq_close(wcodeh,B21,1) -> 6.2 | G21: =IF(BZ="人民币",100*(D21/E21-1),100*(C21/E21-1)) -> 30.856447 | H21: =VLOOKUP(B21,hl,2,FALSE) -> 0.90964
B22: =--IF(QJ="日",[1]!td(B21-1),IF(QJ="周",[1]!td(B21-7),[1]!td(B21-30))) -> 45873 | C22: =IF(BZ="港币",D22/H22,D22) -> 7.4 | D22: =[1]!s_dq_close(wcodea,B22,1) -> 7.4 | E22: =IF(BZ="人民币",F22*H22,F22) -> 5.4298344 | F22: =[1]!s_dq_close(wcodeh,B22,1) -> 5.97 | G22: =IF(BZ="人民币",100*(D22/E22-1),100*(C22/E22-1)) -> 36.284083 | H22: =VLOOKUP(B22,hl,2,FALSE) -> 0.90952 | O22: A-H股溢价走势
B23: =--IF(QJ="日",[1]!td(B22-1),IF(QJ="周",[1]!td(B22-7),[1]!td(B22-30))) -> 45866 | C23: =IF(BZ="港币",D23/H23,D23) -> 7.3 | D23: =[1]!s_dq_close(wcodea,B23,1) -> 7.3 | E23: =IF(BZ="人民币",F23*H23,F23) -> 5.3264835 | F23: =[1]!s_dq_close(wcodeh,B23,1) -> 5.85 | G23: =IF(BZ="人民币",100*(D23/E23-1),100*(C23/E23-1)) -> 37.051021 | H23: =VLOOKUP(B23,hl,2,FALSE) -> 0.91051
B24: =--IF(QJ="日",[1]!td(B23-1),IF(QJ="周",[1]!td(B23-7),[1]!td(B23-30))) -> 45859 | C24: =IF(BZ="港币",D24/H24,D24) -> 7.59 | D24: =[1]!s_dq_close(wcodea,B24,1) -> 7.59 | E24: =IF(BZ="人民币",F24*H24,F24) -> 5.230575 | F24: =[1]!s_dq_close(wcodeh,B24,1) -> 5.74 | G24: =IF(BZ="人民币",100*(D24/E24-1),100*(C24/E24-1)) -> 45.108329 | H24: =VLOOKUP(B24,hl,2,FALSE) -> 0.91125
B25: =--IF(QJ="日",[1]!td(B24-1),IF(QJ="周",[1]!td(B24-7),[1]!td(B24-30))) -> 45852 | C25: =IF(BZ="港币",D25/H25,D25) -> 7.63 | D25: =[1]!s_dq_close(wcodea,B25,1) -> 7.63 | E25: =IF(BZ="人民币",F25*H25,F25) -> 5.1091392 | F25: =[1]!s_dq_close(wcodeh,B25,1) -> 5.61 | G25: =IF(BZ="人民币",100*(D25/E25-1),100*(C25/E25-1)) -> 49.340225 | H25: =VLOOKUP(B25,hl,2,FALSE) -> 0.91072
B26: =--IF(QJ="日",[1]!td(B25-1),IF(QJ="周",[1]!td(B25-7),[1]!td(B25-30))) -> 45845 | C26: =IF(BZ="港币",D26/H26,D26) -> 7.65 | D26: =[1]!s_dq_close(wcodea,B26,1) -> 7.65 | E26: =IF(BZ="人民币",F26*H26,F26) -> 5.0373876 | F26: =[1]!s_dq_close(wcodeh,B26,1) -> 5.53 | G26: =IF(BZ="人民币",100*(D26/E26-1),100*(C26/E26-1)) -> 51.864431 | H26: =VLOOKUP(B26,hl,2,FALSE) -> 0.91092
B27: =--IF(QJ="日",[1]!td(B26-1),IF(QJ="周",[1]!td(B26-7),[1]!td(B26-30))) -> 45838 | C27: =IF(BZ="港币",D27/H27,D27) -> 7.75 | D27: =[1]!s_dq_close(wcodea,B27,1) -> 7.75 | E27: =IF(BZ="人民币",F27*H27,F27) -> 5.088681 | F27: =[1]!s_dq_close(wcodeh,B27,1) -> 5.58 | G27: =IF(BZ="人民币",100*(D27/E27-1),100*(C27/E27-1)) -> 52.298798 | H27: =VLOOKUP(B27,hl,2,FALSE) -> 0.91195
B28: =--IF(QJ="日",[1]!td(B27-1),IF(QJ="周",[1]!td(B27-7),[1]!td(B27-30))) -> 45831 | C28: =IF(BZ="港币",D28/H28,D28) -> 7.86 | D28: =[1]!s_dq_close(wcodea,B28,1) -> 7.86 | E28: =IF(BZ="人民币",F28*H28,F28) -> 5.115712 | F28: =[1]!s_dq_close(wcodeh,B28,1) -> 5.6 | G28: =IF(BZ="人民币",100*(D28/E28-1),100*(C28/E28-1)) -> 53.644302 | H28: =VLOOKUP(B28,hl,2,FALSE) -> 0.91352
B29: =--IF(QJ="日",[1]!td(B28-1),IF(QJ="周",[1]!td(B28-7),[1]!td(B28-30))) -> 45824 | C29: =IF(BZ="港币",D29/H29,D29) -> 7.75 | D29: =[1]!s_dq_close(wcodea,B29,1) -> 7.75 | E29: =IF(BZ="人民币",F29*H29,F29) -> 5.2587775 | F29: =[1]!s_dq_close(wcodeh,B29,1) -> 5.75 | G29: =IF(BZ="人民币",100*(D29/E29-1),100*(C29/E29-1)) -> 47.372655 | H29: =VLOOKUP(B29,hl,2,FALSE) -> 0.91457
B30: =--IF(QJ="日",[1]!td(B29-1),IF(QJ="周",[1]!td(B29-7),[1]!td(B29-30))) -> 45817 | C30: =IF(BZ="港币",D30/H30,D30) -> 8 | D30: =[1]!s_dq_close(wcodea,B30,1) -> 8 | E30: =IF(BZ="人民币",F30*H30,F30) -> 5.2925148 | F30: =[1]!s_dq_close(wcodeh,B30,1) -> 5.78 | G30: =IF(BZ="人民币",100*(D30/E30-1),100*(C30/E30-1)) -> 51.156875 | H30: =VLOOKUP(B30,hl,2,FALSE) -> 0.91566
B31: =--IF(QJ="日",[1]!td(B30-1),IF(QJ="周",[1]!td(B30-7),[1]!td(B30-30))) -> 45807 | C31: =IF(BZ="港币",D31/H31,D31) -> 8.03 | D31: =[1]!s_dq_close(wcodea,B31,1) -> 8.03 | E31: =IF(BZ="人民币",F31*H31,F31) -> 5.4801916 | F31: =[1]!s_dq_close(wcodeh,B31,1) -> 5.98 | G31: =IF(BZ="人民币",100*(D31/E31-1),100*(C31/E31-1)) -> 46.527724 | H31: =VLOOKUP(B31,hl,2,FALSE) -> 0.91642
B32: =--IF(QJ="日",[1]!td(B31-1),IF(QJ="周",[1]!td(B31-7),[1]!td(B31-30))) -> 45800 | C32: =IF(BZ="港币",D32/H32,D32) -> 7.92 | D32: =[1]!s_dq_close(wcodea,B32,1) -> 7.92 | E32: =IF(BZ="人民币",F32*H32,F32) -> 5.337066 | F32: =[1]!s_dq_close(wcodeh,B32,1) -> 5.81 | G32: =IF(BZ="人民币",100*(D32/E32-1),100*(C32/E32-1)) -> 48.396141 | H32: =VLOOKUP(B32,hl,2,FALSE) -> 0.9186
B33: =--IF(QJ="日",[1]!td(B32-1),IF(QJ="周",[1]!td(B32-7),[1]!td(B32-30))) -> 45793 | C33: =IF(BZ="港币",D33/H33,D33) -> 7.82 | D33: =[1]!s_dq_close(wcodea,B33,1) -> 7.82 | E33: =IF(BZ="人民币",F33*H33,F33) -> 5.1878198 | F33: =[1]!s_dq_close(wcodeh,B33,1) -> 5.63 | G33: =IF(BZ="人民币",100*(D33/E33-1),100*(C33/E33-1)) -> 50.737695 | H33: =VLOOKUP(B33,hl,2,FALSE) -> 0.92146
B34: =--IF(QJ="日",[1]!td(B33-1),IF(QJ="周",[1]!td(B33-7),[1]!td(B33-30))) -> 45786 | C34: =IF(BZ="港币",D34/H34,D34) -> 7.81 | D34: =[1]!s_dq_close(wcodea,B34,1) -> 7.81 | E34: =IF(BZ="人民币",F34*H34,F34) -> 5.194784 | F34: =[1]!s_dq_close(wcodeh,B34,1) -> 5.6 | G34: =IF(BZ="人民币",100*(D34/E34-1),100*(C34/E34-1)) -> 50.343113 | H34: =VLOOKUP(B34,hl,2,FALSE) -> 0.92764
... B118: =--IF(QJ="日",[1]!td(B117-1),IF(QJ="周",[1]!td(B117-7),[1]!td(B117-30))) -> 45169 | C118: =IF(BZ="港币",D118/H118,D118) -> 5.76 | D118: =[1]!s_dq_close(wcodea,B118,1) -> 5.76 | E118: =IF(BZ="人民币",F118*H118,F118) -> 3.432675 | F118: =[1]!s_dq_close(wcodeh,B118,1) -> 3.75 | G118: =IF(BZ="人民币",100*(D118/E118-1),100*(C118/E118-1)) -> 67.799165 | H118: =VLOOKUP(B118,hl,2,FALSE) -> 0.91538

Sheet Wind模板
A1: AH股溢价分析

Sheet 公司名单
B1: 组合 | C1: 公司名称 | D1: A股代码 | E1: H股代码
B2: =D2&" "&C2&" "&"("&E2&")" -> 601728.SH 中国电信 (0728.HK) | C2: 中国电信 | D2: 601728.SH | E2: 0728.HK
B3: =D3&" "&C3&" "&"("&E3&")" -> 601330.SH 绿色动力 (1330.HK) | C3: 绿色动力 | D3: 601330.SH | E3: 1330.HK
B4: =D4&" "&C4&" "&"("&E4&")" -> 601088.SH 中国神华 (1088.HK) | C4: 中国神华 | D4: 601088.SH | E4: 1088.HK
B5: =D5&" "&C5&" "&"("&E5&")" -> 600876.SH 凯盛新能 (1108.HK) | C5: 凯盛新能 | D5: 600876.SH | E5: 1108.HK
B6: =D6&" "&C6&" "&"("&E6&")" -> 600874.SH 创业环保 (1065.HK) | C6: 创业环保 | D6: 600874.SH | E6: 1065.HK
B7: =D7&" "&C7&" "&"("&E7&")" -> 001236.SZ 弘业期货 (3678.HK) | C7: 弘业期货 | D7: 001236.SZ | E7: 3678.HK
B8: =D8&" "&C8&" "&"("&E8&")" -> 600956.SH 新天绿能 (0956.HK) | C8: 新天绿能 | D8: 600956.SH | E8: 0956.HK
B9: =D9&" "&C9&" "&"("&E9&")" -> 600196.SH 复星医药 (2196.HK) | C9: 复星医药 | D9: 600196.SH | E9: 2196.HK
B10: =D10&" "&C10&" "&"("&E10&")" -> 601375.SH 中原证券 (1375.HK) | C10: 中原证券 | D10: 601375.SH | E10: 1375.HK
B11: =D11&" "&C11&" "&"("&E11&")" -> 600332.SH 白云山 (0874.HK) | C11: 白云山 | D11: 600332.SH | E11: 0874.HK
B12: =D12&" "&C12&" "&"("&E12&")" -> 300759.SZ 康龙化成 (3759.HK) | C12: 康龙化成 | D12: 300759.SZ | E12: 3759.HK
B13: =D13&" "&C13&" "&"("&E13&")" -> 600958.SH 东方证券 (3958.HK) | C13: 东方证券 | D13: 600958.SH | E13: 3958.HK
... B162: =D162&" "&C162&" "&"("&E162&")" -> 688234.SH 天岳先进 (2631.HK) | C162: 天岳先进 | D162: 688234.SH | E162: 2631.HK

Sheet 汇率表
A1: =[1]!edb() -> Wind
A2: 指标名称 | B2: 中间价:港元兑人民币
A3: 45895 | B3: 0.91164
A4: 45894 | B4: 0.91066
A5: 45891 | B5: 0.91285
A6: 45890 | B6: 0.91254
A7: 45889 | B7: 0.91477
A8: 45888 | B8: 0.91247
A9: 45887 | B9: 0.91108
A10: 45884 | B10: 0.91054
A11: 45883 | B11: 0.90887
A12: 45882 | B12: 0.90897
A13: 45881 | B13: 0.9098
A14: 45880 | B14: 0.90964
... A7774: 36969 | B7774: 1.0612
A7775: 36968
A7776: 36967
A7777: 36966 | B7777: 1.0615
A7778: 36965 | B7778: 1.0609
A7779: 36964 | B7779: 1.0613
A7780: 36963 | B7780: 1.0613
A7781: 36962 | B7781: 1.0615
A7782: 36961
A7783: 36960
A7784: 36959 | B7784: 1.061
A7785: 36958 | B7785: 1.0612
A7786: 36957 | B7786: 1.0614
A7787: 36956 | B7787: 1.0612
A7788: 36955 | B7788: 1.0613
A7789: 36954
A7790: 36953
A7791: 36952 | B7791: 1.061
A7792: 36951 | B7792: 1.0612
A7793: 36950 | B7793: 1.0613
A7794: 36949 | B7794: 1.0607
A7795: 36948 | B7795: 1.0609
A7796: 36947
A7797: 36946
A7798: 36945 | B7798: 1.0608
A7799: 36944 | B7799: 1.0616
...

Sheet Sheet1
