Workbook

Sheet 走势图
C1: 历史波动率（HVG）走势图（日线） | X1: 最近更新： | Y1: =TODAY() -> 45671
B3: 品种选择 | C3: 510050.SH | E3: 开始日期 | F3: 45294 | G3: 截止日期 | H3: =TODAY()-1 -> 45670 | J3: 年化系数 | K3: 245
B5: 计算周期 | C5: 5 | D5: 10 | E5: 20 | F5: 60
B6: HV | C6: =B6&C5 -> HV5 | D6: =B6&D5 -> HV10 | E6: =B6&E5 -> HV20 | F6: =B6&F5 -> HV60
C8: 收益率标准差模型 | P8: 传统收益率标准差模型—风险中性调整
C28: Parkinson模型 | P28: Garman-Klass模型
I48: Rogers-Satchell模型

Sheet 计算区域
A1: 参数区域 | E1: 数据区域 | F1: =[1]!s_info_name(F2) -> 上证50ETF | K1: 计算区域
A2: 标的 | B2: =走势图!C3 -> 510050.SH | F2: =B2 -> 510050.SH
A3: 开始日期 | B3: =走势图!F3 -> 45294 | E3: 日期 | F3: 开盘价 | G3: 最高价 | H3: 最低价 | I3: 收盘价 | K3: PKM | Q3: GK | W3: RS | AC3: 收益率标准差模型-风险中性调整 | AI3: 收益率标准差模型
A4: 截止日期 | B4: =走势图!H3 -> 45670 | E4: Date | F4: open | G4: high | H4: low | I4: close | K4: 步骤1 | L4: 周期1结果 | M4: 周期2结果 | N4: 周期3结果 | O4: 周期4结果 | Q4: 步骤1 | R4: 周期1结果 | S4: 周期2结果 | T4: 周期3结果 | U4: 周期4结果 | W4: 步骤1 | X4: 周期1结果 | Y4: 周期2结果 | Z4: 周期3结果 | AA4: 周期4结果 | AC4: 步骤1 | AD4: 周期1结果 | AE4: 周期2结果 | AF4: 周期3结果 | AG4: 周期4结果 | AI4: 步骤1 | AJ4: 周期1结果 | AK4: 周期2结果 | AL4: 周期3结果 | AM4: 周期4结果
A5: 计算周期1 | B5: =走势图!C5 -> 5 | E5: 45670 | F5: =[1]!WSD(F2,F4:I4,B3,B4,"TradingCalendar=SSE","PriceAdj=F","Sort=D","rptType=1","ShowParams=Y","cols=4;rows=249") -> 2.603 | G5: 2.616 | H5: 2.586 | I5: 2.607 | K5: =(LN(G5/H5))^2 -> 0.00013303669 | L5: =SQRT(AVERAGE(K5:OFFSET(K5,$B$5-1,0))*$B$9/(4*LN(2))) -> 0.12378764 | M5: =SQRT(AVERAGE(K5:OFFSET(K5,$B$6-1,0))*$B$9/(4*LN(2))) -> 0.15906682 | N5: =SQRT(AVERAGE(K5:OFFSET(K5,$B$7-1,0))*$B$9/(4*LN(2))) -> 0.1342643 | O5: =SQRT(AVERAGE(K5:OFFSET(K5,$B$8-1,0))*$B$9/(4*LN(2))) -> 0.16555027 | Q5: =0.511*(LN(G5/H5))^2-0.019*(LN(I5/F5)*LN(G5*H5/F5^2)-2*LN(G5/F5)*LN(H5/F5))-0.383*(LN(I5/F5))^2 -> 6.588412e-05 | R5: =SQRT($B$9*AVERAGE((Q5:OFFSET(Q5,$B$5-1,0)))) -> 0.13709221 | S5: =SQRT($B$9*AVERAGE((Q5:OFFSET(Q5,$B$6-1,0)))) -> 0.15954002 | T5: =SQRT($B$9*AVERAGE((Q5:OFFSET(Q5,$B$7-1,0)))) -> 0.13814946 | U5: =SQRT($B$9*AVERAGE((Q5:OFFSET(Q5,$B$8-1,0)))) -> 0.16341351 | W5: =LN(G5/I5)*LN(G5/F5)+LN(H5/I5)*LN(H5/F5) -> 7.0163216e-05 | X5: =SQRT($B$9*AVERAGE(W5:OFFSET(W5,$B$5-1,0))) -> 0.13940318 | Y5: =SQRT($B$9*AVERAGE(W5:OFFSET(W5,$B$6-1,0))) -> 0.15664737 | Z5: =SQRT($B$9*AVERAGE(W5:OFFSET(W5,$B$7-1,0))) -> 0.13855263 | AA5: =SQRT($B$9*AVERAGE(W5:OFFSET(W5,$B$8-1,0))) -> 0.16224784 | AC5: =(LN(I5/I6))^2 -> 9.3878666e-06 | AD5: =SQRT($B$9*SUM(AC5:OFFSET(AC5,$B$5-1,0))/($B$5-1)) -> 0.095119079 | AE5: =SQRT($B$9*SUM(AC5:OFFSET(AC5,$B$6-1,0))/($B$6-1)) -> 0.17770283 | AF5: =SQRT($B$9*SUM(AC5:OFFSET(AC5,$B$7-1,0))/($B$7-1)) -> 0.13759927 | AG5: =SQRT($B$9*SUM(AC5:OFFSET(AC5,$B$8-1,0))/($B$8-1)) -> 0.16791869 | AI5: =LN(I5/I6) -> -0.0030639626 | AJ5: =SQRT($B$9)*_xlfn.STDEV.S(AI5:OFFSET(AI5,$B$5-1,0)) -> 0.090013931 | AK5: =SQRT($B$9)*_xlfn.STDEV.S(AI5:OFFSET(AI5,$B$6-1,0)) -> 0.15292859 | AL5: =SQRT($B$9)*_xlfn.STDEV.S(AI5:OFFSET(AI5,$B$7-1,0)) -> 0.13527845 | AM5: =SQRT($B$9)*_xlfn.STDEV.S(AI5:OFFSET(AI5,$B$8-1,0)) -> 0.16741718
A6: 计算周期2 | B6: =走势图!D5 -> 10 | E6: 45667 | F6: 2.636 | G6: 2.651 | H6: 2.613 | I6: 2.615 | K6: =(LN(G6/H6))^2 -> 0.00020845413 | L6: =SQRT(AVERAGE(K6:OFFSET(K6,$B$5-1,0))*$B$9/(4*LN(2))) -> 0.12988054 | M6: =SQRT(AVERAGE(K6:OFFSET(K6,$B$6-1,0))*$B$9/(4*LN(2))) -> 0.15844924 | N6: =SQRT(AVERAGE(K6:OFFSET(K6,$B$7-1,0))*$B$9/(4*LN(2))) -> 0.1400067 | O6: =SQRT(AVERAGE(K6:OFFSET(K6,$B$8-1,0))*$B$9/(4*LN(2))) -> 0.18129664 | Q6: =0.511*(LN(G6/H6))^2-0.019*(LN(I6/F6)*LN(G6*H6/F6^2)-2*LN(G6/F6)*LN(H6/F6))-0.383*(LN(I6/F6))^2 -> 7.9657999e-05 | R6: =SQRT($B$9*AVERAGE((Q6:OFFSET(Q6,$B$5-1,0)))) -> 0.14377501 | S6: =SQRT($B$9*AVERAGE((Q6:OFFSET(Q6,$B$6-1,0)))) -> 0.15874764 | T6: =SQRT($B$9*AVERAGE((Q6:OFFSET(Q6,$B$7-1,0)))) -> 0.13996481 | U6: =SQRT($B$9*AVERAGE((Q6:OFFSET(Q6,$B$8-1,0)))) -> 0.18154318 | W6: =LN(G6/I6)*LN(G6/F6)+LN(H6/I6)*LN(H6/F6) -> 8.4289034e-05 | X6: =SQRT($B$9*AVERAGE(W6:OFFSET(W6,$B$5-1,0))) -> 0.14877603 | Y6: =SQRT($B$9*AVERAGE(W6:OFFSET(W6,$B$6-1,0))) -> 0.15549481 | Z6: =SQRT($B$9*AVERAGE(W6:OFFSET(W6,$B$7-1,0))) -> 0.13862471 | AA6: =SQRT($B$9*AVERAGE(W6:OFFSET(W6,$B$8-1,0))) -> 0.18051212 | AC6: =(LN(I6/I7))^2 -> 7.6684292e-05 | AD6: =SQRT($B$9*SUM(AC6:OFFSET(AC6,$B$5-1,0))/($B$5-1)) -> 0.09767107 | AE6: =SQRT($B$9*SUM(AC6:OFFSET(AC6,$B$6-1,0))/($B$6-1)) -> 0.17707344 | AF6: =SQRT($B$9*SUM(AC6:OFFSET(AC6,$B$7-1,0))/($B$7-1)) -> 0.16314752 | AG6: =SQRT($B$9*SUM(AC6:OFFSET(AC6,$B$8-1,0))/($B$8-1)) -> 0.17869357 | AI6: =LN(I6/I7) -> -0.0087569568 | AJ6: =SQRT($B$9)*_xlfn.STDEV.S(AI6:OFFSET(AI6,$B$5-1,0)) -> 0.091326791 | AK6: =SQRT($B$9)*_xlfn.STDEV.S(AI6:OFFSET(AI6,$B$6-1,0)) -> 0.15408811 | AL6: =SQRT($B$9)*_xlfn.STDEV.S(AI6:OFFSET(AI6,$B$7-1,0)) -> 0.15752557 | AM6: =SQRT($B$9)*_xlfn.STDEV.S(AI6:OFFSET(AI6,$B$8-1,0)) -> 0.17864346
A7: 计算周期3 | B7: =走势图!E5 -> 20 | E7: 45666 | F7: 2.649 | G7: 2.651 | H7: 2.627 | I7: 2.638 | K7: =(LN(G7/H7))^2 -> 8.2708413e-05 | L7: =SQRT(AVERAGE(K7:OFFSET(K7,$B$5-1,0))*$B$9/(4*LN(2))) -> 0.13355387 | M7: =SQRT(AVERAGE(K7:OFFSET(K7,$B$6-1,0))*$B$9/(4*LN(2))) -> 0.15362373 | N7: =SQRT(AVERAGE(K7:OFFSET(K7,$B$7-1,0))*$B$9/(4*LN(2))) -> 0.1397545 | O7: =SQRT(AVERAGE(K7:OFFSET(K7,$B$8-1,0))*$B$9/(4*LN(2))) -> 0.1833065 | Q7: =0.511*(LN(G7/H7))^2-0.019*(LN(I7/F7)*LN(G7*H7/F7^2)-2*LN(G7/F7)*LN(H7/F7))-0.383*(LN(I7/F7))^2 -> 3.479341e-05 | R7: =SQRT($B$9*AVERAGE((Q7:OFFSET(Q7,$B$5-1,0)))) -> 0.14803066 | S7: =SQRT($B$9*AVERAGE((Q7:OFFSET(Q7,$B$6-1,0)))) -> 0.15385898 | T7: =SQRT($B$9*AVERAGE((Q7:OFFSET(Q7,$B$7-1,0)))) -> 0.13878034 | U7: =SQRT($B$9*AVERAGE((Q7:OFFSET(Q7,$B$8-1,0)))) -> 0.18265166 | W7: =LN(G7/I7)*LN(G7/F7)+LN(H7/I7)*LN(H7/F7) -> 3.8557891e-05 | X7: =SQRT($B$9*AVERAGE(W7:OFFSET(W7,$B$5-1,0))) -> 0.15099945 | Y7: =SQRT($B$9*AVERAGE(W7:OFFSET(W7,$B$6-1,0))) -> 0.15033632 | Z7: =SQRT($B$9*AVERAGE(W7:OFFSET(W7,$B$7-1,0))) -> 0.13681719 | AA7: =SQRT($B$9*AVERAGE(W7:OFFSET(W7,$B$8-1,0))) -> 0.18114156 | AC7: =(LN(I7/I8))^2 -> 2.4165807e-05 | AD7: =SQRT($B$9*SUM(AC7:OFFSET(AC7,$B$5-1,0))/($B$5-1)) -> 0.10354278 | AE7: =SQRT($B$9*SUM(AC7:OFFSET(AC7,$B$6-1,0))/($B$6-1)) -> 0.17158826 | AF7: =SQRT($B$9*SUM(AC7:OFFSET(AC7,$B$7-1,0))/($B$7-1)) -> 0.16515778 | AG7: =SQRT($B$9*SUM(AC7:OFFSET(AC7,$B$8-1,0))/($B$8-1)) -> 0.18053722 | AI7: =LN(I7/I8) -> -0.004915873 | AJ7: =SQRT($B$9)*_xlfn.STDEV.S(AI7:OFFSET(AI7,$B$5-1,0)) -> 0.09621231 | AK7: =SQRT($B$9)*_xlfn.STDEV.S(AI7:OFFSET(AI7,$B$6-1,0)) -> 0.15335049 | AL7: =SQRT($B$9)*_xlfn.STDEV.S(AI7:OFFSET(AI7,$B$7-1,0)) -> 0.16304249 | AM7: =SQRT($B$9)*_xlfn.STDEV.S(AI7:OFFSET(AI7,$B$8-1,0)) -> 0.18043846
A8: 计算周期4 | B8: =走势图!F5 -> 60 | E8: 45665 | F8: 2.642 | G8: 2.667 | H8: 2.619 | I8: 2.651 | K8: =(LN(G8/H8))^2 -> 0.00032984661 | L8: =SQRT(AVERAGE(K8:OFFSET(K8,$B$5-1,0))*$B$9/(4*LN(2))) -> 0.19359593 | M8: =SQRT(AVERAGE(K8:OFFSET(K8,$B$6-1,0))*$B$9/(4*LN(2))) -> 0.15359536 | N8: =SQRT(AVERAGE(K8:OFFSET(K8,$B$7-1,0))*$B$9/(4*LN(2))) -> 0.13976836 | O8: =SQRT(AVERAGE(K8:OFFSET(K8,$B$8-1,0))*$B$9/(4*LN(2))) -> 0.18429197 | Q8: =0.511*(LN(G8/H8))^2-0.019*(LN(I8/F8)*LN(G8*H8/F8^2)-2*LN(G8/F8)*LN(H8/F8))-0.383*(LN(I8/F8))^2 -> 0.00016094946 | R8: =SQRT($B$9*AVERAGE((Q8:OFFSET(Q8,$B$5-1,0)))) -> 0.19513893 | S8: =SQRT($B$9*AVERAGE((Q8:OFFSET(Q8,$B$6-1,0)))) -> 0.15429045 | T8: =SQRT($B$9*AVERAGE((Q8:OFFSET(Q8,$B$7-1,0)))) -> 0.13881583 | U8: =SQRT($B$9*AVERAGE((Q8:OFFSET(Q8,$B$8-1,0)))) -> 0.18397685 | W8: =LN(G8/I8)*LN(G8/F8)+LN(H8/I8)*LN(H8/F8) -> 0.00016285727 | X8: =SQRT($B$9*AVERAGE(W8:OFFSET(W8,$B$5-1,0))) -> 0.19117657 | Y8: =SQRT($B$9*AVERAGE(W8:OFFSET(W8,$B$6-1,0))) -> 0.15069538 | Z8: =SQRT($B$9*AVERAGE(W8:OFFSET(W8,$B$7-1,0))) -> 0.13670519 | AA8: =SQRT($B$9*AVERAGE(W8:OFFSET(W8,$B$8-1,0))) -> 0.18277041 | AC8: =(LN(I8/I9))^2 -> 5.1341306e-06 | AD8: =SQRT($B$9*SUM(AC8:OFFSET(AC8,$B$5-1,0))/($B$5-1)) -> 0.22698364 | AE8: =SQRT($B$9*SUM(AC8:OFFSET(AC8,$B$6-1,0))/($B$6-1)) -> 0.17093145 | AF8: =SQRT($B$9*SUM(AC8:OFFSET(AC8,$B$7-1,0))/($B$7-1)) -> 0.16590362 | AG8: =SQRT($B$9*SUM(AC8:OFFSET(AC8,$B$8-1,0))/($B$8-1)) -> 0.18028335 | AI8: =LN(I8/I9) -> 0.002265862 | AJ8: =SQRT($B$9)*_xlfn.STDEV.S(AI8:OFFSET(AI8,$B$5-1,0)) -> 0.19684651 | AK8: =SQRT($B$9)*_xlfn.STDEV.S(AI8:OFFSET(AI8,$B$6-1,0)) -> 0.15917707 | AL8: =SQRT($B$9)*_xlfn.STDEV.S(AI8:OFFSET(AI8,$B$7-1,0)) -> 0.16357723 | AM8: =SQRT($B$9)*_xlfn.STDEV.S(AI8:OFFSET(AI8,$B$8-1,0)) -> 0.18021234
A9: 年化系数 | B9: =走势图!K3 -> 245 | E9: 45664 | F9: 2.629 | G9: 2.648 | H9: 2.62 | I9: 2.645 | K9: =(LN(G9/H9))^2 -> 0.00011300371 | L9: =SQRT(AVERAGE(K9:OFFSET(K9,$B$5-1,0))*$B$9/(4*LN(2))) -> 0.18959874 | M9: =SQRT(AVERAGE(K9:OFFSET(K9,$B$6-1,0))*$B$9/(4*LN(2))) -> 0.15085159 | N9: =SQRT(AVERAGE(K9:OFFSET(K9,$B$7-1,0))*$B$9/(4*LN(2))) -> 0.14598433 | O9: =SQRT(AVERAGE(K9:OFFSET(K9,$B$8-1,0))*$B$9/(4*LN(2))) -> 0.18600013 | Q9: =0.511*(LN(G9/H9))^2-0.019*(LN(I9/F9)*LN(G9*H9/F9^2)-2*LN(G9/F9)*LN(H9/F9))-0.383*(LN(I9/F9))^2 -> 4.2271619e-05 | R9: =SQRT($B$9*AVERAGE((Q9:OFFSET(Q9,$B$5-1,0)))) -> 0.18232008 | S9: =SQRT($B$9*AVERAGE((Q9:OFFSET(Q9,$B$6-1,0)))) -> 0.14816909 | T9: =SQRT($B$9*AVERAGE((Q9:OFFSET(Q9,$B$7-1,0)))) -> 0.14106997 | U9: =SQRT($B$9*AVERAGE((Q9:OFFSET(Q9,$B$8-1,0)))) -> 0.18465921 | W9: =LN(G9/I9)*LN(G9/F9)+LN(H9/I9)*LN(H9/F9) -> 4.0729474e-05 | X9: =SQRT($B$9*AVERAGE(W9:OFFSET(W9,$B$5-1,0))) -> 0.1757082 | Y9: =SQRT($B$9*AVERAGE(W9:OFFSET(W9,$B$6-1,0))) -> 0.14361332 | Z9: =SQRT($B$9*AVERAGE(W9:OFFSET(W9,$B$7-1,0))) -> 0.13698973 | AA9: =SQRT($B$9*AVERAGE(W9:OFFSET(W9,$B$8-1,0))) -> 0.18313644 | AC9: =(LN(I9/I10))^2 -> 3.2344461e-05 | AD9: =SQRT($B$9*SUM(AC9:OFFSET(AC9,$B$5-1,0))/($B$5-1)) -> 0.24716248 | AE9: =SQRT($B$9*SUM(AC9:OFFSET(AC9,$B$6-1,0))/($B$6-1)) -> 0.17925017 | AF9: =SQRT($B$9*SUM(AC9:OFFSET(AC9,$B$7-1,0))/($B$7-1)) -> 0.1689319 | AG9: =SQRT($B$9*SUM(AC9:OFFSET(AC9,$B$8-1,0))/($B$8-1)) -> 0.18712644 | AI9: =LN(I9/I10) -> 0.0056872191 | AJ9: =SQRT($B$9)*_xlfn.STDEV.S(AI9:OFFSET(AI9,$B$5-1,0)) -> 0.18365819 | AK9: =SQRT($B$9)*_xlfn.STDEV.S(AI9:OFFSET(AI9,$B$6-1,0)) -> 0.17254793 | AL9: =SQRT($B$9)*_xlfn.STDEV.S(AI9:OFFSET(AI9,$B$7-1,0)) -> 0.16747268 | AM9: =SQRT($B$9)*_xlfn.STDEV.S(AI9:OFFSET(AI9,$B$8-1,0)) -> 0.18673118
E10: 45663 | F10: 2.641 | G10: 2.646 | H10: 2.607 | I10: 2.63 | K10: =(LN(G10/H10))^2 -> 0.00022049074 | L10: =SQRT(AVERAGE(K10:OFFSET(K10,$B$5-1,0))*$B$9/(4*LN(2))) -> 0.1878327 | M10: =SQRT(AVERAGE(K10:OFFSET(K10,$B$6-1,0))*$B$9/(4*LN(2))) -> 0.15384186 | N10: =SQRT(AVERAGE(K10:OFFSET(K10,$B$7-1,0))*$B$9/(4*LN(2))) -> 0.14649516 | O10: =SQRT(AVERAGE(K10:OFFSET(K10,$B$8-1,0))*$B$9/(4*LN(2))) -> 0.18779265 | Q10: =0.511*(LN(G10/H10))^2-0.019*(LN(I10/F10)*LN(G10*H10/F10^2)-2*LN(G10/F10)*LN(H10/F10))-0.383*(LN(I10/F10))^2 -> 0.00010418985 | R10: =SQRT($B$9*AVERAGE((Q10:OFFSET(Q10,$B$5-1,0)))) -> 0.17919754 | S10: =SQRT($B$9*AVERAGE((Q10:OFFSET(Q10,$B$6-1,0)))) -> 0.15129887 | T10: =SQRT($B$9*AVERAGE((Q10:OFFSET(Q10,$B$7-1,0)))) -> 0.14235486 | U10: =SQRT($B$9*AVERAGE((Q10:OFFSET(Q10,$B$8-1,0)))) -> 0.18706169 | W10: =LN(G10/I10)*LN(G10/F10)+LN(H10/I10)*LN(H10/F10) -> 0.00012528688 | X10: =SQRT($B$9*AVERAGE(W10:OFFSET(W10,$B$5-1,0))) -> 0.17217303 | Y10: =SQRT($B$9*AVERAGE(W10:OFFSET(W10,$B$6-1,0))) -> 0.14787723 | Z10: =SQRT($B$9*AVERAGE(W10:OFFSET(W10,$B$7-1,0))) -> 0.13899837 | AA10: =SQRT($B$9*AVERAGE(W10:OFFSET(W10,$B$8-1,0))) -> 0.18555371 | AC10: =(LN(I10/I11))^2 -> 1.7420499e-05 | AD10: =SQRT($B$9*SUM(AC10:OFFSET(AC10,$B$5-1,0))/($B$5-1)) -> 0.24900507 | AE10: =SQRT($B$9*SUM(AC10:OFFSET(AC10,$B$6-1,0))/($B$6-1)) -> 0.18222892 | AF10: =SQRT($B$9*SUM(AC10:OFFSET(AC10,$B$7-1,0))/($B$7-1)) -> 0.16773976 | AG10: =SQRT($B$9*SUM(AC10:OFFSET(AC10,$B$8-1,0))/($B$8-1)) -> 0.18829367 | AI10: =LN(I10/I11) -> -0.0041737871 | AJ10: =SQRT($B$9)*_xlfn.STDEV.S(AI10:OFFSET(AI10,$B$5-1,0)) -> 0.18974443 | AK10: =SQRT($B$9)*_xlfn.STDEV.S(AI10:OFFSET(AI10,$B$6-1,0)) -> 0.17684938 | AL10: =SQRT($B$9)*_xlfn.STDEV.S(AI10:OFFSET(AI10,$B$7-1,0)) -> 0.16573811 | AM10: =SQRT($B$9)*_xlfn.STDEV.S(AI10:OFFSET(AI10,$B$8-1,0)) -> 0.18799713
E11: 45660 | F11: 2.663 | G11: 2.672 | H11: 2.629 | I11: 2.641 | K11: =(LN(G11/H11))^2 -> 0.00026320876 | L11: =SQRT(AVERAGE(K11:OFFSET(K11,$B$5-1,0))*$B$9/(4*LN(2))) -> 0.18260166 | M11: =SQRT(AVERAGE(K11:OFFSET(K11,$B$6-1,0))*$B$9/(4*LN(2))) -> 0.15032324 | N11: =SQRT(AVERAGE(K11:OFFSET(K11,$B$7-1,0))*$B$9/(4*LN(2))) -> 0.14936079 | O11: =SQRT(AVERAGE(K11:OFFSET(K11,$B$8-1,0))*$B$9/(4*LN(2))) -> 0.19121881 | Q11: =0.511*(LN(G11/H11))^2-0.019*(LN(I11/F11)*LN(G11*H11/F11^2)-2*LN(G11/F11)*LN(H11/F11))-0.383*(LN(I11/F11))^2 -> 0.00010500128 | R11: =SQRT($B$9*AVERAGE((Q11:OFFSET(Q11,$B$5-1,0)))) -> 0.17242498 | S11: =SQRT($B$9*AVERAGE((Q11:OFFSET(Q11,$B$6-1,0)))) -> 0.14677341 | T11: =SQRT($B$9*AVERAGE((Q11:OFFSET(Q11,$B$7-1,0)))) -> 0.14494225 | U11: =SQRT($B$9*AVERAGE((Q11:OFFSET(Q11,$B$8-1,0)))) -> 0.19074313 | W11: =LN(G11/I11)*LN(G11/F11)+LN(H11/I11)*LN(H11/F11) -> 9.7891646e-05 | X11: =SQRT($B$9*AVERAGE(W11:OFFSET(W11,$B$5-1,0))) -> 0.16193507 | Y11: =SQRT($B$9*AVERAGE(W11:OFFSET(W11,$B$6-1,0))) -> 0.142087 | Z11: =SQRT($B$9*AVERAGE(W11:OFFSET(W11,$B$7-1,0))) -> 0.14067996 | AA11: =SQRT($B$9*AVERAGE(W11:OFFSET(W11,$B$8-1,0))) -> 0.18940779 | AC11: =(LN(I11/I12))^2 -> 9.5973604e-05 | AD11: =SQRT($B$9*SUM(AC11:OFFSET(AC11,$B$5-1,0))/($B$5-1)) -> 0.24700024 | AE11: =SQRT($B$9*SUM(AC11:OFFSET(AC11,$B$6-1,0))/($B$6-1)) -> 0.1815799 | AF11: =SQRT($B$9*SUM(AC11:OFFSET(AC11,$B$7-1,0))/($B$7-1)) -> 0.17145832 | AG11: =SQRT($B$9*SUM(AC11:OFFSET(AC11,$B$8-1,0))/($B$8-1)) -> 0.19270483 | AI11: =LN(I11/I12) -> -0.0097966119 | AJ11: =SQRT($B$9)*_xlfn.STDEV.S(AI11:OFFSET(AI11,$B$5-1,0)) -> 0.1958932 | AK11: =SQRT($B$9)*_xlfn.STDEV.S(AI11:OFFSET(AI11,$B$6-1,0)) -> 0.17666906 | AL11: =SQRT($B$9)*_xlfn.STDEV.S(AI11:OFFSET(AI11,$B$7-1,0)) -> 0.17089679 | AM11: =SQRT($B$9)*_xlfn.STDEV.S(AI11:OFFSET(AI11,$B$8-1,0)) -> 0.19213022
E12: 45659 | F12: 2.733 | G12: 2.738 | H12: 2.645 | I12: 2.667 | K12: =(LN(G12/H12))^2 -> 0.0011941629 | L12: =SQRT(AVERAGE(K12:OFFSET(K12,$B$5-1,0))*$B$9/(4*LN(2))) -> 0.17135889 | M12: =SQRT(AVERAGE(K12:OFFSET(K12,$B$6-1,0))*$B$9/(4*LN(2))) -> 0.14666198 | N12: =SQRT(AVERAGE(K12:OFFSET(K12,$B$7-1,0))*$B$9/(4*LN(2))) -> 0.14633897 | O12: =SQRT(AVERAGE(K12:OFFSET(K12,$B$8-1,0))*$B$9/(4*LN(2))) -> 0.19946053 | Q12: =0.511*(LN(G12/H12))^2-0.019*(LN(I12/F12)*LN(G12*H12/F12^2)-2*LN(G12/F12)*LN(H12/F12))-0.383*(LN(I12/F12))^2 -> 0.00036471433 | R12: =SQRT($B$9*AVERAGE((Q12:OFFSET(Q12,$B$5-1,0)))) -> 0.15947443 | S12: =SQRT($B$9*AVERAGE((Q12:OFFSET(Q12,$B$6-1,0)))) -> 0.14347753 | T12: =SQRT($B$9*AVERAGE((Q12:OFFSET(Q12,$B$7-1,0)))) -> 0.14174136 | U12: =SQRT($B$9*AVERAGE((Q12:OFFSET(Q12,$B$8-1,0)))) -> 0.20027192 | W12: =LN(G12/I12)*LN(G12/F12)+LN(H12/I12)*LN(H12/F12) -> 0.00031912208 | X12: =SQRT($B$9*AVERAGE(W12:OFFSET(W12,$B$5-1,0))) -> 0.14967026 | Y12: =SQRT($B$9*AVERAGE(W12:OFFSET(W12,$B$6-1,0))) -> 0.13923943 | Z12: =SQRT($B$9*AVERAGE(W12:OFFSET(W12,$B$7-1,0))) -> 0.13769797 | AA12: =SQRT($B$9*AVERAGE(W12:OFFSET(W12,$B$8-1,0))) -> 0.20065359 | AC12: =(LN(I12/I13))^2 -> 0.00069029584 | AD12: =SQRT($B$9*SUM(AC12:OFFSET(AC12,$B$5-1,0))/($B$5-1)) -> 0.23563655 | AE12: =SQRT($B$9*SUM(AC12:OFFSET(AC12,$B$6-1,0))/($B$6-1)) -> 0.17529467 | AF12: =SQRT($B$9*SUM(AC12:OFFSET(AC12,$B$7-1,0))/($B$7-1)) -> 0.16857176 | AG12: =SQRT($B$9*SUM(AC12:OFFSET(AC12,$B$8-1,0))/($B$8-1)) -> 0.20226314 | AI12: =LN(I12/I13) -> -0.026273482 | AJ12: =SQRT($B$9)*_xlfn.STDEV.S(AI12:OFFSET(AI12,$B$5-1,0)) -> 0.19972607 | AK12: =SQRT($B$9)*_xlfn.STDEV.S(AI12:OFFSET(AI12,$B$6-1,0)) -> 0.17237511 | AL12: =SQRT($B$9)*_xlfn.STDEV.S(AI12:OFFSET(AI12,$B$7-1,0)) -> 0.1682995 | AM12: =SQRT($B$9)*_xlfn.STDEV.S(AI12:OFFSET(AI12,$B$8-1,0)) -> 0.20222451
E13: 45657 | F13: 2.772 | G13: 2.779 | H13: 2.736 | I13: 2.738 | K13: =(LN(G13/H13))^2 -> 0.00024317755 | L13: =SQRT(AVERAGE(K13:OFFSET(K13,$B$5-1,0))*$B$9/(4*LN(2))) -> 0.098507274 | M13: =SQRT(AVERAGE(K13:OFFSET(K13,$B$6-1,0))*$B$9/(4*LN(2))) -> 0.10672001 | N13: =SQRT(AVERAGE(K13:OFFSET(K13,$B$7-1,0))*$B$9/(4*LN(2))) -> 0.12852206 | O13: =SQRT(AVERAGE(K13:OFFSET(K13,$B$8-1,0))*$B$9/(4*LN(2))) -> 0.20985725 | Q13: =0.511*(LN(G13/H13))^2-0.019*(LN(I13/F13)*LN(G13*H13/F13^2)-2*LN(G13/F13)*LN(H13/F13))-0.383*(LN(I13/F13))^2 -> 6.2202729e-05 | R13: =SQRT($B$9*AVERAGE((Q13:OFFSET(Q13,$B$5-1,0)))) -> 0.097631383 | S13: =SQRT($B$9*AVERAGE((Q13:OFFSET(Q13,$B$6-1,0)))) -> 0.11010213 | T13: =SQRT($B$9*AVERAGE((Q13:OFFSET(Q13,$B$7-1,0)))) -> 0.12708176 | U13: =SQRT($B$9*AVERAGE((Q13:OFFSET(Q13,$B$8-1,0)))) -> 0.2064485 | W13: =LN(G13/I13)*LN(G13/F13)+LN(H13/I13)*LN(H13/F13) -> 4.7038711e-05 | X13: =SQRT($B$9*AVERAGE(W13:OFFSET(W13,$B$5-1,0))) -> 0.094179155 | Y13: =SQRT($B$9*AVERAGE(W13:OFFSET(W13,$B$6-1,0))) -> 0.11015891 | Z13: =SQRT($B$9*AVERAGE(W13:OFFSET(W13,$B$7-1,0))) -> 0.12481008 | AA13: =SQRT($B$9*AVERAGE(W13:OFFSET(W13,$B$8-1,0))) -> 0.20462518 | AC13: =(LN(I13/I14))^2 -> 0.00016134181 | AD13: =SQRT($B$9*SUM(AC13:OFFSET(AC13,$B$5-1,0))/($B$5-1)) -> 0.11923898 | AE13: =SQRT($B$9*SUM(AC13:OFFSET(AC13,$B$6-1,0))/($B$6-1)) -> 0.11521915 | AF13: =SQRT($B$9*SUM(AC13:OFFSET(AC13,$B$7-1,0))/($B$7-1)) -> 0.13975396 | AG13: =SQRT($B$9*SUM(AC13:OFFSET(AC13,$B$8-1,0))/($B$8-1)) -> 0.24771234 | AI13: =LN(I13/I14) -> -0.01270204 | AJ13: =SQRT($B$9)*_xlfn.STDEV.S(AI13:OFFSET(AI13,$B$5-1,0)) -> 0.11769569 | AK13: =SQRT($B$9)*_xlfn.STDEV.S(AI13:OFFSET(AI13,$B$6-1,0)) -> 0.11288812 | AL13: =SQRT($B$9)*_xlfn.STDEV.S(AI13:OFFSET(AI13,$B$7-1,0)) -> 0.13934929 | AM13: =SQRT($B$9)*_xlfn.STDEV.S(AI13:OFFSET(AI13,$B$8-1,0)) -> 0.24714508
E14: 45656 | F14: 2.754 | G14: 2.778 | H14: 2.754 | I14: 2.773 | K14: =(LN(G14/H14))^2 -> 7.5287622e-05 | L14: =SQRT(AVERAGE(K14:OFFSET(K14,$B$5-1,0))*$B$9/(4*LN(2))) -> 0.097799385 | M14: =SQRT(AVERAGE(K14:OFFSET(K14,$B$6-1,0))*$B$9/(4*LN(2))) -> 0.10572108 | N14: =SQRT(AVERAGE(K14:OFFSET(K14,$B$7-1,0))*$B$9/(4*LN(2))) -> 0.12724032 | O14: =SQRT(AVERAGE(K14:OFFSET(K14,$B$8-1,0))*$B$9/(4*LN(2))) -> 0.23889164 | Q14: =0.511*(LN(G14/H14))^2-0.019*(LN(I14/F14)*LN(G14*H14/F14^2)-2*LN(G14/F14)*LN(H14/F14))-0.383*(LN(I14/F14))^2 -> 1.9233838e-05 | R14: =SQRT($B$9*AVERAGE((Q14:OFFSET(Q14,$B$5-1,0)))) -> 0.10328382 | S14: =SQRT($B$9*AVERAGE((Q14:OFFSET(Q14,$B$6-1,0)))) -> 0.11347411 | T14: =SQRT($B$9*AVERAGE((Q14:OFFSET(Q14,$B$7-1,0)))) -> 0.12765801 | U14: =SQRT($B$9*AVERAGE((Q14:OFFSET(Q14,$B$8-1,0)))) -> 0.22960311 | W14: =LN(G14/I14)*LN(G14/F14)+LN(H14/I14)*LN(H14/F14) -> 1.5631141e-05 | X14: =SQRT($B$9*AVERAGE(W14:OFFSET(W14,$B$5-1,0))) -> 0.10186365 | Y14: =SQRT($B$9*AVERAGE(W14:OFFSET(W14,$B$6-1,0))) -> 0.11800806 | Z14: =SQRT($B$9*AVERAGE(W14:OFFSET(W14,$B$7-1,0))) -> 0.1260673 | AA14: =SQRT($B$9*AVERAGE(W14:OFFSET(W14,$B$8-1,0))) -> 0.22540148 | AC14: =(LN(I14/I15))^2 -> 4.7270662e-05 | AD14: =SQRT($B$9*SUM(AC14:OFFSET(AC14,$B$5-1,0))/($B$5-1)) -> 0.10585183 | AE14: =SQRT($B$9*SUM(AC14:OFFSET(AC14,$B$6-1,0))/($B$6-1)) -> 0.098076923 | AF14: =SQRT($B$9*SUM(AC14:OFFSET(AC14,$B$7-1,0))/($B$7-1)) -> 0.13341172 | AG14: =SQRT($B$9*SUM(AC14:OFFSET(AC14,$B$8-1,0))/($B$8-1)) -> 0.25094515 | AI14: =LN(I14/I15) -> 0.0068753663 | AJ14: =SQRT($B$9)*_xlfn.STDEV.S(AI14:OFFSET(AI14,$B$5-1,0)) -> 0.085504 | AK14: =SQRT($B$9)*_xlfn.STDEV.S(AI14:OFFSET(AI14,$B$6-1,0)) -> 0.082782685 | AL14: =SQRT($B$9)*_xlfn.STDEV.S(AI14:OFFSET(AI14,$B$7-1,0)) -> 0.13104882 | AM14: =SQRT($B$9)*_xlfn.STDEV.S(AI14:OFFSET(AI14,$B$8-1,0)) -> 0.25084053
E15: 45653 | F15: 2.754 | G15: 2.769 | H15: 2.74 | I15: 2.754 | K15: =(LN(G15/H15))^2 -> 0.0001108456 | L15: =SQRT(AVERAGE(K15:OFFSET(K15,$B$5-1,0))*$B$9/(4*LN(2))) -> 0.10978847 | M15: =SQRT(AVERAGE(K15:OFFSET(K15,$B$6-1,0))*$B$9/(4*LN(2))) -> 0.10368969 | N15: =SQRT(AVERAGE(K15:OFFSET(K15,$B$7-1,0))*$B$9/(4*LN(2))) -> 0.12871904 | O15: =SQRT(AVERAGE(K15:OFFSET(K15,$B$8-1,0))*$B$9/(4*LN(2))) -> 0.25692649 | Q15: =0.511*(LN(G15/H15))^2-0.019*(LN(I15/F15)*LN(G15*H15/F15^2)-2*LN(G15/F15)*LN(H15/F15))-0.383*(LN(I15/F15))^2 -> 5.5590138e-05 | R15: =SQRT($B$9*AVERAGE((Q15:OFFSET(Q15,$B$5-1,0)))) -> 0.11692279 | S15: =SQRT($B$9*AVERAGE((Q15:OFFSET(Q15,$B$6-1,0)))) -> 0.11277202 | T15: =SQRT($B$9*AVERAGE((Q15:OFFSET(Q15,$B$7-1,0)))) -> 0.13032098 | U15: =SQRT($B$9*AVERAGE((Q15:OFFSET(Q15,$B$8-1,0)))) -> 0.25088527 | W15: =LN(G15/I15)*LN(G15/F15)+LN(H15/I15)*LN(H15/F15) -> 5.5479035e-05 | X15: =SQRT($B$9*AVERAGE(W15:OFFSET(W15,$B$5-1,0))) -> 0.11870888 | Y15: =SQRT($B$9*AVERAGE(W15:OFFSET(W15,$B$6-1,0))) -> 0.11770838 | Z15: =SQRT($B$9*AVERAGE(W15:OFFSET(W15,$B$7-1,0))) -> 0.12897254 | AA15: =SQRT($B$9*AVERAGE(W15:OFFSET(W15,$B$8-1,0))) -> 0.24685148 | AC15: =(LN(I15/I16))^2 -> 1.1853368e-06 | AD15: =SQRT($B$9*SUM(AC15:OFFSET(AC15,$B$5-1,0))/($B$5-1)) -> 0.1127523 | AE15: =SQRT($B$9*SUM(AC15:OFFSET(AC15,$B$6-1,0))/($B$6-1)) -> 0.091610873 | AF15: =SQRT($B$9*SUM(AC15:OFFSET(AC15,$B$7-1,0))/($B$7-1)) -> 0.13193179 | AG15: =SQRT($B$9*SUM(AC15:OFFSET(AC15,$B$8-1,0))/($B$8-1)) -> 0.28408792 | AI15: =LN(I15/I16) -> -0.0010887317 | AJ15: =SQRT($B$9)*_xlfn.STDEV.S(AI15:OFFSET(AI15,$B$5-1,0)) -> 0.08992938 | AK15: =SQRT($B$9)*_xlfn.STDEV.S(AI15:OFFSET(AI15,$B$6-1,0)) -> 0.082991052 | AL15: =SQRT($B$9)*_xlfn.STDEV.S(AI15:OFFSET(AI15,$B$7-1,0)) -> 0.12995199 | AM15: =SQRT($B$9)*_xlfn.STDEV.S(AI15:OFFSET(AI15,$B$8-1,0)) -> 0.28396863
E16: 45652 | F16: 2.763 | G16: 2.765 | H16: 2.748 | I16: 2.757 | K16: =(LN(G16/H16))^2 -> 3.8035103e-05 | L16: =SQRT(AVERAGE(K16:OFFSET(K16,$B$5-1,0))*$B$9/(4*LN(2))) -> 0.10886132 | M16: =SQRT(AVERAGE(K16:OFFSET(K16,$B$6-1,0))*$B$9/(4*LN(2))) -> 0.11873328 | N16: =SQRT(AVERAGE(K16:OFFSET(K16,$B$7-1,0))*$B$9/(4*LN(2))) -> 0.13269499 | O16: =SQRT(AVERAGE(K16:OFFSET(K16,$B$8-1,0))*$B$9/(4*LN(2))) -> 0.27327798 | Q16: =0.511*(LN(G16/H16))^2-0.019*(LN(I16/F16)*LN(G16*H16/F16^2)-2*LN(G16/F16)*LN(H16/F16))-0.383*(LN(I16/F16))^2 -> 1.7281276e-05 | R16: =SQRT($B$9*AVERAGE((Q16:OFFSET(Q16,$B$5-1,0)))) -> 0.11556166 | S16: =SQRT($B$9*AVERAGE((Q16:OFFSET(Q16,$B$6-1,0)))) -> 0.11823485 | T16: =SQRT($B$9*AVERAGE((Q16:OFFSET(Q16,$B$7-1,0)))) -> 0.13528037 | U16: =SQRT($B$9*AVERAGE((Q16:OFFSET(Q16,$B$8-1,0)))) -> 0.27226457 | W16: =LN(G16/I16)*LN(G16/F16)+LN(H16/I16)*LN(H16/F16) -> 1.9896088e-05 | X16: =SQRT($B$9*AVERAGE(W16:OFFSET(W16,$B$5-1,0))) -> 0.11897252 | Y16: =SQRT($B$9*AVERAGE(W16:OFFSET(W16,$B$6-1,0))) -> 0.11939424 | Z16: =SQRT($B$9*AVERAGE(W16:OFFSET(W16,$B$7-1,0))) -> 0.13720204 | AA16: =SQRT($B$9*AVERAGE(W16:OFFSET(W16,$B$8-1,0))) -> 0.26874794 | AC16: =(LN(I16/I17))^2 -> 6.4301491e-06 | AD16: =SQRT($B$9*SUM(AC16:OFFSET(AC16,$B$5-1,0))/($B$5-1)) -> 0.1147877 | AE16: =SQRT($B$9*SUM(AC16:OFFSET(AC16,$B$6-1,0))/($B$6-1)) -> 0.15759658 | AF16: =SQRT($B$9*SUM(AC16:OFFSET(AC16,$B$7-1,0))/($B$7-1)) -> 0.13354996 | AG16: =SQRT($B$9*SUM(AC16:OFFSET(AC16,$B$8-1,0))/($B$8-1)) -> 0.29536883 | AI16: =LN(I16/I17) -> -0.0025357739 | AJ16: =SQRT($B$9)*_xlfn.STDEV.S(AI16:OFFSET(AI16,$B$5-1,0)) -> 0.096939925 | AK16: =SQRT($B$9)*_xlfn.STDEV.S(AI16:OFFSET(AI16,$B$6-1,0)) -> 0.15759658 | AL16: =SQRT($B$9)*_xlfn.STDEV.S(AI16:OFFSET(AI16,$B$7-1,0)) -> 0.13050389 | AM16: =SQRT($B$9)*_xlfn.STDEV.S(AI16:OFFSET(AI16,$B$8-1,0)) -> 0.29475968
E17: 45651 | F17: 2.76 | G17: 2.778 | H17: 2.753 | I17: 2.764 | K17: =(LN(G17/H17))^2 -> 8.1721929e-05 | L17: =SQRT(AVERAGE(K17:OFFSET(K17,$B$5-1,0))*$B$9/(4*LN(2))) -> 0.11685721 | M17: =SQRT(AVERAGE(K17:OFFSET(K17,$B$6-1,0))*$B$9/(4*LN(2))) -> 0.12434786 | N17: =SQRT(AVERAGE(K17:OFFSET(K17,$B$7-1,0))*$B$9/(4*LN(2))) -> 0.13480467 | O17: =SQRT(AVERAGE(K17:OFFSET(K17,$B$8-1,0))*$B$9/(4*LN(2))) -> 0.28153902 | Q17: =0.511*(LN(G17/H17))^2-0.019*(LN(I17/F17)*LN(G17*H17/F17^2)-2*LN(G17/F17)*LN(H17/F17))-0.383*(LN(I17/F17))^2 -> 4.0220322e-05 | R17: =SQRT($B$9*AVERAGE((Q17:OFFSET(Q17,$B$5-1,0)))) -> 0.1254572 | S17: =SQRT($B$9*AVERAGE((Q17:OFFSET(Q17,$B$6-1,0)))) -> 0.12184982 | T17: =SQRT($B$9*AVERAGE((Q17:OFFSET(Q17,$B$7-1,0)))) -> 0.13770687 | U17: =SQRT($B$9*AVERAGE((Q17:OFFSET(Q17,$B$8-1,0)))) -> 0.27494723 | W17: =LN(G17/I17)*LN(G17/F17)+LN(H17/I17)*LN(H17/F17) -> 4.296958e-05 | X17: =SQRT($B$9*AVERAGE(W17:OFFSET(W17,$B$5-1,0))) -> 0.12796113 | Y17: =SQRT($B$9*AVERAGE(W17:OFFSET(W17,$B$6-1,0))) -> 0.12180673 | Z17: =SQRT($B$9*AVERAGE(W17:OFFSET(W17,$B$7-1,0))) -> 0.13962249 | AA17: =SQRT($B$9*AVERAGE(W17:OFFSET(W17,$B$8-1,0))) -> 0.26892234 | AC17: =(LN(I17/I18))^2 -> 1.590159e-05 | AD17: =SQRT($B$9*SUM(AC17:OFFSET(AC17,$B$5-1,0))/($B$5-1)) -> 0.11667869 | AE17: =SQRT($B$9*SUM(AC17:OFFSET(AC17,$B$6-1,0))/($B$6-1)) -> 0.1677571 | AF17: =SQRT($B$9*SUM(AC17:OFFSET(AC17,$B$7-1,0))/($B$7-1)) -> 0.13433796 | AG17: =SQRT($B$9*SUM(AC17:OFFSET(AC17,$B$8-1,0))/($B$8-1)) -> 0.31526682 | AI17: =LN(I17/I18) -> 0.0039876797 | AJ17: =SQRT($B$9)*_xlfn.STDEV.S(AI17:OFFSET(AI17,$B$5-1,0)) -> 0.10155409 | AK17: =SQRT($B$9)*_xlfn.STDEV.S(AI17:OFFSET(AI17,$B$6-1,0)) -> 0.1661949 | AL17: =SQRT($B$9)*_xlfn.STDEV.S(AI17:OFFSET(AI17,$B$7-1,0)) -> 0.13168567 | AM17: =SQRT($B$9)*_xlfn.STDEV.S(AI17:OFFSET(AI17,$B$8-1,0)) -> 0.31344183
E18: 45650 | F18: 2.728 | G18: 2.759 | H18: 2.717 | I18: 2.753 | K18: =(LN(G18/H18))^2 -> 0.00023531452 | L18: =SQRT(AVERAGE(K18:OFFSET(K18,$B$5-1,0))*$B$9/(4*LN(2))) -> 0.11434438 | M18: =SQRT(AVERAGE(K18:OFFSET(K18,$B$6-1,0))*$B$9/(4*LN(2))) -> 0.12441405 | N18: =SQRT(AVERAGE(K18:OFFSET(K18,$B$7-1,0))*$B$9/(4*LN(2))) -> 0.13775649 | O18: =SQRT(AVERAGE(K18:OFFSET(K18,$B$8-1,0))*$B$9/(4*LN(2))) -> 0.28237116 | Q18: =0.511*(LN(G18/H18))^2-0.019*(LN(I18/F18)*LN(G18*H18/F18^2)-2*LN(G18/F18)*LN(H18/F18))-0.383*(LN(I18/F18))^2 -> 8.5379463e-05 | R18: =SQRT($B$9*AVERAGE((Q18:OFFSET(Q18,$B$5-1,0)))) -> 0.12129745 | S18: =SQRT($B$9*AVERAGE((Q18:OFFSET(Q18,$B$6-1,0)))) -> 0.12138421 | T18: =SQRT($B$9*AVERAGE((Q18:OFFSET(Q18,$B$7-1,0)))) -> 0.13936757 | U18: =SQRT($B$9*AVERAGE((Q18:OFFSET(Q18,$B$8-1,0)))) -> 0.27613725 | W18: =LN(G18/I18)*LN(G18/F18)+LN(H18/I18)*LN(H18/F18) -> 7.7783402e-05 | X18: =SQRT($B$9*AVERAGE(W18:OFFSET(W18,$B$5-1,0))) -> 0.12409777 | Y18: =SQRT($B$9*AVERAGE(W18:OFFSET(W18,$B$6-1,0))) -> 0.12110954 | Z18: =SQRT($B$9*AVERAGE(W18:OFFSET(W18,$B$7-1,0))) -> 0.14066369 | AA18: =SQRT($B$9*AVERAGE(W18:OFFSET(W18,$B$8-1,0))) -> 0.27075064 | AC18: =(LN(I18/I19))^2 -> 0.00011214467 | AD18: =SQRT($B$9*SUM(AC18:OFFSET(AC18,$B$5-1,0))/($B$5-1)) -> 0.12510728 | AE18: =SQRT($B$9*SUM(AC18:OFFSET(AC18,$B$6-1,0))/($B$6-1)) -> 0.16996671 | AF18: =SQRT($B$9*SUM(AC18:OFFSET(AC18,$B$7-1,0))/($B$7-1)) -> 0.14012724 | AG18: =SQRT($B$9*SUM(AC18:OFFSET(AC18,$B$8-1,0))/($B$8-1)) -> 0.31613639 | AI18: =LN(I18/I19) -> 0.010589838 | AJ18: =SQRT($B$9)*_xlfn.STDEV.S(AI18:OFFSET(AI18,$B$5-1,0)) -> 0.10498881 | AK18: =SQRT($B$9)*_xlfn.STDEV.S(AI18:OFFSET(AI18,$B$6-1,0)) -> 0.16988083 | AL18: =SQRT($B$9)*_xlfn.STDEV.S(AI18:OFFSET(AI18,$B$7-1,0)) -> 0.13622673 | AM18: =SQRT($B$9)*_xlfn.STDEV.S(AI18:OFFSET(AI18,$B$8-1,0)) -> 0.314077
E19: 45649 | F19: 2.701 | G19: 2.741 | H19: 2.701 | I19: 2.724 | K19: =(LN(G19/H19))^2 -> 0.00021611183 | L19: =SQRT(AVERAGE(K19:OFFSET(K19,$B$5-1,0))*$B$9/(4*LN(2))) -> 0.11308922 | M19: =SQRT(AVERAGE(K19:OFFSET(K19,$B$6-1,0))*$B$9/(4*LN(2))) -> 0.1409491 | N19: =SQRT(AVERAGE(K19:OFFSET(K19,$B$7-1,0))*$B$9/(4*LN(2))) -> 0.13717003 | O19: =SQRT(AVERAGE(K19:OFFSET(K19,$B$8-1,0))*$B$9/(4*LN(2))) -> 0.28672746 | Q19: =0.511*(LN(G19/H19))^2-0.019*(LN(I19/F19)*LN(G19*H19/F19^2)-2*LN(G19/F19)*LN(H19/F19))-0.383*(LN(I19/F19))^2 -> 8.0527529e-05 | R19: =SQRT($B$9*AVERAGE((Q19:OFFSET(Q19,$B$5-1,0)))) -> 0.12282182 | S19: =SQRT($B$9*AVERAGE((Q19:OFFSET(Q19,$B$6-1,0)))) -> 0.13359414 | T19: =SQRT($B$9*AVERAGE((Q19:OFFSET(Q19,$B$7-1,0)))) -> 0.13905589 | U19: =SQRT($B$9*AVERAGE((Q19:OFFSET(Q19,$B$8-1,0)))) -> 0.27817251 | W19: =LN(G19/I19)*LN(G19/F19)+LN(H19/I19)*LN(H19/F19) -> 9.1459626e-05 | X19: =SQRT($B$9*AVERAGE(W19:OFFSET(W19,$B$5-1,0))) -> 0.13219532 | Y19: =SQRT($B$9*AVERAGE(W19:OFFSET(W19,$B$6-1,0))) -> 0.13002917 | Z19: =SQRT($B$9*AVERAGE(W19:OFFSET(W19,$B$7-1,0))) -> 0.14115877 | AA19: =SQRT($B$9*AVERAGE(W19:OFFSET(W19,$B$8-1,0))) -> 0.27170819 | AC19: =(LN(I19/I20))^2 -> 7.1898757e-05 | AD19: =SQRT($B$9*SUM(AC19:OFFSET(AC19,$B$5-1,0))/($B$5-1)) -> 0.10216813 | AE19: =SQRT($B$9*SUM(AC19:OFFSET(AC19,$B$6-1,0))/($B$6-1)) -> 0.16767897 | AF19: =SQRT($B$9*SUM(AC19:OFFSET(AC19,$B$7-1,0))/($B$7-1)) -> 0.13552676 | AG19: =SQRT($B$9*SUM(AC19:OFFSET(AC19,$B$8-1,0))/($B$8-1)) -> 0.33158611 | AI19: =LN(I19/I20) -> 0.0084793135 | AJ19: =SQRT($B$9)*_xlfn.STDEV.S(AI19:OFFSET(AI19,$B$5-1,0)) -> 0.089558554 | AK19: =SQRT($B$9)*_xlfn.STDEV.S(AI19:OFFSET(AI19,$B$6-1,0)) -> 0.16765157 | AL19: =SQRT($B$9)*_xlfn.STDEV.S(AI19:OFFSET(AI19,$B$7-1,0)) -> 0.13274636 | AM19: =SQRT($B$9)*_xlfn.STDEV.S(AI19:OFFSET(AI19,$B$8-1,0)) -> 0.32831632
E20: 45646 | F20: 2.705 | G20: 2.722 | H20: 2.695 | I20: 2.701 | K20: =(LN(G20/H20))^2 -> 9.9374977e-05 | L20: =SQRT(AVERAGE(K20:OFFSET(K20,$B$5-1,0))*$B$9/(4*LN(2))) -> 0.097209026 | M20: =SQRT(AVERAGE(K20:OFFSET(K20,$B$6-1,0))*$B$9/(4*LN(2))) -> 0.13876003 | N20: =SQRT(AVERAGE(K20:OFFSET(K20,$B$7-1,0))*$B$9/(4*LN(2))) -> 0.14033869 | O20: =SQRT(AVERAGE(K20:OFFSET(K20,$B$8-1,0))*$B$9/(4*LN(2))) -> 0.28644456 | Q20: =0.511*(LN(G20/H20))^2-0.019*(LN(I20/F20)*LN(G20*H20/F20^2)-2*LN(G20/F20)*LN(H20/F20))-0.383*(LN(I20/F20))^2 -> 4.9132149e-05 | R20: =SQRT($B$9*AVERAGE((Q20:OFFSET(Q20,$B$5-1,0)))) -> 0.10846253 | S20: =SQRT($B$9*AVERAGE((Q20:OFFSET(Q20,$B$6-1,0)))) -> 0.13280988 | T20: =SQRT($B$9*AVERAGE((Q20:OFFSET(Q20,$B$7-1,0)))) -> 0.1431364 | U20: =SQRT($B$9*AVERAGE((Q20:OFFSET(Q20,$B$8-1,0)))) -> 0.27792996 | W20: =LN(G20/I20)*LN(G20/F20)+LN(H20/I20)*LN(H20/F20) -> 5.675786e-05 | X20: =SQRT($B$9*AVERAGE(W20:OFFSET(W20,$B$5-1,0))) -> 0.1166993 | Y20: =SQRT($B$9*AVERAGE(W20:OFFSET(W20,$B$6-1,0))) -> 0.12951223 | Z20: =SQRT($B$9*AVERAGE(W20:OFFSET(W20,$B$7-1,0))) -> 0.1443012 | AA20: =SQRT($B$9*AVERAGE(W20:OFFSET(W20,$B$8-1,0))) -> 0.27144589 | AC20: =(LN(I20/I21))^2 -> 8.746737e-06 | AD20: =SQRT($B$9*SUM(AC20:OFFSET(AC20,$B$5-1,0))/($B$5-1)) -> 0.078550376 | AE20: =SQRT($B$9*SUM(AC20:OFFSET(AC20,$B$6-1,0))/($B$6-1)) -> 0.16183995 | AF20: =SQRT($B$9*SUM(AC20:OFFSET(AC20,$B$7-1,0))/($B$7-1)) -> 0.13556234 | AG20: =SQRT($B$9*SUM(AC20:OFFSET(AC20,$B$8-1,0))/($B$8-1)) -> 0.33119235 | AI20: =LN(I20/I21) -> -0.0029574883 | AJ20: =SQRT($B$9)*_xlfn.STDEV.S(AI20:OFFSET(AI20,$B$5-1,0)) -> 0.07724089 | AK20: =SQRT($B$9)*_xlfn.STDEV.S(AI20:OFFSET(AI20,$B$6-1,0)) -> 0.16158179 | AL20: =SQRT($B$9)*_xlfn.STDEV.S(AI20:OFFSET(AI20,$B$7-1,0)) -> 0.13487246 | AM20: =SQRT($B$9)*_xlfn.STDEV.S(AI20:OFFSET(AI20,$B$8-1,0)) -> 0.32811929
E21: 45645 | F21: 2.7 | G21: 2.719 | H21: 2.687 | I21: 2.709 | K21: =(LN(G21/H21))^2 -> 0.00014015804 | L21: =SQRT(AVERAGE(K21:OFFSET(K21,$B$5-1,0))*$B$9/(4*LN(2))) -> 0.12784521 | M21: =SQRT(AVERAGE(K21:OFFSET(K21,$B$6-1,0))*$B$9/(4*LN(2))) -> 0.14839211 | N21: =SQRT(AVERAGE(K21:OFFSET(K21,$B$7-1,0))*$B$9/(4*LN(2))) -> 0.15423209 | O21: =SQRT(AVERAGE(K21:OFFSET(K21,$B$8-1,0))*$B$9/(4*LN(2))) -> 0.28665021 | Q21: =0.511*(LN(G21/H21))^2-0.019*(LN(I21/F21)*LN(G21*H21/F21^2)-2*LN(G21/F21)*LN(H21/F21))-0.383*(LN(I21/F21))^2 -> 6.5955024e-05 | R21: =SQRT($B$9*AVERAGE((Q21:OFFSET(Q21,$B$5-1,0)))) -> 0.12084893 | S21: =SQRT($B$9*AVERAGE((Q21:OFFSET(Q21,$B$6-1,0)))) -> 0.14308766 | T21: =SQRT($B$9*AVERAGE((Q21:OFFSET(Q21,$B$7-1,0)))) -> 0.1497099 | U21: =SQRT($B$9*AVERAGE((Q21:OFFSET(Q21,$B$8-1,0)))) -> 0.27819658 | W21: =LN(G21/I21)*LN(G21/F21)+LN(H21/I21)*LN(H21/F21) -> 6.5193826e-05 | X21: =SQRT($B$9*AVERAGE(W21:OFFSET(W21,$B$5-1,0))) -> 0.11981446 | Y21: =SQRT($B$9*AVERAGE(W21:OFFSET(W21,$B$6-1,0))) -> 0.1392587 | Z21: =SQRT($B$9*AVERAGE(W21:OFFSET(W21,$B$7-1,0))) -> 0.14697955 | AA21: =SQRT($B$9*AVERAGE(W21:OFFSET(W21,$B$8-1,0))) -> 0.27170676 | AC21: =(LN(I21/I22))^2 -> 1.3576296e-05 | AD21: =SQRT($B$9*SUM(AC21:OFFSET(AC21,$B$5-1,0))/($B$5-1)) -> 0.20665506 | AE21: =SQRT($B$9*SUM(AC21:OFFSET(AC21,$B$6-1,0))/($B$6-1)) -> 0.1705611 | AF21: =SQRT($B$9*SUM(AC21:OFFSET(AC21,$B$7-1,0))/($B$7-1)) -> 0.17160711 | AG21: =SQRT($B$9*SUM(AC21:OFFSET(AC21,$B$8-1,0))/($B$8-1)) -> 0.33115614 | AI21: =LN(I21/I22) -> -0.0036846025 | AJ21: =SQRT($B$9)*_xlfn.STDEV.S(AI21:OFFSET(AI21,$B$5-1,0)) -> 0.1973004 | AK21: =SQRT($B$9)*_xlfn.STDEV.S(AI21:OFFSET(AI21,$B$6-1,0)) -> 0.17002966 | AL21: =SQRT($B$9)*_xlfn.STDEV.S(AI21:OFFSET(AI21,$B$7-1,0)) -> 0.1714381 | AM21: =SQRT($B$9)*_xlfn.STDEV.S(AI21:OFFSET(AI21,$B$8-1,0)) -> 0.32791143
... E253: 45294 | F253: 2.2772133 | G253: 2.2889717 | H253: 2.2732938 | I253: 2.2850522 | K253: =(LN(G253/H253))^2 -> 4.723647e-05 | L253: =SQRT(AVERAGE(K253:OFFSET(K253,$B$5-1,0))*$B$9/(4*LN(2))) -> #DIV/0! | M253: =SQRT(AVERAGE(K253:OFFSET(K253,$B$6-1,0))*$B$9/(4*LN(2))) -> #DIV/0! | N253: =SQRT(AVERAGE(K253:OFFSET(K253,$B$7-1,0))*$B$9/(4*LN(2))) -> #DIV/0! | O253: =SQRT(AVERAGE(K253:OFFSET(K253,$B$8-1,0))*$B$9/(4*LN(2))) -> #DIV/0! | Q253: =0.511*(LN(G253/H253))^2-0.019*(LN(I253/F253)*LN(G253*H253/F253^2)-2*LN(G253/F253)*LN(H253/F253))-0.383*(LN(I253/F253))^2 -> 1.9054039e-05 | R253: =SQRT($B$9*AVERAGE((Q253:OFFSET(Q253,$B$5-1,0)))) -> #DIV/0! | S253: =SQRT($B$9*AVERAGE((Q253:OFFSET(Q253,$B$6-1,0)))) -> #DIV/0! | T253: =SQRT($B$9*AVERAGE((Q253:OFFSET(Q253,$B$7-1,0)))) -> #DIV/0! | U253: =SQRT($B$9*AVERAGE((Q253:OFFSET(Q253,$B$8-1,0)))) -> #DIV/0! | W253: =LN(G253/I253)*LN(G253/F253)+LN(H253/I253)*LN(H253/F253) -> 1.771375e-05 | X253: =SQRT($B$9*AVERAGE(W253:OFFSET(W253,$B$5-1,0))) -> #DIV/0! | Y253: =SQRT($B$9*AVERAGE(W253:OFFSET(W253,$B$6-1,0))) -> #DIV/0! | Z253: =SQRT($B$9*AVERAGE(W253:OFFSET(W253,$B$7-1,0))) -> #DIV/0! | AA253: =SQRT($B$9*AVERAGE(W253:OFFSET(W253,$B$8-1,0))) -> #DIV/0! | AC253: =(LN(I253/I254))^2 -> #DIV/0! | AD253: =SQRT($B$9*SUM(AC253:OFFSET(AC253,$B$5-1,0))/($B$5-1)) -> #DIV/0! | AE253: =SQRT($B$9*SUM(AC253:OFFSET(AC253,$B$6-1,0))/($B$6-1)) -> #DIV/0! | AF253: =SQRT($B$9*SUM(AC253:OFFSET(AC253,$B$7-1,0))/($B$7-1)) -> #DIV/0! | AG253: =SQRT($B$9*SUM(AC253:OFFSET(AC253,$B$8-1,0))/($B$8-1)) -> #DIV/0! | AI253: =LN(I253/I254) -> #DIV/0! | AJ253: =SQRT($B$9)*_xlfn.STDEV.S(AI253:OFFSET(AI253,$B$5-1,0)) -> #DIV/0! | AK253: =SQRT($B$9)*_xlfn.STDEV.S(AI253:OFFSET(AI253,$B$6-1,0)) -> #DIV/0! | AL253: =SQRT($B$9)*_xlfn.STDEV.S(AI253:OFFSET(AI253,$B$7-1,0)) -> #DIV/0! | AM253: =SQRT($B$9)*_xlfn.STDEV.S(AI253:OFFSET(AI253,$B$8-1,0)) -> #DIV/0!
E254: 45282 | K254: =(LN(G254/H254))^2 -> #DIV/0! | L254: =SQRT(AVERAGE(K254:OFFSET(K254,$B$5-1,0))*$B$9/(4*LN(2))) -> #DIV/0! | M254: =SQRT(AVERAGE(K254:OFFSET(K254,$B$6-1,0))*$B$9/(4*LN(2))) -> #DIV/0! | N254: =SQRT(AVERAGE(K254:OFFSET(K254,$B$7-1,0))*$B$9/(4*LN(2))) -> #DIV/0! | O254: =SQRT(AVERAGE(K254:OFFSET(K254,$B$8-1,0))*$B$9/(4*LN(2))) -> #DIV/0! | Q254: =0.511*(LN(G254/H254))^2-0.019*(LN(I254/F254)*LN(G254*H254/F254^2)-2*LN(G254/F254)*LN(H254/F254))-0.383*(LN(I254/F254))^2 -> #DIV/0! | R254: =SQRT($B$9*AVERAGE((Q254:OFFSET(Q254,$B$5-1,0)))) -> #DIV/0! | S254: =SQRT($B$9*AVERAGE((Q254:OFFSET(Q254,$B$6-1,0)))) -> #DIV/0! | T254: =SQRT($B$9*AVERAGE((Q254:OFFSET(Q254,$B$7-1,0)))) -> #DIV/0! | U254: =SQRT($B$9*AVERAGE((Q254:OFFSET(Q254,$B$8-1,0)))) -> #DIV/0! | W254: =LN(G254/I254)*LN(G254/F254)+LN(H254/I254)*LN(H254/F254) -> #DIV/0! | X254: =SQRT($B$9*AVERAGE(W254:OFFSET(W254,$B$5-1,0))) -> #DIV/0! | Y254: =SQRT($B$9*AVERAGE(W254:OFFSET(W254,$B$6-1,0))) -> #DIV/0! | Z254: =SQRT($B$9*AVERAGE(W254:OFFSET(W254,$B$7-1,0))) -> #DIV/0! | AA254: =SQRT($B$9*AVERAGE(W254:OFFSET(W254,$B$8-1,0))) -> #DIV/0! | AC254: =(LN(I254/I255))^2 -> #DIV/0! | AD254: =SQRT($B$9*SUM(AC254:OFFSET(AC254,$B$5-1,0))/($B$5-1)) -> #DIV/0! | AE254: =SQRT($B$9*SUM(AC254:OFFSET(AC254,$B$6-1,0))/($B$6-1)) -> #DIV/0! | AF254: =SQRT($B$9*SUM(AC254:OFFSET(AC254,$B$7-1,0))/($B$7-1)) -> #DIV/0! | AG254: =SQRT($B$9*SUM(AC254:OFFSET(AC254,$B$8-1,0))/($B$8-1)) -> #DIV/0! | AI254: =LN(I254/I255) -> #DIV/0! | AJ254: =SQRT($B$9)*_xlfn.STDEV.S(AI254:OFFSET(AI254,$B$5-1,0)) -> #DIV/0! | AK254: =SQRT($B$9)*_xlfn.STDEV.S(AI254:OFFSET(AI254,$B$6-1,0)) -> #DIV/0! | AL254: =SQRT($B$9)*_xlfn.STDEV.S(AI254:OFFSET(AI254,$B$7-1,0)) -> #DIV/0! | AM254: =SQRT($B$9)*_xlfn.STDEV.S(AI254:OFFSET(AI254,$B$8-1,0)) -> #DIV/0!
E255: 45281 | K255: =(LN(G255/H255))^2 -> #DIV/0! | L255: =SQRT(AVERAGE(K255:OFFSET(K255,$B$5-1,0))*$B$9/(4*LN(2))) -> #DIV/0! | M255: =SQRT(AVERAGE(K255:OFFSET(K255,$B$6-1,0))*$B$9/(4*LN(2))) -> #DIV/0! | N255: =SQRT(AVERAGE(K255:OFFSET(K255,$B$7-1,0))*$B$9/(4*LN(2))) -> #DIV/0! | O255: =SQRT(AVERAGE(K255:OFFSET(K255,$B$8-1,0))*$B$9/(4*LN(2))) -> #DIV/0! | Q255: =0.511*(LN(G255/H255))^2-0.019*(LN(I255/F255)*LN(G255*H255/F255^2)-2*LN(G255/F255)*LN(H255/F255))-0.383*(LN(I255/F255))^2 -> #DIV/0! | R255: =SQRT($B$9*AVERAGE((Q255:OFFSET(Q255,$B$5-1,0)))) -> #DIV/0! | S255: =SQRT($B$9*AVERAGE((Q255:OFFSET(Q255,$B$6-1,0)))) -> #DIV/0! | T255: =SQRT($B$9*AVERAGE((Q255:OFFSET(Q255,$B$7-1,0)))) -> #DIV/0! | U255: =SQRT($B$9*AVERAGE((Q255:OFFSET(Q255,$B$8-1,0)))) -> #DIV/0! | W255: =LN(G255/I255)*LN(G255/F255)+LN(H255/I255)*LN(H255/F255) -> #DIV/0! | X255: =SQRT($B$9*AVERAGE(W255:OFFSET(W255,$B$5-1,0))) -> #DIV/0! | Y255: =SQRT($B$9*AVERAGE(W255:OFFSET(W255,$B$6-1,0))) -> #DIV/0! | Z255: =SQRT($B$9*AVERAGE(W255:OFFSET(W255,$B$7-1,0))) -> #DIV/0! | AA255: =SQRT($B$9*AVERAGE(W255:OFFSET(W255,$B$8-1,0))) -> #DIV/0! | AC255: =(LN(I255/I256))^2 -> #DIV/0! | AD255: =SQRT($B$9*SUM(AC255:OFFSET(AC255,$B$5-1,0))/($B$5-1)) -> #DIV/0! | AE255: =SQRT($B$9*SUM(AC255:OFFSET(AC255,$B$6-1,0))/($B$6-1)) -> #DIV/0! | AF255: =SQRT($B$9*SUM(AC255:OFFSET(AC255,$B$7-1,0))/($B$7-1)) -> #DIV/0! | AG255: =SQRT($B$9*SUM(AC255:OFFSET(AC255,$B$8-1,0))/($B$8-1)) -> #DIV/0! | AI255: =LN(I255/I256) -> #DIV/0! | AJ255: =SQRT($B$9)*_xlfn.STDEV.S(AI255:OFFSET(AI255,$B$5-1,0)) -> #DIV/0! | AK255: =SQRT($B$9)*_xlfn.STDEV.S(AI255:OFFSET(AI255,$B$6-1,0)) -> #DIV/0! | AL255: =SQRT($B$9)*_xlfn.STDEV.S(AI255:OFFSET(AI255,$B$7-1,0)) -> #DIV/0! | AM255: =SQRT($B$9)*_xlfn.STDEV.S(AI255:OFFSET(AI255,$B$8-1,0)) -> #DIV/0!
E256: 45280 | K256: =(LN(G256/H256))^2 -> #DIV/0! | L256: =SQRT(AVERAGE(K256:OFFSET(K256,$B$5-1,0))*$B$9/(4*LN(2))) -> #DIV/0! | M256: =SQRT(AVERAGE(K256:OFFSET(K256,$B$6-1,0))*$B$9/(4*LN(2))) -> #DIV/0! | N256: =SQRT(AVERAGE(K256:OFFSET(K256,$B$7-1,0))*$B$9/(4*LN(2))) -> #DIV/0! | O256: =SQRT(AVERAGE(K256:OFFSET(K256,$B$8-1,0))*$B$9/(4*LN(2))) -> #DIV/0! | Q256: =0.511*(LN(G256/H256))^2-0.019*(LN(I256/F256)*LN(G256*H256/F256^2)-2*LN(G256/F256)*LN(H256/F256))-0.383*(LN(I256/F256))^2 -> #DIV/0! | R256: =SQRT($B$9*AVERAGE((Q256:OFFSET(Q256,$B$5-1,0)))) -> #DIV/0! | S256: =SQRT($B$9*AVERAGE((Q256:OFFSET(Q256,$B$6-1,0)))) -> #DIV/0! | T256: =SQRT($B$9*AVERAGE((Q256:OFFSET(Q256,$B$7-1,0)))) -> #DIV/0! | U256: =SQRT($B$9*AVERAGE((Q256:OFFSET(Q256,$B$8-1,0)))) -> #DIV/0! | W256: =LN(G256/I256)*LN(G256/F256)+LN(H256/I256)*LN(H256/F256) -> #DIV/0! | X256: =SQRT($B$9*AVERAGE(W256:OFFSET(W256,$B$5-1,0))) -> #DIV/0! | Y256: =SQRT($B$9*AVERAGE(W256:OFFSET(W256,$B$6-1,0))) -> #DIV/0! | Z256: =SQRT($B$9*AVERAGE(W256:OFFSET(W256,$B$7-1,0))) -> #DIV/0! | AA256: =SQRT($B$9*AVERAGE(W256:OFFSET(W256,$B$8-1,0))) -> #DIV/0! | AC256: =(LN(I256/I257))^2 -> #DIV/0! | AD256: =SQRT($B$9*SUM(AC256:OFFSET(AC256,$B$5-1,0))/($B$5-1)) -> #DIV/0! | AE256: =SQRT($B$9*SUM(AC256:OFFSET(AC256,$B$6-1,0))/($B$6-1)) -> #DIV/0! | AF256: =SQRT($B$9*SUM(AC256:OFFSET(AC256,$B$7-1,0))/($B$7-1)) -> #DIV/0! | AG256: =SQRT($B$9*SUM(AC256:OFFSET(AC256,$B$8-1,0))/($B$8-1)) -> #DIV/0! | AI256: =LN(I256/I257) -> #DIV/0! | AJ256: =SQRT($B$9)*_xlfn.STDEV.S(AI256:OFFSET(AI256,$B$5-1,0)) -> #DIV/0! | AK256: =SQRT($B$9)*_xlfn.STDEV.S(AI256:OFFSET(AI256,$B$6-1,0)) -> #DIV/0! | AL256: =SQRT($B$9)*_xlfn.STDEV.S(AI256:OFFSET(AI256,$B$7-1,0)) -> #DIV/0! | AM256: =SQRT($B$9)*_xlfn.STDEV.S(AI256:OFFSET(AI256,$B$8-1,0)) -> #DIV/0!
E257: 45279 | K257: =(LN(G257/H257))^2 -> #DIV/0! | L257: =SQRT(AVERAGE(K257:OFFSET(K257,$B$5-1,0))*$B$9/(4*LN(2))) -> #DIV/0! | M257: =SQRT(AVERAGE(K257:OFFSET(K257,$B$6-1,0))*$B$9/(4*LN(2))) -> #DIV/0! | N257: =SQRT(AVERAGE(K257:OFFSET(K257,$B$7-1,0))*$B$9/(4*LN(2))) -> #DIV/0! | O257: =SQRT(AVERAGE(K257:OFFSET(K257,$B$8-1,0))*$B$9/(4*LN(2))) -> #DIV/0! | Q257: =0.511*(LN(G257/H257))^2-0.019*(LN(I257/F257)*LN(G257*H257/F257^2)-2*LN(G257/F257)*LN(H257/F257))-0.383*(LN(I257/F257))^2 -> #DIV/0! | R257: =SQRT($B$9*AVERAGE((Q257:OFFSET(Q257,$B$5-1,0)))) -> #DIV/0! | S257: =SQRT($B$9*AVERAGE((Q257:OFFSET(Q257,$B$6-1,0)))) -> #DIV/0! | T257: =SQRT($B$9*AVERAGE((Q257:OFFSET(Q257,$B$7-1,0)))) -> #DIV/0! | U257: =SQRT($B$9*AVERAGE((Q257:OFFSET(Q257,$B$8-1,0)))) -> #DIV/0! | W257: =LN(G257/I257)*LN(G257/F257)+LN(H257/I257)*LN(H257/F257) -> #DIV/0! | X257: =SQRT($B$9*AVERAGE(W257:OFFSET(W257,$B$5-1,0))) -> #DIV/0! | Y257: =SQRT($B$9*AVERAGE(W257:OFFSET(W257,$B$6-1,0))) -> #DIV/0! | Z257: =SQRT($B$9*AVERAGE(W257:OFFSET(W257,$B$7-1,0))) -> #DIV/0! | AA257: =SQRT($B$9*AVERAGE(W257:OFFSET(W257,$B$8-1,0))) -> #DIV/0! | AC257: =(LN(I257/I258))^2 -> #DIV/0! | AD257: =SQRT($B$9*SUM(AC257:OFFSET(AC257,$B$5-1,0))/($B$5-1)) -> #DIV/0! | AE257: =SQRT($B$9*SUM(AC257:OFFSET(AC257,$B$6-1,0))/($B$6-1)) -> #DIV/0! | AF257: =SQRT($B$9*SUM(AC257:OFFSET(AC257,$B$7-1,0))/($B$7-1)) -> #DIV/0! | AG257: =SQRT($B$9*SUM(AC257:OFFSET(AC257,$B$8-1,0))/($B$8-1)) -> #DIV/0! | AI257: =LN(I257/I258) -> #DIV/0! | AJ257: =SQRT($B$9)*_xlfn.STDEV.S(AI257:OFFSET(AI257,$B$5-1,0)) -> #DIV/0! | AK257: =SQRT($B$9)*_xlfn.STDEV.S(AI257:OFFSET(AI257,$B$6-1,0)) -> #DIV/0! | AL257: =SQRT($B$9)*_xlfn.STDEV.S(AI257:OFFSET(AI257,$B$7-1,0)) -> #DIV/0! | AM257: =SQRT($B$9)*_xlfn.STDEV.S(AI257:OFFSET(AI257,$B$8-1,0)) -> #DIV/0!
E258: 45278 | K258: =(LN(G258/H258))^2 -> #DIV/0! | L258: =SQRT(AVERAGE(K258:OFFSET(K258,$B$5-1,0))*$B$9/(4*LN(2))) -> #DIV/0! | M258: =SQRT(AVERAGE(K258:OFFSET(K258,$B$6-1,0))*$B$9/(4*LN(2))) -> #DIV/0! | N258: =SQRT(AVERAGE(K258:OFFSET(K258,$B$7-1,0))*$B$9/(4*LN(2))) -> #DIV/0! | O258: =SQRT(AVERAGE(K258:OFFSET(K258,$B$8-1,0))*$B$9/(4*LN(2))) -> #DIV/0! | Q258: =0.511*(LN(G258/H258))^2-0.019*(LN(I258/F258)*LN(G258*H258/F258^2)-2*LN(G258/F258)*LN(H258/F258))-0.383*(LN(I258/F258))^2 -> #DIV/0! | R258: =SQRT($B$9*AVERAGE((Q258:OFFSET(Q258,$B$5-1,0)))) -> #DIV/0! | S258: =SQRT($B$9*AVERAGE((Q258:OFFSET(Q258,$B$6-1,0)))) -> #DIV/0! | T258: =SQRT($B$9*AVERAGE((Q258:OFFSET(Q258,$B$7-1,0)))) -> #DIV/0! | U258: =SQRT($B$9*AVERAGE((Q258:OFFSET(Q258,$B$8-1,0)))) -> #DIV/0! | W258: =LN(G258/I258)*LN(G258/F258)+LN(H258/I258)*LN(H258/F258) -> #DIV/0! | X258: =SQRT($B$9*AVERAGE(W258:OFFSET(W258,$B$5-1,0))) -> #DIV/0! | Y258: =SQRT($B$9*AVERAGE(W258:OFFSET(W258,$B$6-1,0))) -> #DIV/0! | Z258: =SQRT($B$9*AVERAGE(W258:OFFSET(W258,$B$7-1,0))) -> #DIV/0! | AA258: =SQRT($B$9*AVERAGE(W258:OFFSET(W258,$B$8-1,0))) -> #DIV/0! | AC258: =(LN(I258/I259))^2 -> #DIV/0! | AD258: =SQRT($B$9*SUM(AC258:OFFSET(AC258,$B$5-1,0))/($B$5-1)) -> #DIV/0! | AE258: =SQRT($B$9*SUM(AC258:OFFSET(AC258,$B$6-1,0))/($B$6-1)) -> #DIV/0! | AF258: =SQRT($B$9*SUM(AC258:OFFSET(AC258,$B$7-1,0))/($B$7-1)) -> #DIV/0! | AG258: =SQRT($B$9*SUM(AC258:OFFSET(AC258,$B$8-1,0))/($B$8-1)) -> #DIV/0! | AI258: =LN(I258/I259) -> #DIV/0! | AJ258: =SQRT($B$9)*_xlfn.STDEV.S(AI258:OFFSET(AI258,$B$5-1,0)) -> #DIV/0! | AK258: =SQRT($B$9)*_xlfn.STDEV.S(AI258:OFFSET(AI258,$B$6-1,0)) -> #DIV/0! | AL258: =SQRT($B$9)*_xlfn.STDEV.S(AI258:OFFSET(AI258,$B$7-1,0)) -> #DIV/0! | AM258: =SQRT($B$9)*_xlfn.STDEV.S(AI258:OFFSET(AI258,$B$8-1,0)) -> #DIV/0!
E259: 45275 | K259: =(LN(G259/H259))^2 -> #DIV/0! | L259: =SQRT(AVERAGE(K259:OFFSET(K259,$B$5-1,0))*$B$9/(4*LN(2))) -> #DIV/0! | M259: =SQRT(AVERAGE(K259:OFFSET(K259,$B$6-1,0))*$B$9/(4*LN(2))) -> #DIV/0! | N259: =SQRT(AVERAGE(K259:OFFSET(K259,$B$7-1,0))*$B$9/(4*LN(2))) -> #DIV/0! | O259: =SQRT(AVERAGE(K259:OFFSET(K259,$B$8-1,0))*$B$9/(4*LN(2))) -> #DIV/0! | Q259: =0.511*(LN(G259/H259))^2-0.019*(LN(I259/F259)*LN(G259*H259/F259^2)-2*LN(G259/F259)*LN(H259/F259))-0.383*(LN(I259/F259))^2 -> #DIV/0! | R259: =SQRT($B$9*AVERAGE((Q259:OFFSET(Q259,$B$5-1,0)))) -> #DIV/0! | S259: =SQRT($B$9*AVERAGE((Q259:OFFSET(Q259,$B$6-1,0)))) -> #DIV/0! | T259: =SQRT($B$9*AVERAGE((Q259:OFFSET(Q259,$B$7-1,0)))) -> #DIV/0! | U259: =SQRT($B$9*AVERAGE((Q259:OFFSET(Q259,$B$8-1,0)))) -> #DIV/0! | W259: =LN(G259/I259)*LN(G259/F259)+LN(H259/I259)*LN(H259/F259) -> #DIV/0! | X259: =SQRT($B$9*AVERAGE(W259:OFFSET(W259,$B$5-1,0))) -> #DIV/0! | Y259: =SQRT($B$9*AVERAGE(W259:OFFSET(W259,$B$6-1,0))) -> #DIV/0! | Z259: =SQRT($B$9*AVERAGE(W259:OFFSET(W259,$B$7-1,0))) -> #DIV/0! | AA259: =SQRT($B$9*AVERAGE(W259:OFFSET(W259,$B$8-1,0))) -> #DIV/0! | AC259: =(LN(I259/I260))^2 -> #DIV/0! | AD259: =SQRT($B$9*SUM(AC259:OFFSET(AC259,$B$5-1,0))/($B$5-1)) -> #DIV/0! | AE259: =SQRT($B$9*SUM(AC259:OFFSET(AC259,$B$6-1,0))/($B$6-1)) -> #DIV/0! | AF259: =SQRT($B$9*SUM(AC259:OFFSET(AC259,$B$7-1,0))/($B$7-1)) -> #DIV/0! | AG259: =SQRT($B$9*SUM(AC259:OFFSET(AC259,$B$8-1,0))/($B$8-1)) -> #DIV/0! | AI259: =LN(I259/I260) -> #DIV/0! | AJ259: =SQRT($B$9)*_xlfn.STDEV.S(AI259:OFFSET(AI259,$B$5-1,0)) -> #DIV/0! | AK259: =SQRT($B$9)*_xlfn.STDEV.S(AI259:OFFSET(AI259,$B$6-1,0)) -> #DIV/0! | AL259: =SQRT($B$9)*_xlfn.STDEV.S(AI259:OFFSET(AI259,$B$7-1,0)) -> #DIV/0! | AM259: =SQRT($B$9)*_xlfn.STDEV.S(AI259:OFFSET(AI259,$B$8-1,0)) -> #DIV/0!
E260: 45274 | K260: =(LN(G260/H260))^2 -> #DIV/0! | L260: =SQRT(AVERAGE(K260:OFFSET(K260,$B$5-1,0))*$B$9/(4*LN(2))) -> #DIV/0! | M260: =SQRT(AVERAGE(K260:OFFSET(K260,$B$6-1,0))*$B$9/(4*LN(2))) -> #DIV/0! | N260: =SQRT(AVERAGE(K260:OFFSET(K260,$B$7-1,0))*$B$9/(4*LN(2))) -> #DIV/0! | O260: =SQRT(AVERAGE(K260:OFFSET(K260,$B$8-1,0))*$B$9/(4*LN(2))) -> #DIV/0! | Q260: =0.511*(LN(G260/H260))^2-0.019*(LN(I260/F260)*LN(G260*H260/F260^2)-2*LN(G260/F260)*LN(H260/F260))-0.383*(LN(I260/F260))^2 -> #DIV/0! | R260: =SQRT($B$9*AVERAGE((Q260:OFFSET(Q260,$B$5-1,0)))) -> #DIV/0! | S260: =SQRT($B$9*AVERAGE((Q260:OFFSET(Q260,$B$6-1,0)))) -> #DIV/0! | T260: =SQRT($B$9*AVERAGE((Q260:OFFSET(Q260,$B$7-1,0)))) -> #DIV/0! | U260: =SQRT($B$9*AVERAGE((Q260:OFFSET(Q260,$B$8-1,0)))) -> #DIV/0! | W260: =LN(G260/I260)*LN(G260/F260)+LN(H260/I260)*LN(H260/F260) -> #DIV/0! | X260: =SQRT($B$9*AVERAGE(W260:OFFSET(W260,$B$5-1,0))) -> #DIV/0! | Y260: =SQRT($B$9*AVERAGE(W260:OFFSET(W260,$B$6-1,0))) -> #DIV/0! | Z260: =SQRT($B$9*AVERAGE(W260:OFFSET(W260,$B$7-1,0))) -> #DIV/0! | AA260: =SQRT($B$9*AVERAGE(W260:OFFSET(W260,$B$8-1,0))) -> #DIV/0! | AC260: =(LN(I260/I261))^2 -> #DIV/0! | AD260: =SQRT($B$9*SUM(AC260:OFFSET(AC260,$B$5-1,0))/($B$5-1)) -> #DIV/0! | AE260: =SQRT($B$9*SUM(AC260:OFFSET(AC260,$B$6-1,0))/($B$6-1)) -> #DIV/0! | AF260: =SQRT($B$9*SUM(AC260:OFFSET(AC260,$B$7-1,0))/($B$7-1)) -> #DIV/0! | AG260: =SQRT($B$9*SUM(AC260:OFFSET(AC260,$B$8-1,0))/($B$8-1)) -> #DIV/0! | AI260: =LN(I260/I261) -> #DIV/0! | AJ260: =SQRT($B$9)*_xlfn.STDEV.S(AI260:OFFSET(AI260,$B$5-1,0)) -> #DIV/0! | AK260: =SQRT($B$9)*_xlfn.STDEV.S(AI260:OFFSET(AI260,$B$6-1,0)) -> #DIV/0! | AL260: =SQRT($B$9)*_xlfn.STDEV.S(AI260:OFFSET(AI260,$B$7-1,0)) -> #DIV/0! | AM260: =SQRT($B$9)*_xlfn.STDEV.S(AI260:OFFSET(AI260,$B$8-1,0)) -> #DIV/0!
E261: 45273 | K261: =(LN(G261/H261))^2 -> #DIV/0! | L261: =SQRT(AVERAGE(K261:OFFSET(K261,$B$5-1,0))*$B$9/(4*LN(2))) -> #DIV/0! | M261: =SQRT(AVERAGE(K261:OFFSET(K261,$B$6-1,0))*$B$9/(4*LN(2))) -> #DIV/0! | N261: =SQRT(AVERAGE(K261:OFFSET(K261,$B$7-1,0))*$B$9/(4*LN(2))) -> #DIV/0! | O261: =SQRT(AVERAGE(K261:OFFSET(K261,$B$8-1,0))*$B$9/(4*LN(2))) -> #DIV/0! | Q261: =0.511*(LN(G261/H261))^2-0.019*(LN(I261/F261)*LN(G261*H261/F261^2)-2*LN(G261/F261)*LN(H261/F261))-0.383*(LN(I261/F261))^2 -> #DIV/0! | R261: =SQRT($B$9*AVERAGE((Q261:OFFSET(Q261,$B$5-1,0)))) -> #DIV/0! | S261: =SQRT($B$9*AVERAGE((Q261:OFFSET(Q261,$B$6-1,0)))) -> #DIV/0! | T261: =SQRT($B$9*AVERAGE((Q261:OFFSET(Q261,$B$7-1,0)))) -> #DIV/0! | U261: =SQRT($B$9*AVERAGE((Q261:OFFSET(Q261,$B$8-1,0)))) -> #DIV/0! | W261: =LN(G261/I261)*LN(G261/F261)+LN(H261/I261)*LN(H261/F261) -> #DIV/0! | X261: =SQRT($B$9*AVERAGE(W261:OFFSET(W261,$B$5-1,0))) -> #DIV/0! | Y261: =SQRT($B$9*AVERAGE(W261:OFFSET(W261,$B$6-1,0))) -> #DIV/0! | Z261: =SQRT($B$9*AVERAGE(W261:OFFSET(W261,$B$7-1,0))) -> #DIV/0! | AA261: =SQRT($B$9*AVERAGE(W261:OFFSET(W261,$B$8-1,0))) -> #DIV/0! | AC261: =(LN(I261/I262))^2 -> #DIV/0! | AD261: =SQRT($B$9*SUM(AC261:OFFSET(AC261,$B$5-1,0))/($B$5-1)) -> #DIV/0! | AE261: =SQRT($B$9*SUM(AC261:OFFSET(AC261,$B$6-1,0))/($B$6-1)) -> #DIV/0! | AF261: =SQRT($B$9*SUM(AC261:OFFSET(AC261,$B$7-1,0))/($B$7-1)) -> #DIV/0! | AG261: =SQRT($B$9*SUM(AC261:OFFSET(AC261,$B$8-1,0))/($B$8-1)) -> #DIV/0! | AI261: =LN(I261/I262) -> #DIV/0! | AJ261: =SQRT($B$9)*_xlfn.STDEV.S(AI261:OFFSET(AI261,$B$5-1,0)) -> #DIV/0! | AK261: =SQRT($B$9)*_xlfn.STDEV.S(AI261:OFFSET(AI261,$B$6-1,0)) -> #DIV/0! | AL261: =SQRT($B$9)*_xlfn.STDEV.S(AI261:OFFSET(AI261,$B$7-1,0)) -> #DIV/0! | AM261: =SQRT($B$9)*_xlfn.STDEV.S(AI261:OFFSET(AI261,$B$8-1,0)) -> #DIV/0!
E262: 45272 | K262: =(LN(G262/H262))^2 -> #DIV/0! | L262: =SQRT(AVERAGE(K262:OFFSET(K262,$B$5-1,0))*$B$9/(4*LN(2))) -> #DIV/0! | M262: =SQRT(AVERAGE(K262:OFFSET(K262,$B$6-1,0))*$B$9/(4*LN(2))) -> #DIV/0! | N262: =SQRT(AVERAGE(K262:OFFSET(K262,$B$7-1,0))*$B$9/(4*LN(2))) -> #DIV/0! | O262: =SQRT(AVERAGE(K262:OFFSET(K262,$B$8-1,0))*$B$9/(4*LN(2))) -> #DIV/0! | Q262: =0.511*(LN(G262/H262))^2-0.019*(LN(I262/F262)*LN(G262*H262/F262^2)-2*LN(G262/F262)*LN(H262/F262))-0.383*(LN(I262/F262))^2 -> #DIV/0! | R262: =SQRT($B$9*AVERAGE((Q262:OFFSET(Q262,$B$5-1,0)))) -> #DIV/0! | S262: =SQRT($B$9*AVERAGE((Q262:OFFSET(Q262,$B$6-1,0)))) -> #DIV/0! | T262: =SQRT($B$9*AVERAGE((Q262:OFFSET(Q262,$B$7-1,0)))) -> #DIV/0! | U262: =SQRT($B$9*AVERAGE((Q262:OFFSET(Q262,$B$8-1,0)))) -> #DIV/0! | W262: =LN(G262/I262)*LN(G262/F262)+LN(H262/I262)*LN(H262/F262) -> #DIV/0! | X262: =SQRT($B$9*AVERAGE(W262:OFFSET(W262,$B$5-1,0))) -> #DIV/0! | Y262: =SQRT($B$9*AVERAGE(W262:OFFSET(W262,$B$6-1,0))) -> #DIV/0! | Z262: =SQRT($B$9*AVERAGE(W262:OFFSET(W262,$B$7-1,0))) -> #DIV/0! | AA262: =SQRT($B$9*AVERAGE(W262:OFFSET(W262,$B$8-1,0))) -> #DIV/0! | AC262: =(LN(I262/I263))^2 -> #DIV/0! | AD262: =SQRT($B$9*SUM(AC262:OFFSET(AC262,$B$5-1,0))/($B$5-1)) -> #DIV/0! | AE262: =SQRT($B$9*SUM(AC262:OFFSET(AC262,$B$6-1,0))/($B$6-1)) -> #DIV/0! | AF262: =SQRT($B$9*SUM(AC262:OFFSET(AC262,$B$7-1,0))/($B$7-1)) -> #DIV/0! | AG262: =SQRT($B$9*SUM(AC262:OFFSET(AC262,$B$8-1,0))/($B$8-1)) -> #DIV/0! | AI262: =LN(I262/I263) -> #DIV/0! | AJ262: =SQRT($B$9)*_xlfn.STDEV.S(AI262:OFFSET(AI262,$B$5-1,0)) -> #DIV/0! | AK262: =SQRT($B$9)*_xlfn.STDEV.S(AI262:OFFSET(AI262,$B$6-1,0)) -> #DIV/0! | AL262: =SQRT($B$9)*_xlfn.STDEV.S(AI262:OFFSET(AI262,$B$7-1,0)) -> #DIV/0! | AM262: =SQRT($B$9)*_xlfn.STDEV.S(AI262:OFFSET(AI262,$B$8-1,0)) -> #DIV/0!
E263: 45271 | K263: =(LN(G263/H263))^2 -> #DIV/0! | L263: =SQRT(AVERAGE(K263:OFFSET(K263,$B$5-1,0))*$B$9/(4*LN(2))) -> #DIV/0! | M263: =SQRT(AVERAGE(K263:OFFSET(K263,$B$6-1,0))*$B$9/(4*LN(2))) -> #DIV/0! | N263: =SQRT(AVERAGE(K263:OFFSET(K263,$B$7-1,0))*$B$9/(4*LN(2))) -> #DIV/0! | O263: =SQRT(AVERAGE(K263:OFFSET(K263,$B$8-1,0))*$B$9/(4*LN(2))) -> #DIV/0! | Q263: =0.511*(LN(G263/H263))^2-0.019*(LN(I263/F263)*LN(G263*H263/F263^2)-2*LN(G263/F263)*LN(H263/F263))-0.383*(LN(I263/F263))^2 -> #DIV/0! | R263: =SQRT($B$9*AVERAGE((Q263:OFFSET(Q263,$B$5-1,0)))) -> #DIV/0! | S263: =SQRT($B$9*AVERAGE((Q263:OFFSET(Q263,$B$6-1,0)))) -> #DIV/0! | T263: =SQRT($B$9*AVERAGE((Q263:OFFSET(Q263,$B$7-1,0)))) -> #DIV/0! | U263: =SQRT($B$9*AVERAGE((Q263:OFFSET(Q263,$B$8-1,0)))) -> #DIV/0! | W263: =LN(G263/I263)*LN(G263/F263)+LN(H263/I263)*LN(H263/F263) -> #DIV/0! | X263: =SQRT($B$9*AVERAGE(W263:OFFSET(W263,$B$5-1,0))) -> #DIV/0! | Y263: =SQRT($B$9*AVERAGE(W263:OFFSET(W263,$B$6-1,0))) -> #DIV/0! | Z263: =SQRT($B$9*AVERAGE(W263:OFFSET(W263,$B$7-1,0))) -> #DIV/0! | AA263: =SQRT($B$9*AVERAGE(W263:OFFSET(W263,$B$8-1,0))) -> #DIV/0! | AC263: =(LN(I263/I264))^2 -> #DIV/0! | AD263: =SQRT($B$9*SUM(AC263:OFFSET(AC263,$B$5-1,0))/($B$5-1)) -> #DIV/0! | AE263: =SQRT($B$9*SUM(AC263:OFFSET(AC263,$B$6-1,0))/($B$6-1)) -> #DIV/0! | AF263: =SQRT($B$9*SUM(AC263:OFFSET(AC263,$B$7-1,0))/($B$7-1)) -> #DIV/0! | AG263: =SQRT($B$9*SUM(AC263:OFFSET(AC263,$B$8-1,0))/($B$8-1)) -> #DIV/0! | AI263: =LN(I263/I264) -> #DIV/0! | AJ263: =SQRT($B$9)*_xlfn.STDEV.S(AI263:OFFSET(AI263,$B$5-1,0)) -> #DIV/0! | AK263: =SQRT($B$9)*_xlfn.STDEV.S(AI263:OFFSET(AI263,$B$6-1,0)) -> #DIV/0! | AL263: =SQRT($B$9)*_xlfn.STDEV.S(AI263:OFFSET(AI263,$B$7-1,0)) -> #DIV/0! | AM263: =SQRT($B$9)*_xlfn.STDEV.S(AI263:OFFSET(AI263,$B$8-1,0)) -> #DIV/0!
E264: 45268 | K264: =(LN(G264/H264))^2 -> #DIV/0! | L264: =SQRT(AVERAGE(K264:OFFSET(K264,$B$5-1,0))*$B$9/(4*LN(2))) -> #DIV/0! | M264: =SQRT(AVERAGE(K264:OFFSET(K264,$B$6-1,0))*$B$9/(4*LN(2))) -> #DIV/0! | N264: =SQRT(AVERAGE(K264:OFFSET(K264,$B$7-1,0))*$B$9/(4*LN(2))) -> #DIV/0! | O264: =SQRT(AVERAGE(K264:OFFSET(K264,$B$8-1,0))*$B$9/(4*LN(2))) -> #DIV/0! | Q264: =0.511*(LN(G264/H264))^2-0.019*(LN(I264/F264)*LN(G264*H264/F264^2)-2*LN(G264/F264)*LN(H264/F264))-0.383*(LN(I264/F264))^2 -> #DIV/0! | R264: =SQRT($B$9*AVERAGE((Q264:OFFSET(Q264,$B$5-1,0)))) -> #DIV/0! | S264: =SQRT($B$9*AVERAGE((Q264:OFFSET(Q264,$B$6-1,0)))) -> #DIV/0! | T264: =SQRT($B$9*AVERAGE((Q264:OFFSET(Q264,$B$7-1,0)))) -> #DIV/0! | U264: =SQRT($B$9*AVERAGE((Q264:OFFSET(Q264,$B$8-1,0)))) -> #DIV/0! | W264: =LN(G264/I264)*LN(G264/F264)+LN(H264/I264)*LN(H264/F264) -> #DIV/0! | X264: =SQRT($B$9*AVERAGE(W264:OFFSET(W264,$B$5-1,0))) -> #DIV/0! | Y264: =SQRT($B$9*AVERAGE(W264:OFFSET(W264,$B$6-1,0))) -> #DIV/0! | Z264: =SQRT($B$9*AVERAGE(W264:OFFSET(W264,$B$7-1,0))) -> #DIV/0! | AA264: =SQRT($B$9*AVERAGE(W264:OFFSET(W264,$B$8-1,0))) -> #DIV/0! | AC264: =(LN(I264/I265))^2 -> #DIV/0! | AD264: =SQRT($B$9*SUM(AC264:OFFSET(AC264,$B$5-1,0))/($B$5-1)) -> #DIV/0! | AE264: =SQRT($B$9*SUM(AC264:OFFSET(AC264,$B$6-1,0))/($B$6-1)) -> #DIV/0! | AF264: =SQRT($B$9*SUM(AC264:OFFSET(AC264,$B$7-1,0))/($B$7-1)) -> #DIV/0! | AG264: =SQRT($B$9*SUM(AC264:OFFSET(AC264,$B$8-1,0))/($B$8-1)) -> #DIV/0! | AI264: =LN(I264/I265) -> #DIV/0! | AJ264: =SQRT($B$9)*_xlfn.STDEV.S(AI264:OFFSET(AI264,$B$5-1,0)) -> #DIV/0! | AK264: =SQRT($B$9)*_xlfn.STDEV.S(AI264:OFFSET(AI264,$B$6-1,0)) -> #DIV/0! | AL264: =SQRT($B$9)*_xlfn.STDEV.S(AI264:OFFSET(AI264,$B$7-1,0)) -> #DIV/0! | AM264: =SQRT($B$9)*_xlfn.STDEV.S(AI264:OFFSET(AI264,$B$8-1,0)) -> #DIV/0!
E265: 45267 | K265: =(LN(G265/H265))^2 -> #DIV/0! | L265: =SQRT(AVERAGE(K265:OFFSET(K265,$B$5-1,0))*$B$9/(4*LN(2))) -> #DIV/0! | M265: =SQRT(AVERAGE(K265:OFFSET(K265,$B$6-1,0))*$B$9/(4*LN(2))) -> #DIV/0! | N265: =SQRT(AVERAGE(K265:OFFSET(K265,$B$7-1,0))*$B$9/(4*LN(2))) -> #DIV/0! | O265: =SQRT(AVERAGE(K265:OFFSET(K265,$B$8-1,0))*$B$9/(4*LN(2))) -> #DIV/0! | Q265: =0.511*(LN(G265/H265))^2-0.019*(LN(I265/F265)*LN(G265*H265/F265^2)-2*LN(G265/F265)*LN(H265/F265))-0.383*(LN(I265/F265))^2 -> #DIV/0! | R265: =SQRT($B$9*AVERAGE((Q265:OFFSET(Q265,$B$5-1,0)))) -> #DIV/0! | S265: =SQRT($B$9*AVERAGE((Q265:OFFSET(Q265,$B$6-1,0)))) -> #DIV/0! | T265: =SQRT($B$9*AVERAGE((Q265:OFFSET(Q265,$B$7-1,0)))) -> #DIV/0! | U265: =SQRT($B$9*AVERAGE((Q265:OFFSET(Q265,$B$8-1,0)))) -> #DIV/0! | W265: =LN(G265/I265)*LN(G265/F265)+LN(H265/I265)*LN(H265/F265) -> #DIV/0! | X265: =SQRT($B$9*AVERAGE(W265:OFFSET(W265,$B$5-1,0))) -> #DIV/0! | Y265: =SQRT($B$9*AVERAGE(W265:OFFSET(W265,$B$6-1,0))) -> #DIV/0! | Z265: =SQRT($B$9*AVERAGE(W265:OFFSET(W265,$B$7-1,0))) -> #DIV/0! | AA265: =SQRT($B$9*AVERAGE(W265:OFFSET(W265,$B$8-1,0))) -> #DIV/0! | AC265: =(LN(I265/I266))^2 -> #DIV/0! | AD265: =SQRT($B$9*SUM(AC265:OFFSET(AC265,$B$5-1,0))/($B$5-1)) -> #DIV/0! | AE265: =SQRT($B$9*SUM(AC265:OFFSET(AC265,$B$6-1,0))/($B$6-1)) -> #DIV/0! | AF265: =SQRT($B$9*SUM(AC265:OFFSET(AC265,$B$7-1,0))/($B$7-1)) -> #DIV/0! | AG265: =SQRT($B$9*SUM(AC265:OFFSET(AC265,$B$8-1,0))/($B$8-1)) -> #DIV/0! | AI265: =LN(I265/I266) -> #DIV/0! | AJ265: =SQRT($B$9)*_xlfn.STDEV.S(AI265:OFFSET(AI265,$B$5-1,0)) -> #DIV/0! | AK265: =SQRT($B$9)*_xlfn.STDEV.S(AI265:OFFSET(AI265,$B$6-1,0)) -> #DIV/0! | AL265: =SQRT($B$9)*_xlfn.STDEV.S(AI265:OFFSET(AI265,$B$7-1,0)) -> #DIV/0! | AM265: =SQRT($B$9)*_xlfn.STDEV.S(AI265:OFFSET(AI265,$B$8-1,0)) -> #DIV/0!
... E994: 43985 | K994: =(LN(G994/H994))^2 -> #DIV/0! | L994: =SQRT(AVERAGE(K994:OFFSET(K994,$B$5-1,0))*$B$9/(4*LN(2))) -> #DIV/0! | M994: =SQRT(AVERAGE(K994:OFFSET(K994,$B$6-1,0))*$B$9/(4*LN(2))) -> #DIV/0! | N994: =SQRT(AVERAGE(K994:OFFSET(K994,$B$7-1,0))*$B$9/(4*LN(2))) -> #DIV/0! | O994: =SQRT(AVERAGE(K994:OFFSET(K994,$B$8-1,0))*$B$9/(4*LN(2))) -> #DIV/0! | Q994: =0.511*(LN(G994/H994))^2-0.019*(LN(I994/F994)*LN(G994*H994/F994^2)-2*LN(G994/F994)*LN(H994/F994))-0.383*(LN(I994/F994))^2 -> #DIV/0! | R994: =SQRT($B$9*AVERAGE((Q994:OFFSET(Q994,$B$5-1,0)))) -> #DIV/0! | S994: =SQRT($B$9*AVERAGE((Q994:OFFSET(Q994,$B$6-1,0)))) -> #DIV/0! | T994: =SQRT($B$9*AVERAGE((Q994:OFFSET(Q994,$B$7-1,0)))) -> #DIV/0! | U994: =SQRT($B$9*AVERAGE((Q994:OFFSET(Q994,$B$8-1,0)))) -> #DIV/0! | W994: =LN(G994/I994)*LN(G994/F994)+LN(H994/I994)*LN(H994/F994) -> #DIV/0! | X994: =SQRT($B$9*AVERAGE(W994:OFFSET(W994,$B$5-1,0))) -> #DIV/0! | Y994: =SQRT($B$9*AVERAGE(W994:OFFSET(W994,$B$6-1,0))) -> #DIV/0! | Z994: =SQRT($B$9*AVERAGE(W994:OFFSET(W994,$B$7-1,0))) -> #DIV/0! | AA994: =SQRT($B$9*AVERAGE(W994:OFFSET(W994,$B$8-1,0))) -> #DIV/0! | AC994: =(LN(I994/I995))^2 -> #DIV/0! | AD994: =SQRT($B$9*SUM(AC994:OFFSET(AC994,$B$5-1,0))/($B$5-1)) -> #DIV/0! | AE994: =SQRT($B$9*SUM(AC994:OFFSET(AC994,$B$6-1,0))/($B$6-1)) -> #DIV/0! | AF994: =SQRT($B$9*SUM(AC994:OFFSET(AC994,$B$7-1,0))/($B$7-1)) -> #DIV/0! | AG994: =SQRT($B$9*SUM(AC994:OFFSET(AC994,$B$8-1,0))/($B$8-1)) -> #DIV/0! | AI994: =LN(I994/I995) -> #DIV/0! | AJ994: =SQRT($B$9)*_xlfn.STDEV.S(AI994:OFFSET(AI994,$B$5-1,0)) -> #DIV/0! | AK994: =SQRT($B$9)*_xlfn.STDEV.S(AI994:OFFSET(AI994,$B$6-1,0)) -> #DIV/0! | AL994: =SQRT($B$9)*_xlfn.STDEV.S(AI994:OFFSET(AI994,$B$7-1,0)) -> #DIV/0! | AM994: =SQRT($B$9)*_xlfn.STDEV.S(AI994:OFFSET(AI994,$B$8-1,0)) -> #DIV/0!
K995: =(LN(G995/H995))^2 -> #DIV/0! | L995: =SQRT(AVERAGE(K995:OFFSET(K995,$B$5-1,0))*$B$9/(4*LN(2))) -> #DIV/0! | M995: =SQRT(AVERAGE(K995:OFFSET(K995,$B$6-1,0))*$B$9/(4*LN(2))) -> #DIV/0! | N995: =SQRT(AVERAGE(K995:OFFSET(K995,$B$7-1,0))*$B$9/(4*LN(2))) -> #DIV/0! | O995: =SQRT(AVERAGE(K995:OFFSET(K995,$B$8-1,0))*$B$9/(4*LN(2))) -> #DIV/0! | Q995: =0.511*(LN(G995/H995))^2-0.019*(LN(I995/F995)*LN(G995*H995/F995^2)-2*LN(G995/F995)*LN(H995/F995))-0.383*(LN(I995/F995))^2 -> #DIV/0! | R995: =SQRT($B$9*AVERAGE((Q995:OFFSET(Q995,$B$5-1,0)))) -> #DIV/0! | S995: =SQRT($B$9*AVERAGE((Q995:OFFSET(Q995,$B$6-1,0)))) -> #DIV/0! | T995: =SQRT($B$9*AVERAGE((Q995:OFFSET(Q995,$B$7-1,0)))) -> #DIV/0! | U995: =SQRT($B$9*AVERAGE((Q995:OFFSET(Q995,$B$8-1,0)))) -> #DIV/0! | W995: =LN(G995/I995)*LN(G995/F995)+LN(H995/I995)*LN(H995/F995) -> #DIV/0! | X995: =SQRT($B$9*AVERAGE(W995:OFFSET(W995,$B$5-1,0))) -> #DIV/0! | Y995: =SQRT($B$9*AVERAGE(W995:OFFSET(W995,$B$6-1,0))) -> #DIV/0! | Z995: =SQRT($B$9*AVERAGE(W995:OFFSET(W995,$B$7-1,0))) -> #DIV/0! | AA995: =SQRT($B$9*AVERAGE(W995:OFFSET(W995,$B$8-1,0))) -> #DIV/0! | AC995: =(LN(I995/I996))^2 -> #DIV/0! | AD995: =SQRT($B$9*SUM(AC995:OFFSET(AC995,$B$5-1,0))/($B$5-1)) -> #DIV/0! | AE995: =SQRT($B$9*SUM(AC995:OFFSET(AC995,$B$6-1,0))/($B$6-1)) -> #DIV/0! | AF995: =SQRT($B$9*SUM(AC995:OFFSET(AC995,$B$7-1,0))/($B$7-1)) -> #DIV/0! | AG995: =SQRT($B$9*SUM(AC995:OFFSET(AC995,$B$8-1,0))/($B$8-1)) -> #DIV/0! | AI995: =LN(I995/I996) -> #DIV/0! | AJ995: =SQRT($B$9)*_xlfn.STDEV.S(AI995:OFFSET(AI995,$B$5-1,0)) -> #DIV/0! | AK995: =SQRT($B$9)*_xlfn.STDEV.S(AI995:OFFSET(AI995,$B$6-1,0)) -> #DIV/0! | AL995: =SQRT($B$9)*_xlfn.STDEV.S(AI995:OFFSET(AI995,$B$7-1,0)) -> #DIV/0! | AM995: =SQRT($B$9)*_xlfn.STDEV.S(AI995:OFFSET(AI995,$B$8-1,0)) -> #DIV/0!
