Workbook

Sheet 基本资料
M1: 可比公司 V1.2 | U1: 最近更新： | V1: =TODAY() -> 45635
C4: 基础信息 | M4: 证券基本资料
C6: 时间 | D6: 日期 | E6: 月份 | F6: 季度 | G6: 年份 | H6: 年初 | I6: 年底 | M6: Wind代码 | N6: 证券简称 | O6: 上市日期 | P6: 上市地点 | Q6: 上市板 | R6: ISIN代码 | S6: 省份 | T6: 城市 | U6: 所属Wind行业 | V6: 行情速览 | Y6: 总市值 | AA6: EPS | AB6: P/E(TTM) | AC6: P/B(MRQ) | AD6: EV/EBITDA | AE6: ROA | AF6: ROE | AG6: 股本股东指标 | AP6: ESG评级
C7: 今日 | D7: =TODAY() -> 45635 | E7: =MONTH(D7) -> 12 | F7: =LEN(2^E7) -> 4 | G7: =YEAR(D7) -> 2024 | H7: =DATE(YEAR(D7),1,1) -> 45292 | I7: =DATE(YEAR(D7),12,31) -> 45657 | V7: 最近交易日 | W7: 最新收盘价 | X7: 最新涨跌幅(%) | Y7: 企业市值(亿元) | Z7: 证券总市值(亿元) | AG7: 总股本(亿股) | AH7: 已发行普通股 | AI7: A股合计 | AJ7: B股 | AK7: 香港股 | AL7: 海外股 | AM7: 股东名称(第1名) | AN7: 股东持股数量(第1名)(万股) | AO7: 股东持股比例(第1名)(%) | AP7: Wind ESG评级 | AQ7: Wind ESG综合得分
C8: 1年前 | D8: =DATE(YEAR(D7)-1,MONTH(D7),DAY(D7)) -> 45269 | E8: =MONTH(D8) -> 12 | F8: =LEN(2^E8) -> 4 | G8: =YEAR(D8) -> 2023 | H8: =DATE(YEAR(D8),1,1) -> 44927 | I8: =DATE(YEAR(D8),12,31) -> 45291 | M8: 000001.SZ | N8: =IF(M8="","",[1]!hks_info_name(M8)) -> 平安银行 | O8: =IF(M8="","",[1]!s_ipo_listeddate(M8)) -> 1991-04-03 | P8: =IF(M8="","",[1]!s_info_exchmarket(M8)) -> 深圳 | Q8: =IF(M8="","",[1]!s_info_mkt(M8)) -> 主板 | R8: =IF(M8="","",[1]!hks_info_isincode(M8)) -> CNE000000040 | S8: =IF(M8="","",[1]!s_info_province(M8)) -> 广东省 | T8: =IF(M8="","",[1]!s_info_city(M8)) -> 深圳市 | U8: =IF(M8="","",[1]!s_info_industry_gics(M8,9)) -> 金融--银行--商业银行--多元化银行 | V8: =IF(M8="","",[1]!lastradeday_s(M8,$D$7)) -> 2024-12-09 | W8: =IF(M8="","",[1]!s_dq_close(M8,V8,3)) -> 11.67 | X8: =IF(M8="","",[1]!s_dq_pctchange(M8,V8)) -> 0.085763293 | Y8: =IF(M8="","",[1]!hks_val_ev(M8,V8,"",100000000)) -> 2264.6707 | Z8: =IF(M8="","",[1]!hks_val_mv_ard(M8,V8,"",100000000)) -> 2264.6707 | AA8: =IF(M8="","",[1]!hks_fa_eps_basic(M8,[1]!s_fa_latelyrd_bt(M8,V8),"")) -> 1.94 | AB8: =IF(M8="","",[1]!hks_val_pe_ttm(M8,V8)) -> 4.8651328 | AC8: =IF(M8="","",[1]!pb_mrq(M8,V8)) -> 0.53853413 | AD8: =IF(M8="","",[1]!s_val_evtoebitda2(M8,V8)) -> 0 | AE8: =IF(M8="","",[1]!hks_fa_roa2(M8,[1]!s_fa_latelyrd_bt(M8,V8))) -> 0 | AF8: =IF(M8="","",[1]!hks_fa_roe(M8,[1]!s_fa_latelyrd_bt(M8,V8))) -> 8.2528 | AG8: =IF(M8="","",[1]!s_share_total(M8,V8,100000000)) -> 194.05918 | AH8: =IF(M8="","",[1]!hks_share_total(M8,V8,100000000)) -> 194.05918 | AI8: =IF(M8="","",[1]!hks_share_totala(M8,V8,100000000)) -> 194.05918 | AJ8: =IF(M8="","",[1]!hks_share_totalb(M8,V8,100000000)) -> 0 | AK8: =IF(M8="","",[1]!hks_share_h(M8,V8,100000000)) -> 0 | AL8: =IF(M8="","",[1]!hks_share_oversea(M8,V8,100000000)) -> 0 | AM8: =IF(M8="","",[1]!hks_holder_name(M8,V8,1)) -> 中国平安保险(集团)股份有限公司-集团本级-自有资金 | AN8: =IF(M8="","",[1]!hks_holder_quantity(M8,V8,1,10000)) -> 961854.02 | AO8: =IF(M8="","",[1]!hks_holder_pct(M8,V8,1)) -> 49.560001 | AP8: =IF(M8="","",[1]!s_esg_rating_wind(M8,V8)) -> A | AQ8: =IF(M8="","",[1]!s_esg_score_wind(M8,V8)) -> 7.19
C9: 2年前 | D9: =DATE(YEAR(D8)-1,MONTH(D8),DAY(D8)) -> 44904 | E9: =MONTH(D9) -> 12 | F9: =LEN(2^E9) -> 4 | G9: =YEAR(D9) -> 2022 | H9: =DATE(YEAR(D9),1,1) -> 44562 | I9: =DATE(YEAR(D9),12,31) -> 44926 | M9: 000002.SZ | N9: =IF(M9="","",[1]!hks_info_name(M9)) -> 万科A | O9: =IF(M9="","",[1]!s_ipo_listeddate(M9)) -> 1991-01-29 | P9: =IF(M9="","",[1]!s_info_exchmarket(M9)) -> 深圳 | Q9: =IF(M9="","",[1]!s_info_mkt(M9)) -> 主板 | R9: =IF(M9="","",[1]!hks_info_isincode(M9)) -> CNE0000000T2 | S9: =IF(M9="","",[1]!s_info_province(M9)) -> 广东省 | T9: =IF(M9="","",[1]!s_info_city(M9)) -> 深圳市 | U9: =IF(M9="","",[1]!s_info_industry_gics(M9,9)) -> 房地产--房地产Ⅱ--房地产管理和开发--房地产开发 | V9: =IF(M9="","",[1]!lastradeday_s(M9,$D$7)) -> 2024-12-09 | W9: =IF(M9="","",[1]!s_dq_close(M9,V9,3)) -> 8.42 | X9: =IF(M9="","",[1]!s_dq_pctchange(M9,V9)) -> -2.9953917 | Y9: =IF(M9="","",[1]!hks_val_ev(M9,V9,"",100000000)) -> 950.57466 | Z9: =IF(M9="","",[1]!hks_val_mv_ard(M9,V9,"",100000000)) -> 1004.5657 | AA9: =IF(M9="","",[1]!hks_fa_eps_basic(M9,[1]!s_fa_latelyrd_bt(M9,V9),"")) -> -1.5132 | AB9: =IF(M9="","",[1]!hks_val_pe_ttm(M9,V9)) -> -5.1776156 | AC9: =IF(M9="","",[1]!pb_mrq(M9,V9)) -> 0.42908166 | AD9: =IF(M9="","",[1]!s_val_evtoebitda2(M9,V9)) -> 9.3365582 | AE9: =IF(M9="","",[1]!hks_fa_roa2(M9,[1]!s_fa_latelyrd_bt(M9,V9))) -> -0.5053 | AF9: =IF(M9="","",[1]!hks_fa_roe(M9,[1]!s_fa_latelyrd_bt(M9,V9))) -> -7.4008 | AG9: =IF(M9="","",[1]!s_share_total(M9,V9,100000000)) -> 119.30709 | AH9: =IF(M9="","",[1]!hks_share_total(M9,V9,100000000)) -> 119.30709 | AI9: =IF(M9="","",[1]!hks_share_totala(M9,V9,100000000)) -> 97.241965 | AJ9: =IF(M9="","",[1]!hks_share_totalb(M9,V9,100000000)) -> 0 | AK9: =IF(M9="","",[1]!hks_share_h(M9,V9,100000000)) -> 22.065129 | AL9: =IF(M9="","",[1]!hks_share_oversea(M9,V9,100000000)) -> 0 | AM9: =IF(M9="","",[1]!hks_holder_name(M9,V9,1)) -> 深圳市地铁集团有限公司 | AN9: =IF(M9="","",[1]!hks_holder_quantity(M9,V9,1,10000)) -> 324281.08 | AO9: =IF(M9="","",[1]!hks_holder_pct(M9,V9,1)) -> 27.18 | AP9: =IF(M9="","",[1]!s_esg_rating_wind(M9,V9)) -> AA | AQ9: =IF(M9="","",[1]!s_esg_score_wind(M9,V9)) -> 8.99
C10: 1年后 | D10: =DATE(YEAR(D7)+1,MONTH(D7),DAY(D7)) -> 46000 | E10: =MONTH(D10) -> 12 | F10: =LEN(2^E10) -> 4 | G10: =YEAR(D10) -> 2025 | H10: =DATE(YEAR(D10),1,1) -> 45658 | I10: =DATE(YEAR(D10),12,31) -> 46022 | M10: 002123.SZ | N10: =IF(M10="","",[1]!hks_info_name(M10)) -> 梦网科技 | O10: =IF(M10="","",[1]!s_ipo_listeddate(M10)) -> 2007-03-28 | P10: =IF(M10="","",[1]!s_info_exchmarket(M10)) -> 深圳 | Q10: =IF(M10="","",[1]!s_info_mkt(M10)) -> 主板 | R10: =IF(M10="","",[1]!hks_info_isincode(M10)) -> CNE100000049 | S10: =IF(M10="","",[1]!s_info_province(M10)) -> 辽宁省 | T10: =IF(M10="","",[1]!s_info_city(M10)) -> 鞍山市 | U10: =IF(M10="","",[1]!s_info_industry_gics(M10,9)) -> 信息技术--技术硬件与设备--通信设备Ⅲ--通信设备 | V10: =IF(M10="","",[1]!lastradeday_s(M10,$D$7)) -> 2024-12-09 | W10: =IF(M10="","",[1]!s_dq_close(M10,V10,3)) -> 10.81 | X10: =IF(M10="","",[1]!s_dq_pctchange(M10,V10)) -> -1.1882998 | Y10: =IF(M10="","",[1]!hks_val_ev(M10,V10,"",100000000)) -> 86.523391 | Z10: =IF(M10="","",[1]!hks_val_mv_ard(M10,V10,"",100000000)) -> 86.523391 | AA10: =IF(M10="","",[1]!hks_fa_eps_basic(M10,[1]!s_fa_latelyrd_bt(M10,V10),"")) -> 0.04 | AB10: =IF(M10="","",[1]!hks_val_pe_ttm(M10,V10)) -> -4.8143735 | AC10: =IF(M10="","",[1]!pb_mrq(M10,V10)) -> 5.2245281 | AD10: =IF(M10="","",[1]!s_val_evtoebitda2(M10,V10)) -> -119.6056 | AE10: =IF(M10="","",[1]!hks_fa_roa2(M10,[1]!s_fa_latelyrd_bt(M10,V10))) -> 0.9579 | AF10: =IF(M10="","",[1]!hks_fa_roe(M10,[1]!s_fa_latelyrd_bt(M10,V10))) -> 1.8552 | AG10: =IF(M10="","",[1]!s_share_total(M10,V10,100000000)) -> 8.004014 | AH10: =IF(M10="","",[1]!hks_share_total(M10,V10,100000000)) -> 8.004014 | AI10: =IF(M10="","",[1]!hks_share_totala(M10,V10,100000000)) -> 8.004014 | AJ10: =IF(M10="","",[1]!hks_share_totalb(M10,V10,100000000)) -> 0 | AK10: =IF(M10="","",[1]!hks_share_h(M10,V10,100000000)) -> 0 | AL10: =IF(M10="","",[1]!hks_share_oversea(M10,V10,100000000)) -> 0 | AM10: =IF(M10="","",[1]!hks_holder_name(M10,V10,1)) -> 余文胜 | AN10: =IF(M10="","",[1]!hks_holder_quantity(M10,V10,1,10000)) -> 11318.737 | AO10: =IF(M10="","",[1]!hks_holder_pct(M10,V10,1)) -> 14.14 | AP10: =IF(M10="","",[1]!s_esg_rating_wind(M10,V10)) -> B | AQ10: =IF(M10="","",[1]!s_esg_score_wind(M10,V10)) -> 4.76
C11: 2年后 | D11: =DATE(YEAR(D10)+1,MONTH(D8),DAY(D8)) -> 46365 | E11: =MONTH(D11) -> 12 | F11: =LEN(2^E11) -> 4 | G11: =YEAR(D11) -> 2026 | H11: =DATE(YEAR(D11),1,1) -> 46023 | I11: =DATE(YEAR(D11),12,31) -> 46387 | M11: 002230.SZ | N11: =IF(M11="","",[1]!hks_info_name(M11)) -> 科大讯飞 | O11: =IF(M11="","",[1]!s_ipo_listeddate(M11)) -> 2008-05-12 | P11: =IF(M11="","",[1]!s_info_exchmarket(M11)) -> 深圳 | Q11: =IF(M11="","",[1]!s_info_mkt(M11)) -> 主板 | R11: =IF(M11="","",[1]!hks_info_isincode(M11)) -> CNE100000B81 | S11: =IF(M11="","",[1]!s_info_province(M11)) -> 安徽省 | T11: =IF(M11="","",[1]!s_info_city(M11)) -> 合肥市 | U11: =IF(M11="","",[1]!s_info_industry_gics(M11,9)) -> 信息技术--软件与服务--软件--应用软件 | V11: =IF(M11="","",[1]!lastradeday_s(M11,$D$7)) -> 2024-12-09 | W11: =IF(M11="","",[1]!s_dq_close(M11,V11,3)) -> 52.68 | X11: =IF(M11="","",[1]!s_dq_pctchange(M11,V11)) -> 1.6595909 | Y11: =IF(M11="","",[1]!hks_val_ev(M11,V11,"",100000000)) -> 1217.8216 | Z11: =IF(M11="","",[1]!hks_val_mv_ard(M11,V11,"",100000000)) -> 1217.8216 | AA11: =IF(M11="","",[1]!hks_fa_eps_basic(M11,[1]!s_fa_latelyrd_bt(M11,V11),"")) -> -0.1489 | AB11: =IF(M11="","",[1]!hks_val_pe_ttm(M11,V11)) -> 568.42059 | AC11: =IF(M11="","",[1]!pb_mrq(M11,V11)) -> 7.3859272 | AD11: =IF(M11="","",[1]!s_val_evtoebitda2(M11,V11)) -> 59.525166 | AE11: =IF(M11="","",[1]!hks_fa_roa2(M11,[1]!s_fa_latelyrd_bt(M11,V11))) -> -1.3872 | AF11: =IF(M11="","",[1]!hks_fa_roe(M11,[1]!s_fa_latelyrd_bt(M11,V11))) -> -2.0507 | AG11: =IF(M11="","",[1]!s_share_total(M11,V11,100000000)) -> 23.117342 | AH11: =IF(M11="","",[1]!hks_share_total(M11,V11,100000000)) -> 23.117342 | AI11: =IF(M11="","",[1]!hks_share_totala(M11,V11,100000000)) -> 23.117342 | AJ11: =IF(M11="","",[1]!hks_share_totalb(M11,V11,100000000)) -> 0 | AK11: =IF(M11="","",[1]!hks_share_h(M11,V11,100000000)) -> 0 | AL11: =IF(M11="","",[1]!hks_share_oversea(M11,V11,100000000)) -> 0 | AM11: =IF(M11="","",[1]!hks_holder_name(M11,V11,1)) -> 中国移动通信有限公司 | AN11: =IF(M11="","",[1]!hks_holder_quantity(M11,V11,1,10000)) -> 23180.05 | AO11: =IF(M11="","",[1]!hks_holder_pct(M11,V11,1)) -> 10.03 | AP11: =IF(M11="","",[1]!s_esg_rating_wind(M11,V11)) -> AAA | AQ11: =IF(M11="","",[1]!s_esg_score_wind(M11,V11)) -> 9.07
M12: 600004.SH | N12: =IF(M12="","",[1]!hks_info_name(M12)) -> 白云机场 | O12: =IF(M12="","",[1]!s_ipo_listeddate(M12)) -> 2003-04-28 | P12: =IF(M12="","",[1]!s_info_exchmarket(M12)) -> 上海 | Q12: =IF(M12="","",[1]!s_info_mkt(M12)) -> 主板 | R12: =IF(M12="","",[1]!hks_info_isincode(M12)) -> CNE000001DX0 | S12: =IF(M12="","",[1]!s_info_province(M12)) -> 广东省 | T12: =IF(M12="","",[1]!s_info_city(M12)) -> 广州市 | U12: =IF(M12="","",[1]!s_info_industry_gics(M12,9)) -> 工业--运输--交通基础设施--机场服务 | V12: =IF(M12="","",[1]!lastradeday_s(M12,$D$7)) -> 2024-12-09 | W12: =IF(M12="","",[1]!s_dq_close(M12,V12,3)) -> 9.85 | X12: =IF(M12="","",[1]!s_dq_pctchange(M12,V12)) -> -0.10141988 | Y12: =IF(M12="","",[1]!hks_val_ev(M12,V12,"",100000000)) -> 233.12175 | Z12: =IF(M12="","",[1]!hks_val_mv_ard(M12,V12,"",100000000)) -> 233.12175 | AA12: =IF(M12="","",[1]!hks_fa_eps_basic(M12,[1]!s_fa_latelyrd_bt(M12,V12),"")) -> 0.28 | AB12: =IF(M12="","",[1]!hks_val_pe_ttm(M12,V12)) -> 27.892939 | AC12: =IF(M12="","",[1]!pb_mrq(M12,V12)) -> 1.289262 | AD12: =IF(M12="","",[1]!s_val_evtoebitda2(M12,V12)) -> 8.8978944 | AE12: =IF(M12="","",[1]!hks_fa_roa2(M12,[1]!s_fa_latelyrd_bt(M12,V12))) -> 3.5914 | AF12: =IF(M12="","",[1]!hks_fa_roe(M12,[1]!s_fa_latelyrd_bt(M12,V12))) -> 3.7446 | AG12: =IF(M12="","",[1]!s_share_total(M12,V12,100000000)) -> 23.667183 | AH12: =IF(M12="","",[1]!hks_share_total(M12,V12,100000000)) -> 23.667183 | AI12: =IF(M12="","",[1]!hks_share_totala(M12,V12,100000000)) -> 23.667183 | AJ12: =IF(M12="","",[1]!hks_share_totalb(M12,V12,100000000)) -> 0 | AK12: =IF(M12="","",[1]!hks_share_h(M12,V12,100000000)) -> 0 | AL12: =IF(M12="","",[1]!hks_share_oversea(M12,V12,100000000)) -> 0 | AM12: =IF(M12="","",[1]!hks_holder_name(M12,V12,1)) -> 广东省机场管理集团有限公司 | AN12: =IF(M12="","",[1]!hks_holder_quantity(M12,V12,1,10000)) -> 135374.46 | AO12: =IF(M12="","",[1]!hks_holder_pct(M12,V12,1)) -> 57.200001 | AP12: =IF(M12="","",[1]!s_esg_rating_wind(M12,V12)) -> BBB | AQ12: =IF(M12="","",[1]!s_esg_score_wind(M12,V12)) -> 6.59
C13: *注：此excel中所有财务相关数据均采用了GSD标准 | M13: 600006.SH | N13: =IF(M13="","",[1]!hks_info_name(M13)) -> 东风股份 | O13: =IF(M13="","",[1]!s_ipo_listeddate(M13)) -> 1999-07-27 | P13: =IF(M13="","",[1]!s_info_exchmarket(M13)) -> 上海 | Q13: =IF(M13="","",[1]!s_info_mkt(M13)) -> 主板 | R13: =IF(M13="","",[1]!hks_info_isincode(M13)) -> CNE000000ZT3 | S13: =IF(M13="","",[1]!s_info_province(M13)) -> 湖北省 | T13: =IF(M13="","",[1]!s_info_city(M13)) -> 襄阳市 | U13: =IF(M13="","",[1]!s_info_industry_gics(M13,9)) -> 可选消费--汽车与汽车零部件--汽车--汽车制造 | V13: =IF(M13="","",[1]!lastradeday_s(M13,$D$7)) -> 2024-12-09 | W13: =IF(M13="","",[1]!s_dq_close(M13,V13,3)) -> 7.86 | X13: =IF(M13="","",[1]!s_dq_pctchange(M13,V13)) -> 4.3824701 | Y13: =IF(M13="","",[1]!hks_val_ev(M13,V13,"",100000000)) -> 157.2 | Z13: =IF(M13="","",[1]!hks_val_mv_ard(M13,V13,"",100000000)) -> 157.2 | AA13: =IF(M13="","",[1]!hks_fa_eps_basic(M13,[1]!s_fa_latelyrd_bt(M13,V13),"")) -> -0.0573 | AB13: =IF(M13="","",[1]!hks_val_pe_ttm(M13,V13)) -> 326.86746 | AC13: =IF(M13="","",[1]!pb_mrq(M13,V13)) -> 1.9324399 | AD13: =IF(M13="","",[1]!s_val_evtoebitda2(M13,V13)) -> -68.989772 | AE13: =IF(M13="","",[1]!hks_fa_roa2(M13,[1]!s_fa_latelyrd_bt(M13,V13))) -> -0.5868 | AF13: =IF(M13="","",[1]!hks_fa_roe(M13,[1]!s_fa_latelyrd_bt(M13,V13))) -> -1.3943 | AG13: =IF(M13="","",[1]!s_share_total(M13,V13,100000000)) -> 20 | AH13: =IF(M13="","",[1]!hks_share_total(M13,V13,100000000)) -> 20 | AI13: =IF(M13="","",[1]!hks_share_totala(M13,V13,100000000)) -> 20 | AJ13: =IF(M13="","",[1]!hks_share_totalb(M13,V13,100000000)) -> 0 | AK13: =IF(M13="","",[1]!hks_share_h(M13,V13,100000000)) -> 0 | AL13: =IF(M13="","",[1]!hks_share_oversea(M13,V13,100000000)) -> 0 | AM13: =IF(M13="","",[1]!hks_holder_name(M13,V13,1)) -> 东风汽车集团股份有限公司 | AN13: =IF(M13="","",[1]!hks_holder_quantity(M13,V13,1,10000)) -> 110000 | AO13: =IF(M13="","",[1]!hks_holder_pct(M13,V13,1)) -> 55 | AP13: =IF(M13="","",[1]!s_esg_rating_wind(M13,V13)) -> BBB | AQ13: =IF(M13="","",[1]!s_esg_score_wind(M13,V13)) -> 6.24
M14: 600007.SH | N14: =IF(M14="","",[1]!hks_info_name(M14)) -> 中国国贸 | O14: =IF(M14="","",[1]!s_ipo_listeddate(M14)) -> 1999-03-12 | P14: =IF(M14="","",[1]!s_info_exchmarket(M14)) -> 上海 | Q14: =IF(M14="","",[1]!s_info_mkt(M14)) -> 主板 | R14: =IF(M14="","",[1]!hks_info_isincode(M14)) -> CNE000000YH1 | S14: =IF(M14="","",[1]!s_info_province(M14)) -> 北京 | T14: =IF(M14="","",[1]!s_info_city(M14)) -> 北京市 | U14: =IF(M14="","",[1]!s_info_industry_gics(M14,9)) -> 房地产--房地产Ⅱ--房地产管理和开发--房地产经营公司 | V14: =IF(M14="","",[1]!lastradeday_s(M14,$D$7)) -> 2024-12-09 | W14: =IF(M14="","",[1]!s_dq_close(M14,V14,3)) -> 22.8 | X14: =IF(M14="","",[1]!s_dq_pctchange(M14,V14)) -> 0.043878894 | Y14: =IF(M14="","",[1]!hks_val_ev(M14,V14,"",100000000)) -> 229.66042 | Z14: =IF(M14="","",[1]!hks_val_mv_ard(M14,V14,"",100000000)) -> 229.66042 | AA14: =IF(M14="","",[1]!hks_fa_eps_basic(M14,[1]!s_fa_latelyrd_bt(M14,V14),"")) -> 1.01 | AB14: =IF(M14="","",[1]!hks_val_pe_ttm(M14,V14)) -> 18.005089 | AC14: =IF(M14="","",[1]!pb_mrq(M14,V14)) -> 2.4407808 | AD14: =IF(M14="","",[1]!s_val_evtoebitda2(M14,V14)) -> 9.337436 | AE14: =IF(M14="","",[1]!hks_fa_roa2(M14,[1]!s_fa_latelyrd_bt(M14,V14))) -> 10.8692 | AF14: =IF(M14="","",[1]!hks_fa_roe(M14,[1]!s_fa_latelyrd_bt(M14,V14))) -> 10.6608 | AG14: =IF(M14="","",[1]!s_share_total(M14,V14,100000000)) -> 10.072825 | AH14: =IF(M14="","",[1]!hks_share_total(M14,V14,100000000)) -> 10.072825 | AI14: =IF(M14="","",[1]!hks_share_totala(M14,V14,100000000)) -> 10.072825 | AJ14: =IF(M14="","",[1]!hks_share_totalb(M14,V14,100000000)) -> 0 | AK14: =IF(M14="","",[1]!hks_share_h(M14,V14,100000000)) -> 0 | AL14: =IF(M14="","",[1]!hks_share_oversea(M14,V14,100000000)) -> 0 | AM14: =IF(M14="","",[1]!hks_holder_name(M14,V14,1)) -> 中国国际贸易中心有限公司 | AN14: =IF(M14="","",[1]!hks_holder_quantity(M14,V14,1,10000)) -> 81236.024 | AO14: =IF(M14="","",[1]!hks_holder_pct(M14,V14,1)) -> 80.650002 | AP14: =IF(M14="","",[1]!s_esg_rating_wind(M14,V14)) -> B | AQ14: =IF(M14="","",[1]!s_esg_score_wind(M14,V14)) -> 4.62
M15: 600941.SH | N15: =IF(M15="","",[1]!hks_info_name(M15)) -> 中国移动 | O15: =IF(M15="","",[1]!s_ipo_listeddate(M15)) -> 2022-01-05 | P15: =IF(M15="","",[1]!s_info_exchmarket(M15)) -> 上海 | Q15: =IF(M15="","",[1]!s_info_mkt(M15)) -> 主板 | R15: =IF(M15="","",[1]!hks_info_isincode(M15)) -> CNE1000055G1 | S15: =IF(M15="","",[1]!s_info_province(M15)) -> 北京 | T15: =IF(M15="","",[1]!s_info_city(M15)) -> 北京市 | U15: =IF(M15="","",[1]!s_info_industry_gics(M15,9)) -> 电信服务--电信服务Ⅱ--多元电信服务--综合电信服务 | V15: =IF(M15="","",[1]!lastradeday_s(M15,$D$7)) -> 2024-12-09 | W15: =IF(M15="","",[1]!s_dq_close(M15,V15,3)) -> 107.29 | X15: =IF(M15="","",[1]!s_dq_pctchange(M15,V15)) -> 0.065286327 | Y15: =IF(M15="","",[1]!hks_val_ev(M15,V15,"",100000000)) -> 14793.594 | Z15: =IF(M15="","",[1]!hks_val_mv_ard(M15,V15,"",100000000)) -> 23053.51 | AA15: =IF(M15="","",[1]!hks_fa_eps_basic(M15,[1]!s_fa_latelyrd_bt(M15,V15),"")) -> 5.18 | AB15: =IF(M15="","",[1]!hks_val_pe_ttm(M15,V15)) -> 16.81008 | AC15: =IF(M15="","",[1]!pb_mrq(M15,V15)) -> 1.7395738 | AD15: =IF(M15="","",[1]!s_val_evtoebitda2(M15,V15)) -> 4.0123437 | AE15: =IF(M15="","",[1]!hks_fa_roa2(M15,[1]!s_fa_latelyrd_bt(M15,V15))) -> 6.42 | AF15: =IF(M15="","",[1]!hks_fa_roe(M15,[1]!s_fa_latelyrd_bt(M15,V15))) -> 8.2065 | AG15: =IF(M15="","",[1]!s_share_total(M15,V15,100000000)) -> 214.87101 | AH15: =IF(M15="","",[1]!hks_share_total(M15,V15,100000000)) -> 214.87101 | AI15: =IF(M15="","",[1]!hks_share_totala(M15,V15,100000000)) -> 9.0276787 | AJ15: =IF(M15="","",[1]!hks_share_totalb(M15,V15,100000000)) -> 0 | AK15: =IF(M15="","",[1]!hks_share_h(M15,V15,100000000)) -> 205.84333 | AL15: =IF(M15="","",[1]!hks_share_oversea(M15,V15,100000000)) -> 0 | AM15: =IF(M15="","",[1]!hks_holder_name(M15,V15,1)) -> 中国移动香港(BVI)有限公司 | AN15: =IF(M15="","",[1]!hks_holder_quantity(M15,V15,1,10000)) -> 1489011.7 | AO15: =IF(M15="","",[1]!hks_holder_pct(M15,V15,1)) -> 69.349998 | AP15: =IF(M15="","",[1]!s_esg_rating_wind(M15,V15)) -> AA | AQ15: =IF(M15="","",[1]!s_esg_score_wind(M15,V15)) -> 8.48
M16: 603160.SH | N16: =IF(M16="","",[1]!hks_info_name(M16)) -> 汇顶科技 | O16: =IF(M16="","",[1]!s_ipo_listeddate(M16)) -> 2016-10-17 | P16: =IF(M16="","",[1]!s_info_exchmarket(M16)) -> 上海 | Q16: =IF(M16="","",[1]!s_info_mkt(M16)) -> 主板 | R16: =IF(M16="","",[1]!hks_info_isincode(M16)) -> CNE100002G84 | S16: =IF(M16="","",[1]!s_info_province(M16)) -> 广东省 | T16: =IF(M16="","",[1]!s_info_city(M16)) -> 深圳市 | U16: =IF(M16="","",[1]!s_info_industry_gics(M16,9)) -> 信息技术--半导体与半导体生产设备--半导体产品与半导体设备--半导体产品 | V16: =IF(M16="","",[1]!lastradeday_s(M16,$D$7)) -> 2024-12-09 | W16: =IF(M16="","",[1]!s_dq_close(M16,V16,3)) -> 89.98 | X16: =IF(M16="","",[1]!s_dq_pctchange(M16,V16)) -> 10 | Y16: =IF(M16="","",[1]!hks_val_ev(M16,V16,"",100000000)) -> 412.34755 | Z16: =IF(M16="","",[1]!hks_val_mv_ard(M16,V16,"",100000000)) -> 412.34755 | AA16: =IF(M16="","",[1]!hks_fa_eps_basic(M16,[1]!s_fa_latelyrd_bt(M16,V16),"")) -> 0.98 | AB16: =IF(M16="","",[1]!hks_val_pe_ttm(M16,V16)) -> 68.642334 | AC16: =IF(M16="","",[1]!pb_mrq(M16,V16)) -> 4.8911095 | AD16: =IF(M16="","",[1]!s_val_evtoebitda2(M16,V16)) -> 70.516108 | AE16: =IF(M16="","",[1]!hks_fa_roa2(M16,[1]!s_fa_latelyrd_bt(M16,V16))) -> 5.3145 | AF16: =IF(M16="","",[1]!hks_fa_roe(M16,[1]!s_fa_latelyrd_bt(M16,V16))) -> 5.4397 | AG16: =IF(M16="","",[1]!s_share_total(M16,V16,100000000)) -> 4.5826578 | AH16: =IF(M16="","",[1]!hks_share_total(M16,V16,100000000)) -> 4.5826578 | AI16: =IF(M16="","",[1]!hks_share_totala(M16,V16,100000000)) -> 4.5826578 | AJ16: =IF(M16="","",[1]!hks_share_totalb(M16,V16,100000000)) -> 0 | AK16: =IF(M16="","",[1]!hks_share_h(M16,V16,100000000)) -> 0 | AL16: =IF(M16="","",[1]!hks_share_oversea(M16,V16,100000000)) -> 0 | AM16: =IF(M16="","",[1]!hks_holder_name(M16,V16,1)) -> 张帆 | AN16: =IF(M16="","",[1]!hks_holder_quantity(M16,V16,1,10000)) -> 20629.638 | AO16: =IF(M16="","",[1]!hks_holder_pct(M16,V16,1)) -> 45.0168 | AP16: =IF(M16="","",[1]!s_esg_rating_wind(M16,V16)) -> B | AQ16: =IF(M16="","",[1]!s_esg_score_wind(M16,V16)) -> 4.64
M17: 688111.SH | N17: =IF(M17="","",[1]!hks_info_name(M17)) -> 金山办公 | O17: =IF(M17="","",[1]!s_ipo_listeddate(M17)) -> 2019-11-18 | P17: =IF(M17="","",[1]!s_info_exchmarket(M17)) -> 上海 | Q17: =IF(M17="","",[1]!s_info_mkt(M17)) -> 科创板 | R17: =IF(M17="","",[1]!hks_info_isincode(M17)) -> CNE100003PM2 | S17: =IF(M17="","",[1]!s_info_province(M17)) -> 北京 | T17: =IF(M17="","",[1]!s_info_city(M17)) -> 北京市 | U17: =IF(M17="","",[1]!s_info_industry_gics(M17,9)) -> 信息技术--软件与服务--软件--应用软件 | V17: =IF(M17="","",[1]!lastradeday_s(M17,$D$7)) -> 2024-12-09 | W17: =IF(M17="","",[1]!s_dq_close(M17,V17,3)) -> 312.6 | X17: =IF(M17="","",[1]!s_dq_pctchange(M17,V17)) -> 4.189581 | Y17: =IF(M17="","",[1]!hks_val_ev(M17,V17,"",100000000)) -> 1445.8552 | Z17: =IF(M17="","",[1]!hks_val_mv_ard(M17,V17,"",100000000)) -> 1445.8552 | AA17: =IF(M17="","",[1]!hks_fa_eps_basic(M17,[1]!s_fa_latelyrd_bt(M17,V17),"")) -> 2.25 | AB17: =IF(M17="","",[1]!hks_val_pe_ttm(M17,V17)) -> 98.737564 | AC17: =IF(M17="","",[1]!pb_mrq(M17,V17)) -> 13.507145 | AD17: =IF(M17="","",[1]!s_val_evtoebitda2(M17,V17)) -> 118.53599 | AE17: =IF(M17="","",[1]!hks_fa_roa2(M17,[1]!s_fa_latelyrd_bt(M17,V17))) -> 7.6847 | AF17: =IF(M17="","",[1]!hks_fa_roe(M17,[1]!s_fa_latelyrd_bt(M17,V17))) -> 10.0699 | AG17: =IF(M17="","",[1]!s_share_total(M17,V17,100000000)) -> 4.6252564 | AH17: =IF(M17="","",[1]!hks_share_total(M17,V17,100000000)) -> 4.6252564 | AI17: =IF(M17="","",[1]!hks_share_totala(M17,V17,100000000)) -> 4.6252564 | AJ17: =IF(M17="","",[1]!hks_share_totalb(M17,V17,100000000)) -> 0 | AK17: =IF(M17="","",[1]!hks_share_h(M17,V17,100000000)) -> 0 | AL17: =IF(M17="","",[1]!hks_share_oversea(M17,V17,100000000)) -> 0 | AM17: =IF(M17="","",[1]!hks_holder_name(M17,V17,1)) -> Kingsoft WPS Corporation Limited | AN17: =IF(M17="","",[1]!hks_holder_quantity(M17,V17,1,10000)) -> 23838.735 | AO17: =IF(M17="","",[1]!hks_holder_pct(M17,V17,1)) -> 51.540001 | AP17: =IF(M17="","",[1]!s_esg_rating_wind(M17,V17)) -> AA | AQ17: =IF(M17="","",[1]!s_esg_score_wind(M17,V17)) -> 8.4
M18: 0700.HK | N18: =IF(M18="","",[1]!hks_info_name(M18)) -> 腾讯控股 | O18: =IF(M18="","",[1]!s_ipo_listeddate(M18)) -> 2004-06-16 | P18: =IF(M18="","",[1]!s_info_exchmarket(M18)) -> 香港联交所 | Q18: =IF(M18="","",[1]!s_info_mkt(M18)) -> 主板 | R18: =IF(M18="","",[1]!hks_info_isincode(M18)) -> KYG875721634 | S18: =IF(M18="","",[1]!s_info_province(M18)) -> 广东省 | T18: =IF(M18="","",[1]!s_info_city(M18)) -> 深圳市 | U18: =IF(M18="","",[1]!s_info_industry_gics(M18,9)) -> 信息技术--软件与服务--互联网软件与服务Ⅲ--互联网软件与服务 | V18: =IF(M18="","",[1]!lastradeday_s(M18,$D$7)) -> 2024-12-06 | W18: =IF(M18="","",[1]!s_dq_close(M18,V18,3)) -> 412.6 | X18: =IF(M18="","",[1]!s_dq_pctchange(M18,V18)) -> 1.8262586 | Y18: =IF(M18="","",[1]!hks_val_ev(M18,V18,"",100000000)) -> 38237.595 | Z18: =IF(M18="","",[1]!hks_val_mv_ard(M18,V18,"",100000000)) -> 38237.595 | AA18: =IF(M18="","",[1]!hks_fa_eps_basic(M18,[1]!s_fa_latelyrd_bt(M18,V18),"")) -> 15.346 | AB18: =IF(M18="","",[1]!hks_val_pe_ttm(M18,V18)) -> 20.310696 | AC18: =IF(M18="","",[1]!pb_mrq(M18,V18)) -> 3.8682324 | AD18: =IF(M18="","",[1]!s_val_evtoebitda2(M18,V18)) -> 17.197141 | AE18: =IF(M18="","",[1]!hks_fa_roa2(M18,[1]!s_fa_latelyrd_bt(M18,V18))) -> 10.6412 | AF18: =IF(M18="","",[1]!hks_fa_roe(M18,[1]!s_fa_latelyrd_bt(M18,V18))) -> 16.5874 | AG18: =IF(M18="","",[1]!s_share_total(M18,V18,100000000)) -> 92.674734 | AH18: =IF(M18="","",[1]!hks_share_total(M18,V18,100000000)) -> 92.674734 | AI18: =IF(M18="","",[1]!hks_share_totala(M18,V18,100000000)) -> 0 | AJ18: =IF(M18="","",[1]!hks_share_totalb(M18,V18,100000000)) -> 0 | AK18: =IF(M18="","",[1]!hks_share_h(M18,V18,100000000)) -> 92.674734 | AL18: =IF(M18="","",[1]!hks_share_oversea(M18,V18,100000000)) -> 0 | AM18: =IF(M18="","",[1]!hks_holder_name(M18,V18,1)) -> MIH Internet Holdings B.V. | AN18: =IF(M18="","",[1]!hks_holder_quantity(M18,V18,1,10000)) -> 228503.13 | AO18: =IF(M18="","",[1]!hks_holder_pct(M18,V18,1)) -> 24.43 | AP18: =IF(M18="","",[1]!s_esg_rating_wind(M18,V18)) -> AA | AQ18: =IF(M18="","",[1]!s_esg_score_wind(M18,V18)) -> 8.14
M19: 9896.HK | N19: =IF(M19="","",[1]!hks_info_name(M19)) -> 名创优品 | O19: =IF(M19="","",[1]!s_ipo_listeddate(M19)) -> 2022-07-13 | P19: =IF(M19="","",[1]!s_info_exchmarket(M19)) -> 香港联交所 | Q19: =IF(M19="","",[1]!s_info_mkt(M19)) -> 主板 | R19: =IF(M19="","",[1]!hks_info_isincode(M19)) -> KYG6180F1081 | S19: =IF(M19="","",[1]!s_info_province(M19)) -> 广东省 | T19: =IF(M19="","",[1]!s_info_city(M19)) -> 广州市 | U19: =IF(M19="","",[1]!s_info_industry_gics(M19,9)) -> 可选消费--零售业--多元化零售--百货商店 | V19: =IF(M19="","",[1]!lastradeday_s(M19,$D$7)) -> 2024-12-06 | W19: =IF(M19="","",[1]!s_dq_close(M19,V19,3)) -> 47.4 | X19: =IF(M19="","",[1]!s_dq_pctchange(M19,V19)) -> 0.74388948 | Y19: =IF(M19="","",[1]!hks_val_ev(M19,V19,"",100000000)) -> 595.47674 | Z19: =IF(M19="","",[1]!hks_val_mv_ard(M19,V19,"",100000000)) -> 595.47674 | AA19: =IF(M19="","",[1]!hks_fa_eps_basic(M19,[1]!s_fa_latelyrd_bt(M19,V19),"")) -> 1.46 | AB19: =IF(M19="","",[1]!hks_val_pe_ttm(M19,V19)) -> 22.843327 | AC19: =IF(M19="","",[1]!pb_mrq(M19,V19)) -> 5.7716712 | AD19: =IF(M19="","",[1]!s_val_evtoebitda2(M19,V19)) -> 0 | AE19: =IF(M19="","",[1]!hks_fa_roa2(M19,[1]!s_fa_latelyrd_bt(M19,V19))) -> 15.6207 | AF19: =IF(M19="","",[1]!hks_fa_roe(M19,[1]!s_fa_latelyrd_bt(M19,V19))) -> 19.3854 | AG19: =IF(M19="","",[1]!s_share_total(M19,V19,100000000)) -> 12.5628 | AH19: =IF(M19="","",[1]!hks_share_total(M19,V19,100000000)) -> 12.5628 | AI19: =IF(M19="","",[1]!hks_share_totala(M19,V19,100000000)) -> 0 | AJ19: =IF(M19="","",[1]!hks_share_totalb(M19,V19,100000000)) -> 0 | AK19: =IF(M19="","",[1]!hks_share_h(M19,V19,100000000)) -> 12.5628 | AL19: =IF(M19="","",[1]!hks_share_oversea(M19,V19,100000000)) -> 0 | AM19: =IF(M19="","",[1]!hks_holder_name(M19,V19,1)) -> Mini Investment Limited | AN19: =IF(M19="","",[1]!hks_holder_quantity(M19,V19,1,10000)) -> 32829.048 | AO19: =IF(M19="","",[1]!hks_holder_pct(M19,V19,1)) -> 26.1 | AP19: =IF(M19="","",[1]!s_esg_rating_wind(M19,V19)) -> AA | AQ19: =IF(M19="","",[1]!s_esg_score_wind(M19,V19)) -> 7.97
M20: 9999.HK | N20: =IF(M20="","",[1]!hks_info_name(M20)) -> 网易-S | O20: =IF(M20="","",[1]!s_ipo_listeddate(M20)) -> 2020-06-11 | P20: =IF(M20="","",[1]!s_info_exchmarket(M20)) -> 香港联交所 | Q20: =IF(M20="","",[1]!s_info_mkt(M20)) -> 主板 | R20: =IF(M20="","",[1]!hks_info_isincode(M20)) -> KYG6427A1022 | S20: =IF(M20="","",[1]!s_info_province(M20)) -> 浙江省 | T20: =IF(M20="","",[1]!s_info_city(M20)) -> 杭州市 | U20: =IF(M20="","",[1]!s_info_industry_gics(M20,9)) -> 信息技术--软件与服务--互联网软件与服务Ⅲ--互联网软件与服务 | V20: =IF(M20="","",[1]!lastradeday_s(M20,$D$7)) -> 2024-12-09 | W20: =IF(M20="","",[1]!s_dq_close(M20,V20,3)) -> 150.9 | X20: =IF(M20="","",[1]!s_dq_pctchange(M20,V20)) -> 6.0435699 | Y20: =IF(M20="","",[1]!hks_val_ev(M20,V20,"",100000000)) -> 4845.0718 | Z20: =IF(M20="","",[1]!hks_val_mv_ard(M20,V20,"",100000000)) -> 0 | AA20: =IF(M20="","",[1]!hks_fa_eps_basic(M20,[1]!s_fa_latelyrd_bt(M20,V20),"")) -> 6.52 | AB20: =IF(M20="","",[1]!hks_val_pe_ttm(M20,V20)) -> 0 | AC20: =IF(M20="","",[1]!pb_mrq(M20,V20)) -> 0 | AD20: =IF(M20="","",[1]!s_val_evtoebitda2(M20,V20)) -> 13.972753 | AE20: =IF(M20="","",[1]!hks_fa_roa2(M20,[1]!s_fa_latelyrd_bt(M20,V20))) -> 13.7068 | AF20: =IF(M20="","",[1]!hks_fa_roe(M20,[1]!s_fa_latelyrd_bt(M20,V20))) -> 16.3246 | AG20: =IF(M20="","",[1]!s_share_total(M20,V20,100000000)) -> 32.107831 | AH20: =IF(M20="","",[1]!hks_share_total(M20,V20,100000000)) -> 32.107831 | AI20: =IF(M20="","",[1]!hks_share_totala(M20,V20,100000000)) -> 0 | AJ20: =IF(M20="","",[1]!hks_share_totalb(M20,V20,100000000)) -> 0 | AK20: =IF(M20="","",[1]!hks_share_h(M20,V20,100000000)) -> 32.107831 | AL20: =IF(M20="","",[1]!hks_share_oversea(M20,V20,100000000)) -> 0 | AM20: =IF(M20="","",[1]!hks_holder_name(M20,V20,1)) -> Shining Globe International Limited | AN20: =IF(M20="","",[1]!hks_holder_quantity(M20,V20,1,10000)) -> 145030 | AO20: =IF(M20="","",[1]!hks_holder_pct(M20,V20,1)) -> 45 | AP20: =IF(M20="","",[1]!s_esg_rating_wind(M20,V20)) -> BB | AQ20: =IF(M20="","",[1]!s_esg_score_wind(M20,V20)) -> 6.05
N21: =IF(M21="","",[1]!hks_info_name(M21)) | O21: =IF(M21="","",[1]!s_ipo_listeddate(M21)) | P21: =IF(M21="","",[1]!s_info_exchmarket(M21)) | Q21: =IF(M21="","",[1]!s_info_mkt(M21)) | R21: =IF(M21="","",[1]!hks_info_isincode(M21)) | S21: =IF(M21="","",[1]!s_info_province(M21)) | T21: =IF(M21="","",[1]!s_info_city(M21)) | U21: =IF(M21="","",[1]!s_info_industry_gics(M21,9)) | V21: =IF(M21="","",[1]!lastradeday_s(M21,$D$7)) | W21: =IF(M21="","",[1]!s_dq_close(M21,V21,3)) | X21: =IF(M21="","",[1]!s_dq_pctchange(M21,V21)) | Y21: =IF(M21="","",[1]!hks_val_ev(M21,V21,"",100000000)) | Z21: =IF(M21="","",[1]!hks_val_mv_ard(M21,V21,"",100000000)) | AA21: =IF(M21="","",[1]!hks_fa_eps_basic(M21,[1]!s_fa_latelyrd_bt(M21,V21),"")) | AB21: =IF(M21="","",[1]!hks_val_pe_ttm(M21,V21)) | AC21: =IF(M21="","",[1]!pb_mrq(M21,V21)) | AD21: =IF(M21="","",[1]!s_val_evtoebitda2(M21,V21)) | AE21: =IF(M21="","",[1]!hks_fa_roa2(M21,[1]!s_fa_latelyrd_bt(M21,V21))) | AF21: =IF(M21="","",[1]!hks_fa_roe(M21,[1]!s_fa_latelyrd_bt(M21,V21))) | AG21: =IF(M21="","",[1]!s_share_total(M21,V21,100000000)) | AH21: =IF(M21="","",[1]!hks_share_total(M21,V21,100000000)) | AI21: =IF(M21="","",[1]!hks_share_totala(M21,V21,100000000)) | AJ21: =IF(M21="","",[1]!hks_share_totalb(M21,V21,100000000)) | AK21: =IF(M21="","",[1]!hks_share_h(M21,V21,100000000)) | AL21: =IF(M21="","",[1]!hks_share_oversea(M21,V21,100000000)) | AM21: =IF(M21="","",[1]!hks_holder_name(M21,V21,1)) | AN21: =IF(M21="","",[1]!hks_holder_quantity(M21,V21,1,10000)) | AO21: =IF(M21="","",[1]!hks_holder_pct(M21,V21,1)) | AP21: =IF(M21="","",[1]!s_esg_rating_wind(M21,V21)) | AQ21: =IF(M21="","",[1]!s_esg_score_wind(M21,V21))
N22: =IF(M22="","",[1]!hks_info_name(M22)) | O22: =IF(M22="","",[1]!s_ipo_listeddate(M22)) | P22: =IF(M22="","",[1]!s_info_exchmarket(M22)) | Q22: =IF(M22="","",[1]!s_info_mkt(M22)) | R22: =IF(M22="","",[1]!hks_info_isincode(M22)) | S22: =IF(M22="","",[1]!s_info_province(M22)) | T22: =IF(M22="","",[1]!s_info_city(M22)) | U22: =IF(M22="","",[1]!s_info_industry_gics(M22,9)) | V22: =IF(M22="","",[1]!lastradeday_s(M22,$D$7)) | W22: =IF(M22="","",[1]!s_dq_close(M22,V22,3)) | X22: =IF(M22="","",[1]!s_dq_pctchange(M22,V22)) | Y22: =IF(M22="","",[1]!hks_val_ev(M22,V22,"",100000000)) | Z22: =IF(M22="","",[1]!hks_val_mv_ard(M22,V22,"",100000000)) | AA22: =IF(M22="","",[1]!hks_fa_eps_basic(M22,[1]!s_fa_latelyrd_bt(M22,V22),"")) | AB22: =IF(M22="","",[1]!hks_val_pe_ttm(M22,V22)) | AC22: =IF(M22="","",[1]!pb_mrq(M22,V22)) | AD22: =IF(M22="","",[1]!s_val_evtoebitda2(M22,V22)) | AE22: =IF(M22="","",[1]!hks_fa_roa2(M22,[1]!s_fa_latelyrd_bt(M22,V22))) | AF22: =IF(M22="","",[1]!hks_fa_roe(M22,[1]!s_fa_latelyrd_bt(M22,V22))) | AG22: =IF(M22="","",[1]!s_share_total(M22,V22,100000000)) | AH22: =IF(M22="","",[1]!hks_share_total(M22,V22,100000000)) | AI22: =IF(M22="","",[1]!hks_share_totala(M22,V22,100000000)) | AJ22: =IF(M22="","",[1]!hks_share_totalb(M22,V22,100000000)) | AK22: =IF(M22="","",[1]!hks_share_h(M22,V22,100000000)) | AL22: =IF(M22="","",[1]!hks_share_oversea(M22,V22,100000000)) | AM22: =IF(M22="","",[1]!hks_holder_name(M22,V22,1)) | AN22: =IF(M22="","",[1]!hks_holder_quantity(M22,V22,1,10000)) | AO22: =IF(M22="","",[1]!hks_holder_pct(M22,V22,1)) | AP22: =IF(M22="","",[1]!s_esg_rating_wind(M22,V22)) | AQ22: =IF(M22="","",[1]!s_esg_score_wind(M22,V22))
N23: =IF(M23="","",[1]!hks_info_name(M23)) | O23: =IF(M23="","",[1]!s_ipo_listeddate(M23)) | P23: =IF(M23="","",[1]!s_info_exchmarket(M23)) | Q23: =IF(M23="","",[1]!s_info_mkt(M23)) | R23: =IF(M23="","",[1]!hks_info_isincode(M23)) | S23: =IF(M23="","",[1]!s_info_province(M23)) | T23: =IF(M23="","",[1]!s_info_city(M23)) | U23: =IF(M23="","",[1]!s_info_industry_gics(M23,9)) | V23: =IF(M23="","",[1]!lastradeday_s(M23,$D$7)) | W23: =IF(M23="","",[1]!s_dq_close(M23,V23,3)) | X23: =IF(M23="","",[1]!s_dq_pctchange(M23,V23)) | Y23: =IF(M23="","",[1]!hks_val_ev(M23,V23,"",100000000)) | Z23: =IF(M23="","",[1]!hks_val_mv_ard(M23,V23,"",100000000)) | AA23: =IF(M23="","",[1]!hks_fa_eps_basic(M23,[1]!s_fa_latelyrd_bt(M23,V23),"")) | AB23: =IF(M23="","",[1]!hks_val_pe_ttm(M23,V23)) | AC23: =IF(M23="","",[1]!pb_mrq(M23,V23)) | AD23: =IF(M23="","",[1]!s_val_evtoebitda2(M23,V23)) | AE23: =IF(M23="","",[1]!hks_fa_roa2(M23,[1]!s_fa_latelyrd_bt(M23,V23))) | AF23: =IF(M23="","",[1]!hks_fa_roe(M23,[1]!s_fa_latelyrd_bt(M23,V23))) | AG23: =IF(M23="","",[1]!s_share_total(M23,V23,100000000)) | AH23: =IF(M23="","",[1]!hks_share_total(M23,V23,100000000)) | AI23: =IF(M23="","",[1]!hks_share_totala(M23,V23,100000000)) | AJ23: =IF(M23="","",[1]!hks_share_totalb(M23,V23,100000000)) | AK23: =IF(M23="","",[1]!hks_share_h(M23,V23,100000000)) | AL23: =IF(M23="","",[1]!hks_share_oversea(M23,V23,100000000)) | AM23: =IF(M23="","",[1]!hks_holder_name(M23,V23,1)) | AN23: =IF(M23="","",[1]!hks_holder_quantity(M23,V23,1,10000)) | AO23: =IF(M23="","",[1]!hks_holder_pct(M23,V23,1)) | AP23: =IF(M23="","",[1]!s_esg_rating_wind(M23,V23)) | AQ23: =IF(M23="","",[1]!s_esg_score_wind(M23,V23))
N24: =IF(M24="","",[1]!hks_info_name(M24)) | O24: =IF(M24="","",[1]!s_ipo_listeddate(M24)) | P24: =IF(M24="","",[1]!s_info_exchmarket(M24)) | Q24: =IF(M24="","",[1]!s_info_mkt(M24)) | R24: =IF(M24="","",[1]!hks_info_isincode(M24)) | S24: =IF(M24="","",[1]!s_info_province(M24)) | T24: =IF(M24="","",[1]!s_info_city(M24)) | U24: =IF(M24="","",[1]!s_info_industry_gics(M24,9)) | V24: =IF(M24="","",[1]!lastradeday_s(M24,$D$7)) | W24: =IF(M24="","",[1]!s_dq_close(M24,V24,3)) | X24: =IF(M24="","",[1]!s_dq_pctchange(M24,V24)) | Y24: =IF(M24="","",[1]!hks_val_ev(M24,V24,"",100000000)) | Z24: =IF(M24="","",[1]!hks_val_mv_ard(M24,V24,"",100000000)) | AA24: =IF(M24="","",[1]!hks_fa_eps_basic(M24,[1]!s_fa_latelyrd_bt(M24,V24),"")) | AB24: =IF(M24="","",[1]!hks_val_pe_ttm(M24,V24)) | AC24: =IF(M24="","",[1]!pb_mrq(M24,V24)) | AD24: =IF(M24="","",[1]!s_val_evtoebitda2(M24,V24)) | AE24: =IF(M24="","",[1]!hks_fa_roa2(M24,[1]!s_fa_latelyrd_bt(M24,V24))) | AF24: =IF(M24="","",[1]!hks_fa_roe(M24,[1]!s_fa_latelyrd_bt(M24,V24))) | AG24: =IF(M24="","",[1]!s_share_total(M24,V24,100000000)) | AH24: =IF(M24="","",[1]!hks_share_total(M24,V24,100000000)) | AI24: =IF(M24="","",[1]!hks_share_totala(M24,V24,100000000)) | AJ24: =IF(M24="","",[1]!hks_share_totalb(M24,V24,100000000)) | AK24: =IF(M24="","",[1]!hks_share_h(M24,V24,100000000)) | AL24: =IF(M24="","",[1]!hks_share_oversea(M24,V24,100000000)) | AM24: =IF(M24="","",[1]!hks_holder_name(M24,V24,1)) | AN24: =IF(M24="","",[1]!hks_holder_quantity(M24,V24,1,10000)) | AO24: =IF(M24="","",[1]!hks_holder_pct(M24,V24,1)) | AP24: =IF(M24="","",[1]!s_esg_rating_wind(M24,V24)) | AQ24: =IF(M24="","",[1]!s_esg_score_wind(M24,V24))
N25: =IF(M25="","",[1]!hks_info_name(M25)) | O25: =IF(M25="","",[1]!s_ipo_listeddate(M25)) | P25: =IF(M25="","",[1]!s_info_exchmarket(M25)) | Q25: =IF(M25="","",[1]!s_info_mkt(M25)) | R25: =IF(M25="","",[1]!hks_info_isincode(M25)) | S25: =IF(M25="","",[1]!s_info_province(M25)) | T25: =IF(M25="","",[1]!s_info_city(M25)) | U25: =IF(M25="","",[1]!s_info_industry_gics(M25,9)) | V25: =IF(M25="","",[1]!lastradeday_s(M25,$D$7)) | W25: =IF(M25="","",[1]!s_dq_close(M25,V25,3)) | X25: =IF(M25="","",[1]!s_dq_pctchange(M25,V25)) | Y25: =IF(M25="","",[1]!hks_val_ev(M25,V25,"",100000000)) | Z25: =IF(M25="","",[1]!hks_val_mv_ard(M25,V25,"",100000000)) | AA25: =IF(M25="","",[1]!hks_fa_eps_basic(M25,[1]!s_fa_latelyrd_bt(M25,V25),"")) | AB25: =IF(M25="","",[1]!hks_val_pe_ttm(M25,V25)) | AC25: =IF(M25="","",[1]!pb_mrq(M25,V25)) | AD25: =IF(M25="","",[1]!s_val_evtoebitda2(M25,V25)) | AE25: =IF(M25="","",[1]!hks_fa_roa2(M25,[1]!s_fa_latelyrd_bt(M25,V25))) | AF25: =IF(M25="","",[1]!hks_fa_roe(M25,[1]!s_fa_latelyrd_bt(M25,V25))) | AG25: =IF(M25="","",[1]!s_share_total(M25,V25,100000000)) | AH25: =IF(M25="","",[1]!hks_share_total(M25,V25,100000000)) | AI25: =IF(M25="","",[1]!hks_share_totala(M25,V25,100000000)) | AJ25: =IF(M25="","",[1]!hks_share_totalb(M25,V25,100000000)) | AK25: =IF(M25="","",[1]!hks_share_h(M25,V25,100000000)) | AL25: =IF(M25="","",[1]!hks_share_oversea(M25,V25,100000000)) | AM25: =IF(M25="","",[1]!hks_holder_name(M25,V25,1)) | AN25: =IF(M25="","",[1]!hks_holder_quantity(M25,V25,1,10000)) | AO25: =IF(M25="","",[1]!hks_holder_pct(M25,V25,1)) | AP25: =IF(M25="","",[1]!s_esg_rating_wind(M25,V25)) | AQ25: =IF(M25="","",[1]!s_esg_score_wind(M25,V25))
N26: =IF(M26="","",[1]!hks_info_name(M26)) | O26: =IF(M26="","",[1]!s_ipo_listeddate(M26)) | P26: =IF(M26="","",[1]!s_info_exchmarket(M26)) | Q26: =IF(M26="","",[1]!s_info_mkt(M26)) | R26: =IF(M26="","",[1]!hks_info_isincode(M26)) | S26: =IF(M26="","",[1]!s_info_province(M26)) | T26: =IF(M26="","",[1]!s_info_city(M26)) | U26: =IF(M26="","",[1]!s_info_industry_gics(M26,9)) | V26: =IF(M26="","",[1]!lastradeday_s(M26,$D$7)) | W26: =IF(M26="","",[1]!s_dq_close(M26,V26,3)) | X26: =IF(M26="","",[1]!s_dq_pctchange(M26,V26)) | Y26: =IF(M26="","",[1]!hks_val_ev(M26,V26,"",100000000)) | Z26: =IF(M26="","",[1]!hks_val_mv_ard(M26,V26,"",100000000)) | AA26: =IF(M26="","",[1]!hks_fa_eps_basic(M26,[1]!s_fa_latelyrd_bt(M26,V26),"")) | AB26: =IF(M26="","",[1]!hks_val_pe_ttm(M26,V26)) | AC26: =IF(M26="","",[1]!pb_mrq(M26,V26)) | AD26: =IF(M26="","",[1]!s_val_evtoebitda2(M26,V26)) | AE26: =IF(M26="","",[1]!hks_fa_roa2(M26,[1]!s_fa_latelyrd_bt(M26,V26))) | AF26: =IF(M26="","",[1]!hks_fa_roe(M26,[1]!s_fa_latelyrd_bt(M26,V26))) | AG26: =IF(M26="","",[1]!s_share_total(M26,V26,100000000)) | AH26: =IF(M26="","",[1]!hks_share_total(M26,V26,100000000)) | AI26: =IF(M26="","",[1]!hks_share_totala(M26,V26,100000000)) | AJ26: =IF(M26="","",[1]!hks_share_totalb(M26,V26,100000000)) | AK26: =IF(M26="","",[1]!hks_share_h(M26,V26,100000000)) | AL26: =IF(M26="","",[1]!hks_share_oversea(M26,V26,100000000)) | AM26: =IF(M26="","",[1]!hks_holder_name(M26,V26,1)) | AN26: =IF(M26="","",[1]!hks_holder_quantity(M26,V26,1,10000)) | AO26: =IF(M26="","",[1]!hks_holder_pct(M26,V26,1)) | AP26: =IF(M26="","",[1]!s_esg_rating_wind(M26,V26)) | AQ26: =IF(M26="","",[1]!s_esg_score_wind(M26,V26))
N27: =IF(M27="","",[1]!hks_info_name(M27)) | O27: =IF(M27="","",[1]!s_ipo_listeddate(M27)) | P27: =IF(M27="","",[1]!s_info_exchmarket(M27)) | Q27: =IF(M27="","",[1]!s_info_mkt(M27)) | R27: =IF(M27="","",[1]!hks_info_isincode(M27)) | S27: =IF(M27="","",[1]!s_info_province(M27)) | T27: =IF(M27="","",[1]!s_info_city(M27)) | U27: =IF(M27="","",[1]!s_info_industry_gics(M27,9)) | V27: =IF(M27="","",[1]!lastradeday_s(M27,$D$7)) | W27: =IF(M27="","",[1]!s_dq_close(M27,V27,3)) | X27: =IF(M27="","",[1]!s_dq_pctchange(M27,V27)) | Y27: =IF(M27="","",[1]!hks_val_ev(M27,V27,"",100000000)) | Z27: =IF(M27="","",[1]!hks_val_mv_ard(M27,V27,"",100000000)) | AA27: =IF(M27="","",[1]!hks_fa_eps_basic(M27,[1]!s_fa_latelyrd_bt(M27,V27),"")) | AB27: =IF(M27="","",[1]!hks_val_pe_ttm(M27,V27)) | AC27: =IF(M27="","",[1]!pb_mrq(M27,V27)) | AD27: =IF(M27="","",[1]!s_val_evtoebitda2(M27,V27)) | AE27: =IF(M27="","",[1]!hks_fa_roa2(M27,[1]!s_fa_latelyrd_bt(M27,V27))) | AF27: =IF(M27="","",[1]!hks_fa_roe(M27,[1]!s_fa_latelyrd_bt(M27,V27))) | AG27: =IF(M27="","",[1]!s_share_total(M27,V27,100000000)) | AH27: =IF(M27="","",[1]!hks_share_total(M27,V27,100000000)) | AI27: =IF(M27="","",[1]!hks_share_totala(M27,V27,100000000)) | AJ27: =IF(M27="","",[1]!hks_share_totalb(M27,V27,100000000)) | AK27: =IF(M27="","",[1]!hks_share_h(M27,V27,100000000)) | AL27: =IF(M27="","",[1]!hks_share_oversea(M27,V27,100000000)) | AM27: =IF(M27="","",[1]!hks_holder_name(M27,V27,1)) | AN27: =IF(M27="","",[1]!hks_holder_quantity(M27,V27,1,10000)) | AO27: =IF(M27="","",[1]!hks_holder_pct(M27,V27,1)) | AP27: =IF(M27="","",[1]!s_esg_rating_wind(M27,V27)) | AQ27: =IF(M27="","",[1]!s_esg_score_wind(M27,V27))
N28: =IF(M28="","",[1]!hks_info_name(M28)) | O28: =IF(M28="","",[1]!s_ipo_listeddate(M28)) | P28: =IF(M28="","",[1]!s_info_exchmarket(M28)) | Q28: =IF(M28="","",[1]!s_info_mkt(M28)) | R28: =IF(M28="","",[1]!hks_info_isincode(M28)) | S28: =IF(M28="","",[1]!s_info_province(M28)) | T28: =IF(M28="","",[1]!s_info_city(M28)) | U28: =IF(M28="","",[1]!s_info_industry_gics(M28,9)) | V28: =IF(M28="","",[1]!lastradeday_s(M28,$D$7)) | W28: =IF(M28="","",[1]!s_dq_close(M28,V28,3)) | X28: =IF(M28="","",[1]!s_dq_pctchange(M28,V28)) | Y28: =IF(M28="","",[1]!hks_val_ev(M28,V28,"",100000000)) | Z28: =IF(M28="","",[1]!hks_val_mv_ard(M28,V28,"",100000000)) | AA28: =IF(M28="","",[1]!hks_fa_eps_basic(M28,[1]!s_fa_latelyrd_bt(M28,V28),"")) | AB28: =IF(M28="","",[1]!hks_val_pe_ttm(M28,V28)) | AC28: =IF(M28="","",[1]!pb_mrq(M28,V28)) | AD28: =IF(M28="","",[1]!s_val_evtoebitda2(M28,V28)) | AE28: =IF(M28="","",[1]!hks_fa_roa2(M28,[1]!s_fa_latelyrd_bt(M28,V28))) | AF28: =IF(M28="","",[1]!hks_fa_roe(M28,[1]!s_fa_latelyrd_bt(M28,V28))) | AG28: =IF(M28="","",[1]!s_share_total(M28,V28,100000000)) | AH28: =IF(M28="","",[1]!hks_share_total(M28,V28,100000000)) | AI28: =IF(M28="","",[1]!hks_share_totala(M28,V28,100000000)) | AJ28: =IF(M28="","",[1]!hks_share_totalb(M28,V28,100000000)) | AK28: =IF(M28="","",[1]!hks_share_h(M28,V28,100000000)) | AL28: =IF(M28="","",[1]!hks_share_oversea(M28,V28,100000000)) | AM28: =IF(M28="","",[1]!hks_holder_name(M28,V28,1)) | AN28: =IF(M28="","",[1]!hks_holder_quantity(M28,V28,1,10000)) | AO28: =IF(M28="","",[1]!hks_holder_pct(M28,V28,1)) | AP28: =IF(M28="","",[1]!s_esg_rating_wind(M28,V28)) | AQ28: =IF(M28="","",[1]!s_esg_score_wind(M28,V28))
N29: =IF(M29="","",[1]!hks_info_name(M29)) | O29: =IF(M29="","",[1]!s_ipo_listeddate(M29)) | P29: =IF(M29="","",[1]!s_info_exchmarket(M29)) | Q29: =IF(M29="","",[1]!s_info_mkt(M29)) | R29: =IF(M29="","",[1]!hks_info_isincode(M29)) | S29: =IF(M29="","",[1]!s_info_province(M29)) | T29: =IF(M29="","",[1]!s_info_city(M29)) | U29: =IF(M29="","",[1]!s_info_industry_gics(M29,9)) | V29: =IF(M29="","",[1]!lastradeday_s(M29,$D$7)) | W29: =IF(M29="","",[1]!s_dq_close(M29,V29,3)) | X29: =IF(M29="","",[1]!s_dq_pctchange(M29,V29)) | Y29: =IF(M29="","",[1]!hks_val_ev(M29,V29,"",100000000)) | Z29: =IF(M29="","",[1]!hks_val_mv_ard(M29,V29,"",100000000)) | AA29: =IF(M29="","",[1]!hks_fa_eps_basic(M29,[1]!s_fa_latelyrd_bt(M29,V29),"")) | AB29: =IF(M29="","",[1]!hks_val_pe_ttm(M29,V29)) | AC29: =IF(M29="","",[1]!pb_mrq(M29,V29)) | AD29: =IF(M29="","",[1]!s_val_evtoebitda2(M29,V29)) | AE29: =IF(M29="","",[1]!hks_fa_roa2(M29,[1]!s_fa_latelyrd_bt(M29,V29))) | AF29: =IF(M29="","",[1]!hks_fa_roe(M29,[1]!s_fa_latelyrd_bt(M29,V29))) | AG29: =IF(M29="","",[1]!s_share_total(M29,V29,100000000)) | AH29: =IF(M29="","",[1]!hks_share_total(M29,V29,100000000)) | AI29: =IF(M29="","",[1]!hks_share_totala(M29,V29,100000000)) | AJ29: =IF(M29="","",[1]!hks_share_totalb(M29,V29,100000000)) | AK29: =IF(M29="","",[1]!hks_share_h(M29,V29,100000000)) | AL29: =IF(M29="","",[1]!hks_share_oversea(M29,V29,100000000)) | AM29: =IF(M29="","",[1]!hks_holder_name(M29,V29,1)) | AN29: =IF(M29="","",[1]!hks_holder_quantity(M29,V29,1,10000)) | AO29: =IF(M29="","",[1]!hks_holder_pct(M29,V29,1)) | AP29: =IF(M29="","",[1]!s_esg_rating_wind(M29,V29)) | AQ29: =IF(M29="","",[1]!s_esg_score_wind(M29,V29))
N30: =IF(M30="","",[1]!hks_info_name(M30)) | O30: =IF(M30="","",[1]!s_ipo_listeddate(M30)) | P30: =IF(M30="","",[1]!s_info_exchmarket(M30)) | Q30: =IF(M30="","",[1]!s_info_mkt(M30)) | R30: =IF(M30="","",[1]!hks_info_isincode(M30)) | S30: =IF(M30="","",[1]!s_info_province(M30)) | T30: =IF(M30="","",[1]!s_info_city(M30)) | U30: =IF(M30="","",[1]!s_info_industry_gics(M30,9)) | V30: =IF(M30="","",[1]!lastradeday_s(M30,$D$7)) | W30: =IF(M30="","",[1]!s_dq_close(M30,V30,3)) | X30: =IF(M30="","",[1]!s_dq_pctchange(M30,V30)) | Y30: =IF(M30="","",[1]!hks_val_ev(M30,V30,"",100000000)) | Z30: =IF(M30="","",[1]!hks_val_mv_ard(M30,V30,"",100000000)) | AA30: =IF(M30="","",[1]!hks_fa_eps_basic(M30,[1]!s_fa_latelyrd_bt(M30,V30),"")) | AB30: =IF(M30="","",[1]!hks_val_pe_ttm(M30,V30)) | AC30: =IF(M30="","",[1]!pb_mrq(M30,V30)) | AD30: =IF(M30="","",[1]!s_val_evtoebitda2(M30,V30)) | AE30: =IF(M30="","",[1]!hks_fa_roa2(M30,[1]!s_fa_latelyrd_bt(M30,V30))) | AF30: =IF(M30="","",[1]!hks_fa_roe(M30,[1]!s_fa_latelyrd_bt(M30,V30))) | AG30: =IF(M30="","",[1]!s_share_total(M30,V30,100000000)) | AH30: =IF(M30="","",[1]!hks_share_total(M30,V30,100000000)) | AI30: =IF(M30="","",[1]!hks_share_totala(M30,V30,100000000)) | AJ30: =IF(M30="","",[1]!hks_share_totalb(M30,V30,100000000)) | AK30: =IF(M30="","",[1]!hks_share_h(M30,V30,100000000)) | AL30: =IF(M30="","",[1]!hks_share_oversea(M30,V30,100000000)) | AM30: =IF(M30="","",[1]!hks_holder_name(M30,V30,1)) | AN30: =IF(M30="","",[1]!hks_holder_quantity(M30,V30,1,10000)) | AO30: =IF(M30="","",[1]!hks_holder_pct(M30,V30,1)) | AP30: =IF(M30="","",[1]!s_esg_rating_wind(M30,V30)) | AQ30: =IF(M30="","",[1]!s_esg_score_wind(M30,V30))
N31: =IF(M31="","",[1]!hks_info_name(M31)) | O31: =IF(M31="","",[1]!s_ipo_listeddate(M31)) | P31: =IF(M31="","",[1]!s_info_exchmarket(M31)) | Q31: =IF(M31="","",[1]!s_info_mkt(M31)) | R31: =IF(M31="","",[1]!hks_info_isincode(M31)) | S31: =IF(M31="","",[1]!s_info_province(M31)) | T31: =IF(M31="","",[1]!s_info_city(M31)) | U31: =IF(M31="","",[1]!s_info_industry_gics(M31,9)) | V31: =IF(M31="","",[1]!lastradeday_s(M31,$D$7)) | W31: =IF(M31="","",[1]!s_dq_close(M31,V31,3)) | X31: =IF(M31="","",[1]!s_dq_pctchange(M31,V31)) | Y31: =IF(M31="","",[1]!hks_val_ev(M31,V31,"",100000000)) | Z31: =IF(M31="","",[1]!hks_val_mv_ard(M31,V31,"",100000000)) | AA31: =IF(M31="","",[1]!hks_fa_eps_basic(M31,[1]!s_fa_latelyrd_bt(M31,V31),"")) | AB31: =IF(M31="","",[1]!hks_val_pe_ttm(M31,V31)) | AC31: =IF(M31="","",[1]!pb_mrq(M31,V31)) | AD31: =IF(M31="","",[1]!s_val_evtoebitda2(M31,V31)) | AE31: =IF(M31="","",[1]!hks_fa_roa2(M31,[1]!s_fa_latelyrd_bt(M31,V31))) | AF31: =IF(M31="","",[1]!hks_fa_roe(M31,[1]!s_fa_latelyrd_bt(M31,V31))) | AG31: =IF(M31="","",[1]!s_share_total(M31,V31,100000000)) | AH31: =IF(M31="","",[1]!hks_share_total(M31,V31,100000000)) | AI31: =IF(M31="","",[1]!hks_share_totala(M31,V31,100000000)) | AJ31: =IF(M31="","",[1]!hks_share_totalb(M31,V31,100000000)) | AK31: =IF(M31="","",[1]!hks_share_h(M31,V31,100000000)) | AL31: =IF(M31="","",[1]!hks_share_oversea(M31,V31,100000000)) | AM31: =IF(M31="","",[1]!hks_holder_name(M31,V31,1)) | AN31: =IF(M31="","",[1]!hks_holder_quantity(M31,V31,1,10000)) | AO31: =IF(M31="","",[1]!hks_holder_pct(M31,V31,1)) | AP31: =IF(M31="","",[1]!s_esg_rating_wind(M31,V31)) | AQ31: =IF(M31="","",[1]!s_esg_score_wind(M31,V31))
N32: =IF(M32="","",[1]!hks_info_name(M32)) | O32: =IF(M32="","",[1]!s_ipo_listeddate(M32)) | P32: =IF(M32="","",[1]!s_info_exchmarket(M32)) | Q32: =IF(M32="","",[1]!s_info_mkt(M32)) | R32: =IF(M32="","",[1]!hks_info_isincode(M32)) | S32: =IF(M32="","",[1]!s_info_province(M32)) | T32: =IF(M32="","",[1]!s_info_city(M32)) | U32: =IF(M32="","",[1]!s_info_industry_gics(M32,9)) | V32: =IF(M32="","",[1]!lastradeday_s(M32,$D$7)) | W32: =IF(M32="","",[1]!s_dq_close(M32,V32,3)) | X32: =IF(M32="","",[1]!s_dq_pctchange(M32,V32)) | Y32: =IF(M32="","",[1]!hks_val_ev(M32,V32,"",100000000)) | Z32: =IF(M32="","",[1]!hks_val_mv_ard(M32,V32,"",100000000)) | AA32: =IF(M32="","",[1]!hks_fa_eps_basic(M32,[1]!s_fa_latelyrd_bt(M32,V32),"")) | AB32: =IF(M32="","",[1]!hks_val_pe_ttm(M32,V32)) | AC32: =IF(M32="","",[1]!pb_mrq(M32,V32)) | AD32: =IF(M32="","",[1]!s_val_evtoebitda2(M32,V32)) | AE32: =IF(M32="","",[1]!hks_fa_roa2(M32,[1]!s_fa_latelyrd_bt(M32,V32))) | AF32: =IF(M32="","",[1]!hks_fa_roe(M32,[1]!s_fa_latelyrd_bt(M32,V32))) | AG32: =IF(M32="","",[1]!s_share_total(M32,V32,100000000)) | AH32: =IF(M32="","",[1]!hks_share_total(M32,V32,100000000)) | AI32: =IF(M32="","",[1]!hks_share_totala(M32,V32,100000000)) | AJ32: =IF(M32="","",[1]!hks_share_totalb(M32,V32,100000000)) | AK32: =IF(M32="","",[1]!hks_share_h(M32,V32,100000000)) | AL32: =IF(M32="","",[1]!hks_share_oversea(M32,V32,100000000)) | AM32: =IF(M32="","",[1]!hks_holder_name(M32,V32,1)) | AN32: =IF(M32="","",[1]!hks_holder_quantity(M32,V32,1,10000)) | AO32: =IF(M32="","",[1]!hks_holder_pct(M32,V32,1)) | AP32: =IF(M32="","",[1]!s_esg_rating_wind(M32,V32)) | AQ32: =IF(M32="","",[1]!s_esg_score_wind(M32,V32))
... N100: =IF(M100="","",[1]!hks_info_name(M100)) | O100: =IF(M100="","",[1]!s_ipo_listeddate(M100)) | P100: =IF(M100="","",[1]!s_info_exchmarket(M100)) | Q100: =IF(M100="","",[1]!s_info_mkt(M100)) | R100: =IF(M100="","",[1]!hks_info_isincode(M100)) | S100: =IF(M100="","",[1]!s_info_province(M100)) | T100: =IF(M100="","",[1]!s_info_city(M100)) | U100: =IF(M100="","",[1]!s_info_industry_gics(M100,9)) | V100: =IF(M100="","",[1]!lastradeday_s(M100,$D$7)) | W100: =IF(M100="","",[1]!s_dq_close(M100,V100,3)) | X100: =IF(M100="","",[1]!s_dq_pctchange(M100,V100)) | Y100: =IF(M100="","",[1]!hks_val_ev(M100,V100,"",100000000)) | Z100: =IF(M100="","",[1]!hks_val_mv_ard(M100,V100,"",100000000)) | AA100: =IF(M100="","",[1]!hks_fa_eps_basic(M100,[1]!s_fa_latelyrd_bt(M100,V100),"")) | AB100: =IF(M100="","",[1]!hks_val_pe_ttm(M100,V100)) | AC100: =IF(M100="","",[1]!pb_mrq(M100,V100)) | AD100: =IF(M100="","",[1]!s_val_evtoebitda2(M100,V100)) | AE100: =IF(M100="","",[1]!hks_fa_roa2(M100,[1]!s_fa_latelyrd_bt(M100,V100))) | AF100: =IF(M100="","",[1]!hks_fa_roe(M100,[1]!s_fa_latelyrd_bt(M100,V100))) | AG100: =IF(M100="","",[1]!s_share_total(M100,V100,100000000)) | AH100: =IF(M100="","",[1]!hks_share_total(M100,V100,100000000)) | AI100: =IF(M100="","",[1]!hks_share_totala(M100,V100,100000000)) | AJ100: =IF(M100="","",[1]!hks_share_totalb(M100,V100,100000000)) | AK100: =IF(M100="","",[1]!hks_share_h(M100,V100,100000000)) | AL100: =IF(M100="","",[1]!hks_share_oversea(M100,V100,100000000)) | AM100: =IF(M100="","",[1]!hks_holder_name(M100,V100,1)) | AN100: =IF(M100="","",[1]!hks_holder_quantity(M100,V100,1,10000)) | AO100: =IF(M100="","",[1]!hks_holder_pct(M100,V100,1)) | AP100: =IF(M100="","",[1]!s_esg_rating_wind(M100,V100)) | AQ100: =IF(M100="","",[1]!s_esg_score_wind(M100,V100))

Sheet 财务报表摘要
D1: 可比公司-资产负债表
C4: 财务报表摘要
C6: Wind代码 | D6: 证券简称 | E6: 最新收盘日 | F6: 最近一期年报日期 | G6: 最近一期年报记账本位币 | H6: 利润表摘要(亿元) | Q6: 资产负债表摘要(亿元) | AB6: 现金流量表摘要(亿元)
H7: 营业总收入 | I7: 营业总成本 | J7: 营业利润 | K7: 净利润 | L7: 归属普通股东净利润 | M7: 非经常性损益 | N7: 研发支出 | O7: EBIT(反推法) | P7: EBITDA(反推法) | Q7: 现金及现金等价物 | R7: 流动资产 | S7: 固定资产 | T7: 非流动资产合计 | U7: 权益性投资 | V7: 资产总计 | W7: 流动负债 | X7: 非流动负债 | Y7: 负债合计 | Z7: 股东权益 | AA7: 归属母公司股东的权益 | AB7: 经营活动现金净流量 | AC7: 资本性支出 | AD7: 投资活动现金净流量 | AE7: 筹资活动现金净流量 | AF7: 现金及现金等价物净增加额 | AG7: 现金及现金等价物期末余额
C8: =IF(表1[[#This Row],[列1]]="","",表1[[#This Row],[列1]]) -> 000001.SZ | D8: =IF(C8="","",[1]!hks_info_name(C8)) -> 平安银行 | E8: =IF(C8="","",[1]!lastradeday_s(C8,TODAY())) -> 2024-12-09 | F8: =IF(C8="","",IF(OR([1]!s_stm_rpt_e(C8,基本资料!$I$8,0)="#N/A",[1]!s_stm_rpt_e(C8,基本资料!$I$8,0)="",[1]!s_stm_rpt_e(C8,基本资料!$I$8,0)=0),[1]!s_stm_rpt_e(C8,基本资料!$I$9,0),[1]!s_stm_rpt_e(C8,基本资料!$I$8,0))) -> 2023-12-31 | G8: =IF(C8="","",[1]!hks_info_cur2(C8,F8)) -> CNY | H8: =IF(C8="","",[1]!hks_stm_is(C8,"83",F8,1,"",100000000)) -> 1629.81 | I8: =IF(C8="","",[1]!hks_stm_is(C8,"1032",F8,1,"",100000000)) -> 1050.53 | J8: =IF(C8="","",[1]!hks_stm_is(C8,"1041",F8,1,"",100000000)) -> 579.28 | K8: =IF(C8="","",[1]!hks_stm_is(C8,"61",F8,1,"",100000000)) -> 464.55 | L8: =IF(C8="","",[1]!hks_stm_is(C8,"1075",F8,1,"",100000000)) -> 464.55 | M8: =IF(C8="","",[1]!hks_stm_is(C8,"1077",F8,1,"",100000000)) -> -5.64 | N8: =IF(C8="","",[1]!hks_stm_is(C8,"1030",F8,1,"",100000000)) -> 0 | O8: =IF(C8="","",[1]!hks_fa_ebit(C8,F8,1,"",100000000)) -> 0 | P8: =IF(C8="","",[1]!hks_fa_ebitda(C8,F8,1,"",100000000)) -> 0 | Q8: =IF(C8="","",[1]!hks_stm_bs(C8,"9",F8,1,"",100000000)) -> 0 | R8: =IF(C8="","",[1]!hks_stm_bs(C8,"25",F8,1,"",100000000)) -> 0 | S8: =IF(C8="","",[1]!hks_stm_bs(C8,"1088",F8,1,"",100000000)) -> 0 | T8: =IF(C8="","",[1]!hks_stm_bs(C8,"46",F8,1,"",100000000)) -> 0 | U8: =IF(C8="","",[1]!hks_stm_bs(C8,"29",F8,1,"",100000000)) -> 0 | V8: =IF(C8="","",[1]!hks_stm_bs(C8,"74",F8,1,"",100000000)) -> 55871.16 | W8: =IF(C8="","",[1]!hks_stm_bs(C8,"93",F8,1,"",100000000)) -> 0 | X8: =IF(C8="","",[1]!hks_stm_bs(C8,"1017",F8,1,"",100000000)) -> 0 | Y8: =IF(C8="","",[1]!hks_stm_bs(C8,"128",F8,1,"",100000000)) -> 51147.88 | Z8: =IF(C8="","",[1]!hks_stm_bs(C8,"145",F8,1,"",100000000)) -> 4723.28 | AA8: =IF(C8="","",[1]!hks_stm_bs(C8,"140",F8,1,"",100000000)) -> 4723.28 | AB8: =IF(C8="","",[1]!hks_stm_cs(C8,"39",F8,1,"",100000000)) -> 924.61 | AC8: =IF(C8="","",[1]!hks_stm_cs(C8,"1020",F8,1,"",100000000)) -> 30.96 | AD8: =IF(C8="","",[1]!hks_stm_cs(C8,"59",F8,1,"",100000000)) -> -261.42 | AE8: =IF(C8="","",[1]!hks_stm_cs(C8,"77",F8,1,"",100000000)) -> 80.89 | AF8: =IF(C8="","",[1]!hks_stm_cs(C8,"82",F8,1,"",100000000)) -> 758.93 | AG8: =IF(C8="","",[1]!hks_stm_cs(C8,"84",F8,1,"",100000000)) -> 2982.19
C9: =IF(表1[[#This Row],[列1]]="","",表1[[#This Row],[列1]]) -> 000002.SZ | D9: =IF(C9="","",[1]!hks_info_name(C9)) -> 万科A | E9: =IF(C9="","",[1]!lastradeday_s(C9,TODAY())) -> 2024-12-09 | F9: =IF(C9="","",IF(OR([1]!s_stm_rpt_e(C9,基本资料!$I$8,0)="#N/A",[1]!s_stm_rpt_e(C9,基本资料!$I$8,0)="",[1]!s_stm_rpt_e(C9,基本资料!$I$8,0)=0),[1]!s_stm_rpt_e(C9,基本资料!$I$9,0),[1]!s_stm_rpt_e(C9,基本资料!$I$8,0))) -> 2023-12-31 | G9: =IF(C9="","",[1]!hks_info_cur2(C9,F9)) -> CNY | H9: =IF(C9="","",[1]!hks_stm_is(C9,"83",F9,1,"",100000000)) -> 4663.5415 | I9: =IF(C9="","",[1]!hks_stm_is(C9,"1032",F9,1,"",100000000)) -> 4225.5719 | J9: =IF(C9="","",[1]!hks_stm_is(C9,"1041",F9,1,"",100000000)) -> 437.96966 | K9: =IF(C9="","",[1]!hks_stm_is(C9,"61",F9,1,"",100000000)) -> 121.62684 | L9: =IF(C9="","",[1]!hks_stm_is(C9,"1075",F9,1,"",100000000)) -> 121.62684 | M9: =IF(C9="","",[1]!hks_stm_is(C9,"1077",F9,1,"",100000000)) -> 34.67674 | N9: =IF(C9="","",[1]!hks_stm_is(C9,"1030",F9,1,"",100000000)) -> 0 | O9: =IF(C9="","",[1]!hks_fa_ebit(C9,F9,1,"",100000000)) -> 468.16806 | P9: =IF(C9="","",[1]!hks_fa_ebitda(C9,F9,1,"",100000000)) -> 558.97601 | Q9: =IF(C9="","",[1]!hks_stm_bs(C9,"9",F9,1,"",100000000)) -> 969.42577 | R9: =IF(C9="","",[1]!hks_stm_bs(C9,"25",F9,1,"",100000000)) -> 11502.821 | S9: =IF(C9="","",[1]!hks_stm_bs(C9,"1088",F9,1,"",100000000)) -> 0 | T9: =IF(C9="","",[1]!hks_stm_bs(C9,"46",F9,1,"",100000000)) -> 3545.9011 | U9: =IF(C9="","",[1]!hks_stm_bs(C9,"29",F9,1,"",100000000)) -> 1305.6253 | V9: =IF(C9="","",[1]!hks_stm_bs(C9,"74",F9,1,"",100000000)) -> 15048.722 | W9: =IF(C9="","",[1]!hks_stm_bs(C9,"93",F9,1,"",100000000)) -> 8217.8526 | X9: =IF(C9="","",[1]!hks_stm_bs(C9,"1017",F9,1,"",100000000)) -> 2801.5338 | Y9: =IF(C9="","",[1]!hks_stm_bs(C9,"128",F9,1,"",100000000)) -> 11019.386 | Z9: =IF(C9="","",[1]!hks_stm_bs(C9,"145",F9,1,"",100000000)) -> 4029.3353 | AA9: =IF(C9="","",[1]!hks_stm_bs(C9,"140",F9,1,"",100000000)) -> 2507.8461 | AB9: =IF(C9="","",[1]!hks_stm_cs(C9,"39",F9,1,"",100000000)) -> 39.12323 | AC9: =IF(C9="","",[1]!hks_stm_cs(C9,"1020",F9,1,"",100000000)) -> 83.34153 | AD9: =IF(C9="","",[1]!hks_stm_cs(C9,"59",F9,1,"",100000000)) -> -46.15642 | AE9: =IF(C9="","",[1]!hks_stm_cs(C9,"77",F9,1,"",100000000)) -> -368.13164 | AF9: =IF(C9="","",[1]!hks_stm_cs(C9,"82",F9,1,"",100000000)) -> -374.82093 | AG9: =IF(C9="","",[1]!hks_stm_cs(C9,"84",F9,1,"",100000000)) -> 969.42577
C10: =IF(表1[[#This Row],[列1]]="","",表1[[#This Row],[列1]]) -> 002123.SZ | D10: =IF(C10="","",[1]!hks_info_name(C10)) -> 梦网科技 | E10: =IF(C10="","",[1]!lastradeday_s(C10,TODAY())) -> 2024-12-09 | F10: =IF(C10="","",IF(OR([1]!s_stm_rpt_e(C10,基本资料!$I$8,0)="#N/A",[1]!s_stm_rpt_e(C10,基本资料!$I$8,0)="",[1]!s_stm_rpt_e(C10,基本资料!$I$8,0)=0),[1]!s_stm_rpt_e(C10,基本资料!$I$9,0),[1]!s_stm_rpt_e(C10,基本资料!$I$8,0))) -> 2023-12-31 | G10: =IF(C10="","",[1]!hks_info_cur2(C10,F10)) -> CNY | H10: =IF(C10="","",[1]!hks_stm_is(C10,"83",F10,1,"",100000000)) -> 52.26865 | I10: =IF(C10="","",[1]!hks_stm_is(C10,"1032",F10,1,"",100000000)) -> 87.476583 | J10: =IF(C10="","",[1]!hks_stm_is(C10,"1041",F10,1,"",100000000)) -> -35.207933 | K10: =IF(C10="","",[1]!hks_stm_is(C10,"61",F10,1,"",100000000)) -> -18.224854 | L10: =IF(C10="","",[1]!hks_stm_is(C10,"1075",F10,1,"",100000000)) -> -18.224854 | M10: =IF(C10="","",[1]!hks_stm_is(C10,"1077",F10,1,"",100000000)) -> -0.082948486 | N10: =IF(C10="","",[1]!hks_stm_is(C10,"1030",F10,1,"",100000000)) -> 0 | O10: =IF(C10="","",[1]!hks_fa_ebit(C10,F10,1,"",100000000)) -> -18.32476 | P10: =IF(C10="","",[1]!hks_fa_ebitda(C10,F10,1,"",100000000)) -> -17.900584 | Q10: =IF(C10="","",[1]!hks_stm_bs(C10,"9",F10,1,"",100000000)) -> 3.7838149 | R10: =IF(C10="","",[1]!hks_stm_bs(C10,"25",F10,1,"",100000000)) -> 34.642016 | S10: =IF(C10="","",[1]!hks_stm_bs(C10,"1088",F10,1,"",100000000)) -> 0 | T10: =IF(C10="","",[1]!hks_stm_bs(C10,"46",F10,1,"",100000000)) -> 8.8545093 | U10: =IF(C10="","",[1]!hks_stm_bs(C10,"29",F10,1,"",100000000)) -> 0.99310165 | V10: =IF(C10="","",[1]!hks_stm_bs(C10,"74",F10,1,"",100000000)) -> 43.496525 | W10: =IF(C10="","",[1]!hks_stm_bs(C10,"93",F10,1,"",100000000)) -> 25.122499 | X10: =IF(C10="","",[1]!hks_stm_bs(C10,"1017",F10,1,"",100000000)) -> 2.0673113 | Y10: =IF(C10="","",[1]!hks_stm_bs(C10,"128",F10,1,"",100000000)) -> 27.18981 | Z10: =IF(C10="","",[1]!hks_stm_bs(C10,"145",F10,1,"",100000000)) -> 16.306715 | AA10: =IF(C10="","",[1]!hks_stm_bs(C10,"140",F10,1,"",100000000)) -> 16.253357 | AB10: =IF(C10="","",[1]!hks_stm_cs(C10,"39",F10,1,"",100000000)) -> -3.9893286 | AC10: =IF(C10="","",[1]!hks_stm_cs(C10,"1020",F10,1,"",100000000)) -> 0.09988601 | AD10: =IF(C10="","",[1]!hks_stm_cs(C10,"59",F10,1,"",100000000)) -> 3.9889926 | AE10: =IF(C10="","",[1]!hks_stm_cs(C10,"77",F10,1,"",100000000)) -> -1.4448183 | AF10: =IF(C10="","",[1]!hks_stm_cs(C10,"82",F10,1,"",100000000)) -> -1.4129896 | AG10: =IF(C10="","",[1]!hks_stm_cs(C10,"84",F10,1,"",100000000)) -> 3.7838149
C11: =IF(表1[[#This Row],[列1]]="","",表1[[#This Row],[列1]]) -> 002230.SZ | D11: =IF(C11="","",[1]!hks_info_name(C11)) -> 科大讯飞 | E11: =IF(C11="","",[1]!lastradeday_s(C11,TODAY())) -> 2024-12-09 | F11: =IF(C11="","",IF(OR([1]!s_stm_rpt_e(C11,基本资料!$I$8,0)="#N/A",[1]!s_stm_rpt_e(C11,基本资料!$I$8,0)="",[1]!s_stm_rpt_e(C11,基本资料!$I$8,0)=0),[1]!s_stm_rpt_e(C11,基本资料!$I$9,0),[1]!s_stm_rpt_e(C11,基本资料!$I$8,0))) -> 2023-12-31 | G11: =IF(C11="","",[1]!hks_info_cur2(C11,F11)) -> CNY | H11: =IF(C11="","",[1]!hks_stm_is(C11,"83",F11,1,"",100000000)) -> 195.23881 | I11: =IF(C11="","",[1]!hks_stm_is(C11,"1032",F11,1,"",100000000)) -> 205.49054 | J11: =IF(C11="","",[1]!hks_stm_is(C11,"1041",F11,1,"",100000000)) -> -10.251725 | K11: =IF(C11="","",[1]!hks_stm_is(C11,"61",F11,1,"",100000000)) -> 6.5731291 | L11: =IF(C11="","",[1]!hks_stm_is(C11,"1075",F11,1,"",100000000)) -> 6.5731291 | M11: =IF(C11="","",[1]!hks_stm_is(C11,"1077",F11,1,"",100000000)) -> 0.70491983 | N11: =IF(C11="","",[1]!hks_stm_is(C11,"1030",F11,1,"",100000000)) -> 0 | O11: =IF(C11="","",[1]!hks_fa_ebit(C11,F11,1,"",100000000)) -> 4.19771 | P11: =IF(C11="","",[1]!hks_fa_ebitda(C11,F11,1,"",100000000)) -> 22.151207 | Q11: =IF(C11="","",[1]!hks_stm_bs(C11,"9",F11,1,"",100000000)) -> 33.829103 | R11: =IF(C11="","",[1]!hks_stm_bs(C11,"25",F11,1,"",100000000)) -> 211.99919 | S11: =IF(C11="","",[1]!hks_stm_bs(C11,"1088",F11,1,"",100000000)) -> 0 | T11: =IF(C11="","",[1]!hks_stm_bs(C11,"46",F11,1,"",100000000)) -> 166.31204 | U11: =IF(C11="","",[1]!hks_stm_bs(C11,"29",F11,1,"",100000000)) -> 14.37179 | V11: =IF(C11="","",[1]!hks_stm_bs(C11,"74",F11,1,"",100000000)) -> 378.31123 | W11: =IF(C11="","",[1]!hks_stm_bs(C11,"93",F11,1,"",100000000)) -> 129.07582 | X11: =IF(C11="","",[1]!hks_stm_bs(C11,"1017",F11,1,"",100000000)) -> 71.915069 | Y11: =IF(C11="","",[1]!hks_stm_bs(C11,"128",F11,1,"",100000000)) -> 200.99089 | Z11: =IF(C11="","",[1]!hks_stm_bs(C11,"145",F11,1,"",100000000)) -> 177.32034 | AA11: =IF(C11="","",[1]!hks_stm_bs(C11,"140",F11,1,"",100000000)) -> 170.32285 | AB11: =IF(C11="","",[1]!hks_stm_cs(C11,"39",F11,1,"",100000000)) -> 3.4975781 | AC11: =IF(C11="","",[1]!hks_stm_cs(C11,"1020",F11,1,"",100000000)) -> 40.818576 | AD11: =IF(C11="","",[1]!hks_stm_cs(C11,"59",F11,1,"",100000000)) -> -39.787283 | AE11: =IF(C11="","",[1]!hks_stm_cs(C11,"77",F11,1,"",100000000)) -> 28.297044 | AF11: =IF(C11="","",[1]!hks_stm_cs(C11,"82",F11,1,"",100000000)) -> -7.8994421 | AG11: =IF(C11="","",[1]!hks_stm_cs(C11,"84",F11,1,"",100000000)) -> 33.829103
