Workbook
Name A股列表: [1]证券列表!$A$1:$A$1898
Name Index: [1]证券列表!$B$1:$B$7

Sheet 情景分析
B5: 分析基准日 | D5: =[2]!td(TODAY()-2) -> 2025-10-24 | J5: 中债估值
B6: 基准日YTM | D6: 1 | E6: =IF(D6=3,"请至-持仓数据-页F列输入分析基准日收益率","") | I6: 净价 | J6: 加权平均YTM
B7: 分析价格 | D7: 1 | I7: 全价 | J7: 自定义
J8: 银行间中债交易所中证
B9: 持有期收益率
B10: 单位:% | D10: 20 | E10: 15 | F10: 10 | G10: 0 | H10: -10 | I10: -15 | J10: -20
D11: BP | E11: BP | F11: BP | G11: BP | H11: BP | I11: BP | J11: BP
B12: 1W | C12: =TODAY()+7 -> 45965 | D12: =((持仓数据!O$3/IF($D$6=1,持仓数据!$I$3,IF($D$6=2,持仓数据!$D$3,IF($D$6=4,持仓数据!$M$3,持仓数据!$F$3))))-1)*365/($C12-$D$5)*100 -> 10.437467 | E12: =((持仓数据!P$3/IF($D$6=1,持仓数据!$I$3,IF($D$6=2,持仓数据!$D$3,IF($D$6=4,持仓数据!$M$3,持仓数据!$F$3))))-1)*365/($C12-$D$5)*100 -> 18.290186 | F12: =((持仓数据!Q$3/IF($D$6=1,持仓数据!$I$3,IF($D$6=2,持仓数据!$D$3,IF($D$6=4,持仓数据!$M$3,持仓数据!$F$3))))-1)*365/($C12-$D$5)*100 -> 26.167456 | G12: =((持仓数据!R$3/IF($D$6=1,持仓数据!$I$3,IF($D$6=2,持仓数据!$D$3,IF($D$6=4,持仓数据!$M$3,持仓数据!$F$3))))-1)*365/($C12-$D$5)*100 -> 41.996014 | H12: =((持仓数据!S$3/IF($D$6=1,持仓数据!$I$3,IF($D$6=2,持仓数据!$D$3,IF($D$6=4,持仓数据!$M$3,持仓数据!$F$3))))-1)*365/($C12-$D$5)*100 -> 57.923867 | I12: =((持仓数据!T$3/IF($D$6=1,持仓数据!$I$3,IF($D$6=2,持仓数据!$D$3,IF($D$6=4,持仓数据!$M$3,持仓数据!$F$3))))-1)*365/($C12-$D$5)*100 -> 65.925258 | J12: =((持仓数据!U$3/IF($D$6=1,持仓数据!$I$3,IF($D$6=2,持仓数据!$D$3,IF($D$6=4,持仓数据!$M$3,持仓数据!$F$3))))-1)*365/($C12-$D$5)*100 -> 73.951747
B13: 1M | C13: =DATE(YEAR(TODAY()),MONTH(TODAY())+1,DAY(TODAY())) -> 45989 | D13: =((持仓数据!V$3/IF($D$6=1,持仓数据!$I$3,IF($D$6=2,持仓数据!$D$3,IF($D$6=4,持仓数据!$M$3,持仓数据!$F$3))))-1)*365/($C13-$D$5)*100 -> 2.5539096 | E13: =((持仓数据!W$3/IF($D$6=1,持仓数据!$I$3,IF($D$6=2,持仓数据!$D$3,IF($D$6=4,持仓数据!$M$3,持仓数据!$F$3))))-1)*365/($C13-$D$5)*100 -> 4.9906997 | F13: =((持仓数据!X$3/IF($D$6=1,持仓数据!$I$3,IF($D$6=2,持仓数据!$D$3,IF($D$6=4,持仓数据!$M$3,持仓数据!$F$3))))-1)*365/($C13-$D$5)*100 -> 7.4350426 | G13: =((持仓数据!Y$3/IF($D$6=1,持仓数据!$I$3,IF($D$6=2,持仓数据!$D$3,IF($D$6=4,持仓数据!$M$3,持仓数据!$F$3))))-1)*365/($C13-$D$5)*100 -> 12.346498 | H13: =((持仓数据!Z$3/IF($D$6=1,持仓数据!$I$3,IF($D$6=2,持仓数据!$D$3,IF($D$6=4,持仓数据!$M$3,持仓数据!$F$3))))-1)*365/($C13-$D$5)*100 -> 17.288496 | I13: =((持仓数据!AA$3/IF($D$6=1,持仓数据!$I$3,IF($D$6=2,持仓数据!$D$3,IF($D$6=4,持仓数据!$M$3,持仓数据!$F$3))))-1)*365/($C13-$D$5)*100 -> 19.771019 | J13: =((持仓数据!AB$3/IF($D$6=1,持仓数据!$I$3,IF($D$6=2,持仓数据!$D$3,IF($D$6=4,持仓数据!$M$3,持仓数据!$F$3))))-1)*365/($C13-$D$5)*100 -> 22.261261
B14: 3M | C14: =DATE(YEAR(TODAY()),MONTH(TODAY())+3,DAY(TODAY())) -> 46050 | D14: =((持仓数据!AC$3/IF($D$6=1,持仓数据!$I$3,IF($D$6=2,持仓数据!$D$3,IF($D$6=4,持仓数据!$M$3,持仓数据!$F$3))))-1)*365/($C14-$D$5)*100 -> 0.25511837 | E14: =((持仓数据!AD$3/IF($D$6=1,持仓数据!$I$3,IF($D$6=2,持仓数据!$D$3,IF($D$6=4,持仓数据!$M$3,持仓数据!$F$3))))-1)*365/($C14-$D$5)*100 -> 1.1145194 | F14: =((持仓数据!AE$3/IF($D$6=1,持仓数据!$I$3,IF($D$6=2,持仓数据!$D$3,IF($D$6=4,持仓数据!$M$3,持仓数据!$F$3))))-1)*365/($C14-$D$5)*100 -> 1.9765252 | G14: =((持仓数据!AF$3/IF($D$6=1,持仓数据!$I$3,IF($D$6=2,持仓数据!$D$3,IF($D$6=4,持仓数据!$M$3,持仓数据!$F$3))))-1)*365/($C14-$D$5)*100 -> 3.7083884 | H14: =((持仓数据!AG$3/IF($D$6=1,持仓数据!$I$3,IF($D$6=2,持仓数据!$D$3,IF($D$6=4,持仓数据!$M$3,持仓数据!$F$3))))-1)*365/($C14-$D$5)*100 -> 5.4507828 | I14: =((持仓数据!AH$3/IF($D$6=1,持仓数据!$I$3,IF($D$6=2,持仓数据!$D$3,IF($D$6=4,持仓数据!$M$3,持仓数据!$F$3))))-1)*365/($C14-$D$5)*100 -> 6.3259528 | J14: =((持仓数据!AI$3/IF($D$6=1,持仓数据!$I$3,IF($D$6=2,持仓数据!$D$3,IF($D$6=4,持仓数据!$M$3,持仓数据!$F$3))))-1)*365/($C14-$D$5)*100 -> 7.203784
B15: 6M | C15: =DATE(YEAR(TODAY()),MONTH(TODAY())+6,DAY(TODAY())) -> 46140 | D15: =((持仓数据!AJ$3/IF($D$6=1,持仓数据!$I$3,IF($D$6=2,持仓数据!$D$3,IF($D$6=4,持仓数据!$M$3,持仓数据!$F$3))))-1)*365/($C15-$D$5)*100 -> 0.131674 | E15: =((持仓数据!AK$3/IF($D$6=1,持仓数据!$I$3,IF($D$6=2,持仓数据!$D$3,IF($D$6=4,持仓数据!$M$3,持仓数据!$F$3))))-1)*365/($C15-$D$5)*100 -> 0.57523581 | F15: =((持仓数据!AL$3/IF($D$6=1,持仓数据!$I$3,IF($D$6=2,持仓数据!$D$3,IF($D$6=4,持仓数据!$M$3,持仓数据!$F$3))))-1)*365/($C15-$D$5)*100 -> 1.020142 | G15: =((持仓数据!AM$3/IF($D$6=1,持仓数据!$I$3,IF($D$6=2,持仓数据!$D$3,IF($D$6=4,持仓数据!$M$3,持仓数据!$F$3))))-1)*365/($C15-$D$5)*100 -> 1.9140069 | H15: =((持仓数据!AN$3/IF($D$6=1,持仓数据!$I$3,IF($D$6=2,持仓数据!$D$3,IF($D$6=4,持仓数据!$M$3,持仓数据!$F$3))))-1)*365/($C15-$D$5)*100 -> 2.8133072 | I15: =((持仓数据!AO$3/IF($D$6=1,持仓数据!$I$3,IF($D$6=2,持仓数据!$D$3,IF($D$6=4,持仓数据!$M$3,持仓数据!$F$3))))-1)*365/($C15-$D$5)*100 -> 3.2650079 | J15: =((持仓数据!AP$3/IF($D$6=1,持仓数据!$I$3,IF($D$6=2,持仓数据!$D$3,IF($D$6=4,持仓数据!$M$3,持仓数据!$F$3))))-1)*365/($C15-$D$5)*100 -> 3.7180821
B16: 1Y | C16: =DATE(YEAR(TODAY())+1,MONTH(TODAY()),DAY(TODAY())) -> 46323 | D16: =((持仓数据!AQ$3/IF($D$6=1,持仓数据!$I$3,IF($D$6=2,持仓数据!$D$3,IF($D$6=4,持仓数据!$M$3,持仓数据!$F$3))))-1)*365/($C16-$D$5)*100 -> -0.72997647 | E16: =((持仓数据!AR$3/IF($D$6=1,持仓数据!$I$3,IF($D$6=2,持仓数据!$D$3,IF($D$6=4,持仓数据!$M$3,持仓数据!$F$3))))-1)*365/($C16-$D$5)*100 -> -0.54009833 | F16: =((持仓数据!AS$3/IF($D$6=1,持仓数据!$I$3,IF($D$6=2,持仓数据!$D$3,IF($D$6=4,持仓数据!$M$3,持仓数据!$F$3))))-1)*365/($C16-$D$5)*100 -> -0.3497013 | G16: =((持仓数据!AT$3/IF($D$6=1,持仓数据!$I$3,IF($D$6=2,持仓数据!$D$3,IF($D$6=4,持仓数据!$M$3,持仓数据!$F$3))))-1)*365/($C16-$D$5)*100 -> 0.032656165 | H16: =((持仓数据!AU$3/IF($D$6=1,持仓数据!$I$3,IF($D$6=2,持仓数据!$D$3,IF($D$6=4,持仓数据!$M$3,持仓数据!$F$3))))-1)*365/($C16-$D$5)*100 -> 0.41710952 | I16: =((持仓数据!AV$3/IF($D$6=1,持仓数据!$I$3,IF($D$6=2,持仓数据!$D$3,IF($D$6=4,持仓数据!$M$3,持仓数据!$F$3))))-1)*365/($C16-$D$5)*100 -> 0.61012643 | J16: =((持仓数据!AW$3/IF($D$6=1,持仓数据!$I$3,IF($D$6=2,持仓数据!$D$3,IF($D$6=4,持仓数据!$M$3,持仓数据!$F$3))))-1)*365/($C16-$D$5)*100 -> 0.80367246
B18: 持有期损益
B19: 持仓总额 | D19: =IF(持仓数据!H3=0,持仓数据!B3*100,持仓数据!H3) -> 300
B20: 单位:万元 | D20: =D10 -> 20 | E20: =E10 -> 15 | F20: =F10 -> 10 | G20: =G10 -> 0 | H20: =H10 -> -10 | I20: =I10 -> -15 | J20: =J10 -> -20
D21: BP | E21: BP | F21: BP | G21: BP | H21: BP | I21: BP | J21: BP
B22: =B12 -> 1W | C22: =C12 -> 45965 | D22: =(持仓数据!O$3-IF($D$6=1,持仓数据!$I$3,IF($D$6=2,持仓数据!$D$3,IF($D$6=4,持仓数据!$M$3,持仓数据!$F$3)))) -> 0.98840798 | E22: =(持仓数据!P$3-IF($D$6=1,持仓数据!$I$3,IF($D$6=2,持仓数据!$D$3,IF($D$6=4,持仓数据!$M$3,持仓数据!$F$3)))) -> 1.7320452 | F22: =(持仓数据!Q$3-IF($D$6=1,持仓数据!$I$3,IF($D$6=2,持仓数据!$D$3,IF($D$6=4,持仓数据!$M$3,持仓数据!$F$3)))) -> 2.4780075 | G22: =(持仓数据!R$3-IF($D$6=1,持仓数据!$I$3,IF($D$6=2,持仓数据!$D$3,IF($D$6=4,持仓数据!$M$3,持仓数据!$F$3)))) -> 3.9769413 | H22: =(持仓数据!S$3-IF($D$6=1,持仓数据!$I$3,IF($D$6=2,持仓数据!$D$3,IF($D$6=4,持仓数据!$M$3,持仓数据!$F$3)))) -> 5.4852782 | I22: =(持仓数据!T$3-IF($D$6=1,持仓数据!$I$3,IF($D$6=2,持仓数据!$D$3,IF($D$6=4,持仓数据!$M$3,持仓数据!$F$3)))) -> 6.2429944 | J22: =(持仓数据!U$3-IF($D$6=1,持仓数据!$I$3,IF($D$6=2,持仓数据!$D$3,IF($D$6=4,持仓数据!$M$3,持仓数据!$F$3)))) -> 7.0030874
B23: =B13 -> 1M | C23: =C13 -> 45989 | D23: =(持仓数据!V$3-IF($D$6=1,持仓数据!$I$3,IF($D$6=2,持仓数据!$D$3,IF($D$6=4,持仓数据!$M$3,持仓数据!$F$3)))) -> 0.76952368 | E23: =(持仓数据!W$3-IF($D$6=1,持仓数据!$I$3,IF($D$6=2,持仓数据!$D$3,IF($D$6=4,持仓数据!$M$3,持仓数据!$F$3)))) -> 1.5037578 | F23: =(持仓数据!X$3-IF($D$6=1,持仓数据!$I$3,IF($D$6=2,持仓数据!$D$3,IF($D$6=4,持仓数据!$M$3,持仓数据!$F$3)))) -> 2.2402678 | G23: =(持仓数据!Y$3-IF($D$6=1,持仓数据!$I$3,IF($D$6=2,持仓数据!$D$3,IF($D$6=4,持仓数据!$M$3,持仓数据!$F$3)))) -> 3.7201482 | H23: =(持仓数据!Z$3-IF($D$6=1,持仓数据!$I$3,IF($D$6=2,持仓数据!$D$3,IF($D$6=4,持仓数据!$M$3,持仓数据!$F$3)))) -> 5.2092318 | I23: =(持仓数据!AA$3-IF($D$6=1,持仓数据!$I$3,IF($D$6=2,持仓数据!$D$3,IF($D$6=4,持仓数据!$M$3,持仓数据!$F$3)))) -> 5.9572457 | J23: =(持仓数据!AB$3-IF($D$6=1,持仓数据!$I$3,IF($D$6=2,持仓数据!$D$3,IF($D$6=4,持仓数据!$M$3,持仓数据!$F$3)))) -> 6.7075857
B24: =B14 -> 3M | C24: =C14 -> 46050 | D24: =(持仓数据!AC$3-IF($D$6=1,持仓数据!$I$3,IF($D$6=2,持仓数据!$D$3,IF($D$6=4,持仓数据!$M$3,持仓数据!$F$3)))) -> 0.21084406 | E24: =(持仓数据!AD$3-IF($D$6=1,持仓数据!$I$3,IF($D$6=2,持仓数据!$D$3,IF($D$6=4,持仓数据!$M$3,持仓数据!$F$3)))) -> 0.92110106 | F24: =(持仓数据!AE$3-IF($D$6=1,持仓数据!$I$3,IF($D$6=2,持仓数据!$D$3,IF($D$6=4,持仓数据!$M$3,持仓数据!$F$3)))) -> 1.6335108 | G24: =(持仓数据!AF$3-IF($D$6=1,持仓数据!$I$3,IF($D$6=2,持仓数据!$D$3,IF($D$6=4,持仓数据!$M$3,持仓数据!$F$3)))) -> 3.0648192 | H24: =(持仓数据!AG$3-IF($D$6=1,持仓数据!$I$3,IF($D$6=2,持仓数据!$D$3,IF($D$6=4,持仓数据!$M$3,持仓数据!$F$3)))) -> 4.5048313 | I24: =(持仓数据!AH$3-IF($D$6=1,持仓数据!$I$3,IF($D$6=2,持仓数据!$D$3,IF($D$6=4,持仓数据!$M$3,持仓数据!$F$3)))) -> 5.2281207 | J24: =(持仓数据!AI$3-IF($D$6=1,持仓数据!$I$3,IF($D$6=2,持仓数据!$D$3,IF($D$6=4,持仓数据!$M$3,持仓数据!$F$3)))) -> 5.9536094
B25: =B15 -> 6M | C25: =C15 -> 46140 | D25: =(持仓数据!AJ$3-IF($D$6=1,持仓数据!$I$3,IF($D$6=2,持仓数据!$D$3,IF($D$6=4,持仓数据!$M$3,持仓数据!$F$3)))) -> 0.21084406 | E25: =(持仓数据!AK$3-IF($D$6=1,持仓数据!$I$3,IF($D$6=2,持仓数据!$D$3,IF($D$6=4,持仓数据!$M$3,持仓数据!$F$3)))) -> 0.92110106 | F25: =(持仓数据!AL$3-IF($D$6=1,持仓数据!$I$3,IF($D$6=2,持仓数据!$D$3,IF($D$6=4,持仓数据!$M$3,持仓数据!$F$3)))) -> 1.6335108 | G25: =(持仓数据!AM$3-IF($D$6=1,持仓数据!$I$3,IF($D$6=2,持仓数据!$D$3,IF($D$6=4,持仓数据!$M$3,持仓数据!$F$3)))) -> 3.0648192 | H25: =(持仓数据!AN$3-IF($D$6=1,持仓数据!$I$3,IF($D$6=2,持仓数据!$D$3,IF($D$6=4,持仓数据!$M$3,持仓数据!$F$3)))) -> 4.5048313 | I25: =(持仓数据!AO$3-IF($D$6=1,持仓数据!$I$3,IF($D$6=2,持仓数据!$D$3,IF($D$6=4,持仓数据!$M$3,持仓数据!$F$3)))) -> 5.2281207 | J25: =(持仓数据!AP$3-IF($D$6=1,持仓数据!$I$3,IF($D$6=2,持仓数据!$D$3,IF($D$6=4,持仓数据!$M$3,持仓数据!$F$3)))) -> 5.9536094
B26: =B16 -> 1Y | C26: =C16 -> 46323 | D26: =(持仓数据!AQ$3-IF($D$6=1,持仓数据!$I$3,IF($D$6=2,持仓数据!$D$3,IF($D$6=4,持仓数据!$M$3,持仓数据!$F$3)))) -> -2.3189087 | E26: =(持仓数据!AR$3-IF($D$6=1,持仓数据!$I$3,IF($D$6=2,持仓数据!$D$3,IF($D$6=4,持仓数据!$M$3,持仓数据!$F$3)))) -> -1.7157248 | F26: =(持仓数据!AS$3-IF($D$6=1,持仓数据!$I$3,IF($D$6=2,持仓数据!$D$3,IF($D$6=4,持仓数据!$M$3,持仓数据!$F$3)))) -> -1.1108925 | G26: =(持仓数据!AT$3-IF($D$6=1,持仓数据!$I$3,IF($D$6=2,持仓数据!$D$3,IF($D$6=4,持仓数据!$M$3,持仓数据!$F$3)))) -> 0.1037385 | H26: =(持仓数据!AU$3-IF($D$6=1,持仓数据!$I$3,IF($D$6=2,持仓数据!$D$3,IF($D$6=4,持仓数据!$M$3,持仓数据!$F$3)))) -> 1.3250275 | I26: =(持仓数据!AV$3-IF($D$6=1,持仓数据!$I$3,IF($D$6=2,持仓数据!$D$3,IF($D$6=4,持仓数据!$M$3,持仓数据!$F$3)))) -> 1.9381823 | J26: =(持仓数据!AW$3-IF($D$6=1,持仓数据!$I$3,IF($D$6=2,持仓数据!$D$3,IF($D$6=4,持仓数据!$M$3,持仓数据!$F$3)))) -> 2.553018

Sheet 持仓数据
O1: =情景分析!C12 -> 45965 | V1: =情景分析!C13 -> 45989 | AC1: =[3]情景分析!C14 -> 46050 | AJ1: =情景分析!C14 -> 46050 | AQ1: =情景分析!C16 -> 46323
B2: 活跃城投债 | C2: 交易场所 | D2: 前日加权均价/YTM | F2: 自定义输入 | H2: 持仓(百万) | I2: 中债估价/YTM | K2: 中证估价/YTM | M2: 混合估值/YTM | O2: =[3]情景分析!D10 -> 20 | P2: =[3]情景分析!E10 -> 15 | Q2: =[3]情景分析!F10 -> 10 | R2: =[3]情景分析!G10 -> 0 | S2: =[3]情景分析!H10 -> -10 | T2: =[3]情景分析!I10 -> -15 | U2: =[3]情景分析!J10 -> -20 | V2: =O2 -> 20 | W2: =P2 -> 15 | X2: =Q2 -> 10 | Y2: =R2 -> 0 | Z2: =S2 -> -10 | AA2: =T2 -> -15 | AB2: =U2 -> -20 | AC2: =O2 -> 20 | AD2: =P2 -> 15 | AE2: =Q2 -> 10 | AF2: =R2 -> 0 | AG2: =S2 -> -10 | AH2: =T2 -> -15 | AI2: =U2 -> -20 | AJ2: =O2 -> 20 | AK2: =P2 -> 15 | AL2: =Q2 -> 10 | AM2: =R2 -> 0 | AN2: =S2 -> -10 | AO2: =T2 -> -15 | AP2: =U2 -> -20 | AQ2: =O2 -> 20 | AR2: =P2 -> 15 | AS2: =Q2 -> 10 | AT2: =R2 -> 0 | AU2: =S2 -> -10 | AV2: =T2 -> -15 | AW2: =U2 -> -20
B3: =COUNTA(A:A) -> 3 | D3: =SUM(D4:OFFSET(D4,$B$3,0)) -> 212.9216 | E3: =AVERAGE(E4:E24) -> 1.2013667 | F3: =SUM(F4:OFFSET(F4,$B$3,0)) -> 0 | G3: 输入YTM | H3: =SUM(H4:OFFSET(H4,$B$3,0)) -> 0 | I3: =SUM(I4:OFFSET(I4,$B$3,0)) -> 314.2254 | J3: =AVERAGE(J4:J24) -> 1.8084667 | K3: =SUM(K4:OFFSET(K4,$B$3,0)) -> 314.2072 | L3: =AVERAGE(L4:L24) -> 1.8073333 | M3: =SUM(M4:OFFSET(M4,$B$3,0)) -> 314.232 | N3: =AVERAGE(N4:N24) -> 1.8073333 | O3: =SUM(O4:OFFSET(O4,$B$3,0)) -> 315.21381 | P3: =SUM(P4:OFFSET(P4,$B$3,0)) -> 315.95745 | Q3: =SUM(Q4:OFFSET(Q4,$B$3,0)) -> 316.70341 | R3: =SUM(R4:OFFSET(R4,$B$3,0)) -> 318.20234 | S3: =SUM(S4:OFFSET(S4,$B$3,0)) -> 319.71068 | T3: =SUM(T4:OFFSET(T4,$B$3,0)) -> 320.46839 | U3: =SUM(U4:OFFSET(U4,$B$3,0)) -> 321.22849 | V3: =SUM(V4:OFFSET(V4,$B$3,0)) -> 314.99492 | ... AW3: =SUM(AW4:OFFSET(AW4,$B$3,0)) -> 316.77842
A4: 220010.IB | B4: =IF(A4="","",[2]!b_info_name(A4)) -> 22附息国债10 | C4: =[2]!b_info_listedmkt(A4) -> 银行间 | D4: =IFERROR(IF(A4="","", [2]!b_dq_avgprice(A4, 情景分析!$D$5, 情景分析!$D$7) * IF($H4="",1,$H4)),0) -> 106.5166 | E4: =IF(A4="","", N([2]!b_dq_avgprice(A4,情景分析!$D$5,3))) -> 1.7052 | F4: =IF($G4 = "", "", IFERROR( [2]!b_calc_pv(A4, 情景分析!$D$5,$G4, "1", 情景分析!$D$7), [2]!b_calc_pv(A4, 情景分析!$D$5,$G4, "2", 情景分析!$D$7) ) ) | I4: =IF(A4="","",IF(情景分析!$D$7=1,[2]!b_anal_net_cnbd(A4,情景分析!$D$5,1),[2]!b_anal_dirty_cnbd(A4,情景分析!$D$5,1))*IF($H4="",1,$H4)) -> 106.4947 | J4: =IF(A4="","",[2]!b_anal_yield_cnbd(A4,情景分析!$D$5,1)) -> 1.71 | K4: =IF(A4="","",IF(情景分析!$D$7=1,[2]!b_anal_net_csi1(A4,情景分析!$D$5,1),[2]!b_anal_dirty_csi1(A4,情景分析!$D$5,1))*IF($H4="",1,$H4)) -> 106.4778 | L4: =IF(A4="","",[2]!b_anal_yield_csi1(A4,情景分析!$D$5,1)) -> 1.71 | M4: =IF($C4="银行间",$I4,$K4) -> 106.4947 | N4: =IF($C4="银行间",$J4,$L4) -> 1.71 | O4: =IF($A4="","",[2]!B_CALC_PRICE($A4,$O$1,IF(情景分析!$D$6=1,$J4,IF(情景分析!$D$6=2,$E4,IF(情景分析!$D$6=4,IF($C4="银行间",$J4,$L4),$G4)))+O$2/100,情景分析!$D$7,"",,,,"",)*IF($H4="",1,$H4)) -> 105.19461 | P4: =IF($A4="","",[2]!B_CALC_PRICE($A4,$O$1,IF(情景分析!$D$6=1,$J4,IF(情景分析!$D$6=2,$E4,IF(情景分析!$D$6=4,IF($C4="银行间",$J4,$L4),$G4)))+P$2/100,情景分析!$D$7,"",,,,"",)*IF($H4="",1,$H4)) -> 105.50961 | Q4: =IF($A4="","",[2]!B_CALC_PRICE($A4,$O$1,IF(情景分析!$D$6=1,$J4,IF(情景分析!$D$6=2,$E4,IF(情景分析!$D$6=4,IF($C4="银行间",$J4,$L4),$G4)))+Q$2/100,情景分析!$D$7,"",,,,"",)*IF($H4="",1,$H4)) -> 105.82568 | R4: =IF($A4="","",[2]!B_CALC_PRICE($A4,$O$1,IF(情景分析!$D$6=1,$J4,IF(情景分析!$D$6=2,$E4,IF(情景分析!$D$6=4,IF($C4="银行间",$J4,$L4),$G4)))+R$2/100,情景分析!$D$7,"",,,,"",)*IF($H4="",1,$H4)) -> 106.46105 | S4: =IF($A4="","",[2]!B_CALC_PRICE($A4,$O$1,IF(情景分析!$D$6=1,$J4,IF(情景分析!$D$6=2,$E4,IF(情景分析!$D$6=4,IF($C4="银行间",$J4,$L4),$G4)))+S$2/100,情景分析!$D$7,"",,,,"",)*IF($H4="",1,$H4)) -> 107.10074 | T4: =IF($A4="","",[2]!B_CALC_PRICE($A4,$O$1,IF(情景分析!$D$6=1,$J4,IF(情景分析!$D$6=2,$E4,IF(情景分析!$D$6=4,IF($C4="银行间",$J4,$L4),$G4)))+T$2/100,情景分析!$D$7,"",,,,"",)*IF($H4="",1,$H4)) -> 107.42221 | U4: =IF($A4="","",[2]!B_CALC_PRICE($A4,$O$1,IF(情景分析!$D$6=1,$J4,IF(情景分析!$D$6=2,$E4,IF(情景分析!$D$6=4,IF($C4="银行间",$J4,$L4),$G4)))+U$2/100,情景分析!$D$7,"",,,,"",)*IF($H4="",1,$H4)) -> 107.74478 | V4: =IF($A4="","",[2]!B_CALC_PRICE($A4,$V$1,IF(情景分析!$D$6=1,$J4,IF(情景分析!$D$6=2,$E4,IF(情景分析!$D$6=4,IF($C4="银行间",$J4,$L4),$G4)))+V$2/100,情景分析!$D$7,"",,,,"",)*IF($H4="",1,$H4)) -> 105.14534 | W4: =IF($A4="","",[2]!B_CALC_PRICE($A4,$V$1,IF(情景分析!$D$6=1,$J4,IF(情景分析!$D$6=2,$E4,IF(情景分析!$D$6=4,IF($C4="银行间",$J4,$L4),$G4)))+W$2/100,情景分析!$D$7,"",,,,"",)*IF($H4="",1,$H4)) -> 105.45728 | X4: =IF($A4="","",[2]!B_CALC_PRICE($A4,$V$1,IF(情景分析!$D$6=1,$J4,IF(情景分析!$D$6=2,$E4,IF(情景分析!$D$6=4,IF($C4="银行间",$J4,$L4),$G4)))+X$2/100,情景分析!$D$7,"",,,,"",)*IF($H4="",1,$H4)) -> 105.77026 | Y4: =IF($A4="","",[2]!B_CALC_PRICE($A4,$V$1,IF(情景分析!$D$6=1,$J4,IF(情景分析!$D$6=2,$E4,IF(情景分析!$D$6=4,IF($C4="银行间",$J4,$L4),$G4)))+Y$2/100,情景分析!$D$7,"",,,,"",)*IF($H4="",1,$H4)) -> 106.39939 | Z4: =IF($A4="","",[2]!B_CALC_PRICE($A4,$V$1,IF(情景分析!$D$6=1,$J4,IF(情景分析!$D$6=2,$E4,IF(情景分析!$D$6=4,IF($C4="银行间",$J4,$L4),$G4)))+Z$2/100,情景分析!$D$7,"",,,,"",)*IF($H4="",1,$H4)) -> 107.03277 | AA4: =IF($A4="","",[2]!B_CALC_PRICE($A4,$V$1,IF(情景分析!$D$6=1,$J4,IF(情景分析!$D$6=2,$E4,IF(情景分析!$D$6=4,IF($C4="银行间",$J4,$L4),$G4)))+AA$2/100,情景分析!$D$7,"",,,,"",)*IF($H4="",1,$H4)) -> 107.35105 | AB4: =IF($A4="","",[2]!B_CALC_PRICE($A4,$V$1,IF(情景分析!$D$6=1,$J4,IF(情景分析!$D$6=2,$E4,IF(情景分析!$D$6=4,IF($C4="银行间",$J4,$L4),$G4)))+AB$2/100,情景分析!$D$7,"",,,,"",)*IF($H4="",1,$H4)) -> 107.67041 | AC4: =IF($A4="","",[2]!B_CALC_PRICE($A4,$AC$1,IF(情景分析!$D$6=1,$J4,IF(情景分析!$D$6=2,$E4,IF(情景分析!$D$6=4,IF($C4="银行间",$J4,$L4),$G4)))+AC$2/100,情景分析!$D$7,"",,,,"",)*IF($H4="",1,$H4)) -> 105.01792 | AD4: =IF($A4="","",[2]!B_CALC_PRICE($A4,$AC$1,IF(情景分析!$D$6=1,$J4,IF(情景分析!$D$6=2,$E4,IF(情景分析!$D$6=4,IF($C4="银行间",$J4,$L4),$G4)))+AD$2/100,情景分析!$D$7,"",,,,"",)*IF($H4="",1,$H4)) -> 105.32202 | AE4: =IF($A4="","",[2]!B_CALC_PRICE($A4,$AC$1,IF(情景分析!$D$6=1,$J4,IF(情景分析!$D$6=2,$E4,IF(情景分析!$D$6=4,IF($C4="银行间",$J4,$L4),$G4)))+AE$2/100,情景分析!$D$7,"",,,,"",)*IF($H4="",1,$H4)) -> 105.62712 | AF4: =IF($A4="","",[2]!B_CALC_PRICE($A4,$AC$1,IF(情景分析!$D$6=1,$J4,IF(情景分析!$D$6=2,$E4,IF(情景分析!$D$6=4,IF($C4="银行间",$J4,$L4),$G4)))+AF$2/100,情景分析!$D$7,"",,,,"",)*IF($H4="",1,$H4)) -> 106.24032 | AG4: =IF($A4="","",[2]!B_CALC_PRICE($A4,$AC$1,IF(情景分析!$D$6=1,$J4,IF(情景分析!$D$6=2,$E4,IF(情景分析!$D$6=4,IF($C4="银行间",$J4,$L4),$G4)))+AG$2/100,情景分析!$D$7,"",,,,"",)*IF($H4="",1,$H4)) -> 106.85756 | AH4: =IF($A4="","",[2]!B_CALC_PRICE($A4,$AC$1,IF(情景分析!$D$6=1,$J4,IF(情景分析!$D$6=2,$E4,IF(情景分析!$D$6=4,IF($C4="银行间",$J4,$L4),$G4)))+AH$2/100,情景分析!$D$7,"",,,,"",)*IF($H4="",1,$H4)) -> 107.1677 | AI4: =IF($A4="","",[2]!B_CALC_PRICE($A4,$AC$1,IF(情景分析!$D$6=1,$J4,IF(情景分析!$D$6=2,$E4,IF(情景分析!$D$6=4,IF($C4="银行间",$J4,$L4),$G4)))+AI$2/100,情景分析!$D$7,"",,,,"",)*IF($H4="",1,$H4)) -> 107.47887 | AJ4: =IF($A4="","",[2]!B_CALC_PRICE($A4,$AJ$1,IF(情景分析!$D$6=1,$J4,IF(情景分析!$D$6=2,$E4,IF(情景分析!$D$6=4,IF($C4="银行间",$J4,$L4),$G4)))+AJ$2/100,情景分析!$D$7,"",,,,"",)*IF($H4="",1,$H4)) -> 105.01792 | AK4: =IF($A4="","",[2]!B_CALC_PRICE($A4,$AJ$1,IF(情景分析!$D$6=1,$J4,IF(情景分析!$D$6=2,$E4,IF(情景分析!$D$6=4,IF($C4="银行间",$J4,$L4),$G4)))+AK$2/100,情景分析!$D$7,"",,,,"",)*IF($H4="",1,$H4)) -> 105.32202 | AL4: =IF($A4="","",[2]!B_CALC_PRICE($A4,$AJ$1,IF(情景分析!$D$6=1,$J4,IF(情景分析!$D$6=2,$E4,IF(情景分析!$D$6=4,IF($C4="银行间",$J4,$L4),$G4)))+AL$2/100,情景分析!$D$7,"",,,,"",)*IF($H4="",1,$H4)) -> 105.62712 | AM4: =IF($A4="","",[2]!B_CALC_PRICE($A4,$AJ$1,IF(情景分析!$D$6=1,$J4,IF(情景分析!$D$6=2,$E4,IF(情景分析!$D$6=4,IF($C4="银行间",$J4,$L4),$G4)))+AM$2/100,情景分析!$D$7,"",,,,"",)*IF($H4="",1,$H4)) -> 106.24032 | AN4: =IF($A4="","",[2]!B_CALC_PRICE($A4,$AJ$1,IF(情景分析!$D$6=1,$J4,IF(情景分析!$D$6=2,$E4,IF(情景分析!$D$6=4,IF($C4="银行间",$J4,$L4),$G4)))+AN$2/100,情景分析!$D$7,"",,,,"",)*IF($H4="",1,$H4)) -> 106.85756 | AO4: =IF($A4="","",[2]!B_CALC_PRICE($A4,$AJ$1,IF(情景分析!$D$6=1,$J4,IF(情景分析!$D$6=2,$E4,IF(情景分析!$D$6=4,IF($C4="银行间",$J4,$L4),$G4)))+AO$2/100,情景分析!$D$7,"",,,,"",)*IF($H4="",1,$H4)) -> 107.1677 | AP4: =IF($A4="","",[2]!B_CALC_PRICE($A4,$AJ$1,IF(情景分析!$D$6=1,$J4,IF(情景分析!$D$6=2,$E4,IF(情景分析!$D$6=4,IF($C4="银行间",$J4,$L4),$G4)))+AP$2/100,情景分析!$D$7,"",,,,"",)*IF($H4="",1,$H4)) -> 107.47887 | AQ4: =IF($A4="","",[2]!B_CALC_PRICE($A4,$AQ$1,IF(情景分析!$D$6=1,$J4,IF(情景分析!$D$6=2,$E4,IF(情景分析!$D$6=4,IF($C4="银行间",$J4,$L4),$G4)))+AQ$2/100,情景分析!$D$7,"",,,,"",)*IF($H4="",1,$H4)) -> 104.45452 | AR4: =IF($A4="","",[2]!B_CALC_PRICE($A4,$AQ$1,IF(情景分析!$D$6=1,$J4,IF(情景分析!$D$6=2,$E4,IF(情景分析!$D$6=4,IF($C4="银行间",$J4,$L4),$G4)))+AR$2/100,情景分析!$D$7,"",,,,"",)*IF($H4="",1,$H4)) -> 104.72356 | AS4: =IF($A4="","",[2]!B_CALC_PRICE($A4,$AQ$1,IF(情景分析!$D$6=1,$J4,IF(情景分析!$D$6=2,$E4,IF(情景分析!$D$6=4,IF($C4="银行间",$J4,$L4),$G4)))+AS$2/100,情景分析!$D$7,"",,,,"",)*IF($H4="",1,$H4)) -> 104.99339 | AT4: =IF($A4="","",[2]!B_CALC_PRICE($A4,$AQ$1,IF(情景分析!$D$6=1,$J4,IF(情景分析!$D$6=2,$E4,IF(情景分析!$D$6=4,IF($C4="银行间",$J4,$L4),$G4)))+AT$2/100,情景分析!$D$7,"",,,,"",)*IF($H4="",1,$H4)) -> 105.53543 | AU4: =IF($A4="","",[2]!B_CALC_PRICE($A4,$AQ$1,IF(情景分析!$D$6=1,$J4,IF(情景分析!$D$6=2,$E4,IF(情景分析!$D$6=4,IF($C4="银行间",$J4,$L4),$G4)))+AU$2/100,情景分析!$D$7,"",,,,"",)*IF($H4="",1,$H4)) -> 106.08065 | AV4: =IF($A4="","",[2]!B_CALC_PRICE($A4,$AQ$1,IF(情景分析!$D$6=1,$J4,IF(情景分析!$D$6=2,$E4,IF(情景分析!$D$6=4,IF($C4="银行间",$J4,$L4),$G4)))+AV$2/100,情景分析!$D$7,"",,,,"",)*IF($H4="",1,$H4)) -> 106.35447 | AW4: =IF($A4="","",[2]!B_CALC_PRICE($A4,$AQ$1,IF(情景分析!$D$6=1,$J4,IF(情景分析!$D$6=2,$E4,IF(情景分析!$D$6=4,IF($C4="银行间",$J4,$L4),$G4)))+AW$2/100,情景分析!$D$7,"",,,,"",)*IF($H4="",1,$H4)) -> 106.62908
A5: 220205.IB | B5: =IF(A5="","",[2]!b_info_name(A5)) -> 22国开05 | C5: =[2]!b_info_listedmkt(A5) -> 银行间 | D5: =IFERROR(IF(A5="","", [2]!b_dq_avgprice(A5, 情景分析!$D$5, 情景分析!$D$7) * IF($H5="",1,$H5)),0) -> 106.405 | E5: =IF(A5="","", N([2]!b_dq_avgprice(A5,情景分析!$D$5,3))) -> 1.8989 | F5: =IF($G5 = "", "", IFERROR( [2]!b_calc_pv(A5, 情景分析!$D$5,$G5, "1", 情景分析!$D$7), [2]!b_calc_pv(A5, 情景分析!$D$5,$G5, "2", 情景分析!$D$7) ) ) | I5: =IF(A5="","",IF(情景分析!$D$7=1,[2]!b_anal_net_cnbd(A5,情景分析!$D$5,1),[2]!b_anal_dirty_cnbd(A5,情景分析!$D$5,1))*IF($H5="",1,$H5)) -> 106.3914 | J5: =IF(A5="","",[2]!b_anal_yield_cnbd(A5,情景分析!$D$5,1)) -> 1.902 | K5: =IF(A5="","",IF(情景分析!$D$7=1,[2]!b_anal_net_csi1(A5,情景分析!$D$5,1),[2]!b_anal_dirty_csi1(A5,情景分析!$D$5,1))*IF($H5="",1,$H5)) -> 106.3835 | L5: =IF(A5="","",[2]!b_anal_yield_csi1(A5,情景分析!$D$5,1)) -> 1.902 | M5: =IF($C5="银行间",$I5,$K5) -> 106.3914 | N5: =IF($C5="银行间",$J5,$L5) -> 1.902 | O5: =IF($A5="","",[2]!B_CALC_PRICE($A5,$O$1,IF(情景分析!$D$6=1,$J5,IF(情景分析!$D$6=2,$E5,IF(情景分析!$D$6=4,IF($C5="银行间",$J5,$L5),$G5)))+O$2/100,情景分析!$D$7,"",,,,"",)*IF($H5="",1,$H5)) -> 105.16646 | P5: =IF($A5="","",[2]!B_CALC_PRICE($A5,$O$1,IF(情景分析!$D$6=1,$J5,IF(情景分析!$D$6=2,$E5,IF(情景分析!$D$6=4,IF($C5="银行间",$J5,$L5),$G5)))+P$2/100,情景分析!$D$7,"",,,,"",)*IF($H5="",1,$H5)) -> 105.46399 | Q5: =IF($A5="","",[2]!B_CALC_PRICE($A5,$O$1,IF(情景分析!$D$6=1,$J5,IF(情景分析!$D$6=2,$E5,IF(情景分析!$D$6=4,IF($C5="银行间",$J5,$L5),$G5)))+Q$2/100,情景分析!$D$7,"",,,,"",)*IF($H5="",1,$H5)) -> 105.76255 | R5: =IF($A5="","",[2]!B_CALC_PRICE($A5,$O$1,IF(情景分析!$D$6=1,$J5,IF(情景分析!$D$6=2,$E5,IF(情景分析!$D$6=4,IF($C5="银行间",$J5,$L5),$G5)))+R$2/100,情景分析!$D$7,"",,,,"",)*IF($H5="",1,$H5)) -> 106.36276 | S5: =IF($A5="","",[2]!B_CALC_PRICE($A5,$O$1,IF(情景分析!$D$6=1,$J5,IF(情景分析!$D$6=2,$E5,IF(情景分析!$D$6=4,IF($C5="银行间",$J5,$L5),$G5)))+S$2/100,情景分析!$D$7,"",,,,"",)*IF($H5="",1,$H5)) -> 106.96712 | T5: =IF($A5="","",[2]!B_CALC_PRICE($A5,$O$1,IF(情景分析!$D$6=1,$J5,IF(情景分析!$D$6=2,$E5,IF(情景分析!$D$6=4,IF($C5="银行间",$J5,$L5),$G5)))+T$2/100,情景分析!$D$7,"",,,,"",)*IF($H5="",1,$H5)) -> 107.27086 | U5: =IF($A5="","",[2]!B_CALC_PRICE($A5,$O$1,IF(情景分析!$D$6=1,$J5,IF(情景分析!$D$6=2,$E5,IF(情景分析!$D$6=4,IF($C5="银行间",$J5,$L5),$G5)))+U$2/100,情景分析!$D$7,"",,,,"",)*IF($H5="",1,$H5)) -> 107.57566 | V5: =IF($A5="","",[2]!B_CALC_PRICE($A5,$V$1,IF(情景分析!$D$6=1,$J5,IF(情景分析!$D$6=2,$E5,IF(情景分析!$D$6=4,IF($C5="银行间",$J5,$L5),$G5)))+V$2/100,情景分析!$D$7,"",,,,"",)*IF($H5="",1,$H5)) -> 105.11642 | W5: =IF($A5="","",[2]!B_CALC_PRICE($A5,$V$1,IF(情景分析!$D$6=1,$J5,IF(情景分析!$D$6=2,$E5,IF(情景分析!$D$6=4,IF($C5="银行间",$J5,$L5),$G5)))+W$2/100,情景分析!$D$7,"",,,,"",)*IF($H5="",1,$H5)) -> 105.41088 | X5: =IF($A5="","",[2]!B_CALC_PRICE($A5,$V$1,IF(情景分析!$D$6=1,$J5,IF(情景分析!$D$6=2,$E5,IF(情景分析!$D$6=4,IF($C5="银行间",$J5,$L5),$G5)))+X$2/100,情景分析!$D$7,"",,,,"",)*IF($H5="",1,$H5)) -> 105.70635 | Y5: =IF($A5="","",[2]!B_CALC_PRICE($A5,$V$1,IF(情景分析!$D$6=1,$J5,IF(情景分析!$D$6=2,$E5,IF(情景分析!$D$6=4,IF($C5="银行间",$J5,$L5),$G5)))+Y$2/100,情景分析!$D$7,"",,,,"",)*IF($H5="",1,$H5)) -> 106.30032 | Z5: =IF($A5="","",[2]!B_CALC_PRICE($A5,$V$1,IF(情景分析!$D$6=1,$J5,IF(情景分析!$D$6=2,$E5,IF(情景分析!$D$6=4,IF($C5="银行间",$J5,$L5),$G5)))+Z$2/100,情景分析!$D$7,"",,,,"",)*IF($H5="",1,$H5)) -> 106.89835 | AA5: =IF($A5="","",[2]!B_CALC_PRICE($A5,$V$1,IF(情景分析!$D$6=1,$J5,IF(情景分析!$D$6=2,$E5,IF(情景分析!$D$6=4,IF($C5="银行间",$J5,$L5),$G5)))+AA$2/100,情景分析!$D$7,"",,,,"",)*IF($H5="",1,$H5)) -> 107.19891 | AB5: =IF($A5="","",[2]!B_CALC_PRICE($A5,$V$1,IF(情景分析!$D$6=1,$J5,IF(情景分析!$D$6=2,$E5,IF(情景分析!$D$6=4,IF($C5="银行间",$J5,$L5),$G5)))+AB$2/100,情景分析!$D$7,"",,,,"",)*IF($H5="",1,$H5)) -> 107.5005 | AC5: =IF($A5="","",[2]!B_CALC_PRICE($A5,$AC$1,IF(情景分析!$D$6=1,$J5,IF(情景分析!$D$6=2,$E5,IF(情景分析!$D$6=4,IF($C5="银行间",$J5,$L5),$G5)))+AC$2/100,情景分析!$D$7,"",,,,"",)*IF($H5="",1,$H5)) -> 104.98826 | AD5: =IF($A5="","",[2]!B_CALC_PRICE($A5,$AC$1,IF(情景分析!$D$6=1,$J5,IF(情景分析!$D$6=2,$E5,IF(情景分析!$D$6=4,IF($C5="银行间",$J5,$L5),$G5)))+AD$2/100,情景分析!$D$7,"",,,,"",)*IF($H5="",1,$H5)) -> 105.27492 | AE5: =IF($A5="","",[2]!B_CALC_PRICE($A5,$AC$1,IF(情景分析!$D$6=1,$J5,IF(情景分析!$D$6=2,$E5,IF(情景分析!$D$6=4,IF($C5="银行间",$J5,$L5),$G5)))+AE$2/100,情景分析!$D$7,"",,,,"",)*IF($H5="",1,$H5)) -> 105.56254 | AF5: =IF($A5="","",[2]!B_CALC_PRICE($A5,$AC$1,IF(情景分析!$D$6=1,$J5,IF(情景分析!$D$6=2,$E5,IF(情景分析!$D$6=4,IF($C5="银行间",$J5,$L5),$G5)))+AF$2/100,情景分析!$D$7,"",,,,"",)*IF($H5="",1,$H5)) -> 106.14066 | AG5: =IF($A5="","",[2]!B_CALC_PRICE($A5,$AC$1,IF(情景分析!$D$6=1,$J5,IF(情景分析!$D$6=2,$E5,IF(情景分析!$D$6=4,IF($C5="银行间",$J5,$L5),$G5)))+AG$2/100,情景分析!$D$7,"",,,,"",)*IF($H5="",1,$H5)) -> 106.72265 | AH5: =IF($A5="","",[2]!B_CALC_PRICE($A5,$AC$1,IF(情景分析!$D$6=1,$J5,IF(情景分析!$D$6=2,$E5,IF(情景分析!$D$6=4,IF($C5="银行间",$J5,$L5),$G5)))+AH$2/100,情景分析!$D$7,"",,,,"",)*IF($H5="",1,$H5)) -> 107.01511 | AI5: =IF($A5="","",[2]!B_CALC_PRICE($A5,$AC$1,IF(情景分析!$D$6=1,$J5,IF(情景分析!$D$6=2,$E5,IF(情景分析!$D$6=4,IF($C5="银行间",$J5,$L5),$G5)))+AI$2/100,情景分析!$D$7,"",,,,"",)*IF($H5="",1,$H5)) -> 107.30855 | AJ5: =IF($A5="","",[2]!B_CALC_PRICE($A5,$AJ$1,IF(情景分析!$D$6=1,$J5,IF(情景分析!$D$6=2,$E5,IF(情景分析!$D$6=4,IF($C5="银行间",$J5,$L5),$G5)))+AJ$2/100,情景分析!$D$7,"",,,,"",)*IF($H5="",1,$H5)) -> 104.98826 | AK5: =IF($A5="","",[2]!B_CALC_PRICE($A5,$AJ$1,IF(情景分析!$D$6=1,$J5,IF(情景分析!$D$6=2,$E5,IF(情景分析!$D$6=4,IF($C5="银行间",$J5,$L5),$G5)))+AK$2/100,情景分析!$D$7,"",,,,"",)*IF($H5="",1,$H5)) -> 105.27492 | AL5: =IF($A5="","",[2]!B_CALC_PRICE($A5,$AJ$1,IF(情景分析!$D$6=1,$J5,IF(情景分析!$D$6=2,$E5,IF(情景分析!$D$6=4,IF($C5="银行间",$J5,$L5),$G5)))+AL$2/100,情景分析!$D$7,"",,,,"",)*IF($H5="",1,$H5)) -> 105.56254 | AM5: =IF($A5="","",[2]!B_CALC_PRICE($A5,$AJ$1,IF(情景分析!$D$6=1,$J5,IF(情景分析!$D$6=2,$E5,IF(情景分析!$D$6=4,IF($C5="银行间",$J5,$L5),$G5)))+AM$2/100,情景分析!$D$7,"",,,,"",)*IF($H5="",1,$H5)) -> 106.14066 | AN5: =IF($A5="","",[2]!B_CALC_PRICE($A5,$AJ$1,IF(情景分析!$D$6=1,$J5,IF(情景分析!$D$6=2,$E5,IF(情景分析!$D$6=4,IF($C5="银行间",$J5,$L5),$G5)))+AN$2/100,情景分析!$D$7,"",,,,"",)*IF($H5="",1,$H5)) -> 106.72265 | AO5: =IF($A5="","",[2]!B_CALC_PRICE($A5,$AJ$1,IF(情景分析!$D$6=1,$J5,IF(情景分析!$D$6=2,$E5,IF(情景分析!$D$6=4,IF($C5="银行间",$J5,$L5),$G5)))+AO$2/100,情景分析!$D$7,"",,,,"",)*IF($H5="",1,$H5)) -> 107.01511 | AP5: =IF($A5="","",[2]!B_CALC_PRICE($A5,$AJ$1,IF(情景分析!$D$6=1,$J5,IF(情景分析!$D$6=2,$E5,IF(情景分析!$D$6=4,IF($C5="银行间",$J5,$L5),$G5)))+AP$2/100,情景分析!$D$7,"",,,,"",)*IF($H5="",1,$H5)) -> 107.30855 | AQ5: =IF($A5="","",[2]!B_CALC_PRICE($A5,$AQ$1,IF(情景分析!$D$6=1,$J5,IF(情景分析!$D$6=2,$E5,IF(情景分析!$D$6=4,IF($C5="银行间",$J5,$L5),$G5)))+AQ$2/100,情景分析!$D$7,"",,,,"",)*IF($H5="",1,$H5)) -> 104.39211 | AR5: =IF($A5="","",[2]!B_CALC_PRICE($A5,$AQ$1,IF(情景分析!$D$6=1,$J5,IF(情景分析!$D$6=2,$E5,IF(情景分析!$D$6=4,IF($C5="银行间",$J5,$L5),$G5)))+AR$2/100,情景分析!$D$7,"",,,,"",)*IF($H5="",1,$H5)) -> 104.64407 | AS5: =IF($A5="","",[2]!B_CALC_PRICE($A5,$AQ$1,IF(情景分析!$D$6=1,$J5,IF(情景分析!$D$6=2,$E5,IF(情景分析!$D$6=4,IF($C5="银行间",$J5,$L5),$G5)))+AS$2/100,情景分析!$D$7,"",,,,"",)*IF($H5="",1,$H5)) -> 104.89677 | AT5: =IF($A5="","",[2]!B_CALC_PRICE($A5,$AQ$1,IF(情景分析!$D$6=1,$J5,IF(情景分析!$D$6=2,$E5,IF(情景分析!$D$6=4,IF($C5="银行间",$J5,$L5),$G5)))+AT$2/100,情景分析!$D$7,"",,,,"",)*IF($H5="",1,$H5)) -> 105.40446 | AU5: =IF($A5="","",[2]!B_CALC_PRICE($A5,$AQ$1,IF(情景分析!$D$6=1,$J5,IF(情景分析!$D$6=2,$E5,IF(情景分析!$D$6=4,IF($C5="银行间",$J5,$L5),$G5)))+AU$2/100,情景分析!$D$7,"",,,,"",)*IF($H5="",1,$H5)) -> 105.91519 | AV5: =IF($A5="","",[2]!B_CALC_PRICE($A5,$AQ$1,IF(情景分析!$D$6=1,$J5,IF(情景分析!$D$6=2,$E5,IF(情景分析!$D$6=4,IF($C5="银行间",$J5,$L5),$G5)))+AV$2/100,情景分析!$D$7,"",,,,"",)*IF($H5="",1,$H5)) -> 106.17171 | AW5: =IF($A5="","",[2]!B_CALC_PRICE($A5,$AQ$1,IF(情景分析!$D$6=1,$J5,IF(情景分析!$D$6=2,$E5,IF(情景分析!$D$6=4,IF($C5="银行间",$J5,$L5),$G5)))+AW$2/100,情景分析!$D$7,"",,,,"",)*IF($H5="",1,$H5)) -> 106.42899
A6: 251245.SH | B6: =IF(A6="","",[2]!b_info_name(A6)) -> 23津港01 | C6: =[2]!b_info_listedmkt(A6) -> 上海 | D6: =IFERROR(IF(A6="","", [2]!b_dq_avgprice(A6, 情景分析!$D$5, 情景分析!$D$7) * IF($H6="",1,$H6)),0) -> 0 | E6: =IF(A6="","", N([2]!b_dq_avgprice(A6,情景分析!$D$5,3))) -> 0 | F6: =IF($G6 = "", "", IFERROR( [2]!b_calc_pv(A6, 情景分析!$D$5,$G6, "1", 情景分析!$D$7), [2]!b_calc_pv(A6, 情景分析!$D$5,$G6, "2", 情景分析!$D$7) ) ) | I6: =IF(A6="","",IF(情景分析!$D$7=1,[2]!b_anal_net_cnbd(A6,情景分析!$D$5,1),[2]!b_anal_dirty_cnbd(A6,情景分析!$D$5,1))*IF($H6="",1,$H6)) -> 101.3393 | J6: =IF(A6="","",[2]!b_anal_yield_cnbd(A6,情景分析!$D$5,1)) -> 1.8134 | K6: =IF(A6="","",IF(情景分析!$D$7=1,[2]!b_anal_net_csi1(A6,情景分析!$D$5,1),[2]!b_anal_dirty_csi1(A6,情景分析!$D$5,1))*IF($H6="",1,$H6)) -> 101.3459 | L6: =IF(A6="","",[2]!b_anal_yield_csi1(A6,情景分析!$D$5,1)) -> 1.81 | M6: =IF($C6="银行间",$I6,$K6) -> 101.3459 | N6: =IF($C6="银行间",$J6,$L6) -> 1.81 | O6: =IF($A6="","",[2]!B_CALC_PRICE($A6,$O$1,IF(情景分析!$D$6=1,$J6,IF(情景分析!$D$6=2,$E6,IF(情景分析!$D$6=4,IF($C6="银行间",$J6,$L6),$G6)))+O$2/100,情景分析!$D$7,"",,,,"",)*IF($H6="",1,$H6)) -> 104.85274 | P6: =IF($A6="","",[2]!B_CALC_PRICE($A6,$O$1,IF(情景分析!$D$6=1,$J6,IF(情景分析!$D$6=2,$E6,IF(情景分析!$D$6=4,IF($C6="银行间",$J6,$L6),$G6)))+P$2/100,情景分析!$D$7,"",,,,"",)*IF($H6="",1,$H6)) -> 104.98384 | Q6: =IF($A6="","",[2]!B_CALC_PRICE($A6,$O$1,IF(情景分析!$D$6=1,$J6,IF(情景分析!$D$6=2,$E6,IF(情景分析!$D$6=4,IF($C6="银行间",$J6,$L6),$G6)))+Q$2/100,情景分析!$D$7,"",,,,"",)*IF($H6="",1,$H6)) -> 105.11518 | R6: =IF($A6="","",[2]!B_CALC_PRICE($A6,$O$1,IF(情景分析!$D$6=1,$J6,IF(情景分析!$D$6=2,$E6,IF(情景分析!$D$6=4,IF($C6="银行间",$J6,$L6),$G6)))+R$2/100,情景分析!$D$7,"",,,,"",)*IF($H6="",1,$H6)) -> 105.37854 | S6: =IF($A6="","",[2]!B_CALC_PRICE($A6,$O$1,IF(情景分析!$D$6=1,$J6,IF(情景分析!$D$6=2,$E6,IF(情景分析!$D$6=4,IF($C6="银行间",$J6,$L6),$G6)))+S$2/100,情景分析!$D$7,"",,,,"",)*IF($H6="",1,$H6)) -> 105.64283 | T6: =IF($A6="","",[2]!B_CALC_PRICE($A6,$O$1,IF(情景分析!$D$6=1,$J6,IF(情景分析!$D$6=2,$E6,IF(情景分析!$D$6=4,IF($C6="银行间",$J6,$L6),$G6)))+T$2/100,情景分析!$D$7,"",,,,"",)*IF($H6="",1,$H6)) -> 105.77532 | U6: =IF($A6="","",[2]!B_CALC_PRICE($A6,$O$1,IF(情景分析!$D$6=1,$J6,IF(情景分析!$D$6=2,$E6,IF(情景分析!$D$6=4,IF($C6="银行间",$J6,$L6),$G6)))+U$2/100,情景分析!$D$7,"",,,,"",)*IF($H6="",1,$H6)) -> 105.90805 | V6: =IF($A6="","",[2]!B_CALC_PRICE($A6,$V$1,IF(情景分析!$D$6=1,$J6,IF(情景分析!$D$6=2,$E6,IF(情景分析!$D$6=4,IF($C6="银行间",$J6,$L6),$G6)))+V$2/100,情景分析!$D$7,"",,,,"",)*IF($H6="",1,$H6)) -> 104.73316 | W6: =IF($A6="","",[2]!B_CALC_PRICE($A6,$V$1,IF(情景分析!$D$6=1,$J6,IF(情景分析!$D$6=2,$E6,IF(情景分析!$D$6=4,IF($C6="银行间",$J6,$L6),$G6)))+W$2/100,情景分析!$D$7,"",,,,"",)*IF($H6="",1,$H6)) -> 104.861 | X6: =IF($A6="","",[2]!B_CALC_PRICE($A6,$V$1,IF(情景分析!$D$6=1,$J6,IF(情景分析!$D$6=2,$E6,IF(情景分析!$D$6=4,IF($C6="银行间",$J6,$L6),$G6)))+X$2/100,情景分析!$D$7,"",,,,"",)*IF($H6="",1,$H6)) -> 104.98906 | Y6: =IF($A6="","",[2]!B_CALC_PRICE($A6,$V$1,IF(情景分析!$D$6=1,$J6,IF(情景分析!$D$6=2,$E6,IF(情景分析!$D$6=4,IF($C6="银行间",$J6,$L6),$G6)))+Y$2/100,情景分析!$D$7,"",,,,"",)*IF($H6="",1,$H6)) -> 105.24584 | Z6: =IF($A6="","",[2]!B_CALC_PRICE($A6,$V$1,IF(情景分析!$D$6=1,$J6,IF(情景分析!$D$6=2,$E6,IF(情景分析!$D$6=4,IF($C6="银行间",$J6,$L6),$G6)))+Z$2/100,情景分析!$D$7,"",,,,"",)*IF($H6="",1,$H6)) -> 105.50351 | AA6: =IF($A6="","",[2]!B_CALC_PRICE($A6,$V$1,IF(情景分析!$D$6=1,$J6,IF(情景分析!$D$6=2,$E6,IF(情景分析!$D$6=4,IF($C6="银行间",$J6,$L6),$G6)))+AA$2/100,情景分析!$D$7,"",,,,"",)*IF($H6="",1,$H6)) -> 105.63268 | AB6: =IF($A6="","",[2]!B_CALC_PRICE($A6,$V$1,IF(情景分析!$D$6=1,$J6,IF(情景分析!$D$6=2,$E6,IF(情景分析!$D$6=4,IF($C6="银行间",$J6,$L6),$G6)))+AB$2/100,情景分析!$D$7,"",,,,"",)*IF($H6="",1,$H6)) -> 105.76208 | AC6: =IF($A6="","",[2]!B_CALC_PRICE($A6,$AC$1,IF(情景分析!$D$6=1,$J6,IF(情景分析!$D$6=2,$E6,IF(情景分析!$D$6=4,IF($C6="银行间",$J6,$L6),$G6)))+AC$2/100,情景分析!$D$7,"",,,,"",)*IF($H6="",1,$H6)) -> 104.43006 | AD6: =IF($A6="","",[2]!B_CALC_PRICE($A6,$AC$1,IF(情景分析!$D$6=1,$J6,IF(情景分析!$D$6=2,$E6,IF(情景分析!$D$6=4,IF($C6="银行间",$J6,$L6),$G6)))+AD$2/100,情景分析!$D$7,"",,,,"",)*IF($H6="",1,$H6)) -> 104.54956 | AE6: =IF($A6="","",[2]!B_CALC_PRICE($A6,$AC$1,IF(情景分析!$D$6=1,$J6,IF(情景分析!$D$6=2,$E6,IF(情景分析!$D$6=4,IF($C6="银行间",$J6,$L6),$G6)))+AE$2/100,情景分析!$D$7,"",,,,"",)*IF($H6="",1,$H6)) -> 104.66926 | AF6: =IF($A6="","",[2]!B_CALC_PRICE($A6,$AC$1,IF(情景分析!$D$6=1,$J6,IF(情景分析!$D$6=2,$E6,IF(情景分析!$D$6=4,IF($C6="银行间",$J6,$L6),$G6)))+AF$2/100,情景分析!$D$7,"",,,,"",)*IF($H6="",1,$H6)) -> 104.90925 | AG6: =IF($A6="","",[2]!B_CALC_PRICE($A6,$AC$1,IF(情景分析!$D$6=1,$J6,IF(情景分析!$D$6=2,$E6,IF(情景分析!$D$6=4,IF($C6="银行间",$J6,$L6),$G6)))+AG$2/100,情景分析!$D$7,"",,,,"",)*IF($H6="",1,$H6)) -> 105.15002 | AH6: =IF($A6="","",[2]!B_CALC_PRICE($A6,$AC$1,IF(情景分析!$D$6=1,$J6,IF(情景分析!$D$6=2,$E6,IF(情景分析!$D$6=4,IF($C6="银行间",$J6,$L6),$G6)))+AH$2/100,情景分析!$D$7,"",,,,"",)*IF($H6="",1,$H6)) -> 105.27071 | AI6: =IF($A6="","",[2]!B_CALC_PRICE($A6,$AC$1,IF(情景分析!$D$6=1,$J6,IF(情景分析!$D$6=2,$E6,IF(情景分析!$D$6=4,IF($C6="银行间",$J6,$L6),$G6)))+AI$2/100,情景分析!$D$7,"",,,,"",)*IF($H6="",1,$H6)) -> 105.3916 | AJ6: =IF($A6="","",[2]!B_CALC_PRICE($A6,$AJ$1,IF(情景分析!$D$6=1,$J6,IF(情景分析!$D$6=2,$E6,IF(情景分析!$D$6=4,IF($C6="银行间",$J6,$L6),$G6)))+AJ$2/100,情景分析!$D$7,"",,,,"",)*IF($H6="",1,$H6)) -> 104.43006 | AK6: =IF($A6="","",[2]!B_CALC_PRICE($A6,$AJ$1,IF(情景分析!$D$6=1,$J6,IF(情景分析!$D$6=2,$E6,IF(情景分析!$D$6=4,IF($C6="银行间",$J6,$L6),$G6)))+AK$2/100,情景分析!$D$7,"",,,,"",)*IF($H6="",1,$H6)) -> 104.54956 | AL6: =IF($A6="","",[2]!B_CALC_PRICE($A6,$AJ$1,IF(情景分析!$D$6=1,$J6,IF(情景分析!$D$6=2,$E6,IF(情景分析!$D$6=4,IF($C6="银行间",$J6,$L6),$G6)))+AL$2/100,情景分析!$D$7,"",,,,"",)*IF($H6="",1,$H6)) -> 104.66926 | AM6: =IF($A6="","",[2]!B_CALC_PRICE($A6,$AJ$1,IF(情景分析!$D$6=1,$J6,IF(情景分析!$D$6=2,$E6,IF(情景分析!$D$6=4,IF($C6="银行间",$J6,$L6),$G6)))+AM$2/100,情景分析!$D$7,"",,,,"",)*IF($H6="",1,$H6)) -> 104.90925 | AN6: =IF($A6="","",[2]!B_CALC_PRICE($A6,$AJ$1,IF(情景分析!$D$6=1,$J6,IF(情景分析!$D$6=2,$E6,IF(情景分析!$D$6=4,IF($C6="银行间",$J6,$L6),$G6)))+AN$2/100,情景分析!$D$7,"",,,,"",)*IF($H6="",1,$H6)) -> 105.15002 | AO6: =IF($A6="","",[2]!B_CALC_PRICE($A6,$AJ$1,IF(情景分析!$D$6=1,$J6,IF(情景分析!$D$6=2,$E6,IF(情景分析!$D$6=4,IF($C6="银行间",$J6,$L6),$G6)))+AO$2/100,情景分析!$D$7,"",,,,"",)*IF($H6="",1,$H6)) -> 105.27071 | AP6: =IF($A6="","",[2]!B_CALC_PRICE($A6,$AJ$1,IF(情景分析!$D$6=1,$J6,IF(情景分析!$D$6=2,$E6,IF(情景分析!$D$6=4,IF($C6="银行间",$J6,$L6),$G6)))+AP$2/100,情景分析!$D$7,"",,,,"",)*IF($H6="",1,$H6)) -> 105.3916 | AQ6: =IF($A6="","",[2]!B_CALC_PRICE($A6,$AQ$1,IF(情景分析!$D$6=1,$J6,IF(情景分析!$D$6=2,$E6,IF(情景分析!$D$6=4,IF($C6="银行间",$J6,$L6),$G6)))+AQ$2/100,情景分析!$D$7,"",,,,"",)*IF($H6="",1,$H6)) -> 103.05986 | AR6: =IF($A6="","",[2]!B_CALC_PRICE($A6,$AQ$1,IF(情景分析!$D$6=1,$J6,IF(情景分析!$D$6=2,$E6,IF(情景分析!$D$6=4,IF($C6="银行间",$J6,$L6),$G6)))+AR$2/100,情景分析!$D$7,"",,,,"",)*IF($H6="",1,$H6)) -> 103.14205 | AS6: =IF($A6="","",[2]!B_CALC_PRICE($A6,$AQ$1,IF(情景分析!$D$6=1,$J6,IF(情景分析!$D$6=2,$E6,IF(情景分析!$D$6=4,IF($C6="银行间",$J6,$L6),$G6)))+AS$2/100,情景分析!$D$7,"",,,,"",)*IF($H6="",1,$H6)) -> 103.22434 | AT6: =IF($A6="","",[2]!B_CALC_PRICE($A6,$AQ$1,IF(情景分析!$D$6=1,$J6,IF(情景分析!$D$6=2,$E6,IF(情景分析!$D$6=4,IF($C6="银行间",$J6,$L6),$G6)))+AT$2/100,情景分析!$D$7,"",,,,"",)*IF($H6="",1,$H6)) -> 103.38925 | AU6: =IF($A6="","",[2]!B_CALC_PRICE($A6,$AQ$1,IF(情景分析!$D$6=1,$J6,IF(情景分析!$D$6=2,$E6,IF(情景分析!$D$6=4,IF($C6="银行间",$J6,$L6),$G6)))+AU$2/100,情景分析!$D$7,"",,,,"",)*IF($H6="",1,$H6)) -> 103.55458 | AV6: =IF($A6="","",[2]!B_CALC_PRICE($A6,$AQ$1,IF(情景分析!$D$6=1,$J6,IF(情景分析!$D$6=2,$E6,IF(情景分析!$D$6=4,IF($C6="银行间",$J6,$L6),$G6)))+AV$2/100,情景分析!$D$7,"",,,,"",)*IF($H6="",1,$H6)) -> 103.63741 | AW6: =IF($A6="","",[2]!B_CALC_PRICE($A6,$AQ$1,IF(情景分析!$D$6=1,$J6,IF(情景分析!$D$6=2,$E6,IF(情景分析!$D$6=4,IF($C6="银行间",$J6,$L6),$G6)))+AW$2/100,情景分析!$D$7,"",,,,"",)*IF($H6="",1,$H6)) -> 103.72034
B7: =IF(A7="","",[2]!b_info_name(A7)) | C7: =[2]!b_info_listedmkt(A7) -> #N/A | D7: =IFERROR(IF(A7="","", [2]!b_dq_avgprice(A7, 情景分析!$D$5, 情景分析!$D$7) * IF($H7="",1,$H7)),0) | E7: =IF(A7="","", N([2]!b_dq_avgprice(A7,情景分析!$D$5,3))) | F7: =IF($G7 = "", "", IFERROR( [2]!b_calc_pv(A7, 情景分析!$D$5,$G7, "1", 情景分析!$D$7), [2]!b_calc_pv(A7, 情景分析!$D$5,$G7, "2", 情景分析!$D$7) ) ) | I7: =IF(A7="","",IF(情景分析!$D$7=1,[2]!b_anal_net_cnbd(A7,情景分析!$D$5,1),[2]!b_anal_dirty_cnbd(A7,情景分析!$D$5,1))*IF($H7="",1,$H7)) | J7: =IF(A7="","",[2]!b_anal_yield_cnbd(A7,情景分析!$D$5,1)) | K7: =IF(A7="","",IF(情景分析!$D$7=1,[2]!b_anal_net_csi1(A7,情景分析!$D$5,1),[2]!b_anal_dirty_csi1(A7,情景分析!$D$5,1))*IF($H7="",1,$H7)) | L7: =IF(A7="","",[2]!b_anal_yield_csi1(A7,情景分析!$D$5,1)) | M7: =IF($C7="银行间",$I7,$K7) | N7: =IF($C7="银行间",$J7,$L7) | O7: =IF($A7="","",[2]!B_CALC_PRICE($A7,$O$1,IF(情景分析!$D$6=1,$J7,IF(情景分析!$D$6=2,$E7,IF(情景分析!$D$6=4,IF($C7="银行间",$J7,$L7),$G7)))+O$2/100,情景分析!$D$7,"",,,,"",)*IF($H7="",1,$H7)) | P7: =IF($A7="","",[2]!B_CALC_PRICE($A7,$O$1,IF(情景分析!$D$6=1,$J7,IF(情景分析!$D$6=2,$E7,IF(情景分析!$D$6=4,IF($C7="银行间",$J7,$L7),$G7)))+P$2/100,情景分析!$D$7,"",,,,"",)*IF($H7="",1,$H7)) | Q7: =IF($A7="","",[2]!B_CALC_PRICE($A7,$O$1,IF(情景分析!$D$6=1,$J7,IF(情景分析!$D$6=2,$E7,IF(情景分析!$D$6=4,IF($C7="银行间",$J7,$L7),$G7)))+Q$2/100,情景分析!$D$7,"",,,,"",)*IF($H7="",1,$H7)) | R7: =IF($A7="","",[2]!B_CALC_PRICE($A7,$O$1,IF(情景分析!$D$6=1,$J7,IF(情景分析!$D$6=2,$E7,IF(情景分析!$D$6=4,IF($C7="银行间",$J7,$L7),$G7)))+R$2/100,情景分析!$D$7,"",,,,"",)*IF($H7="",1,$H7)) | S7: =IF($A7="","",[2]!B_CALC_PRICE($A7,$O$1,IF(情景分析!$D$6=1,$J7,IF(情景分析!$D$6=2,$E7,IF(情景分析!$D$6=4,IF($C7="银行间",$J7,$L7),$G7)))+S$2/100,情景分析!$D$7,"",,,,"",)*IF($H7="",1,$H7)) | T7: =IF($A7="","",[2]!B_CALC_PRICE($A7,$O$1,IF(情景分析!$D$6=1,$J7,IF(情景分析!$D$6=2,$E7,IF(情景分析!$D$6=4,IF($C7="银行间",$J7,$L7),$G7)))+T$2/100,情景分析!$D$7,"",,,,"",)*IF($H7="",1,$H7)) | U7: =IF($A7="","",[2]!B_CALC_PRICE($A7,$O$1,IF(情景分析!$D$6=1,$J7,IF(情景分析!$D$6=2,$E7,IF(情景分析!$D$6=4,IF($C7="银行间",$J7,$L7),$G7)))+U$2/100,情景分析!$D$7,"",,,,"",)*IF($H7="",1,$H7)) | V7: =IF($A7="","",[2]!B_CALC_PRICE($A7,$V$1,IF(情景分析!$D$6=1,$J7,IF(情景分析!$D$6=2,$E7,IF(情景分析!$D$6=4,IF($C7="银行间",$J7,$L7),$G7)))+V$2/100,情景分析!$D$7,"",,,,"",)*IF($H7="",1,$H7)) | W7: =IF($A7="","",[2]!B_CALC_PRICE($A7,$V$1,IF(情景分析!$D$6=1,$J7,IF(情景分析!$D$6=2,$E7,IF(情景分析!$D$6=4,IF($C7="银行间",$J7,$L7),$G7)))+W$2/100,情景分析!$D$7,"",,,,"",)*IF($H7="",1,$H7)) | X7: =IF($A7="","",[2]!B_CALC_PRICE($A7,$V$1,IF(情景分析!$D$6=1,$J7,IF(情景分析!$D$6=2,$E7,IF(情景分析!$D$6=4,IF($C7="银行间",$J7,$L7),$G7)))+X$2/100,情景分析!$D$7,"",,,,"",)*IF($H7="",1,$H7)) | Y7: =IF($A7="","",[2]!B_CALC_PRICE($A7,$V$1,IF(情景分析!$D$6=1,$J7,IF(情景分析!$D$6=2,$E7,IF(情景分析!$D$6=4,IF($C7="银行间",$J7,$L7),$G7)))+Y$2/100,情景分析!$D$7,"",,,,"",)*IF($H7="",1,$H7)) | Z7: =IF($A7="","",[2]!B_CALC_PRICE($A7,$V$1,IF(情景分析!$D$6=1,$J7,IF(情景分析!$D$6=2,$E7,IF(情景分析!$D$6=4,IF($C7="银行间",$J7,$L7),$G7)))+Z$2/100,情景分析!$D$7,"",,,,"",)*IF($H7="",1,$H7)) | AA7: =IF($A7="","",[2]!B_CALC_PRICE($A7,$V$1,IF(情景分析!$D$6=1,$J7,IF(情景分析!$D$6=2,$E7,IF(情景分析!$D$6=4,IF($C7="银行间",$J7,$L7),$G7)))+AA$2/100,情景分析!$D$7,"",,,,"",)*IF($H7="",1,$H7)) | AB7: =IF($A7="","",[2]!B_CALC_PRICE($A7,$V$1,IF(情景分析!$D$6=1,$J7,IF(情景分析!$D$6=2,$E7,IF(情景分析!$D$6=4,IF($C7="银行间",$J7,$L7),$G7)))+AB$2/100,情景分析!$D$7,"",,,,"",)*IF($H7="",1,$H7)) | AC7: =IF($A7="","",[2]!B_CALC_PRICE($A7,$AC$1,IF(情景分析!$D$6=1,$J7,IF(情景分析!$D$6=2,$E7,IF(情景分析!$D$6=4,IF($C7="银行间",$J7,$L7),$G7)))+AC$2/100,情景分析!$D$7,"",,,,"",)*IF($H7="",1,$H7)) | AD7: =IF($A7="","",[2]!B_CALC_PRICE($A7,$AC$1,IF(情景分析!$D$6=1,$J7,IF(情景分析!$D$6=2,$E7,IF(情景分析!$D$6=4,IF($C7="银行间",$J7,$L7),$G7)))+AD$2/100,情景分析!$D$7,"",,,,"",)*IF($H7="",1,$H7)) | AE7: =IF($A7="","",[2]!B_CALC_PRICE($A7,$AC$1,IF(情景分析!$D$6=1,$J7,IF(情景分析!$D$6=2,$E7,IF(情景分析!$D$6=4,IF($C7="银行间",$J7,$L7),$G7)))+AE$2/100,情景分析!$D$7,"",,,,"",)*IF($H7="",1,$H7)) | AF7: =IF($A7="","",[2]!B_CALC_PRICE($A7,$AC$1,IF(情景分析!$D$6=1,$J7,IF(情景分析!$D$6=2,$E7,IF(情景分析!$D$6=4,IF($C7="银行间",$J7,$L7),$G7)))+AF$2/100,情景分析!$D$7,"",,,,"",)*IF($H7="",1,$H7)) | AG7: =IF($A7="","",[2]!B_CALC_PRICE($A7,$AC$1,IF(情景分析!$D$6=1,$J7,IF(情景分析!$D$6=2,$E7,IF(情景分析!$D$6=4,IF($C7="银行间",$J7,$L7),$G7)))+AG$2/100,情景分析!$D$7,"",,,,"",)*IF($H7="",1,$H7)) | AH7: =IF($A7="","",[2]!B_CALC_PRICE($A7,$AC$1,IF(情景分析!$D$6=1,$J7,IF(情景分析!$D$6=2,$E7,IF(情景分析!$D$6=4,IF($C7="银行间",$J7,$L7),$G7)))+AH$2/100,情景分析!$D$7,"",,,,"",)*IF($H7="",1,$H7)) | AI7: =IF($A7="","",[2]!B_CALC_PRICE($A7,$AC$1,IF(情景分析!$D$6=1,$J7,IF(情景分析!$D$6=2,$E7,IF(情景分析!$D$6=4,IF($C7="银行间",$J7,$L7),$G7)))+AI$2/100,情景分析!$D$7,"",,,,"",)*IF($H7="",1,$H7)) | AJ7: =IF($A7="","",[2]!B_CALC_PRICE($A7,$AJ$1,IF(情景分析!$D$6=1,$J7,IF(情景分析!$D$6=2,$E7,IF(情景分析!$D$6=4,IF($C7="银行间",$J7,$L7),$G7)))+AJ$2/100,情景分析!$D$7,"",,,,"",)*IF($H7="",1,$H7)) | AK7: =IF($A7="","",[2]!B_CALC_PRICE($A7,$AJ$1,IF(情景分析!$D$6=1,$J7,IF(情景分析!$D$6=2,$E7,IF(情景分析!$D$6=4,IF($C7="银行间",$J7,$L7),$G7)))+AK$2/100,情景分析!$D$7,"",,,,"",)*IF($H7="",1,$H7)) | AL7: =IF($A7="","",[2]!B_CALC_PRICE($A7,$AJ$1,IF(情景分析!$D$6=1,$J7,IF(情景分析!$D$6=2,$E7,IF(情景分析!$D$6=4,IF($C7="银行间",$J7,$L7),$G7)))+AL$2/100,情景分析!$D$7,"",,,,"",)*IF($H7="",1,$H7)) | AM7: =IF($A7="","",[2]!B_CALC_PRICE($A7,$AJ$1,IF(情景分析!$D$6=1,$J7,IF(情景分析!$D$6=2,$E7,IF(情景分析!$D$6=4,IF($C7="银行间",$J7,$L7),$G7)))+AM$2/100,情景分析!$D$7,"",,,,"",)*IF($H7="",1,$H7)) | AN7: =IF($A7="","",[2]!B_CALC_PRICE($A7,$AJ$1,IF(情景分析!$D$6=1,$J7,IF(情景分析!$D$6=2,$E7,IF(情景分析!$D$6=4,IF($C7="银行间",$J7,$L7),$G7)))+AN$2/100,情景分析!$D$7,"",,,,"",)*IF($H7="",1,$H7)) | AO7: =IF($A7="","",[2]!B_CALC_PRICE($A7,$AJ$1,IF(情景分析!$D$6=1,$J7,IF(情景分析!$D$6=2,$E7,IF(情景分析!$D$6=4,IF($C7="银行间",$J7,$L7),$G7)))+AO$2/100,情景分析!$D$7,"",,,,"",)*IF($H7="",1,$H7)) | AP7: =IF($A7="","",[2]!B_CALC_PRICE($A7,$AJ$1,IF(情景分析!$D$6=1,$J7,IF(情景分析!$D$6=2,$E7,IF(情景分析!$D$6=4,IF($C7="银行间",$J7,$L7),$G7)))+AP$2/100,情景分析!$D$7,"",,,,"",)*IF($H7="",1,$H7)) | AQ7: =IF($A7="","",[2]!B_CALC_PRICE($A7,$AQ$1,IF(情景分析!$D$6=1,$J7,IF(情景分析!$D$6=2,$E7,IF(情景分析!$D$6=4,IF($C7="银行间",$J7,$L7),$G7)))+AQ$2/100,情景分析!$D$7,"",,,,"",)*IF($H7="",1,$H7)) | AR7: =IF($A7="","",[2]!B_CALC_PRICE($A7,$AQ$1,IF(情景分析!$D$6=1,$J7,IF(情景分析!$D$6=2,$E7,IF(情景分析!$D$6=4,IF($C7="银行间",$J7,$L7),$G7)))+AR$2/100,情景分析!$D$7,"",,,,"",)*IF($H7="",1,$H7)) | AS7: =IF($A7="","",[2]!B_CALC_PRICE($A7,$AQ$1,IF(情景分析!$D$6=1,$J7,IF(情景分析!$D$6=2,$E7,IF(情景分析!$D$6=4,IF($C7="银行间",$J7,$L7),$G7)))+AS$2/100,情景分析!$D$7,"",,,,"",)*IF($H7="",1,$H7)) | AT7: =IF($A7="","",[2]!B_CALC_PRICE($A7,$AQ$1,IF(情景分析!$D$6=1,$J7,IF(情景分析!$D$6=2,$E7,IF(情景分析!$D$6=4,IF($C7="银行间",$J7,$L7),$G7)))+AT$2/100,情景分析!$D$7,"",,,,"",)*IF($H7="",1,$H7)) | AU7: =IF($A7="","",[2]!B_CALC_PRICE($A7,$AQ$1,IF(情景分析!$D$6=1,$J7,IF(情景分析!$D$6=2,$E7,IF(情景分析!$D$6=4,IF($C7="银行间",$J7,$L7),$G7)))+AU$2/100,情景分析!$D$7,"",,,,"",)*IF($H7="",1,$H7)) | AV7: =IF($A7="","",[2]!B_CALC_PRICE($A7,$AQ$1,IF(情景分析!$D$6=1,$J7,IF(情景分析!$D$6=2,$E7,IF(情景分析!$D$6=4,IF($C7="银行间",$J7,$L7),$G7)))+AV$2/100,情景分析!$D$7,"",,,,"",)*IF($H7="",1,$H7)) | AW7: =IF($A7="","",[2]!B_CALC_PRICE($A7,$AQ$1,IF(情景分析!$D$6=1,$J7,IF(情景分析!$D$6=2,$E7,IF(情景分析!$D$6=4,IF($C7="银行间",$J7,$L7),$G7)))+AW$2/100,情景分析!$D$7,"",,,,"",)*IF($H7="",1,$H7))
B8: =IF(A8="","",[2]!b_info_name(A8)) | C8: =[2]!b_info_listedmkt(A8) -> #N/A | D8: =IFERROR(IF(A8="","", [2]!b_dq_avgprice(A8, 情景分析!$D$5, 情景分析!$D$7) * IF($H8="",1,$H8)),0) | E8: =IF(A8="","", N([2]!b_dq_avgprice(A8,情景分析!$D$5,3))) | F8: =IF($G8 = "", "", IFERROR( [2]!b_calc_pv(A8, 情景分析!$D$5,$G8, "1", 情景分析!$D$7), [2]!b_calc_pv(A8, 情景分析!$D$5,$G8, "2", 情景分析!$D$7) ) ) | I8: =IF(A8="","",IF(情景分析!$D$7=1,[2]!b_anal_net_cnbd(A8,情景分析!$D$5,1),[2]!b_anal_dirty_cnbd(A8,情景分析!$D$5,1))*IF($H8="",1,$H8)) | J8: =IF(A8="","",[2]!b_anal_yield_cnbd(A8,情景分析!$D$5,1)) | K8: =IF(A8="","",IF(情景分析!$D$7=1,[2]!b_anal_net_csi1(A8,情景分析!$D$5,1),[2]!b_anal_dirty_csi1(A8,情景分析!$D$5,1))*IF($H8="",1,$H8)) | L8: =IF(A8="","",[2]!b_anal_yield_csi1(A8,情景分析!$D$5,1)) | M8: =IF($C8="银行间",$I8,$K8) | N8: =IF($C8="银行间",$J8,$L8) | O8: =IF($A8="","",[2]!B_CALC_PRICE($A8,$O$1,IF(情景分析!$D$6=1,$J8,IF(情景分析!$D$6=2,$E8,IF(情景分析!$D$6=4,IF($C8="银行间",$J8,$L8),$G8)))+O$2/100,情景分析!$D$7,"",,,,"",)*IF($H8="",1,$H8)) | P8: =IF($A8="","",[2]!B_CALC_PRICE($A8,$O$1,IF(情景分析!$D$6=1,$J8,IF(情景分析!$D$6=2,$E8,IF(情景分析!$D$6=4,IF($C8="银行间",$J8,$L8),$G8)))+P$2/100,情景分析!$D$7,"",,,,"",)*IF($H8="",1,$H8)) | Q8: =IF($A8="","",[2]!B_CALC_PRICE($A8,$O$1,IF(情景分析!$D$6=1,$J8,IF(情景分析!$D$6=2,$E8,IF(情景分析!$D$6=4,IF($C8="银行间",$J8,$L8),$G8)))+Q$2/100,情景分析!$D$7,"",,,,"",)*IF($H8="",1,$H8)) | R8: =IF($A8="","",[2]!B_CALC_PRICE($A8,$O$1,IF(情景分析!$D$6=1,$J8,IF(情景分析!$D$6=2,$E8,IF(情景分析!$D$6=4,IF($C8="银行间",$J8,$L8),$G8)))+R$2/100,情景分析!$D$7,"",,,,"",)*IF($H8="",1,$H8)) | S8: =IF($A8="","",[2]!B_CALC_PRICE($A8,$O$1,IF(情景分析!$D$6=1,$J8,IF(情景分析!$D$6=2,$E8,IF(情景分析!$D$6=4,IF($C8="银行间",$J8,$L8),$G8)))+S$2/100,情景分析!$D$7,"",,,,"",)*IF($H8="",1,$H8)) | T8: =IF($A8="","",[2]!B_CALC_PRICE($A8,$O$1,IF(情景分析!$D$6=1,$J8,IF(情景分析!$D$6=2,$E8,IF(情景分析!$D$6=4,IF($C8="银行间",$J8,$L8),$G8)))+T$2/100,情景分析!$D$7,"",,,,"",)*IF($H8="",1,$H8)) | U8: =IF($A8="","",[2]!B_CALC_PRICE($A8,$O$1,IF(情景分析!$D$6=1,$J8,IF(情景分析!$D$6=2,$E8,IF(情景分析!$D$6=4,IF($C8="银行间",$J8,$L8),$G8)))+U$2/100,情景分析!$D$7,"",,,,"",)*IF($H8="",1,$H8)) | V8: =IF($A8="","",[2]!B_CALC_PRICE($A8,$V$1,IF(情景分析!$D$6=1,$J8,IF(情景分析!$D$6=2,$E8,IF(情景分析!$D$6=4,IF($C8="银行间",$J8,$L8),$G8)))+V$2/100,情景分析!$D$7,"",,,,"",)*IF($H8="",1,$H8)) | W8: =IF($A8="","",[2]!B_CALC_PRICE($A8,$V$1,IF(情景分析!$D$6=1,$J8,IF(情景分析!$D$6=2,$E8,IF(情景分析!$D$6=4,IF($C8="银行间",$J8,$L8),$G8)))+W$2/100,情景分析!$D$7,"",,,,"",)*IF($H8="",1,$H8)) | X8: =IF($A8="","",[2]!B_CALC_PRICE($A8,$V$1,IF(情景分析!$D$6=1,$J8,IF(情景分析!$D$6=2,$E8,IF(情景分析!$D$6=4,IF($C8="银行间",$J8,$L8),$G8)))+X$2/100,情景分析!$D$7,"",,,,"",)*IF($H8="",1,$H8)) | Y8: =IF($A8="","",[2]!B_CALC_PRICE($A8,$V$1,IF(情景分析!$D$6=1,$J8,IF(情景分析!$D$6=2,$E8,IF(情景分析!$D$6=4,IF($C8="银行间",$J8,$L8),$G8)))+Y$2/100,情景分析!$D$7,"",,,,"",)*IF($H8="",1,$H8)) | Z8: =IF($A8="","",[2]!B_CALC_PRICE($A8,$V$1,IF(情景分析!$D$6=1,$J8,IF(情景分析!$D$6=2,$E8,IF(情景分析!$D$6=4,IF($C8="银行间",$J8,$L8),$G8)))+Z$2/100,情景分析!$D$7,"",,,,"",)*IF($H8="",1,$H8)) | AA8: =IF($A8="","",[2]!B_CALC_PRICE($A8,$V$1,IF(情景分析!$D$6=1,$J8,IF(情景分析!$D$6=2,$E8,IF(情景分析!$D$6=4,IF($C8="银行间",$J8,$L8),$G8)))+AA$2/100,情景分析!$D$7,"",,,,"",)*IF($H8="",1,$H8)) | AB8: =IF($A8="","",[2]!B_CALC_PRICE($A8,$V$1,IF(情景分析!$D$6=1,$J8,IF(情景分析!$D$6=2,$E8,IF(情景分析!$D$6=4,IF($C8="银行间",$J8,$L8),$G8)))+AB$2/100,情景分析!$D$7,"",,,,"",)*IF($H8="",1,$H8)) | AC8: =IF($A8="","",[2]!B_CALC_PRICE($A8,$AC$1,IF(情景分析!$D$6=1,$J8,IF(情景分析!$D$6=2,$E8,IF(情景分析!$D$6=4,IF($C8="银行间",$J8,$L8),$G8)))+AC$2/100,情景分析!$D$7,"",,,,"",)*IF($H8="",1,$H8)) | AD8: =IF($A8="","",[2]!B_CALC_PRICE($A8,$AC$1,IF(情景分析!$D$6=1,$J8,IF(情景分析!$D$6=2,$E8,IF(情景分析!$D$6=4,IF($C8="银行间",$J8,$L8),$G8)))+AD$2/100,情景分析!$D$7,"",,,,"",)*IF($H8="",1,$H8)) | AE8: =IF($A8="","",[2]!B_CALC_PRICE($A8,$AC$1,IF(情景分析!$D$6=1,$J8,IF(情景分析!$D$6=2,$E8,IF(情景分析!$D$6=4,IF($C8="银行间",$J8,$L8),$G8)))+AE$2/100,情景分析!$D$7,"",,,,"",)*IF($H8="",1,$H8)) | AF8: =IF($A8="","",[2]!B_CALC_PRICE($A8,$AC$1,IF(情景分析!$D$6=1,$J8,IF(情景分析!$D$6=2,$E8,IF(情景分析!$D$6=4,IF($C8="银行间",$J8,$L8),$G8)))+AF$2/100,情景分析!$D$7,"",,,,"",)*IF($H8="",1,$H8)) | AG8: =IF($A8="","",[2]!B_CALC_PRICE($A8,$AC$1,IF(情景分析!$D$6=1,$J8,IF(情景分析!$D$6=2,$E8,IF(情景分析!$D$6=4,IF($C8="银行间",$J8,$L8),$G8)))+AG$2/100,情景分析!$D$7,"",,,,"",)*IF($H8="",1,$H8)) | AH8: =IF($A8="","",[2]!B_CALC_PRICE($A8,$AC$1,IF(情景分析!$D$6=1,$J8,IF(情景分析!$D$6=2,$E8,IF(情景分析!$D$6=4,IF($C8="银行间",$J8,$L8),$G8)))+AH$2/100,情景分析!$D$7,"",,,,"",)*IF($H8="",1,$H8)) | AI8: =IF($A8="","",[2]!B_CALC_PRICE($A8,$AC$1,IF(情景分析!$D$6=1,$J8,IF(情景分析!$D$6=2,$E8,IF(情景分析!$D$6=4,IF($C8="银行间",$J8,$L8),$G8)))+AI$2/100,情景分析!$D$7,"",,,,"",)*IF($H8="",1,$H8)) | AJ8: =IF($A8="","",[2]!B_CALC_PRICE($A8,$AJ$1,IF(情景分析!$D$6=1,$J8,IF(情景分析!$D$6=2,$E8,IF(情景分析!$D$6=4,IF($C8="银行间",$J8,$L8),$G8)))+AJ$2/100,情景分析!$D$7,"",,,,"",)*IF($H8="",1,$H8)) | AK8: =IF($A8="","",[2]!B_CALC_PRICE($A8,$AJ$1,IF(情景分析!$D$6=1,$J8,IF(情景分析!$D$6=2,$E8,IF(情景分析!$D$6=4,IF($C8="银行间",$J8,$L8),$G8)))+AK$2/100,情景分析!$D$7,"",,,,"",)*IF($H8="",1,$H8)) | AL8: =IF($A8="","",[2]!B_CALC_PRICE($A8,$AJ$1,IF(情景分析!$D$6=1,$J8,IF(情景分析!$D$6=2,$E8,IF(情景分析!$D$6=4,IF($C8="银行间",$J8,$L8),$G8)))+AL$2/100,情景分析!$D$7,"",,,,"",)*IF($H8="",1,$H8)) | AM8: =IF($A8="","",[2]!B_CALC_PRICE($A8,$AJ$1,IF(情景分析!$D$6=1,$J8,IF(情景分析!$D$6=2,$E8,IF(情景分析!$D$6=4,IF($C8="银行间",$J8,$L8),$G8)))+AM$2/100,情景分析!$D$7,"",,,,"",)*IF($H8="",1,$H8)) | AN8: =IF($A8="","",[2]!B_CALC_PRICE($A8,$AJ$1,IF(情景分析!$D$6=1,$J8,IF(情景分析!$D$6=2,$E8,IF(情景分析!$D$6=4,IF($C8="银行间",$J8,$L8),$G8)))+AN$2/100,情景分析!$D$7,"",,,,"",)*IF($H8="",1,$H8)) | AO8: =IF($A8="","",[2]!B_CALC_PRICE($A8,$AJ$1,IF(情景分析!$D$6=1,$J8,IF(情景分析!$D$6=2,$E8,IF(情景分析!$D$6=4,IF($C8="银行间",$J8,$L8),$G8)))+AO$2/100,情景分析!$D$7,"",,,,"",)*IF($H8="",1,$H8)) | AP8: =IF($A8="","",[2]!B_CALC_PRICE($A8,$AJ$1,IF(情景分析!$D$6=1,$J8,IF(情景分析!$D$6=2,$E8,IF(情景分析!$D$6=4,IF($C8="银行间",$J8,$L8),$G8)))+AP$2/100,情景分析!$D$7,"",,,,"",)*IF($H8="",1,$H8)) | AQ8: =IF($A8="","",[2]!B_CALC_PRICE($A8,$AQ$1,IF(情景分析!$D$6=1,$J8,IF(情景分析!$D$6=2,$E8,IF(情景分析!$D$6=4,IF($C8="银行间",$J8,$L8),$G8)))+AQ$2/100,情景分析!$D$7,"",,,,"",)*IF($H8="",1,$H8)) | AR8: =IF($A8="","",[2]!B_CALC_PRICE($A8,$AQ$1,IF(情景分析!$D$6=1,$J8,IF(情景分析!$D$6=2,$E8,IF(情景分析!$D$6=4,IF($C8="银行间",$J8,$L8),$G8)))+AR$2/100,情景分析!$D$7,"",,,,"",)*IF($H8="",1,$H8)) | AS8: =IF($A8="","",[2]!B_CALC_PRICE($A8,$AQ$1,IF(情景分析!$D$6=1,$J8,IF(情景分析!$D$6=2,$E8,IF(情景分析!$D$6=4,IF($C8="银行间",$J8,$L8),$G8)))+AS$2/100,情景分析!$D$7,"",,,,"",)*IF($H8="",1,$H8)) | AT8: =IF($A8="","",[2]!B_CALC_PRICE($A8,$AQ$1,IF(情景分析!$D$6=1,$J8,IF(情景分析!$D$6=2,$E8,IF(情景分析!$D$6=4,IF($C8="银行间",$J8,$L8),$G8)))+AT$2/100,情景分析!$D$7,"",,,,"",)*IF($H8="",1,$H8)) | AU8: =IF($A8="","",[2]!B_CALC_PRICE($A8,$AQ$1,IF(情景分析!$D$6=1,$J8,IF(情景分析!$D$6=2,$E8,IF(情景分析!$D$6=4,IF($C8="银行间",$J8,$L8),$G8)))+AU$2/100,情景分析!$D$7,"",,,,"",)*IF($H8="",1,$H8)) | AV8: =IF($A8="","",[2]!B_CALC_PRICE($A8,$AQ$1,IF(情景分析!$D$6=1,$J8,IF(情景分析!$D$6=2,$E8,IF(情景分析!$D$6=4,IF($C8="银行间",$J8,$L8),$G8)))+AV$2/100,情景分析!$D$7,"",,,,"",)*IF($H8="",1,$H8)) | AW8: =IF($A8="","",[2]!B_CALC_PRICE($A8,$AQ$1,IF(情景分析!$D$6=1,$J8,IF(情景分析!$D$6=2,$E8,IF(情景分析!$D$6=4,IF($C8="银行间",$J8,$L8),$G8)))+AW$2/100,情景分析!$D$7,"",,,,"",)*IF($H8="",1,$H8))
B9: =IF(A9="","",[2]!b_info_name(A9)) | C9: =[2]!b_info_listedmkt(A9) -> #N/A | D9: =IFERROR(IF(A9="","", [2]!b_dq_avgprice(A9, 情景分析!$D$5, 情景分析!$D$7) * IF($H9="",1,$H9)),0) | E9: =IF(A9="","", N([2]!b_dq_avgprice(A9,情景分析!$D$5,3))) | F9: =IF($G9 = "", "", IFERROR( [2]!b_calc_pv(A9, 情景分析!$D$5,$G9, "1", 情景分析!$D$7), [2]!b_calc_pv(A9, 情景分析!$D$5,$G9, "2", 情景分析!$D$7) ) ) | I9: =IF(A9="","",IF(情景分析!$D$7=1,[2]!b_anal_net_cnbd(A9,情景分析!$D$5,1),[2]!b_anal_dirty_cnbd(A9,情景分析!$D$5,1))*IF($H9="",1,$H9)) | J9: =IF(A9="","",[2]!b_anal_yield_cnbd(A9,情景分析!$D$5,1)) | K9: =IF(A9="","",IF(情景分析!$D$7=1,[2]!b_anal_net_csi1(A9,情景分析!$D$5,1),[2]!b_anal_dirty_csi1(A9,情景分析!$D$5,1))*IF($H9="",1,$H9)) | L9: =IF(A9="","",[2]!b_anal_yield_csi1(A9,情景分析!$D$5,1)) | M9: =IF($C9="银行间",$I9,$K9) | N9: =IF($C9="银行间",$J9,$L9) | O9: =IF($A9="","",[2]!B_CALC_PRICE($A9,$O$1,IF(情景分析!$D$6=1,$J9,IF(情景分析!$D$6=2,$E9,IF(情景分析!$D$6=4,IF($C9="银行间",$J9,$L9),$G9)))+O$2/100,情景分析!$D$7,"",,,,"",)*IF($H9="",1,$H9)) | P9: =IF($A9="","",[2]!B_CALC_PRICE($A9,$O$1,IF(情景分析!$D$6=1,$J9,IF(情景分析!$D$6=2,$E9,IF(情景分析!$D$6=4,IF($C9="银行间",$J9,$L9),$G9)))+P$2/100,情景分析!$D$7,"",,,,"",)*IF($H9="",1,$H9)) | Q9: =IF($A9="","",[2]!B_CALC_PRICE($A9,$O$1,IF(情景分析!$D$6=1,$J9,IF(情景分析!$D$6=2,$E9,IF(情景分析!$D$6=4,IF($C9="银行间",$J9,$L9),$G9)))+Q$2/100,情景分析!$D$7,"",,,,"",)*IF($H9="",1,$H9)) | R9: =IF($A9="","",[2]!B_CALC_PRICE($A9,$O$1,IF(情景分析!$D$6=1,$J9,IF(情景分析!$D$6=2,$E9,IF(情景分析!$D$6=4,IF($C9="银行间",$J9,$L9),$G9)))+R$2/100,情景分析!$D$7,"",,,,"",)*IF($H9="",1,$H9)) | S9: =IF($A9="","",[2]!B_CALC_PRICE($A9,$O$1,IF(情景分析!$D$6=1,$J9,IF(情景分析!$D$6=2,$E9,IF(情景分析!$D$6=4,IF($C9="银行间",$J9,$L9),$G9)))+S$2/100,情景分析!$D$7,"",,,,"",)*IF($H9="",1,$H9)) | T9: =IF($A9="","",[2]!B_CALC_PRICE($A9,$O$1,IF(情景分析!$D$6=1,$J9,IF(情景分析!$D$6=2,$E9,IF(情景分析!$D$6=4,IF($C9="银行间",$J9,$L9),$G9)))+T$2/100,情景分析!$D$7,"",,,,"",)*IF($H9="",1,$H9)) | U9: =IF($A9="","",[2]!B_CALC_PRICE($A9,$O$1,IF(情景分析!$D$6=1,$J9,IF(情景分析!$D$6=2,$E9,IF(情景分析!$D$6=4,IF($C9="银行间",$J9,$L9),$G9)))+U$2/100,情景分析!$D$7,"",,,,"",)*IF($H9="",1,$H9)) | V9: =IF($A9="","",[2]!B_CALC_PRICE($A9,$V$1,IF(情景分析!$D$6=1,$J9,IF(情景分析!$D$6=2,$E9,IF(情景分析!$D$6=4,IF($C9="银行间",$J9,$L9),$G9)))+V$2/100,情景分析!$D$7,"",,,,"",)*IF($H9="",1,$H9)) | W9: =IF($A9="","",[2]!B_CALC_PRICE($A9,$V$1,IF(情景分析!$D$6=1,$J9,IF(情景分析!$D$6=2,$E9,IF(情景分析!$D$6=4,IF($C9="银行间",$J9,$L9),$G9)))+W$2/100,情景分析!$D$7,"",,,,"",)*IF($H9="",1,$H9)) | X9: =IF($A9="","",[2]!B_CALC_PRICE($A9,$V$1,IF(情景分析!$D$6=1,$J9,IF(情景分析!$D$6=2,$E9,IF(情景分析!$D$6=4,IF($C9="银行间",$J9,$L9),$G9)))+X$2/100,情景分析!$D$7,"",,,,"",)*IF($H9="",1,$H9)) | Y9: =IF($A9="","",[2]!B_CALC_PRICE($A9,$V$1,IF(情景分析!$D$6=1,$J9,IF(情景分析!$D$6=2,$E9,IF(情景分析!$D$6=4,IF($C9="银行间",$J9,$L9),$G9)))+Y$2/100,情景分析!$D$7,"",,,,"",)*IF($H9="",1,$H9)) | Z9: =IF($A9="","",[2]!B_CALC_PRICE($A9,$V$1,IF(情景分析!$D$6=1,$J9,IF(情景分析!$D$6=2,$E9,IF(情景分析!$D$6=4,IF($C9="银行间",$J9,$L9),$G9)))+Z$2/100,情景分析!$D$7,"",,,,"",)*IF($H9="",1,$H9)) | AA9: =IF($A9="","",[2]!B_CALC_PRICE($A9,$V$1,IF(情景分析!$D$6=1,$J9,IF(情景分析!$D$6=2,$E9,IF(情景分析!$D$6=4,IF($C9="银行间",$J9,$L9),$G9)))+AA$2/100,情景分析!$D$7,"",,,,"",)*IF($H9="",1,$H9)) | AB9: =IF($A9="","",[2]!B_CALC_PRICE($A9,$V$1,IF(情景分析!$D$6=1,$J9,IF(情景分析!$D$6=2,$E9,IF(情景分析!$D$6=4,IF($C9="银行间",$J9,$L9),$G9)))+AB$2/100,情景分析!$D$7,"",,,,"",)*IF($H9="",1,$H9)) | AC9: =IF($A9="","",[2]!B_CALC_PRICE($A9,$AC$1,IF(情景分析!$D$6=1,$J9,IF(情景分析!$D$6=2,$E9,IF(情景分析!$D$6=4,IF($C9="银行间",$J9,$L9),$G9)))+AC$2/100,情景分析!$D$7,"",,,,"",)*IF($H9="",1,$H9)) | AD9: =IF($A9="","",[2]!B_CALC_PRICE($A9,$AC$1,IF(情景分析!$D$6=1,$J9,IF(情景分析!$D$6=2,$E9,IF(情景分析!$D$6=4,IF($C9="银行间",$J9,$L9),$G9)))+AD$2/100,情景分析!$D$7,"",,,,"",)*IF($H9="",1,$H9)) | AE9: =IF($A9="","",[2]!B_CALC_PRICE($A9,$AC$1,IF(情景分析!$D$6=1,$J9,IF(情景分析!$D$6=2,$E9,IF(情景分析!$D$6=4,IF($C9="银行间",$J9,$L9),$G9)))+AE$2/100,情景分析!$D$7,"",,,,"",)*IF($H9="",1,$H9)) | AF9: =IF($A9="","",[2]!B_CALC_PRICE($A9,$AC$1,IF(情景分析!$D$6=1,$J9,IF(情景分析!$D$6=2,$E9,IF(情景分析!$D$6=4,IF($C9="银行间",$J9,$L9),$G9)))+AF$2/100,情景分析!$D$7,"",,,,"",)*IF($H9="",1,$H9)) | AG9: =IF($A9="","",[2]!B_CALC_PRICE($A9,$AC$1,IF(情景分析!$D$6=1,$J9,IF(情景分析!$D$6=2,$E9,IF(情景分析!$D$6=4,IF($C9="银行间",$J9,$L9),$G9)))+AG$2/100,情景分析!$D$7,"",,,,"",)*IF($H9="",1,$H9)) | AH9: =IF($A9="","",[2]!B_CALC_PRICE($A9,$AC$1,IF(情景分析!$D$6=1,$J9,IF(情景分析!$D$6=2,$E9,IF(情景分析!$D$6=4,IF($C9="银行间",$J9,$L9),$G9)))+AH$2/100,情景分析!$D$7,"",,,,"",)*IF($H9="",1,$H9)) | AI9: =IF($A9="","",[2]!B_CALC_PRICE($A9,$AC$1,IF(情景分析!$D$6=1,$J9,IF(情景分析!$D$6=2,$E9,IF(情景分析!$D$6=4,IF($C9="银行间",$J9,$L9),$G9)))+AI$2/100,情景分析!$D$7,"",,,,"",)*IF($H9="",1,$H9)) | AJ9: =IF($A9="","",[2]!B_CALC_PRICE($A9,$AJ$1,IF(情景分析!$D$6=1,$J9,IF(情景分析!$D$6=2,$E9,IF(情景分析!$D$6=4,IF($C9="银行间",$J9,$L9),$G9)))+AJ$2/100,情景分析!$D$7,"",,,,"",)*IF($H9="",1,$H9)) | AK9: =IF($A9="","",[2]!B_CALC_PRICE($A9,$AJ$1,IF(情景分析!$D$6=1,$J9,IF(情景分析!$D$6=2,$E9,IF(情景分析!$D$6=4,IF($C9="银行间",$J9,$L9),$G9)))+AK$2/100,情景分析!$D$7,"",,,,"",)*IF($H9="",1,$H9)) | AL9: =IF($A9="","",[2]!B_CALC_PRICE($A9,$AJ$1,IF(情景分析!$D$6=1,$J9,IF(情景分析!$D$6=2,$E9,IF(情景分析!$D$6=4,IF($C9="银行间",$J9,$L9),$G9)))+AL$2/100,情景分析!$D$7,"",,,,"",)*IF($H9="",1,$H9)) | AM9: =IF($A9="","",[2]!B_CALC_PRICE($A9,$AJ$1,IF(情景分析!$D$6=1,$J9,IF(情景分析!$D$6=2,$E9,IF(情景分析!$D$6=4,IF($C9="银行间",$J9,$L9),$G9)))+AM$2/100,情景分析!$D$7,"",,,,"",)*IF($H9="",1,$H9)) | AN9: =IF($A9="","",[2]!B_CALC_PRICE($A9,$AJ$1,IF(情景分析!$D$6=1,$J9,IF(情景分析!$D$6=2,$E9,IF(情景分析!$D$6=4,IF($C9="银行间",$J9,$L9),$G9)))+AN$2/100,情景分析!$D$7,"",,,,"",)*IF($H9="",1,$H9)) | AO9: =IF($A9="","",[2]!B_CALC_PRICE($A9,$AJ$1,IF(情景分析!$D$6=1,$J9,IF(情景分析!$D$6=2,$E9,IF(情景分析!$D$6=4,IF($C9="银行间",$J9,$L9),$G9)))+AO$2/100,情景分析!$D$7,"",,,,"",)*IF($H9="",1,$H9)) | AP9: =IF($A9="","",[2]!B_CALC_PRICE($A9,$AJ$1,IF(情景分析!$D$6=1,$J9,IF(情景分析!$D$6=2,$E9,IF(情景分析!$D$6=4,IF($C9="银行间",$J9,$L9),$G9)))+AP$2/100,情景分析!$D$7,"",,,,"",)*IF($H9="",1,$H9)) | AQ9: =IF($A9="","",[2]!B_CALC_PRICE($A9,$AQ$1,IF(情景分析!$D$6=1,$J9,IF(情景分析!$D$6=2,$E9,IF(情景分析!$D$6=4,IF($C9="银行间",$J9,$L9),$G9)))+AQ$2/100,情景分析!$D$7,"",,,,"",)*IF($H9="",1,$H9)) | AR9: =IF($A9="","",[2]!B_CALC_PRICE($A9,$AQ$1,IF(情景分析!$D$6=1,$J9,IF(情景分析!$D$6=2,$E9,IF(情景分析!$D$6=4,IF($C9="银行间",$J9,$L9),$G9)))+AR$2/100,情景分析!$D$7,"",,,,"",)*IF($H9="",1,$H9)) | AS9: =IF($A9="","",[2]!B_CALC_PRICE($A9,$AQ$1,IF(情景分析!$D$6=1,$J9,IF(情景分析!$D$6=2,$E9,IF(情景分析!$D$6=4,IF($C9="银行间",$J9,$L9),$G9)))+AS$2/100,情景分析!$D$7,"",,,,"",)*IF($H9="",1,$H9)) | AT9: =IF($A9="","",[2]!B_CALC_PRICE($A9,$AQ$1,IF(情景分析!$D$6=1,$J9,IF(情景分析!$D$6=2,$E9,IF(情景分析!$D$6=4,IF($C9="银行间",$J9,$L9),$G9)))+AT$2/100,情景分析!$D$7,"",,,,"",)*IF($H9="",1,$H9)) | AU9: =IF($A9="","",[2]!B_CALC_PRICE($A9,$AQ$1,IF(情景分析!$D$6=1,$J9,IF(情景分析!$D$6=2,$E9,IF(情景分析!$D$6=4,IF($C9="银行间",$J9,$L9),$G9)))+AU$2/100,情景分析!$D$7,"",,,,"",)*IF($H9="",1,$H9)) | AV9: =IF($A9="","",[2]!B_CALC_PRICE($A9,$AQ$1,IF(情景分析!$D$6=1,$J9,IF(情景分析!$D$6=2,$E9,IF(情景分析!$D$6=4,IF($C9="银行间",$J9,$L9),$G9)))+AV$2/100,情景分析!$D$7,"",,,,"",)*IF($H9="",1,$H9)) | AW9: =IF($A9="","",[2]!B_CALC_PRICE($A9,$AQ$1,IF(情景分析!$D$6=1,$J9,IF(情景分析!$D$6=2,$E9,IF(情景分析!$D$6=4,IF($C9="银行间",$J9,$L9),$G9)))+AW$2/100,情景分析!$D$7,"",,,,"",)*IF($H9="",1,$H9))
