Workbook
Name compare: OFFSET(report!$U$5,1,2,report!$M$5,1)
Name comparetime: OFFSET(report!$T$5,1,0,report!$M$5,1)
Name correlX: OFFSET(report!$D$6,COLUMN()-COLUMN(#REF!)-1,0,1,1)
Name CORRELY: OFFSET(report!$D$6,ROW()-ROW(#REF!)-1,0,1,1)
Name indexclose: OFFSET(report!$J$5,1,1,report!$M$5,1)
Name indexcode: OFFSET(rawdate!$C$4,1,0,rawdate!$K$6,1)
Name indexcompare1: OFFSET(report!$U$5,1,0,report!$M$5,1)
Name indexcompare2: OFFSET(report!$U$5,1,1,report!$M$5,1)
Name indexpct: OFFSET(report!$J$5,1,2,report!$M$5,1)
Name indexpct2: OFFSET(report!$J$5,1,3,report!$M$5,1)
Name indextime: OFFSET(report!$J$5,1,0,report!$M$5,1)
Name indics: OFFSET(rawdate!$D$4,1,0,rawdate!$K$6,1)
Name indsnumms: rawdate!$O$6
Name industry: OFFSET(rawdate!$N$4,1,0,rawdate!$O$4,1)
Name mkt: OFFSET(rawdate!$L$4,1,0,rawdate!$M$4,1)
Name mktnums: rawdate!$M$5
Name size: OFFSET(rawdate!$P$4,1,0,rawdate!$Q$4,1)
Name sizenums: rawdate!$Q$6
Name top20indics: OFFSET(report!$R$5,0,0,40,1)
Name top20stdev: OFFSET(report!$U$4,1,3,40,1)
Name topfield: OFFSET(rawdate!$A$4,1,0,rawdate!$K$6,7)
Name topturn: OFFSET(report!$R$5,0,1,40,1)
Name type: OFFSET(rawdate!$R$4,1,0,rawdate!$S$4,1)
Name typenums: rawdate!$S$6
Name world: OFFSET(rawdate!$J$4,1,0,rawdate!$K$4,1)
Name worldbox: OFFSET(report!$C$5,1,5,rawdate!$K$5,1)
Name worldfield: OFFSET(rawdate!$B$4,1,0,rawdate!$K$6,4)
Name worldnums: rawdate!$K$5
Name worldstdev: OFFSET(report!$I$5,1,0,rawdate!$K$5,1)
Name worldx: OFFSET(report!$C$5,1,3,rawdate!$K$5,1)
Name worldy: OFFSET(report!$C$5,1,4,rawdate!$K$5,1)

Sheet 指数分析
E1: 指数分析
C3: 参数设置 | G3: =report!$F$5 -> 全球指数一览 | T3: =report!$P$4 -> 指数涨跌幅top20
C4: 区域 | D4: 全球
C5: 起始日期： | D5: =TODAY()-360 -> 45114
C6: 截止日期： | D6: =TODAY() -> 45474
C7: 周期： | D7: 周
C31: 指数选择 | G31: =report!$J$5 -> 胡志明指数阶段收益率 | T31: 指数区间统计
T49: 区间统计
T51: 指数区间统计 | Z51: 分布 | AA51: 当前值
S52: =RANK(W52,$W$52:$W$56,1) -> 4 | T52: 截止日期值 | U52: =report!K6 -> 1245.32 | W52: =RANK(U52,$U$52:$U$56,1)+ROW()*0.00001 -> 4.00052 | X52: 1 | Y52: =IF(ISERROR(VLOOKUP(X52,$S$52:$U$56,3,FALSE)),NA(),VLOOKUP(X52,$S$52:$U$56,3,FALSE)) -> 1055.45 | Z52: {=FREQUENCY(indexclose,$Y$52:$Y$56)/report!$M$5} -> 0.020408163 | AA52: =IF($U$55=Y52,1,NA()) -> #N/A | AF52: =IF($U$55=Z52,1,NA()) -> #N/A
S53: =RANK(W53,$W$52:$W$56,1) -> 5 | T53: 区间最高值 | U53: =MAX(indexclose) -> 1287.58 | W53: =RANK(U53,$U$52:$U$56,1)+ROW()*0.00001 -> 5.00053 | X53: 2 | Y53: =IF(ISERROR(VLOOKUP(X53,$S$52:$U$56,3,FALSE)),NA(),VLOOKUP(X53,$S$52:$U$56,3,FALSE)) -> 1193.8765 | Z53: 0.42857143 | AA53: =IF($U$55=Y53,1,NA()) -> 1 | AF53: =IF($U$55=Z53,1,NA()) -> #N/A
S54: =RANK(W54,$W$52:$W$56,1) -> 3 | T54: 区间中值 | U54: =MEDIAN(indexclose) -> 1209.52 | W54: =RANK(U54,$U$52:$U$56,1)+ROW()*0.00001 -> 3.00054 | X54: 3 | Y54: =IF(ISERROR(VLOOKUP(X54,$S$52:$U$56,3,FALSE)),NA(),VLOOKUP(X54,$S$52:$U$56,3,FALSE)) -> 1209.52 | Z54: 0.06122449 | AA54: =IF($U$55=Y54,1,NA()) -> #N/A | AF54: =IF($U$55=Z54,1,NA()) -> #N/A
S55: =RANK(W55,$W$52:$W$56,1) -> 2 | T55: 区间均值 | U55: =AVERAGE(indexclose) -> 1193.8765 | W55: =RANK(U55,$U$52:$U$56,1)+ROW()*0.00001 -> 2.00055 | X55: 4 | Y55: =IF(ISERROR(VLOOKUP(X55,$S$52:$U$56,3,FALSE)),NA(),VLOOKUP(X55,$S$52:$U$56,3,FALSE)) -> 1245.32 | Z55: 0.28571429 | AA55: =IF($U$55=Y55,1,NA()) -> #N/A | AF55: =IF($U$55=Z55,1,NA()) -> #N/A
S56: =RANK(W56,$W$52:$W$56,1) -> 1 | T56: 区间最小值 | U56: =MIN(indexclose) -> 1055.45 | W56: =RANK(U56,$U$52:$U$56,1)+ROW()*0.00001 -> 1.00056 | X56: 5 | Y56: =IF(ISERROR(VLOOKUP(X56,$S$52:$U$56,3,FALSE)),NA(),VLOOKUP(X56,$S$52:$U$56,3,FALSE)) -> 1287.58 | Z56: 0.20408163 | AA56: =IF($U$55=Y56,1,NA()) -> #N/A | AF56: =IF($U$55=Z56,1,NA()) -> #N/A

Sheet report
B4: =指数分析!C4 -> 区域 | P4: 指数涨跌幅top20 | X4: 波动率
B5: 排序 | C5: 序号 | D5: 指数 | E5: 区间收益率 | F5: =指数分析!$D$4&"指数一览" -> 全球指数一览 | G5: 调整后收益率 | H5: 24 | I5: 区间周波动率 | J5: =[1]!f_info_name(K5)&"阶段收益率" -> 胡志明指数阶段收益率 | K5: =LEFT(OFFSET(H5,H5,0,1,1),FIND(".",OFFSET(H5,H5,0,1,1),1)+2) -> VNINDEX.GI | L5: 当期涨跌幅 | M5: =COUNTIF(J:J,">1") -> 49 | P5: 1 | Q5: =VLOOKUP(P5,topfield,3,FALSE) -> MERV.GI | R5: =Q5&VLOOKUP(P5,topfield,4,FALSE)&TEXT(S5,"0.0%") -> MERV.GI阿根廷MERV285.9% | S5: =VLOOKUP(P5,topfield,7,FALSE) -> 2.8589395 | X5: =IF(R5="","",[1]!s_risk_stdevy(LEFT(R5,FIND(".",R5)+2),指数分析!$D$5,指数分析!$D$6,2,1)) -> 70.67481
B6: =IF(E6="","",IF(COUNTIF(E$6:E6,E6)=1,RANK(E6,E:E,0),RANK(E6,E:E,0)+COUNTIF(E$6:E6,E6)-1)) -> 44 | C6: =IF(ROW()-ROW($C$5)>worldnums,"",ROW()-ROW($C$5)) -> 1 | D6: =IF(C6="","",VLOOKUP(C6,worldfield,2,FALSE)&VLOOKUP(C6,worldfield,3,FALSE)) -> 000001.SH上证指数 | E6: =IF(C6="","",[1]!f_pq_pctchange(VLOOKUP(C6,worldfield,2,FALSE),指数分析!$D$5,指数分析!$D$6)/100) -> -0.074299311 | F6: =IF(C6="","",VLOOKUP(C6,B:E,3,FALSE)) -> MERV.GI阿根廷MERV | G6: =IF(C6="","",VLOOKUP(C6,B:E,4,FALSE)) -> 2.8589395 | H6: =IF(C6="","",F6&":"&TEXT(G6,"0.0%")) -> MERV.GI阿根廷MERV:285.9% | I6: =IF(H6="","",[1]!s_risk_stdevy(LEFT(H6,FIND(".",H6)+2),指数分析!$D$5,指数分析!$D$6,2,1)) -> 70.67481 | J6: =--指数分析!$D$6 -> 45474 | K6: =IF(J6="","",[1]!f_dq_close($K$5,J6)) -> 1245.32 | L6: =IF(J6="","",[1]!f_pq_pctchange($K$5,J6,J6)/100) -> 0 | M6: =IF(J6="","",[1]!f_pq_pctchange($K$5,指数分析!$D$5,J6)/100) -> 0.10575198 | P6: 2 | Q6: =VLOOKUP(P6,topfield,3,FALSE) -> IBVC.GI | R6: =Q6&VLOOKUP(P6,topfield,4,FALSE)&TEXT(S6,"0.0%") -> IBVC.GI委内瑞拉IBC128.8% | S6: =VLOOKUP(P6,topfield,7,FALSE) -> 1.288498 | X6: =IF(R6="","",[1]!s_risk_stdevy(LEFT(R6,FIND(".",R6)+2),指数分析!$D$5,指数分析!$D$6,2,1)) -> 34.116552
B7: =IF(E7="","",IF(COUNTIF(E$6:E7,E7)=1,RANK(E7,E:E,0),RANK(E7,E:E,0)+COUNTIF(E$6:E7,E7)-1)) -> 47 | C7: =IF(ROW()-ROW($C$5)>worldnums,"",ROW()-ROW($C$5)) -> 2 | D7: =IF(C7="","",VLOOKUP(C7,worldfield,2,FALSE)&VLOOKUP(C7,worldfield,3,FALSE)) -> 399001.SZ深证成指 | E7: =IF(C7="","",[1]!f_pq_pctchange(VLOOKUP(C7,worldfield,2,FALSE),指数分析!$D$5,指数分析!$D$6)/100) -> -0.19325301 | F7: =IF(C7="","",VLOOKUP(C7,B:E,3,FALSE)) -> IBVC.GI委内瑞拉IBC | G7: =IF(C7="","",VLOOKUP(C7,B:E,4,FALSE)) -> 1.288498 | H7: =IF(C7="","",F7&":"&TEXT(G7,"0.0%")) -> IBVC.GI委内瑞拉IBC:128.8% | I7: =IF(H7="","",[1]!s_risk_stdevy(LEFT(H7,FIND(".",H7)+2),指数分析!$D$5,指数分析!$D$6,2,1)) -> 34.116552 | J7: =IF(J6="","",IF([1]!td(J6-IF(指数分析!$D$7="日",1,IF(指数分析!$D$7="周",7,30)))-指数分析!$D$5>=0,--[1]!td(J6-IF(指数分析!$D$7="日",1,IF(指数分析!$D$7="周",7,30))),"")) -> 45467 | K7: =IF(J7="","",[1]!f_dq_close($K$5,J7)) -> 1254.12 | L7: =IF(J7="","",[1]!f_pq_pctchange($K$5,J7,J7)/100) -> -0.021762531 | M7: =IF(J7="","",[1]!f_pq_pctchange($K$5,指数分析!$D$5,J7)/100) -> 0.11356573 | P7: 3 | Q7: =VLOOKUP(P7,topfield,3,FALSE) -> TWSE078.TW | R7: =Q7&VLOOKUP(P7,topfield,4,FALSE)&TEXT(S7,"0.0%") -> TWSE078.TW台湾其他电子指数76.5% | S7: =VLOOKUP(P7,topfield,7,FALSE) -> 0.76466108 | X7: =IF(R7="","",[1]!s_risk_stdevy(LEFT(R7,FIND(".",R7)+2),指数分析!$D$5,指数分析!$D$6,2,1)) -> 26.134725
B8: =IF(E8="","",IF(COUNTIF(E$6:E8,E8)=1,RANK(E8,E:E,0),RANK(E8,E:E,0)+COUNTIF(E$6:E8,E8)-1)) -> 43 | C8: =IF(ROW()-ROW($C$5)>worldnums,"",ROW()-ROW($C$5)) -> 3 | D8: =IF(C8="","",VLOOKUP(C8,worldfield,2,FALSE)&VLOOKUP(C8,worldfield,3,FALSE)) -> HSI.HI恒生指数 | E8: =IF(C8="","",[1]!f_pq_pctchange(VLOOKUP(C8,worldfield,2,FALSE),指数分析!$D$5,指数分析!$D$6)/100) -> -0.043945276 | F8: =IF(C8="","",VLOOKUP(C8,B:E,3,FALSE)) -> KAX.GI丹麦OMX20 | G8: =IF(C8="","",VLOOKUP(C8,B:E,4,FALSE)) -> 0.43910266 | H8: =IF(C8="","",F8&":"&TEXT(G8,"0.0%")) -> KAX.GI丹麦OMX20:43.9% | I8: =IF(H8="","",[1]!s_risk_stdevy(LEFT(H8,FIND(".",H8)+2),指数分析!$D$5,指数分析!$D$6,2,1)) -> 18.287825 | J8: =IF(J7="","",IF([1]!td(J7-IF(指数分析!$D$7="日",1,IF(指数分析!$D$7="周",7,30)))-指数分析!$D$5>=0,--[1]!td(J7-IF(指数分析!$D$7="日",1,IF(指数分析!$D$7="周",7,30))),"")) -> 45460 | K8: =IF(J8="","",[1]!f_dq_close($K$5,J8)) -> 1274.77 | L8: =IF(J8="","",[1]!f_pq_pctchange($K$5,J8,J8)/100) -> -0.0040159074 | M8: =IF(J8="","",[1]!f_pq_pctchange($K$5,指数分析!$D$5,J8)/100) -> 0.1319014 | P8: 4 | Q8: =VLOOKUP(P8,topfield,3,FALSE) -> TWSE071.TW | R8: =Q8&VLOOKUP(P8,topfield,4,FALSE)&TEXT(S8,"0.0%") -> TWSE071.TW台湾半导体指数63.5% | S8: =VLOOKUP(P8,topfield,7,FALSE) -> 0.63512832 | X8: =IF(R8="","",[1]!s_risk_stdevy(LEFT(R8,FIND(".",R8)+2),指数分析!$D$5,指数分析!$D$6,2,1)) -> 24.748102
B9: =IF(E9="","",IF(COUNTIF(E$6:E9,E9)=1,RANK(E9,E:E,0),RANK(E9,E:E,0)+COUNTIF(E$6:E9,E9)-1)) -> 5 | C9: =IF(ROW()-ROW($C$5)>worldnums,"",ROW()-ROW($C$5)) -> 4 | D9: =IF(C9="","",VLOOKUP(C9,worldfield,2,FALSE)&VLOOKUP(C9,worldfield,3,FALSE)) -> TWII.TW台湾加权指数 | E9: =IF(C9="","",[1]!f_pq_pctchange(VLOOKUP(C9,worldfield,2,FALSE),指数分析!$D$5,指数分析!$D$6)/100) -> 0.37406135 | F9: =IF(C9="","",VLOOKUP(C9,B:E,3,FALSE)) -> 8884057.WITAMAMA科技指数 | G9: =IF(C9="","",VLOOKUP(C9,B:E,4,FALSE)) -> 0.42971903 | H9: =IF(C9="","",F9&":"&TEXT(G9,"0.0%")) -> 8884057.WITAMAMA科技指数:43.0% | I9: =IF(H9="","",[1]!s_risk_stdevy(LEFT(H9,FIND(".",H9)+2),指数分析!$D$5,指数分析!$D$6,2,1)) -> 20.06117 | J9: =IF(J8="","",IF([1]!td(J8-IF(指数分析!$D$7="日",1,IF(指数分析!$D$7="周",7,30)))-指数分析!$D$5>=0,--[1]!td(J8-IF(指数分析!$D$7="日",1,IF(指数分析!$D$7="周",7,30))),"")) -> 45450 | K9: =IF(J9="","",[1]!f_dq_close($K$5,J9)) -> 1287.58 | L9: =IF(J9="","",[1]!f_pq_pctchange($K$5,J9,J9)/100) -> 0.0031319144 | M9: =IF(J9="","",[1]!f_pq_pctchange($K$5,指数分析!$D$5,J9)/100) -> 0.14327574 | P9: 5 | Q9: =VLOOKUP(P9,topfield,3,FALSE) -> TWSE006.TW | R9: =Q9&VLOOKUP(P9,topfield,4,FALSE)&TEXT(S9,"0.0%") -> TWSE006.TW台湾建材营造指数56.2% | S9: =VLOOKUP(P9,topfield,7,FALSE) -> 0.56211358 | X9: =IF(R9="","",[1]!s_risk_stdevy(LEFT(R9,FIND(".",R9)+2),指数分析!$D$5,指数分析!$D$6,2,1)) -> 19.301593
B10: =IF(E10="","",IF(COUNTIF(E$6:E10,E10)=1,RANK(E10,E:E,0),RANK(E10,E:E,0)+COUNTIF(E$6:E10,E10)-1)) -> 46 | C10: =IF(ROW()-ROW($C$5)>worldnums,"",ROW()-ROW($C$5)) -> 5 | D10: =IF(C10="","",VLOOKUP(C10,worldfield,2,FALSE)&VLOOKUP(C10,worldfield,3,FALSE)) -> 899050.BJ北证50 | E10: =IF(C10="","",[1]!f_pq_pctchange(VLOOKUP(C10,worldfield,2,FALSE),指数分析!$D$5,指数分析!$D$6)/100) -> -0.19312021 | F10: =IF(C10="","",VLOOKUP(C10,B:E,3,FALSE)) -> TWII.TW台湾加权指数 | G10: =IF(C10="","",VLOOKUP(C10,B:E,4,FALSE)) -> 0.37406135 | H10: =IF(C10="","",F10&":"&TEXT(G10,"0.0%")) -> TWII.TW台湾加权指数:37.4% | I10: =IF(H10="","",[1]!s_risk_stdevy(LEFT(H10,FIND(".",H10)+2),指数分析!$D$5,指数分析!$D$6,2,1)) -> 14.527951 | J10: =IF(J9="","",IF([1]!td(J9-IF(指数分析!$D$7="日",1,IF(指数分析!$D$7="周",7,30)))-指数分析!$D$5>=0,--[1]!td(J9-IF(指数分析!$D$7="日",1,IF(指数分析!$D$7="周",7,30))),"")) -> 45443 | K10: =IF(J10="","",[1]!f_dq_close($K$5,J10)) -> 1261.72 | L10: =IF(J10="","",[1]!f_pq_pctchange($K$5,J10,J10)/100) -> -0.0036325731 | M10: =IF(J10="","",[1]!f_pq_pctchange($K$5,指数分析!$D$5,J10)/100) -> 0.12031397 | P10: 6 | Q10: =VLOOKUP(P10,topfield,3,FALSE) -> TWSE020.TW | R10: =Q10&VLOOKUP(P10,topfield,4,FALSE)&TEXT(S10,"0.0%") -> TWSE020.TW台湾电子指数53.0% | S10: =VLOOKUP(P10,topfield,7,FALSE) -> 0.52989338 | X10: =IF(R10="","",[1]!s_risk_stdevy(LEFT(R10,FIND(".",R10)+2),指数分析!$D$5,指数分析!$D$6,2,1)) -> 19.239693
B11: =IF(E11="","",IF(COUNTIF(E$6:E11,E11)=1,RANK(E11,E:E,0),RANK(E11,E:E,0)+COUNTIF(E$6:E11,E11)-1)) -> 4 | C11: =IF(ROW()-ROW($C$5)>worldnums,"",ROW()-ROW($C$5)) -> 6 | D11: =IF(C11="","",VLOOKUP(C11,worldfield,2,FALSE)&VLOOKUP(C11,worldfield,3,FALSE)) -> 8884057.WITAMAMA科技指数 | E11: =IF(C11="","",[1]!f_pq_pctchange(VLOOKUP(C11,worldfield,2,FALSE),指数分析!$D$5,指数分析!$D$6)/100) -> 0.42971903 | F11: =IF(C11="","",VLOOKUP(C11,B:E,3,FALSE)) -> IXIC.GI纳斯达克指数 | G11: =IF(C11="","",VLOOKUP(C11,B:E,4,FALSE)) -> 0.29633366 | H11: =IF(C11="","",F11&":"&TEXT(G11,"0.0%")) -> IXIC.GI纳斯达克指数:29.6% | I11: =IF(H11="","",[1]!s_risk_stdevy(LEFT(H11,FIND(".",H11)+2),指数分析!$D$5,指数分析!$D$6,2,1)) -> 16.5396 | J11: =IF(J10="","",IF([1]!td(J10-IF(指数分析!$D$7="日",1,IF(指数分析!$D$7="周",7,30)))-指数分析!$D$5>=0,--[1]!td(J10-IF(指数分析!$D$7="日",1,IF(指数分析!$D$7="周",7,30))),"")) -> 45436 | K11: =IF(J11="","",[1]!f_dq_close($K$5,J11)) -> 1261.93 | L11: =IF(J11="","",[1]!f_pq_pctchange($K$5,J11,J11)/100) -> -0.014909877 | M11: =IF(J11="","",[1]!f_pq_pctchange($K$5,指数分析!$D$5,J11)/100) -> 0.12050044 | P11: 7 | Q11: =VLOOKUP(P11,topfield,3,FALSE) -> TWSE005.TW | R11: =Q11&VLOOKUP(P11,topfield,4,FALSE)&TEXT(S11,"0.0%") -> TWSE005.TW台湾机电指数52.3% | S11: =VLOOKUP(P11,topfield,7,FALSE) -> 0.52263642 | X11: =IF(R11="","",[1]!s_risk_stdevy(LEFT(R11,FIND(".",R11)+2),指数分析!$D$5,指数分析!$D$6,2,1)) -> 18.692234
B12: =IF(E12="","",IF(COUNTIF(E$6:E12,E12)=1,RANK(E12,E:E,0),RANK(E12,E:E,0)+COUNTIF(E$6:E12,E12)-1)) -> 19 | C12: =IF(ROW()-ROW($C$5)>worldnums,"",ROW()-ROW($C$5)) -> 7 | D12: =IF(C12="","",VLOOKUP(C12,worldfield,2,FALSE)&VLOOKUP(C12,worldfield,3,FALSE)) -> DJI.GI道琼斯工业指数 | E12: =IF(C12="","",[1]!f_pq_pctchange(VLOOKUP(C12,worldfield,2,FALSE),指数分析!$D$5,指数分析!$D$6)/100) -> 0.15319144 | F12: =IF(C12="","",VLOOKUP(C12,B:E,3,FALSE)) -> SPX.GI标普500 | G12: =IF(C12="","",VLOOKUP(C12,B:E,4,FALSE)) -> 0.23775782 | H12: =IF(C12="","",F12&":"&TEXT(G12,"0.0%")) -> SPX.GI标普500:23.8% | I12: =IF(H12="","",[1]!s_risk_stdevy(LEFT(H12,FIND(".",H12)+2),指数分析!$D$5,指数分析!$D$6,2,1)) -> 12.027852 | J12: =IF(J11="","",IF([1]!td(J11-IF(指数分析!$D$7="日",1,IF(指数分析!$D$7="周",7,30)))-指数分析!$D$5>=0,--[1]!td(J11-IF(指数分析!$D$7="日",1,IF(指数分析!$D$7="周",7,30))),"")) -> 45429 | K12: =IF(J12="","",[1]!f_dq_close($K$5,J12)) -> 1273.11 | L12: =IF(J12="","",[1]!f_pq_pctchange($K$5,J12,J12)/100) -> 0.0034127272 | M12: =IF(J12="","",[1]!f_pq_pctchange($K$5,指数分析!$D$5,J12)/100) -> 0.13042745 | P12: 8 | Q12: =VLOOKUP(P12,topfield,3,FALSE) -> TWSE076.TW | R12: =Q12&VLOOKUP(P12,topfield,4,FALSE)&TEXT(S12,"0.0%") -> TWSE076.TW台湾电子通路指数49.7% | S12: =VLOOKUP(P12,topfield,7,FALSE) -> 0.49726365 | X12: =IF(R12="","",[1]!s_risk_stdevy(LEFT(R12,FIND(".",R12)+2),指数分析!$D$5,指数分析!$D$6,2,1)) -> 16.30292
B13: =IF(E13="","",IF(COUNTIF(E$6:E13,E13)=1,RANK(E13,E:E,0),RANK(E13,E:E,0)+COUNTIF(E$6:E13,E13)-1)) -> 25 | C13: =IF(ROW()-ROW($C$5)>worldnums,"",ROW()-ROW($C$5)) -> 8 | D13: =IF(C13="","",VLOOKUP(C13,worldfield,2,FALSE)&VLOOKUP(C13,worldfield,3,FALSE)) -> GSPTSE.GI加拿大S&P/TSX综合 | E13: =IF(C13="","",[1]!f_pq_pctchange(VLOOKUP(C13,worldfield,2,FALSE),指数分析!$D$5,指数分析!$D$6)/100) -> 0.1042417 | F13: =IF(C13="","",VLOOKUP(C13,B:E,3,FALSE)) -> AEX.GI荷兰AEX | G13: =IF(C13="","",VLOOKUP(C13,B:E,4,FALSE)) -> 0.2263387 | H13: =IF(C13="","",F13&":"&TEXT(G13,"0.0%")) -> AEX.GI荷兰AEX:22.6% | I13: =IF(H13="","",[1]!s_risk_stdevy(LEFT(H13,FIND(".",H13)+2),指数分析!$D$5,指数分析!$D$6,2,1)) -> 12.373331 | J13: =IF(J12="","",IF([1]!td(J12-IF(指数分析!$D$7="日",1,IF(指数分析!$D$7="周",7,30)))-指数分析!$D$5>=0,--[1]!td(J12-IF(指数分析!$D$7="日",1,IF(指数分析!$D$7="周",7,30))),"")) -> 45422 | K13: =IF(J13="","",[1]!f_dq_close($K$5,J13)) -> 1244.7 | L13: =IF(J13="","",[1]!f_pq_pctchange($K$5,J13,J13)/100) -> -0.0031554331 | M13: =IF(J13="","",[1]!f_pq_pctchange($K$5,指数分析!$D$5,J13)/100) -> 0.10520147 | P13: 9 | Q13: =VLOOKUP(P13,topfield,3,FALSE) -> KAX.GI | R13: =Q13&VLOOKUP(P13,topfield,4,FALSE)&TEXT(S13,"0.0%") -> KAX.GI丹麦OMX2043.9% | S13: =VLOOKUP(P13,topfield,7,FALSE) -> 0.43910266 | X13: =IF(R13="","",[1]!s_risk_stdevy(LEFT(R13,FIND(".",R13)+2),指数分析!$D$5,指数分析!$D$6,2,1)) -> 18.287825
B14: =IF(E14="","",IF(COUNTIF(E$6:E14,E14)=1,RANK(E14,E:E,0),RANK(E14,E:E,0)+COUNTIF(E$6:E14,E14)-1)) -> 34 | C14: =IF(ROW()-ROW($C$5)>worldnums,"",ROW()-ROW($C$5)) -> 9 | D14: =IF(C14="","",VLOOKUP(C14,worldfield,2,FALSE)&VLOOKUP(C14,worldfield,3,FALSE)) -> IBOVESPA.GI巴西IBOVESPA指数 | E14: =IF(C14="","",[1]!f_pq_pctchange(VLOOKUP(C14,worldfield,2,FALSE),指数分析!$D$5,指数分析!$D$6)/100) -> 0.05519107 | F14: =IF(C14="","",VLOOKUP(C14,B:E,3,FALSE)) -> OSEAX.GI挪威OSEAX | G14: =IF(C14="","",VLOOKUP(C14,B:E,4,FALSE)) -> 0.2102724 | H14: =IF(C14="","",F14&":"&TEXT(G14,"0.0%")) -> OSEAX.GI挪威OSEAX:21.0% | I14: =IF(H14="","",[1]!s_risk_stdevy(LEFT(H14,FIND(".",H14)+2),指数分析!$D$5,指数分析!$D$6,2,1)) -> 12.054658 | J14: =IF(J13="","",IF([1]!td(J13-IF(指数分析!$D$7="日",1,IF(指数分析!$D$7="周",7,30)))-指数分析!$D$5>=0,--[1]!td(J13-IF(指数分析!$D$7="日",1,IF(指数分析!$D$7="周",7,30))),"")) -> 45412 | K14: =IF(J14="","",[1]!f_dq_close($K$5,J14)) -> 1209.52 | L14: =IF(J14="","",[1]!f_pq_pctchange($K$5,J14,J14)/100) -> 0 | M14: =IF(J14="","",[1]!f_pq_pctchange($K$5,指数分析!$D$5,J14)/100) -> 0.073964234 | P14: 10 | Q14: =VLOOKUP(P14,topfield,3,FALSE) -> 8884057.WI | R14: =Q14&VLOOKUP(P14,topfield,4,FALSE)&TEXT(S14,"0.0%") -> 8884057.WITAMAMA科技指数43.0% | S14: =VLOOKUP(P14,topfield,7,FALSE) -> 0.42971903 | X14: =IF(R14="","",[1]!s_risk_stdevy(LEFT(R14,FIND(".",R14)+2),指数分析!$D$5,指数分析!$D$6,2,1)) -> 20.06117
B15: =IF(E15="","",IF(COUNTIF(E$6:E15,E15)=1,RANK(E15,E:E,0),RANK(E15,E:E,0)+COUNTIF(E$6:E15,E15)-1)) -> 2 | C15: =IF(ROW()-ROW($C$5)>worldnums,"",ROW()-ROW($C$5)) -> 10 | D15: =IF(C15="","",VLOOKUP(C15,worldfield,2,FALSE)&VLOOKUP(C15,worldfield,3,FALSE)) -> IBVC.GI委内瑞拉IBC | E15: =IF(C15="","",[1]!f_pq_pctchange(VLOOKUP(C15,worldfield,2,FALSE),指数分析!$D$5,指数分析!$D$6)/100) -> 1.288498 | F15: =IF(C15="","",VLOOKUP(C15,B:E,3,FALSE)) -> N225.GI日经225 | G15: =IF(C15="","",VLOOKUP(C15,B:E,4,FALSE)) -> 0.2077947 | H15: =IF(C15="","",F15&":"&TEXT(G15,"0.0%")) -> N225.GI日经225:20.8% | I15: =IF(H15="","",[1]!s_risk_stdevy(LEFT(H15,FIND(".",H15)+2),指数分析!$D$5,指数分析!$D$6,2,1)) -> 17.709586 | J15: =IF(J14="","",IF([1]!td(J14-IF(指数分析!$D$7="日",1,IF(指数分析!$D$7="周",7,30)))-指数分析!$D$5>=0,--[1]!td(J14-IF(指数分析!$D$7="日",1,IF(指数分析!$D$7="周",7,30))),"")) -> 45405 | K15: =IF(J15="","",[1]!f_dq_close($K$5,J15)) -> 1177.4 | L15: =IF(J15="","",[1]!f_pq_pctchange($K$5,J15,J15)/100) -> -0.010771118 | M15: =IF(J15="","",[1]!f_pq_pctchange($K$5,指数分析!$D$5,J15)/100) -> 0.045444052 | P15: 11 | Q15: =VLOOKUP(P15,topfield,3,FALSE) -> TWSE013.TW | R15: =Q15&VLOOKUP(P15,topfield,4,FALSE)&TEXT(S15,"0.0%") -> TWSE013.TW台湾电机机械指数40.7% | S15: =VLOOKUP(P15,topfield,7,FALSE) -> 0.40730486 | X15: =IF(R15="","",[1]!s_risk_stdevy(LEFT(R15,FIND(".",R15)+2),指数分析!$D$5,指数分析!$D$6,2,1)) -> 23.233936
B16: =IF(E16="","",IF(COUNTIF(E$6:E16,E16)=1,RANK(E16,E:E,0),RANK(E16,E:E,0)+COUNTIF(E$6:E16,E16)-1)) -> 6 | C16: =IF(ROW()-ROW($C$5)>worldnums,"",ROW()-ROW($C$5)) -> 11 | D16: =IF(C16="","",VLOOKUP(C16,worldfield,2,FALSE)&VLOOKUP(C16,worldfield,3,FALSE)) -> IXIC.GI纳斯达克指数 | E16: =IF(C16="","",[1]!f_pq_pctchange(VLOOKUP(C16,worldfield,2,FALSE),指数分析!$D$5,指数分析!$D$6)/100) -> 0.29633366 | F16: =IF(C16="","",VLOOKUP(C16,B:E,3,FALSE)) -> PX.GI布拉格综指 | G16: =IF(C16="","",VLOOKUP(C16,B:E,4,FALSE)) -> 0.20217275 | H16: =IF(C16="","",F16&":"&TEXT(G16,"0.0%")) -> PX.GI布拉格综指:20.2% | I16: =IF(H16="","",[1]!s_risk_stdevy(LEFT(H16,FIND(".",H16)+2),指数分析!$D$5,指数分析!$D$6,2,1)) -> 8.7912061 | J16: =IF(J15="","",IF([1]!td(J15-IF(指数分析!$D$7="日",1,IF(指数分析!$D$7="周",7,30)))-指数分析!$D$5>=0,--[1]!td(J15-IF(指数分析!$D$7="日",1,IF(指数分析!$D$7="周",7,30))),"")) -> 45398 | K16: =IF(J16="","",[1]!f_dq_close($K$5,J16)) -> 1215.68 | L16: =IF(J16="","",[1]!f_pq_pctchange($K$5,J16,J16)/100) -> -0.00076441916 | M16: =IF(J16="","",[1]!f_pq_pctchange($K$5,指数分析!$D$5,J16)/100) -> 0.079433858 | P16: 12 | Q16: =VLOOKUP(P16,topfield,3,FALSE) -> CI005106.WI | R16: =Q16&VLOOKUP(P16,topfield,4,FALSE)&TEXT(S16,"0.0%") -> CI005106.WI贵金属(中信)40.7% | S16: =VLOOKUP(P16,topfield,7,FALSE) -> 0.40696925 | X16: =IF(R16="","",[1]!s_risk_stdevy(LEFT(R16,FIND(".",R16)+2),指数分析!$D$5,指数分析!$D$6,2,1)) -> 26.36002
B17: =IF(E17="","",IF(COUNTIF(E$6:E17,E17)=1,RANK(E17,E:E,0),RANK(E17,E:E,0)+COUNTIF(E$6:E17,E17)-1)) -> 1 | C17: =IF(ROW()-ROW($C$5)>worldnums,"",ROW()-ROW($C$5)) -> 12 | D17: =IF(C17="","",VLOOKUP(C17,worldfield,2,FALSE)&VLOOKUP(C17,worldfield,3,FALSE)) -> MERV.GI阿根廷MERV | E17: =IF(C17="","",[1]!f_pq_pctchange(VLOOKUP(C17,worldfield,2,FALSE),指数分析!$D$5,指数分析!$D$6)/100) -> 2.8589395 | F17: =IF(C17="","",VLOOKUP(C17,B:E,3,FALSE)) -> SENSEX.BO印度SENSEX30 | G17: =IF(C17="","",VLOOKUP(C17,B:E,4,FALSE)) -> 0.2013675 | H17: =IF(C17="","",F17&":"&TEXT(G17,"0.0%")) -> SENSEX.BO印度SENSEX30:20.1% | I17: =IF(H17="","",[1]!s_risk_stdevy(LEFT(H17,FIND(".",H17)+2),指数分析!$D$5,指数分析!$D$6,2,1)) -> 10.242817 | J17: =IF(J16="","",IF([1]!td(J16-IF(指数分析!$D$7="日",1,IF(指数分析!$D$7="周",7,30)))-指数分析!$D$5>=0,--[1]!td(J16-IF(指数分析!$D$7="日",1,IF(指数分析!$D$7="周",7,30))),"")) -> 45391 | K17: =IF(J17="","",[1]!f_dq_close($K$5,J17)) -> 1262.82 | L17: =IF(J17="","",[1]!f_pq_pctchange($K$5,J17,J17)/100) -> 0.0099732075 | M17: =IF(J17="","",[1]!f_pq_pctchange($K$5,指数分析!$D$5,J17)/100) -> 0.12129069 | P17: 13 | Q17: =VLOOKUP(P17,topfield,3,FALSE) -> TWSE072.TW | R17: =Q17&VLOOKUP(P17,topfield,4,FALSE)&TEXT(S17,"0.0%") -> TWSE072.TW台湾计算机及外围设备指数39.9% | S17: =VLOOKUP(P17,topfield,7,FALSE) -> 0.3991147 | X17: =IF(R17="","",[1]!s_risk_stdevy(LEFT(R17,FIND(".",R17)+2),指数分析!$D$5,指数分析!$D$6,2,1)) -> 31.086451
B18: =IF(E18="","",IF(COUNTIF(E$6:E18,E18)=1,RANK(E18,E:E,0),RANK(E18,E:E,0)+COUNTIF(E$6:E18,E18)-1)) -> 41 | C18: =IF(ROW()-ROW($C$5)>worldnums,"",ROW()-ROW($C$5)) -> 13 | D18: =IF(C18="","",VLOOKUP(C18,worldfield,2,FALSE)&VLOOKUP(C18,worldfield,3,FALSE)) -> MXX.GI墨西哥MXX | E18: =IF(C18="","",[1]!f_pq_pctchange(VLOOKUP(C18,worldfield,2,FALSE),指数分析!$D$5,指数分析!$D$6)/100) -> -0.018118736 | F18: =IF(C18="","",VLOOKUP(C18,B:E,3,FALSE)) -> RTSI.GIRTS指数 | G18: =IF(C18="","",VLOOKUP(C18,B:E,4,FALSE)) -> 0.19354639 | H18: =IF(C18="","",F18&":"&TEXT(G18,"0.0%")) -> RTSI.GIRTS指数:19.4% | I18: =IF(H18="","",[1]!s_risk_stdevy(LEFT(H18,FIND(".",H18)+2),指数分析!$D$5,指数分析!$D$6,2,1)) -> 18.38845 | J18: =IF(J17="","",IF([1]!td(J17-IF(指数分析!$D$7="日",1,IF(指数分析!$D$7="周",7,30)))-指数分析!$D$5>=0,--[1]!td(J17-IF(指数分析!$D$7="日",1,IF(指数分析!$D$7="周",7,30))),"")) -> 45384 | K18: =IF(J18="","",[1]!f_dq_close($K$5,J18)) -> 1287.04 | L18: =IF(J18="","",[1]!f_pq_pctchange($K$5,J18,J18)/100) -> 0.004307385 | M18: =IF(J18="","",[1]!f_pq_pctchange($K$5,指数分析!$D$5,J18)/100) -> 0.14279626 | P18: 14 | Q18: =VLOOKUP(P18,topfield,3,FALSE) -> TWSE002.TW | R18: =Q18&VLOOKUP(P18,topfield,4,FALSE)&TEXT(S18,"0.0%") -> TWSE002.TW台湾未含金融保险指数38.9% | S18: =VLOOKUP(P18,topfield,7,FALSE) -> 0.38870988 | X18: =IF(R18="","",[1]!s_risk_stdevy(LEFT(R18,FIND(".",R18)+2),指数分析!$D$5,指数分析!$D$6,2,1)) -> 15.325016
... B24: =IF(E24="","",IF(COUNTIF(E$6:E24,E24)=1,RANK(E24,E:E,0),RANK(E24,E:E,0)+COUNTIF(E$6:E24,E24)-1)) -> 33 | C24: =IF(ROW()-ROW($C$5)>worldnums,"",ROW()-ROW($C$5)) -> 19 | D24: =IF(C24="","",VLOOKUP(C24,worldfield,2,FALSE)&VLOOKUP(C24,worldfield,3,FALSE)) -> FCHI.GI法国CAC40 | E24: =IF(C24="","",[1]!f_pq_pctchange(VLOOKUP(C24,worldfield,2,FALSE),指数分析!$D$5,指数分析!$D$6)/100) -> 0.056070847 | F24: =IF(C24="","",VLOOKUP(C24,B:E,3,FALSE)) -> DJI.GI道琼斯工业指数 | G24: =IF(C24="","",VLOOKUP(C24,B:E,4,FALSE)) -> 0.15319144 | H24: =IF(C24="","",F24&":"&TEXT(G24,"0.0%")) -> DJI.GI道琼斯工业指数:15.3% | I24: =IF(H24="","",[1]!s_risk_stdevy(LEFT(H24,FIND(".",H24)+2),指数分析!$D$5,指数分析!$D$6,2,1)) -> 10.830906 | J24: =IF(J23="","",IF([1]!td(J23-IF(指数分析!$D$7="日",1,IF(指数分析!$D$7="周",7,30)))-指数分析!$D$5>=0,--[1]!td(J23-IF(指数分析!$D$7="日",1,IF(指数分析!$D$7="周",7,30))),"")) -> 45342 | K24: =IF(J24="","",[1]!f_dq_close($K$5,J24)) -> 1230.06 | L24: =IF(J24="","",[1]!f_pq_pctchange($K$5,J24,J24)/100) -> 0.0041552038 | M24: =IF(J24="","",[1]!f_pq_pctchange($K$5,指数分析!$D$5,J24)/100) -> 0.092202234 | P24: 20 | Q24: =VLOOKUP(P24,topfield,3,FALSE) -> 801951.SI | R24: =Q24&VLOOKUP(P24,topfield,4,FALSE)&TEXT(S24,"0.0%") -> 801951.SI煤炭开采(申万)28.1% | S24: =VLOOKUP(P24,topfield,7,FALSE) -> 0.28056239 | X24: =IF(R24="","",[1]!s_risk_stdevy(LEFT(R24,FIND(".",R24)+2),指数分析!$D$5,指数分析!$D$6,2,1)) -> 23.269822
B25: =IF(E25="","",IF(COUNTIF(E$6:E25,E25)=1,RANK(E25,E:E,0),RANK(E25,E:E,0)+COUNTIF(E$6:E25,E25)-1)) -> 21 | C25: =IF(ROW()-ROW($C$5)>worldnums,"",ROW()-ROW($C$5)) -> 20 | D25: =IF(C25="","",VLOOKUP(C25,worldfield,2,FALSE)&VLOOKUP(C25,worldfield,3,FALSE)) -> FTSE.GI英国富时100 | E25: =IF(C25="","",[1]!f_pq_pctchange(VLOOKUP(C25,worldfield,2,FALSE),指数分析!$D$5,指数分析!$D$6)/100) -> 0.12136804 | F25: =IF(C25="","",VLOOKUP(C25,B:E,3,FALSE)) -> KLSE.GI富时马来西亚综指 | G25: =IF(C25="","",VLOOKUP(C25,B:E,4,FALSE)) -> 0.14729247 | H25: =IF(C25="","",F25&":"&TEXT(G25,"0.0%")) -> KLSE.GI富时马来西亚综指:14.7% | I25: =IF(H25="","",[1]!s_risk_stdevy(LEFT(H25,FIND(".",H25)+2),指数分析!$D$5,指数分析!$D$6,2,1)) -> 7.2064578 | J25: =IF(J24="","",IF([1]!td(J24-IF(指数分析!$D$7="日",1,IF(指数分析!$D$7="周",7,30)))-指数分析!$D$5>=0,--[1]!td(J24-IF(指数分析!$D$7="日",1,IF(指数分析!$D$7="周",7,30))),"")) -> 45330 | K25: =IF(J25="","",[1]!f_dq_close($K$5,J25)) -> 1198.53 | L25: =IF(J25="","",[1]!f_pq_pctchange($K$5,J25,J25)/100) -> 0 | M25: =IF(J25="","",[1]!f_pq_pctchange($K$5,指数分析!$D$5,J25)/100) -> 0.064205928 | P25: =MAX(rawdate!A:A)-19 -> 478 | Q25: =VLOOKUP(P25,topfield,3,FALSE) -> 801156.SI | R25: =Q25&VLOOKUP(P25,topfield,4,FALSE)&TEXT(S25,"0.0%") -> 801156.SI医疗服务(申万)-40.4% | S25: =VLOOKUP(P25,topfield,7,FALSE) -> -0.40400988 | X25: =IF(R25="","",[1]!s_risk_stdevy(LEFT(R25,FIND(".",R25)+2),指数分析!$D$5,指数分析!$D$6,2,1)) -> 30.457177
B26: =IF(E26="","",IF(COUNTIF(E$6:E26,E26)=1,RANK(E26,E:E,0),RANK(E26,E:E,0)+COUNTIF(E$6:E26,E26)-1)) -> 16 | C26: =IF(ROW()-ROW($C$5)>worldnums,"",ROW()-ROW($C$5)) -> 21 | D26: =IF(C26="","",VLOOKUP(C26,worldfield,2,FALSE)&VLOOKUP(C26,worldfield,3,FALSE)) -> GDAXI.GI德国DAX | E26: =IF(C26="","",[1]!f_pq_pctchange(VLOOKUP(C26,worldfield,2,FALSE),指数分析!$D$5,指数分析!$D$6)/100) -> 0.17431838 | F26: =IF(C26="","",VLOOKUP(C26,B:E,3,FALSE)) -> FTSE.GI英国富时100 | G26: =IF(C26="","",VLOOKUP(C26,B:E,4,FALSE)) -> 0.12136804 | H26: =IF(C26="","",F26&":"&TEXT(G26,"0.0%")) -> FTSE.GI英国富时100:12.1% | I26: =IF(H26="","",[1]!s_risk_stdevy(LEFT(H26,FIND(".",H26)+2),指数分析!$D$5,指数分析!$D$6,2,1)) -> 10.951168 | J26: =IF(J25="","",IF([1]!td(J25-IF(指数分析!$D$7="日",1,IF(指数分析!$D$7="周",7,30)))-指数分析!$D$5>=0,--[1]!td(J25-IF(指数分析!$D$7="日",1,IF(指数分析!$D$7="周",7,30))),"")) -> 45323 | K26: =IF(J26="","",[1]!f_dq_close($K$5,J26)) -> 1173.02 | L26: =IF(J26="","",[1]!f_pq_pctchange($K$5,J26,J26)/100) -> 0.0074808256 | M26: =IF(J26="","",[1]!f_pq_pctchange($K$5,指数分析!$D$5,J26)/100) -> 0.041554936 | P26: =MAX(rawdate!A:A)-18 -> 479 | Q26: =VLOOKUP(P26,topfield,3,FALSE) -> 801736.SI | R26: =Q26&VLOOKUP(P26,topfield,4,FALSE)&TEXT(S26,"0.0%") -> 801736.SI风电设备(申万)-40.6% | S26: =VLOOKUP(P26,topfield,7,FALSE) -> -0.40576849 | X26: =IF(R26="","",[1]!s_risk_stdevy(LEFT(R26,FIND(".",R26)+2),指数分析!$D$5,指数分析!$D$6,2,1)) -> 28.316564
B27: =IF(E27="","",IF(COUNTIF(E$6:E27,E27)=1,RANK(E27,E:E,0),RANK(E27,E:E,0)+COUNTIF(E$6:E27,E27)-1)) -> 36 | C27: =IF(ROW()-ROW($C$5)>worldnums,"",ROW()-ROW($C$5)) -> 22 | D27: =IF(C27="","",VLOOKUP(C27,worldfield,2,FALSE)&VLOOKUP(C27,worldfield,3,FALSE)) -> HEX.GI芬兰OMX全指 | E27: =IF(C27="","",[1]!f_pq_pctchange(VLOOKUP(C27,worldfield,2,FALSE),指数分析!$D$5,指数分析!$D$6)/100) -> 0.011399392 | F27: =IF(C27="","",VLOOKUP(C27,B:E,3,FALSE)) -> BFX.GI比利时BFX | G27: =IF(C27="","",VLOOKUP(C27,B:E,4,FALSE)) -> 0.11204435 | H27: =IF(C27="","",F27&":"&TEXT(G27,"0.0%")) -> BFX.GI比利时BFX:11.2% | I27: =IF(H27="","",[1]!s_risk_stdevy(LEFT(H27,FIND(".",H27)+2),指数分析!$D$5,指数分析!$D$6,2,1)) -> 15.412277 | J27: =IF(J26="","",IF([1]!td(J26-IF(指数分析!$D$7="日",1,IF(指数分析!$D$7="周",7,30)))-指数分析!$D$5>=0,--[1]!td(J26-IF(指数分析!$D$7="日",1,IF(指数分析!$D$7="周",7,30))),"")) -> 45316 | K27: =IF(J27="","",[1]!f_dq_close($K$5,J27)) -> 1170.37 | L27: =IF(J27="","",[1]!f_pq_pctchange($K$5,J27,J27)/100) -> -0.0022165955 | M27: =IF(J27="","",[1]!f_pq_pctchange($K$5,指数分析!$D$5,J27)/100) -> 0.039201932 | P27: =MAX(rawdate!A:A)-17 -> 480 | Q27: =VLOOKUP(P27,topfield,3,FALSE) -> 801994.SI | R27: =Q27&VLOOKUP(P27,topfield,4,FALSE)&TEXT(S27,"0.0%") -> 801994.SI教育(申万)-41.2% | S27: =VLOOKUP(P27,topfield,7,FALSE) -> -0.41199276 | X27: =IF(R27="","",[1]!s_risk_stdevy(LEFT(R27,FIND(".",R27)+2),指数分析!$D$5,指数分析!$D$6,2,1)) -> 39.959592
B28: =IF(E28="","",IF(COUNTIF(E$6:E28,E28)=1,RANK(E28,E:E,0),RANK(E28,E:E,0)+COUNTIF(E$6:E28,E28)-1)) -> 15 | C28: =IF(ROW()-ROW($C$5)>worldnums,"",ROW()-ROW($C$5)) -> 23 | D28: =IF(C28="","",VLOOKUP(C28,worldfield,2,FALSE)&VLOOKUP(C28,worldfield,3,FALSE)) -> IBEX.GI西班牙IBEX35 | E28: =IF(C28="","",[1]!f_pq_pctchange(VLOOKUP(C28,worldfield,2,FALSE),指数分析!$D$5,指数分析!$D$6)/100) -> 0.17864297 | F28: =IF(C28="","",VLOOKUP(C28,B:E,3,FALSE)) -> ISEQ.GI爱尔兰综指 | G28: =IF(C28="","",VLOOKUP(C28,B:E,4,FALSE)) -> 0.109367 | H28: =IF(C28="","",F28&":"&TEXT(G28,"0.0%")) -> ISEQ.GI爱尔兰综指:10.9% | I28: =IF(H28="","",[1]!s_risk_stdevy(LEFT(H28,FIND(".",H28)+2),指数分析!$D$5,指数分析!$D$6,2,1)) -> 16.197553 | J28: =IF(J27="","",IF([1]!td(J27-IF(指数分析!$D$7="日",1,IF(指数分析!$D$7="周",7,30)))-指数分析!$D$5>=0,--[1]!td(J27-IF(指数分析!$D$7="日",1,IF(指数分析!$D$7="周",7,30))),"")) -> 45309 | K28: =IF(J28="","",[1]!f_dq_close($K$5,J28)) -> 1169.06 | L28: =IF(J28="","",[1]!f_pq_pctchange($K$5,J28,J28)/100) -> 0.0056170593 | M28: =IF(J28="","",[1]!f_pq_pctchange($K$5,指数分析!$D$5,J28)/100) -> 0.038038749 | P28: =MAX(rawdate!A:A)-16 -> 481 | Q28: =VLOOKUP(P28,topfield,3,FALSE) -> 801219.SI | R28: =Q28&VLOOKUP(P28,topfield,4,FALSE)&TEXT(S28,"0.0%") -> 801219.SI酒店餐饮(申万)-41.4% | S28: =VLOOKUP(P28,topfield,7,FALSE) -> -0.4138595 | X28: =IF(R28="","",[1]!s_risk_stdevy(LEFT(R28,FIND(".",R28)+2),指数分析!$D$5,指数分析!$D$6,2,1)) -> 32.467305
B29: =IF(E29="","",IF(COUNTIF(E$6:E29,E29)=1,RANK(E29,E:E,0),RANK(E29,E:E,0)+COUNTIF(E$6:E29,E29)-1)) -> 23 | C29: =IF(ROW()-ROW($C$5)>worldnums,"",ROW()-ROW($C$5)) -> 24 | D29: =IF(C29="","",VLOOKUP(C29,worldfield,2,FALSE)&VLOOKUP(C29,worldfield,3,FALSE)) -> ISEQ.GI爱尔兰综指 | E29: =IF(C29="","",[1]!f_pq_pctchange(VLOOKUP(C29,worldfield,2,FALSE),指数分析!$D$5,指数分析!$D$6)/100) -> 0.109367 | F29: =IF(C29="","",VLOOKUP(C29,B:E,3,FALSE)) -> VNINDEX.GI胡志明指数 | G29: =IF(C29="","",VLOOKUP(C29,B:E,4,FALSE)) -> 0.10575198 | H29: =IF(C29="","",F29&":"&TEXT(G29,"0.0%")) -> VNINDEX.GI胡志明指数:10.6% | I29: =IF(H29="","",[1]!s_risk_stdevy(LEFT(H29,FIND(".",H29)+2),指数分析!$D$5,指数分析!$D$6,2,1)) -> 17.11782 | J29: =IF(J28="","",IF([1]!td(J28-IF(指数分析!$D$7="日",1,IF(指数分析!$D$7="周",7,30)))-指数分析!$D$5>=0,--[1]!td(J28-IF(指数分析!$D$7="日",1,IF(指数分析!$D$7="周",7,30))),"")) -> 45302 | K29: =IF(J29="","",[1]!f_dq_close($K$5,J29)) -> 1162.22 | L29: =IF(J29="","",[1]!f_pq_pctchange($K$5,J29,J29)/100) -> 0.00058542969 | M29: =IF(J29="","",[1]!f_pq_pctchange($K$5,指数分析!$D$5,J29)/100) -> 0.031965335 | P29: =MAX(rawdate!A:A)-15 -> 482 | Q29: =VLOOKUP(P29,topfield,3,FALSE) -> CI005825.WI | R29: =Q29&VLOOKUP(P29,topfield,4,FALSE)&TEXT(S29,"0.0%") -> CI005825.WI林业(中信)-41.7% | S29: =VLOOKUP(P29,topfield,7,FALSE) -> -0.41686496 | X29: =IF(R29="","",[1]!s_risk_stdevy(LEFT(R29,FIND(".",R29)+2),指数分析!$D$5,指数分析!$D$6,2,1)) -> 42.396525
B30: =IF(E30="","",IF(COUNTIF(E$6:E30,E30)=1,RANK(E30,E:E,0),RANK(E30,E:E,0)+COUNTIF(E$6:E30,E30)-1)) -> 31 | C30: =IF(ROW()-ROW($C$5)>worldnums,"",ROW()-ROW($C$5)) -> 25 | D30: =IF(C30="","",VLOOKUP(C30,worldfield,2,FALSE)&VLOOKUP(C30,worldfield,3,FALSE)) -> JALSH.GI南非富时综指 | E30: =IF(C30="","",[1]!f_pq_pctchange(VLOOKUP(C30,worldfield,2,FALSE),指数分析!$D$5,指数分析!$D$6)/100) -> 0.075477627 | F30: =IF(C30="","",VLOOKUP(C30,B:E,3,FALSE)) -> GSPTSE.GI加拿大S&P/TSX综合 | G30: =IF(C30="","",VLOOKUP(C30,B:E,4,FALSE)) -> 0.1042417 | H30: =IF(C30="","",F30&":"&TEXT(G30,"0.0%")) -> GSPTSE.GI加拿大S&P/TSX综合:10.4% | I30: =IF(H30="","",[1]!s_risk_stdevy(LEFT(H30,FIND(".",H30)+2),指数分析!$D$5,指数分析!$D$6,2,1)) -> 12.003382 | J30: =IF(J29="","",IF([1]!td(J29-IF(指数分析!$D$7="日",1,IF(指数分析!$D$7="周",7,30)))-指数分析!$D$5>=0,--[1]!td(J29-IF(指数分析!$D$7="日",1,IF(指数分析!$D$7="周",7,30))),"")) -> 45295 | K30: =IF(J30="","",[1]!f_dq_close($K$5,J30)) -> 1150.72 | L30: =IF(J30="","",[1]!f_pq_pctchange($K$5,J30,J30)/100) -> 0.0057246738 | M30: =IF(J30="","",[1]!f_pq_pctchange($K$5,指数分析!$D$5,J30)/100) -> 0.021754187 | P30: =MAX(rawdate!A:A)-14 -> 483 | Q30: =VLOOKUP(P30,topfield,3,FALSE) -> CI005816.WI | R30: =Q30&VLOOKUP(P30,topfield,4,FALSE)&TEXT(S30,"0.0%") -> CI005816.WI教育(中信)-43.0% | S30: =VLOOKUP(P30,topfield,7,FALSE) -> -0.42969896 | X30: =IF(R30="","",[1]!s_risk_stdevy(LEFT(R30,FIND(".",R30)+2),指数分析!$D$5,指数分析!$D$6,2,1)) -> 35.677845
B31: =IF(E31="","",IF(COUNTIF(E$6:E31,E31)=1,RANK(E31,E:E,0),RANK(E31,E:E,0)+COUNTIF(E$6:E31,E31)-1)) -> 3 | C31: =IF(ROW()-ROW($C$5)>worldnums,"",ROW()-ROW($C$5)) -> 26 | D31: =IF(C31="","",VLOOKUP(C31,worldfield,2,FALSE)&VLOOKUP(C31,worldfield,3,FALSE)) -> KAX.GI丹麦OMX20 | E31: =IF(C31="","",[1]!f_pq_pctchange(VLOOKUP(C31,worldfield,2,FALSE),指数分析!$D$5,指数分析!$D$6)/100) -> 0.43910266 | F31: =IF(C31="","",VLOOKUP(C31,B:E,3,FALSE)) -> ASE.GI希腊ASE综指 | G31: =IF(C31="","",VLOOKUP(C31,B:E,4,FALSE)) -> 0.097592622 | H31: =IF(C31="","",F31&":"&TEXT(G31,"0.0%")) -> ASE.GI希腊ASE综指:9.8% | I31: =IF(H31="","",[1]!s_risk_stdevy(LEFT(H31,FIND(".",H31)+2),指数分析!$D$5,指数分析!$D$6,2,1)) -> 14.984474 | J31: =IF(J30="","",IF([1]!td(J30-IF(指数分析!$D$7="日",1,IF(指数分析!$D$7="周",7,30)))-指数分析!$D$5>=0,--[1]!td(J30-IF(指数分析!$D$7="日",1,IF(指数分析!$D$7="周",7,30))),"")) -> 45288 | K31: =IF(J31="","",[1]!f_dq_close($K$5,J31)) -> 1128.93 | L31: =IF(J31="","",[1]!f_pq_pctchange($K$5,J31,J31)/100) -> 0.0061854384 | M31: =IF(J31="","",[1]!f_pq_pctchange($K$5,指数分析!$D$5,J31)/100) -> 0.0024062794 | P31: =MAX(rawdate!A:A)-13 -> 484 | Q31: =VLOOKUP(P31,topfield,3,FALSE) -> CI005144.WI | R31: =Q31&VLOOKUP(P31,topfield,4,FALSE)&TEXT(S31,"0.0%") -> CI005144.WI酒店及餐饮(中信)-43.2% | S31: =VLOOKUP(P31,topfield,7,FALSE) -> -0.43228689 | X31: =IF(R31="","",[1]!s_risk_stdevy(LEFT(R31,FIND(".",R31)+2),指数分析!$D$5,指数分析!$D$6,2,1)) -> 33.368234
B32: =IF(E32="","",IF(COUNTIF(E$6:E32,E32)=1,RANK(E32,E:E,0),RANK(E32,E:E,0)+COUNTIF(E$6:E32,E32)-1)) -> 42 | C32: =IF(ROW()-ROW($C$5)>worldnums,"",ROW()-ROW($C$5)) -> 27 | D32: =IF(C32="","",VLOOKUP(C32,worldfield,2,FALSE)&VLOOKUP(C32,worldfield,3,FALSE)) -> LUXXX.GI卢森堡LUXX | E32: =IF(C32="","",[1]!f_pq_pctchange(VLOOKUP(C32,worldfield,2,FALSE),指数分析!$D$5,指数分析!$D$6)/100) -> -0.036760436 | F32: =IF(C32="","",VLOOKUP(C32,B:E,3,FALSE)) -> KS11.GI韩国综合指数 | G32: =IF(C32="","",VLOOKUP(C32,B:E,4,FALSE)) -> 0.094484585 | H32: =IF(C32="","",F32&":"&TEXT(G32,"0.0%")) -> KS11.GI韩国综合指数:9.4% | I32: =IF(H32="","",[1]!s_risk_stdevy(LEFT(H32,FIND(".",H32)+2),指数分析!$D$5,指数分析!$D$6,2,1)) -> 14.884064 | J32: =IF(J31="","",IF([1]!td(J31-IF(指数分析!$D$7="日",1,IF(指数分析!$D$7="周",7,30)))-指数分析!$D$5>=0,--[1]!td(J31-IF(指数分析!$D$7="日",1,IF(指数分析!$D$7="周",7,30))),"")) -> 45281 | K32: =IF(J32="","",[1]!f_dq_close($K$5,J32)) -> 1102.43 | L32: =IF(J32="","",[1]!f_pq_pctchange($K$5,J32,J32)/100) -> 0.0015171336 | M32: =IF(J32="","",[1]!f_pq_pctchange($K$5,指数分析!$D$5,J32)/100) -> -0.021123759 | P32: =MAX(rawdate!A:A)-12 -> 485 | Q32: =VLOOKUP(P32,topfield,3,FALSE) -> 801104.SI | R32: =Q32&VLOOKUP(P32,topfield,4,FALSE)&TEXT(S32,"0.0%") -> 801104.SI软件开发(申万)-43.4% | S32: =VLOOKUP(P32,topfield,7,FALSE) -> -0.43418669 | X32: =IF(R32="","",[1]!s_risk_stdevy(LEFT(R32,FIND(".",R32)+2),指数分析!$D$5,指数分析!$D$6,2,1)) -> 34.178577
B33: =IF(E33="","",IF(COUNTIF(E$6:E33,E33)=1,RANK(E33,E:E,0),RANK(E33,E:E,0)+COUNTIF(E$6:E33,E33)-1)) -> 14 | C33: =IF(ROW()-ROW($C$5)>worldnums,"",ROW()-ROW($C$5)) -> 28 | D33: =IF(C33="","",VLOOKUP(C33,worldfield,2,FALSE)&VLOOKUP(C33,worldfield,3,FALSE)) -> OMXSPI.GI瑞典OMX全指 | E33: =IF(C33="","",[1]!f_pq_pctchange(VLOOKUP(C33,worldfield,2,FALSE),指数分析!$D$5,指数分析!$D$6)/100) -> 0.18316319 | F33: =IF(C33="","",VLOOKUP(C33,B:E,3,FALSE)) -> SSMI.GI瑞士SMI | G33: =IF(C33="","",VLOOKUP(C33,B:E,4,FALSE)) -> 0.091660159 | H33: =IF(C33="","",F33&":"&TEXT(G33,"0.0%")) -> SSMI.GI瑞士SMI:9.2% | I33: =IF(H33="","",[1]!s_risk_stdevy(LEFT(H33,FIND(".",H33)+2),指数分析!$D$5,指数分析!$D$6,2,1)) -> 11.339105 | J33: =IF(J32="","",IF([1]!td(J32-IF(指数分析!$D$7="日",1,IF(指数分析!$D$7="周",7,30)))-指数分析!$D$5>=0,--[1]!td(J32-IF(指数分析!$D$7="日",1,IF(指数分析!$D$7="周",7,30))),"")) -> 45274 | K33: =IF(J33="","",[1]!f_dq_close($K$5,J33)) -> 1110.13 | L33: =IF(J33="","",[1]!f_pq_pctchange($K$5,J33,J33)/100) -> -0.0036528451 | M33: =IF(J33="","",[1]!f_pq_pctchange($K$5,指数分析!$D$5,J33)/100) -> -0.014286729 | P33: =MAX(rawdate!A:A)-11 -> 486 | Q33: =VLOOKUP(P33,topfield,3,FALSE) -> 801092.SI | R33: =Q33&VLOOKUP(P33,topfield,4,FALSE)&TEXT(S33,"0.0%") -> 801092.SI汽车服务(申万)-43.8% | S33: =VLOOKUP(P33,topfield,7,FALSE) -> -0.43823391 | X33: =IF(R33="","",[1]!s_risk_stdevy(LEFT(R33,FIND(".",R33)+2),指数分析!$D$5,指数分析!$D$6,2,1)) -> 31.196028
B34: =IF(E34="","",IF(COUNTIF(E$6:E34,E34)=1,RANK(E34,E:E,0),RANK(E34,E:E,0)+COUNTIF(E$6:E34,E34)-1)) -> 9 | C34: =IF(ROW()-ROW($C$5)>worldnums,"",ROW()-ROW($C$5)) -> 29 | D34: =IF(C34="","",VLOOKUP(C34,worldfield,2,FALSE)&VLOOKUP(C34,worldfield,3,FALSE)) -> OSEAX.GI挪威OSEAX | E34: =IF(C34="","",[1]!f_pq_pctchange(VLOOKUP(C34,worldfield,2,FALSE),指数分析!$D$5,指数分析!$D$6)/100) -> 0.2102724 | F34: =IF(C34="","",VLOOKUP(C34,B:E,3,FALSE)) -> TA125.GI以色列TA125 | G34: =IF(C34="","",VLOOKUP(C34,B:E,4,FALSE)) -> 0.090589923 | H34: =IF(C34="","",F34&":"&TEXT(G34,"0.0%")) -> TA125.GI以色列TA125:9.1% | I34: =IF(H34="","",[1]!s_risk_stdevy(LEFT(H34,FIND(".",H34)+2),指数分析!$D$5,指数分析!$D$6,2,1)) -> 13.853068 | J34: =IF(J33="","",IF([1]!td(J33-IF(指数分析!$D$7="日",1,IF(指数分析!$D$7="周",7,30)))-指数分析!$D$5>=0,--[1]!td(J33-IF(指数分析!$D$7="日",1,IF(指数分析!$D$7="周",7,30))),"")) -> 45267 | K34: =IF(J34="","",[1]!f_dq_close($K$5,J34)) -> 1121.49 | L34: =IF(J34="","",[1]!f_pq_pctchange($K$5,J34,J34)/100) -> -0.0043855366 | M34: =IF(J34="","",[1]!f_pq_pctchange($K$5,指数分析!$D$5,J34)/100) -> -0.0041998899 | P34: =MAX(rawdate!A:A)-10 -> 487 | Q34: =VLOOKUP(P34,topfield,3,FALSE) -> 801722.SI | R34: =Q34&VLOOKUP(P34,topfield,4,FALSE)&TEXT(S34,"0.0%") -> 801722.SI装修装饰Ⅱ(申万)-43.9% | S34: =VLOOKUP(P34,topfield,7,FALSE) -> -0.43867987 | X34: =IF(R34="","",[1]!s_risk_stdevy(LEFT(R34,FIND(".",R34)+2),指数分析!$D$5,指数分析!$D$6,2,1)) -> 32.741632
B35: =IF(E35="","",IF(COUNTIF(E$6:E35,E35)=1,RANK(E35,E:E,0),RANK(E35,E:E,0)+COUNTIF(E$6:E35,E35)-1)) -> 11 | C35: =IF(ROW()-ROW($C$5)>worldnums,"",ROW()-ROW($C$5)) -> 30 | D35: =IF(C35="","",VLOOKUP(C35,worldfield,2,FALSE)&VLOOKUP(C35,worldfield,3,FALSE)) -> PX.GI布拉格综指 | E35: =IF(C35="","",[1]!f_pq_pctchange(VLOOKUP(C35,worldfield,2,FALSE),指数分析!$D$5,指数分析!$D$6)/100) -> 0.20217275 | F35: =IF(C35="","",VLOOKUP(C35,B:E,3,FALSE)) -> AS51.GI澳洲标普200 | G35: =IF(C35="","",VLOOKUP(C35,B:E,4,FALSE)) -> 0.084679728 | H35: =IF(C35="","",F35&":"&TEXT(G35,"0.0%")) -> AS51.GI澳洲标普200:8.5% | I35: =IF(H35="","",[1]!s_risk_stdevy(LEFT(H35,FIND(".",H35)+2),指数分析!$D$5,指数分析!$D$6,2,1)) -> 11.196407 | J35: =IF(J34="","",IF([1]!td(J34-IF(指数分析!$D$7="日",1,IF(指数分析!$D$7="周",7,30)))-指数分析!$D$5>=0,--[1]!td(J34-IF(指数分析!$D$7="日",1,IF(指数分析!$D$7="周",7,30))),"")) -> 45260 | K35: =IF(J35="","",[1]!f_dq_close($K$5,J35)) -> 1094.13 | L35: =IF(J35="","",[1]!f_pq_pctchange($K$5,J35,J35)/100) -> -0.0078618063 | M35: =IF(J35="","",[1]!f_pq_pctchange($K$5,指数分析!$D$5,J35)/100) -> -0.028493545 | P35: =MAX(rawdate!A:A)-9 -> 488 | Q35: =VLOOKUP(P35,topfield,3,FALSE) -> 801206.SI | R35: =Q35&VLOOKUP(P35,topfield,4,FALSE)&TEXT(S35,"0.0%") -> 801206.SI互联网电商(申万)-44.6% | S35: =VLOOKUP(P35,topfield,7,FALSE) -> -0.44626872 | X35: =IF(R35="","",[1]!s_risk_stdevy(LEFT(R35,FIND(".",R35)+2),指数分析!$D$5,指数分析!$D$6,2,1)) -> 36.827171
B36: =IF(E36="","",IF(COUNTIF(E$6:E36,E36)=1,RANK(E36,E:E,0),RANK(E36,E:E,0)+COUNTIF(E$6:E36,E36)-1)) -> 13 | C36: =IF(ROW()-ROW($C$5)>worldnums,"",ROW()-ROW($C$5)) -> 31 | D36: =IF(C36="","",VLOOKUP(C36,worldfield,2,FALSE)&VLOOKUP(C36,worldfield,3,FALSE)) -> RTSI.GIRTS指数 | E36: =IF(C36="","",[1]!f_pq_pctchange(VLOOKUP(C36,worldfield,2,FALSE),指数分析!$D$5,指数分析!$D$6)/100) -> 0.19354639 | F36: =IF(C36="","",VLOOKUP(C36,B:E,3,FALSE)) -> JALSH.GI南非富时综指 | G36: =IF(C36="","",VLOOKUP(C36,B:E,4,FALSE)) -> 0.075477627 | H36: =IF(C36="","",F36&":"&TEXT(G36,"0.0%")) -> JALSH.GI南非富时综指:7.5% | I36: =IF(H36="","",[1]!s_risk_stdevy(LEFT(H36,FIND(".",H36)+2),指数分析!$D$5,指数分析!$D$6,2,1)) -> 15.668177 | J36: =IF(J35="","",IF([1]!td(J35-IF(指数分析!$D$7="日",1,IF(指数分析!$D$7="周",7,30)))-指数分析!$D$5>=0,--[1]!td(J35-IF(指数分析!$D$7="日",1,IF(指数分析!$D$7="周",7,30))),"")) -> 45253 | K36: =IF(J36="","",[1]!f_dq_close($K$5,J36)) -> 1088.49 | L36: =IF(J36="","",[1]!f_pq_pctchange($K$5,J36,J36)/100) -> -0.022741556 | M36: =IF(J36="","",[1]!f_pq_pctchange($K$5,指数分析!$D$5,J36)/100) -> -0.033501447 | P36: =MAX(rawdate!A:A)-8 -> 489 | Q36: =VLOOKUP(P36,topfield,3,FALSE) -> 801764.SI | R36: =Q36&VLOOKUP(P36,topfield,4,FALSE)&TEXT(S36,"0.0%") -> 801764.SI游戏Ⅱ(申万)-44.8% | S36: =VLOOKUP(P36,topfield,7,FALSE) -> -0.44837223 | X36: =IF(R36="","",[1]!s_risk_stdevy(LEFT(R36,FIND(".",R36)+2),指数分析!$D$5,指数分析!$D$6,2,1)) -> 37.858282
B37: =IF(E37="","",IF(COUNTIF(E$6:E37,E37)=1,RANK(E37,E:E,0),RANK(E37,E:E,0)+COUNTIF(E$6:E37,E37)-1)) -> 28 | C37: =IF(ROW()-ROW($C$5)>worldnums,"",ROW()-ROW($C$5)) -> 32 | D37: =IF(C37="","",VLOOKUP(C37,worldfield,2,FALSE)&VLOOKUP(C37,worldfield,3,FALSE)) -> SSMI.GI瑞士SMI | E37: =IF(C37="","",[1]!f_pq_pctchange(VLOOKUP(C37,worldfield,2,FALSE),指数分析!$D$5,指数分析!$D$6)/100) -> 0.091660159 | F37: =IF(C37="","",VLOOKUP(C37,B:E,3,FALSE)) -> STI.GI富时新加坡海峡指数 | G37: =IF(C37="","",VLOOKUP(C37,B:E,4,FALSE)) -> 0.057887336 | H37: =IF(C37="","",F37&":"&TEXT(G37,"0.0%")) -> STI.GI富时新加坡海峡指数:5.8% | I37: =IF(H37="","",[1]!s_risk_stdevy(LEFT(H37,FIND(".",H37)+2),指数分析!$D$5,指数分析!$D$6,2,1)) -> 11.289745 | J37: =IF(J36="","",IF([1]!td(J36-IF(指数分析!$D$7="日",1,IF(指数分析!$D$7="周",7,30)))-指数分析!$D$5>=0,--[1]!td(J36-IF(指数分析!$D$7="日",1,IF(指数分析!$D$7="周",7,30))),"")) -> 45246 | K37: =IF(J37="","",[1]!f_dq_close($K$5,J37)) -> 1125.53 | L37: =IF(J37="","",[1]!f_pq_pctchange($K$5,J37,J37)/100) -> 0.0026993318 | M37: =IF(J37="","",[1]!f_pq_pctchange($K$5,指数分析!$D$5,J37)/100) -> -0.00061266893 | P37: =MAX(rawdate!A:A)-7 -> 490 | Q37: =VLOOKUP(P37,topfield,3,FALSE) -> CI005809.WI | R37: =Q37&VLOOKUP(P37,topfield,4,FALSE)&TEXT(S37,"0.0%") -> CI005809.WI电源设备(中信)-45.0% | S37: =VLOOKUP(P37,topfield,7,FALSE) -> -0.4499155 | X37: =IF(R37="","",[1]!s_risk_stdevy(LEFT(R37,FIND(".",R37)+2),指数分析!$D$5,指数分析!$D$6,2,1)) -> 27.300252
B38: =IF(E38="","",IF(COUNTIF(E$6:E38,E38)=1,RANK(E38,E:E,0),RANK(E38,E:E,0)+COUNTIF(E$6:E38,E38)-1)) -> 18 | C38: =IF(ROW()-ROW($C$5)>worldnums,"",ROW()-ROW($C$5)) -> 33 | D38: =IF(C38="","",VLOOKUP(C38,worldfield,2,FALSE)&VLOOKUP(C38,worldfield,3,FALSE)) -> SX5P.GI欧洲STOXX50(欧元)(退市) | E38: =IF(C38="","",[1]!f_pq_pctchange(VLOOKUP(C38,worldfield,2,FALSE),指数分析!$D$5,指数分析!$D$6)/100) -> 0.16118532 | F38: =IF(C38="","",VLOOKUP(C38,B:E,3,FALSE)) -> FCHI.GI法国CAC40 | G38: =IF(C38="","",VLOOKUP(C38,B:E,4,FALSE)) -> 0.056070847 | H38: =IF(C38="","",F38&":"&TEXT(G38,"0.0%")) -> FCHI.GI法国CAC40:5.6% | I38: =IF(H38="","",[1]!s_risk_stdevy(LEFT(H38,FIND(".",H38)+2),指数分析!$D$5,指数分析!$D$6,2,1)) -> 13.447935 | J38: =IF(J37="","",IF([1]!td(J37-IF(指数分析!$D$7="日",1,IF(指数分析!$D$7="周",7,30)))-指数分析!$D$5>=0,--[1]!td(J37-IF(指数分析!$D$7="日",1,IF(指数分析!$D$7="周",7,30))),"")) -> 45239 | K38: =IF(J38="","",[1]!f_dq_close($K$5,J38)) -> 1113.89 | L38: =IF(J38="","",[1]!f_pq_pctchange($K$5,J38,J38)/100) -> 0.00041313778 | M38: =IF(J38="","",[1]!f_pq_pctchange($K$5,指数分析!$D$5,J38)/100) -> -0.010948127 | P38: =MAX(rawdate!A:A)-6 -> 491 | Q38: =VLOOKUP(P38,topfield,3,FALSE) -> CI005196.WI | R38: =Q38&VLOOKUP(P38,topfield,4,FALSE)&TEXT(S38,"0.0%") -> CI005196.WI建筑装修Ⅱ(中信)-45.0% | S38: =VLOOKUP(P38,topfield,7,FALSE) -> -0.45039056 | X38: =IF(R38="","",[1]!s_risk_stdevy(LEFT(R38,FIND(".",R38)+2),指数分析!$D$5,指数分析!$D$6,2,1)) -> 33.730782
B39: =IF(E39="","",IF(COUNTIF(E$6:E39,E39)=1,RANK(E39,E:E,0),RANK(E39,E:E,0)+COUNTIF(E$6:E39,E39)-1)) -> 29 | C39: =IF(ROW()-ROW($C$5)>worldnums,"",ROW()-ROW($C$5)) -> 34 | D39: =IF(C39="","",VLOOKUP(C39,worldfield,2,FALSE)&VLOOKUP(C39,worldfield,3,FALSE)) -> TA125.GI以色列TA125 | E39: =IF(C39="","",[1]!f_pq_pctchange(VLOOKUP(C39,worldfield,2,FALSE),指数分析!$D$5,指数分析!$D$6)/100) -> 0.090589923 | F39: =IF(C39="","",VLOOKUP(C39,B:E,3,FALSE)) -> IBOVESPA.GI巴西IBOVESPA指数 | G39: =IF(C39="","",VLOOKUP(C39,B:E,4,FALSE)) -> 0.05519107 | H39: =IF(C39="","",F39&":"&TEXT(G39,"0.0%")) -> IBOVESPA.GI巴西IBOVESPA指数:5.5% | I39: =IF(H39="","",[1]!s_risk_stdevy(LEFT(H39,FIND(".",H39)+2),指数分析!$D$5,指数分析!$D$6,2,1)) -> 12.120657 | J39: =IF(J38="","",IF([1]!td(J38-IF(指数分析!$D$7="日",1,IF(指数分析!$D$7="周",7,30)))-指数分析!$D$5>=0,--[1]!td(J38-IF(指数分析!$D$7="日",1,IF(指数分析!$D$7="周",7,30))),"")) -> 45232 | K39: =IF(J39="","",[1]!f_dq_close($K$5,J39)) -> 1075.47 | L39: =IF(J39="","",[1]!f_pq_pctchange($K$5,J39,J39)/100) -> 0.034443953 | M39: =IF(J39="","",[1]!f_pq_pctchange($K$5,指数分析!$D$5,J39)/100) -> -0.045062244 | P39: =MAX(rawdate!A:A)-5 -> 492 | Q39: =VLOOKUP(P39,topfield,3,FALSE) -> CI005817.WI | R39: =Q39&VLOOKUP(P39,topfield,4,FALSE)&TEXT(S39,"0.0%") -> CI005817.WI综合服务(中信)-46.1% | S39: =VLOOKUP(P39,topfield,7,FALSE) -> -0.46128005 | X39: =IF(R39="","",[1]!s_risk_stdevy(LEFT(R39,FIND(".",R39)+2),指数分析!$D$5,指数分析!$D$6,2,1)) -> 29.157069
B40: =IF(E40="","",IF(COUNTIF(E$6:E40,E40)=1,RANK(E40,E:E,0),RANK(E40,E:E,0)+COUNTIF(E$6:E40,E40)-1)) -> 30 | C40: =IF(ROW()-ROW($C$5)>worldnums,"",ROW()-ROW($C$5)) -> 35 | D40: =IF(C40="","",VLOOKUP(C40,worldfield,2,FALSE)&VLOOKUP(C40,worldfield,3,FALSE)) -> AS51.GI澳洲标普200 | E40: =IF(C40="","",[1]!f_pq_pctchange(VLOOKUP(C40,worldfield,2,FALSE),指数分析!$D$5,指数分析!$D$6)/100) -> 0.084679728 | F40: =IF(C40="","",VLOOKUP(C40,B:E,3,FALSE)) -> JKSE.GI印尼综指 | G40: =IF(C40="","",VLOOKUP(C40,B:E,4,FALSE)) -> 0.045320556 | H40: =IF(C40="","",F40&":"&TEXT(G40,"0.0%")) -> JKSE.GI印尼综指:4.5% | I40: =IF(H40="","",[1]!s_risk_stdevy(LEFT(H40,FIND(".",H40)+2),指数分析!$D$5,指数分析!$D$6,2,1)) -> 9.6756233 | J40: =IF(J39="","",IF([1]!td(J39-IF(指数分析!$D$7="日",1,IF(指数分析!$D$7="周",7,30)))-指数分析!$D$5>=0,--[1]!td(J39-IF(指数分析!$D$7="日",1,IF(指数分析!$D$7="周",7,30))),"")) -> 45225 | K40: =IF(J40="","",[1]!f_dq_close($K$5,J40)) -> 1055.45 | L40: =IF(J40="","",[1]!f_pq_pctchange($K$5,J40,J40)/100) -> -0.048166586 | M40: =IF(J40="","",[1]!f_pq_pctchange($K$5,指数分析!$D$5,J40)/100) -> -0.062838522 | P40: =MAX(rawdate!A:A)-4 -> 493 | Q40: =VLOOKUP(P40,topfield,3,FALSE) -> 801056.SI | R40: =Q40&VLOOKUP(P40,topfield,4,FALSE)&TEXT(S40,"0.0%") -> 801056.SI能源金属(申万)-46.2% | S40: =VLOOKUP(P40,topfield,7,FALSE) -> -0.46238181 | X40: =IF(R40="","",[1]!s_risk_stdevy(LEFT(R40,FIND(".",R40)+2),指数分析!$D$5,指数分析!$D$6,2,1)) -> 35.116292
B41: =IF(E41="","",IF(COUNTIF(E$6:E41,E41)=1,RANK(E41,E:E,0),RANK(E41,E:E,0)+COUNTIF(E$6:E41,E41)-1)) -> 38 | C41: =IF(ROW()-ROW($C$5)>worldnums,"",ROW()-ROW($C$5)) -> 36 | D41: =IF(C41="","",VLOOKUP(C41,worldfield,2,FALSE)&VLOOKUP(C41,worldfield,3,FALSE)) -> BLOM.GI贝鲁特BLOM | E41: =IF(C41="","",[1]!f_pq_pctchange(VLOOKUP(C41,worldfield,2,FALSE),指数分析!$D$5,指数分析!$D$6)/100) -> -0.0049050262 | F41: =IF(C41="","",VLOOKUP(C41,B:E,3,FALSE)) -> HEX.GI芬兰OMX全指 | G41: =IF(C41="","",VLOOKUP(C41,B:E,4,FALSE)) -> 0.011399392 | H41: =IF(C41="","",F41&":"&TEXT(G41,"0.0%")) -> HEX.GI芬兰OMX全指:1.1% | I41: =IF(H41="","",[1]!s_risk_stdevy(LEFT(H41,FIND(".",H41)+2),指数分析!$D$5,指数分析!$D$6,2,1)) -> 12.969204 | J41: =IF(J40="","",IF([1]!td(J40-IF(指数分析!$D$7="日",1,IF(指数分析!$D$7="周",7,30)))-指数分析!$D$5>=0,--[1]!td(J40-IF(指数分析!$D$7="日",1,IF(指数分析!$D$7="周",7,30))),"")) -> 45218 | K41: =IF(J41="","",[1]!f_dq_close($K$5,J41)) -> 1087.85 | L41: =IF(J41="","",[1]!f_pq_pctchange($K$5,J41,J41)/100) -> -0.020572612 | M41: =IF(J41="","",[1]!f_pq_pctchange($K$5,指数分析!$D$5,J41)/100) -> -0.03406972 | P41: =MAX(rawdate!A:A)-3 -> 494 | Q41: =VLOOKUP(P41,topfield,3,FALSE) -> CI005814.WI | R41: =Q41&VLOOKUP(P41,topfield,4,FALSE)&TEXT(S41,"0.0%") -> CI005814.WI电商及服务Ⅱ(中信)-46.4% | S41: =VLOOKUP(P41,topfield,7,FALSE) -> -0.46416229 | X41: =IF(R41="","",[1]!s_risk_stdevy(LEFT(R41,FIND(".",R41)+2),指数分析!$D$5,指数分析!$D$6,2,1)) -> 35.88994
B42: =IF(E42="","",IF(COUNTIF(E$6:E42,E42)=1,RANK(E42,E:E,0),RANK(E42,E:E,0)+COUNTIF(E$6:E42,E42)-1)) -> 35 | C42: =IF(ROW()-ROW($C$5)>worldnums,"",ROW()-ROW($C$5)) -> 37 | D42: =IF(C42="","",VLOOKUP(C42,worldfield,2,FALSE)&VLOOKUP(C42,worldfield,3,FALSE)) -> JKSE.GI印尼综指 | E42: =IF(C42="","",[1]!f_pq_pctchange(VLOOKUP(C42,worldfield,2,FALSE),指数分析!$D$5,指数分析!$D$6)/100) -> 0.045320556 | F42: =IF(C42="","",VLOOKUP(C42,B:E,3,FALSE)) -> SASEIDX.GI沙特全指 | G42: =IF(C42="","",VLOOKUP(C42,B:E,4,FALSE)) -> 0.0070348882 | H42: =IF(C42="","",F42&":"&TEXT(G42,"0.0%")) -> SASEIDX.GI沙特全指:0.7% | I42: =IF(H42="","",[1]!s_risk_stdevy(LEFT(H42,FIND(".",H42)+2),指数分析!$D$5,指数分析!$D$6,2,1)) -> 11.529692 | J42: =IF(J41="","",IF([1]!td(J41-IF(指数分析!$D$7="日",1,IF(指数分析!$D$7="周",7,30)))-指数分析!$D$5>=0,--[1]!td(J41-IF(指数分析!$D$7="日",1,IF(指数分析!$D$7="周",7,30))),"")) -> 45211 | K42: =IF(J42="","",[1]!f_dq_close($K$5,J42)) -> 1151.61 | L42: =IF(J42="","",[1]!f_pq_pctchange($K$5,J42,J42)/100) -> 0.00069516254 | M42: =IF(J42="","",[1]!f_pq_pctchange($K$5,指数分析!$D$5,J42)/100) -> 0.022544441 | P42: =MAX(rawdate!A:A)-2 -> 495 | Q42: =VLOOKUP(P42,topfield,3,FALSE) -> CI005139.WI | R42: =Q42&VLOOKUP(P42,topfield,4,FALSE)&TEXT(S42,"0.0%") -> CI005139.WI汽车销售及服务Ⅱ(中信)-48.5% | S42: =VLOOKUP(P42,topfield,7,FALSE) -> -0.48480068 | X42: =IF(R42="","",[1]!s_risk_stdevy(LEFT(R42,FIND(".",R42)+2),指数分析!$D$5,指数分析!$D$6,2,1)) -> 30.003158
B43: =IF(E43="","",IF(COUNTIF(E$6:E43,E43)=1,RANK(E43,E:E,0),RANK(E43,E:E,0)+COUNTIF(E$6:E43,E43)-1)) -> 20 | C43: =IF(ROW()-ROW($C$5)>worldnums,"",ROW()-ROW($C$5)) -> 38 | D43: =IF(C43="","",VLOOKUP(C43,worldfield,2,FALSE)&VLOOKUP(C43,worldfield,3,FALSE)) -> KLSE.GI富时马来西亚综指 | E43: =IF(C43="","",[1]!f_pq_pctchange(VLOOKUP(C43,worldfield,2,FALSE),指数分析!$D$5,指数分析!$D$6)/100) -> 0.14729247 | F43: =IF(C43="","",VLOOKUP(C43,B:E,3,FALSE)) -> BLOM.GI贝鲁特BLOM | G43: =IF(C43="","",VLOOKUP(C43,B:E,4,FALSE)) -> -0.0049050262 | H43: =IF(C43="","",F43&":"&TEXT(G43,"0.0%")) -> BLOM.GI贝鲁特BLOM:-0.5% | I43: =IF(H43="","",[1]!s_risk_stdevy(LEFT(H43,FIND(".",H43)+2),指数分析!$D$5,指数分析!$D$6,2,1)) -> 23.083261 | J43: =IF(J42="","",IF([1]!td(J42-IF(指数分析!$D$7="日",1,IF(指数分析!$D$7="周",7,30)))-指数分析!$D$5>=0,--[1]!td(J42-IF(指数分析!$D$7="日",1,IF(指数分析!$D$7="周",7,30))),"")) -> 45197 | K43: =IF(J43="","",[1]!f_dq_close($K$5,J43)) -> 1152.43 | L43: =IF(J43="","",[1]!f_pq_pctchange($K$5,J43,J43)/100) -> -0.0012306626 | M43: =IF(J43="","",[1]!f_pq_pctchange($K$5,指数分析!$D$5,J43)/100) -> 0.02327254 | P43: =MAX(rawdate!A:A)-1 -> 496 | Q43: =VLOOKUP(P43,topfield,3,FALSE) -> 801735.SI | R43: =Q43&VLOOKUP(P43,topfield,4,FALSE)&TEXT(S43,"0.0%") -> 801735.SI光伏设备(申万)-50.7% | S43: =VLOOKUP(P43,topfield,7,FALSE) -> -0.50680979 | X43: =IF(R43="","",[1]!s_risk_stdevy(LEFT(R43,FIND(".",R43)+2),指数分析!$D$5,指数分析!$D$6,2,1)) -> 31.606658
B44: =IF(E44="","",IF(COUNTIF(E$6:E44,E44)=1,RANK(E44,E:E,0),RANK(E44,E:E,0)+COUNTIF(E$6:E44,E44)-1)) -> 27 | C44: =IF(ROW()-ROW($C$5)>worldnums,"",ROW()-ROW($C$5)) -> 39 | D44: =IF(C44="","",VLOOKUP(C44,worldfield,2,FALSE)&VLOOKUP(C44,worldfield,3,FALSE)) -> KS11.GI韩国综合指数 | E44: =IF(C44="","",[1]!f_pq_pctchange(VLOOKUP(C44,worldfield,2,FALSE),指数分析!$D$5,指数分析!$D$6)/100) -> 0.094484585 | F44: =IF(C44="","",VLOOKUP(C44,B:E,3,FALSE)) -> PSI.GI马尼拉综指 | G44: =IF(C44="","",VLOOKUP(C44,B:E,4,FALSE)) -> -0.0096304443 | H44: =IF(C44="","",F44&":"&TEXT(G44,"0.0%")) -> PSI.GI马尼拉综指:-1.0% | I44: =IF(H44="","",[1]!s_risk_stdevy(LEFT(H44,FIND(".",H44)+2),指数分析!$D$5,指数分析!$D$6,2,1)) -> 13.877156 | J44: =IF(J43="","",IF([1]!td(J43-IF(指数分析!$D$7="日",1,IF(指数分析!$D$7="周",7,30)))-指数分析!$D$5>=0,--[1]!td(J43-IF(指数分析!$D$7="日",1,IF(指数分析!$D$7="周",7,30))),"")) -> 45190 | K44: =IF(J44="","",[1]!f_dq_close($K$5,J44)) -> 1218.56 | L44: =IF(J44="","",[1]!f_pq_pctchange($K$5,J44,J44)/100) -> -0.0061576857 | M44: =IF(J44="","",[1]!f_pq_pctchange($K$5,指数分析!$D$5,J44)/100) -> 0.081991085 | P44: =MAX(rawdate!A:A) -> 497 | Q44: =VLOOKUP(P44,topfield,3,FALSE) -> TWSE025.TW | R44: =Q44&VLOOKUP(P44,topfield,4,FALSE)&TEXT(S44,"0.0%") -> TWSE025.TW台湾综合行业指数-100.0% | S44: =VLOOKUP(P44,topfield,7,FALSE) -> -1 | X44: =IF(R44="","",[1]!s_risk_stdevy(LEFT(R44,FIND(".",R44)+2),指数分析!$D$5,指数分析!$D$6,2,1)) -> 0
B45: =IF(E45="","",IF(COUNTIF(E$6:E45,E45)=1,RANK(E45,E:E,0),RANK(E45,E:E,0)+COUNTIF(E$6:E45,E45)-1)) -> 10 | C45: =IF(ROW()-ROW($C$5)>worldnums,"",ROW()-ROW($C$5)) -> 40 | D45: =IF(C45="","",VLOOKUP(C45,worldfield,2,FALSE)&VLOOKUP(C45,worldfield,3,FALSE)) -> N225.GI日经225 | E45: =IF(C45="","",[1]!f_pq_pctchange(VLOOKUP(C45,worldfield,2,FALSE),指数分析!$D$5,指数分析!$D$6)/100) -> 0.2077947 | F45: =IF(C45="","",VLOOKUP(C45,B:E,3,FALSE)) -> NZ50.GI新西兰标普50 | G45: =IF(C45="","",VLOOKUP(C45,B:E,4,FALSE)) -> -0.013260776 | H45: =IF(C45="","",F45&":"&TEXT(G45,"0.0%")) -> NZ50.GI新西兰标普50:-1.3% | I45: =IF(H45="","",[1]!s_risk_stdevy(LEFT(H45,FIND(".",H45)+2),指数分析!$D$5,指数分析!$D$6,2,1)) -> 8.0851112 | J45: =IF(J44="","",IF([1]!td(J44-IF(指数分析!$D$7="日",1,IF(指数分析!$D$7="周",7,30)))-指数分析!$D$5>=0,--[1]!td(J44-IF(指数分析!$D$7="日",1,IF(指数分析!$D$7="周",7,30))),"")) -> 45183 | K45: =IF(J45="","",[1]!f_dq_close($K$5,J45)) -> 1229.58 | L45: =IF(J45="","",[1]!f_pq_pctchange($K$5,J45,J45)/100) -> -0.0086430702 | M45: =IF(J45="","",[1]!f_pq_pctchange($K$5,指数分析!$D$5,J45)/100) -> 0.09177603 | X45: =IF(R45="","",[1]!s_risk_stdevy(LEFT(R45,FIND(".",R45)+2),指数分析!$D$5,指数分析!$D$6,2,1))
B46: =IF(E46="","",IF(COUNTIF(E$6:E46,E46)=1,RANK(E46,E:E,0),RANK(E46,E:E,0)+COUNTIF(E$6:E46,E46)-1)) -> 40 | C46: =IF(ROW()-ROW($C$5)>worldnums,"",ROW()-ROW($C$5)) -> 41 | D46: =IF(C46="","",VLOOKUP(C46,worldfield,2,FALSE)&VLOOKUP(C46,worldfield,3,FALSE)) -> NZ50.GI新西兰标普50 | E46: =IF(C46="","",[1]!f_pq_pctchange(VLOOKUP(C46,worldfield,2,FALSE),指数分析!$D$5,指数分析!$D$6)/100) -> -0.013260776 | F46: =IF(C46="","",VLOOKUP(C46,B:E,3,FALSE)) -> MXX.GI墨西哥MXX | G46: =IF(C46="","",VLOOKUP(C46,B:E,4,FALSE)) -> -0.018118736 | H46: =IF(C46="","",F46&":"&TEXT(G46,"0.0%")) -> MXX.GI墨西哥MXX:-1.8% | I46: =IF(H46="","",[1]!s_risk_stdevy(LEFT(H46,FIND(".",H46)+2),指数分析!$D$5,指数分析!$D$6,2,1)) -> 13.841909 | J46: =IF(J45="","",IF([1]!td(J45-IF(指数分析!$D$7="日",1,IF(指数分析!$D$7="周",7,30)))-指数分析!$D$5>=0,--[1]!td(J45-IF(指数分析!$D$7="日",1,IF(指数分析!$D$7="周",7,30))),"")) -> 45176 | K46: =IF(J46="","",[1]!f_dq_close($K$5,J46)) -> 1243.14 | L46: =IF(J46="","",[1]!f_pq_pctchange($K$5,J46,J46)/100) -> -0.00069131833 | M46: =IF(J46="","",[1]!f_pq_pctchange($K$5,指数分析!$D$5,J46)/100) -> 0.10381631 | X46: =IF(R46="","",[1]!s_risk_stdevy(LEFT(R46,FIND(".",R46)+2),指数分析!$D$5,指数分析!$D$6,2,1))
B47: =IF(E47="","",IF(COUNTIF(E$6:E47,E47)=1,RANK(E47,E:E,0),RANK(E47,E:E,0)+COUNTIF(E$6:E47,E47)-1)) -> 39 | C47: =IF(ROW()-ROW($C$5)>worldnums,"",ROW()-ROW($C$5)) -> 42 | D47: =IF(C47="","",VLOOKUP(C47,worldfield,2,FALSE)&VLOOKUP(C47,worldfield,3,FALSE)) -> PSI.GI马尼拉综指 | E47: =IF(C47="","",[1]!f_pq_pctchange(VLOOKUP(C47,worldfield,2,FALSE),指数分析!$D$5,指数分析!$D$6)/100) -> -0.0096304443 | F47: =IF(C47="","",VLOOKUP(C47,B:E,3,FALSE)) -> LUXXX.GI卢森堡LUXX | G47: =IF(C47="","",VLOOKUP(C47,B:E,4,FALSE)) -> -0.036760436 | H47: =IF(C47="","",F47&":"&TEXT(G47,"0.0%")) -> LUXXX.GI卢森堡LUXX:-3.7% | I47: =IF(H47="","",[1]!s_risk_stdevy(LEFT(H47,FIND(".",H47)+2),指数分析!$D$5,指数分析!$D$6,2,1)) -> 16.784159 | J47: =IF(J46="","",IF([1]!td(J46-IF(指数分析!$D$7="日",1,IF(指数分析!$D$7="周",7,30)))-指数分析!$D$5>=0,--[1]!td(J46-IF(指数分析!$D$7="日",1,IF(指数分析!$D$7="周",7,30))),"")) -> 45169 | K47: =IF(J47="","",[1]!f_dq_close($K$5,J47)) -> 1224.05 | L47: =IF(J47="","",[1]!f_pq_pctchange($K$5,J47,J47)/100) -> 0.0089765571 | M47: =IF(J47="","",[1]!f_pq_pctchange($K$5,指数分析!$D$5,J47)/100) -> 0.086865799 | X47: =IF(R47="","",[1]!s_risk_stdevy(LEFT(R47,FIND(".",R47)+2),指数分析!$D$5,指数分析!$D$6,2,1))
B48: =IF(E48="","",IF(COUNTIF(E$6:E48,E48)=1,RANK(E48,E:E,0),RANK(E48,E:E,0)+COUNTIF(E$6:E48,E48)-1)) -> 37 | C48: =IF(ROW()-ROW($C$5)>worldnums,"",ROW()-ROW($C$5)) -> 43 | D48: =IF(C48="","",VLOOKUP(C48,worldfield,2,FALSE)&VLOOKUP(C48,worldfield,3,FALSE)) -> SASEIDX.GI沙特全指 | E48: =IF(C48="","",[1]!f_pq_pctchange(VLOOKUP(C48,worldfield,2,FALSE),指数分析!$D$5,指数分析!$D$6)/100) -> 0.0070348882 | F48: =IF(C48="","",VLOOKUP(C48,B:E,3,FALSE)) -> HSI.HI恒生指数 | G48: =IF(C48="","",VLOOKUP(C48,B:E,4,FALSE)) -> -0.043945276 | H48: =IF(C48="","",F48&":"&TEXT(G48,"0.0%")) -> HSI.HI恒生指数:-4.4% | I48: =IF(H48="","",[1]!s_risk_stdevy(LEFT(H48,FIND(".",H48)+2),指数分析!$D$5,指数分析!$D$6,2,1)) -> 22.11651 | J48: =IF(J47="","",IF([1]!td(J47-IF(指数分析!$D$7="日",1,IF(指数分析!$D$7="周",7,30)))-指数分析!$D$5>=0,--[1]!td(J47-IF(指数分析!$D$7="日",1,IF(指数分析!$D$7="周",7,30))),"")) -> 45162 | K48: =IF(J48="","",[1]!f_dq_close($K$5,J48)) -> 1189.39 | L48: =IF(J48="","",[1]!f_pq_pctchange($K$5,J48,J48)/100) -> 0.01435321 | M48: =IF(J48="","",[1]!f_pq_pctchange($K$5,指数分析!$D$5,J48)/100) -> 0.056090284 | X48: =IF(R48="","",[1]!s_risk_stdevy(LEFT(R48,FIND(".",R48)+2),指数分析!$D$5,指数分析!$D$6,2,1))
...

Sheet rawdate
A4: 排序 | B4: world序号 | C4: 指数代码 | D4: 指数名称 | E4: 地区-行业-规模-风格 | F4: =IF(指数分析!D4="沪深","沪深基准",指数分析!D4) -> 全球 | G4: 涨幅 | J4: 全球 | K4: =COUNTA(J:J)-1 -> 5 | L4: 主要市场 | M4: =COUNTA(L:L)-1 -> 2 | N4: 行业类型 | O4: =COUNTA(N:N)-1 -> 8 | P4: 规模类型 | Q4: =COUNTA(P:P)-1 -> 4 | R4: 风格类型 | S4: =COUNTA(R:R)-1 -> 2
A5: =IF(G5="","",IF(COUNTIF(G$5:G5,G5)=1,RANK(G5,G:G,0),RANK(G5,G:G,0)+COUNTIF(G$5:G5,G5)-1)) -> 166 | B5: =IF(F5="","",RANK(F5,F:F,1)) -> 1 | C5: 000001.SH | D5: =[1]!s_info_name(C5) -> 上证指数 | E5: 全球-大中华；沪深基准 | F5: =IF(ISERROR(FIND(F$4,$E5,1)),"",ROW()) -> 5 | G5: =[1]!f_pq_pctchange(C5,指数分析!$D$5,指数分析!$D$6)/100 -> -0.074299311 | J5: 全球 | K5: =MAX(B:B) -> 47 | L5: 沪深 | N5: ="" | P5: ="" | R5: =""
A6: =IF(G6="","",IF(COUNTIF(G$5:G6,G6)=1,RANK(G6,G:G,0),RANK(G6,G:G,0)+COUNTIF(G$5:G6,G6)-1)) -> 293 | B6: =IF(F6="","",RANK(F6,F:F,1)) -> 2 | C6: 399001.SZ | D6: =[1]!s_info_name(C6) -> 深证成指 | E6: 全球-大中华；沪深基准 | F6: =IF(ISERROR(FIND(F$4,$E6,1)),"",ROW()) -> 6 | G6: =[1]!f_pq_pctchange(C6,指数分析!$D$5,指数分析!$D$6)/100 -> -0.19325301 | J6: 大中华 | K6: =COUNTA(B:B)-1 -> 546 | L6: 台湾 | N6: 中信一级 | P6: 巨潮规模 | R6: 巨潮风格
A7: =IF(G7="","",IF(COUNTIF(G$5:G7,G7)=1,RANK(G7,G:G,0),RANK(G7,G:G,0)+COUNTIF(G$5:G7,G7)-1)) -> 150 | B7: =IF(F7="","",RANK(F7,F:F,1)) -> 3 | C7: HSI.HI | D7: =[1]!s_info_name(C7) -> 恒生指数 | E7: 全球-大中华 | F7: =IF(ISERROR(FIND(F$4,$E7,1)),"",ROW()) -> 7 | G7: =[1]!f_pq_pctchange(C7,指数分析!$D$5,指数分析!$D$6)/100 -> -0.043945276 | J7: 美洲 | K7: =MAX(A:A) -> 497 | N7: 中信二级 | P7: 中证规模
A8: =IF(G8="","",IF(COUNTIF(G$5:G8,G8)=1,RANK(G8,G:G,0),RANK(G8,G:G,0)+COUNTIF(G$5:G8,G8)-1)) -> 15 | B8: =IF(F8="","",RANK(F8,F:F,1)) -> 4 | C8: TWII.TW | D8: =[1]!s_info_name(C8) -> 台湾加权指数 | E8: 全球-大中华 | F8: =IF(ISERROR(FIND(F$4,$E8,1)),"",ROW()) -> 8 | G8: =[1]!f_pq_pctchange(C8,指数分析!$D$5,指数分析!$D$6)/100 -> 0.37406135 | J8: 欧非中东 | N8: 申万一级 | P8: 申万规模
A9: =IF(G9="","",IF(COUNTIF(G$5:G9,G9)=1,RANK(G9,G:G,0),RANK(G9,G:G,0)+COUNTIF(G$5:G9,G9)-1)) -> 291 | B9: =IF(F9="","",RANK(F9,F:F,1)) -> 5 | C9: 899050.BJ | D9: =[1]!s_info_name(C9) -> 北证50 | E9: 全球-大中华 | F9: =IF(ISERROR(FIND(F$4,$E9,1)),"",ROW()) -> 9 | G9: =[1]!f_pq_pctchange(C9,指数分析!$D$5,指数分析!$D$6)/100 -> -0.19312021 | J9: 亚太 | N9: 申万二级
A10: =IF(G10="","",IF(COUNTIF(G$5:G10,G10)=1,RANK(G10,G:G,0),RANK(G10,G:G,0)+COUNTIF(G$5:G10,G10)-1)) -> 10 | B10: =IF(F10="","",RANK(F10,F:F,1)) -> 6 | C10: 8884057.WI | D10: =[1]!s_info_name(C10) -> TAMAMA科技指数 | E10: 全球-美洲 | F10: =IF(ISERROR(FIND(F$4,$E10,1)),"",ROW()) -> 10 | G10: =[1]!f_pq_pctchange(C10,指数分析!$D$5,指数分析!$D$6)/100 -> 0.42971903 | N10: wind一级
A11: =IF(G11="","",IF(COUNTIF(G$5:G11,G11)=1,RANK(G11,G:G,0),RANK(G11,G:G,0)+COUNTIF(G$5:G11,G11)-1)) -> 53 | B11: =IF(F11="","",RANK(F11,F:F,1)) -> 7 | C11: DJI.GI | D11: =[1]!s_info_name(C11) -> 道琼斯工业指数 | E11: 全球-美洲 | F11: =IF(ISERROR(FIND(F$4,$E11,1)),"",ROW()) -> 11 | G11: =[1]!f_pq_pctchange(C11,指数分析!$D$5,指数分析!$D$6)/100 -> 0.15319144 | N11: wind二级
A12: =IF(G12="","",IF(COUNTIF(G$5:G12,G12)=1,RANK(G12,G:G,0),RANK(G12,G:G,0)+COUNTIF(G$5:G12,G12)-1)) -> 71 | B12: =IF(F12="","",RANK(F12,F:F,1)) -> 8 | C12: GSPTSE.GI | D12: =[1]!s_info_name(C12) -> 加拿大S&P/TSX综合 | E12: 全球-美洲 | F12: =IF(ISERROR(FIND(F$4,$E12,1)),"",ROW()) -> 12 | G12: =[1]!f_pq_pctchange(C12,指数分析!$D$5,指数分析!$D$6)/100 -> 0.1042417 | N12: 台湾；行业
A13: =IF(G13="","",IF(COUNTIF(G$5:G13,G13)=1,RANK(G13,G:G,0),RANK(G13,G:G,0)+COUNTIF(G$5:G13,G13)-1)) -> 93 | B13: =IF(F13="","",RANK(F13,F:F,1)) -> 9 | C13: IBOVESPA.GI | D13: =[1]!s_info_name(C13) -> 巴西IBOVESPA指数 | E13: 全球-美洲 | F13: =IF(ISERROR(FIND(F$4,$E13,1)),"",ROW()) -> 13 | G13: =[1]!f_pq_pctchange(C13,指数分析!$D$5,指数分析!$D$6)/100 -> 0.05519107
A14: =IF(G14="","",IF(COUNTIF(G$5:G14,G14)=1,RANK(G14,G:G,0),RANK(G14,G:G,0)+COUNTIF(G$5:G14,G14)-1)) -> 2 | B14: =IF(F14="","",RANK(F14,F:F,1)) -> 10 | C14: IBVC.GI | D14: =[1]!s_info_name(C14) -> 委内瑞拉IBC | E14: 全球-美洲 | F14: =IF(ISERROR(FIND(F$4,$E14,1)),"",ROW()) -> 14 | G14: =[1]!f_pq_pctchange(C14,指数分析!$D$5,指数分析!$D$6)/100 -> 1.288498
A15: =IF(G15="","",IF(COUNTIF(G$5:G15,G15)=1,RANK(G15,G:G,0),RANK(G15,G:G,0)+COUNTIF(G$5:G15,G15)-1)) -> 19 | B15: =IF(F15="","",RANK(F15,F:F,1)) -> 11 | C15: IXIC.GI | D15: =[1]!s_info_name(C15) -> 纳斯达克指数 | E15: 全球-美洲 | F15: =IF(ISERROR(FIND(F$4,$E15,1)),"",ROW()) -> 15 | G15: =[1]!f_pq_pctchange(C15,指数分析!$D$5,指数分析!$D$6)/100 -> 0.29633366
