Workbook
Name Bubble: "Bubble"
Name Chart: "Chart"
Name Heatmap: "Heatmap"
Name Histogram: "Histogram"
Name Map: "Map"
Name PieChart: "PieChart"
Name Scatter: "Scatter"
Name Series: "Series"
Name Table: "Table"

Sheet 全行业vs全A季累营收
C1: 全行业 | D1: 全部非金融行业 | E1: 全A营收季累同比（右轴）
B2: 45260 | C2: 0.40299098 | D2: 0.39266272 | E2: #N/A
B3: 45230 | C3: 0.40846521 | D3: 0.39702903 | E3: #N/A
B4: 45199 | C4: 0.40568481 | D4: 0.39352271 | E4: 0.011691
B5: 45169 | C5: 0.38654449 | D5: 0.36786218 | E5: #N/A
B6: 45138 | C6: 0.36663919 | D6: 0.3443694 | E6: #N/A
B7: 45107 | C7: 0.36253525 | D7: 0.33854718 | E7: 0.01365
B8: 45077 | C8: 0.38350771 | D8: 0.36381014 | E8: #N/A
B9: 45046 | C9: 0.3793763 | D9: 0.36078027 | E9: #N/A
B10: 45016 | C10: 0.37777582 | D10: 0.35963576 | E10: 0.018708
B11: 44985 | C11: 0.33396517 | D11: 0.31291272 | E11: #N/A
B12: 44957 | C12: 0.31499302 | D12: 0.29377035 | E12: #N/A
B13: 44926 | C13: 0.30731759 | D13: 0.28350565 | E13: 0.071806
B14: 44895 | C14: 0.33301453 | D14: 0.31384457 | E14: #N/A
B15: 44865 | C15: 0.34876071 | D15: 0.33388393 | E15: #N/A
B16: 44834 | C16: 0.36281271 | D16: 0.35247154 | E16: 0.085554
B17: 44804 | C17: 0.36433901 | D17: 0.35373099 | E17: #N/A
B18: 44773 | C18: 0.37034735 | D18: 0.35773937 | E18: #N/A
B19: 44742 | C19: 0.36250265 | D19: 0.35302877 | E19: 0.093098
B20: 44712 | C20: 0.36553946 | D20: 0.35837592 | E20: #N/A
B21: 44681 | C21: 0.38324265 | D21: 0.38288156 | E21: #N/A
B22: 44651 | C22: 0.42450623 | D22: 0.42890064 | E22: 0.121342
B23: 44620 | C23: 0.46851336 | D23: 0.47834714 | E23: #N/A
B24: 44592 | C24: 0.50212224 | D24: 0.51635929 | E24: #N/A
B25: 44561 | C25: 0.51064684 | D25: 0.52399777 | E25: 0.192332
B26: 44530 | C26: 0.53209755 | D26: 0.5382992 | E26: #N/A
B27: 44500 | C27: 0.54165502 | D27: 0.55300428 | E27: #N/A
B28: 44469 | C28: 0.54965187 | D28: 0.56386055 | E28: 0.233109
B29: 44439 | C29: 0.53925161 | D29: 0.55579579 | E29: #N/A
B30: 44408 | C30: 0.53934841 | D30: 0.55622287 | E30: #N/A
B31: 44377 | C31: 0.5534033 | D31: 0.57077013 | E31: 0.269793
B32: 44347 | C32: 0.56742179 | D32: 0.58309501 | E32: #N/A
B33: 44316 | C33: 0.57830313 | D33: 0.5891569 | E33: #N/A
B34: 44286 | C34: 0.58394866 | D34: 0.5944296 | E34: 0.316118
B35: 44255 | C35: 0.57924482 | D35: 0.58408109 | E35: #N/A
B36: 44227 | C36: 0.5567736 | D36: 0.55814149 | E36: #N/A
B37: 44196 | C37: 0.47593493 | D37: 0.46531519 | E37: 0.03758
B38: 44165 | C38: 0.42755875 | D38: 0.41488498 | E38: #N/A
B39: 44135 | C39: 0.39546685 | D39: 0.38134149 | E39: #N/A
B40: 44104 | C40: 0.3547226 | D40: 0.33649621 | E40: 0.013846
...

Sheet 面板-总览
A1: 一级行业 | R1: 二级行业 | AI1: 三级行业
A2: 景气指数 | B2: 44895 | C2: 44926 | D2: 44957 | E2: 44985 | F2: 45016 | G2: 45046 | H2: 45077 | I2: 45107 | J2: 45138 | K2: 45169 | L2: 45199 | M2: 45230 | N2: 45260 | O2: 3M变化 | R2: 景气指数 | S2: 44895 | T2: 44926 | U2: 44957 | V2: 44985 | W2: 45016 | X2: 45046 | Y2: 45077 | Z2: 45107 | AA2: 45138 | AB2: 45169 | AC2: 45199 | AD2: 45230 | AE2: 45260 | AF2: 3M变化 | AI2: 景气指数 | AJ2: 44895 | AK2: 44926 | AL2: 44957 | AM2: 44985 | AN2: 45016 | AO2: 45046 | AP2: 45077 | AQ2: 45107 | AR2: 45138 | AS2: 45169 | AT2: 45199 | AU2: 45230 | AV2: 45260 | AW2: 3M变化
A3: 石油石化 | B3: =INDEX('面板-景气指数'!$37:$242,MATCH('面板-总览'!$A3,'面板-景气指数'!$A$37:$A$242,0),MATCH('面板-总览'!B$2,'面板-景气指数'!$36:$36,0)) -> 0.5681 | C3: =INDEX('面板-景气指数'!$37:$242,MATCH('面板-总览'!$A3,'面板-景气指数'!$A$37:$A$242,0),MATCH('面板-总览'!C$2,'面板-景气指数'!$36:$36,0)) -> 0.5428 | D3: =INDEX('面板-景气指数'!$37:$242,MATCH('面板-总览'!$A3,'面板-景气指数'!$A$37:$A$242,0),MATCH('面板-总览'!D$2,'面板-景气指数'!$36:$36,0)) -> 0.60375 | E3: =INDEX('面板-景气指数'!$37:$242,MATCH('面板-总览'!$A3,'面板-景气指数'!$A$37:$A$242,0),MATCH('面板-总览'!E$2,'面板-景气指数'!$36:$36,0)) -> 0.64545 | F3: =INDEX('面板-景气指数'!$37:$242,MATCH('面板-总览'!$A3,'面板-景气指数'!$A$37:$A$242,0),MATCH('面板-总览'!F$2,'面板-景气指数'!$36:$36,0)) -> 0.78815 | G3: =INDEX('面板-景气指数'!$37:$242,MATCH('面板-总览'!$A3,'面板-景气指数'!$A$37:$A$242,0),MATCH('面板-总览'!G$2,'面板-景气指数'!$36:$36,0)) -> 0.78095 | H3: =INDEX('面板-景气指数'!$37:$242,MATCH('面板-总览'!$A3,'面板-景气指数'!$A$37:$A$242,0),MATCH('面板-总览'!H$2,'面板-景气指数'!$36:$36,0)) -> 0.75055 | I3: =INDEX('面板-景气指数'!$37:$242,MATCH('面板-总览'!$A3,'面板-景气指数'!$A$37:$A$242,0),MATCH('面板-总览'!I$2,'面板-景气指数'!$36:$36,0)) -> 0.6088 | ... N3: =INDEX('面板-景气指数'!$37:$242,MATCH('面板-总览'!$A3,'面板-景气指数'!$A$37:$A$242,0),MATCH('面板-总览'!N$2,'面板-景气指数'!$36:$36,0)) -> 0.63245 | P3: =N3-K3 -> -0.11015 | R3: 油气开采/油服工程 | S3: =INDEX('面板-景气指数'!$37:$242,MATCH('面板-总览'!$R3,'面板-景气指数'!$A$37:$A$242,0),MATCH('面板-总览'!S$2,'面板-景气指数'!$36:$36,0)) -> 0.72969231 | T3: =INDEX('面板-景气指数'!$37:$242,MATCH('面板-总览'!$R3,'面板-景气指数'!$A$37:$A$242,0),MATCH('面板-总览'!T$2,'面板-景气指数'!$36:$36,0)) -> 0.71930769 | U3: =INDEX('面板-景气指数'!$37:$242,MATCH('面板-总览'!$R3,'面板-景气指数'!$A$37:$A$242,0),MATCH('面板-总览'!U$2,'面板-景气指数'!$36:$36,0)) -> 0.70323077 | V3: =INDEX('面板-景气指数'!$37:$242,MATCH('面板-总览'!$R3,'面板-景气指数'!$A$37:$A$242,0),MATCH('面板-总览'!V$2,'面板-景气指数'!$36:$36,0)) -> 0.692 | W3: =INDEX('面板-景气指数'!$37:$242,MATCH('面板-总览'!$R3,'面板-景气指数'!$A$37:$A$242,0),MATCH('面板-总览'!W$2,'面板-景气指数'!$36:$36,0)) -> 0.68592308 | X3: =INDEX('面板-景气指数'!$37:$242,MATCH('面板-总览'!$R3,'面板-景气指数'!$A$37:$A$242,0),MATCH('面板-总览'!X$2,'面板-景气指数'!$36:$36,0)) -> 0.663 | Y3: =INDEX('面板-景气指数'!$37:$242,MATCH('面板-总览'!$R3,'面板-景气指数'!$A$37:$A$242,0),MATCH('面板-总览'!Y$2,'面板-景气指数'!$36:$36,0)) -> 0.62215385 | Z3: =INDEX('面板-景气指数'!$37:$242,MATCH('面板-总览'!$R3,'面板-景气指数'!$A$37:$A$242,0),MATCH('面板-总览'!Z$2,'面板-景气指数'!$36:$36,0)) -> 0.66738462 | ... AE3: =INDEX('面板-景气指数'!$37:$242,MATCH('面板-总览'!$R3,'面板-景气指数'!$A$37:$A$242,0),MATCH('面板-总览'!AE$2,'面板-景气指数'!$36:$36,0)) -> 0.68384615 | AG3: =AE3-AB3 -> -0.065 | AI3: 铜 | AJ3: =INDEX('面板-景气指数'!$37:$242,MATCH('面板-总览'!$AI3,'面板-景气指数'!$A$37:$A$242,0),MATCH('面板-总览'!AJ$2,'面板-景气指数'!$36:$36,0)) -> 0.159 | AK3: =INDEX('面板-景气指数'!$37:$242,MATCH('面板-总览'!$AI3,'面板-景气指数'!$A$37:$A$242,0),MATCH('面板-总览'!AK$2,'面板-景气指数'!$36:$36,0)) -> 0.308 | AL3: =INDEX('面板-景气指数'!$37:$242,MATCH('面板-总览'!$AI3,'面板-景气指数'!$A$37:$A$242,0),MATCH('面板-总览'!AL$2,'面板-景气指数'!$36:$36,0)) -> 0.404 | AM3: =INDEX('面板-景气指数'!$37:$242,MATCH('面板-总览'!$AI3,'面板-景气指数'!$A$37:$A$242,0),MATCH('面板-总览'!AM$2,'面板-景气指数'!$36:$36,0)) -> 0.372 | AN3: =INDEX('面板-景气指数'!$37:$242,MATCH('面板-总览'!$AI3,'面板-景气指数'!$A$37:$A$242,0),MATCH('面板-总览'!AN$2,'面板-景气指数'!$36:$36,0)) -> 0.297 | AO3: =INDEX('面板-景气指数'!$37:$242,MATCH('面板-总览'!$AI3,'面板-景气指数'!$A$37:$A$242,0),MATCH('面板-总览'!AO$2,'面板-景气指数'!$36:$36,0)) -> 0.202 | AP3: =INDEX('面板-景气指数'!$37:$242,MATCH('面板-总览'!$AI3,'面板-景气指数'!$A$37:$A$242,0),MATCH('面板-总览'!AP$2,'面板-景气指数'!$36:$36,0)) -> 0.276 | AQ3: =INDEX('面板-景气指数'!$37:$242,MATCH('面板-总览'!$AI3,'面板-景气指数'!$A$37:$A$242,0),MATCH('面板-总览'!AQ$2,'面板-景气指数'!$36:$36,0)) -> 0.478 | ... AV3: =INDEX('面板-景气指数'!$37:$242,MATCH('面板-总览'!$AI3,'面板-景气指数'!$A$37:$A$242,0),MATCH('面板-总览'!AV$2,'面板-景气指数'!$36:$36,0)) -> 0.5 | AX3: =AV3-AS3 -> -0.17
A4: 煤炭 | B4: =INDEX('面板-景气指数'!$37:$242,MATCH('面板-总览'!$A4,'面板-景气指数'!$A$37:$A$242,0),MATCH('面板-总览'!B$2,'面板-景气指数'!$36:$36,0)) -> 0.825 | C4: =INDEX('面板-景气指数'!$37:$242,MATCH('面板-总览'!$A4,'面板-景气指数'!$A$37:$A$242,0),MATCH('面板-总览'!C$2,'面板-景气指数'!$36:$36,0)) -> 0.8485 | D4: =INDEX('面板-景气指数'!$37:$242,MATCH('面板-总览'!$A4,'面板-景气指数'!$A$37:$A$242,0),MATCH('面板-总览'!D$2,'面板-景气指数'!$36:$36,0)) -> 0.81 | E4: =INDEX('面板-景气指数'!$37:$242,MATCH('面板-总览'!$A4,'面板-景气指数'!$A$37:$A$242,0),MATCH('面板-总览'!E$2,'面板-景气指数'!$36:$36,0)) -> 0.83983333 | F4: =INDEX('面板-景气指数'!$37:$242,MATCH('面板-总览'!$A4,'面板-景气指数'!$A$37:$A$242,0),MATCH('面板-总览'!F$2,'面板-景气指数'!$36:$36,0)) -> 0.84333333 | G4: =INDEX('面板-景气指数'!$37:$242,MATCH('面板-总览'!$A4,'面板-景气指数'!$A$37:$A$242,0),MATCH('面板-总览'!G$2,'面板-景气指数'!$36:$36,0)) -> 0.8305 | H4: =INDEX('面板-景气指数'!$37:$242,MATCH('面板-总览'!$A4,'面板-景气指数'!$A$37:$A$242,0),MATCH('面板-总览'!H$2,'面板-景气指数'!$36:$36,0)) -> 0.7695 | I4: =INDEX('面板-景气指数'!$37:$242,MATCH('面板-总览'!$A4,'面板-景气指数'!$A$37:$A$242,0),MATCH('面板-总览'!I$2,'面板-景气指数'!$36:$36,0)) -> 0.6895 | ... N4: =INDEX('面板-景气指数'!$37:$242,MATCH('面板-总览'!$A4,'面板-景气指数'!$A$37:$A$242,0),MATCH('面板-总览'!N$2,'面板-景气指数'!$36:$36,0)) -> 0.69716667 | P4: =N4-K4 -> 0.059833333 | R4: 炼化及贸易 | S4: =INDEX('面板-景气指数'!$37:$242,MATCH('面板-总览'!$R4,'面板-景气指数'!$A$37:$A$242,0),MATCH('面板-总览'!S$2,'面板-景气指数'!$36:$36,0)) -> 0.268 | T4: =INDEX('面板-景气指数'!$37:$242,MATCH('面板-总览'!$R4,'面板-景气指数'!$A$37:$A$242,0),MATCH('面板-总览'!T$2,'面板-景气指数'!$36:$36,0)) -> 0.215 | U4: =INDEX('面板-景气指数'!$37:$242,MATCH('面板-总览'!$R4,'面板-景气指数'!$A$37:$A$242,0),MATCH('面板-总览'!U$2,'面板-景气指数'!$36:$36,0)) -> 0.419 | V4: =INDEX('面板-景气指数'!$37:$242,MATCH('面板-总览'!$R4,'面板-景气指数'!$A$37:$A$242,0),MATCH('面板-总览'!V$2,'面板-景气指数'!$36:$36,0)) -> 0.559 | W4: =INDEX('面板-景气指数'!$37:$242,MATCH('面板-总览'!$R4,'面板-景气指数'!$A$37:$A$242,0),MATCH('面板-总览'!W$2,'面板-景气指数'!$36:$36,0)) -> 0.978 | X4: =INDEX('面板-景气指数'!$37:$242,MATCH('面板-总览'!$R4,'面板-景气指数'!$A$37:$A$242,0),MATCH('面板-总览'!X$2,'面板-景气指数'!$36:$36,0)) -> 1 | Y4: =INDEX('面板-景气指数'!$37:$242,MATCH('面板-总览'!$R4,'面板-景气指数'!$A$37:$A$242,0),MATCH('面板-总览'!Y$2,'面板-景气指数'!$36:$36,0)) -> 0.989 | Z4: =INDEX('面板-景气指数'!$37:$242,MATCH('面板-总览'!$R4,'面板-景气指数'!$A$37:$A$242,0),MATCH('面板-总览'!Z$2,'面板-景气指数'!$36:$36,0)) -> 0.5 | ... AE4: =INDEX('面板-景气指数'!$37:$242,MATCH('面板-总览'!$R4,'面板-景气指数'!$A$37:$A$242,0),MATCH('面板-总览'!AE$2,'面板-景气指数'!$36:$36,0)) -> 0.537 | AG4: =AE4-AB4 -> -0.194 | AI4: 铝 | AJ4: =INDEX('面板-景气指数'!$37:$242,MATCH('面板-总览'!$AI4,'面板-景气指数'!$A$37:$A$242,0),MATCH('面板-总览'!AJ$2,'面板-景气指数'!$36:$36,0)) -> 0.202 | AK4: =INDEX('面板-景气指数'!$37:$242,MATCH('面板-总览'!$AI4,'面板-景气指数'!$A$37:$A$242,0),MATCH('面板-总览'!AK$2,'面板-景气指数'!$36:$36,0)) -> 0.223 | AL4: =INDEX('面板-景气指数'!$37:$242,MATCH('面板-总览'!$AI4,'面板-景气指数'!$A$37:$A$242,0),MATCH('面板-总览'!AL$2,'面板-景气指数'!$36:$36,0)) -> 0.085 | AM4: =INDEX('面板-景气指数'!$37:$242,MATCH('面板-总览'!$AI4,'面板-景气指数'!$A$37:$A$242,0),MATCH('面板-总览'!AM$2,'面板-景气指数'!$36:$36,0)) -> 0.01 | AN4: =INDEX('面板-景气指数'!$37:$242,MATCH('面板-总览'!$AI4,'面板-景气指数'!$A$37:$A$242,0),MATCH('面板-总览'!AN$2,'面板-景气指数'!$36:$36,0)) -> 0.021 | AO4: =INDEX('面板-景气指数'!$37:$242,MATCH('面板-总览'!$AI4,'面板-景气指数'!$A$37:$A$242,0),MATCH('面板-总览'!AO$2,'面板-景气指数'!$36:$36,0)) -> 0.053 | AP4: =INDEX('面板-景气指数'!$37:$242,MATCH('面板-总览'!$AI4,'面板-景气指数'!$A$37:$A$242,0),MATCH('面板-总览'!AP$2,'面板-景气指数'!$36:$36,0)) -> 0.127 | AQ4: =INDEX('面板-景气指数'!$37:$242,MATCH('面板-总览'!$AI4,'面板-景气指数'!$A$37:$A$242,0),MATCH('面板-总览'!AQ$2,'面板-景气指数'!$36:$36,0)) -> 0.244 | ... AV4: =INDEX('面板-景气指数'!$37:$242,MATCH('面板-总览'!$AI4,'面板-景气指数'!$A$37:$A$242,0),MATCH('面板-总览'!AV$2,'面板-景气指数'!$36:$36,0)) -> 0.436 | AX4: =AV4-AS4 -> -0.01
A5: 有色金属 | B5: =INDEX('面板-景气指数'!$37:$242,MATCH('面板-总览'!$A5,'面板-景气指数'!$A$37:$A$242,0),MATCH('面板-总览'!B$2,'面板-景气指数'!$36:$36,0)) -> 0.33502201 | C5: =INDEX('面板-景气指数'!$37:$242,MATCH('面板-总览'!$A5,'面板-景气指数'!$A$37:$A$242,0),MATCH('面板-总览'!C$2,'面板-景气指数'!$36:$36,0)) -> 0.40476141 | D5: =INDEX('面板-景气指数'!$37:$242,MATCH('面板-总览'!$A5,'面板-景气指数'!$A$37:$A$242,0),MATCH('面板-总览'!D$2,'面板-景气指数'!$36:$36,0)) -> 0.41246195 | E5: =INDEX('面板-景气指数'!$37:$242,MATCH('面板-总览'!$A5,'面板-景气指数'!$A$37:$A$242,0),MATCH('面板-总览'!E$2,'面板-景气指数'!$36:$36,0)) -> 0.36255989 | F5: =INDEX('面板-景气指数'!$37:$242,MATCH('面板-总览'!$A5,'面板-景气指数'!$A$37:$A$242,0),MATCH('面板-总览'!F$2,'面板-景气指数'!$36:$36,0)) -> 0.30899881 | G5: =INDEX('面板-景气指数'!$37:$242,MATCH('面板-总览'!$A5,'面板-景气指数'!$A$37:$A$242,0),MATCH('面板-总览'!G$2,'面板-景气指数'!$36:$36,0)) -> 0.27583766 | H5: =INDEX('面板-景气指数'!$37:$242,MATCH('面板-总览'!$A5,'面板-景气指数'!$A$37:$A$242,0),MATCH('面板-总览'!H$2,'面板-景气指数'!$36:$36,0)) -> 0.31889132 | I5: =INDEX('面板-景气指数'!$37:$242,MATCH('面板-总览'!$A5,'面板-景气指数'!$A$37:$A$242,0),MATCH('面板-总览'!I$2,'面板-景气指数'!$36:$36,0)) -> 0.43705637 | ... N5: =INDEX('面板-景气指数'!$37:$242,MATCH('面板-总览'!$A5,'面板-景气指数'!$A$37:$A$242,0),MATCH('面板-总览'!N$2,'面板-景气指数'!$36:$36,0)) -> 0.51621997 | P5: =N5-K5 -> -0.069922501 | R5: 动力煤 | S5: =INDEX('面板-景气指数'!$37:$242,MATCH('面板-总览'!$R5,'面板-景气指数'!$A$37:$A$242,0),MATCH('面板-总览'!S$2,'面板-景气指数'!$36:$36,0)) -> 0.936 | T5: =INDEX('面板-景气指数'!$37:$242,MATCH('面板-总览'!$R5,'面板-景气指数'!$A$37:$A$242,0),MATCH('面板-总览'!T$2,'面板-景气指数'!$36:$36,0)) -> 0.989 | U5: =INDEX('面板-景气指数'!$37:$242,MATCH('面板-总览'!$R5,'面板-景气指数'!$A$37:$A$242,0),MATCH('面板-总览'!U$2,'面板-景气指数'!$36:$36,0)) -> 0.893 | V5: =INDEX('面板-景气指数'!$37:$242,MATCH('面板-总览'!$R5,'面板-景气指数'!$A$37:$A$242,0),MATCH('面板-总览'!V$2,'面板-景气指数'!$36:$36,0)) -> 0.872 | W5: =INDEX('面板-景气指数'!$37:$242,MATCH('面板-总览'!$R5,'面板-景气指数'!$A$37:$A$242,0),MATCH('面板-总览'!W$2,'面板-景气指数'!$36:$36,0)) -> 0.861 | X5: =INDEX('面板-景气指数'!$37:$242,MATCH('面板-总览'!$R5,'面板-景气指数'!$A$37:$A$242,0),MATCH('面板-总览'!X$2,'面板-景气指数'!$36:$36,0)) -> 0.84 | Y5: =INDEX('面板-景气指数'!$37:$242,MATCH('面板-总览'!$R5,'面板-景气指数'!$A$37:$A$242,0),MATCH('面板-总览'!Y$2,'面板-景气指数'!$36:$36,0)) -> 0.776 | Z5: =INDEX('面板-景气指数'!$37:$242,MATCH('面板-总览'!$R5,'面板-景气指数'!$A$37:$A$242,0),MATCH('面板-总览'!Z$2,'面板-景气指数'!$36:$36,0)) -> 0.67 | ... AE5: =INDEX('面板-景气指数'!$37:$242,MATCH('面板-总览'!$R5,'面板-景气指数'!$A$37:$A$242,0),MATCH('面板-总览'!AE$2,'面板-景气指数'!$36:$36,0)) -> 0.712 | AG5: =AE5-AB5 -> 0.074 | AI5: 铅锌 | AJ5: =INDEX('面板-景气指数'!$37:$242,MATCH('面板-总览'!$AI5,'面板-景气指数'!$A$37:$A$242,0),MATCH('面板-总览'!AJ$2,'面板-景气指数'!$36:$36,0)) -> 0.478 | AK5: =INDEX('面板-景气指数'!$37:$242,MATCH('面板-总览'!$AI5,'面板-景气指数'!$A$37:$A$242,0),MATCH('面板-总览'!AK$2,'面板-景气指数'!$36:$36,0)) -> 0.473 | AL5: =INDEX('面板-景气指数'!$37:$242,MATCH('面板-总览'!$AI5,'面板-景气指数'!$A$37:$A$242,0),MATCH('面板-总览'!AL$2,'面板-景气指数'!$36:$36,0)) -> 0.441 | AM5: =INDEX('面板-景气指数'!$37:$242,MATCH('面板-总览'!$AI5,'面板-景气指数'!$A$37:$A$242,0),MATCH('面板-总览'!AM$2,'面板-景气指数'!$36:$36,0)) -> 0.4035 | AN5: =INDEX('面板-景气指数'!$37:$242,MATCH('面板-总览'!$AI5,'面板-景气指数'!$A$37:$A$242,0),MATCH('面板-总览'!AN$2,'面板-景气指数'!$36:$36,0)) -> 0.313 | AO5: =INDEX('面板-景气指数'!$37:$242,MATCH('面板-总览'!$AI5,'面板-景气指数'!$A$37:$A$242,0),MATCH('面板-总览'!AO$2,'面板-景气指数'!$36:$36,0)) -> 0.2285 | AP5: =INDEX('面板-景气指数'!$37:$242,MATCH('面板-总览'!$AI5,'面板-景气指数'!$A$37:$A$242,0),MATCH('面板-总览'!AP$2,'面板-景气指数'!$36:$36,0)) -> 0.2335 | AQ5: =INDEX('面板-景气指数'!$37:$242,MATCH('面板-总览'!$AI5,'面板-景气指数'!$A$37:$A$242,0),MATCH('面板-总览'!AQ$2,'面板-景气指数'!$36:$36,0)) -> 0.324 | ... AV5: =INDEX('面板-景气指数'!$37:$242,MATCH('面板-总览'!$AI5,'面板-景气指数'!$A$37:$A$242,0),MATCH('面板-总览'!AV$2,'面板-景气指数'!$36:$36,0)) -> 0.51 | AX5: =AV5-AS5 -> 0.032
A6: 基础化工 | B6: =INDEX('面板-景气指数'!$37:$242,MATCH('面板-总览'!$A6,'面板-景气指数'!$A$37:$A$242,0),MATCH('面板-总览'!B$2,'面板-景气指数'!$36:$36,0)) -> 0.42497993 | C6: =INDEX('面板-景气指数'!$37:$242,MATCH('面板-总览'!$A6,'面板-景气指数'!$A$37:$A$242,0),MATCH('面板-总览'!C$2,'面板-景气指数'!$36:$36,0)) -> 0.4427579 | D6: =INDEX('面板-景气指数'!$37:$242,MATCH('面板-总览'!$A6,'面板-景气指数'!$A$37:$A$242,0),MATCH('面板-总览'!D$2,'面板-景气指数'!$36:$36,0)) -> 0.41965731 | E6: =INDEX('面板-景气指数'!$37:$242,MATCH('面板-总览'!$A6,'面板-景气指数'!$A$37:$A$242,0),MATCH('面板-总览'!E$2,'面板-景气指数'!$36:$36,0)) -> 0.35059498 | F6: =INDEX('面板-景气指数'!$37:$242,MATCH('面板-总览'!$A6,'面板-景气指数'!$A$37:$A$242,0),MATCH('面板-总览'!F$2,'面板-景气指数'!$36:$36,0)) -> 0.28251238 | G6: =INDEX('面板-景气指数'!$37:$242,MATCH('面板-总览'!$A6,'面板-景气指数'!$A$37:$A$242,0),MATCH('面板-总览'!G$2,'面板-景气指数'!$36:$36,0)) -> 0.19747851 | H6: =INDEX('面板-景气指数'!$37:$242,MATCH('面板-总览'!$A6,'面板-景气指数'!$A$37:$A$242,0),MATCH('面板-总览'!H$2,'面板-景气指数'!$36:$36,0)) -> 0.19373464 | I6: =INDEX('面板-景气指数'!$37:$242,MATCH('面板-总览'!$A6,'面板-景气指数'!$A$37:$A$242,0),MATCH('面板-总览'!I$2,'面板-景气指数'!$36:$36,0)) -> 0.2320715 | ... N6: =INDEX('面板-景气指数'!$37:$242,MATCH('面板-总览'!$A6,'面板-景气指数'!$A$37:$A$242,0),MATCH('面板-总览'!N$2,'面板-景气指数'!$36:$36,0)) -> 0.35494094 | P6: =N6-K6 -> 0.0030502845 | R6: 焦煤 | S6: =INDEX('面板-景气指数'!$37:$242,MATCH('面板-总览'!$R6,'面板-景气指数'!$A$37:$A$242,0),MATCH('面板-总览'!S$2,'面板-景气指数'!$36:$36,0)) -> 0.861 | T6: =INDEX('面板-景气指数'!$37:$242,MATCH('面板-总览'!$R6,'面板-景气指数'!$A$37:$A$242,0),MATCH('面板-总览'!T$2,'面板-景气指数'!$36:$36,0)) -> 0.851 | U6: =INDEX('面板-景气指数'!$37:$242,MATCH('面板-总览'!$R6,'面板-景气指数'!$A$37:$A$242,0),MATCH('面板-总览'!U$2,'面板-景气指数'!$36:$36,0)) -> 0.84 | V6: =INDEX('面板-景气指数'!$37:$242,MATCH('面板-总览'!$R6,'面板-景气指数'!$A$37:$A$242,0),MATCH('面板-总览'!V$2,'面板-景气指数'!$36:$36,0)) -> 0.819 | W6: =INDEX('面板-景气指数'!$37:$242,MATCH('面板-总览'!$R6,'面板-景气指数'!$A$37:$A$242,0),MATCH('面板-总览'!W$2,'面板-景气指数'!$36:$36,0)) -> 0.787 | X6: =INDEX('面板-景气指数'!$37:$242,MATCH('面板-总览'!$R6,'面板-景气指数'!$A$37:$A$242,0),MATCH('面板-总览'!X$2,'面板-景气指数'!$36:$36,0)) -> 0.776 | Y6: =INDEX('面板-景气指数'!$37:$242,MATCH('面板-总览'!$R6,'面板-景气指数'!$A$37:$A$242,0),MATCH('面板-总览'!Y$2,'面板-景气指数'!$36:$36,0)) -> 0.734 | Z6: =INDEX('面板-景气指数'!$37:$242,MATCH('面板-总览'!$R6,'面板-景气指数'!$A$37:$A$242,0),MATCH('面板-总览'!Z$2,'面板-景气指数'!$36:$36,0)) -> 0.68 | ... AE6: =INDEX('面板-景气指数'!$37:$242,MATCH('面板-总览'!$R6,'面板-景气指数'!$A$37:$A$242,0),MATCH('面板-总览'!AE$2,'面板-景气指数'!$36:$36,0)) -> 0.755 | AG6: =AE6-AB6 -> 0.138 | AI6: 黄金 | AJ6: =INDEX('面板-景气指数'!$37:$242,MATCH('面板-总览'!$AI6,'面板-景气指数'!$A$37:$A$242,0),MATCH('面板-总览'!AJ$2,'面板-景气指数'!$36:$36,0)) -> 0.148 | AK6: =INDEX('面板-景气指数'!$37:$242,MATCH('面板-总览'!$AI6,'面板-景气指数'!$A$37:$A$242,0),MATCH('面板-总览'!AK$2,'面板-景气指数'!$36:$36,0)) -> 0.329 | AL6: =INDEX('面板-景气指数'!$37:$242,MATCH('面板-总览'!$AI6,'面板-景气指数'!$A$37:$A$242,0),MATCH('面板-总览'!AL$2,'面板-景气指数'!$36:$36,0)) -> 0.393 | AM6: =INDEX('面板-景气指数'!$37:$242,MATCH('面板-总览'!$AI6,'面板-景气指数'!$A$37:$A$242,0),MATCH('面板-总览'!AM$2,'面板-景气指数'!$36:$36,0)) -> 0.361 | AN6: =INDEX('面板-景气指数'!$37:$242,MATCH('面板-总览'!$AI6,'面板-景气指数'!$A$37:$A$242,0),MATCH('面板-总览'!AN$2,'面板-景气指数'!$36:$36,0)) -> 0.351 | AO6: =INDEX('面板-景气指数'!$37:$242,MATCH('面板-总览'!$AI6,'面板-景气指数'!$A$37:$A$242,0),MATCH('面板-总览'!AO$2,'面板-景气指数'!$36:$36,0)) -> 0.457 | AP6: =INDEX('面板-景气指数'!$37:$242,MATCH('面板-总览'!$AI6,'面板-景气指数'!$A$37:$A$242,0),MATCH('面板-总览'!AP$2,'面板-景气指数'!$36:$36,0)) -> 0.553 | AQ6: =INDEX('面板-景气指数'!$37:$242,MATCH('面板-总览'!$AI6,'面板-景气指数'!$A$37:$A$242,0),MATCH('面板-总览'!AQ$2,'面板-景气指数'!$36:$36,0)) -> 0.648 | ... AV6: =INDEX('面板-景气指数'!$37:$242,MATCH('面板-总览'!$AI6,'面板-景气指数'!$A$37:$A$242,0),MATCH('面板-总览'!AV$2,'面板-景气指数'!$36:$36,0)) -> 0.765 | AX6: =AV6-AS6 -> 0.053
A7: 钢铁 | B7: =INDEX('面板-景气指数'!$37:$242,MATCH('面板-总览'!$A7,'面板-景气指数'!$A$37:$A$242,0),MATCH('面板-总览'!B$2,'面板-景气指数'!$36:$36,0)) -> 0.075298268 | C7: =INDEX('面板-景气指数'!$37:$242,MATCH('面板-总览'!$A7,'面板-景气指数'!$A$37:$A$242,0),MATCH('面板-总览'!C$2,'面板-景气指数'!$36:$36,0)) -> 0.088926921 | D7: =INDEX('面板-景气指数'!$37:$242,MATCH('面板-总览'!$A7,'面板-景气指数'!$A$37:$A$242,0),MATCH('面板-总览'!D$2,'面板-景气指数'!$36:$36,0)) -> 0.14488932 | E7: =INDEX('面板-景气指数'!$37:$242,MATCH('面板-总览'!$A7,'面板-景气指数'!$A$37:$A$242,0),MATCH('面板-总览'!E$2,'面板-景气指数'!$36:$36,0)) -> 0.20605129 | F7: =INDEX('面板-景气指数'!$37:$242,MATCH('面板-总览'!$A7,'面板-景气指数'!$A$37:$A$242,0),MATCH('面板-总览'!F$2,'面板-景气指数'!$36:$36,0)) -> 0.20569194 | G7: =INDEX('面板-景气指数'!$37:$242,MATCH('面板-总览'!$A7,'面板-景气指数'!$A$37:$A$242,0),MATCH('面板-总览'!G$2,'面板-景气指数'!$36:$36,0)) -> 0.14934464 | H7: =INDEX('面板-景气指数'!$37:$242,MATCH('面板-总览'!$A7,'面板-景气指数'!$A$37:$A$242,0),MATCH('面板-总览'!H$2,'面板-景气指数'!$36:$36,0)) -> 0.15276635 | I7: =INDEX('面板-景气指数'!$37:$242,MATCH('面板-总览'!$A7,'面板-景气指数'!$A$37:$A$242,0),MATCH('面板-总览'!I$2,'面板-景气指数'!$36:$36,0)) -> 0.22038271 | ... N7: =INDEX('面板-景气指数'!$37:$242,MATCH('面板-总览'!$A7,'面板-景气指数'!$A$37:$A$242,0),MATCH('面板-总览'!N$2,'面板-景气指数'!$36:$36,0)) -> 0.33945338 | P7: =N7-K7 -> -0.014449071 | R7: 无烟煤 | S7: =INDEX('面板-景气指数'!$37:$242,MATCH('面板-总览'!$R7,'面板-景气指数'!$A$37:$A$242,0),MATCH('面板-总览'!S$2,'面板-景气指数'!$36:$36,0)) -> 0.936 | T7: =INDEX('面板-景气指数'!$37:$242,MATCH('面板-总览'!$R7,'面板-景气指数'!$A$37:$A$242,0),MATCH('面板-总览'!T$2,'面板-景气指数'!$36:$36,0)) -> 0.946 | U7: =INDEX('面板-景气指数'!$37:$242,MATCH('面板-总览'!$R7,'面板-景气指数'!$A$37:$A$242,0),MATCH('面板-总览'!U$2,'面板-景气指数'!$36:$36,0)) -> 0.978 | V7: =INDEX('面板-景气指数'!$37:$242,MATCH('面板-总览'!$R7,'面板-景气指数'!$A$37:$A$242,0),MATCH('面板-总览'!V$2,'面板-景气指数'!$36:$36,0)) -> 0.968 | W7: =INDEX('面板-景气指数'!$37:$242,MATCH('面板-总览'!$R7,'面板-景气指数'!$A$37:$A$242,0),MATCH('面板-总览'!W$2,'面板-景气指数'!$36:$36,0)) -> 0.872 | X7: =INDEX('面板-景气指数'!$37:$242,MATCH('面板-总览'!$R7,'面板-景气指数'!$A$37:$A$242,0),MATCH('面板-总览'!X$2,'面板-景气指数'!$36:$36,0)) -> 0.797 | Y7: =INDEX('面板-景气指数'!$37:$242,MATCH('面板-总览'!$R7,'面板-景气指数'!$A$37:$A$242,0),MATCH('面板-总览'!Y$2,'面板-景气指数'!$36:$36,0)) -> 0.755 | Z7: =INDEX('面板-景气指数'!$37:$242,MATCH('面板-总览'!$R7,'面板-景气指数'!$A$37:$A$242,0),MATCH('面板-总览'!Z$2,'面板-景气指数'!$36:$36,0)) -> 0.702 | ... AE7: =INDEX('面板-景气指数'!$37:$242,MATCH('面板-总览'!$R7,'面板-景气指数'!$A$37:$A$242,0),MATCH('面板-总览'!AE$2,'面板-景气指数'!$36:$36,0)) -> 0.765 | AG7: =AE7-AB7 -> 0.053 | AI7: 白银 | AJ7: =INDEX('面板-景气指数'!$37:$242,MATCH('面板-总览'!$AI7,'面板-景气指数'!$A$37:$A$242,0),MATCH('面板-总览'!AJ$2,'面板-景气指数'!$36:$36,0)) -> 0.223 | AK7: =INDEX('面板-景气指数'!$37:$242,MATCH('面板-总览'!$AI7,'面板-景气指数'!$A$37:$A$242,0),MATCH('面板-总览'!AK$2,'面板-景气指数'!$36:$36,0)) -> 0.468 | AL7: =INDEX('面板-景气指数'!$37:$242,MATCH('面板-总览'!$AI7,'面板-景气指数'!$A$37:$A$242,0),MATCH('面板-总览'!AL$2,'面板-景气指数'!$36:$36,0)) -> 0.51 | AM7: =INDEX('面板-景气指数'!$37:$242,MATCH('面板-总览'!$AI7,'面板-景气指数'!$A$37:$A$242,0),MATCH('面板-总览'!AM$2,'面板-景气指数'!$36:$36,0)) -> 0.34 | AN7: =INDEX('面板-景气指数'!$37:$242,MATCH('面板-总览'!$AI7,'面板-景气指数'!$A$37:$A$242,0),MATCH('面板-总览'!AN$2,'面板-景气指数'!$36:$36,0)) -> 0.329 | AO7: =INDEX('面板-景气指数'!$37:$242,MATCH('面板-总览'!$AI7,'面板-景气指数'!$A$37:$A$242,0),MATCH('面板-总览'!AO$2,'面板-景气指数'!$36:$36,0)) -> 0.521 | AP7: =INDEX('面板-景气指数'!$37:$242,MATCH('面板-总览'!$AI7,'面板-景气指数'!$A$37:$A$242,0),MATCH('面板-总览'!AP$2,'面板-景气指数'!$36:$36,0)) -> 0.595 | AQ7: =INDEX('面板-景气指数'!$37:$242,MATCH('面板-总览'!$AI7,'面板-景气指数'!$A$37:$A$242,0),MATCH('面板-总览'!AQ$2,'面板-景气指数'!$36:$36,0)) -> 0.702 | ... AV7: =INDEX('面板-景气指数'!$37:$242,MATCH('面板-总览'!$AI7,'面板-景气指数'!$A$37:$A$242,0),MATCH('面板-总览'!AV$2,'面板-景气指数'!$36:$36,0)) -> 0.627 | AX7: =AV7-AS7 -> -0.213
A8: 建筑材料 | B8: =INDEX('面板-景气指数'!$37:$242,MATCH('面板-总览'!$A8,'面板-景气指数'!$A$37:$A$242,0),MATCH('面板-总览'!B$2,'面板-景气指数'!$36:$36,0)) -> 0.087214839 | C8: =INDEX('面板-景气指数'!$37:$242,MATCH('面板-总览'!$A8,'面板-景气指数'!$A$37:$A$242,0),MATCH('面板-总览'!C$2,'面板-景气指数'!$36:$36,0)) -> 0.092587174 | D8: =INDEX('面板-景气指数'!$37:$242,MATCH('面板-总览'!$A8,'面板-景气指数'!$A$37:$A$242,0),MATCH('面板-总览'!D$2,'面板-景气指数'!$36:$36,0)) -> 0.16430475 | E8: =INDEX('面板-景气指数'!$37:$242,MATCH('面板-总览'!$A8,'面板-景气指数'!$A$37:$A$242,0),MATCH('面板-总览'!E$2,'面板-景气指数'!$36:$36,0)) -> 0.23096377 | F8: =INDEX('面板-景气指数'!$37:$242,MATCH('面板-总览'!$A8,'面板-景气指数'!$A$37:$A$242,0),MATCH('面板-总览'!F$2,'面板-景气指数'!$36:$36,0)) -> 0.26288066 | G8: =INDEX('面板-景气指数'!$37:$242,MATCH('面板-总览'!$A8,'面板-景气指数'!$A$37:$A$242,0),MATCH('面板-总览'!G$2,'面板-景气指数'!$36:$36,0)) -> 0.27610237 | H8: =INDEX('面板-景气指数'!$37:$242,MATCH('面板-总览'!$A8,'面板-景气指数'!$A$37:$A$242,0),MATCH('面板-总览'!H$2,'面板-景气指数'!$36:$36,0)) -> 0.2530502 | I8: =INDEX('面板-景气指数'!$37:$242,MATCH('面板-总览'!$A8,'面板-景气指数'!$A$37:$A$242,0),MATCH('面板-总览'!I$2,'面板-景气指数'!$36:$36,0)) -> 0.2542023 | ... N8: =INDEX('面板-景气指数'!$37:$242,MATCH('面板-总览'!$A8,'面板-景气指数'!$A$37:$A$242,0),MATCH('面板-总览'!N$2,'面板-景气指数'!$36:$36,0)) -> 0.2779487 | P8: =N8-K8 -> 0.020865038 | R8: 工业金属 | S8: =INDEX('面板-景气指数'!$37:$242,MATCH('面板-总览'!$R8,'面板-景气指数'!$A$37:$A$242,0),MATCH('面板-总览'!S$2,'面板-景气指数'!$36:$36,0)) -> 0.32398416 | T8: =INDEX('面板-景气指数'!$37:$242,MATCH('面板-总览'!$R8,'面板-景气指数'!$A$37:$A$242,0),MATCH('面板-总览'!T$2,'面板-景气指数'!$36:$36,0)) -> 0.37910184 | U8: =INDEX('面板-景气指数'!$37:$242,MATCH('面板-总览'!$R8,'面板-景气指数'!$A$37:$A$242,0),MATCH('面板-总览'!U$2,'面板-景气指数'!$36:$36,0)) -> 0.38013127 | V8: =INDEX('面板-景气指数'!$37:$242,MATCH('面板-总览'!$R8,'面板-景气指数'!$A$37:$A$242,0),MATCH('面板-总览'!V$2,'面板-景气指数'!$36:$36,0)) -> 0.33967748 | W8: =INDEX('面板-景气指数'!$37:$242,MATCH('面板-总览'!$R8,'面板-景气指数'!$A$37:$A$242,0),MATCH('面板-总览'!W$2,'面板-景气指数'!$36:$36,0)) -> 0.26835364 | X8: =INDEX('面板-景气指数'!$37:$242,MATCH('面板-总览'!$R8,'面板-景气指数'!$A$37:$A$242,0),MATCH('面板-总览'!X$2,'面板-景气指数'!$36:$36,0)) -> 0.19545376 | Y8: =INDEX('面板-景气指数'!$37:$242,MATCH('面板-总览'!$R8,'面板-景气指数'!$A$37:$A$242,0),MATCH('面板-总览'!Y$2,'面板-景气指数'!$36:$36,0)) -> 0.2350021 | Z8: =INDEX('面板-景气指数'!$37:$242,MATCH('面板-总览'!$R8,'面板-景气指数'!$A$37:$A$242,0),MATCH('面板-总览'!Z$2,'面板-景气指数'!$36:$36,0)) -> 0.37004765 | ... AE8: =INDEX('面板-景气指数'!$37:$242,MATCH('面板-总览'!$R8,'面板-景气指数'!$A$37:$A$242,0),MATCH('面板-总览'!AE$2,'面板-景气指数'!$36:$36,0)) -> 0.49649789 | AG8: =AE8-AB8 -> -0.047903749 | AI8: 稀土 | AJ8: =INDEX('面板-景气指数'!$37:$242,MATCH('面板-总览'!$AI8,'面板-景气指数'!$A$37:$A$242,0),MATCH('面板-总览'!AJ$2,'面板-景气指数'!$36:$36,0)) -> 0.872 | AK8: =INDEX('面板-景气指数'!$37:$242,MATCH('面板-总览'!$AI8,'面板-景气指数'!$A$37:$A$242,0),MATCH('面板-总览'!AK$2,'面板-景气指数'!$36:$36,0)) -> 0.882 | AL8: =INDEX('面板-景气指数'!$37:$242,MATCH('面板-总览'!$AI8,'面板-景气指数'!$A$37:$A$242,0),MATCH('面板-总览'!AL$2,'面板-景气指数'!$36:$36,0)) -> 0.893 | AM8: =INDEX('面板-景气指数'!$37:$242,MATCH('面板-总览'!$AI8,'面板-景气指数'!$A$37:$A$242,0),MATCH('面板-总览'!AM$2,'面板-景气指数'!$36:$36,0)) -> 0.84 | AN8: =INDEX('面板-景气指数'!$37:$242,MATCH('面板-总览'!$AI8,'面板-景气指数'!$A$37:$A$242,0),MATCH('面板-总览'!AN$2,'面板-景气指数'!$36:$36,0)) -> 0.808 | AO8: =INDEX('面板-景气指数'!$37:$242,MATCH('面板-总览'!$AI8,'面板-景气指数'!$A$37:$A$242,0),MATCH('面板-总览'!AO$2,'面板-景气指数'!$36:$36,0)) -> 0.691 | AP8: =INDEX('面板-景气指数'!$37:$242,MATCH('面板-总览'!$AI8,'面板-景气指数'!$A$37:$A$242,0),MATCH('面板-总览'!AP$2,'面板-景气指数'!$36:$36,0)) -> 0.67 | AQ8: =INDEX('面板-景气指数'!$37:$242,MATCH('面板-总览'!$AI8,'面板-景气指数'!$A$37:$A$242,0),MATCH('面板-总览'!AQ$2,'面板-景气指数'!$36:$36,0)) -> 0.648 | ... AV8: =INDEX('面板-景气指数'!$37:$242,MATCH('面板-总览'!$AI8,'面板-景气指数'!$A$37:$A$242,0),MATCH('面板-总览'!AV$2,'面板-景气指数'!$36:$36,0)) -> 0.734 | AX8: =AV8-AS8 -> 0.054
A9: 机械设备 | B9: =INDEX('面板-景气指数'!$37:$242,MATCH('面板-总览'!$A9,'面板-景气指数'!$A$37:$A$242,0),MATCH('面板-总览'!B$2,'面板-景气指数'!$36:$36,0)) -> 0.33039148 | C9: =INDEX('面板-景气指数'!$37:$242,MATCH('面板-总览'!$A9,'面板-景气指数'!$A$37:$A$242,0),MATCH('面板-总览'!C$2,'面板-景气指数'!$36:$36,0)) -> 0.23464843 | D9: =INDEX('面板-景气指数'!$37:$242,MATCH('面板-总览'!$A9,'面板-景气指数'!$A$37:$A$242,0),MATCH('面板-总览'!D$2,'面板-景气指数'!$36:$36,0)) -> 0.30875052 | E9: =INDEX('面板-景气指数'!$37:$242,MATCH('面板-总览'!$A9,'面板-景气指数'!$A$37:$A$242,0),MATCH('面板-总览'!E$2,'面板-景气指数'!$36:$36,0)) -> 0.37022063 | F9: =INDEX('面板-景气指数'!$37:$242,MATCH('面板-总览'!$A9,'面板-景气指数'!$A$37:$A$242,0),MATCH('面板-总览'!F$2,'面板-景气指数'!$36:$36,0)) -> 0.37031435 | G9: =INDEX('面板-景气指数'!$37:$242,MATCH('面板-总览'!$A9,'面板-景气指数'!$A$37:$A$242,0),MATCH('面板-总览'!G$2,'面板-景气指数'!$36:$36,0)) -> 0.30940397 | H9: =INDEX('面板-景气指数'!$37:$242,MATCH('面板-总览'!$A9,'面板-景气指数'!$A$37:$A$242,0),MATCH('面板-总览'!H$2,'面板-景气指数'!$36:$36,0)) -> 0.27417594 | I9: =INDEX('面板-景气指数'!$37:$242,MATCH('面板-总览'!$A9,'面板-景气指数'!$A$37:$A$242,0),MATCH('面板-总览'!I$2,'面板-景气指数'!$36:$36,0)) -> 0.2242322 | ... N9: =INDEX('面板-景气指数'!$37:$242,MATCH('面板-总览'!$A9,'面板-景气指数'!$A$37:$A$242,0),MATCH('面板-总览'!N$2,'面板-景气指数'!$36:$36,0)) -> 0.4357197 | P9: =N9-K9 -> 0.12767485 | R9: 贵金属 | S9: =INDEX('面板-景气指数'!$37:$242,MATCH('面板-总览'!$R9,'面板-景气指数'!$A$37:$A$242,0),MATCH('面板-总览'!S$2,'面板-景气指数'!$36:$36,0)) -> 0.1855 | T9: =INDEX('面板-景气指数'!$37:$242,MATCH('面板-总览'!$R9,'面板-景气指数'!$A$37:$A$242,0),MATCH('面板-总览'!T$2,'面板-景气指数'!$36:$36,0)) -> 0.3985 | U9: =INDEX('面板-景气指数'!$37:$242,MATCH('面板-总览'!$R9,'面板-景气指数'!$A$37:$A$242,0),MATCH('面板-总览'!U$2,'面板-景气指数'!$36:$36,0)) -> 0.4515 | V9: =INDEX('面板-景气指数'!$37:$242,MATCH('面板-总览'!$R9,'面板-景气指数'!$A$37:$A$242,0),MATCH('面板-总览'!V$2,'面板-景气指数'!$36:$36,0)) -> 0.3505 | W9: =INDEX('面板-景气指数'!$37:$242,MATCH('面板-总览'!$R9,'面板-景气指数'!$A$37:$A$242,0),MATCH('面板-总览'!W$2,'面板-景气指数'!$36:$36,0)) -> 0.34 | X9: =INDEX('面板-景气指数'!$37:$242,MATCH('面板-总览'!$R9,'面板-景气指数'!$A$37:$A$242,0),MATCH('面板-总览'!X$2,'面板-景气指数'!$36:$36,0)) -> 0.489 | Y9: =INDEX('面板-景气指数'!$37:$242,MATCH('面板-总览'!$R9,'面板-景气指数'!$A$37:$A$242,0),MATCH('面板-总览'!Y$2,'面板-景气指数'!$36:$36,0)) -> 0.574 | Z9: =INDEX('面板-景气指数'!$37:$242,MATCH('面板-总览'!$R9,'面板-景气指数'!$A$37:$A$242,0),MATCH('面板-总览'!Z$2,'面板-景气指数'!$36:$36,0)) -> 0.675 | ... AE9: =INDEX('面板-景气指数'!$37:$242,MATCH('面板-总览'!$R9,'面板-景气指数'!$A$37:$A$242,0),MATCH('面板-总览'!AE$2,'面板-景气指数'!$36:$36,0)) -> 0.696 | AG9: =AE9-AB9 -> -0.08 | AI9: 钨 | AJ9: =INDEX('面板-景气指数'!$37:$242,MATCH('面板-总览'!$AI9,'面板-景气指数'!$A$37:$A$242,0),MATCH('面板-总览'!AJ$2,'面板-景气指数'!$36:$36,0)) -> 0.372 | AK9: =INDEX('面板-景气指数'!$37:$242,MATCH('面板-总览'!$AI9,'面板-景气指数'!$A$37:$A$242,0),MATCH('面板-总览'!AK$2,'面板-景气指数'!$36:$36,0)) -> 0.414 | AL9: =INDEX('面板-景气指数'!$37:$242,MATCH('面板-总览'!$AI9,'面板-景气指数'!$A$37:$A$242,0),MATCH('面板-总览'!AL$2,'面板-景气指数'!$36:$36,0)) -> 0.436 | AM9: =INDEX('面板-景气指数'!$37:$242,MATCH('面板-总览'!$AI9,'面板-景气指数'!$A$37:$A$242,0),MATCH('面板-总览'!AM$2,'面板-景气指数'!$36:$36,0)) -> 0.393 | AN9: =INDEX('面板-景气指数'!$37:$242,MATCH('面板-总览'!$AI9,'面板-景气指数'!$A$37:$A$242,0),MATCH('面板-总览'!AN$2,'面板-景气指数'!$36:$36,0)) -> 0.351 | AO9: =INDEX('面板-景气指数'!$37:$242,MATCH('面板-总览'!$AI9,'面板-景气指数'!$A$37:$A$242,0),MATCH('面板-总览'!AO$2,'面板-景气指数'!$36:$36,0)) -> 0.382 | AP9: =INDEX('面板-景气指数'!$37:$242,MATCH('面板-总览'!$AI9,'面板-景气指数'!$A$37:$A$242,0),MATCH('面板-总览'!AP$2,'面板-景气指数'!$36:$36,0)) -> 0.478 | AQ9: =INDEX('面板-景气指数'!$37:$242,MATCH('面板-总览'!$AI9,'面板-景气指数'!$A$37:$A$242,0),MATCH('面板-总览'!AQ$2,'面板-景气指数'!$36:$36,0)) -> 0.574 | ... AV9: =INDEX('面板-景气指数'!$37:$242,MATCH('面板-总览'!$AI9,'面板-景气指数'!$A$37:$A$242,0),MATCH('面板-总览'!AV$2,'面板-景气指数'!$36:$36,0)) -> 0.595 | AX9: =AV9-AS9 -> 0.095
A10: 电力设备 | B10: =INDEX('面板-景气指数'!$37:$242,MATCH('面板-总览'!$A10,'面板-景气指数'!$A$37:$A$242,0),MATCH('面板-总览'!B$2,'面板-景气指数'!$36:$36,0)) -> 0.55293114 | C10: =INDEX('面板-景气指数'!$37:$242,MATCH('面板-总览'!$A10,'面板-景气指数'!$A$37:$A$242,0),MATCH('面板-总览'!C$2,'面板-景气指数'!$36:$36,0)) -> 0.49393139 | D10: =INDEX('面板-景气指数'!$37:$242,MATCH('面板-总览'!$A10,'面板-景气指数'!$A$37:$A$242,0),MATCH('面板-总览'!D$2,'面板-景气指数'!$36:$36,0)) -> 0.39883164 | E10: =INDEX('面板-景气指数'!$37:$242,MATCH('面板-总览'!$A10,'面板-景气指数'!$A$37:$A$242,0),MATCH('面板-总览'!E$2,'面板-景气指数'!$36:$36,0)) -> 0.41121242 | F10: =INDEX('面板-景气指数'!$37:$242,MATCH('面板-总览'!$A10,'面板-景气指数'!$A$37:$A$242,0),MATCH('面板-总览'!F$2,'面板-景气指数'!$36:$36,0)) -> 0.47011912 | G10: =INDEX('面板-景气指数'!$37:$242,MATCH('面板-总览'!$A10,'面板-景气指数'!$A$37:$A$242,0),MATCH('面板-总览'!G$2,'面板-景气指数'!$36:$36,0)) -> 0.49141718 | H10: =INDEX('面板-景气指数'!$37:$242,MATCH('面板-总览'!$A10,'面板-景气指数'!$A$37:$A$242,0),MATCH('面板-总览'!H$2,'面板-景气指数'!$36:$36,0)) -> 0.49594429 | I10: =INDEX('面板-景气指数'!$37:$242,MATCH('面板-总览'!$A10,'面板-景气指数'!$A$37:$A$242,0),MATCH('面板-总览'!I$2,'面板-景气指数'!$36:$36,0)) -> 0.47438515 | ... N10: =INDEX('面板-景气指数'!$37:$242,MATCH('面板-总览'!$A10,'面板-景气指数'!$A$37:$A$242,0),MATCH('面板-总览'!N$2,'面板-景气指数'!$36:$36,0)) -> 0.4098391 | P10: =N10-K10 -> -0.0088537247 | R10: 小金属 | S10: =INDEX('面板-景气指数'!$37:$242,MATCH('面板-总览'!$R10,'面板-景气指数'!$A$37:$A$242,0),MATCH('面板-总览'!S$2,'面板-景气指数'!$36:$36,0)) -> 0.53675 | T10: =INDEX('面板-景气指数'!$37:$242,MATCH('面板-总览'!$R10,'面板-景气指数'!$A$37:$A$242,0),MATCH('面板-总览'!T$2,'面板-景气指数'!$36:$36,0)) -> 0.5765 | U10: =INDEX('面板-景气指数'!$37:$242,MATCH('面板-总览'!$R10,'面板-景气指数'!$A$37:$A$242,0),MATCH('面板-总览'!U$2,'面板-景气指数'!$36:$36,0)) -> 0.598 | V10: =INDEX('面板-景气指数'!$37:$242,MATCH('面板-总览'!$R10,'面板-景气指数'!$A$37:$A$242,0),MATCH('面板-总览'!V$2,'面板-景气指数'!$36:$36,0)) -> 0.566 | W10: =INDEX('面板-景气指数'!$37:$242,MATCH('面板-总览'!$R10,'面板-景气指数'!$A$37:$A$242,0),MATCH('面板-总览'!W$2,'面板-景气指数'!$36:$36,0)) -> 0.52375 | X10: =INDEX('面板-景气指数'!$37:$242,MATCH('面板-总览'!$R10,'面板-景气指数'!$A$37:$A$242,0),MATCH('面板-总览'!X$2,'面板-景气指数'!$36:$36,0)) -> 0.43275 | Y10: =INDEX('面板-景气指数'!$37:$242,MATCH('面板-总览'!$R10,'面板-景气指数'!$A$37:$A$242,0),MATCH('面板-总览'!Y$2,'面板-景气指数'!$36:$36,0)) -> 0.449 | Z10: =INDEX('面板-景气指数'!$37:$242,MATCH('面板-总览'!$R10,'面板-景气指数'!$A$37:$A$242,0),MATCH('面板-总览'!Z$2,'面板-景气指数'!$36:$36,0)) -> 0.5445 | ... AE10: =INDEX('面板-景气指数'!$37:$242,MATCH('面板-总览'!$R10,'面板-景气指数'!$A$37:$A$242,0),MATCH('面板-总览'!AE$2,'面板-景气指数'!$36:$36,0)) -> 0.56325 | AG10: =AE10-AB10 -> -0.1385 | AI10: 钼 | AJ10: =INDEX('面板-景气指数'!$37:$242,MATCH('面板-总览'!$AI10,'面板-景气指数'!$A$37:$A$242,0),MATCH('面板-总览'!AJ$2,'面板-景气指数'!$36:$36,0)) -> 0.893 | AK10: =INDEX('面板-景气指数'!$37:$242,MATCH('面板-总览'!$AI10,'面板-景气指数'!$A$37:$A$242,0),MATCH('面板-总览'!AK$2,'面板-景气指数'!$36:$36,0)) -> 0.957 | AL10: =INDEX('面板-景气指数'!$37:$242,MATCH('面板-总览'!$AI10,'面板-景气指数'!$A$37:$A$242,0),MATCH('面板-总览'!AL$2,'面板-景气指数'!$36:$36,0)) -> 1 | AM10: =INDEX('面板-景气指数'!$37:$242,MATCH('面板-总览'!$AI10,'面板-景气指数'!$A$37:$A$242,0),MATCH('面板-总览'!AM$2,'面板-景气指数'!$36:$36,0)) -> 0.989 | AN10: =INDEX('面板-景气指数'!$37:$242,MATCH('面板-总览'!$AI10,'面板-景气指数'!$A$37:$A$242,0),MATCH('面板-总览'!AN$2,'面板-景气指数'!$36:$36,0)) -> 0.936 | AO10: =INDEX('面板-景气指数'!$37:$242,MATCH('面板-总览'!$AI10,'面板-景气指数'!$A$37:$A$242,0),MATCH('面板-总览'!AO$2,'面板-景气指数'!$36:$36,0)) -> 0.627 | AP10: =INDEX('面板-景气指数'!$37:$242,MATCH('面板-总览'!$AI10,'面板-景气指数'!$A$37:$A$242,0),MATCH('面板-总览'!AP$2,'面板-景气指数'!$36:$36,0)) -> 0.553 | AQ10: =INDEX('面板-景气指数'!$37:$242,MATCH('面板-总览'!$AI10,'面板-景气指数'!$A$37:$A$242,0),MATCH('面板-总览'!AQ$2,'面板-景气指数'!$36:$36,0)) -> 0.691 | ... AV10: =INDEX('面板-景气指数'!$37:$242,MATCH('面板-总览'!$AI10,'面板-景气指数'!$A$37:$A$242,0),MATCH('面板-总览'!AV$2,'面板-景气指数'!$36:$36,0)) -> 0.265 | AX10: =AV10-AS10 -> -0.66
A11: 国防军工 | B11: =INDEX('面板-景气指数'!$37:$242,MATCH('面板-总览'!$A11,'面板-景气指数'!$A$37:$A$242,0),MATCH('面板-总览'!B$2,'面板-景气指数'!$36:$36,0)) -> 0.56605613 | C11: =INDEX('面板-景气指数'!$37:$242,MATCH('面板-总览'!$A11,'面板-景气指数'!$A$37:$A$242,0),MATCH('面板-总览'!C$2,'面板-景气指数'!$36:$36,0)) -> 0.55060621 | D11: =INDEX('面板-景气指数'!$37:$242,MATCH('面板-总览'!$A11,'面板-景气指数'!$A$37:$A$242,0),MATCH('面板-总览'!D$2,'面板-景气指数'!$36:$36,0)) -> 0.44931731 | E11: =INDEX('面板-景气指数'!$37:$242,MATCH('面板-总览'!$A11,'面板-景气指数'!$A$37:$A$242,0),MATCH('面板-总览'!E$2,'面板-景气指数'!$36:$36,0)) -> 0.36216855 | F11: =INDEX('面板-景气指数'!$37:$242,MATCH('面板-总览'!$A11,'面板-景气指数'!$A$37:$A$242,0),MATCH('面板-总览'!F$2,'面板-景气指数'!$36:$36,0)) -> 0.36373833 | G11: =INDEX('面板-景气指数'!$37:$242,MATCH('面板-总览'!$A11,'面板-景气指数'!$A$37:$A$242,0),MATCH('面板-总览'!G$2,'面板-景气指数'!$36:$36,0)) -> 0.32209694 | H11: =INDEX('面板-景气指数'!$37:$242,MATCH('面板-总览'!$A11,'面板-景气指数'!$A$37:$A$242,0),MATCH('面板-总览'!H$2,'面板-景气指数'!$36:$36,0)) -> 0.31213806 | I11: =INDEX('面板-景气指数'!$37:$242,MATCH('面板-总览'!$A11,'面板-景气指数'!$A$37:$A$242,0),MATCH('面板-总览'!I$2,'面板-景气指数'!$36:$36,0)) -> 0.28736996 | ... N11: =INDEX('面板-景气指数'!$37:$242,MATCH('面板-总览'!$A11,'面板-景气指数'!$A$37:$A$242,0),MATCH('面板-总览'!N$2,'面板-景气指数'!$36:$36,0)) -> 0.29066285 | P11: =N11-K11 -> 0.0057071721 | R11: 能源金属 | S11: =INDEX('面板-景气指数'!$37:$242,MATCH('面板-总览'!$R11,'面板-景气指数'!$A$37:$A$242,0),MATCH('面板-总览'!S$2,'面板-景气指数'!$36:$36,0)) -> 0.67166667 | T11: =INDEX('面板-景气指数'!$37:$242,MATCH('面板-总览'!$R11,'面板-景气指数'!$A$37:$A$242,0),MATCH('面板-总览'!T$2,'面板-景气指数'!$36:$36,0)) -> 0.629 | U11: =INDEX('面板-景气指数'!$37:$242,MATCH('面板-总览'!$R11,'面板-景气指数'!$A$37:$A$242,0),MATCH('面板-总览'!U$2,'面板-景气指数'!$36:$36,0)) -> 0.55766667 | V11: =INDEX('面板-景气指数'!$37:$242,MATCH('面板-总览'!$R11,'面板-景气指数'!$A$37:$A$242,0),MATCH('面板-总览'!V$2,'面板-景气指数'!$36:$36,0)) -> 0.38466667 | W11: =INDEX('面板-景气指数'!$37:$242,MATCH('面板-总览'!$R11,'面板-景气指数'!$A$37:$A$242,0),MATCH('面板-总览'!W$2,'面板-景气指数'!$36:$36,0)) -> 0.228 | X11: =INDEX('面板-景气指数'!$37:$242,MATCH('面板-总览'!$R11,'面板-景气指数'!$A$37:$A$242,0),MATCH('面板-总览'!X$2,'面板-景气指数'!$36:$36,0)) -> 0.092666667 | Y11: =INDEX('面板-景气指数'!$37:$242,MATCH('面板-总览'!$R11,'面板-景气指数'!$A$37:$A$242,0),MATCH('面板-总览'!Y$2,'面板-景气指数'!$36:$36,0)) -> 0.123 | Z11: =INDEX('面板-景气指数'!$37:$242,MATCH('面板-总览'!$R11,'面板-景气指数'!$A$37:$A$242,0),MATCH('面板-总览'!Z$2,'面板-景气指数'!$36:$36,0)) -> 0.196 | ... AE11: =INDEX('面板-景气指数'!$37:$242,MATCH('面板-总览'!$R11,'面板-景气指数'!$A$37:$A$242,0),MATCH('面板-总览'!AE$2,'面板-景气指数'!$36:$36,0)) -> 0.11166667 | AG11: =AE11-AB11 -> -0.07 | AI11: 其它小金属 | AJ11: =INDEX('面板-景气指数'!$37:$242,MATCH('面板-总览'!$AI11,'面板-景气指数'!$A$37:$A$242,0),MATCH('面板-总览'!AJ$2,'面板-景气指数'!$36:$36,0)) -> 0.01 | AK11: =INDEX('面板-景气指数'!$37:$242,MATCH('面板-总览'!$AI11,'面板-景气指数'!$A$37:$A$242,0),MATCH('面板-总览'!AK$2,'面板-景气指数'!$36:$36,0)) -> 0.053 | AL11: =INDEX('面板-景气指数'!$37:$242,MATCH('面板-总览'!$AI11,'面板-景气指数'!$A$37:$A$242,0),MATCH('面板-总览'!AL$2,'面板-景气指数'!$36:$36,0)) -> 0.063 | AM11: =INDEX('面板-景气指数'!$37:$242,MATCH('面板-总览'!$AI11,'面板-景气指数'!$A$37:$A$242,0),MATCH('面板-总览'!AM$2,'面板-景气指数'!$36:$36,0)) -> 0.042 | AN11: =INDEX('面板-景气指数'!$37:$242,MATCH('面板-总览'!$AI11,'面板-景气指数'!$A$37:$A$242,0),MATCH('面板-总览'!AN$2,'面板-景气指数'!$36:$36,0)) -> 0 | AO11: =INDEX('面板-景气指数'!$37:$242,MATCH('面板-总览'!$AI11,'面板-景气指数'!$A$37:$A$242,0),MATCH('面板-总览'!AO$2,'面板-景气指数'!$36:$36,0)) -> 0.031 | AP11: =INDEX('面板-景气指数'!$37:$242,MATCH('面板-总览'!$AI11,'面板-景气指数'!$A$37:$A$242,0),MATCH('面板-总览'!AP$2,'面板-景气指数'!$36:$36,0)) -> 0.095 | AQ11: =INDEX('面板-景气指数'!$37:$242,MATCH('面板-总览'!$AI11,'面板-景气指数'!$A$37:$A$242,0),MATCH('面板-总览'!AQ$2,'面板-景气指数'!$36:$36,0)) -> 0.265 | ... AV11: =INDEX('面板-景气指数'!$37:$242,MATCH('面板-总览'!$AI11,'面板-景气指数'!$A$37:$A$242,0),MATCH('面板-总览'!AV$2,'面板-景气指数'!$36:$36,0)) -> 0.659 | AX11: =AV11-AS11 -> -0.043
A12: 农林牧渔 | B12: =INDEX('面板-景气指数'!$37:$242,MATCH('面板-总览'!$A12,'面板-景气指数'!$A$37:$A$242,0),MATCH('面板-总览'!B$2,'面板-景气指数'!$36:$36,0)) -> 0.64732336 | C12: =INDEX('面板-景气指数'!$37:$242,MATCH('面板-总览'!$A12,'面板-景气指数'!$A$37:$A$242,0),MATCH('面板-总览'!C$2,'面板-景气指数'!$36:$36,0)) -> 0.52467337 | D12: =INDEX('面板-景气指数'!$37:$242,MATCH('面板-总览'!$A12,'面板-景气指数'!$A$37:$A$242,0),MATCH('面板-总览'!D$2,'面板-景气指数'!$36:$36,0)) -> 0.42204549 | E12: =INDEX('面板-景气指数'!$37:$242,MATCH('面板-总览'!$A12,'面板-景气指数'!$A$37:$A$242,0),MATCH('面板-总览'!E$2,'面板-景气指数'!$36:$36,0)) -> 0.34955774 | F12: =INDEX('面板-景气指数'!$37:$242,MATCH('面板-总览'!$A12,'面板-景气指数'!$A$37:$A$242,0),MATCH('面板-总览'!F$2,'面板-景气指数'!$36:$36,0)) -> 0.28910387 | G12: =INDEX('面板-景气指数'!$37:$242,MATCH('面板-总览'!$A12,'面板-景气指数'!$A$37:$A$242,0),MATCH('面板-总览'!G$2,'面板-景气指数'!$36:$36,0)) -> 0.20418046 | H12: =INDEX('面板-景气指数'!$37:$242,MATCH('面板-总览'!$A12,'面板-景气指数'!$A$37:$A$242,0),MATCH('面板-总览'!H$2,'面板-景气指数'!$36:$36,0)) -> 0.15985486 | I12: =INDEX('面板-景气指数'!$37:$242,MATCH('面板-总览'!$A12,'面板-景气指数'!$A$37:$A$242,0),MATCH('面板-总览'!I$2,'面板-景气指数'!$36:$36,0)) -> 0.16524427 | ... N12: =INDEX('面板-景气指数'!$37:$242,MATCH('面板-总览'!$A12,'面板-景气指数'!$A$37:$A$242,0),MATCH('面板-总览'!N$2,'面板-景气指数'!$36:$36,0)) -> 0.11910765 | P12: =N12-K12 -> -0.10374527 | R12: 金属新材料 | S12: =INDEX('面板-景气指数'!$37:$242,MATCH('面板-总览'!$R12,'面板-景气指数'!$A$37:$A$242,0),MATCH('面板-总览'!S$2,'面板-景气指数'!$36:$36,0)) -> 0.265 | T12: =INDEX('面板-景气指数'!$37:$242,MATCH('面板-总览'!$R12,'面板-景气指数'!$A$37:$A$242,0),MATCH('面板-总览'!T$2,'面板-景气指数'!$36:$36,0)) -> 0.148 | U12: =INDEX('面板-景气指数'!$37:$242,MATCH('面板-总览'!$R12,'面板-景气指数'!$A$37:$A$242,0),MATCH('面板-总览'!U$2,'面板-景气指数'!$36:$36,0)) -> 0.053 | V12: =INDEX('面板-景气指数'!$37:$242,MATCH('面板-总览'!$R12,'面板-景气指数'!$A$37:$A$242,0),MATCH('面板-总览'!V$2,'面板-景气指数'!$36:$36,0)) -> 0.021 | W12: =INDEX('面板-景气指数'!$37:$242,MATCH('面板-总览'!$R12,'面板-景气指数'!$A$37:$A$242,0),MATCH('面板-总览'!W$2,'面板-景气指数'!$36:$36,0)) -> 0 | X12: =INDEX('面板-景气指数'!$37:$242,MATCH('面板-总览'!$R12,'面板-景气指数'!$A$37:$A$242,0),MATCH('面板-总览'!X$2,'面板-景气指数'!$36:$36,0)) -> 0.01 | Y12: =INDEX('面板-景气指数'!$37:$242,MATCH('面板-总览'!$R12,'面板-景气指数'!$A$37:$A$242,0),MATCH('面板-总览'!Y$2,'面板-景气指数'!$36:$36,0)) -> 0.042 | Z12: =INDEX('面板-景气指数'!$37:$242,MATCH('面板-总览'!$R12,'面板-景气指数'!$A$37:$A$242,0),MATCH('面板-总览'!Z$2,'面板-景气指数'!$36:$36,0)) -> 0.106 | ... AE12: =INDEX('面板-景气指数'!$37:$242,MATCH('面板-总览'!$R12,'面板-景气指数'!$A$37:$A$242,0),MATCH('面板-总览'!AE$2,'面板-景气指数'!$36:$36,0)) -> 0.063 | AG12: =AE12-AB12 -> -0.064 | AI12: 锂 | AJ12: =INDEX('面板-景气指数'!$37:$242,MATCH('面板-总览'!$AI12,'面板-景气指数'!$A$37:$A$242,0),MATCH('面板-总览'!AJ$2,'面板-景气指数'!$36:$36,0)) -> 0.788 | AK12: =INDEX('面板-景气指数'!$37:$242,MATCH('面板-总览'!$AI12,'面板-景气指数'!$A$37:$A$242,0),MATCH('面板-总览'!AK$2,'面板-景气指数'!$36:$36,0)) -> 0.76 | AL12: =INDEX('面板-景气指数'!$37:$242,MATCH('面板-总览'!$AI12,'面板-景气指数'!$A$37:$A$242,0),MATCH('面板-总览'!AL$2,'面板-景气指数'!$36:$36,0)) -> 0.69 | AM12: =INDEX('面板-景气指数'!$37:$242,MATCH('面板-总览'!$AI12,'面板-景气指数'!$A$37:$A$242,0),MATCH('面板-总览'!AM$2,'面板-景气指数'!$36:$36,0)) -> 0.577 | AN12: =INDEX('面板-景气指数'!$37:$242,MATCH('面板-总览'!$AI12,'面板-景气指数'!$A$37:$A$242,0),MATCH('面板-总览'!AN$2,'面板-景气指数'!$36:$36,0)) -> 0.436 | AO12: =INDEX('面板-景气指数'!$37:$242,MATCH('面板-总览'!$AI12,'面板-景气指数'!$A$37:$A$242,0),MATCH('面板-总览'!AO$2,'面板-景气指数'!$36:$36,0)) -> 0.14 | AP12: =INDEX('面板-景气指数'!$37:$242,MATCH('面板-总览'!$AI12,'面板-景气指数'!$A$37:$A$242,0),MATCH('面板-总览'!AP$2,'面板-景气指数'!$36:$36,0)) -> 0.169 | AQ12: =INDEX('面板-景气指数'!$37:$242,MATCH('面板-总览'!$AI12,'面板-景气指数'!$A$37:$A$242,0),MATCH('面板-总览'!AQ$2,'面板-景气指数'!$36:$36,0)) -> 0.338 | ... AV12: =INDEX('面板-景气指数'!$37:$242,MATCH('面板-总览'!$AI12,'面板-景气指数'!$A$37:$A$242,0),MATCH('面板-总览'!AV$2,'面板-景气指数'!$36:$36,0)) -> 0 | AX12: =AV12-AS12 -> -0.112
A13: 食品饮料 | B13: =INDEX('面板-景气指数'!$37:$242,MATCH('面板-总览'!$A13,'面板-景气指数'!$A$37:$A$242,0),MATCH('面板-总览'!B$2,'面板-景气指数'!$36:$36,0)) -> 0.30995808 | C13: =INDEX('面板-景气指数'!$37:$242,MATCH('面板-总览'!$A13,'面板-景气指数'!$A$37:$A$242,0),MATCH('面板-总览'!C$2,'面板-景气指数'!$36:$36,0)) -> 0.26931727 | D13: =INDEX('面板-景气指数'!$37:$242,MATCH('面板-总览'!$A13,'面板-景气指数'!$A$37:$A$242,0),MATCH('面板-总览'!D$2,'面板-景气指数'!$36:$36,0)) -> 0.26517991 | E13: =INDEX('面板-景气指数'!$37:$242,MATCH('面板-总览'!$A13,'面板-景气指数'!$A$37:$A$242,0),MATCH('面板-总览'!E$2,'面板-景气指数'!$36:$36,0)) -> 0.30905792 | F13: =INDEX('面板-景气指数'!$37:$242,MATCH('面板-总览'!$A13,'面板-景气指数'!$A$37:$A$242,0),MATCH('面板-总览'!F$2,'面板-景气指数'!$36:$36,0)) -> 0.32775999 | G13: =INDEX('面板-景气指数'!$37:$242,MATCH('面板-总览'!$A13,'面板-景气指数'!$A$37:$A$242,0),MATCH('面板-总览'!G$2,'面板-景气指数'!$36:$36,0)) -> 0.32319099 | H13: =INDEX('面板-景气指数'!$37:$242,MATCH('面板-总览'!$A13,'面板-景气指数'!$A$37:$A$242,0),MATCH('面板-总览'!H$2,'面板-景气指数'!$36:$36,0)) -> 0.31267556 | I13: =INDEX('面板-景气指数'!$37:$242,MATCH('面板-总览'!$A13,'面板-景气指数'!$A$37:$A$242,0),MATCH('面板-总览'!I$2,'面板-景气指数'!$36:$36,0)) -> 0.31245057 | ... N13: =INDEX('面板-景气指数'!$37:$242,MATCH('面板-总览'!$A13,'面板-景气指数'!$A$37:$A$242,0),MATCH('面板-总览'!N$2,'面板-景气指数'!$36:$36,0)) -> 0.40664393 | P13: =N13-K13 -> 0.070400321 | R13: 化学原料 | S13: =INDEX('面板-景气指数'!$37:$242,MATCH('面板-总览'!$R13,'面板-景气指数'!$A$37:$A$242,0),MATCH('面板-总览'!S$2,'面板-景气指数'!$36:$36,0)) -> 0.16300334 | T13: =INDEX('面板-景气指数'!$37:$242,MATCH('面板-总览'!$R13,'面板-景气指数'!$A$37:$A$242,0),MATCH('面板-总览'!T$2,'面板-景气指数'!$36:$36,0)) -> 0.20435886 | U13: =INDEX('面板-景气指数'!$37:$242,MATCH('面板-总览'!$R13,'面板-景气指数'!$A$37:$A$242,0),MATCH('面板-总览'!U$2,'面板-景气指数'!$36:$36,0)) -> 0.23705861 | V13: =INDEX('面板-景气指数'!$37:$242,MATCH('面板-总览'!$R13,'面板-景气指数'!$A$37:$A$242,0),MATCH('面板-总览'!V$2,'面板-景气指数'!$36:$36,0)) -> 0.25443411 | W13: =INDEX('面板-景气指数'!$37:$242,MATCH('面板-总览'!$R13,'面板-景气指数'!$A$37:$A$242,0),MATCH('面板-总览'!W$2,'面板-景气指数'!$36:$36,0)) -> 0.25948103 | X13: =INDEX('面板-景气指数'!$37:$242,MATCH('面板-总览'!$R13,'面板-景气指数'!$A$37:$A$242,0),MATCH('面板-总览'!X$2,'面板-景气指数'!$36:$36,0)) -> 0.21745641 | Y13: =INDEX('面板-景气指数'!$37:$242,MATCH('面板-总览'!$R13,'面板-景气指数'!$A$37:$A$242,0),MATCH('面板-总览'!Y$2,'面板-景气指数'!$36:$36,0)) -> 0.18432678 | Z13: =INDEX('面板-景气指数'!$37:$242,MATCH('面板-总览'!$R13,'面板-景气指数'!$A$37:$A$242,0),MATCH('面板-总览'!Z$2,'面板-景气指数'!$36:$36,0)) -> 0.19344491 | ... AE13: =INDEX('面板-景气指数'!$37:$242,MATCH('面板-总览'!$R13,'面板-景气指数'!$A$37:$A$242,0),MATCH('面板-总览'!AE$2,'面板-景气指数'!$36:$36,0)) -> 0.4052134 | AG13: =AE13-AB13 -> 0.060955515 | AI13: 钴 | AJ13: =INDEX('面板-景气指数'!$37:$242,MATCH('面板-总览'!$AI13,'面板-景气指数'!$A$37:$A$242,0),MATCH('面板-总览'!AJ$2,'面板-景气指数'!$36:$36,0)) -> 0.323 | AK13: =INDEX('面板-景气指数'!$37:$242,MATCH('面板-总览'!$AI13,'面板-景气指数'!$A$37:$A$242,0),MATCH('面板-总览'!AK$2,'面板-景气指数'!$36:$36,0)) -> 0.191 | AL13: =INDEX('面板-景气指数'!$37:$242,MATCH('面板-总览'!$AI13,'面板-景气指数'!$A$37:$A$242,0),MATCH('面板-总览'!AL$2,'面板-景气指数'!$36:$36,0)) -> 0.132 | AM13: =INDEX('面板-景气指数'!$37:$242,MATCH('面板-总览'!$AI13,'面板-景气指数'!$A$37:$A$242,0),MATCH('面板-总览'!AM$2,'面板-景气指数'!$36:$36,0)) -> 0.088 | AN13: =INDEX('面板-景气指数'!$37:$242,MATCH('面板-总览'!$AI13,'面板-景气指数'!$A$37:$A$242,0),MATCH('面板-总览'!AN$2,'面板-景气指数'!$36:$36,0)) -> 0.014 | AO13: =INDEX('面板-景气指数'!$37:$242,MATCH('面板-总览'!$AI13,'面板-景气指数'!$A$37:$A$242,0),MATCH('面板-总览'!AO$2,'面板-景气指数'!$36:$36,0)) -> 0 | AP13: =INDEX('面板-景气指数'!$37:$242,MATCH('面板-总览'!$AI13,'面板-景气指数'!$A$37:$A$242,0),MATCH('面板-总览'!AP$2,'面板-景气指数'!$36:$36,0)) -> 0.073 | AQ13: =INDEX('面板-景气指数'!$37:$242,MATCH('面板-总览'!$AI13,'面板-景气指数'!$A$37:$A$242,0),MATCH('面板-总览'!AQ$2,'面板-景气指数'!$36:$36,0)) -> 0.176 | ... AV13: =INDEX('面板-景气指数'!$37:$242,MATCH('面板-总览'!$AI13,'面板-景气指数'!$A$37:$A$242,0),MATCH('面板-总览'!AV$2,'面板-景气指数'!$36:$36,0)) -> 0.25 | AX13: =AV13-AS13 -> -0.088
A14: 医药生物 | B14: =INDEX('面板-景气指数'!$37:$242,MATCH('面板-总览'!$A14,'面板-景气指数'!$A$37:$A$242,0),MATCH('面板-总览'!B$2,'面板-景气指数'!$36:$36,0)) -> 0.39485501 | C14: =INDEX('面板-景气指数'!$37:$242,MATCH('面板-总览'!$A14,'面板-景气指数'!$A$37:$A$242,0),MATCH('面板-总览'!C$2,'面板-景气指数'!$36:$36,0)) -> 0.37754164 | D14: =INDEX('面板-景气指数'!$37:$242,MATCH('面板-总览'!$A14,'面板-景气指数'!$A$37:$A$242,0),MATCH('面板-总览'!D$2,'面板-景气指数'!$36:$36,0)) -> 0.40413502 | E14: =INDEX('面板-景气指数'!$37:$242,MATCH('面板-总览'!$A14,'面板-景气指数'!$A$37:$A$242,0),MATCH('面板-总览'!E$2,'面板-景气指数'!$36:$36,0)) -> 0.41370575 | F14: =INDEX('面板-景气指数'!$37:$242,MATCH('面板-总览'!$A14,'面板-景气指数'!$A$37:$A$242,0),MATCH('面板-总览'!F$2,'面板-景气指数'!$36:$36,0)) -> 0.36527943 | G14: =INDEX('面板-景气指数'!$37:$242,MATCH('面板-总览'!$A14,'面板-景气指数'!$A$37:$A$242,0),MATCH('面板-总览'!G$2,'面板-景气指数'!$36:$36,0)) -> 0.24755847 | H14: =INDEX('面板-景气指数'!$37:$242,MATCH('面板-总览'!$A14,'面板-景气指数'!$A$37:$A$242,0),MATCH('面板-总览'!H$2,'面板-景气指数'!$36:$36,0)) -> 0.23342928 | I14: =INDEX('面板-景气指数'!$37:$242,MATCH('面板-总览'!$A14,'面板-景气指数'!$A$37:$A$242,0),MATCH('面板-总览'!I$2,'面板-景气指数'!$36:$36,0)) -> 0.24242296 | ... N14: =INDEX('面板-景气指数'!$37:$242,MATCH('面板-总览'!$A14,'面板-景气指数'!$A$37:$A$242,0),MATCH('面板-总览'!N$2,'面板-景气指数'!$36:$36,0)) -> 0.25957937 | P14: =N14-K14 -> 0.033667691 | R14: 化学制品 | S14: =INDEX('面板-景气指数'!$37:$242,MATCH('面板-总览'!$R14,'面板-景气指数'!$A$37:$A$242,0),MATCH('面板-总览'!S$2,'面板-景气指数'!$36:$36,0)) -> 0.37844739 | T14: =INDEX('面板-景气指数'!$37:$242,MATCH('面板-总览'!$R14,'面板-景气指数'!$A$37:$A$242,0),MATCH('面板-总览'!T$2,'面板-景气指数'!$36:$36,0)) -> 0.37494788 | U14: =INDEX('面板-景气指数'!$37:$242,MATCH('面板-总览'!$R14,'面板-景气指数'!$A$37:$A$242,0),MATCH('面板-总览'!U$2,'面板-景气指数'!$36:$36,0)) -> 0.36904072 | V14: =INDEX('面板-景气指数'!$37:$242,MATCH('面板-总览'!$R14,'面板-景气指数'!$A$37:$A$242,0),MATCH('面板-总览'!V$2,'面板-景气指数'!$36:$36,0)) -> 0.2926654 | W14: =INDEX('面板-景气指数'!$37:$242,MATCH('面板-总览'!$R14,'面板-景气指数'!$A$37:$A$242,0),MATCH('面板-总览'!W$2,'面板-景气指数'!$36:$36,0)) -> 0.23703918 | X14: =INDEX('面板-景气指数'!$37:$242,MATCH('面板-总览'!$R14,'面板-景气指数'!$A$37:$A$242,0),MATCH('面板-总览'!X$2,'面板-景气指数'!$36:$36,0)) -> 0.1913979 | Y14: =INDEX('面板-景气指数'!$37:$242,MATCH('面板-总览'!$R14,'面板-景气指数'!$A$37:$A$242,0),MATCH('面板-总览'!Y$2,'面板-景气指数'!$36:$36,0)) -> 0.18788879 | Z14: =INDEX('面板-景气指数'!$37:$242,MATCH('面板-总览'!$R14,'面板-景气指数'!$A$37:$A$242,0),MATCH('面板-总览'!Z$2,'面板-景气指数'!$36:$36,0)) -> 0.24728316 | ... AE14: =INDEX('面板-景气指数'!$37:$242,MATCH('面板-总览'!$R14,'面板-景气指数'!$A$37:$A$242,0),MATCH('面板-总览'!AE$2,'面板-景气指数'!$36:$36,0)) -> 0.45025494 | AG14: =AE14-AB14 -> -0.033758878 | AI14: 镍 | AJ14: =INDEX('面板-景气指数'!$37:$242,MATCH('面板-总览'!$AI14,'面板-景气指数'!$A$37:$A$242,0),MATCH('面板-总览'!AJ$2,'面板-景气指数'!$36:$36,0)) -> 0.904 | AK14: =INDEX('面板-景气指数'!$37:$242,MATCH('面板-总览'!$AI14,'面板-景气指数'!$A$37:$A$242,0),MATCH('面板-总览'!AK$2,'面板-景气指数'!$36:$36,0)) -> 0.936 | AL14: =INDEX('面板-景气指数'!$37:$242,MATCH('面板-总览'!$AI14,'面板-景气指数'!$A$37:$A$242,0),MATCH('面板-总览'!AL$2,'面板-景气指数'!$36:$36,0)) -> 0.851 | AM14: =INDEX('面板-景气指数'!$37:$242,MATCH('面板-总览'!$AI14,'面板-景气指数'!$A$37:$A$242,0),MATCH('面板-总览'!AM$2,'面板-景气指数'!$36:$36,0)) -> 0.489 | AN14: =INDEX('面板-景气指数'!$37:$242,MATCH('面板-总览'!$AI14,'面板-景气指数'!$A$37:$A$242,0),MATCH('面板-总览'!AN$2,'面板-景气指数'!$36:$36,0)) -> 0.234 | AO14: =INDEX('面板-景气指数'!$37:$242,MATCH('面板-总览'!$AI14,'面板-景气指数'!$A$37:$A$242,0),MATCH('面板-总览'!AO$2,'面板-景气指数'!$36:$36,0)) -> 0.138 | AP14: =INDEX('面板-景气指数'!$37:$242,MATCH('面板-总览'!$AI14,'面板-景气指数'!$A$37:$A$242,0),MATCH('面板-总览'!AP$2,'面板-景气指数'!$36:$36,0)) -> 0.127 | AQ14: =INDEX('面板-景气指数'!$37:$242,MATCH('面板-总览'!$AI14,'面板-景气指数'!$A$37:$A$242,0),MATCH('面板-总览'!AQ$2,'面板-景气指数'!$36:$36,0)) -> 0.074 | ... AV14: =INDEX('面板-景气指数'!$37:$242,MATCH('面板-总览'!$AI14,'面板-景气指数'!$A$37:$A$242,0),MATCH('面板-总览'!AV$2,'面板-景气指数'!$36:$36,0)) -> 0.085 | AX14: =AV14-AS14 -> -0.01
... A31: 交通运输 | B31: =INDEX('面板-景气指数'!$37:$242,MATCH('面板-总览'!$A31,'面板-景气指数'!$A$37:$A$242,0),MATCH('面板-总览'!B$2,'面板-景气指数'!$36:$36,0)) -> 0.18802966 | C31: =INDEX('面板-景气指数'!$37:$242,MATCH('面板-总览'!$A31,'面板-景气指数'!$A$37:$A$242,0),MATCH('面板-总览'!C$2,'面板-景气指数'!$36:$36,0)) -> 0.20834337 | D31: =INDEX('面板-景气指数'!$37:$242,MATCH('面板-总览'!$A31,'面板-景气指数'!$A$37:$A$242,0),MATCH('面板-总览'!D$2,'面板-景气指数'!$36:$36,0)) -> 0.22863861 | E31: =INDEX('面板-景气指数'!$37:$242,MATCH('面板-总览'!$A31,'面板-景气指数'!$A$37:$A$242,0),MATCH('面板-总览'!E$2,'面板-景气指数'!$36:$36,0)) -> 0.31106878 | F31: =INDEX('面板-景气指数'!$37:$242,MATCH('面板-总览'!$A31,'面板-景气指数'!$A$37:$A$242,0),MATCH('面板-总览'!F$2,'面板-景气指数'!$36:$36,0)) -> 0.41999701 | G31: =INDEX('面板-景气指数'!$37:$242,MATCH('面板-总览'!$A31,'面板-景气指数'!$A$37:$A$242,0),MATCH('面板-总览'!G$2,'面板-景气指数'!$36:$36,0)) -> 0.46237767 | H31: =INDEX('面板-景气指数'!$37:$242,MATCH('面板-总览'!$A31,'面板-景气指数'!$A$37:$A$242,0),MATCH('面板-总览'!H$2,'面板-景气指数'!$36:$36,0)) -> 0.39642086 | I31: =INDEX('面板-景气指数'!$37:$242,MATCH('面板-总览'!$A31,'面板-景气指数'!$A$37:$A$242,0),MATCH('面板-总览'!I$2,'面板-景气指数'!$36:$36,0)) -> 0.36897028 | ... N31: =INDEX('面板-景气指数'!$37:$242,MATCH('面板-总览'!$A31,'面板-景气指数'!$A$37:$A$242,0),MATCH('面板-总览'!N$2,'面板-景气指数'!$36:$36,0)) -> 0.4732714 | P31: =N31-K31 -> 0.076774085 | R31: 电池 | S31: =INDEX('面板-景气指数'!$37:$242,MATCH('面板-总览'!$R31,'面板-景气指数'!$A$37:$A$242,0),MATCH('面板-总览'!S$2,'面板-景气指数'!$36:$36,0)) -> 0.48833333 | T31: =INDEX('面板-景气指数'!$37:$242,MATCH('面板-总览'!$R31,'面板-景气指数'!$A$37:$A$242,0),MATCH('面板-总览'!T$2,'面板-景气指数'!$36:$36,0)) -> 0.35766667 | U31: =INDEX('面板-景气指数'!$37:$242,MATCH('面板-总览'!$R31,'面板-景气指数'!$A$37:$A$242,0),MATCH('面板-总览'!U$2,'面板-景气指数'!$36:$36,0)) -> 0.35045833 | V31: =INDEX('面板-景气指数'!$37:$242,MATCH('面板-总览'!$R31,'面板-景气指数'!$A$37:$A$242,0),MATCH('面板-总览'!V$2,'面板-景气指数'!$36:$36,0)) -> 0.30408333 | W31: =INDEX('面板-景气指数'!$37:$242,MATCH('面板-总览'!$R31,'面板-景气指数'!$A$37:$A$242,0),MATCH('面板-总览'!W$2,'面板-景气指数'!$36:$36,0)) -> 0.3855 | X31: =INDEX('面板-景气指数'!$37:$242,MATCH('面板-总览'!$R31,'面板-景气指数'!$A$37:$A$242,0),MATCH('面板-总览'!X$2,'面板-景气指数'!$36:$36,0)) -> 0.35891667 | Y31: =INDEX('面板-景气指数'!$37:$242,MATCH('面板-总览'!$R31,'面板-景气指数'!$A$37:$A$242,0),MATCH('面板-总览'!Y$2,'面板-景气指数'!$36:$36,0)) -> 0.38220833 | Z31: =INDEX('面板-景气指数'!$37:$242,MATCH('面板-总览'!$R31,'面板-景气指数'!$A$37:$A$242,0),MATCH('面板-总览'!Z$2,'面板-景气指数'!$36:$36,0)) -> 0.34533333 | ... AE31: =INDEX('面板-景气指数'!$37:$242,MATCH('面板-总览'!$R31,'面板-景气指数'!$A$37:$A$242,0),MATCH('面板-总览'!AE$2,'面板-景气指数'!$36:$36,0)) -> 0.24795833 | AG31: =AE31-AB31 -> -0.035125 | AI31: 其他化学纤维 | AJ31: =INDEX('面板-景气指数'!$37:$242,MATCH('面板-总览'!$AI31,'面板-景气指数'!$A$37:$A$242,0),MATCH('面板-总览'!AJ$2,'面板-景气指数'!$36:$36,0)) -> 0.5045 | AK31: =INDEX('面板-景气指数'!$37:$242,MATCH('面板-总览'!$AI31,'面板-景气指数'!$A$37:$A$242,0),MATCH('面板-总览'!AK$2,'面板-景气指数'!$36:$36,0)) -> 0.4945 | AL31: =INDEX('面板-景气指数'!$37:$242,MATCH('面板-总览'!$AI31,'面板-景气指数'!$A$37:$A$242,0),MATCH('面板-总览'!AL$2,'面板-景气指数'!$36:$36,0)) -> 0.425 | AM31: =INDEX('面板-景气指数'!$37:$242,MATCH('面板-总览'!$AI31,'面板-景气指数'!$A$37:$A$242,0),MATCH('面板-总览'!AM$2,'面板-景气指数'!$36:$36,0)) -> 0.2865 | AN31: =INDEX('面板-景气指数'!$37:$242,MATCH('面板-总览'!$AI31,'面板-景气指数'!$A$37:$A$242,0),MATCH('面板-总览'!AN$2,'面板-景气指数'!$36:$36,0)) -> 0.2605 | AO31: =INDEX('面板-景气指数'!$37:$242,MATCH('面板-总览'!$AI31,'面板-景气指数'!$A$37:$A$242,0),MATCH('面板-总览'!AO$2,'面板-景气指数'!$36:$36,0)) -> 0.239 | AP31: =INDEX('面板-景气指数'!$37:$242,MATCH('面板-总览'!$AI31,'面板-景气指数'!$A$37:$A$242,0),MATCH('面板-总览'!AP$2,'面板-景气指数'!$36:$36,0)) -> 0.308 | AQ31: =INDEX('面板-景气指数'!$37:$242,MATCH('面板-总览'!$AI31,'面板-景气指数'!$A$37:$A$242,0),MATCH('面板-总览'!AQ$2,'面板-景气指数'!$36:$36,0)) -> 0.345 | ... AV31: =INDEX('面板-景气指数'!$37:$242,MATCH('面板-总览'!$AI31,'面板-景气指数'!$A$37:$A$242,0),MATCH('面板-总览'!AV$2,'面板-景气指数'!$36:$36,0)) -> 0.3135 | AX31: =AV31-AS31 -> -0.0315
R32: 电网设备 | S32: =INDEX('面板-景气指数'!$37:$242,MATCH('面板-总览'!$R32,'面板-景气指数'!$A$37:$A$242,0),MATCH('面板-总览'!S$2,'面板-景气指数'!$36:$36,0)) -> 0.622 | T32: =INDEX('面板-景气指数'!$37:$242,MATCH('面板-总览'!$R32,'面板-景气指数'!$A$37:$A$242,0),MATCH('面板-总览'!T$2,'面板-景气指数'!$36:$36,0)) -> 0.6115 | U32: =INDEX('面板-景气指数'!$37:$242,MATCH('面板-总览'!$R32,'面板-景气指数'!$A$37:$A$242,0),MATCH('面板-总览'!U$2,'面板-景气指数'!$36:$36,0)) -> 0.324 | V32: =INDEX('面板-景气指数'!$37:$242,MATCH('面板-总览'!$R32,'面板-景气指数'!$A$37:$A$242,0),MATCH('面板-总览'!V$2,'面板-景气指数'!$36:$36,0)) -> 0.308 | W32: =INDEX('面板-景气指数'!$37:$242,MATCH('面板-总览'!$R32,'面板-景气指数'!$A$37:$A$242,0),MATCH('面板-总览'!W$2,'面板-景气指数'!$36:$36,0)) -> 0.345 | X32: =INDEX('面板-景气指数'!$37:$242,MATCH('面板-总览'!$R32,'面板-景气指数'!$A$37:$A$242,0),MATCH('面板-总览'!X$2,'面板-景气指数'!$36:$36,0)) -> 0.3985 | Y32: =INDEX('面板-景气指数'!$37:$242,MATCH('面板-总览'!$R32,'面板-景气指数'!$A$37:$A$242,0),MATCH('面板-总览'!Y$2,'面板-景气指数'!$36:$36,0)) -> 0.4145 | Z32: =INDEX('面板-景气指数'!$37:$242,MATCH('面板-总览'!$R32,'面板-景气指数'!$A$37:$A$242,0),MATCH('面板-总览'!Z$2,'面板-景气指数'!$36:$36,0)) -> 0.441 | ... AE32: =INDEX('面板-景气指数'!$37:$242,MATCH('面板-总览'!$R32,'面板-景气指数'!$A$37:$A$242,0),MATCH('面板-总览'!AE$2,'面板-景气指数'!$36:$36,0)) -> 0.409 | AG32: =AE32-AB32 -> 0.032 | AI32: 其他塑料制品 | AJ32: =INDEX('面板-景气指数'!$37:$242,MATCH('面板-总览'!$AI32,'面板-景气指数'!$A$37:$A$242,0),MATCH('面板-总览'!AJ$2,'面板-景气指数'!$36:$36,0)) -> 0.308 | AK32: =INDEX('面板-景气指数'!$37:$242,MATCH('面板-总览'!$AI32,'面板-景气指数'!$A$37:$A$242,0),MATCH('面板-总览'!AK$2,'面板-景气指数'!$36:$36,0)) -> 0.351 | AL32: =INDEX('面板-景气指数'!$37:$242,MATCH('面板-总览'!$AI32,'面板-景气指数'!$A$37:$A$242,0),MATCH('面板-总览'!AL$2,'面板-景气指数'!$36:$36,0)) -> 0.329 | AM32: =INDEX('面板-景气指数'!$37:$242,MATCH('面板-总览'!$AI32,'面板-景气指数'!$A$37:$A$242,0),MATCH('面板-总览'!AM$2,'面板-景气指数'!$36:$36,0)) -> 0.255 | AN32: =INDEX('面板-景气指数'!$37:$242,MATCH('面板-总览'!$AI32,'面板-景气指数'!$A$37:$A$242,0),MATCH('面板-总览'!AN$2,'面板-景气指数'!$36:$36,0)) -> 0.202 | AO32: =INDEX('面板-景气指数'!$37:$242,MATCH('面板-总览'!$AI32,'面板-景气指数'!$A$37:$A$242,0),MATCH('面板-总览'!AO$2,'面板-景气指数'!$36:$36,0)) -> 0.223 | AP32: =INDEX('面板-景气指数'!$37:$242,MATCH('面板-总览'!$AI32,'面板-景气指数'!$A$37:$A$242,0),MATCH('面板-总览'!AP$2,'面板-景气指数'!$36:$36,0)) -> 0.276 | AQ32: =INDEX('面板-景气指数'!$37:$242,MATCH('面板-总览'!$AI32,'面板-景气指数'!$A$37:$A$242,0),MATCH('面板-总览'!AQ$2,'面板-景气指数'!$36:$36,0)) -> 0.478 | ... AV32: =INDEX('面板-景气指数'!$37:$242,MATCH('面板-总览'!$AI32,'面板-景气指数'!$A$37:$A$242,0),MATCH('面板-总览'!AV$2,'面板-景气指数'!$36:$36,0)) -> 0.691 | AX32: =AV32-AS32 -> -0.074
R33: 航海装备 | S33: =INDEX('面板-景气指数'!$37:$242,MATCH('面板-总览'!$R33,'面板-景气指数'!$A$37:$A$242,0),MATCH('面板-总览'!S$2,'面板-景气指数'!$36:$36,0)) -> 0.7045 | T33: =INDEX('面板-景气指数'!$37:$242,MATCH('面板-总览'!$R33,'面板-景气指数'!$A$37:$A$242,0),MATCH('面板-总览'!T$2,'面板-景气指数'!$36:$36,0)) -> 0.69625 | U33: =INDEX('面板-景气指数'!$37:$242,MATCH('面板-总览'!$R33,'面板-景气指数'!$A$37:$A$242,0),MATCH('面板-总览'!U$2,'面板-景气指数'!$36:$36,0)) -> 0.59525 | V33: =INDEX('面板-景气指数'!$37:$242,MATCH('面板-总览'!$R33,'面板-景气指数'!$A$37:$A$242,0),MATCH('面板-总览'!V$2,'面板-景气指数'!$36:$36,0)) -> 0.598 | W33: =INDEX('面板-景气指数'!$37:$242,MATCH('面板-总览'!$R33,'面板-景气指数'!$A$37:$A$242,0),MATCH('面板-总览'!W$2,'面板-景气指数'!$36:$36,0)) -> 0.627 | X33: =INDEX('面板-景气指数'!$37:$242,MATCH('面板-总览'!$R33,'面板-景气指数'!$A$37:$A$242,0),MATCH('面板-总览'!X$2,'面板-景气指数'!$36:$36,0)) -> 0.68025 | Y33: =INDEX('面板-景气指数'!$37:$242,MATCH('面板-总览'!$R33,'面板-景气指数'!$A$37:$A$242,0),MATCH('面板-总览'!Y$2,'面板-景气指数'!$36:$36,0)) -> 0.68825 | Z33: =INDEX('面板-景气指数'!$37:$242,MATCH('面板-总览'!$R33,'面板-景气指数'!$A$37:$A$242,0),MATCH('面板-总览'!Z$2,'面板-景气指数'!$36:$36,0)) -> 0.65675 | ... AE33: =INDEX('面板-景气指数'!$37:$242,MATCH('面板-总览'!$R33,'面板-景气指数'!$A$37:$A$242,0),MATCH('面板-总览'!AE$2,'面板-景气指数'!$36:$36,0)) -> 0.6805 | AG33: =AE33-AB33 -> -0.00225 | AI33: 改性塑料 | AJ33: =INDEX('面板-景气指数'!$37:$242,MATCH('面板-总览'!$AI33,'面板-景气指数'!$A$37:$A$242,0),MATCH('面板-总览'!AJ$2,'面板-景气指数'!$36:$36,0)) -> 0.223 | AK33: =INDEX('面板-景气指数'!$37:$242,MATCH('面板-总览'!$AI33,'面板-景气指数'!$A$37:$A$242,0),MATCH('面板-总览'!AK$2,'面板-景气指数'!$36:$36,0)) -> 0.287 | AL33: =INDEX('面板-景气指数'!$37:$242,MATCH('面板-总览'!$AI33,'面板-景气指数'!$A$37:$A$242,0),MATCH('面板-总览'!AL$2,'面板-景气指数'!$36:$36,0)) -> 0.2865 | AM33: =INDEX('面板-景气指数'!$37:$242,MATCH('面板-总览'!$AI33,'面板-景气指数'!$A$37:$A$242,0),MATCH('面板-总览'!AM$2,'面板-景气指数'!$36:$36,0)) -> 0.24175 | AN33: =INDEX('面板-景气指数'!$37:$242,MATCH('面板-总览'!$AI33,'面板-景气指数'!$A$37:$A$242,0),MATCH('面板-总览'!AN$2,'面板-景气指数'!$36:$36,0)) -> 0.17775 | AO33: =INDEX('面板-景气指数'!$37:$242,MATCH('面板-总览'!$AI33,'面板-景气指数'!$A$37:$A$242,0),MATCH('面板-总览'!AO$2,'面板-景气指数'!$36:$36,0)) -> 0.172 | AP33: =INDEX('面板-景气指数'!$37:$242,MATCH('面板-总览'!$AI33,'面板-景气指数'!$A$37:$A$242,0),MATCH('面板-总览'!AP$2,'面板-景气指数'!$36:$36,0)) -> 0.20675 | AQ33: =INDEX('面板-景气指数'!$37:$242,MATCH('面板-总览'!$AI33,'面板-景气指数'!$A$37:$A$242,0),MATCH('面板-总览'!AQ$2,'面板-景气指数'!$36:$36,0)) -> 0.273 | ... AV33: =INDEX('面板-景气指数'!$37:$242,MATCH('面板-总览'!$AI33,'面板-景气指数'!$A$37:$A$242,0),MATCH('面板-总览'!AV$2,'面板-景气指数'!$36:$36,0)) -> 0.48125 | AX33: =AV33-AS33 -> 0.1225
R34: 航空装备 | S34: =INDEX('面板-景气指数'!$37:$242,MATCH('面板-总览'!$R34,'面板-景气指数'!$A$37:$A$242,0),MATCH('面板-总览'!S$2,'面板-景气指数'!$36:$36,0)) -> 0.5845 | T34: =INDEX('面板-景气指数'!$37:$242,MATCH('面板-总览'!$R34,'面板-景气指数'!$A$37:$A$242,0),MATCH('面板-总览'!T$2,'面板-景气指数'!$36:$36,0)) -> 0.606 | U34: =INDEX('面板-景气指数'!$37:$242,MATCH('面板-总览'!$R34,'面板-景气指数'!$A$37:$A$242,0),MATCH('面板-总览'!U$2,'面板-景气指数'!$36:$36,0)) -> 0.4675 | V34: =INDEX('面板-景气指数'!$37:$242,MATCH('面板-总览'!$R34,'面板-景气指数'!$A$37:$A$242,0),MATCH('面板-总览'!V$2,'面板-景气指数'!$36:$36,0)) -> 0.308 | W34: =INDEX('面板-景气指数'!$37:$242,MATCH('面板-总览'!$R34,'面板-景气指数'!$A$37:$A$242,0),MATCH('面板-总览'!W$2,'面板-景气指数'!$36:$36,0)) -> 0.2705 | X34: =INDEX('面板-景气指数'!$37:$242,MATCH('面板-总览'!$R34,'面板-景气指数'!$A$37:$A$242,0),MATCH('面板-总览'!X$2,'面板-景气指数'!$36:$36,0)) -> 0.154 | Y34: =INDEX('面板-景气指数'!$37:$242,MATCH('面板-总览'!$R34,'面板-景气指数'!$A$37:$A$242,0),MATCH('面板-总览'!Y$2,'面板-景气指数'!$36:$36,0)) -> 0.1215 | Z34: =INDEX('面板-景气指数'!$37:$242,MATCH('面板-总览'!$R34,'面板-景气指数'!$A$37:$A$242,0),MATCH('面板-总览'!Z$2,'面板-景气指数'!$36:$36,0)) -> 0.085 | ... AE34: =INDEX('面板-景气指数'!$37:$242,MATCH('面板-总览'!$R34,'面板-景气指数'!$A$37:$A$242,0),MATCH('面板-总览'!AE$2,'面板-景气指数'!$36:$36,0)) -> 0.0155 | AG34: =AE34-AB34 -> -0.0105 | AI34: 合成树脂 | AJ34: =INDEX('面板-景气指数'!$37:$242,MATCH('面板-总览'!$AI34,'面板-景气指数'!$A$37:$A$242,0),MATCH('面板-总览'!AJ$2,'面板-景气指数'!$36:$36,0)) -> 0.414 | AK34: =INDEX('面板-景气指数'!$37:$242,MATCH('面板-总览'!$AI34,'面板-景气指数'!$A$37:$A$242,0),MATCH('面板-总览'!AK$2,'面板-景气指数'!$36:$36,0)) -> 0.393 | AL34: =INDEX('面板-景气指数'!$37:$242,MATCH('面板-总览'!$AI34,'面板-景气指数'!$A$37:$A$242,0),MATCH('面板-总览'!AL$2,'面板-景气指数'!$36:$36,0)) -> 0.34 | AM34: =INDEX('面板-景气指数'!$37:$242,MATCH('面板-总览'!$AI34,'面板-景气指数'!$A$37:$A$242,0),MATCH('面板-总览'!AM$2,'面板-景气指数'!$36:$36,0)) -> 0.329 | AN34: =INDEX('面板-景气指数'!$37:$242,MATCH('面板-总览'!$AI34,'面板-景气指数'!$A$37:$A$242,0),MATCH('面板-总览'!AN$2,'面板-景气指数'!$36:$36,0)) -> 0.382 | AO34: =INDEX('面板-景气指数'!$37:$242,MATCH('面板-总览'!$AI34,'面板-景气指数'!$A$37:$A$242,0),MATCH('面板-总览'!AO$2,'面板-景气指数'!$36:$36,0)) -> 0.404 | AP34: =INDEX('面板-景气指数'!$37:$242,MATCH('面板-总览'!$AI34,'面板-景气指数'!$A$37:$A$242,0),MATCH('面板-总览'!AP$2,'面板-景气指数'!$36:$36,0)) -> 0.436 | AQ34: =INDEX('面板-景气指数'!$37:$242,MATCH('面板-总览'!$AI34,'面板-景气指数'!$A$37:$A$242,0),MATCH('面板-总览'!AQ$2,'面板-景气指数'!$36:$36,0)) -> 0.5 | ... AV34: =INDEX('面板-景气指数'!$37:$242,MATCH('面板-总览'!$AI34,'面板-景气指数'!$A$37:$A$242,0),MATCH('面板-总览'!AV$2,'面板-景气指数'!$36:$36,0)) -> 0.617 | AX34: =AV34-AS34 -> 0.054
R35: 军工电子 | S35: =INDEX('面板-景气指数'!$37:$242,MATCH('面板-总览'!$R35,'面板-景气指数'!$A$37:$A$242,0),MATCH('面板-总览'!S$2,'面板-景气指数'!$36:$36,0)) -> 0.308 | T35: =INDEX('面板-景气指数'!$37:$242,MATCH('面板-总览'!$R35,'面板-景气指数'!$A$37:$A$242,0),MATCH('面板-总览'!T$2,'面板-景气指数'!$36:$36,0)) -> 0.202 | U35: =INDEX('面板-景气指数'!$37:$242,MATCH('面板-总览'!$R35,'面板-景气指数'!$A$37:$A$242,0),MATCH('面板-总览'!U$2,'面板-景气指数'!$36:$36,0)) -> 0.18 | V35: =INDEX('面板-景气指数'!$37:$242,MATCH('面板-总览'!$R35,'面板-景气指数'!$A$37:$A$242,0),MATCH('面板-总览'!V$2,'面板-景气指数'!$36:$36,0)) -> 0.106 | W35: =INDEX('面板-景气指数'!$37:$242,MATCH('面板-总览'!$R35,'面板-景气指数'!$A$37:$A$242,0),MATCH('面板-总览'!W$2,'面板-景气指数'!$36:$36,0)) -> 0.148 | X35: =INDEX('面板-景气指数'!$37:$242,MATCH('面板-总览'!$R35,'面板-景气指数'!$A$37:$A$242,0),MATCH('面板-总览'!X$2,'面板-景气指数'!$36:$36,0)) -> 0.117 | Y35: =INDEX('面板-景气指数'!$37:$242,MATCH('面板-总览'!$R35,'面板-景气指数'!$A$37:$A$242,0),MATCH('面板-总览'!Y$2,'面板-景气指数'!$36:$36,0)) -> 0.127 | Z35: =INDEX('面板-景气指数'!$37:$242,MATCH('面板-总览'!$R35,'面板-景气指数'!$A$37:$A$242,0),MATCH('面板-总览'!Z$2,'面板-景气指数'!$36:$36,0)) -> 0.138 | ... AE35: =INDEX('面板-景气指数'!$37:$242,MATCH('面板-总览'!$R35,'面板-景气指数'!$A$37:$A$242,0),MATCH('面板-总览'!AE$2,'面板-景气指数'!$36:$36,0)) -> 0.265 | AG35: =AE35-AB35 -> 0.053 | AI35: 膜材料 | AJ35: =INDEX('面板-景气指数'!$37:$242,MATCH('面板-总览'!$AI35,'面板-景气指数'!$A$37:$A$242,0),MATCH('面板-总览'!AJ$2,'面板-景气指数'!$36:$36,0)) -> 0.468 | AK35: =INDEX('面板-景气指数'!$37:$242,MATCH('面板-总览'!$AI35,'面板-景气指数'!$A$37:$A$242,0),MATCH('面板-总览'!AK$2,'面板-景气指数'!$36:$36,0)) -> 0.457 | AL35: =INDEX('面板-景气指数'!$37:$242,MATCH('面板-总览'!$AI35,'面板-景气指数'!$A$37:$A$242,0),MATCH('面板-总览'!AL$2,'面板-景气指数'!$36:$36,0)) -> 0.425 | AM35: =INDEX('面板-景气指数'!$37:$242,MATCH('面板-总览'!$AI35,'面板-景气指数'!$A$37:$A$242,0),MATCH('面板-总览'!AM$2,'面板-景气指数'!$36:$36,0)) -> 0.351 | AN35: =INDEX('面板-景气指数'!$37:$242,MATCH('面板-总览'!$AI35,'面板-景气指数'!$A$37:$A$242,0),MATCH('面板-总览'!AN$2,'面板-景气指数'!$36:$36,0)) -> 0.319 | AO35: =INDEX('面板-景气指数'!$37:$242,MATCH('面板-总览'!$AI35,'面板-景气指数'!$A$37:$A$242,0),MATCH('面板-总览'!AO$2,'面板-景气指数'!$36:$36,0)) -> 0.34 | AP35: =INDEX('面板-景气指数'!$37:$242,MATCH('面板-总览'!$AI35,'面板-景气指数'!$A$37:$A$242,0),MATCH('面板-总览'!AP$2,'面板-景气指数'!$36:$36,0)) -> 0.202 | AQ35: =INDEX('面板-景气指数'!$37:$242,MATCH('面板-总览'!$AI35,'面板-景气指数'!$A$37:$A$242,0),MATCH('面板-总览'!AQ$2,'面板-景气指数'!$36:$36,0)) -> 0.148 | ... AV35: =INDEX('面板-景气指数'!$37:$242,MATCH('面板-总览'!$AI35,'面板-景气指数'!$A$37:$A$242,0),MATCH('面板-总览'!AV$2,'面板-景气指数'!$36:$36,0)) -> 0.404 | AX35: =AV35-AS35 -> -0.01
