Workbook

Sheet 相关性分析计算器
E1: 计算函数-相关性分析 V1.1
D4: 开始日期： | F4: 44594
D5: 截止日期： | F5: =TODAY() -> 45674
D6: 周期类型： | F6: 日线
D7: Wind代码(行）： | F7: AU.SHF,AG.SHF,CU.SHF,ZN.SHF,RB.SHF,J.DCE,JM.DCE,TA.CZC,FG.CZC,A.DCE,Y.DCE,M.DCE,C.DCE,SR.CZC,NH0100.NHF
D8: Wind代码(列）： | F8: AU.SHF,AG.SHF,CU.SHF,ZN.SHF,RB.SHF,J.DCE,JM.DCE,TA.CZC,FG.CZC,A.DCE,Y.DCE,M.DCE,C.DCE,SR.CZC,NH0100.NHF
D10: =TRIM(MID(SUBSTITUTE($F$8,",",REPT(" ",LEN($F$8))),(COLUMN(D:D)-4)*LEN($F$8)+1,LEN($F$8))) -> AU.SHF | E10: =TRIM(MID(SUBSTITUTE($F$8,",",REPT(" ",LEN($F$8))),(COLUMN(E:E)-4)*LEN($F$8)+1,LEN($F$8))) -> AG.SHF | F10: =TRIM(MID(SUBSTITUTE($F$8,",",REPT(" ",LEN($F$8))),(COLUMN(F:F)-4)*LEN($F$8)+1,LEN($F$8))) -> CU.SHF | G10: =TRIM(MID(SUBSTITUTE($F$8,",",REPT(" ",LEN($F$8))),(COLUMN(G:G)-4)*LEN($F$8)+1,LEN($F$8))) -> ZN.SHF | H10: =TRIM(MID(SUBSTITUTE($F$8,",",REPT(" ",LEN($F$8))),(COLUMN(H:H)-4)*LEN($F$8)+1,LEN($F$8))) -> RB.SHF | I10: =TRIM(MID(SUBSTITUTE($F$8,",",REPT(" ",LEN($F$8))),(COLUMN(I:I)-4)*LEN($F$8)+1,LEN($F$8))) -> J.DCE | J10: =TRIM(MID(SUBSTITUTE($F$8,",",REPT(" ",LEN($F$8))),(COLUMN(J:J)-4)*LEN($F$8)+1,LEN($F$8))) -> JM.DCE | K10: =TRIM(MID(SUBSTITUTE($F$8,",",REPT(" ",LEN($F$8))),(COLUMN(K:K)-4)*LEN($F$8)+1,LEN($F$8))) -> TA.CZC | L10: =TRIM(MID(SUBSTITUTE($F$8,",",REPT(" ",LEN($F$8))),(COLUMN(L:L)-4)*LEN($F$8)+1,LEN($F$8))) -> FG.CZC | M10: =TRIM(MID(SUBSTITUTE($F$8,",",REPT(" ",LEN($F$8))),(COLUMN(M:M)-4)*LEN($F$8)+1,LEN($F$8))) -> A.DCE | N10: =TRIM(MID(SUBSTITUTE($F$8,",",REPT(" ",LEN($F$8))),(COLUMN(N:N)-4)*LEN($F$8)+1,LEN($F$8))) -> Y.DCE | O10: =TRIM(MID(SUBSTITUTE($F$8,",",REPT(" ",LEN($F$8))),(COLUMN(O:O)-4)*LEN($F$8)+1,LEN($F$8))) -> M.DCE | P10: =TRIM(MID(SUBSTITUTE($F$8,",",REPT(" ",LEN($F$8))),(COLUMN(P:P)-4)*LEN($F$8)+1,LEN($F$8))) -> C.DCE | Q10: =TRIM(MID(SUBSTITUTE($F$8,",",REPT(" ",LEN($F$8))),(COLUMN(Q:Q)-4)*LEN($F$8)+1,LEN($F$8))) -> SR.CZC | R10: =TRIM(MID(SUBSTITUTE($F$8,",",REPT(" ",LEN($F$8))),(COLUMN(R:R)-4)*LEN($F$8)+1,LEN($F$8))) -> NH0100.NHF | S10: =TRIM(MID(SUBSTITUTE($F$8,",",REPT(" ",LEN($F$8))),(COLUMN(S:S)-4)*LEN($F$8)+1,LEN($F$8))) | T10: =TRIM(MID(SUBSTITUTE($F$8,",",REPT(" ",LEN($F$8))),(COLUMN(T:T)-4)*LEN($F$8)+1,LEN($F$8))) | U10: =TRIM(MID(SUBSTITUTE($F$8,",",REPT(" ",LEN($F$8))),(COLUMN(U:U)-4)*LEN($F$8)+1,LEN($F$8))) | V10: =TRIM(MID(SUBSTITUTE($F$8,",",REPT(" ",LEN($F$8))),(COLUMN(V:V)-4)*LEN($F$8)+1,LEN($F$8))) | Z10: 日线
C11: =TRIM(MID(SUBSTITUTE($F$7,",",REPT(" ",LEN($F$7))),(ROW(11:11)-11)*LEN($F$7)+1,LEN($F$7))) -> AU.SHF | D11: =IF(data!B2="","",data!B2) -> 1 | E11: =IF(data!C2="","",data!C2) -> 0.96897998 | F11: =IF(data!D2="","",data!D2) -> 0.71316434 | G11: =IF(data!E2="","",data!E2) -> -0.025495128 | H11: =IF(data!F2="","",data!F2) -> -0.6981002 | I11: =IF(data!G2="","",data!G2) -> -0.73981268 | J11: =IF(data!H2="","",data!H2) -> -0.68618886 | K11: =IF(data!I2="","",data!I2) -> -0.40864656 | ... V11: =IF(data!T2="","",data!T2) | Z11: 周线
C12: =TRIM(MID(SUBSTITUTE($F$7,",",REPT(" ",LEN($F$7))),(ROW(12:12)-11)*LEN($F$7)+1,LEN($F$7))) -> AG.SHF | D12: =IF(data!B3="","",data!B3) -> 0.96897998 | E12: =IF(data!C3="","",data!C3) -> 1 | F12: =IF(data!D3="","",data!D3) -> 0.80840073 | G12: =IF(data!E3="","",data!E3) -> 0.008635457 | H12: =IF(data!F3="","",data!F3) -> -0.61922527 | I12: =IF(data!G3="","",data!G3) -> -0.66391322 | J12: =IF(data!H3="","",data!H3) -> -0.61453193 | K12: =IF(data!I3="","",data!I3) -> -0.33060682 | ... V12: =IF(data!T3="","",data!T3) | Z12: 月线
C13: =TRIM(MID(SUBSTITUTE($F$7,",",REPT(" ",LEN($F$7))),(ROW(13:13)-11)*LEN($F$7)+1,LEN($F$7))) -> CU.SHF | D13: =IF(data!B4="","",data!B4) -> 0.71316434 | E13: =IF(data!C4="","",data!C4) -> 0.80840073 | F13: =IF(data!D4="","",data!D4) -> 1 | G13: =IF(data!E4="","",data!E4) -> 0.29846585 | H13: =IF(data!F4="","",data!F4) -> -0.13612031 | I13: =IF(data!G4="","",data!G4) -> -0.20627265 | J13: =IF(data!H4="","",data!H4) -> -0.16822187 | K13: =IF(data!I4="","",data!I4) -> 0.022447765 | ... V13: =IF(data!T4="","",data!T4)
C14: =TRIM(MID(SUBSTITUTE($F$7,",",REPT(" ",LEN($F$7))),(ROW(14:14)-11)*LEN($F$7)+1,LEN($F$7))) -> ZN.SHF | D14: =IF(data!B5="","",data!B5) -> -0.025495128 | E14: =IF(data!C5="","",data!C5) -> 0.008635457 | F14: =IF(data!D5="","",data!D5) -> 0.29846585 | G14: =IF(data!E5="","",data!E5) -> 1 | H14: =IF(data!F5="","",data!F5) -> 0.38596446 | I14: =IF(data!G5="","",data!G5) -> 0.49783718 | J14: =IF(data!H5="","",data!H5) -> 0.50524812 | K14: =IF(data!I5="","",data!I5) -> -0.016289107 | ... V14: =IF(data!T5="","",data!T5)
C15: =TRIM(MID(SUBSTITUTE($F$7,",",REPT(" ",LEN($F$7))),(ROW(15:15)-11)*LEN($F$7)+1,LEN($F$7))) -> RB.SHF | D15: =IF(data!B6="","",data!B6) -> -0.6981002 | E15: =IF(data!C6="","",data!C6) -> -0.61922527 | F15: =IF(data!D6="","",data!D6) -> -0.13612031 | G15: =IF(data!E6="","",data!E6) -> 0.38596446 | H15: =IF(data!F6="","",data!F6) -> 1 | I15: =IF(data!G6="","",data!G6) -> 0.94245767 | J15: =IF(data!H6="","",data!H6) -> 0.90079667 | K15: =IF(data!I6="","",data!I6) -> 0.59053983 | ... V15: =IF(data!T6="","",data!T6)
C16: =TRIM(MID(SUBSTITUTE($F$7,",",REPT(" ",LEN($F$7))),(ROW(16:16)-11)*LEN($F$7)+1,LEN($F$7))) -> J.DCE | D16: =IF(data!B7="","",data!B7) -> -0.73981268 | E16: =IF(data!C7="","",data!C7) -> -0.66391322 | F16: =IF(data!D7="","",data!D7) -> -0.20627265 | G16: =IF(data!E7="","",data!E7) -> 0.49783718 | H16: =IF(data!F7="","",data!F7) -> 0.94245767 | I16: =IF(data!G7="","",data!G7) -> 1 | J16: =IF(data!H7="","",data!H7) -> 0.97474191 | K16: =IF(data!I7="","",data!I7) -> 0.54823229 | ... V16: =IF(data!T7="","",data!T7)
C17: =TRIM(MID(SUBSTITUTE($F$7,",",REPT(" ",LEN($F$7))),(ROW(17:17)-11)*LEN($F$7)+1,LEN($F$7))) -> JM.DCE | D17: =IF(data!B8="","",data!B8) -> -0.68618886 | E17: =IF(data!C8="","",data!C8) -> -0.61453193 | F17: =IF(data!D8="","",data!D8) -> -0.16822187 | G17: =IF(data!E8="","",data!E8) -> 0.50524812 | H17: =IF(data!F8="","",data!F8) -> 0.90079667 | I17: =IF(data!G8="","",data!G8) -> 0.97474191 | J17: =IF(data!H8="","",data!H8) -> 1 | K17: =IF(data!I8="","",data!I8) -> 0.563998 | ... V17: =IF(data!T8="","",data!T8)
C18: =TRIM(MID(SUBSTITUTE($F$7,",",REPT(" ",LEN($F$7))),(ROW(18:18)-11)*LEN($F$7)+1,LEN($F$7))) -> TA.CZC | D18: =IF(data!B9="","",data!B9) -> -0.40864656 | E18: =IF(data!C9="","",data!C9) -> -0.33060682 | F18: =IF(data!D9="","",data!D9) -> 0.022447765 | G18: =IF(data!E9="","",data!E9) -> -0.016289107 | H18: =IF(data!F9="","",data!F9) -> 0.59053983 | I18: =IF(data!G9="","",data!G9) -> 0.54823229 | J18: =IF(data!H9="","",data!H9) -> 0.563998 | K18: =IF(data!I9="","",data!I9) -> 1 | ... V18: =IF(data!T9="","",data!T9)
C19: =TRIM(MID(SUBSTITUTE($F$7,",",REPT(" ",LEN($F$7))),(ROW(19:19)-11)*LEN($F$7)+1,LEN($F$7))) -> FG.CZC | D19: =IF(data!B10="","",data!B10) -> -0.52686047 | E19: =IF(data!C10="","",data!C10) -> -0.41861986 | F19: =IF(data!D10="","",data!D10) -> -0.057910914 | G19: =IF(data!E10="","",data!E10) -> -0.009758429 | H19: =IF(data!F10="","",data!F10) -> 0.79394966 | I19: =IF(data!G10="","",data!G10) -> 0.65872446 | J19: =IF(data!H10="","",data!H10) -> 0.64468917 | K19: =IF(data!I10="","",data!I10) -> 0.62229803 | ... V19: =IF(data!T10="","",data!T10)
C20: =TRIM(MID(SUBSTITUTE($F$7,",",REPT(" ",LEN($F$7))),(ROW(20:20)-11)*LEN($F$7)+1,LEN($F$7))) -> A.DCE | D20: =IF(data!B11="","",data!B11) -> -0.92663602 | E20: =IF(data!C11="","",data!C11) -> -0.87817387 | F20: =IF(data!D11="","",data!D11) -> -0.50408674 | G20: =IF(data!E11="","",data!E11) -> 0.27965446 | H20: =IF(data!F11="","",data!F11) -> 0.81077541 | I20: =IF(data!G11="","",data!G11) -> 0.8650929 | J20: =IF(data!H11="","",data!H11) -> 0.83484772 | K20: =IF(data!I11="","",data!I11) -> 0.51891024 | ... V20: =IF(data!T11="","",data!T11)
C21: =TRIM(MID(SUBSTITUTE($F$7,",",REPT(" ",LEN($F$7))),(ROW(21:21)-11)*LEN($F$7)+1,LEN($F$7))) -> Y.DCE | D21: =IF(data!B12="","",data!B12) -> -0.61160016 | E21: =IF(data!C12="","",data!C12) -> -0.58367574 | F21: =IF(data!D12="","",data!D12) -> -0.18408564 | G21: =IF(data!E12="","",data!E12) -> 0.68632046 | H21: =IF(data!F12="","",data!F12) -> 0.75044643 | I21: =IF(data!G12="","",data!G12) -> 0.84222248 | J21: =IF(data!H12="","",data!H12) -> 0.8367205 | K21: =IF(data!I12="","",data!I12) -> 0.40909919 | ... V21: =IF(data!T12="","",data!T12)
C22: =TRIM(MID(SUBSTITUTE($F$7,",",REPT(" ",LEN($F$7))),(ROW(22:22)-11)*LEN($F$7)+1,LEN($F$7))) -> M.DCE | D22: =IF(data!B13="","",data!B13) -> -0.81790258 | E22: =IF(data!C13="","",data!C13) -> -0.74198025 | F22: =IF(data!D13="","",data!D13) -> -0.46231818 | G22: =IF(data!E13="","",data!E13) -> 0.04420927 | H22: =IF(data!F13="","",data!F13) -> 0.5823533 | I22: =IF(data!G13="","",data!G13) -> 0.66129029 | J22: =IF(data!H13="","",data!H13) -> 0.62514753 | K22: =IF(data!I13="","",data!I13) -> 0.43641444 | ... V22: =IF(data!T13="","",data!T13)
C23: =TRIM(MID(SUBSTITUTE($F$7,",",REPT(" ",LEN($F$7))),(ROW(23:23)-11)*LEN($F$7)+1,LEN($F$7))) -> C.DCE | D23: =IF(data!B14="","",data!B14) -> -0.9089616 | E23: =IF(data!C14="","",data!C14) -> -0.84338141 | F23: =IF(data!D14="","",data!D14) -> -0.47039591 | G23: =IF(data!E14="","",data!E14) -> 0.18793055 | H23: =IF(data!F14="","",data!F14) -> 0.7271891 | I23: =IF(data!G14="","",data!G14) -> 0.77391125 | J23: =IF(data!H14="","",data!H14) -> 0.70278467 | K23: =IF(data!I14="","",data!I14) -> 0.45932467 | ... V23: =IF(data!T14="","",data!T14)
C24: =TRIM(MID(SUBSTITUTE($F$7,",",REPT(" ",LEN($F$7))),(ROW(24:24)-11)*LEN($F$7)+1,LEN($F$7))) -> SR.CZC | D24: =IF(data!B15="","",data!B15) -> 0.12760064 | E24: =IF(data!C15="","",data!C15) -> 0.14359787 | F24: =IF(data!D15="","",data!D15) -> 0.048304968 | G24: =IF(data!E15="","",data!E15) -> -0.73267821 | H24: =IF(data!F15="","",data!F15) -> -0.15419857 | I24: =IF(data!G15="","",data!G15) -> -0.31192483 | J24: =IF(data!H15="","",data!H15) -> -0.33519045 | K24: =IF(data!I15="","",data!I15) -> 0.2688781 | ... V24: =IF(data!T15="","",data!T15)
C25: =TRIM(MID(SUBSTITUTE($F$7,",",REPT(" ",LEN($F$7))),(ROW(25:25)-11)*LEN($F$7)+1,LEN($F$7))) -> NH0100.NHF | D25: =IF(data!B16="","",data!B16) -> 0.66212267 | E25: =IF(data!C16="","",data!C16) -> 0.72811861 | F25: =IF(data!D16="","",data!D16) -> 0.78434608 | G25: =IF(data!E16="","",data!E16) -> -0.0016888551 | H25: =IF(data!F16="","",data!F16) -> -0.19080575 | I25: =IF(data!G16="","",data!G16) -> -0.23491295 | J25: =IF(data!H16="","",data!H16) -> -0.17377905 | K25: =IF(data!I16="","",data!I16) -> 0.2222688 | ... V25: =IF(data!T16="","",data!T16)
C26: =TRIM(MID(SUBSTITUTE($F$7,",",REPT(" ",LEN($F$7))),(ROW(26:26)-11)*LEN($F$7)+1,LEN($F$7))) | D26: =IF(data!B17="","",data!B17) | E26: =IF(data!C17="","",data!C17) | F26: =IF(data!D17="","",data!D17) | G26: =IF(data!E17="","",data!E17) | H26: =IF(data!F17="","",data!F17) | I26: =IF(data!G17="","",data!G17) | J26: =IF(data!H17="","",data!H17) | K26: =IF(data!I17="","",data!I17) | ... V26: =IF(data!T17="","",data!T17)
C27: =TRIM(MID(SUBSTITUTE($F$7,",",REPT(" ",LEN($F$7))),(ROW(27:27)-11)*LEN($F$7)+1,LEN($F$7))) | D27: =IF(data!B18="","",data!B18) | E27: =IF(data!C18="","",data!C18) | F27: =IF(data!D18="","",data!D18) | G27: =IF(data!E18="","",data!E18) | H27: =IF(data!F18="","",data!F18) | I27: =IF(data!G18="","",data!G18) | J27: =IF(data!H18="","",data!H18) | K27: =IF(data!I18="","",data!I18) | ... V27: =IF(data!T18="","",data!T18)
C28: =TRIM(MID(SUBSTITUTE($F$7,",",REPT(" ",LEN($F$7))),(ROW(28:28)-11)*LEN($F$7)+1,LEN($F$7))) | D28: =IF(data!B19="","",data!B19) | E28: =IF(data!C19="","",data!C19) | F28: =IF(data!D19="","",data!D19) | G28: =IF(data!E19="","",data!E19) | H28: =IF(data!F19="","",data!F19) | I28: =IF(data!G19="","",data!G19) | J28: =IF(data!H19="","",data!H19) | K28: =IF(data!I19="","",data!I19) | ... V28: =IF(data!T19="","",data!T19)
C29: =TRIM(MID(SUBSTITUTE($F$7,",",REPT(" ",LEN($F$7))),(ROW(29:29)-11)*LEN($F$7)+1,LEN($F$7))) | D29: =IF(data!B20="","",data!B20) | E29: =IF(data!C20="","",data!C20) | F29: =IF(data!D20="","",data!D20) | G29: =IF(data!E20="","",data!E20) | H29: =IF(data!F20="","",data!F20) | I29: =IF(data!G20="","",data!G20) | J29: =IF(data!H20="","",data!H20) | K29: =IF(data!I20="","",data!I20) | ... V29: =IF(data!T20="","",data!T20)
C30: =TRIM(MID(SUBSTITUTE($F$7,",",REPT(" ",LEN($F$7))),(ROW(30:30)-11)*LEN($F$7)+1,LEN($F$7))) | D30: =IF(data!B21="","",data!B21) | E30: =IF(data!C21="","",data!C21) | F30: =IF(data!D21="","",data!D21) | G30: =IF(data!E21="","",data!E21) | H30: =IF(data!F21="","",data!F21) | I30: =IF(data!G21="","",data!G21) | J30: =IF(data!H21="","",data!H21) | K30: =IF(data!I21="","",data!I21) | ... V30: =IF(data!T21="","",data!T21)
C31: =TRIM(MID(SUBSTITUTE($F$7,",",REPT(" ",LEN($F$7))),(ROW(31:31)-11)*LEN($F$7)+1,LEN($F$7))) | D31: =IF(data!B22="","",data!B22) | E31: =IF(data!C22="","",data!C22) | F31: =IF(data!D22="","",data!D22) | G31: =IF(data!E22="","",data!E22) | H31: =IF(data!F22="","",data!F22) | I31: =IF(data!G22="","",data!G22) | J31: =IF(data!H22="","",data!H22) | K31: =IF(data!I22="","",data!I22) | ... V31: =IF(data!T22="","",data!T22)
C32: =TRIM(MID(SUBSTITUTE($F$7,",",REPT(" ",LEN($F$7))),(ROW(32:32)-11)*LEN($F$7)+1,LEN($F$7))) | D32: =IF(data!B23="","",data!B23) | E32: =IF(data!C23="","",data!C23) | F32: =IF(data!D23="","",data!D23) | G32: =IF(data!E23="","",data!E23) | H32: =IF(data!F23="","",data!F23) | I32: =IF(data!G23="","",data!G23) | J32: =IF(data!H23="","",data!H23) | K32: =IF(data!I23="","",data!I23) | ... V32: =IF(data!T23="","",data!T23)
C33: =TRIM(MID(SUBSTITUTE($F$7,",",REPT(" ",LEN($F$7))),(ROW(33:33)-11)*LEN($F$7)+1,LEN($F$7))) | D33: =IF(data!B24="","",data!B24) | E33: =IF(data!C24="","",data!C24) | F33: =IF(data!D24="","",data!D24) | G33: =IF(data!E24="","",data!E24) | H33: =IF(data!F24="","",data!F24) | I33: =IF(data!G24="","",data!G24) | J33: =IF(data!H24="","",data!H24) | K33: =IF(data!I24="","",data!I24) | ... V33: =IF(data!T24="","",data!T24)
C34: =TRIM(MID(SUBSTITUTE($F$7,",",REPT(" ",LEN($F$7))),(ROW(34:34)-11)*LEN($F$7)+1,LEN($F$7))) | D34: =IF(data!B25="","",data!B25) | E34: =IF(data!C25="","",data!C25) | F34: =IF(data!D25="","",data!D25) | G34: =IF(data!E25="","",data!E25) | H34: =IF(data!F25="","",data!F25) | I34: =IF(data!G25="","",data!G25) | J34: =IF(data!H25="","",data!H25) | K34: =IF(data!I25="","",data!I25) | ... V34: =IF(data!T25="","",data!T25)
C35: =TRIM(MID(SUBSTITUTE($F$7,",",REPT(" ",LEN($F$7))),(ROW(35:35)-11)*LEN($F$7)+1,LEN($F$7))) | D35: =IF(data!B26="","",data!B26) | E35: =IF(data!C26="","",data!C26) | F35: =IF(data!D26="","",data!D26) | G35: =IF(data!E26="","",data!E26) | H35: =IF(data!F26="","",data!F26) | I35: =IF(data!G26="","",data!G26) | J35: =IF(data!H26="","",data!H26) | K35: =IF(data!I26="","",data!I26) | ... V35: =IF(data!T26="","",data!T26)
C36: =TRIM(MID(SUBSTITUTE($F$7,",",REPT(" ",LEN($F$7))),(ROW(36:36)-11)*LEN($F$7)+1,LEN($F$7))) | D36: =IF(data!B27="","",data!B27) | E36: =IF(data!C27="","",data!C27) | F36: =IF(data!D27="","",data!D27) | G36: =IF(data!E27="","",data!E27) | H36: =IF(data!F27="","",data!F27) | I36: =IF(data!G27="","",data!G27) | J36: =IF(data!H27="","",data!H27) | K36: =IF(data!I27="","",data!I27) | ... V36: =IF(data!T27="","",data!T27)
C37: =TRIM(MID(SUBSTITUTE($F$7,",",REPT(" ",LEN($F$7))),(ROW(37:37)-11)*LEN($F$7)+1,LEN($F$7))) | D37: =IF(data!B28="","",data!B28) | E37: =IF(data!C28="","",data!C28) | F37: =IF(data!D28="","",data!D28) | G37: =IF(data!E28="","",data!E28) | H37: =IF(data!F28="","",data!F28) | I37: =IF(data!G28="","",data!G28) | J37: =IF(data!H28="","",data!H28) | K37: =IF(data!I28="","",data!I28) | ... V37: =IF(data!T28="","",data!T28)
C38: =TRIM(MID(SUBSTITUTE($F$7,",",REPT(" ",LEN($F$7))),(ROW(38:38)-11)*LEN($F$7)+1,LEN($F$7))) | D38: =IF(data!B29="","",data!B29) | E38: =IF(data!C29="","",data!C29) | F38: =IF(data!D29="","",data!D29) | G38: =IF(data!E29="","",data!E29) | H38: =IF(data!F29="","",data!F29) | I38: =IF(data!G29="","",data!G29) | J38: =IF(data!H29="","",data!H29) | K38: =IF(data!I29="","",data!I29) | ... V38: =IF(data!T29="","",data!T29)
C39: =TRIM(MID(SUBSTITUTE($F$7,",",REPT(" ",LEN($F$7))),(ROW(39:39)-11)*LEN($F$7)+1,LEN($F$7))) | D39: =IF(data!B30="","",data!B30) | E39: =IF(data!C30="","",data!C30) | F39: =IF(data!D30="","",data!D30) | G39: =IF(data!E30="","",data!E30) | H39: =IF(data!F30="","",data!F30) | I39: =IF(data!G30="","",data!G30) | J39: =IF(data!H30="","",data!H30) | K39: =IF(data!I30="","",data!I30) | ... V39: =IF(data!T30="","",data!T30)
C40: =TRIM(MID(SUBSTITUTE($F$7,",",REPT(" ",LEN($F$7))),(ROW(40:40)-11)*LEN($F$7)+1,LEN($F$7))) | D40: =IF(data!B31="","",data!B31) | E40: =IF(data!C31="","",data!C31) | F40: =IF(data!D31="","",data!D31) | G40: =IF(data!E31="","",data!E31) | H40: =IF(data!F31="","",data!F31) | I40: =IF(data!G31="","",data!G31) | J40: =IF(data!H31="","",data!H31) | K40: =IF(data!I31="","",data!I31) | ... V40: =IF(data!T31="","",data!T31)
C41: =TRIM(MID(SUBSTITUTE($F$7,",",REPT(" ",LEN($F$7))),(ROW(41:41)-11)*LEN($F$7)+1,LEN($F$7))) | D41: =IF(data!B32="","",data!B32) | E41: =IF(data!C32="","",data!C32) | F41: =IF(data!D32="","",data!D32) | G41: =IF(data!E32="","",data!E32) | H41: =IF(data!F32="","",data!F32) | I41: =IF(data!G32="","",data!G32) | J41: =IF(data!H32="","",data!H32) | K41: =IF(data!I32="","",data!I32) | ... V41: =IF(data!T32="","",data!T32)
C42: =TRIM(MID(SUBSTITUTE($F$7,",",REPT(" ",LEN($F$7))),(ROW(42:42)-11)*LEN($F$7)+1,LEN($F$7))) | D42: =IF(data!B33="","",data!B33) | E42: =IF(data!C33="","",data!C33) | F42: =IF(data!D33="","",data!D33) | G42: =IF(data!E33="","",data!E33) | H42: =IF(data!F33="","",data!F33) | I42: =IF(data!G33="","",data!G33) | J42: =IF(data!H33="","",data!H33) | K42: =IF(data!I33="","",data!I33) | ... V42: =IF(data!T33="","",data!T33)
C43: =TRIM(MID(SUBSTITUTE($F$7,",",REPT(" ",LEN($F$7))),(ROW(43:43)-11)*LEN($F$7)+1,LEN($F$7))) | D43: =IF(data!B34="","",data!B34) | E43: =IF(data!C34="","",data!C34) | F43: =IF(data!D34="","",data!D34) | G43: =IF(data!E34="","",data!E34) | H43: =IF(data!F34="","",data!F34) | I43: =IF(data!G34="","",data!G34) | J43: =IF(data!H34="","",data!H34) | K43: =IF(data!I34="","",data!I34) | ... V43: =IF(data!T34="","",data!T34)
...

Sheet data
B2: =[1]!wset("correlationanalysis","startDate="&TEXT(相关性分析计算器!$F$4,"YYYYMMDD"),"endDate="&TEXT(相关性分析计算器!$F$5,"YYYYMMDD"),"frequency="&相关性分析计算器!$F$6,"windCodes="&相关性分析计算器!$F$7,"relateWindCodes="&相关性分析计算器!$F$8,"cols=15;rows=15") -> 1 | C2: 0.96897998 | D2: 0.71316434 | E2: -0.025495128 | F2: -0.6981002 | G2: -0.73981268 | H2: -0.68618886 | I2: -0.40864656 | J2: -0.52686047 | K2: -0.92663602 | L2: -0.61160016 | M2: -0.81790258 | N2: -0.9089616 | O2: 0.12760064 | P2: 0.66212267
B3: 0.96897998 | C3: 1 | D3: 0.80840073 | E3: 0.008635457 | F3: -0.61922527 | G3: -0.66391322 | H3: -0.61453193 | I3: -0.33060682 | J3: -0.41861986 | K3: -0.87817387 | L3: -0.58367574 | M3: -0.74198025 | N3: -0.84338141 | O3: 0.14359787 | P3: 0.72811861
B4: 0.71316434 | C4: 0.80840073 | D4: 1 | E4: 0.29846585 | F4: -0.13612031 | G4: -0.20627265 | H4: -0.16822187 | I4: 0.022447765 | J4: -0.057910914 | K4: -0.50408674 | L4: -0.18408564 | M4: -0.46231818 | N4: -0.47039591 | O4: 0.048304968 | P4: 0.78434608
B5: -0.025495128 | C5: 0.008635457 | D5: 0.29846585 | E5: 1 | F5: 0.38596446 | G5: 0.49783718 | H5: 0.50524812 | I5: -0.016289107 | J5: -0.009758429 | K5: 0.27965446 | L5: 0.68632046 | M5: 0.04420927 | N5: 0.18793055 | O5: -0.73267821 | P5: -0.0016888551
B6: -0.6981002 | C6: -0.61922527 | D6: -0.13612031 | E6: 0.38596446 | F6: 1 | G6: 0.94245767 | H6: 0.90079667 | I6: 0.59053983 | J6: 0.79394966 | K6: 0.81077541 | L6: 0.75044643 | M6: 0.5823533 | N6: 0.7271891 | O6: -0.15419857 | P6: -0.19080575
B7: -0.73981268 | C7: -0.66391322 | D7: -0.20627265 | E7: 0.49783718 | F7: 0.94245767 | G7: 1 | H7: 0.97474191 | I7: 0.54823229 | J7: 0.65872446 | K7: 0.8650929 | L7: 0.84222248 | M7: 0.66129029 | N7: 0.77391125 | O7: -0.31192483 | P7: -0.23491295
B8: -0.68618886 | C8: -0.61453193 | D8: -0.16822187 | E8: 0.50524812 | F8: 0.90079667 | G8: 0.97474191 | H8: 1 | I8: 0.563998 | J8: 0.64468917 | K8: 0.83484772 | L8: 0.8367205 | M8: 0.62514753 | N8: 0.70278467 | O8: -0.33519045 | P8: -0.17377905
B9: -0.40864656 | C9: -0.33060682 | D9: 0.022447765 | E9: -0.016289107 | F9: 0.59053983 | G9: 0.54823229 | H9: 0.563998 | I9: 1 | J9: 0.62229803 | K9: 0.51891024 | L9: 0.40909919 | M9: 0.43641444 | N9: 0.45932467 | O9: 0.2688781 | P9: 0.2222688
B10: -0.52686047 | C10: -0.41861986 | D10: -0.057910914 | E10: -0.009758429 | F10: 0.79394966 | G10: 0.65872446 | H10: 0.64468917 | I10: 0.62229803 | J10: 1 | K10: 0.55204178 | L10: 0.35730969 | M10: 0.46036826 | N10: 0.50934906 | O10: 0.25851791 | P10: 0.037641892
B11: -0.92663602 | C11: -0.87817387 | D11: -0.50408674 | E11: 0.27965446 | F11: 0.81077541 | G11: 0.8650929 | H11: 0.83484772 | I11: 0.51891024 | J11: 0.55204178 | K11: 1 | L11: 0.79808591 | M11: 0.80633735 | N11: 0.90683936 | O11: -0.25473919 | P11: -0.5434871
B12: -0.61160016 | C12: -0.58367574 | D12: -0.18408564 | E12: 0.68632046 | F12: 0.75044643 | G12: 0.84222248 | H12: 0.8367205 | I12: 0.40909919 | J12: 0.35730969 | K12: 0.79808591 | L12: 1 | M12: 0.60488678 | N12: 0.69325414 | O12: -0.49259984 | P12: -0.31011233
B13: -0.81790258 | C13: -0.74198025 | D13: -0.46231818 | E13: 0.04420927 | F13: 0.5823533 | G13: 0.66129029 | H13: 0.62514753 | I13: 0.43641444 | J13: 0.46036826 | K13: 0.80633735 | L13: 0.60488678 | M13: 1 | N13: 0.86985565 | O13: 0.014399494 | P13: -0.35973017
B14: -0.9089616 | C14: -0.84338141 | D14: -0.47039591 | E14: 0.18793055 | F14: 0.7271891 | G14: 0.77391125 | H14: 0.70278467 | I14: 0.45932467 | J14: 0.50934906 | K14: 0.90683936 | L14: 0.69325414 | M14: 0.86985565 | N14: 1 | O14: -0.14552759 | P14: -0.50599281
... B16: 0.66212267 | C16: 0.72811861 | D16: 0.78434608 | E16: -0.0016888551 | F16: -0.19080575 | G16: -0.23491295 | H16: -0.17377905 | I16: 0.2222688 | J16: 0.037641892 | K16: -0.5434871 | L16: -0.31011233 | M16: -0.35973017 | N16: -0.50599281 | O16: 0.3183468 | P16: 1

Sheet Wind模板
A1: 相关性分析计算器
