Workbook
Name Bubble: "Bubble"
Name Chart: "Chart"
Name Heatmap: "Heatmap"
Name Histogram: "Histogram"
Name Map: "Map"
Name PieChart: "PieChart"
Name Scatter: "Scatter"
Name Series: "Series"
Name Table: "Table"

Sheet 面板-总览
A1: 一级行业 | R1: 二级行业 | AI1: 三级行业
A2: 景气指数 | B2: 45016 | C2: 45046 | D2: 45077 | E2: 45107 | F2: 45138 | G2: 45169 | H2: 45199 | I2: 45230 | J2: 45260 | K2: 45291 | L2: 45322 | M2: 45351 | N2: 45382 | O2: 3M变化 | R2: 景气指数 | S2: 45016 | T2: 45046 | U2: 45077 | V2: 45107 | W2: 45138 | X2: 45169 | Y2: 45199 | Z2: 45230 | AA2: 45260 | AB2: 45291 | AC2: 45322 | AD2: 45351 | AE2: 45382 | AF2: 3M变化 | AI2: 景气指数 | AJ2: 45016 | AK2: 45046 | AL2: 45077 | AM2: 45107 | AN2: 45138 | AO2: 45169 | AP2: 45199 | AQ2: 45230 | AR2: 45260 | AS2: 45291 | AT2: 45322 | AU2: 45351 | AV2: 45382 | AW2: 3M变化
A3: 石油石化 | B3: =INDEX('面板-景气指数'!$37:$242,MATCH('面板-总览'!$A3,'面板-景气指数'!$A$37:$A$242,0),MATCH('面板-总览'!B$2,'面板-景气指数'!$36:$36,0)) -> 0.7742 | C3: =INDEX('面板-景气指数'!$37:$242,MATCH('面板-总览'!$A3,'面板-景气指数'!$A$37:$A$242,0),MATCH('面板-总览'!C$2,'面板-景气指数'!$36:$36,0)) -> 0.76705 | D3: =INDEX('面板-景气指数'!$37:$242,MATCH('面板-总览'!$A3,'面板-景气指数'!$A$37:$A$242,0),MATCH('面板-总览'!D$2,'面板-景气指数'!$36:$36,0)) -> 0.73925 | E3: =INDEX('面板-景气指数'!$37:$242,MATCH('面板-总览'!$A3,'面板-景气指数'!$A$37:$A$242,0),MATCH('面板-总览'!E$2,'面板-景气指数'!$36:$36,0)) -> 0.59605 | F3: =INDEX('面板-景气指数'!$37:$242,MATCH('面板-总览'!$A3,'面板-景气指数'!$A$37:$A$242,0),MATCH('面板-总览'!F$2,'面板-景气指数'!$36:$36,0)) -> 0.64515 | G3: =INDEX('面板-景气指数'!$37:$242,MATCH('面板-总览'!$A3,'面板-景气指数'!$A$37:$A$242,0),MATCH('面板-总览'!G$2,'面板-景气指数'!$36:$36,0)) -> 0.7512 | H3: =INDEX('面板-景气指数'!$37:$242,MATCH('面板-总览'!$A3,'面板-景气指数'!$A$37:$A$242,0),MATCH('面板-总览'!H$2,'面板-景气指数'!$36:$36,0)) -> 0.8029 | I3: =INDEX('面板-景气指数'!$37:$242,MATCH('面板-总览'!$A3,'面板-景气指数'!$A$37:$A$242,0),MATCH('面板-总览'!I$2,'面板-景气指数'!$36:$36,0)) -> 0.7284 | ... N3: =INDEX('面板-景气指数'!$37:$242,MATCH('面板-总览'!$A3,'面板-景气指数'!$A$37:$A$242,0),MATCH('面板-总览'!N$2,'面板-景气指数'!$36:$36,0)) -> 0.6364 | P3: =N3-K3 -> 0.19375 | R3: 油气开采/油服工程 | S3: =INDEX('面板-景气指数'!$37:$242,MATCH('面板-总览'!$R3,'面板-景气指数'!$A$37:$A$242,0),MATCH('面板-总览'!S$2,'面板-景气指数'!$36:$36,0)) -> 0.66392308 | T3: =INDEX('面板-景气指数'!$37:$242,MATCH('面板-总览'!$R3,'面板-景气指数'!$A$37:$A$242,0),MATCH('面板-总览'!T$2,'面板-景气指数'!$36:$36,0)) -> 0.64161538 | U3: =INDEX('面板-景气指数'!$37:$242,MATCH('面板-总览'!$R3,'面板-景气指数'!$A$37:$A$242,0),MATCH('面板-总览'!U$2,'面板-景气指数'!$36:$36,0)) -> 0.60476923 | V3: =INDEX('面板-景气指数'!$37:$242,MATCH('面板-总览'!$R3,'面板-景气指数'!$A$37:$A$242,0),MATCH('面板-总览'!V$2,'面板-景气指数'!$36:$36,0)) -> 0.64776923 | W3: =INDEX('面板-景气指数'!$37:$242,MATCH('面板-总览'!$R3,'面板-景气指数'!$A$37:$A$242,0),MATCH('面板-总览'!W$2,'面板-景气指数'!$36:$36,0)) -> 0.69853846 | X3: =INDEX('面板-景气指数'!$37:$242,MATCH('面板-总览'!$R3,'面板-景气指数'!$A$37:$A$242,0),MATCH('面板-总览'!X$2,'面板-景气指数'!$36:$36,0)) -> 0.75615385 | Y3: =INDEX('面板-景气指数'!$37:$242,MATCH('面板-总览'!$R3,'面板-景气指数'!$A$37:$A$242,0),MATCH('面板-总览'!Y$2,'面板-景气指数'!$36:$36,0)) -> 0.75815385 | Z3: =INDEX('面板-景气指数'!$37:$242,MATCH('面板-总览'!$R3,'面板-景气指数'!$A$37:$A$242,0),MATCH('面板-总览'!Z$2,'面板-景气指数'!$36:$36,0)) -> 0.71569231 | ... AE3: =INDEX('面板-景气指数'!$37:$242,MATCH('面板-总览'!$R3,'面板-景气指数'!$A$37:$A$242,0),MATCH('面板-总览'!AE$2,'面板-景气指数'!$36:$36,0)) -> 0.70715385 | AG3: =AE3-AB3 -> 0.053615385 | AI3: 铜 | AJ3: =INDEX('面板-景气指数'!$37:$242,MATCH('面板-总览'!$AI3,'面板-景气指数'!$A$37:$A$242,0),MATCH('面板-总览'!AJ$2,'面板-景气指数'!$36:$36,0)) -> 0.285 | AK3: =INDEX('面板-景气指数'!$37:$242,MATCH('面板-总览'!$AI3,'面板-景气指数'!$A$37:$A$242,0),MATCH('面板-总览'!AK$2,'面板-景气指数'!$36:$36,0)) -> 0.193 | AL3: =INDEX('面板-景气指数'!$37:$242,MATCH('面板-总览'!$AI3,'面板-景气指数'!$A$37:$A$242,0),MATCH('面板-总览'!AL$2,'面板-景气指数'!$36:$36,0)) -> 0.265 | AM3: =INDEX('面板-景气指数'!$37:$242,MATCH('面板-总览'!$AI3,'面板-景气指数'!$A$37:$A$242,0),MATCH('面板-总览'!AM$2,'面板-景气指数'!$36:$36,0)) -> 0.489 | AN3: =INDEX('面板-景气指数'!$37:$242,MATCH('面板-总览'!$AI3,'面板-景气指数'!$A$37:$A$242,0),MATCH('面板-总览'!AN$2,'面板-景气指数'!$36:$36,0)) -> 0.581 | AO3: =INDEX('面板-景气指数'!$37:$242,MATCH('面板-总览'!$AI3,'面板-景气指数'!$A$37:$A$242,0),MATCH('面板-总览'!AO$2,'面板-景气指数'!$36:$36,0)) -> 0.683 | AP3: =INDEX('面板-景气指数'!$37:$242,MATCH('面板-总览'!$AI3,'面板-景气指数'!$A$37:$A$242,0),MATCH('面板-总览'!AP$2,'面板-景气指数'!$36:$36,0)) -> 0.571 | AQ3: =INDEX('面板-景气指数'!$37:$242,MATCH('面板-总览'!$AI3,'面板-景气指数'!$A$37:$A$242,0),MATCH('面板-总览'!AQ$2,'面板-景气指数'!$36:$36,0)) -> 0.551 | ... AV3: =INDEX('面板-景气指数'!$37:$242,MATCH('面板-总览'!$AI3,'面板-景气指数'!$A$37:$A$242,0),MATCH('面板-总览'!AV$2,'面板-景气指数'!$36:$36,0)) -> 0.459 | AX3: =AV3-AS3 -> -0.041
A4: 煤炭 | B4: =INDEX('面板-景气指数'!$37:$242,MATCH('面板-总览'!$A4,'面板-景气指数'!$A$37:$A$242,0),MATCH('面板-总览'!B$2,'面板-景气指数'!$36:$36,0)) -> 0.8505 | C4: =INDEX('面板-景气指数'!$37:$242,MATCH('面板-总览'!$A4,'面板-景气指数'!$A$37:$A$242,0),MATCH('面板-总览'!C$2,'面板-景气指数'!$36:$36,0)) -> 0.83283333 | D4: =INDEX('面板-景气指数'!$37:$242,MATCH('面板-总览'!$A4,'面板-景气指数'!$A$37:$A$242,0),MATCH('面板-总览'!D$2,'面板-景气指数'!$36:$36,0)) -> 0.7745 | E4: =INDEX('面板-景气指数'!$37:$242,MATCH('面板-总览'!$A4,'面板-景气指数'!$A$37:$A$242,0),MATCH('面板-总览'!E$2,'面板-景气指数'!$36:$36,0)) -> 0.67583333 | F4: =INDEX('面板-景气指数'!$37:$242,MATCH('面板-总览'!$A4,'面板-景气指数'!$A$37:$A$242,0),MATCH('面板-总览'!F$2,'面板-景气指数'!$36:$36,0)) -> 0.63483333 | G4: =INDEX('面板-景气指数'!$37:$242,MATCH('面板-总览'!$A4,'面板-景气指数'!$A$37:$A$242,0),MATCH('面板-总览'!G$2,'面板-景气指数'!$36:$36,0)) -> 0.624 | H4: =INDEX('面板-景气指数'!$37:$242,MATCH('面板-总览'!$A4,'面板-景气指数'!$A$37:$A$242,0),MATCH('面板-总览'!H$2,'面板-景气指数'!$36:$36,0)) -> 0.636 | I4: =INDEX('面板-景气指数'!$37:$242,MATCH('面板-总览'!$A4,'面板-景气指数'!$A$37:$A$242,0),MATCH('面板-总览'!I$2,'面板-景气指数'!$36:$36,0)) -> 0.6625 | ... N4: =INDEX('面板-景气指数'!$37:$242,MATCH('面板-总览'!$A4,'面板-景气指数'!$A$37:$A$242,0),MATCH('面板-总览'!N$2,'面板-景气指数'!$36:$36,0)) -> 0.64833333 | P4: =N4-K4 -> -0.069666667 | R4: 炼化及贸易 | S4: =INDEX('面板-景气指数'!$37:$242,MATCH('面板-总览'!$R4,'面板-景气指数'!$A$37:$A$242,0),MATCH('面板-总览'!S$2,'面板-景气指数'!$36:$36,0)) -> 0.979 | T4: =INDEX('面板-景气指数'!$37:$242,MATCH('面板-总览'!$R4,'面板-景气指数'!$A$37:$A$242,0),MATCH('面板-总览'!T$2,'面板-景气指数'!$36:$36,0)) -> 1 | U4: =INDEX('面板-景气指数'!$37:$242,MATCH('面板-总览'!$R4,'面板-景气指数'!$A$37:$A$242,0),MATCH('面板-总览'!U$2,'面板-景气指数'!$36:$36,0)) -> 0.989 | V4: =INDEX('面板-景气指数'!$37:$242,MATCH('面板-总览'!$R4,'面板-景气指数'!$A$37:$A$242,0),MATCH('面板-总览'!V$2,'面板-景气指数'!$36:$36,0)) -> 0.5 | W4: =INDEX('面板-景气指数'!$37:$242,MATCH('面板-总览'!$R4,'面板-景气指数'!$A$37:$A$242,0),MATCH('面板-总览'!W$2,'面板-景气指数'!$36:$36,0)) -> 0.546 | X4: =INDEX('面板-景气指数'!$37:$242,MATCH('面板-总览'!$R4,'面板-景气指数'!$A$37:$A$242,0),MATCH('面板-总览'!X$2,'面板-景气指数'!$36:$36,0)) -> 0.742 | Y4: =INDEX('面板-景气指数'!$37:$242,MATCH('面板-总览'!$R4,'面板-景气指数'!$A$37:$A$242,0),MATCH('面板-总览'!Y$2,'面板-景气指数'!$36:$36,0)) -> 0.886 | Z4: =INDEX('面板-景气指数'!$37:$242,MATCH('面板-总览'!$R4,'面板-景气指数'!$A$37:$A$242,0),MATCH('面板-总览'!Z$2,'面板-景气指数'!$36:$36,0)) -> 0.752 | ... AE4: =INDEX('面板-景气指数'!$37:$242,MATCH('面板-总览'!$R4,'面板-景气指数'!$A$37:$A$242,0),MATCH('面板-总览'!AE$2,'面板-景气指数'!$36:$36,0)) -> 0.505 | AG4: =AE4-AB4 -> 0.454 | AI4: 铝 | AJ4: =INDEX('面板-景气指数'!$37:$242,MATCH('面板-总览'!$AI4,'面板-景气指数'!$A$37:$A$242,0),MATCH('面板-总览'!AJ$2,'面板-景气指数'!$36:$36,0)) -> 0.02 | AK4: =INDEX('面板-景气指数'!$37:$242,MATCH('面板-总览'!$AI4,'面板-景气指数'!$A$37:$A$242,0),MATCH('面板-总览'!AK$2,'面板-景气指数'!$36:$36,0)) -> 0.051 | AL4: =INDEX('面板-景气指数'!$37:$242,MATCH('面板-总览'!$AI4,'面板-景气指数'!$A$37:$A$242,0),MATCH('面板-总览'!AL$2,'面板-景气指数'!$36:$36,0)) -> 0.122 | AM4: =INDEX('面板-景气指数'!$37:$242,MATCH('面板-总览'!$AI4,'面板-景气指数'!$A$37:$A$242,0),MATCH('面板-总览'!AM$2,'面板-景气指数'!$36:$36,0)) -> 0.234 | AN4: =INDEX('面板-景气指数'!$37:$242,MATCH('面板-总览'!$AI4,'面板-景气指数'!$A$37:$A$242,0),MATCH('面板-总览'!AN$2,'面板-景气指数'!$36:$36,0)) -> 0.346 | AO4: =INDEX('面板-景气指数'!$37:$242,MATCH('面板-总览'!$AI4,'面板-景气指数'!$A$37:$A$242,0),MATCH('面板-总览'!AO$2,'面板-景气指数'!$36:$36,0)) -> 0.448 | AP4: =INDEX('面板-景气指数'!$37:$242,MATCH('面板-总览'!$AI4,'面板-景气指数'!$A$37:$A$242,0),MATCH('面板-总览'!AP$2,'面板-景气指数'!$36:$36,0)) -> 0.52 | AQ4: =INDEX('面板-景气指数'!$37:$242,MATCH('面板-总览'!$AI4,'面板-景气指数'!$A$37:$A$242,0),MATCH('面板-总览'!AQ$2,'面板-景气指数'!$36:$36,0)) -> 0.53 | ... AV4: =INDEX('面板-景气指数'!$37:$242,MATCH('面板-总览'!$AI4,'面板-景气指数'!$A$37:$A$242,0),MATCH('面板-总览'!AV$2,'面板-景气指数'!$36:$36,0)) -> 0.469 | AX4: =AV4-AS4 -> 0.041
A5: 有色金属 | B5: =INDEX('面板-景气指数'!$37:$242,MATCH('面板-总览'!$A5,'面板-景气指数'!$A$37:$A$242,0),MATCH('面板-总览'!B$2,'面板-景气指数'!$36:$36,0)) -> 0.30173882 | C5: =INDEX('面板-景气指数'!$37:$242,MATCH('面板-总览'!$A5,'面板-景气指数'!$A$37:$A$242,0),MATCH('面板-总览'!C$2,'面板-景气指数'!$36:$36,0)) -> 0.27038534 | D5: =INDEX('面板-景气指数'!$37:$242,MATCH('面板-总览'!$A5,'面板-景气指数'!$A$37:$A$242,0),MATCH('面板-总览'!D$2,'面板-景气指数'!$36:$36,0)) -> 0.31641399 | E5: =INDEX('面板-景气指数'!$37:$242,MATCH('面板-总览'!$A5,'面板-景气指数'!$A$37:$A$242,0),MATCH('面板-总览'!E$2,'面板-景气指数'!$36:$36,0)) -> 0.43724984 | F5: =INDEX('面板-景气指数'!$37:$242,MATCH('面板-总览'!$A5,'面板-景气指数'!$A$37:$A$242,0),MATCH('面板-总览'!F$2,'面板-景气指数'!$36:$36,0)) -> 0.50920196 | G5: =INDEX('面板-景气指数'!$37:$242,MATCH('面板-总览'!$A5,'面板-景气指数'!$A$37:$A$242,0),MATCH('面板-总览'!G$2,'面板-景气指数'!$36:$36,0)) -> 0.59629111 | H5: =INDEX('面板-景气指数'!$37:$242,MATCH('面板-总览'!$A5,'面板-景气指数'!$A$37:$A$242,0),MATCH('面板-总览'!H$2,'面板-景气指数'!$36:$36,0)) -> 0.56774032 | I5: =INDEX('面板-景气指数'!$37:$242,MATCH('面板-总览'!$A5,'面板-景气指数'!$A$37:$A$242,0),MATCH('面板-总览'!I$2,'面板-景气指数'!$36:$36,0)) -> 0.56871034 | ... N5: =INDEX('面板-景气指数'!$37:$242,MATCH('面板-总览'!$A5,'面板-景气指数'!$A$37:$A$242,0),MATCH('面板-总览'!N$2,'面板-景气指数'!$36:$36,0)) -> 0.48655131 | P5: =N5-K5 -> 0.0096790578 | R5: 动力煤 | S5: =INDEX('面板-景气指数'!$37:$242,MATCH('面板-总览'!$R5,'面板-景气指数'!$A$37:$A$242,0),MATCH('面板-总览'!S$2,'面板-景气指数'!$36:$36,0)) -> 0.867 | T5: =INDEX('面板-景气指数'!$37:$242,MATCH('面板-总览'!$R5,'面板-景气指数'!$A$37:$A$242,0),MATCH('面板-总览'!T$2,'面板-景气指数'!$36:$36,0)) -> 0.846 | U5: =INDEX('面板-景气指数'!$37:$242,MATCH('面板-总览'!$R5,'面板-景气指数'!$A$37:$A$242,0),MATCH('面板-总览'!U$2,'面板-景气指数'!$36:$36,0)) -> 0.785 | V5: =INDEX('面板-景气指数'!$37:$242,MATCH('面板-总览'!$R5,'面板-景气指数'!$A$37:$A$242,0),MATCH('面板-总览'!V$2,'面板-景气指数'!$36:$36,0)) -> 0.642 | W5: =INDEX('面板-景气指数'!$37:$242,MATCH('面板-总览'!$R5,'面板-景气指数'!$A$37:$A$242,0),MATCH('面板-总览'!W$2,'面板-景气指数'!$36:$36,0)) -> 0.602 | X5: =INDEX('面板-景气指数'!$37:$242,MATCH('面板-总览'!$R5,'面板-景气指数'!$A$37:$A$242,0),MATCH('面板-总览'!X$2,'面板-景气指数'!$36:$36,0)) -> 0.612 | Y5: =INDEX('面板-景气指数'!$37:$242,MATCH('面板-总览'!$R5,'面板-景气指数'!$A$37:$A$242,0),MATCH('面板-总览'!Y$2,'面板-景气指数'!$36:$36,0)) -> 0.653 | Z5: =INDEX('面板-景气指数'!$37:$242,MATCH('面板-总览'!$R5,'面板-景气指数'!$A$37:$A$242,0),MATCH('面板-总览'!Z$2,'面板-景气指数'!$36:$36,0)) -> 0.683 | ... AE5: =INDEX('面板-景气指数'!$37:$242,MATCH('面板-总览'!$R5,'面板-景气指数'!$A$37:$A$242,0),MATCH('面板-总览'!AE$2,'面板-景气指数'!$36:$36,0)) -> 0.663 | AG5: =AE5-AB5 -> -0.041 | AI5: 铅锌 | AJ5: =INDEX('面板-景气指数'!$37:$242,MATCH('面板-总览'!$AI5,'面板-景气指数'!$A$37:$A$242,0),MATCH('面板-总览'!AJ$2,'面板-景气指数'!$36:$36,0)) -> 0.3005 | AK5: =INDEX('面板-景气指数'!$37:$242,MATCH('面板-总览'!$AI5,'面板-景气指数'!$A$37:$A$242,0),MATCH('面板-总览'!AK$2,'面板-景气指数'!$36:$36,0)) -> 0.219 | AL5: =INDEX('面板-景气指数'!$37:$242,MATCH('面板-总览'!$AI5,'面板-景气指数'!$A$37:$A$242,0),MATCH('面板-总览'!AL$2,'面板-景气指数'!$36:$36,0)) -> 0.224 | AM5: =INDEX('面板-景气指数'!$37:$242,MATCH('面板-总览'!$AI5,'面板-景气指数'!$A$37:$A$242,0),MATCH('面板-总览'!AM$2,'面板-景气指数'!$36:$36,0)) -> 0.311 | AN5: =INDEX('面板-景气指数'!$37:$242,MATCH('面板-总览'!$AI5,'面板-景气指数'!$A$37:$A$242,0),MATCH('面板-总览'!AN$2,'面板-景气指数'!$36:$36,0)) -> 0.3565 | AO5: =INDEX('面板-景气指数'!$37:$242,MATCH('面板-总览'!$AI5,'面板-景气指数'!$A$37:$A$242,0),MATCH('面板-总览'!AO$2,'面板-景气指数'!$36:$36,0)) -> 0.484 | AP5: =INDEX('面板-景气指数'!$37:$242,MATCH('面板-总览'!$AI5,'面板-景气指数'!$A$37:$A$242,0),MATCH('面板-总览'!AP$2,'面板-景气指数'!$36:$36,0)) -> 0.484 | AQ5: =INDEX('面板-景气指数'!$37:$242,MATCH('面板-总览'!$AI5,'面板-景气指数'!$A$37:$A$242,0),MATCH('面板-总览'!AQ$2,'面板-景气指数'!$36:$36,0)) -> 0.5355 | ... AV5: =INDEX('面板-景气指数'!$37:$242,MATCH('面板-总览'!$AI5,'面板-景气指数'!$A$37:$A$242,0),MATCH('面板-总览'!AV$2,'面板-景气指数'!$36:$36,0)) -> 0.5605 | AX5: =AV5-AS5 -> 0.0915
A6: 基础化工 | B6: =INDEX('面板-景气指数'!$37:$242,MATCH('面板-总览'!$A6,'面板-景气指数'!$A$37:$A$242,0),MATCH('面板-总览'!B$2,'面板-景气指数'!$36:$36,0)) -> 0.28766882 | C6: =INDEX('面板-景气指数'!$37:$242,MATCH('面板-总览'!$A6,'面板-景气指数'!$A$37:$A$242,0),MATCH('面板-总览'!C$2,'面板-景气指数'!$36:$36,0)) -> 0.20050759 | D6: =INDEX('面板-景气指数'!$37:$242,MATCH('面板-总览'!$A6,'面板-景气指数'!$A$37:$A$242,0),MATCH('面板-总览'!D$2,'面板-景气指数'!$36:$36,0)) -> 0.19729741 | E6: =INDEX('面板-景气指数'!$37:$242,MATCH('面板-总览'!$A6,'面板-景气指数'!$A$37:$A$242,0),MATCH('面板-总览'!E$2,'面板-景气指数'!$36:$36,0)) -> 0.23645825 | F6: =INDEX('面板-景气指数'!$37:$242,MATCH('面板-总览'!$A6,'面板-景气指数'!$A$37:$A$242,0),MATCH('面板-总览'!F$2,'面板-景气指数'!$36:$36,0)) -> 0.30313351 | G6: =INDEX('面板-景气指数'!$37:$242,MATCH('面板-总览'!$A6,'面板-景气指数'!$A$37:$A$242,0),MATCH('面板-总览'!G$2,'面板-景气指数'!$36:$36,0)) -> 0.36400093 | H6: =INDEX('面板-景气指数'!$37:$242,MATCH('面板-总览'!$A6,'面板-景气指数'!$A$37:$A$242,0),MATCH('面板-总览'!H$2,'面板-景气指数'!$36:$36,0)) -> 0.37019438 | I6: =INDEX('面板-景气指数'!$37:$242,MATCH('面板-总览'!$A6,'面板-景气指数'!$A$37:$A$242,0),MATCH('面板-总览'!I$2,'面板-景气指数'!$36:$36,0)) -> 0.36500388 | ... N6: =INDEX('面板-景气指数'!$37:$242,MATCH('面板-总览'!$A6,'面板-景气指数'!$A$37:$A$242,0),MATCH('面板-总览'!N$2,'面板-景气指数'!$36:$36,0)) -> 0.29217727 | P6: =N6-K6 -> -0.046615933 | R6: 焦煤 | S6: =INDEX('面板-景气指数'!$37:$242,MATCH('面板-总览'!$R6,'面板-景气指数'!$A$37:$A$242,0),MATCH('面板-总览'!S$2,'面板-景气指数'!$36:$36,0)) -> 0.795 | T6: =INDEX('面板-景气指数'!$37:$242,MATCH('面板-总览'!$R6,'面板-景气指数'!$A$37:$A$242,0),MATCH('面板-总览'!T$2,'面板-景气指数'!$36:$36,0)) -> 0.755 | U6: =INDEX('面板-景气指数'!$37:$242,MATCH('面板-总览'!$R6,'面板-景气指数'!$A$37:$A$242,0),MATCH('面板-总览'!U$2,'面板-景气指数'!$36:$36,0)) -> 0.704 | V6: =INDEX('面板-景气指数'!$37:$242,MATCH('面板-总览'!$R6,'面板-景气指数'!$A$37:$A$242,0),MATCH('面板-总览'!V$2,'面板-景气指数'!$36:$36,0)) -> 0.653 | W6: =INDEX('面板-景气指数'!$37:$242,MATCH('面板-总览'!$R6,'面板-景气指数'!$A$37:$A$242,0),MATCH('面板-总览'!W$2,'面板-景气指数'!$36:$36,0)) -> 0.622 | X6: =INDEX('面板-景气指数'!$37:$242,MATCH('面板-总览'!$R6,'面板-景气指数'!$A$37:$A$242,0),MATCH('面板-总览'!X$2,'面板-景气指数'!$36:$36,0)) -> 0.591 | Y6: =INDEX('面板-景气指数'!$37:$242,MATCH('面板-总览'!$R6,'面板-景气指数'!$A$37:$A$242,0),MATCH('面板-总览'!Y$2,'面板-景气指数'!$36:$36,0)) -> 0.683 | Z6: =INDEX('面板-景气指数'!$37:$242,MATCH('面板-总览'!$R6,'面板-景气指数'!$A$37:$A$242,0),MATCH('面板-总览'!Z$2,'面板-景气指数'!$36:$36,0)) -> 0.714 | ... AE6: =INDEX('面板-景气指数'!$37:$242,MATCH('面板-总览'!$R6,'面板-景气指数'!$A$37:$A$242,0),MATCH('面板-总览'!AE$2,'面板-景气指数'!$36:$36,0)) -> 0.734 | AG6: =AE6-AB6 -> -0.041 | AI6: 黄金 | AJ6: =INDEX('面板-景气指数'!$37:$242,MATCH('面板-总览'!$AI6,'面板-景气指数'!$A$37:$A$242,0),MATCH('面板-总览'!AJ$2,'面板-景气指数'!$36:$36,0)) -> 0.336 | AK6: =INDEX('面板-景气指数'!$37:$242,MATCH('面板-总览'!$AI6,'面板-景气指数'!$A$37:$A$242,0),MATCH('面板-总览'!AK$2,'面板-景气指数'!$36:$36,0)) -> 0.438 | AL6: =INDEX('面板-景气指数'!$37:$242,MATCH('面板-总览'!$AI6,'面板-景气指数'!$A$37:$A$242,0),MATCH('面板-总览'!AL$2,'面板-景气指数'!$36:$36,0)) -> 0.53 | AM6: =INDEX('面板-景气指数'!$37:$242,MATCH('面板-总览'!$AI6,'面板-景气指数'!$A$37:$A$242,0),MATCH('面板-总览'!AM$2,'面板-景气指数'!$36:$36,0)) -> 0.622 | AN6: =INDEX('面板-景气指数'!$37:$242,MATCH('面板-总览'!$AI6,'面板-景气指数'!$A$37:$A$242,0),MATCH('面板-总览'!AN$2,'面板-景气指数'!$36:$36,0)) -> 0.632 | AO6: =INDEX('面板-景气指数'!$37:$242,MATCH('面板-总览'!$AI6,'面板-景气指数'!$A$37:$A$242,0),MATCH('面板-总览'!AO$2,'面板-景气指数'!$36:$36,0)) -> 0.724 | AP6: =INDEX('面板-景气指数'!$37:$242,MATCH('面板-总览'!$AI6,'面板-景气指数'!$A$37:$A$242,0),MATCH('面板-总览'!AP$2,'面板-景气指数'!$36:$36,0)) -> 0.734 | AQ6: =INDEX('面板-景气指数'!$37:$242,MATCH('面板-总览'!$AI6,'面板-景气指数'!$A$37:$A$242,0),MATCH('面板-总览'!AQ$2,'面板-景气指数'!$36:$36,0)) -> 0.775 | ... AV6: =INDEX('面板-景气指数'!$37:$242,MATCH('面板-总览'!$AI6,'面板-景气指数'!$A$37:$A$242,0),MATCH('面板-总览'!AV$2,'面板-景气指数'!$36:$36,0)) -> 0.704 | AX6: =AV6-AS6 -> -0.01
A7: 钢铁 | B7: =INDEX('面板-景气指数'!$37:$242,MATCH('面板-总览'!$A7,'面板-景气指数'!$A$37:$A$242,0),MATCH('面板-总览'!B$2,'面板-景气指数'!$36:$36,0)) -> 0.21410132 | C7: =INDEX('面板-景气指数'!$37:$242,MATCH('面板-总览'!$A7,'面板-景气指数'!$A$37:$A$242,0),MATCH('面板-总览'!C$2,'面板-景气指数'!$36:$36,0)) -> 0.15995321 | D7: =INDEX('面板-景气指数'!$37:$242,MATCH('面板-总览'!$A7,'面板-景气指数'!$A$37:$A$242,0),MATCH('面板-总览'!D$2,'面板-景气指数'!$36:$36,0)) -> 0.16319651 | E7: =INDEX('面板-景气指数'!$37:$242,MATCH('面板-总览'!$A7,'面板-景气指数'!$A$37:$A$242,0),MATCH('面板-总览'!E$2,'面板-景气指数'!$36:$36,0)) -> 0.22800262 | F7: =INDEX('面板-景气指数'!$37:$242,MATCH('面板-总览'!$A7,'面板-景气指数'!$A$37:$A$242,0),MATCH('面板-总览'!F$2,'面板-景气指数'!$36:$36,0)) -> 0.30860179 | G7: =INDEX('面板-景气指数'!$37:$242,MATCH('面板-总览'!$A7,'面板-景气指数'!$A$37:$A$242,0),MATCH('面板-总览'!G$2,'面板-景气指数'!$36:$36,0)) -> 0.35986888 | H7: =INDEX('面板-景气指数'!$37:$242,MATCH('面板-总览'!$A7,'面板-景气指数'!$A$37:$A$242,0),MATCH('面板-总览'!H$2,'面板-景气指数'!$36:$36,0)) -> 0.35121995 | I7: =INDEX('面板-景气指数'!$37:$242,MATCH('面板-总览'!$A7,'面板-景气指数'!$A$37:$A$242,0),MATCH('面板-总览'!I$2,'面板-景气指数'!$36:$36,0)) -> 0.35451646 | ... N7: =INDEX('面板-景气指数'!$37:$242,MATCH('面板-总览'!$A7,'面板-景气指数'!$A$37:$A$242,0),MATCH('面板-总览'!N$2,'面板-景气指数'!$36:$36,0)) -> 0.23806672 | P7: =N7-K7 -> -0.11230179 | R7: 无烟煤 | S7: =INDEX('面板-景气指数'!$37:$242,MATCH('面板-总览'!$R7,'面板-景气指数'!$A$37:$A$242,0),MATCH('面板-总览'!S$2,'面板-景气指数'!$36:$36,0)) -> 0.877 | T7: =INDEX('面板-景气指数'!$37:$242,MATCH('面板-总览'!$R7,'面板-景气指数'!$A$37:$A$242,0),MATCH('面板-总览'!T$2,'面板-景气指数'!$36:$36,0)) -> 0.806 | U7: =INDEX('面板-景气指数'!$37:$242,MATCH('面板-总览'!$R7,'面板-景气指数'!$A$37:$A$242,0),MATCH('面板-总览'!U$2,'面板-景气指数'!$36:$36,0)) -> 0.775 | V7: =INDEX('面板-景气指数'!$37:$242,MATCH('面板-总览'!$R7,'面板-景气指数'!$A$37:$A$242,0),MATCH('面板-总览'!V$2,'面板-景气指数'!$36:$36,0)) -> 0.714 | W7: =INDEX('面板-景气指数'!$37:$242,MATCH('面板-总览'!$R7,'面板-景气指数'!$A$37:$A$242,0),MATCH('面板-总览'!W$2,'面板-景气指数'!$36:$36,0)) -> 0.704 | X7: =INDEX('面板-景气指数'!$37:$242,MATCH('面板-总览'!$R7,'面板-景气指数'!$A$37:$A$242,0),MATCH('面板-总览'!X$2,'面板-景气指数'!$36:$36,0)) -> 0.724 | Y7: =INDEX('面板-景气指数'!$37:$242,MATCH('面板-总览'!$R7,'面板-景气指数'!$A$37:$A$242,0),MATCH('面板-总览'!Y$2,'面板-景气指数'!$36:$36,0)) -> 0.734 | Z7: =INDEX('面板-景气指数'!$37:$242,MATCH('面板-总览'!$R7,'面板-景气指数'!$A$37:$A$242,0),MATCH('面板-总览'!Z$2,'面板-景气指数'!$36:$36,0)) -> 0.755 | ... AE7: =INDEX('面板-景气指数'!$37:$242,MATCH('面板-总览'!$R7,'面板-景气指数'!$A$37:$A$242,0),MATCH('面板-总览'!AE$2,'面板-景气指数'!$36:$36,0)) -> 0.642 | AG7: =AE7-AB7 -> -0.051 | AI7: 白银 | AJ7: =INDEX('面板-景气指数'!$37:$242,MATCH('面板-总览'!$AI7,'面板-景气指数'!$A$37:$A$242,0),MATCH('面板-总览'!AJ$2,'面板-景气指数'!$36:$36,0)) -> 0.316 | AK7: =INDEX('面板-景气指数'!$37:$242,MATCH('面板-总览'!$AI7,'面板-景气指数'!$A$37:$A$242,0),MATCH('面板-总览'!AK$2,'面板-景气指数'!$36:$36,0)) -> 0.5 | AL7: =INDEX('面板-景气指数'!$37:$242,MATCH('面板-总览'!$AI7,'面板-景气指数'!$A$37:$A$242,0),MATCH('面板-总览'!AL$2,'面板-景气指数'!$36:$36,0)) -> 0.612 | AM7: =INDEX('面板-景气指数'!$37:$242,MATCH('面板-总览'!$AI7,'面板-景气指数'!$A$37:$A$242,0),MATCH('面板-总览'!AM$2,'面板-景气指数'!$36:$36,0)) -> 0.714 | AN7: =INDEX('面板-景气指数'!$37:$242,MATCH('面板-总览'!$AI7,'面板-景气指数'!$A$37:$A$242,0),MATCH('面板-总览'!AN$2,'面板-景气指数'!$36:$36,0)) -> 0.765 | AO7: =INDEX('面板-景气指数'!$37:$242,MATCH('面板-总览'!$AI7,'面板-景气指数'!$A$37:$A$242,0),MATCH('面板-总览'!AO$2,'面板-景气指数'!$36:$36,0)) -> 0.846 | AP7: =INDEX('面板-景气指数'!$37:$242,MATCH('面板-总览'!$AI7,'面板-景气指数'!$A$37:$A$242,0),MATCH('面板-总览'!AP$2,'面板-景气指数'!$36:$36,0)) -> 0.785 | AQ7: =INDEX('面板-景气指数'!$37:$242,MATCH('面板-总览'!$AI7,'面板-景气指数'!$A$37:$A$242,0),MATCH('面板-总览'!AQ$2,'面板-景气指数'!$36:$36,0)) -> 0.724 | ... AV7: =INDEX('面板-景气指数'!$37:$242,MATCH('面板-总览'!$AI7,'面板-景气指数'!$A$37:$A$242,0),MATCH('面板-总览'!AV$2,'面板-景气指数'!$36:$36,0)) -> 0.591 | AX7: =AV7-AS7 -> 0.04
A8: 建筑材料 | B8: =INDEX('面板-景气指数'!$37:$242,MATCH('面板-总览'!$A8,'面板-景气指数'!$A$37:$A$242,0),MATCH('面板-总览'!B$2,'面板-景气指数'!$36:$36,0)) -> 0.26046305 | C8: =INDEX('面板-景气指数'!$37:$242,MATCH('面板-总览'!$A8,'面板-景气指数'!$A$37:$A$242,0),MATCH('面板-总览'!C$2,'面板-景气指数'!$36:$36,0)) -> 0.273204 | D8: =INDEX('面板-景气指数'!$37:$242,MATCH('面板-总览'!$A8,'面板-景气指数'!$A$37:$A$242,0),MATCH('面板-总览'!D$2,'面板-景气指数'!$36:$36,0)) -> 0.2485819 | E8: =INDEX('面板-景气指数'!$37:$242,MATCH('面板-总览'!$A8,'面板-景气指数'!$A$37:$A$242,0),MATCH('面板-总览'!E$2,'面板-景气指数'!$36:$36,0)) -> 0.25206015 | F8: =INDEX('面板-景气指数'!$37:$242,MATCH('面板-总览'!$A8,'面板-景气指数'!$A$37:$A$242,0),MATCH('面板-总览'!F$2,'面板-景气指数'!$36:$36,0)) -> 0.2537603 | G8: =INDEX('面板-景气指数'!$37:$242,MATCH('面板-总览'!$A8,'面板-景气指数'!$A$37:$A$242,0),MATCH('面板-总览'!G$2,'面板-景气指数'!$36:$36,0)) -> 0.25760361 | H8: =INDEX('面板-景气指数'!$37:$242,MATCH('面板-总览'!$A8,'面板-景气指数'!$A$37:$A$242,0),MATCH('面板-总览'!H$2,'面板-景气指数'!$36:$36,0)) -> 0.25369446 | I8: =INDEX('面板-景气指数'!$37:$242,MATCH('面板-总览'!$A8,'面板-景气指数'!$A$37:$A$242,0),MATCH('面板-总览'!I$2,'面板-景气指数'!$36:$36,0)) -> 0.26119798 | ... N8: =INDEX('面板-景气指数'!$37:$242,MATCH('面板-总览'!$A8,'面板-景气指数'!$A$37:$A$242,0),MATCH('面板-总览'!N$2,'面板-景气指数'!$36:$36,0)) -> 0.26686985 | P8: =N8-K8 -> -0.063187514 | R8: 工业金属 | S8: =INDEX('面板-景气指数'!$37:$242,MATCH('面板-总览'!$R8,'面板-景气指数'!$A$37:$A$242,0),MATCH('面板-总览'!S$2,'面板-景气指数'!$36:$36,0)) -> 0.25756408 | T8: =INDEX('面板-景气指数'!$37:$242,MATCH('面板-总览'!$R8,'面板-景气指数'!$A$37:$A$242,0),MATCH('面板-总览'!T$2,'面板-景气指数'!$36:$36,0)) -> 0.18713326 | U8: =INDEX('面板-景气指数'!$37:$242,MATCH('面板-总览'!$R8,'面板-景气指数'!$A$37:$A$242,0),MATCH('面板-总览'!U$2,'面板-景气指数'!$36:$36,0)) -> 0.22554747 | V8: =INDEX('面板-景气指数'!$37:$242,MATCH('面板-总览'!$R8,'面板-景气指数'!$A$37:$A$242,0),MATCH('面板-总览'!V$2,'面板-景气指数'!$36:$36,0)) -> 0.36627701 | W8: =INDEX('面板-景气指数'!$37:$242,MATCH('面板-总览'!$R8,'面板-景气指数'!$A$37:$A$242,0),MATCH('面板-总览'!W$2,'面板-景气指数'!$36:$36,0)) -> 0.43771431 | X8: =INDEX('面板-景气指数'!$37:$242,MATCH('面板-总览'!$R8,'面板-景气指数'!$A$37:$A$242,0),MATCH('面板-总览'!X$2,'面板-景气指数'!$36:$36,0)) -> 0.55244644 | Y8: =INDEX('面板-景气指数'!$37:$242,MATCH('面板-总览'!$R8,'面板-景气指数'!$A$37:$A$242,0),MATCH('面板-总览'!Y$2,'面板-景气指数'!$36:$36,0)) -> 0.52079141 | Z8: =INDEX('面板-景气指数'!$37:$242,MATCH('面板-总览'!$R8,'面板-景气指数'!$A$37:$A$242,0),MATCH('面板-总览'!Z$2,'面板-景气指数'!$36:$36,0)) -> 0.5404734 | ... AE8: =INDEX('面板-景气指数'!$37:$242,MATCH('面板-总览'!$R8,'面板-景气指数'!$A$37:$A$242,0),MATCH('面板-总览'!AE$2,'面板-景气指数'!$36:$36,0)) -> 0.51100625 | AG8: =AE8-AB8 -> 0.036041529 | AI8: 稀土 | AJ8: =INDEX('面板-景气指数'!$37:$242,MATCH('面板-总览'!$AI8,'面板-景气指数'!$A$37:$A$242,0),MATCH('面板-总览'!AJ$2,'面板-景气指数'!$36:$36,0)) -> 0.816 | AK8: =INDEX('面板-景气指数'!$37:$242,MATCH('面板-总览'!$AI8,'面板-景气指数'!$A$37:$A$242,0),MATCH('面板-总览'!AK$2,'面板-景气指数'!$36:$36,0)) -> 0.704 | AL8: =INDEX('面板-景气指数'!$37:$242,MATCH('面板-总览'!$AI8,'面板-景气指数'!$A$37:$A$242,0),MATCH('面板-总览'!AL$2,'面板-景气指数'!$36:$36,0)) -> 0.683 | AM8: =INDEX('面板-景气指数'!$37:$242,MATCH('面板-总览'!$AI8,'面板-景气指数'!$A$37:$A$242,0),MATCH('面板-总览'!AM$2,'面板-景气指数'!$36:$36,0)) -> 0.663 | AN8: =INDEX('面板-景气指数'!$37:$242,MATCH('面板-总览'!$AI8,'面板-景气指数'!$A$37:$A$242,0),MATCH('面板-总览'!AN$2,'面板-景气指数'!$36:$36,0)) -> 0.673 | AO8: =INDEX('面板-景气指数'!$37:$242,MATCH('面板-总览'!$AI8,'面板-景气指数'!$A$37:$A$242,0),MATCH('面板-总览'!AO$2,'面板-景气指数'!$36:$36,0)) -> 0.693 | AP8: =INDEX('面板-景气指数'!$37:$242,MATCH('面板-总览'!$AI8,'面板-景气指数'!$A$37:$A$242,0),MATCH('面板-总览'!AP$2,'面板-景气指数'!$36:$36,0)) -> 0.734 | AQ8: =INDEX('面板-景气指数'!$37:$242,MATCH('面板-总览'!$AI8,'面板-景气指数'!$A$37:$A$242,0),MATCH('面板-总览'!AQ$2,'面板-景气指数'!$36:$36,0)) -> 0.755 | ... AV8: =INDEX('面板-景气指数'!$37:$242,MATCH('面板-总览'!$AI8,'面板-景气指数'!$A$37:$A$242,0),MATCH('面板-总览'!AV$2,'面板-景气指数'!$36:$36,0)) -> 0.561 | AX8: =AV8-AS8 -> -0.092
A9: 机械设备 | B9: =INDEX('面板-景气指数'!$37:$242,MATCH('面板-总览'!$A9,'面板-景气指数'!$A$37:$A$242,0),MATCH('面板-总览'!B$2,'面板-景气指数'!$36:$36,0)) -> 0.36539702 | C9: =INDEX('面板-景气指数'!$37:$242,MATCH('面板-总览'!$A9,'面板-景气指数'!$A$37:$A$242,0),MATCH('面板-总览'!C$2,'面板-景气指数'!$36:$36,0)) -> 0.30310761 | D9: =INDEX('面板-景气指数'!$37:$242,MATCH('面板-总览'!$A9,'面板-景气指数'!$A$37:$A$242,0),MATCH('面板-总览'!D$2,'面板-景气指数'!$36:$36,0)) -> 0.26956095 | E9: =INDEX('面板-景气指数'!$37:$242,MATCH('面板-总览'!$A9,'面板-景气指数'!$A$37:$A$242,0),MATCH('面板-总览'!E$2,'面板-景气指数'!$36:$36,0)) -> 0.21891265 | F9: =INDEX('面板-景气指数'!$37:$242,MATCH('面板-总览'!$A9,'面板-景气指数'!$A$37:$A$242,0),MATCH('面板-总览'!F$2,'面板-景气指数'!$36:$36,0)) -> 0.26957784 | G9: =INDEX('面板-景气指数'!$37:$242,MATCH('面板-总览'!$A9,'面板-景气指数'!$A$37:$A$242,0),MATCH('面板-总览'!G$2,'面板-景气指数'!$36:$36,0)) -> 0.29601372 | H9: =INDEX('面板-景气指数'!$37:$242,MATCH('面板-总览'!$A9,'面板-景气指数'!$A$37:$A$242,0),MATCH('面板-总览'!H$2,'面板-景气指数'!$36:$36,0)) -> 0.35192771 | I9: =INDEX('面板-景气指数'!$37:$242,MATCH('面板-总览'!$A9,'面板-景气指数'!$A$37:$A$242,0),MATCH('面板-总览'!I$2,'面板-景气指数'!$36:$36,0)) -> 0.42514267 | ... N9: =INDEX('面板-景气指数'!$37:$242,MATCH('面板-总览'!$A9,'面板-景气指数'!$A$37:$A$242,0),MATCH('面板-总览'!N$2,'面板-景气指数'!$36:$36,0)) -> 0.5185558 | P9: =N9-K9 -> -0.021487394 | R9: 贵金属 | S9: =INDEX('面板-景气指数'!$37:$242,MATCH('面板-总览'!$R9,'面板-景气指数'!$A$37:$A$242,0),MATCH('面板-总览'!S$2,'面板-景气指数'!$36:$36,0)) -> 0.326 | T9: =INDEX('面板-景气指数'!$37:$242,MATCH('面板-总览'!$R9,'面板-景气指数'!$A$37:$A$242,0),MATCH('面板-总览'!T$2,'面板-景气指数'!$36:$36,0)) -> 0.469 | U9: =INDEX('面板-景气指数'!$37:$242,MATCH('面板-总览'!$R9,'面板-景气指数'!$A$37:$A$242,0),MATCH('面板-总览'!U$2,'面板-景气指数'!$36:$36,0)) -> 0.571 | V9: =INDEX('面板-景气指数'!$37:$242,MATCH('面板-总览'!$R9,'面板-景气指数'!$A$37:$A$242,0),MATCH('面板-总览'!V$2,'面板-景气指数'!$36:$36,0)) -> 0.668 | W9: =INDEX('面板-景气指数'!$37:$242,MATCH('面板-总览'!$R9,'面板-景气指数'!$A$37:$A$242,0),MATCH('面板-总览'!W$2,'面板-景气指数'!$36:$36,0)) -> 0.6985 | X9: =INDEX('面板-景气指数'!$37:$242,MATCH('面板-总览'!$R9,'面板-景气指数'!$A$37:$A$242,0),MATCH('面板-总览'!X$2,'面板-景气指数'!$36:$36,0)) -> 0.785 | Y9: =INDEX('面板-景气指数'!$37:$242,MATCH('面板-总览'!$R9,'面板-景气指数'!$A$37:$A$242,0),MATCH('面板-总览'!Y$2,'面板-景气指数'!$36:$36,0)) -> 0.7595 | Z9: =INDEX('面板-景气指数'!$37:$242,MATCH('面板-总览'!$R9,'面板-景气指数'!$A$37:$A$242,0),MATCH('面板-总览'!Z$2,'面板-景气指数'!$36:$36,0)) -> 0.7495 | ... AE9: =INDEX('面板-景气指数'!$37:$242,MATCH('面板-总览'!$R9,'面板-景气指数'!$A$37:$A$242,0),MATCH('面板-总览'!AE$2,'面板-景气指数'!$36:$36,0)) -> 0.6475 | AG9: =AE9-AB9 -> 0.015 | AI9: 钨 | AJ9: =INDEX('面板-景气指数'!$37:$242,MATCH('面板-总览'!$AI9,'面板-景气指数'!$A$37:$A$242,0),MATCH('面板-总览'!AJ$2,'面板-景气指数'!$36:$36,0)) -> 0.336 | AK9: =INDEX('面板-景气指数'!$37:$242,MATCH('面板-总览'!$AI9,'面板-景气指数'!$A$37:$A$242,0),MATCH('面板-总览'!AK$2,'面板-景气指数'!$36:$36,0)) -> 0.367 | AL9: =INDEX('面板-景气指数'!$37:$242,MATCH('面板-总览'!$AI9,'面板-景气指数'!$A$37:$A$242,0),MATCH('面板-总览'!AL$2,'面板-景气指数'!$36:$36,0)) -> 0.469 | AM9: =INDEX('面板-景气指数'!$37:$242,MATCH('面板-总览'!$AI9,'面板-景气指数'!$A$37:$A$242,0),MATCH('面板-总览'!AM$2,'面板-景气指数'!$36:$36,0)) -> 0.591 | AN9: =INDEX('面板-景气指数'!$37:$242,MATCH('面板-总览'!$AI9,'面板-景气指数'!$A$37:$A$242,0),MATCH('面板-总览'!AN$2,'面板-景气指数'!$36:$36,0)) -> 0.581 | AO9: =INDEX('面板-景气指数'!$37:$242,MATCH('面板-总览'!$AI9,'面板-景气指数'!$A$37:$A$242,0),MATCH('面板-总览'!AO$2,'面板-景气指数'!$36:$36,0)) -> 0.51 | AP9: =INDEX('面板-景气指数'!$37:$242,MATCH('面板-总览'!$AI9,'面板-景气指数'!$A$37:$A$242,0),MATCH('面板-总览'!AP$2,'面板-景气指数'!$36:$36,0)) -> 0.52 | AQ9: =INDEX('面板-景气指数'!$37:$242,MATCH('面板-总览'!$AI9,'面板-景气指数'!$A$37:$A$242,0),MATCH('面板-总览'!AQ$2,'面板-景气指数'!$36:$36,0)) -> 0.561 | ... AV9: =INDEX('面板-景气指数'!$37:$242,MATCH('面板-总览'!$AI9,'面板-景气指数'!$A$37:$A$242,0),MATCH('面板-总览'!AV$2,'面板-景气指数'!$36:$36,0)) -> 0.479 | AX9: =AV9-AS9 -> -0.092
A10: 电力设备 | B10: =INDEX('面板-景气指数'!$37:$242,MATCH('面板-总览'!$A10,'面板-景气指数'!$A$37:$A$242,0),MATCH('面板-总览'!B$2,'面板-景气指数'!$36:$36,0)) -> 0.47734998 | C10: =INDEX('面板-景气指数'!$37:$242,MATCH('面板-总览'!$A10,'面板-景气指数'!$A$37:$A$242,0),MATCH('面板-总览'!C$2,'面板-景气指数'!$36:$36,0)) -> 0.50168186 | D10: =INDEX('面板-景气指数'!$37:$242,MATCH('面板-总览'!$A10,'面板-景气指数'!$A$37:$A$242,0),MATCH('面板-总览'!D$2,'面板-景气指数'!$36:$36,0)) -> 0.50472554 | E10: =INDEX('面板-景气指数'!$37:$242,MATCH('面板-总览'!$A10,'面板-景气指数'!$A$37:$A$242,0),MATCH('面板-总览'!E$2,'面板-景气指数'!$36:$36,0)) -> 0.47644901 | F10: =INDEX('面板-景气指数'!$37:$242,MATCH('面板-总览'!$A10,'面板-景气指数'!$A$37:$A$242,0),MATCH('面板-总览'!F$2,'面板-景气指数'!$36:$36,0)) -> 0.44502906 | G10: =INDEX('面板-景气指数'!$37:$242,MATCH('面板-总览'!$A10,'面板-景气指数'!$A$37:$A$242,0),MATCH('面板-总览'!G$2,'面板-景气指数'!$36:$36,0)) -> 0.41705813 | H10: =INDEX('面板-景气指数'!$37:$242,MATCH('面板-总览'!$A10,'面板-景气指数'!$A$37:$A$242,0),MATCH('面板-总览'!H$2,'面板-景气指数'!$36:$36,0)) -> 0.40768674 | I10: =INDEX('面板-景气指数'!$37:$242,MATCH('面板-总览'!$A10,'面板-景气指数'!$A$37:$A$242,0),MATCH('面板-总览'!I$2,'面板-景气指数'!$36:$36,0)) -> 0.4227109 | ... N10: =INDEX('面板-景气指数'!$37:$242,MATCH('面板-总览'!$A10,'面板-景气指数'!$A$37:$A$242,0),MATCH('面板-总览'!N$2,'面板-景气指数'!$36:$36,0)) -> 0.45549044 | P10: =N10-K10 -> -0.017629702 | R10: 小金属 | S10: =INDEX('面板-景气指数'!$37:$242,MATCH('面板-总览'!$R10,'面板-景气指数'!$A$37:$A$242,0),MATCH('面板-总览'!S$2,'面板-景气指数'!$36:$36,0)) -> 0.5225 | T10: =INDEX('面板-景气指数'!$37:$242,MATCH('面板-总览'!$R10,'面板-景气指数'!$A$37:$A$242,0),MATCH('面板-总览'!T$2,'面板-景气指数'!$36:$36,0)) -> 0.43575 | U10: =INDEX('面板-景气指数'!$37:$242,MATCH('面板-总览'!$R10,'面板-景气指数'!$A$37:$A$242,0),MATCH('面板-总览'!U$2,'面板-景气指数'!$36:$36,0)) -> 0.4535 | V10: =INDEX('面板-景气指数'!$37:$242,MATCH('面板-总览'!$R10,'面板-景气指数'!$A$37:$A$242,0),MATCH('面板-总览'!V$2,'面板-景气指数'!$36:$36,0)) -> 0.55325 | W10: =INDEX('面板-景气指数'!$37:$242,MATCH('面板-总览'!$R10,'面板-景气指数'!$A$37:$A$242,0),MATCH('面板-总览'!W$2,'面板-景气指数'!$36:$36,0)) -> 0.6985 | X10: =INDEX('面板-景气指数'!$37:$242,MATCH('面板-总览'!$R10,'面板-景气指数'!$A$37:$A$242,0),MATCH('面板-总览'!X$2,'面板-景气指数'!$36:$36,0)) -> 0.71125 | Y10: =INDEX('面板-景气指数'!$37:$242,MATCH('面板-总览'!$R10,'面板-景气指数'!$A$37:$A$242,0),MATCH('面板-总览'!Y$2,'面板-景气指数'!$36:$36,0)) -> 0.678 | Z10: =INDEX('面板-景气指数'!$37:$242,MATCH('面板-总览'!$R10,'面板-景气指数'!$A$37:$A$242,0),MATCH('面板-总览'!Z$2,'面板-景气指数'!$36:$36,0)) -> 0.64275 | ... AE10: =INDEX('面板-景气指数'!$37:$242,MATCH('面板-总览'!$R10,'面板-景气指数'!$A$37:$A$242,0),MATCH('面板-总览'!AE$2,'面板-景气指数'!$36:$36,0)) -> 0.4025 | AG10: =AE10-AB10 -> -0.07675 | AI10: 钼 | AJ10: =INDEX('面板-景气指数'!$37:$242,MATCH('面板-总览'!$AI10,'面板-景气指数'!$A$37:$A$242,0),MATCH('面板-总览'!AJ$2,'面板-景气指数'!$36:$36,0)) -> 0.938 | AK10: =INDEX('面板-景气指数'!$37:$242,MATCH('面板-总览'!$AI10,'面板-景气指数'!$A$37:$A$242,0),MATCH('面板-总览'!AK$2,'面板-景气指数'!$36:$36,0)) -> 0.642 | AL10: =INDEX('面板-景气指数'!$37:$242,MATCH('面板-总览'!$AI10,'面板-景气指数'!$A$37:$A$242,0),MATCH('面板-总览'!AL$2,'面板-景气指数'!$36:$36,0)) -> 0.571 | AM10: =INDEX('面板-景气指数'!$37:$242,MATCH('面板-总览'!$AI10,'面板-景气指数'!$A$37:$A$242,0),MATCH('面板-总览'!AM$2,'面板-景气指数'!$36:$36,0)) -> 0.704 | AN10: =INDEX('面板-景气指数'!$37:$242,MATCH('面板-总览'!$AI10,'面板-景气指数'!$A$37:$A$242,0),MATCH('面板-总览'!AN$2,'面板-景气指数'!$36:$36,0)) -> 0.908 | AO10: =INDEX('面板-景气指数'!$37:$242,MATCH('面板-总览'!$AI10,'面板-景气指数'!$A$37:$A$242,0),MATCH('面板-总览'!AO$2,'面板-景气指数'!$36:$36,0)) -> 0.928 | AP10: =INDEX('面板-景气指数'!$37:$242,MATCH('面板-总览'!$AI10,'面板-景气指数'!$A$37:$A$242,0),MATCH('面板-总览'!AP$2,'面板-景气指数'!$36:$36,0)) -> 0.765 | AQ10: =INDEX('面板-景气指数'!$37:$242,MATCH('面板-总览'!$AI10,'面板-景气指数'!$A$37:$A$242,0),MATCH('面板-总览'!AQ$2,'面板-景气指数'!$36:$36,0)) -> 0.551 | ... AV10: =INDEX('面板-景气指数'!$37:$242,MATCH('面板-总览'!$AI10,'面板-景气指数'!$A$37:$A$242,0),MATCH('面板-总览'!AV$2,'面板-景气指数'!$36:$36,0)) -> 0.03 | AX10: =AV10-AS10 -> -0.082
A11: 国防军工 | B11: =INDEX('面板-景气指数'!$37:$242,MATCH('面板-总览'!$A11,'面板-景气指数'!$A$37:$A$242,0),MATCH('面板-总览'!B$2,'面板-景气指数'!$36:$36,0)) -> 0.35345019 | C11: =INDEX('面板-景气指数'!$37:$242,MATCH('面板-总览'!$A11,'面板-景气指数'!$A$37:$A$242,0),MATCH('面板-总览'!C$2,'面板-景气指数'!$36:$36,0)) -> 0.3205133 | D11: =INDEX('面板-景气指数'!$37:$242,MATCH('面板-总览'!$A11,'面板-景气指数'!$A$37:$A$242,0),MATCH('面板-总览'!D$2,'面板-景气指数'!$36:$36,0)) -> 0.31676427 | E11: =INDEX('面板-景气指数'!$37:$242,MATCH('面板-总览'!$A11,'面板-景气指数'!$A$37:$A$242,0),MATCH('面板-总览'!E$2,'面板-景气指数'!$36:$36,0)) -> 0.29040137 | F11: =INDEX('面板-景气指数'!$37:$242,MATCH('面板-总览'!$A11,'面板-景气指数'!$A$37:$A$242,0),MATCH('面板-总览'!F$2,'面板-景气指数'!$36:$36,0)) -> 0.28238223 | G11: =INDEX('面板-景气指数'!$37:$242,MATCH('面板-总览'!$A11,'面板-景气指数'!$A$37:$A$242,0),MATCH('面板-总览'!G$2,'面板-景气指数'!$36:$36,0)) -> 0.28142789 | H11: =INDEX('面板-景气指数'!$37:$242,MATCH('面板-总览'!$A11,'面板-景气指数'!$A$37:$A$242,0),MATCH('面板-总览'!H$2,'面板-景气指数'!$36:$36,0)) -> 0.28988789 | I11: =INDEX('面板-景气指数'!$37:$242,MATCH('面板-总览'!$A11,'面板-景气指数'!$A$37:$A$242,0),MATCH('面板-总览'!I$2,'面板-景气指数'!$36:$36,0)) -> 0.2890373 | ... N11: =INDEX('面板-景气指数'!$37:$242,MATCH('面板-总览'!$A11,'面板-景气指数'!$A$37:$A$242,0),MATCH('面板-总览'!N$2,'面板-景气指数'!$36:$36,0)) -> 0.30929651 | P11: =N11-K11 -> -0.011003154 | R11: 能源金属 | S11: =INDEX('面板-景气指数'!$37:$242,MATCH('面板-总览'!$R11,'面板-景气指数'!$A$37:$A$242,0),MATCH('面板-总览'!S$2,'面板-景气指数'!$36:$36,0)) -> 0.248 | T11: =INDEX('面板-景气指数'!$37:$242,MATCH('面板-总览'!$R11,'面板-景气指数'!$A$37:$A$242,0),MATCH('面板-总览'!T$2,'面板-景气指数'!$36:$36,0)) -> 0.11966667 | U11: =INDEX('面板-景气指数'!$37:$242,MATCH('面板-总览'!$R11,'面板-景气指数'!$A$37:$A$242,0),MATCH('面板-总览'!U$2,'面板-景气指数'!$36:$36,0)) -> 0.14833333 | V11: =INDEX('面板-景气指数'!$37:$242,MATCH('面板-总览'!$R11,'面板-景气指数'!$A$37:$A$242,0),MATCH('面板-总览'!V$2,'面板-景气指数'!$36:$36,0)) -> 0.22033333 | W11: =INDEX('面板-景气指数'!$37:$242,MATCH('面板-总览'!$R11,'面板-景气指数'!$A$37:$A$242,0),MATCH('面板-总览'!W$2,'面板-景气指数'!$36:$36,0)) -> 0.23166667 | X11: =INDEX('面板-景气指数'!$37:$242,MATCH('面板-总览'!$R11,'面板-景气指数'!$A$37:$A$242,0),MATCH('面板-总览'!X$2,'面板-景气指数'!$36:$36,0)) -> 0.20833333 | Y11: =INDEX('面板-景气指数'!$37:$242,MATCH('面板-总览'!$R11,'面板-景气指数'!$A$37:$A$242,0),MATCH('面板-总览'!Y$2,'面板-景气指数'!$36:$36,0)) -> 0.17466667 | Z11: =INDEX('面板-景气指数'!$37:$242,MATCH('面板-总览'!$R11,'面板-景气指数'!$A$37:$A$242,0),MATCH('面板-总览'!Z$2,'面板-景气指数'!$36:$36,0)) -> 0.148 | ... AE11: =INDEX('面板-景气指数'!$37:$242,MATCH('面板-总览'!$R11,'面板-景气指数'!$A$37:$A$242,0),MATCH('面板-总览'!AE$2,'面板-景气指数'!$36:$36,0)) -> 0.17233333 | AG11: =AE11-AB11 -> 0.053333333 | AI11: 其它小金属 | AJ11: =INDEX('面板-景气指数'!$37:$242,MATCH('面板-总览'!$AI11,'面板-景气指数'!$A$37:$A$242,0),MATCH('面板-总览'!AJ$2,'面板-景气指数'!$36:$36,0)) -> 0 | AK11: =INDEX('面板-景气指数'!$37:$242,MATCH('面板-总览'!$AI11,'面板-景气指数'!$A$37:$A$242,0),MATCH('面板-总览'!AK$2,'面板-景气指数'!$36:$36,0)) -> 0.03 | AL11: =INDEX('面板-景气指数'!$37:$242,MATCH('面板-总览'!$AI11,'面板-景气指数'!$A$37:$A$242,0),MATCH('面板-总览'!AL$2,'面板-景气指数'!$36:$36,0)) -> 0.091 | AM11: =INDEX('面板-景气指数'!$37:$242,MATCH('面板-总览'!$AI11,'面板-景气指数'!$A$37:$A$242,0),MATCH('面板-总览'!AM$2,'面板-景气指数'!$36:$36,0)) -> 0.255 | AN11: =INDEX('面板-景气指数'!$37:$242,MATCH('面板-总览'!$AI11,'面板-景气指数'!$A$37:$A$242,0),MATCH('面板-总览'!AN$2,'面板-景气指数'!$36:$36,0)) -> 0.632 | AO11: =INDEX('面板-景气指数'!$37:$242,MATCH('面板-总览'!$AI11,'面板-景气指数'!$A$37:$A$242,0),MATCH('面板-总览'!AO$2,'面板-景气指数'!$36:$36,0)) -> 0.714 | AP11: =INDEX('面板-景气指数'!$37:$242,MATCH('面板-总览'!$AI11,'面板-景气指数'!$A$37:$A$242,0),MATCH('面板-总览'!AP$2,'面板-景气指数'!$36:$36,0)) -> 0.693 | AQ11: =INDEX('面板-景气指数'!$37:$242,MATCH('面板-总览'!$AI11,'面板-景气指数'!$A$37:$A$242,0),MATCH('面板-总览'!AQ$2,'面板-景气指数'!$36:$36,0)) -> 0.704 | ... AV11: =INDEX('面板-景气指数'!$37:$242,MATCH('面板-总览'!$AI11,'面板-景气指数'!$A$37:$A$242,0),MATCH('面板-总览'!AV$2,'面板-景气指数'!$36:$36,0)) -> 0.54 | AX11: =AV11-AS11 -> -0.041
A12: 农林牧渔 | B12: =INDEX('面板-景气指数'!$37:$242,MATCH('面板-总览'!$A12,'面板-景气指数'!$A$37:$A$242,0),MATCH('面板-总览'!B$2,'面板-景气指数'!$36:$36,0)) -> 0.30418053 | C12: =INDEX('面板-景气指数'!$37:$242,MATCH('面板-总览'!$A12,'面板-景气指数'!$A$37:$A$242,0),MATCH('面板-总览'!C$2,'面板-景气指数'!$36:$36,0)) -> 0.22292741 | D12: =INDEX('面板-景气指数'!$37:$242,MATCH('面板-总览'!$A12,'面板-景气指数'!$A$37:$A$242,0),MATCH('面板-总览'!D$2,'面板-景气指数'!$36:$36,0)) -> 0.18332428 | E12: =INDEX('面板-景气指数'!$37:$242,MATCH('面板-总览'!$A12,'面板-景气指数'!$A$37:$A$242,0),MATCH('面板-总览'!E$2,'面板-景气指数'!$36:$36,0)) -> 0.18107007 | F12: =INDEX('面板-景气指数'!$37:$242,MATCH('面板-总览'!$A12,'面板-景气指数'!$A$37:$A$242,0),MATCH('面板-总览'!F$2,'面板-景气指数'!$36:$36,0)) -> 0.22442499 | G12: =INDEX('面板-景气指数'!$37:$242,MATCH('面板-总览'!$A12,'面板-景气指数'!$A$37:$A$242,0),MATCH('面板-总览'!G$2,'面板-景气指数'!$36:$36,0)) -> 0.24071517 | H12: =INDEX('面板-景气指数'!$37:$242,MATCH('面板-总览'!$A12,'面板-景气指数'!$A$37:$A$242,0),MATCH('面板-总览'!H$2,'面板-景气指数'!$36:$36,0)) -> 0.20650992 | I12: =INDEX('面板-景气指数'!$37:$242,MATCH('面板-总览'!$A12,'面板-景气指数'!$A$37:$A$242,0),MATCH('面板-总览'!I$2,'面板-景气指数'!$36:$36,0)) -> 0.15384665 | ... N12: =INDEX('面板-景气指数'!$37:$242,MATCH('面板-总览'!$A12,'面板-景气指数'!$A$37:$A$242,0),MATCH('面板-总览'!N$2,'面板-景气指数'!$36:$36,0)) -> 0.11322438 | P12: =N12-K12 -> -0.022662999 | R12: 金属新材料 | S12: =INDEX('面板-景气指数'!$37:$242,MATCH('面板-总览'!$R12,'面板-景气指数'!$A$37:$A$242,0),MATCH('面板-总览'!S$2,'面板-景气指数'!$36:$36,0)) -> 0.03 | T12: =INDEX('面板-景气指数'!$37:$242,MATCH('面板-总览'!$R12,'面板-景气指数'!$A$37:$A$242,0),MATCH('面板-总览'!T$2,'面板-景气指数'!$36:$36,0)) -> 0.051 | U12: =INDEX('面板-景气指数'!$37:$242,MATCH('面板-总览'!$R12,'面板-景气指数'!$A$37:$A$242,0),MATCH('面板-总览'!U$2,'面板-景气指数'!$36:$36,0)) -> 0.091 | V12: =INDEX('面板-景气指数'!$37:$242,MATCH('面板-总览'!$R12,'面板-景气指数'!$A$37:$A$242,0),MATCH('面板-总览'!V$2,'面板-景气指数'!$36:$36,0)) -> 0.142 | W12: =INDEX('面板-景气指数'!$37:$242,MATCH('面板-总览'!$R12,'面板-景气指数'!$A$37:$A$242,0),MATCH('面板-总览'!W$2,'面板-景气指数'!$36:$36,0)) -> 0.132 | X12: =INDEX('面板-景气指数'!$37:$242,MATCH('面板-总览'!$R12,'面板-景气指数'!$A$37:$A$242,0),MATCH('面板-总览'!X$2,'面板-景气指数'!$36:$36,0)) -> 0.163 | Y12: =INDEX('面板-景气指数'!$37:$242,MATCH('面板-总览'!$R12,'面板-景气指数'!$A$37:$A$242,0),MATCH('面板-总览'!Y$2,'面板-景气指数'!$36:$36,0)) -> 0.173 | Z12: =INDEX('面板-景气指数'!$37:$242,MATCH('面板-总览'!$R12,'面板-景气指数'!$A$37:$A$242,0),MATCH('面板-总览'!Z$2,'面板-景气指数'!$36:$36,0)) -> 0.122 | ... AE12: =INDEX('面板-景气指数'!$37:$242,MATCH('面板-总览'!$R12,'面板-景气指数'!$A$37:$A$242,0),MATCH('面板-总览'!AE$2,'面板-景气指数'!$36:$36,0)) -> 0.01 | AG12: =AE12-AB12 -> -0.03 | AI12: 锂 | AJ12: =INDEX('面板-景气指数'!$37:$242,MATCH('面板-总览'!$AI12,'面板-景气指数'!$A$37:$A$242,0),MATCH('面板-总览'!AJ$2,'面板-景气指数'!$36:$36,0)) -> 0.466 | AK12: =INDEX('面板-景气指数'!$37:$242,MATCH('面板-总览'!$AI12,'面板-景气指数'!$A$37:$A$242,0),MATCH('面板-总览'!AK$2,'面板-景气指数'!$36:$36,0)) -> 0.186 | AL12: =INDEX('面板-景气指数'!$37:$242,MATCH('面板-总览'!$AI12,'面板-景气指数'!$A$37:$A$242,0),MATCH('面板-总览'!AL$2,'面板-景气指数'!$36:$36,0)) -> 0.213 | AM12: =INDEX('面板-景气指数'!$37:$242,MATCH('面板-总览'!$AI12,'面板-景气指数'!$A$37:$A$242,0),MATCH('面板-总览'!AM$2,'面板-景气指数'!$36:$36,0)) -> 0.373 | AN12: =INDEX('面板-景气指数'!$37:$242,MATCH('面板-总览'!$AI12,'面板-景气指数'!$A$37:$A$242,0),MATCH('面板-总览'!AN$2,'面板-景气指数'!$36:$36,0)) -> 0.333 | AO12: =INDEX('面板-景气指数'!$37:$242,MATCH('面板-总览'!$AI12,'面板-景气指数'!$A$37:$A$242,0),MATCH('面板-总览'!AO$2,'面板-景气指数'!$36:$36,0)) -> 0.16 | AP12: =INDEX('面板-景气指数'!$37:$242,MATCH('面板-总览'!$AI12,'面板-景气指数'!$A$37:$A$242,0),MATCH('面板-总览'!AP$2,'面板-景气指数'!$36:$36,0)) -> 0.08 | AQ12: =INDEX('面板-景气指数'!$37:$242,MATCH('面板-总览'!$AI12,'面板-景气指数'!$A$37:$A$242,0),MATCH('面板-总览'!AQ$2,'面板-景气指数'!$36:$36,0)) -> 0.066 | ... AV12: =INDEX('面板-景气指数'!$37:$242,MATCH('面板-总览'!$AI12,'面板-景气指数'!$A$37:$A$242,0),MATCH('面板-总览'!AV$2,'面板-景气指数'!$36:$36,0)) -> 0.053 | AX12: =AV12-AS12 -> 0.04
A13: 食品饮料 | B13: =INDEX('面板-景气指数'!$37:$242,MATCH('面板-总览'!$A13,'面板-景气指数'!$A$37:$A$242,0),MATCH('面板-总览'!B$2,'面板-景气指数'!$36:$36,0)) -> 0.34366576 | C13: =INDEX('面板-景气指数'!$37:$242,MATCH('面板-总览'!$A13,'面板-景气指数'!$A$37:$A$242,0),MATCH('面板-总览'!C$2,'面板-景气指数'!$36:$36,0)) -> 0.33289853 | D13: =INDEX('面板-景气指数'!$37:$242,MATCH('面板-总览'!$A13,'面板-景气指数'!$A$37:$A$242,0),MATCH('面板-总览'!D$2,'面板-景气指数'!$36:$36,0)) -> 0.32309401 | E13: =INDEX('面板-景气指数'!$37:$242,MATCH('面板-总览'!$A13,'面板-景气指数'!$A$37:$A$242,0),MATCH('面板-总览'!E$2,'面板-景气指数'!$36:$36,0)) -> 0.30963971 | F13: =INDEX('面板-景气指数'!$37:$242,MATCH('面板-总览'!$A13,'面板-景气指数'!$A$37:$A$242,0),MATCH('面板-总览'!F$2,'面板-景气指数'!$36:$36,0)) -> 0.25662555 | G13: =INDEX('面板-景气指数'!$37:$242,MATCH('面板-总览'!$A13,'面板-景气指数'!$A$37:$A$242,0),MATCH('面板-总览'!G$2,'面板-景气指数'!$36:$36,0)) -> 0.25973161 | H13: =INDEX('面板-景气指数'!$37:$242,MATCH('面板-总览'!$A13,'面板-景气指数'!$A$37:$A$242,0),MATCH('面板-总览'!H$2,'面板-景气指数'!$36:$36,0)) -> 0.27113135 | I13: =INDEX('面板-景气指数'!$37:$242,MATCH('面板-总览'!$A13,'面板-景气指数'!$A$37:$A$242,0),MATCH('面板-总览'!I$2,'面板-景气指数'!$36:$36,0)) -> 0.31715787 | ... N13: =INDEX('面板-景气指数'!$37:$242,MATCH('面板-总览'!$A13,'面板-景气指数'!$A$37:$A$242,0),MATCH('面板-总览'!N$2,'面板-景气指数'!$36:$36,0)) -> 0.36871466 | P13: =N13-K13 -> 0.012084676 | R13: 化学原料 | S13: =INDEX('面板-景气指数'!$37:$242,MATCH('面板-总览'!$R13,'面板-景气指数'!$A$37:$A$242,0),MATCH('面板-总览'!S$2,'面板-景气指数'!$36:$36,0)) -> 0.25952884 | T13: =INDEX('面板-景气指数'!$37:$242,MATCH('面板-总览'!$R13,'面板-景气指数'!$A$37:$A$242,0),MATCH('面板-总览'!T$2,'面板-景气指数'!$36:$36,0)) -> 0.21636422 | U13: =INDEX('面板-景气指数'!$37:$242,MATCH('面板-总览'!$R13,'面板-景气指数'!$A$37:$A$242,0),MATCH('面板-总览'!U$2,'面板-景气指数'!$36:$36,0)) -> 0.17959427 | V13: =INDEX('面板-景气指数'!$37:$242,MATCH('面板-总览'!$R13,'面板-景气指数'!$A$37:$A$242,0),MATCH('面板-总览'!V$2,'面板-景气指数'!$36:$36,0)) -> 0.20179675 | W13: =INDEX('面板-景气指数'!$37:$242,MATCH('面板-总览'!$R13,'面板-景气指数'!$A$37:$A$242,0),MATCH('面板-总览'!W$2,'面板-景气指数'!$36:$36,0)) -> 0.25872219 | X13: =INDEX('面板-景气指数'!$37:$242,MATCH('面板-总览'!$R13,'面板-景气指数'!$A$37:$A$242,0),MATCH('面板-总览'!X$2,'面板-景气指数'!$36:$36,0)) -> 0.36939494 | Y13: =INDEX('面板-景气指数'!$37:$242,MATCH('面板-总览'!$R13,'面板-景气指数'!$A$37:$A$242,0),MATCH('面板-总览'!Y$2,'面板-景气指数'!$36:$36,0)) -> 0.42447936 | Z13: =INDEX('面板-景气指数'!$37:$242,MATCH('面板-总览'!$R13,'面板-景气指数'!$A$37:$A$242,0),MATCH('面板-总览'!Z$2,'面板-景气指数'!$36:$36,0)) -> 0.43610154 | ... AE13: =INDEX('面板-景气指数'!$37:$242,MATCH('面板-总览'!$R13,'面板-景气指数'!$A$37:$A$242,0),MATCH('面板-总览'!AE$2,'面板-景气指数'!$36:$36,0)) -> 0.24918726 | AG13: =AE13-AB13 -> -0.070964899 | AI13: 钴 | AJ13: =INDEX('面板-景气指数'!$37:$242,MATCH('面板-总览'!$AI13,'面板-景气指数'!$A$37:$A$242,0),MATCH('面板-总览'!AJ$2,'面板-景气指数'!$36:$36,0)) -> 0.013 | AK13: =INDEX('面板-景气指数'!$37:$242,MATCH('面板-总览'!$AI13,'面板-景气指数'!$A$37:$A$242,0),MATCH('面板-总览'!AK$2,'面板-景气指数'!$36:$36,0)) -> 0 | AL13: =INDEX('面板-景气指数'!$37:$242,MATCH('面板-总览'!$AI13,'面板-景气指数'!$A$37:$A$242,0),MATCH('面板-总览'!AL$2,'面板-景气指数'!$36:$36,0)) -> 0.069 | AM13: =INDEX('面板-景气指数'!$37:$242,MATCH('面板-总览'!$AI13,'面板-景气指数'!$A$37:$A$242,0),MATCH('面板-总览'!AM$2,'面板-景气指数'!$36:$36,0)) -> 0.166 | AN13: =INDEX('面板-景气指数'!$37:$242,MATCH('面板-总览'!$AI13,'面板-景气指数'!$A$37:$A$242,0),MATCH('面板-总览'!AN$2,'面板-景气指数'!$36:$36,0)) -> 0.25 | AO13: =INDEX('面板-景气指数'!$37:$242,MATCH('面板-总览'!$AI13,'面板-景气指数'!$A$37:$A$242,0),MATCH('面板-总览'!AO$2,'面板-景气指数'!$36:$36,0)) -> 0.333 | AP13: =INDEX('面板-景气指数'!$37:$242,MATCH('面板-总览'!$AI13,'面板-景气指数'!$A$37:$A$242,0),MATCH('面板-总览'!AP$2,'面板-景气指数'!$36:$36,0)) -> 0.291 | AQ13: =INDEX('面板-景气指数'!$37:$242,MATCH('面板-总览'!$AI13,'面板-景气指数'!$A$37:$A$242,0),MATCH('面板-总览'!AQ$2,'面板-景气指数'!$36:$36,0)) -> 0.236 | ... AV13: =INDEX('面板-景气指数'!$37:$242,MATCH('面板-总览'!$AI13,'面板-景气指数'!$A$37:$A$242,0),MATCH('面板-总览'!AV$2,'面板-景气指数'!$36:$36,0)) -> 0.444 | AX13: =AV13-AS13 -> 0.181
A14: 医药生物 | B14: =INDEX('面板-景气指数'!$37:$242,MATCH('面板-总览'!$A14,'面板-景气指数'!$A$37:$A$242,0),MATCH('面板-总览'!B$2,'面板-景气指数'!$36:$36,0)) -> 0.36205903 | C14: =INDEX('面板-景气指数'!$37:$242,MATCH('面板-总览'!$A14,'面板-景气指数'!$A$37:$A$242,0),MATCH('面板-总览'!C$2,'面板-景气指数'!$36:$36,0)) -> 0.25237578 | D14: =INDEX('面板-景气指数'!$37:$242,MATCH('面板-总览'!$A14,'面板-景气指数'!$A$37:$A$242,0),MATCH('面板-总览'!D$2,'面板-景气指数'!$36:$36,0)) -> 0.24136964 | E14: =INDEX('面板-景气指数'!$37:$242,MATCH('面板-总览'!$A14,'面板-景气指数'!$A$37:$A$242,0),MATCH('面板-总览'!E$2,'面板-景气指数'!$36:$36,0)) -> 0.25172913 | F14: =INDEX('面板-景气指数'!$37:$242,MATCH('面板-总览'!$A14,'面板-景气指数'!$A$37:$A$242,0),MATCH('面板-总览'!F$2,'面板-景气指数'!$36:$36,0)) -> 0.25585745 | G14: =INDEX('面板-景气指数'!$37:$242,MATCH('面板-总览'!$A14,'面板-景气指数'!$A$37:$A$242,0),MATCH('面板-总览'!G$2,'面板-景气指数'!$36:$36,0)) -> 0.23669935 | H14: =INDEX('面板-景气指数'!$37:$242,MATCH('面板-总览'!$A14,'面板-景气指数'!$A$37:$A$242,0),MATCH('面板-总览'!H$2,'面板-景气指数'!$36:$36,0)) -> 0.22866365 | I14: =INDEX('面板-景气指数'!$37:$242,MATCH('面板-总览'!$A14,'面板-景气指数'!$A$37:$A$242,0),MATCH('面板-总览'!I$2,'面板-景气指数'!$36:$36,0)) -> 0.25212105 | ... N14: =INDEX('面板-景气指数'!$37:$242,MATCH('面板-总览'!$A14,'面板-景气指数'!$A$37:$A$242,0),MATCH('面板-总览'!N$2,'面板-景气指数'!$36:$36,0)) -> 0.22473958 | P14: =N14-K14 -> -0.017375413 | R14: 化学制品 | S14: =INDEX('面板-景气指数'!$37:$242,MATCH('面板-总览'!$R14,'面板-景气指数'!$A$37:$A$242,0),MATCH('面板-总览'!S$2,'面板-景气指数'!$36:$36,0)) -> 0.23367675 | T14: =INDEX('面板-景气指数'!$37:$242,MATCH('面板-总览'!$R14,'面板-景气指数'!$A$37:$A$242,0),MATCH('面板-总览'!T$2,'面板-景气指数'!$36:$36,0)) -> 0.18558362 | U14: =INDEX('面板-景气指数'!$37:$242,MATCH('面板-总览'!$R14,'面板-景气指数'!$A$37:$A$242,0),MATCH('面板-总览'!U$2,'面板-景气指数'!$36:$36,0)) -> 0.18543823 | V14: =INDEX('面板-景气指数'!$37:$242,MATCH('面板-总览'!$R14,'面板-景气指数'!$A$37:$A$242,0),MATCH('面板-总览'!V$2,'面板-景气指数'!$36:$36,0)) -> 0.24248097 | W14: =INDEX('面板-景气指数'!$37:$242,MATCH('面板-总览'!$R14,'面板-景气指数'!$A$37:$A$242,0),MATCH('面板-总览'!W$2,'面板-景气指数'!$36:$36,0)) -> 0.33991038 | X14: =INDEX('面板-景气指数'!$37:$242,MATCH('面板-总览'!$R14,'面板-景气指数'!$A$37:$A$242,0),MATCH('面板-总览'!X$2,'面板-景气指数'!$36:$36,0)) -> 0.48679031 | Y14: =INDEX('面板-景气指数'!$37:$242,MATCH('面板-总览'!$R14,'面板-景气指数'!$A$37:$A$242,0),MATCH('面板-总览'!Y$2,'面板-景气指数'!$36:$36,0)) -> 0.47078158 | Z14: =INDEX('面板-景气指数'!$37:$242,MATCH('面板-总览'!$R14,'面板-景气指数'!$A$37:$A$242,0),MATCH('面板-总览'!Z$2,'面板-景气指数'!$36:$36,0)) -> 0.46987481 | ... AE14: =INDEX('面板-景气指数'!$37:$242,MATCH('面板-总览'!$R14,'面板-景气指数'!$A$37:$A$242,0),MATCH('面板-总览'!AE$2,'面板-景气指数'!$36:$36,0)) -> 0.41705216 | AG14: =AE14-AB14 -> -0.037973722 | AI14: 镍 | AJ14: =INDEX('面板-景气指数'!$37:$242,MATCH('面板-总览'!$AI14,'面板-景气指数'!$A$37:$A$242,0),MATCH('面板-总览'!AJ$2,'面板-景气指数'!$36:$36,0)) -> 0.265 | AK14: =INDEX('面板-景气指数'!$37:$242,MATCH('面板-总览'!$AI14,'面板-景气指数'!$A$37:$A$242,0),MATCH('面板-总览'!AK$2,'面板-景气指数'!$36:$36,0)) -> 0.173 | AL14: =INDEX('面板-景气指数'!$37:$242,MATCH('面板-总览'!$AI14,'面板-景气指数'!$A$37:$A$242,0),MATCH('面板-总览'!AL$2,'面板-景气指数'!$36:$36,0)) -> 0.163 | AM14: =INDEX('面板-景气指数'!$37:$242,MATCH('面板-总览'!$AI14,'面板-景气指数'!$A$37:$A$242,0),MATCH('面板-总览'!AM$2,'面板-景气指数'!$36:$36,0)) -> 0.122 | AN14: =INDEX('面板-景气指数'!$37:$242,MATCH('面板-总览'!$AI14,'面板-景气指数'!$A$37:$A$242,0),MATCH('面板-总览'!AN$2,'面板-景气指数'!$36:$36,0)) -> 0.112 | AO14: =INDEX('面板-景气指数'!$37:$242,MATCH('面板-总览'!$AI14,'面板-景气指数'!$A$37:$A$242,0),MATCH('面板-总览'!AO$2,'面板-景气指数'!$36:$36,0)) -> 0.132 | AP14: =INDEX('面板-景气指数'!$37:$242,MATCH('面板-总览'!$AI14,'面板-景气指数'!$A$37:$A$242,0),MATCH('面板-总览'!AP$2,'面板-景气指数'!$36:$36,0)) -> 0.153 | AQ14: =INDEX('面板-景气指数'!$37:$242,MATCH('面板-总览'!$AI14,'面板-景气指数'!$A$37:$A$242,0),MATCH('面板-总览'!AQ$2,'面板-景气指数'!$36:$36,0)) -> 0.142 | ... AV14: =INDEX('面板-景气指数'!$37:$242,MATCH('面板-总览'!$AI14,'面板-景气指数'!$A$37:$A$242,0),MATCH('面板-总览'!AV$2,'面板-景气指数'!$36:$36,0)) -> 0.02 | AX14: =AV14-AS14 -> -0.061
... A31: 交通运输 | B31: =INDEX('面板-景气指数'!$37:$242,MATCH('面板-总览'!$A31,'面板-景气指数'!$A$37:$A$242,0),MATCH('面板-总览'!B$2,'面板-景气指数'!$36:$36,0)) -> 0.41207138 | C31: =INDEX('面板-景气指数'!$37:$242,MATCH('面板-总览'!$A31,'面板-景气指数'!$A$37:$A$242,0),MATCH('面板-总览'!C$2,'面板-景气指数'!$36:$36,0)) -> 0.46042553 | D31: =INDEX('面板-景气指数'!$37:$242,MATCH('面板-总览'!$A31,'面板-景气指数'!$A$37:$A$242,0),MATCH('面板-总览'!D$2,'面板-景气指数'!$36:$36,0)) -> 0.38262417 | E31: =INDEX('面板-景气指数'!$37:$242,MATCH('面板-总览'!$A31,'面板-景气指数'!$A$37:$A$242,0),MATCH('面板-总览'!E$2,'面板-景气指数'!$36:$36,0)) -> 0.35709206 | F31: =INDEX('面板-景气指数'!$37:$242,MATCH('面板-总览'!$A31,'面板-景气指数'!$A$37:$A$242,0),MATCH('面板-总览'!F$2,'面板-景气指数'!$36:$36,0)) -> 0.35800351 | G31: =INDEX('面板-景气指数'!$37:$242,MATCH('面板-总览'!$A31,'面板-景气指数'!$A$37:$A$242,0),MATCH('面板-总览'!G$2,'面板-景气指数'!$36:$36,0)) -> 0.38628423 | H31: =INDEX('面板-景气指数'!$37:$242,MATCH('面板-总览'!$A31,'面板-景气指数'!$A$37:$A$242,0),MATCH('面板-总览'!H$2,'面板-景气指数'!$36:$36,0)) -> 0.4339256 | I31: =INDEX('面板-景气指数'!$37:$242,MATCH('面板-总览'!$A31,'面板-景气指数'!$A$37:$A$242,0),MATCH('面板-总览'!I$2,'面板-景气指数'!$36:$36,0)) -> 0.50066672 | ... N31: =INDEX('面板-景气指数'!$37:$242,MATCH('面板-总览'!$A31,'面板-景气指数'!$A$37:$A$242,0),MATCH('面板-总览'!N$2,'面板-景气指数'!$36:$36,0)) -> 0.54915539 | P31: =N31-K31 -> 0.042401346 | R31: 电池 | S31: =INDEX('面板-景气指数'!$37:$242,MATCH('面板-总览'!$R31,'面板-景气指数'!$A$37:$A$242,0),MATCH('面板-总览'!S$2,'面板-景气指数'!$36:$36,0)) -> 0.40479167 | T31: =INDEX('面板-景气指数'!$37:$242,MATCH('面板-总览'!$R31,'面板-景气指数'!$A$37:$A$242,0),MATCH('面板-总览'!T$2,'面板-景气指数'!$36:$36,0)) -> 0.386 | U31: =INDEX('面板-景气指数'!$37:$242,MATCH('面板-总览'!$R31,'面板-景气指数'!$A$37:$A$242,0),MATCH('面板-总览'!U$2,'面板-景气指数'!$36:$36,0)) -> 0.40670833 | V31: =INDEX('面板-景气指数'!$37:$242,MATCH('面板-总览'!$R31,'面板-景气指数'!$A$37:$A$242,0),MATCH('面板-总览'!V$2,'面板-景气指数'!$36:$36,0)) -> 0.34625 | W31: =INDEX('面板-景气指数'!$37:$242,MATCH('面板-总览'!$R31,'面板-景气指数'!$A$37:$A$242,0),MATCH('面板-总览'!W$2,'面板-景气指数'!$36:$36,0)) -> 0.31558333 | X31: =INDEX('面板-景气指数'!$37:$242,MATCH('面板-总览'!$R31,'面板-景气指数'!$A$37:$A$242,0),MATCH('面板-总览'!X$2,'面板-景气指数'!$36:$36,0)) -> 0.282375 | Y31: =INDEX('面板-景气指数'!$37:$242,MATCH('面板-总览'!$R31,'面板-景气指数'!$A$37:$A$242,0),MATCH('面板-总览'!Y$2,'面板-景气指数'!$36:$36,0)) -> 0.29091667 | Z31: =INDEX('面板-景气指数'!$37:$242,MATCH('面板-总览'!$R31,'面板-景气指数'!$A$37:$A$242,0),MATCH('面板-总览'!Z$2,'面板-景气指数'!$36:$36,0)) -> 0.27820833 | ... AE31: =INDEX('面板-景气指数'!$37:$242,MATCH('面板-总览'!$R31,'面板-景气指数'!$A$37:$A$242,0),MATCH('面板-总览'!AE$2,'面板-景气指数'!$36:$36,0)) -> 0.33495833 | AG31: =AE31-AB31 -> 0.036666667 | AI31: 其他化学纤维 | AJ31: =INDEX('面板-景气指数'!$37:$242,MATCH('面板-总览'!$AI31,'面板-景气指数'!$A$37:$A$242,0),MATCH('面板-总览'!AJ$2,'面板-景气指数'!$36:$36,0)) -> 0.2545 | AK31: =INDEX('面板-景气指数'!$37:$242,MATCH('面板-总览'!$AI31,'面板-景气指数'!$A$37:$A$242,0),MATCH('面板-总览'!AK$2,'面板-景气指数'!$36:$36,0)) -> 0.234 | AL31: =INDEX('面板-景气指数'!$37:$242,MATCH('面板-总览'!$AI31,'面板-景气指数'!$A$37:$A$242,0),MATCH('面板-总览'!AL$2,'面板-景气指数'!$36:$36,0)) -> 0.3105 | AM31: =INDEX('面板-景气指数'!$37:$242,MATCH('面板-总览'!$AI31,'面板-景气指数'!$A$37:$A$242,0),MATCH('面板-总览'!AM$2,'面板-景气指数'!$36:$36,0)) -> 0.3515 | AN31: =INDEX('面板-景气指数'!$37:$242,MATCH('面板-总览'!$AI31,'面板-景气指数'!$A$37:$A$242,0),MATCH('面板-总览'!AN$2,'面板-景气指数'!$36:$36,0)) -> 0.3515 | AO31: =INDEX('面板-景气指数'!$37:$242,MATCH('面板-总览'!$AI31,'面板-景气指数'!$A$37:$A$242,0),MATCH('面板-总览'!AO$2,'面板-景气指数'!$36:$36,0)) -> 0.3415 | AP31: =INDEX('面板-景气指数'!$37:$242,MATCH('面板-总览'!$AI31,'面板-景气指数'!$A$37:$A$242,0),MATCH('面板-总览'!AP$2,'面板-景气指数'!$36:$36,0)) -> 0.3055 | AQ31: =INDEX('面板-景气指数'!$37:$242,MATCH('面板-总览'!$AI31,'面板-景气指数'!$A$37:$A$242,0),MATCH('面板-总览'!AQ$2,'面板-景气指数'!$36:$36,0)) -> 0.326 | ... AV31: =INDEX('面板-景气指数'!$37:$242,MATCH('面板-总览'!$AI31,'面板-景气指数'!$A$37:$A$242,0),MATCH('面板-总览'!AV$2,'面板-景气指数'!$36:$36,0)) -> 0.2855 | AX31: =AV31-AS31 -> -0.2035
R32: 电网设备 | S32: =INDEX('面板-景气指数'!$37:$242,MATCH('面板-总览'!$R32,'面板-景气指数'!$A$37:$A$242,0),MATCH('面板-总览'!S$2,'面板-景气指数'!$36:$36,0)) -> 0.3515 | T32: =INDEX('面板-景气指数'!$37:$242,MATCH('面板-总览'!$R32,'面板-景气指数'!$A$37:$A$242,0),MATCH('面板-总览'!T$2,'面板-景气指数'!$36:$36,0)) -> 0.4025 | U32: =INDEX('面板-景气指数'!$37:$242,MATCH('面板-总览'!$R32,'面板-景气指数'!$A$37:$A$242,0),MATCH('面板-总览'!U$2,'面板-景气指数'!$36:$36,0)) -> 0.418 | V32: =INDEX('面板-景气指数'!$37:$242,MATCH('面板-总览'!$R32,'面板-景气指数'!$A$37:$A$242,0),MATCH('面板-总览'!V$2,'面板-景气指数'!$36:$36,0)) -> 0.4435 | W32: =INDEX('面板-景气指数'!$37:$242,MATCH('面板-总览'!$R32,'面板-景气指数'!$A$37:$A$242,0),MATCH('面板-总览'!W$2,'面板-景气指数'!$36:$36,0)) -> 0.4285 | X32: =INDEX('面板-景气指数'!$37:$242,MATCH('面板-总览'!$R32,'面板-景气指数'!$A$37:$A$242,0),MATCH('面板-总览'!X$2,'面板-景气指数'!$36:$36,0)) -> 0.3665 | Y32: =INDEX('面板-景气指数'!$37:$242,MATCH('面板-总览'!$R32,'面板-景气指数'!$A$37:$A$242,0),MATCH('面板-总览'!Y$2,'面板-景气指数'!$36:$36,0)) -> 0.3415 | Z32: =INDEX('面板-景气指数'!$37:$242,MATCH('面板-总览'!$R32,'面板-景气指数'!$A$37:$A$242,0),MATCH('面板-总览'!Z$2,'面板-景气指数'!$36:$36,0)) -> 0.3975 | ... AE32: =INDEX('面板-景气指数'!$37:$242,MATCH('面板-总览'!$R32,'面板-景气指数'!$A$37:$A$242,0),MATCH('面板-总览'!AE$2,'面板-景气指数'!$36:$36,0)) -> 0.6065 | AG32: =AE32-AB32 -> 0.056 | AI32: 其他塑料制品 | AJ32: =INDEX('面板-景气指数'!$37:$242,MATCH('面板-总览'!$AI32,'面板-景气指数'!$A$37:$A$242,0),MATCH('面板-总览'!AJ$2,'面板-景气指数'!$36:$36,0)) -> 0.193 | AK32: =INDEX('面板-景气指数'!$37:$242,MATCH('面板-总览'!$AI32,'面板-景气指数'!$A$37:$A$242,0),MATCH('面板-总览'!AK$2,'面板-景气指数'!$36:$36,0)) -> 0.214 | AL32: =INDEX('面板-景气指数'!$37:$242,MATCH('面板-总览'!$AI32,'面板-景气指数'!$A$37:$A$242,0),MATCH('面板-总览'!AL$2,'面板-景气指数'!$36:$36,0)) -> 0.265 | AM32: =INDEX('面板-景气指数'!$37:$242,MATCH('面板-总览'!$AI32,'面板-景气指数'!$A$37:$A$242,0),MATCH('面板-总览'!AM$2,'面板-景气指数'!$36:$36,0)) -> 0.459 | AN32: =INDEX('面板-景气指数'!$37:$242,MATCH('面板-总览'!$AI32,'面板-景气指数'!$A$37:$A$242,0),MATCH('面板-总览'!AN$2,'面板-景气指数'!$36:$36,0)) -> 0.714 | AO32: =INDEX('面板-景气指数'!$37:$242,MATCH('面板-总览'!$AI32,'面板-景气指数'!$A$37:$A$242,0),MATCH('面板-总览'!AO$2,'面板-景气指数'!$36:$36,0)) -> 0.775 | AP32: =INDEX('面板-景气指数'!$37:$242,MATCH('面板-总览'!$AI32,'面板-景气指数'!$A$37:$A$242,0),MATCH('面板-总览'!AP$2,'面板-景气指数'!$36:$36,0)) -> 0.744 | AQ32: =INDEX('面板-景气指数'!$37:$242,MATCH('面板-总览'!$AI32,'面板-景气指数'!$A$37:$A$242,0),MATCH('面板-总览'!AQ$2,'面板-景气指数'!$36:$36,0)) -> 0.663 | ... AV32: =INDEX('面板-景气指数'!$37:$242,MATCH('面板-总览'!$AI32,'面板-景气指数'!$A$37:$A$242,0),MATCH('面板-总览'!AV$2,'面板-景气指数'!$36:$36,0)) -> 0.642 | AX32: =AV32-AS32 -> -0.062
R33: 航海装备 | S33: =INDEX('面板-景气指数'!$37:$242,MATCH('面板-总览'!$R33,'面板-景气指数'!$A$37:$A$242,0),MATCH('面板-总览'!S$2,'面板-景气指数'!$36:$36,0)) -> 0.62175 | T33: =INDEX('面板-景气指数'!$37:$242,MATCH('面板-总览'!$R33,'面板-景气指数'!$A$37:$A$242,0),MATCH('面板-总览'!T$2,'面板-景气指数'!$36:$36,0)) -> 0.67325 | U33: =INDEX('面板-景气指数'!$37:$242,MATCH('面板-总览'!$R33,'面板-景气指数'!$A$37:$A$242,0),MATCH('面板-总览'!U$2,'面板-景气指数'!$36:$36,0)) -> 0.691 | V33: =INDEX('面板-景气指数'!$37:$242,MATCH('面板-总览'!$R33,'面板-景气指数'!$A$37:$A$242,0),MATCH('面板-总览'!V$2,'面板-景气指数'!$36:$36,0)) -> 0.63975 | W33: =INDEX('面板-景气指数'!$37:$242,MATCH('面板-总览'!$R33,'面板-景气指数'!$A$37:$A$242,0),MATCH('面板-总览'!W$2,'面板-景气指数'!$36:$36,0)) -> 0.645 | X33: =INDEX('面板-景气指数'!$37:$242,MATCH('面板-总览'!$R33,'面板-景气指数'!$A$37:$A$242,0),MATCH('面板-总览'!X$2,'面板-景气指数'!$36:$36,0)) -> 0.6655 | Y33: =INDEX('面板-景气指数'!$37:$242,MATCH('面板-总览'!$R33,'面板-景气指数'!$A$37:$A$242,0),MATCH('面板-总览'!Y$2,'面板-景气指数'!$36:$36,0)) -> 0.6985 | Z33: =INDEX('面板-景气指数'!$37:$242,MATCH('面板-总览'!$R33,'面板-景气指数'!$A$37:$A$242,0),MATCH('面板-总览'!Z$2,'面板-景气指数'!$36:$36,0)) -> 0.655 | ... AE33: =INDEX('面板-景气指数'!$37:$242,MATCH('面板-总览'!$R33,'面板-景气指数'!$A$37:$A$242,0),MATCH('面板-总览'!AE$2,'面板-景气指数'!$36:$36,0)) -> 0.7065 | AG33: =AE33-AB33 -> 0.02075 | AI33: 改性塑料 | AJ33: =INDEX('面板-景气指数'!$37:$242,MATCH('面板-总览'!$AI33,'面板-景气指数'!$A$37:$A$242,0),MATCH('面板-总览'!AJ$2,'面板-景气指数'!$36:$36,0)) -> 0.17075 | AK33: =INDEX('面板-景气指数'!$37:$242,MATCH('面板-总览'!$AI33,'面板-景气指数'!$A$37:$A$242,0),MATCH('面板-总览'!AK$2,'面板-景气指数'!$36:$36,0)) -> 0.165 | AL33: =INDEX('面板-景气指数'!$37:$242,MATCH('面板-总览'!$AI33,'面板-景气指数'!$A$37:$A$242,0),MATCH('面板-总览'!AL$2,'面板-景气指数'!$36:$36,0)) -> 0.1985 | AM33: =INDEX('面板-景气指数'!$37:$242,MATCH('面板-总览'!$AI33,'面板-景气指数'!$A$37:$A$242,0),MATCH('面板-总览'!AM$2,'面板-景气指数'!$36:$36,0)) -> 0.2625 | AN33: =INDEX('面板-景气指数'!$37:$242,MATCH('面板-总览'!$AI33,'面板-景气指数'!$A$37:$A$242,0),MATCH('面板-总览'!AN$2,'面板-景气指数'!$36:$36,0)) -> 0.3435 | AO33: =INDEX('面板-景气指数'!$37:$242,MATCH('面板-总览'!$AI33,'面板-景气指数'!$A$37:$A$242,0),MATCH('面板-总览'!AO$2,'面板-景气指数'!$36:$36,0)) -> 0.34375 | AP33: =INDEX('面板-景气指数'!$37:$242,MATCH('面板-总览'!$AI33,'面板-景气指数'!$A$37:$A$242,0),MATCH('面板-总览'!AP$2,'面板-景气指数'!$36:$36,0)) -> 0.40225 | AQ33: =INDEX('面板-景气指数'!$37:$242,MATCH('面板-总览'!$AI33,'面板-景气指数'!$A$37:$A$242,0),MATCH('面板-总览'!AQ$2,'面板-景气指数'!$36:$36,0)) -> 0.41775 | ... AV33: =INDEX('面板-景气指数'!$37:$242,MATCH('面板-总览'!$AI33,'面板-景气指数'!$A$37:$A$242,0),MATCH('面板-总览'!AV$2,'面板-景气指数'!$36:$36,0)) -> 0.54075 | AX33: =AV33-AS33 -> 0.031
R34: 航空装备 | S34: =INDEX('面板-景气指数'!$37:$242,MATCH('面板-总览'!$R34,'面板-景气指数'!$A$37:$A$242,0),MATCH('面板-总览'!S$2,'面板-景气指数'!$36:$36,0)) -> 0.2545 | T34: =INDEX('面板-景气指数'!$37:$242,MATCH('面板-总览'!$R34,'面板-景气指数'!$A$37:$A$242,0),MATCH('面板-总览'!T$2,'面板-景气指数'!$36:$36,0)) -> 0.158 | U34: =INDEX('面板-景气指数'!$37:$242,MATCH('面板-总览'!$R34,'面板-景气指数'!$A$37:$A$242,0),MATCH('面板-总览'!U$2,'面板-景气指数'!$36:$36,0)) -> 0.132 | V34: =INDEX('面板-景气指数'!$37:$242,MATCH('面板-总览'!$R34,'面板-景气指数'!$A$37:$A$242,0),MATCH('面板-总览'!V$2,'面板-景气指数'!$36:$36,0)) -> 0.107 | W34: =INDEX('面板-景气指数'!$37:$242,MATCH('面板-总览'!$R34,'面板-景气指数'!$A$37:$A$242,0),MATCH('面板-总览'!W$2,'面板-景气指数'!$36:$36,0)) -> 0.071 | X34: =INDEX('面板-景气指数'!$37:$242,MATCH('面板-总览'!$R34,'面板-景气指数'!$A$37:$A$242,0),MATCH('面板-总览'!X$2,'面板-景气指数'!$36:$36,0)) -> 0.03 | Y34: =INDEX('面板-景气指数'!$37:$242,MATCH('面板-总览'!$R34,'面板-景气指数'!$A$37:$A$242,0),MATCH('面板-总览'!Y$2,'面板-景气指数'!$36:$36,0)) -> 0.015 | Z34: =INDEX('面板-景气指数'!$37:$242,MATCH('面板-总览'!$R34,'面板-景气指数'!$A$37:$A$242,0),MATCH('面板-总览'!Z$2,'面板-景气指数'!$36:$36,0)) -> 0.0405 | ... AE34: =INDEX('面板-景气指数'!$37:$242,MATCH('面板-总览'!$R34,'面板-景气指数'!$A$37:$A$242,0),MATCH('面板-总览'!AE$2,'面板-景气指数'!$36:$36,0)) -> 0.071 | AG34: =AE34-AB34 -> 0.051 | AI34: 合成树脂 | AJ34: =INDEX('面板-景气指数'!$37:$242,MATCH('面板-总览'!$AI34,'面板-景气指数'!$A$37:$A$242,0),MATCH('面板-总览'!AJ$2,'面板-景气指数'!$36:$36,0)) -> 0.367 | AK34: =INDEX('面板-景气指数'!$37:$242,MATCH('面板-总览'!$AI34,'面板-景气指数'!$A$37:$A$242,0),MATCH('面板-总览'!AK$2,'面板-景气指数'!$36:$36,0)) -> 0.387 | AL34: =INDEX('面板-景气指数'!$37:$242,MATCH('面板-总览'!$AI34,'面板-景气指数'!$A$37:$A$242,0),MATCH('面板-总览'!AL$2,'面板-景气指数'!$36:$36,0)) -> 0.418 | AM34: =INDEX('面板-景气指数'!$37:$242,MATCH('面板-总览'!$AI34,'面板-景气指数'!$A$37:$A$242,0),MATCH('面板-总览'!AM$2,'面板-景气指数'!$36:$36,0)) -> 0.479 | AN34: =INDEX('面板-景气指数'!$37:$242,MATCH('面板-总览'!$AI34,'面板-景气指数'!$A$37:$A$242,0),MATCH('面板-总览'!AN$2,'面板-景气指数'!$36:$36,0)) -> 0.52 | AO34: =INDEX('面板-景气指数'!$37:$242,MATCH('面板-总览'!$AI34,'面板-景气指数'!$A$37:$A$242,0),MATCH('面板-总览'!AO$2,'面板-景气指数'!$36:$36,0)) -> 0.54 | AP34: =INDEX('面板-景气指数'!$37:$242,MATCH('面板-总览'!$AI34,'面板-景气指数'!$A$37:$A$242,0),MATCH('面板-总览'!AP$2,'面板-景气指数'!$36:$36,0)) -> 0.551 | AQ34: =INDEX('面板-景气指数'!$37:$242,MATCH('面板-总览'!$AI34,'面板-景气指数'!$A$37:$A$242,0),MATCH('面板-总览'!AQ$2,'面板-景气指数'!$36:$36,0)) -> 0.571 | ... AV34: =INDEX('面板-景气指数'!$37:$242,MATCH('面板-总览'!$AI34,'面板-景气指数'!$A$37:$A$242,0),MATCH('面板-总览'!AV$2,'面板-景气指数'!$36:$36,0)) -> 0.602 | AX34: =AV34-AS34 -> -0.02
R35: 军工电子 | S35: =INDEX('面板-景气指数'!$37:$242,MATCH('面板-总览'!$R35,'面板-景气指数'!$A$37:$A$242,0),MATCH('面板-总览'!S$2,'面板-景气指数'!$36:$36,0)) -> 0.142 | T35: =INDEX('面板-景气指数'!$37:$242,MATCH('面板-总览'!$R35,'面板-景气指数'!$A$37:$A$242,0),MATCH('面板-总览'!T$2,'面板-景气指数'!$36:$36,0)) -> 0.112 | U35: =INDEX('面板-景气指数'!$37:$242,MATCH('面板-总览'!$R35,'面板-景气指数'!$A$37:$A$242,0),MATCH('面板-总览'!U$2,'面板-景气指数'!$36:$36,0)) -> 0.122 | V35: =INDEX('面板-景气指数'!$37:$242,MATCH('面板-总览'!$R35,'面板-景气指数'!$A$37:$A$242,0),MATCH('面板-总览'!V$2,'面板-景气指数'!$36:$36,0)) -> 0.132 | W35: =INDEX('面板-景气指数'!$37:$242,MATCH('面板-总览'!$R35,'面板-景气指数'!$A$37:$A$242,0),MATCH('面板-总览'!W$2,'面板-景气指数'!$36:$36,0)) -> 0.163 | X35: =INDEX('面板-景气指数'!$37:$242,MATCH('面板-总览'!$R35,'面板-景气指数'!$A$37:$A$242,0),MATCH('面板-总览'!X$2,'面板-景气指数'!$36:$36,0)) -> 0.214 | Y35: =INDEX('面板-景气指数'!$37:$242,MATCH('面板-总览'!$R35,'面板-景气指数'!$A$37:$A$242,0),MATCH('面板-总览'!Y$2,'面板-景气指数'!$36:$36,0)) -> 0.234 | Z35: =INDEX('面板-景气指数'!$37:$242,MATCH('面板-总览'!$R35,'面板-景气指数'!$A$37:$A$242,0),MATCH('面板-总览'!Z$2,'面板-景气指数'!$36:$36,0)) -> 0.244 | ... AE35: =INDEX('面板-景气指数'!$37:$242,MATCH('面板-总览'!$R35,'面板-景气指数'!$A$37:$A$242,0),MATCH('面板-总览'!AE$2,'面板-景气指数'!$36:$36,0)) -> 0.193 | AG35: =AE35-AB35 -> -0.194 | AI35: 膜材料 | AJ35: =INDEX('面板-景气指数'!$37:$242,MATCH('面板-总览'!$AI35,'面板-景气指数'!$A$37:$A$242,0),MATCH('面板-总览'!AJ$2,'面板-景气指数'!$36:$36,0)) -> 0.306 | AK35: =INDEX('面板-景气指数'!$37:$242,MATCH('面板-总览'!$AI35,'面板-景气指数'!$A$37:$A$242,0),MATCH('面板-总览'!AK$2,'面板-景气指数'!$36:$36,0)) -> 0.326 | AL35: =INDEX('面板-景气指数'!$37:$242,MATCH('面板-总览'!$AI35,'面板-景气指数'!$A$37:$A$242,0),MATCH('面板-总览'!AL$2,'面板-景气指数'!$36:$36,0)) -> 0.193 | AM35: =INDEX('面板-景气指数'!$37:$242,MATCH('面板-总览'!$AI35,'面板-景气指数'!$A$37:$A$242,0),MATCH('面板-总览'!AM$2,'面板-景气指数'!$36:$36,0)) -> 0.142 | AN35: =INDEX('面板-景气指数'!$37:$242,MATCH('面板-总览'!$AI35,'面板-景气指数'!$A$37:$A$242,0),MATCH('面板-总览'!AN$2,'面板-景气指数'!$36:$36,0)) -> 0.183 | AO35: =INDEX('面板-景气指数'!$37:$242,MATCH('面板-总览'!$AI35,'面板-景气指数'!$A$37:$A$242,0),MATCH('面板-总览'!AO$2,'面板-景气指数'!$36:$36,0)) -> 0.387 | AP35: =INDEX('面板-景气指数'!$37:$242,MATCH('面板-总览'!$AI35,'面板-景气指数'!$A$37:$A$242,0),MATCH('面板-总览'!AP$2,'面板-景气指数'!$36:$36,0)) -> 0.459 | AQ35: =INDEX('面板-景气指数'!$37:$242,MATCH('面板-总览'!$AI35,'面板-景气指数'!$A$37:$A$242,0),MATCH('面板-总览'!AQ$2,'面板-景气指数'!$36:$36,0)) -> 0.489 | ... AV35: =INDEX('面板-景气指数'!$37:$242,MATCH('面板-总览'!$AI35,'面板-景气指数'!$A$37:$A$242,0),MATCH('面板-总览'!AV$2,'面板-景气指数'!$36:$36,0)) -> 0.53 | AX35: =AV35-AS35 -> 0.02
R36: 半导体 | S36: =INDEX('面板-景气指数'!$37:$242,MATCH('面板-总览'!$R36,'面板-景气指数'!$A$37:$A$242,0),MATCH('面板-总览'!S$2,'面板-景气指数'!$36:$36,0)) -> 0.251 | T36: =INDEX('面板-景气指数'!$37:$242,MATCH('面板-总览'!$R36,'面板-景气指数'!$A$37:$A$242,0),MATCH('面板-总览'!T$2,'面板-景气指数'!$36:$36,0)) -> 0.22857143 | U36: =INDEX('面板-景气指数'!$37:$242,MATCH('面板-总览'!$R36,'面板-景气指数'!$A$37:$A$242,0),MATCH('面板-总览'!U$2,'面板-景气指数'!$36:$36,0)) -> 0.21971429 | V36: =INDEX('面板-景气指数'!$37:$242,MATCH('面板-总览'!$R36,'面板-景气指数'!$A$37:$A$242,0),MATCH('面板-总览'!V$2,'面板-景气指数'!$36:$36,0)) -> 0.18864286 | W36: =INDEX('面板-景气指数'!$37:$242,MATCH('面板-总览'!$R36,'面板-景气指数'!$A$37:$A$242,0),MATCH('面板-总览'!W$2,'面板-景气指数'!$36:$36,0)) -> 0.20707143 | X36: =INDEX('面板-景气指数'!$37:$242,MATCH('面板-总览'!$R36,'面板-景气指数'!$A$37:$A$242,0),MATCH('面板-总览'!X$2,'面板-景气指数'!$36:$36,0)) -> 0.22664286 | Y36: =INDEX('面板-景气指数'!$37:$242,MATCH('面板-总览'!$R36,'面板-景气指数'!$A$37:$A$242,0),MATCH('面板-总览'!Y$2,'面板-景气指数'!$36:$36,0)) -> 0.26664286 | Z36: =INDEX('面板-景气指数'!$37:$242,MATCH('面板-总览'!$R36,'面板-景气指数'!$A$37:$A$242,0),MATCH('面板-总览'!Z$2,'面板-景气指数'!$36:$36,0)) -> 0.307 | ... AE36: =INDEX('面板-景气指数'!$37:$242,MATCH('面板-总览'!$R36,'面板-景气指数'!$A$37:$A$242,0),MATCH('面板-总览'!AE$2,'面板-景气指数'!$36:$36,0)) -> 0.48635714 | AG36: =AE36-AB36 -> 0.069071429 | AI36: 其他橡胶制品 | AJ36: =INDEX('面板-景气指数'!$37:$242,MATCH('面板-总览'!$AI36,'面板-景气指数'!$A$37:$A$242,0),MATCH('面板-总览'!AJ$2,'面板-景气指数'!$36:$36,0)) -> 0.265 | AK36: =INDEX('面板-景气指数'!$37:$242,MATCH('面板-总览'!$AI36,'面板-景气指数'!$A$37:$A$242,0),MATCH('面板-总览'!AK$2,'面板-景气指数'!$36:$36,0)) -> 0.244 | AL36: =INDEX('面板-景气指数'!$37:$242,MATCH('面板-总览'!$AI36,'面板-景气指数'!$A$37:$A$242,0),MATCH('面板-总览'!AL$2,'面板-景气指数'!$36:$36,0)) -> 0.326 | AM36: =INDEX('面板-景气指数'!$37:$242,MATCH('面板-总览'!$AI36,'面板-景气指数'!$A$37:$A$242,0),MATCH('面板-总览'!AM$2,'面板-景气指数'!$36:$36,0)) -> 0.397 | AN36: =INDEX('面板-景气指数'!$37:$242,MATCH('面板-总览'!$AI36,'面板-景气指数'!$A$37:$A$242,0),MATCH('面板-总览'!AN$2,'面板-景气指数'!$36:$36,0)) -> 0.459 | AO36: =INDEX('面板-景气指数'!$37:$242,MATCH('面板-总览'!$AI36,'面板-景气指数'!$A$37:$A$242,0),MATCH('面板-总览'!AO$2,'面板-景气指数'!$36:$36,0)) -> 0.551 | AP36: =INDEX('面板-景气指数'!$37:$242,MATCH('面板-总览'!$AI36,'面板-景气指数'!$A$37:$A$242,0),MATCH('面板-总览'!AP$2,'面板-景气指数'!$36:$36,0)) -> 0.693 | AQ36: =INDEX('面板-景气指数'!$37:$242,MATCH('面板-总览'!$AI36,'面板-景气指数'!$A$37:$A$242,0),MATCH('面板-总览'!AQ$2,'面板-景气指数'!$36:$36,0)) -> 0.724 | ... AV36: =INDEX('面板-景气指数'!$37:$242,MATCH('面板-总览'!$AI36,'面板-景气指数'!$A$37:$A$242,0),MATCH('面板-总览'!AV$2,'面板-景气指数'!$36:$36,0)) -> 0.785 | AX36: =AV36-AS36 -> 0.214
