Workbook
Name Bubble: "Bubble"
Name Chart: "Chart"
Name Heatmap: "Heatmap"
Name Histogram: "Histogram"
Name Map: "Map"
Name PieChart: "PieChart"
Name Scatter: "Scatter"
Name Series: "Series"
Name Table: "Table"

Sheet 面板-总览
A1: 一级行业 | R1: 二级行业 | AI1: 三级行业
A2: 景气指数 | B2: 45199 | C2: 45230 | D2: 45260 | E2: 45291 | F2: 45322 | G2: 45351 | H2: 45382 | I2: 45412 | J2: 45443 | K2: 45473 | L2: 45504 | M2: 45535 | N2: 45565 | O2: 3M变化 | R2: 景气指数 | S2: 45199 | T2: 45230 | U2: 45260 | V2: 45291 | W2: 45322 | X2: 45351 | Y2: 45382 | Z2: 45412 | AA2: 45443 | AB2: 45473 | AC2: 45504 | AD2: 45535 | AE2: 45565 | AF2: 3M变化 | AI2: 景气指数 | AJ2: 45199 | AK2: 45230 | AL2: 45260 | AM2: 45291 | AN2: 45322 | AO2: 45351 | AP2: 45382 | AQ2: 45412 | AR2: 45443 | AS2: 45473 | AT2: 45504 | AU2: 45535 | AV2: 45565 | AW2: 3M变化
A3: 石油石化 | B3: =INDEX('面板-景气指数'!$37:$244,MATCH('面板-总览'!$A3,'面板-景气指数'!$A$37:$A$244,0),MATCH('面板-总览'!B$2,'面板-景气指数'!$36:$36,0)) -> 0.8104 | C3: =INDEX('面板-景气指数'!$37:$244,MATCH('面板-总览'!$A3,'面板-景气指数'!$A$37:$A$244,0),MATCH('面板-总览'!C$2,'面板-景气指数'!$36:$36,0)) -> 0.7364 | D3: =INDEX('面板-景气指数'!$37:$244,MATCH('面板-总览'!$A3,'面板-景气指数'!$A$37:$A$244,0),MATCH('面板-总览'!D$2,'面板-景气指数'!$36:$36,0)) -> 0.56205 | E3: =INDEX('面板-景气指数'!$37:$244,MATCH('面板-总览'!$A3,'面板-景气指数'!$A$37:$A$244,0),MATCH('面板-总览'!E$2,'面板-景气指数'!$36:$36,0)) -> 0.4319 | F3: =INDEX('面板-景气指数'!$37:$244,MATCH('面板-总览'!$A3,'面板-景气指数'!$A$37:$A$244,0),MATCH('面板-总览'!F$2,'面板-景气指数'!$36:$36,0)) -> 0.46545 | G3: =INDEX('面板-景气指数'!$37:$244,MATCH('面板-总览'!$A3,'面板-景气指数'!$A$37:$A$244,0),MATCH('面板-总览'!G$2,'面板-景气指数'!$36:$36,0)) -> 0.5842 | H3: =INDEX('面板-景气指数'!$37:$244,MATCH('面板-总览'!$A3,'面板-景气指数'!$A$37:$A$244,0),MATCH('面板-总览'!H$2,'面板-景气指数'!$36:$36,0)) -> 0.6277 | I3: =INDEX('面板-景气指数'!$37:$244,MATCH('面板-总览'!$A3,'面板-景气指数'!$A$37:$A$244,0),MATCH('面板-总览'!I$2,'面板-景气指数'!$36:$36,0)) -> 0.5402 | ... N3: =INDEX('面板-景气指数'!$37:$244,MATCH('面板-总览'!$A3,'面板-景气指数'!$A$37:$A$244,0),MATCH('面板-总览'!N$2,'面板-景气指数'!$36:$36,0)) -> 0.5797 | P3: =N3-K3 -> -0.03455 | R3: 油气开采/油服工程 | S3: =INDEX('面板-景气指数'!$37:$244,MATCH('面板-总览'!$R3,'面板-景气指数'!$A$37:$A$244,0),MATCH('面板-总览'!S$2,'面板-景气指数'!$36:$36,0)) -> 0.76592308 | T3: =INDEX('面板-景气指数'!$37:$244,MATCH('面板-总览'!$R3,'面板-景气指数'!$A$37:$A$244,0),MATCH('面板-总览'!T$2,'面板-景气指数'!$36:$36,0)) -> 0.72046154 | U3: =INDEX('面板-景气指数'!$37:$244,MATCH('面板-总览'!$R3,'面板-景气指数'!$A$37:$A$244,0),MATCH('面板-总览'!U$2,'面板-景气指数'!$36:$36,0)) -> 0.67138462 | V3: =INDEX('面板-景气指数'!$37:$244,MATCH('面板-总览'!$R3,'面板-景气指数'!$A$37:$A$244,0),MATCH('面板-总览'!V$2,'面板-景气指数'!$36:$36,0)) -> 0.63861538 | W3: =INDEX('面板-景气指数'!$37:$244,MATCH('面板-总览'!$R3,'面板-景气指数'!$A$37:$A$244,0),MATCH('面板-总览'!W$2,'面板-景气指数'!$36:$36,0)) -> 0.64338462 | X3: =INDEX('面板-景气指数'!$37:$244,MATCH('面板-总览'!$R3,'面板-景气指数'!$A$37:$A$244,0),MATCH('面板-总览'!X$2,'面板-景气指数'!$36:$36,0)) -> 0.66884615 | Y3: =INDEX('面板-景气指数'!$37:$244,MATCH('面板-总览'!$R3,'面板-景气指数'!$A$37:$A$244,0),MATCH('面板-总览'!Y$2,'面板-景气指数'!$36:$36,0)) -> 0.72015385 | Z3: =INDEX('面板-景气指数'!$37:$244,MATCH('面板-总览'!$R3,'面板-景气指数'!$A$37:$A$244,0),MATCH('面板-总览'!Z$2,'面板-景气指数'!$36:$36,0)) -> 0.711 | ... AE3: =INDEX('面板-景气指数'!$37:$244,MATCH('面板-总览'!$R3,'面板-景气指数'!$A$37:$A$244,0),MATCH('面板-总览'!AE$2,'面板-景气指数'!$36:$36,0)) -> 0.54723077 | AG3: =AE3-AB3 -> -0.11076923 | AI3: 铜 | AJ3: =INDEX('面板-景气指数'!$37:$244,MATCH('面板-总览'!$AI3,'面板-景气指数'!$A$37:$A$244,0),MATCH('面板-总览'!AJ$2,'面板-景气指数'!$36:$36,0)) -> 0.548 | AK3: =INDEX('面板-景气指数'!$37:$244,MATCH('面板-总览'!$AI3,'面板-景气指数'!$A$37:$A$244,0),MATCH('面板-总览'!AK$2,'面板-景气指数'!$36:$36,0)) -> 0.519 | AL3: =INDEX('面板-景气指数'!$37:$244,MATCH('面板-总览'!$AI3,'面板-景气指数'!$A$37:$A$244,0),MATCH('面板-总览'!AL$2,'面板-景气指数'!$36:$36,0)) -> 0.48 | AM3: =INDEX('面板-景气指数'!$37:$244,MATCH('面板-总览'!$AI3,'面板-景气指数'!$A$37:$A$244,0),MATCH('面板-总览'!AM$2,'面板-景气指数'!$36:$36,0)) -> 0.461 | AN3: =INDEX('面板-景气指数'!$37:$244,MATCH('面板-总览'!$AI3,'面板-景气指数'!$A$37:$A$244,0),MATCH('面板-总览'!AN$2,'面板-景气指数'!$36:$36,0)) -> 0.432 | AO3: =INDEX('面板-景气指数'!$37:$244,MATCH('面板-总览'!$AI3,'面板-景气指数'!$A$37:$A$244,0),MATCH('面板-总览'!AO$2,'面板-景气指数'!$36:$36,0)) -> 0.423 | AP3: =INDEX('面板-景气指数'!$37:$244,MATCH('面板-总览'!$AI3,'面板-景气指数'!$A$37:$A$244,0),MATCH('面板-总览'!AP$2,'面板-景气指数'!$36:$36,0)) -> 0.5 | AQ3: =INDEX('面板-景气指数'!$37:$244,MATCH('面板-总览'!$AI3,'面板-景气指数'!$A$37:$A$244,0),MATCH('面板-总览'!AQ$2,'面板-景气指数'!$36:$36,0)) -> 0.682 | ... AV3: =INDEX('面板-景气指数'!$37:$244,MATCH('面板-总览'!$AI3,'面板-景气指数'!$A$37:$A$244,0),MATCH('面板-总览'!AV$2,'面板-景气指数'!$36:$36,0)) -> 0.538 | AX3: =AV3-AS3 -> -0.231
A4: 煤炭 | B4: =INDEX('面板-景气指数'!$37:$244,MATCH('面板-总览'!$A4,'面板-景气指数'!$A$37:$A$244,0),MATCH('面板-总览'!B$2,'面板-景气指数'!$36:$36,0)) -> 0.6415 | C4: =INDEX('面板-景气指数'!$37:$244,MATCH('面板-总览'!$A4,'面板-景气指数'!$A$37:$A$244,0),MATCH('面板-总览'!C$2,'面板-景气指数'!$36:$36,0)) -> 0.6695 | D4: =INDEX('面板-景气指数'!$37:$244,MATCH('面板-总览'!$A4,'面板-景气指数'!$A$37:$A$244,0),MATCH('面板-总览'!D$2,'面板-景气指数'!$36:$36,0)) -> 0.7005 | E4: =INDEX('面板-景气指数'!$37:$244,MATCH('面板-总览'!$A4,'面板-景气指数'!$A$37:$A$244,0),MATCH('面板-总览'!E$2,'面板-景气指数'!$36:$36,0)) -> 0.72783333 | F4: =INDEX('面板-景气指数'!$37:$244,MATCH('面板-总览'!$A4,'面板-景气指数'!$A$37:$A$244,0),MATCH('面板-总览'!F$2,'面板-景气指数'!$36:$36,0)) -> 0.67166667 | G4: =INDEX('面板-景气指数'!$37:$244,MATCH('面板-总览'!$A4,'面板-景气指数'!$A$37:$A$244,0),MATCH('面板-总览'!G$2,'面板-景气指数'!$36:$36,0)) -> 0.6575 | H4: =INDEX('面板-景气指数'!$37:$244,MATCH('面板-总览'!$A4,'面板-景气指数'!$A$37:$A$244,0),MATCH('面板-总览'!H$2,'面板-景气指数'!$36:$36,0)) -> 0.64333333 | I4: =INDEX('面板-景气指数'!$37:$244,MATCH('面板-总览'!$A4,'面板-景气指数'!$A$37:$A$244,0),MATCH('面板-总览'!I$2,'面板-景气指数'!$36:$36,0)) -> 0.62216667 | ... N4: =INDEX('面板-景气指数'!$37:$244,MATCH('面板-总览'!$A4,'面板-景气指数'!$A$37:$A$244,0),MATCH('面板-总览'!N$2,'面板-景气指数'!$36:$36,0)) -> 0.52933333 | P4: =N4-K4 -> -0.089833333 | R4: 炼化及贸易 | S4: =INDEX('面板-景气指数'!$37:$244,MATCH('面板-总览'!$R4,'面板-景气指数'!$A$37:$A$244,0),MATCH('面板-总览'!S$2,'面板-景气指数'!$36:$36,0)) -> 0.893 | T4: =INDEX('面板-景气指数'!$37:$244,MATCH('面板-总览'!$R4,'面板-景气指数'!$A$37:$A$244,0),MATCH('面板-总览'!T$2,'面板-景气指数'!$36:$36,0)) -> 0.766 | U4: =INDEX('面板-景气指数'!$37:$244,MATCH('面板-总览'!$R4,'面板-景气指数'!$A$37:$A$244,0),MATCH('面板-总览'!U$2,'面板-景气指数'!$36:$36,0)) -> 0.359 | V4: =INDEX('面板-景气指数'!$37:$244,MATCH('面板-总览'!$R4,'面板-景气指数'!$A$37:$A$244,0),MATCH('面板-总览'!V$2,'面板-景气指数'!$36:$36,0)) -> 0.048 | W4: =INDEX('面板-景气指数'!$37:$244,MATCH('面板-总览'!$R4,'面板-景气指数'!$A$37:$A$244,0),MATCH('面板-总览'!W$2,'面板-景气指数'!$36:$36,0)) -> 0.135 | X4: =INDEX('面板-景气指数'!$37:$244,MATCH('面板-总览'!$R4,'面板-景气指数'!$A$37:$A$244,0),MATCH('面板-总览'!X$2,'面板-景气指数'!$36:$36,0)) -> 0.427 | Y4: =INDEX('面板-景气指数'!$37:$244,MATCH('面板-总览'!$R4,'面板-景气指数'!$A$37:$A$244,0),MATCH('面板-总览'!Y$2,'面板-景气指数'!$36:$36,0)) -> 0.456 | Z4: =INDEX('面板-景气指数'!$37:$244,MATCH('面板-总览'!$R4,'面板-景气指数'!$A$37:$A$244,0),MATCH('面板-总览'!Z$2,'面板-景气指数'!$36:$36,0)) -> 0.223 | ... AE4: =INDEX('面板-景气指数'!$37:$244,MATCH('面板-总览'!$R4,'面板-景气指数'!$A$37:$A$244,0),MATCH('面板-总览'!AE$2,'面板-景气指数'!$36:$36,0)) -> 0.64 | AG4: =AE4-AB4 -> 0.107 | AI4: 铝 | AJ4: =INDEX('面板-景气指数'!$37:$244,MATCH('面板-总览'!$AI4,'面板-景气指数'!$A$37:$A$244,0),MATCH('面板-总览'!AJ$2,'面板-景气指数'!$36:$36,0)) -> 0.49 | AK4: =INDEX('面板-景气指数'!$37:$244,MATCH('面板-总览'!$AI4,'面板-景气指数'!$A$37:$A$244,0),MATCH('面板-总览'!AK$2,'面板-景气指数'!$36:$36,0)) -> 0.5 | AL4: =INDEX('面板-景气指数'!$37:$244,MATCH('面板-总览'!$AI4,'面板-景气指数'!$A$37:$A$244,0),MATCH('面板-总览'!AL$2,'面板-景气指数'!$36:$36,0)) -> 0.384 | AM4: =INDEX('面板-景气指数'!$37:$244,MATCH('面板-总览'!$AI4,'面板-景气指数'!$A$37:$A$244,0),MATCH('面板-总览'!AM$2,'面板-景气指数'!$36:$36,0)) -> 0.403 | AN4: =INDEX('面板-景气指数'!$37:$244,MATCH('面板-总览'!$AI4,'面板-景气指数'!$A$37:$A$244,0),MATCH('面板-总览'!AN$2,'面板-景气指数'!$36:$36,0)) -> 0.394 | AO4: =INDEX('面板-景气指数'!$37:$244,MATCH('面板-总览'!$AI4,'面板-景气指数'!$A$37:$A$244,0),MATCH('面板-总览'!AO$2,'面板-景气指数'!$36:$36,0)) -> 0.48 | AP4: =INDEX('面板-景气指数'!$37:$244,MATCH('面板-总览'!$AI4,'面板-景气指数'!$A$37:$A$244,0),MATCH('面板-总览'!AP$2,'面板-景气指数'!$36:$36,0)) -> 0.567 | AQ4: =INDEX('面板-景气指数'!$37:$244,MATCH('面板-总览'!$AI4,'面板-景气指数'!$A$37:$A$244,0),MATCH('面板-总览'!AQ$2,'面板-景气指数'!$36:$36,0)) -> 0.653 | ... AV4: =INDEX('面板-景气指数'!$37:$244,MATCH('面板-总览'!$AI4,'面板-景气指数'!$A$37:$A$244,0),MATCH('面板-总览'!AV$2,'面板-景气指数'!$36:$36,0)) -> 0.423 | AX4: =AV4-AS4 -> -0.259
A5: 有色金属 | B5: =INDEX('面板-景气指数'!$37:$244,MATCH('面板-总览'!$A5,'面板-景气指数'!$A$37:$A$244,0),MATCH('面板-总览'!B$2,'面板-景气指数'!$36:$36,0)) -> 0.54875983 | C5: =INDEX('面板-景气指数'!$37:$244,MATCH('面板-总览'!$A5,'面板-景气指数'!$A$37:$A$244,0),MATCH('面板-总览'!C$2,'面板-景气指数'!$36:$36,0)) -> 0.54575121 | D5: =INDEX('面板-景气指数'!$37:$244,MATCH('面板-总览'!$A5,'面板-景气指数'!$A$37:$A$244,0),MATCH('面板-总览'!D$2,'面板-景气指数'!$36:$36,0)) -> 0.47491315 | E5: =INDEX('面板-景气指数'!$37:$244,MATCH('面板-总览'!$A5,'面板-景气指数'!$A$37:$A$244,0),MATCH('面板-总览'!E$2,'面板-景气指数'!$36:$36,0)) -> 0.44749714 | F5: =INDEX('面板-景气指数'!$37:$244,MATCH('面板-总览'!$A5,'面板-景气指数'!$A$37:$A$244,0),MATCH('面板-总览'!F$2,'面板-景气指数'!$36:$36,0)) -> 0.41348719 | G5: =INDEX('面板-景气指数'!$37:$244,MATCH('面板-总览'!$A5,'面板-景气指数'!$A$37:$A$244,0),MATCH('面板-总览'!G$2,'面板-景气指数'!$36:$36,0)) -> 0.44850184 | H5: =INDEX('面板-景气指数'!$37:$244,MATCH('面板-总览'!$A5,'面板-景气指数'!$A$37:$A$244,0),MATCH('面板-总览'!H$2,'面板-景气指数'!$36:$36,0)) -> 0.5085526 | I5: =INDEX('面板-景气指数'!$37:$244,MATCH('面板-总览'!$A5,'面板-景气指数'!$A$37:$A$244,0),MATCH('面板-总览'!I$2,'面板-景气指数'!$36:$36,0)) -> 0.61090604 | ... N5: =INDEX('面板-景气指数'!$37:$244,MATCH('面板-总览'!$A5,'面板-景气指数'!$A$37:$A$244,0),MATCH('面板-总览'!N$2,'面板-景气指数'!$36:$36,0)) -> 0.60105749 | P5: =N5-K5 -> -0.10885069 | R5: 动力煤 | S5: =INDEX('面板-景气指数'!$37:$244,MATCH('面板-总览'!$R5,'面板-景气指数'!$A$37:$A$244,0),MATCH('面板-总览'!S$2,'面板-景气指数'!$36:$36,0)) -> 0.682 | T5: =INDEX('面板-景气指数'!$37:$244,MATCH('面板-总览'!$R5,'面板-景气指数'!$A$37:$A$244,0),MATCH('面板-总览'!T$2,'面板-景气指数'!$36:$36,0)) -> 0.701 | U5: =INDEX('面板-景气指数'!$37:$244,MATCH('面板-总览'!$R5,'面板-景气指数'!$A$37:$A$244,0),MATCH('面板-总览'!U$2,'面板-景气指数'!$36:$36,0)) -> 0.74 | V5: =INDEX('面板-景气指数'!$37:$244,MATCH('面板-总览'!$R5,'面板-景气指数'!$A$37:$A$244,0),MATCH('面板-总览'!V$2,'面板-景气指数'!$36:$36,0)) -> 0.721 | W5: =INDEX('面板-景气指数'!$37:$244,MATCH('面板-总览'!$R5,'面板-景气指数'!$A$37:$A$244,0),MATCH('面板-总览'!W$2,'面板-景气指数'!$36:$36,0)) -> 0.701 | X5: =INDEX('面板-景气指数'!$37:$244,MATCH('面板-总览'!$R5,'面板-景气指数'!$A$37:$A$244,0),MATCH('面板-总览'!X$2,'面板-景气指数'!$36:$36,0)) -> 0.692 | Y5: =INDEX('面板-景气指数'!$37:$244,MATCH('面板-总览'!$R5,'面板-景气指数'!$A$37:$A$244,0),MATCH('面板-总览'!Y$2,'面板-景气指数'!$36:$36,0)) -> 0.673 | Z5: =INDEX('面板-景气指数'!$37:$244,MATCH('面板-总览'!$R5,'面板-景气指数'!$A$37:$A$244,0),MATCH('面板-总览'!Z$2,'面板-景气指数'!$36:$36,0)) -> 0.634 | ... AE5: =INDEX('面板-景气指数'!$37:$244,MATCH('面板-总览'!$R5,'面板-景气指数'!$A$37:$A$244,0),MATCH('面板-总览'!AE$2,'面板-景气指数'!$36:$36,0)) -> 0.567 | AG5: =AE5-AB5 -> -0.029 | AI5: 铅锌 | AJ5: =INDEX('面板-景气指数'!$37:$244,MATCH('面板-总览'!$AI5,'面板-景气指数'!$A$37:$A$244,0),MATCH('面板-总览'!AJ$2,'面板-景气指数'!$36:$36,0)) -> 0.4615 | AK5: =INDEX('面板-景气指数'!$37:$244,MATCH('面板-总览'!$AI5,'面板-景气指数'!$A$37:$A$244,0),MATCH('面板-总览'!AK$2,'面板-景气指数'!$36:$36,0)) -> 0.5095 | AL5: =INDEX('面板-景气指数'!$37:$244,MATCH('面板-总览'!$AI5,'面板-景气指数'!$A$37:$A$244,0),MATCH('面板-总览'!AL$2,'面板-景气指数'!$36:$36,0)) -> 0.432 | AM5: =INDEX('面板-景气指数'!$37:$244,MATCH('面板-总览'!$AI5,'面板-景气指数'!$A$37:$A$244,0),MATCH('面板-总览'!AM$2,'面板-景气指数'!$36:$36,0)) -> 0.442 | AN5: =INDEX('面板-景气指数'!$37:$244,MATCH('面板-总览'!$AI5,'面板-景气指数'!$A$37:$A$244,0),MATCH('面板-总览'!AN$2,'面板-景气指数'!$36:$36,0)) -> 0.4275 | AO5: =INDEX('面板-景气指数'!$37:$244,MATCH('面板-总览'!$AI5,'面板-景气指数'!$A$37:$A$244,0),MATCH('面板-总览'!AO$2,'面板-景气指数'!$36:$36,0)) -> 0.519 | AP5: =INDEX('面板-景气指数'!$37:$244,MATCH('面板-总览'!$AI5,'面板-景气指数'!$A$37:$A$244,0),MATCH('面板-总览'!AP$2,'面板-景气指数'!$36:$36,0)) -> 0.557 | AQ5: =INDEX('面板-景气指数'!$37:$244,MATCH('面板-总览'!$AI5,'面板-景气指数'!$A$37:$A$244,0),MATCH('面板-总览'!AQ$2,'面板-景气指数'!$36:$36,0)) -> 0.634 | ... AV5: =INDEX('面板-景气指数'!$37:$244,MATCH('面板-总览'!$AI5,'面板-景气指数'!$A$37:$A$244,0),MATCH('面板-总览'!AV$2,'面板-景气指数'!$36:$36,0)) -> 0.634 | AX5: =AV5-AS5 -> -0.1585
A6: 基础化工 | B6: =INDEX('面板-景气指数'!$37:$244,MATCH('面板-总览'!$A6,'面板-景气指数'!$A$37:$A$244,0),MATCH('面板-总览'!B$2,'面板-景气指数'!$36:$36,0)) -> 0.37710011 | C6: =INDEX('面板-景气指数'!$37:$244,MATCH('面板-总览'!$A6,'面板-景气指数'!$A$37:$A$244,0),MATCH('面板-总览'!C$2,'面板-景气指数'!$36:$36,0)) -> 0.37416285 | D6: =INDEX('面板-景气指数'!$37:$244,MATCH('面板-总览'!$A6,'面板-景气指数'!$A$37:$A$244,0),MATCH('面板-总览'!D$2,'面板-景气指数'!$36:$36,0)) -> 0.37532625 | E6: =INDEX('面板-景气指数'!$37:$244,MATCH('面板-总览'!$A6,'面板-景气指数'!$A$37:$A$244,0),MATCH('面板-总览'!E$2,'面板-景气指数'!$36:$36,0)) -> 0.34536085 | F6: =INDEX('面板-景气指数'!$37:$244,MATCH('面板-总览'!$A6,'面板-景气指数'!$A$37:$A$244,0),MATCH('面板-总览'!F$2,'面板-景气指数'!$36:$36,0)) -> 0.32295038 | G6: =INDEX('面板-景气指数'!$37:$244,MATCH('面板-总览'!$A6,'面板-景气指数'!$A$37:$A$244,0),MATCH('面板-总览'!G$2,'面板-景气指数'!$36:$36,0)) -> 0.28960632 | H6: =INDEX('面板-景气指数'!$37:$244,MATCH('面板-总览'!$A6,'面板-景气指数'!$A$37:$A$244,0),MATCH('面板-总览'!H$2,'面板-景气指数'!$36:$36,0)) -> 0.32157047 | I6: =INDEX('面板-景气指数'!$37:$244,MATCH('面板-总览'!$A6,'面板-景气指数'!$A$37:$A$244,0),MATCH('面板-总览'!I$2,'面板-景气指数'!$36:$36,0)) -> 0.37066705 | ... N6: =INDEX('面板-景气指数'!$37:$244,MATCH('面板-总览'!$A6,'面板-景气指数'!$A$37:$A$244,0),MATCH('面板-总览'!N$2,'面板-景气指数'!$36:$36,0)) -> 0.27327124 | P6: =N6-K6 -> -0.11694211 | R6: 焦煤 | S6: =INDEX('面板-景气指数'!$37:$244,MATCH('面板-总览'!$R6,'面板-景气指数'!$A$37:$A$244,0),MATCH('面板-总览'!S$2,'面板-景气指数'!$36:$36,0)) -> 0.673 | T6: =INDEX('面板-景气指数'!$37:$244,MATCH('面板-总览'!$R6,'面板-景气指数'!$A$37:$A$244,0),MATCH('面板-总览'!T$2,'面板-景气指数'!$36:$36,0)) -> 0.73 | U6: =INDEX('面板-景气指数'!$37:$244,MATCH('面板-总览'!$R6,'面板-景气指数'!$A$37:$A$244,0),MATCH('面板-总览'!U$2,'面板-景气指数'!$36:$36,0)) -> 0.759 | V6: =INDEX('面板-景气指数'!$37:$244,MATCH('面板-总览'!$R6,'面板-景气指数'!$A$37:$A$244,0),MATCH('面板-总览'!V$2,'面板-景气指数'!$36:$36,0)) -> 0.788 | W6: =INDEX('面板-景气指数'!$37:$244,MATCH('面板-总览'!$R6,'面板-景气指数'!$A$37:$A$244,0),MATCH('面板-总览'!W$2,'面板-景气指数'!$36:$36,0)) -> 0.798 | X6: =INDEX('面板-景气指数'!$37:$244,MATCH('面板-总览'!$R6,'面板-景气指数'!$A$37:$A$244,0),MATCH('面板-总览'!X$2,'面板-景气指数'!$36:$36,0)) -> 0.778 | Y6: =INDEX('面板-景气指数'!$37:$244,MATCH('面板-总览'!$R6,'面板-景气指数'!$A$37:$A$244,0),MATCH('面板-总览'!Y$2,'面板-景气指数'!$36:$36,0)) -> 0.74 | Z6: =INDEX('面板-景气指数'!$37:$244,MATCH('面板-总览'!$R6,'面板-景气指数'!$A$37:$A$244,0),MATCH('面板-总览'!Z$2,'面板-景气指数'!$36:$36,0)) -> 0.711 | ... AE6: =INDEX('面板-景气指数'!$37:$244,MATCH('面板-总览'!$R6,'面板-景气指数'!$A$37:$A$244,0),MATCH('面板-总览'!AE$2,'面板-景气指数'!$36:$36,0)) -> 0.317 | AG6: =AE6-AB6 -> -0.375 | AI6: 黄金 | AJ6: =INDEX('面板-景气指数'!$37:$244,MATCH('面板-总览'!$AI6,'面板-景气指数'!$A$37:$A$244,0),MATCH('面板-总览'!AJ$2,'面板-景气指数'!$36:$36,0)) -> 0.692 | AK6: =INDEX('面板-景气指数'!$37:$244,MATCH('面板-总览'!$AI6,'面板-景气指数'!$A$37:$A$244,0),MATCH('面板-总览'!AK$2,'面板-景气指数'!$36:$36,0)) -> 0.73 | AL6: =INDEX('面板-景气指数'!$37:$244,MATCH('面板-总览'!$AI6,'面板-景气指数'!$A$37:$A$244,0),MATCH('面板-总览'!AL$2,'面板-景气指数'!$36:$36,0)) -> 0.721 | AM6: =INDEX('面板-景气指数'!$37:$244,MATCH('面板-总览'!$AI6,'面板-景气指数'!$A$37:$A$244,0),MATCH('面板-总览'!AM$2,'面板-景气指数'!$36:$36,0)) -> 0.663 | AN6: =INDEX('面板-景气指数'!$37:$244,MATCH('面板-总览'!$AI6,'面板-景气指数'!$A$37:$A$244,0),MATCH('面板-总览'!AN$2,'面板-景气指数'!$36:$36,0)) -> 0.605 | AO6: =INDEX('面板-景气指数'!$37:$244,MATCH('面板-总览'!$AI6,'面板-景气指数'!$A$37:$A$244,0),MATCH('面板-总览'!AO$2,'面板-景气指数'!$36:$36,0)) -> 0.615 | AP6: =INDEX('面板-景气指数'!$37:$244,MATCH('面板-总览'!$AI6,'面板-景气指数'!$A$37:$A$244,0),MATCH('面板-总览'!AP$2,'面板-景气指数'!$36:$36,0)) -> 0.682 | AQ6: =INDEX('面板-景气指数'!$37:$244,MATCH('面板-总览'!$AI6,'面板-景气指数'!$A$37:$A$244,0),MATCH('面板-总览'!AQ$2,'面板-景气指数'!$36:$36,0)) -> 0.759 | ... AV6: =INDEX('面板-景气指数'!$37:$244,MATCH('面板-总览'!$AI6,'面板-景气指数'!$A$37:$A$244,0),MATCH('面板-总览'!AV$2,'面板-景气指数'!$36:$36,0)) -> 0.99 | AX6: =AV6-AS6 -> 0.164
A7: 钢铁 | B7: =INDEX('面板-景气指数'!$37:$244,MATCH('面板-总览'!$A7,'面板-景气指数'!$A$37:$A$244,0),MATCH('面板-总览'!B$2,'面板-景气指数'!$36:$36,0)) -> 0.37704824 | C7: =INDEX('面板-景气指数'!$37:$244,MATCH('面板-总览'!$A7,'面板-景气指数'!$A$37:$A$244,0),MATCH('面板-总览'!C$2,'面板-景气指数'!$36:$36,0)) -> 0.38678485 | D7: =INDEX('面板-景气指数'!$37:$244,MATCH('面板-总览'!$A7,'面板-景气指数'!$A$37:$A$244,0),MATCH('面板-总览'!D$2,'面板-景气指数'!$36:$36,0)) -> 0.39858746 | E7: =INDEX('面板-景气指数'!$37:$244,MATCH('面板-总览'!$A7,'面板-景气指数'!$A$37:$A$244,0),MATCH('面板-总览'!E$2,'面板-景气指数'!$36:$36,0)) -> 0.37331075 | F7: =INDEX('面板-景气指数'!$37:$244,MATCH('面板-总览'!$A7,'面板-景气指数'!$A$37:$A$244,0),MATCH('面板-总览'!F$2,'面板-景气指数'!$36:$36,0)) -> 0.32578492 | G7: =INDEX('面板-景气指数'!$37:$244,MATCH('面板-总览'!$A7,'面板-景气指数'!$A$37:$A$244,0),MATCH('面板-总览'!G$2,'面板-景气指数'!$36:$36,0)) -> 0.26191319 | H7: =INDEX('面板-景气指数'!$37:$244,MATCH('面板-总览'!$A7,'面板-景气指数'!$A$37:$A$244,0),MATCH('面板-总览'!H$2,'面板-景气指数'!$36:$36,0)) -> 0.24570715 | I7: =INDEX('面板-景气指数'!$37:$244,MATCH('面板-总览'!$A7,'面板-景气指数'!$A$37:$A$244,0),MATCH('面板-总览'!I$2,'面板-景气指数'!$36:$36,0)) -> 0.28660648 | ... N7: =INDEX('面板-景气指数'!$37:$244,MATCH('面板-总览'!$A7,'面板-景气指数'!$A$37:$A$244,0),MATCH('面板-总览'!N$2,'面板-景气指数'!$36:$36,0)) -> 0.16136377 | P7: =N7-K7 -> -0.13929227 | R7: 无烟煤 | S7: =INDEX('面板-景气指数'!$37:$244,MATCH('面板-总览'!$R7,'面板-景气指数'!$A$37:$A$244,0),MATCH('面板-总览'!S$2,'面板-景气指数'!$36:$36,0)) -> 0.73 | T7: =INDEX('面板-景气指数'!$37:$244,MATCH('面板-总览'!$R7,'面板-景气指数'!$A$37:$A$244,0),MATCH('面板-总览'!T$2,'面板-景气指数'!$36:$36,0)) -> 0.769 | U7: =INDEX('面板-景气指数'!$37:$244,MATCH('面板-总览'!$R7,'面板-景气指数'!$A$37:$A$244,0),MATCH('面板-总览'!U$2,'面板-景气指数'!$36:$36,0)) -> 0.778 | V7: =INDEX('面板-景气指数'!$37:$244,MATCH('面板-总览'!$R7,'面板-景气指数'!$A$37:$A$244,0),MATCH('面板-总览'!V$2,'面板-景气指数'!$36:$36,0)) -> 0.663 | W7: =INDEX('面板-景气指数'!$37:$244,MATCH('面板-总览'!$R7,'面板-景气指数'!$A$37:$A$244,0),MATCH('面板-总览'!W$2,'面板-景气指数'!$36:$36,0)) -> 0.653 | X7: =INDEX('面板-景气指数'!$37:$244,MATCH('面板-总览'!$R7,'面板-景气指数'!$A$37:$A$244,0),MATCH('面板-总览'!X$2,'面板-景气指数'!$36:$36,0)) -> 0.615 | Y7: =INDEX('面板-景气指数'!$37:$244,MATCH('面板-总览'!$R7,'面板-景气指数'!$A$37:$A$244,0),MATCH('面板-总览'!Y$2,'面板-景气指数'!$36:$36,0)) -> 0.625 | Z7: =INDEX('面板-景气指数'!$37:$244,MATCH('面板-总览'!$R7,'面板-景气指数'!$A$37:$A$244,0),MATCH('面板-总览'!Z$2,'面板-景气指数'!$36:$36,0)) -> 0.644 | ... AE7: =INDEX('面板-景气指数'!$37:$244,MATCH('面板-总览'!$R7,'面板-景气指数'!$A$37:$A$244,0),MATCH('面板-总览'!AE$2,'面板-景气指数'!$36:$36,0)) -> 0.682 | AG7: =AE7-AB7 -> -0.077 | AI7: 白银 | AJ7: =INDEX('面板-景气指数'!$37:$244,MATCH('面板-总览'!$AI7,'面板-景气指数'!$A$37:$A$244,0),MATCH('面板-总览'!AJ$2,'面板-景气指数'!$36:$36,0)) -> 0.759 | AK7: =INDEX('面板-景气指数'!$37:$244,MATCH('面板-总览'!$AI7,'面板-景气指数'!$A$37:$A$244,0),MATCH('面板-总览'!AK$2,'面板-景气指数'!$36:$36,0)) -> 0.692 | AL7: =INDEX('面板-景气指数'!$37:$244,MATCH('面板-总览'!$AI7,'面板-景气指数'!$A$37:$A$244,0),MATCH('面板-总览'!AL$2,'面板-景气指数'!$36:$36,0)) -> 0.596 | AM7: =INDEX('面板-景气指数'!$37:$244,MATCH('面板-总览'!$AI7,'面板-景气指数'!$A$37:$A$244,0),MATCH('面板-总览'!AM$2,'面板-景气指数'!$36:$36,0)) -> 0.519 | AN7: =INDEX('面板-景气指数'!$37:$244,MATCH('面板-总览'!$AI7,'面板-景气指数'!$A$37:$A$244,0),MATCH('面板-总览'!AN$2,'面板-景气指数'!$36:$36,0)) -> 0.48 | AO7: =INDEX('面板-景气指数'!$37:$244,MATCH('面板-总览'!$AI7,'面板-景气指数'!$A$37:$A$244,0),MATCH('面板-总览'!AO$2,'面板-景气指数'!$36:$36,0)) -> 0.528 | AP7: =INDEX('面板-景气指数'!$37:$244,MATCH('面板-总览'!$AI7,'面板-景气指数'!$A$37:$A$244,0),MATCH('面板-总览'!AP$2,'面板-景气指数'!$36:$36,0)) -> 0.576 | AQ7: =INDEX('面板-景气指数'!$37:$244,MATCH('面板-总览'!$AI7,'面板-景气指数'!$A$37:$A$244,0),MATCH('面板-总览'!AQ$2,'面板-景气指数'!$36:$36,0)) -> 0.615 | ... AV7: =INDEX('面板-景气指数'!$37:$244,MATCH('面板-总览'!$AI7,'面板-景气指数'!$A$37:$A$244,0),MATCH('面板-总览'!AV$2,'面板-景气指数'!$36:$36,0)) -> 0.875 | AX7: =AV7-AS7 -> 0.058
A8: 建筑材料 | B8: =INDEX('面板-景气指数'!$37:$244,MATCH('面板-总览'!$A8,'面板-景气指数'!$A$37:$A$244,0),MATCH('面板-总览'!B$2,'面板-景气指数'!$36:$36,0)) -> 0.25350935 | C8: =INDEX('面板-景气指数'!$37:$244,MATCH('面板-总览'!$A8,'面板-景气指数'!$A$37:$A$244,0),MATCH('面板-总览'!C$2,'面板-景气指数'!$36:$36,0)) -> 0.26314281 | D8: =INDEX('面板-景气指数'!$37:$244,MATCH('面板-总览'!$A8,'面板-景气指数'!$A$37:$A$244,0),MATCH('面板-总览'!D$2,'面板-景气指数'!$36:$36,0)) -> 0.29998686 | E8: =INDEX('面板-景气指数'!$37:$244,MATCH('面板-总览'!$A8,'面板-景气指数'!$A$37:$A$244,0),MATCH('面板-总览'!E$2,'面板-景气指数'!$36:$36,0)) -> 0.32513939 | F8: =INDEX('面板-景气指数'!$37:$244,MATCH('面板-总览'!$A8,'面板-景气指数'!$A$37:$A$244,0),MATCH('面板-总览'!F$2,'面板-景气指数'!$36:$36,0)) -> 0.32065609 | G8: =INDEX('面板-景气指数'!$37:$244,MATCH('面板-总览'!$A8,'面板-景气指数'!$A$37:$A$244,0),MATCH('面板-总览'!G$2,'面板-景气指数'!$36:$36,0)) -> 0.28661189 | H8: =INDEX('面板-景气指数'!$37:$244,MATCH('面板-总览'!$A8,'面板-景气指数'!$A$37:$A$244,0),MATCH('面板-总览'!H$2,'面板-景气指数'!$36:$36,0)) -> 0.25047061 | I8: =INDEX('面板-景气指数'!$37:$244,MATCH('面板-总览'!$A8,'面板-景气指数'!$A$37:$A$244,0),MATCH('面板-总览'!I$2,'面板-景气指数'!$36:$36,0)) -> 0.2737038 | ... N8: =INDEX('面板-景气指数'!$37:$244,MATCH('面板-总览'!$A8,'面板-景气指数'!$A$37:$A$244,0),MATCH('面板-总览'!N$2,'面板-景气指数'!$36:$36,0)) -> 0.39886622 | P8: =N8-K8 -> -0.033456104 | R8: 工业金属 | S8: =INDEX('面板-景气指数'!$37:$244,MATCH('面板-总览'!$R8,'面板-景气指数'!$A$37:$A$244,0),MATCH('面板-总览'!S$2,'面板-景气指数'!$36:$36,0)) -> 0.49711191 | T8: =INDEX('面板-景气指数'!$37:$244,MATCH('面板-总览'!$R8,'面板-景气指数'!$A$37:$A$244,0),MATCH('面板-总览'!T$2,'面板-景气指数'!$36:$36,0)) -> 0.51173467 | U8: =INDEX('面板-景气指数'!$37:$244,MATCH('面板-总览'!$R8,'面板-景气指数'!$A$37:$A$244,0),MATCH('面板-总览'!U$2,'面板-景气指数'!$36:$36,0)) -> 0.44329097 | V8: =INDEX('面板-景气指数'!$37:$244,MATCH('面板-总览'!$R8,'面板-景气指数'!$A$37:$A$244,0),MATCH('面板-总览'!V$2,'面板-景气指数'!$36:$36,0)) -> 0.44381462 | W8: =INDEX('面板-景气指数'!$37:$244,MATCH('面板-总览'!$R8,'面板-景气指数'!$A$37:$A$244,0),MATCH('面板-总览'!W$2,'面板-景气指数'!$36:$36,0)) -> 0.42470918 | X8: =INDEX('面板-景气指数'!$37:$244,MATCH('面板-总览'!$R8,'面板-景气指数'!$A$37:$A$244,0),MATCH('面板-总览'!X$2,'面板-景气指数'!$36:$36,0)) -> 0.4784987 | Y8: =INDEX('面板-景气指数'!$37:$244,MATCH('面板-总览'!$R8,'面板-景气指数'!$A$37:$A$244,0),MATCH('面板-总览'!Y$2,'面板-景气指数'!$36:$36,0)) -> 0.53735338 | Z8: =INDEX('面板-景气指数'!$37:$244,MATCH('面板-总览'!$R8,'面板-景气指数'!$A$37:$A$244,0),MATCH('面板-总览'!Z$2,'面板-景气指数'!$36:$36,0)) -> 0.65418428 | ... AE8: =INDEX('面板-景气指数'!$37:$244,MATCH('面板-总览'!$R8,'面板-景气指数'!$A$37:$A$244,0),MATCH('面板-总览'!AE$2,'面板-景气指数'!$36:$36,0)) -> 0.5706681 | AG8: =AE8-AB8 -> -0.1985174 | AI8: 稀土 | AJ8: =INDEX('面板-景气指数'!$37:$244,MATCH('面板-总览'!$AI8,'面板-景气指数'!$A$37:$A$244,0),MATCH('面板-总览'!AJ$2,'面板-景气指数'!$36:$36,0)) -> 0.75 | AK8: =INDEX('面板-景气指数'!$37:$244,MATCH('面板-总览'!$AI8,'面板-景气指数'!$A$37:$A$244,0),MATCH('面板-总览'!AK$2,'面板-景气指数'!$36:$36,0)) -> 0.769 | AL8: =INDEX('面板-景气指数'!$37:$244,MATCH('面板-总览'!$AI8,'面板-景气指数'!$A$37:$A$244,0),MATCH('面板-总览'!AL$2,'面板-景气指数'!$36:$36,0)) -> 0.74 | AM8: =INDEX('面板-景气指数'!$37:$244,MATCH('面板-总览'!$AI8,'面板-景气指数'!$A$37:$A$244,0),MATCH('面板-总览'!AM$2,'面板-景气指数'!$36:$36,0)) -> 0.673 | AN8: =INDEX('面板-景气指数'!$37:$244,MATCH('面板-总览'!$AI8,'面板-景气指数'!$A$37:$A$244,0),MATCH('面板-总览'!AN$2,'面板-景气指数'!$36:$36,0)) -> 0.653 | AO8: =INDEX('面板-景气指数'!$37:$244,MATCH('面板-总览'!$AI8,'面板-景气指数'!$A$37:$A$244,0),MATCH('面板-总览'!AO$2,'面板-景气指数'!$36:$36,0)) -> 0.586 | AP8: =INDEX('面板-景气指数'!$37:$244,MATCH('面板-总览'!$AI8,'面板-景气指数'!$A$37:$A$244,0),MATCH('面板-总览'!AP$2,'面板-景气指数'!$36:$36,0)) -> 0.548 | AQ8: =INDEX('面板-景气指数'!$37:$244,MATCH('面板-总览'!$AI8,'面板-景气指数'!$A$37:$A$244,0),MATCH('面板-总览'!AQ$2,'面板-景气指数'!$36:$36,0)) -> 0.596 | ... AV8: =INDEX('面板-景气指数'!$37:$244,MATCH('面板-总览'!$AI8,'面板-景气指数'!$A$37:$A$244,0),MATCH('面板-总览'!AV$2,'面板-景气指数'!$36:$36,0)) -> 0.615 | AX8: =AV8-AS8 -> 0.048
A9: 机械设备 | B9: =INDEX('面板-景气指数'!$37:$244,MATCH('面板-总览'!$A9,'面板-景气指数'!$A$37:$A$244,0),MATCH('面板-总览'!B$2,'面板-景气指数'!$36:$36,0)) -> 0.36061112 | C9: =INDEX('面板-景气指数'!$37:$244,MATCH('面板-总览'!$A9,'面板-景气指数'!$A$37:$A$244,0),MATCH('面板-总览'!C$2,'面板-景气指数'!$36:$36,0)) -> 0.43480873 | D9: =INDEX('面板-景气指数'!$37:$244,MATCH('面板-总览'!$A9,'面板-景气指数'!$A$37:$A$244,0),MATCH('面板-总览'!D$2,'面板-景气指数'!$36:$36,0)) -> 0.50520542 | E9: =INDEX('面板-景气指数'!$37:$244,MATCH('面板-总览'!$A9,'面板-景气指数'!$A$37:$A$244,0),MATCH('面板-总览'!E$2,'面板-景气指数'!$36:$36,0)) -> 0.53714328 | F9: =INDEX('面板-景气指数'!$37:$244,MATCH('面板-总览'!$A9,'面板-景气指数'!$A$37:$A$244,0),MATCH('面板-总览'!F$2,'面板-景气指数'!$36:$36,0)) -> 0.48888551 | G9: =INDEX('面板-景气指数'!$37:$244,MATCH('面板-总览'!$A9,'面板-景气指数'!$A$37:$A$244,0),MATCH('面板-总览'!G$2,'面板-景气指数'!$36:$36,0)) -> 0.35140682 | H9: =INDEX('面板-景气指数'!$37:$244,MATCH('面板-总览'!$A9,'面板-景气指数'!$A$37:$A$244,0),MATCH('面板-总览'!H$2,'面板-景气指数'!$36:$36,0)) -> 0.3892641 | I9: =INDEX('面板-景气指数'!$37:$244,MATCH('面板-总览'!$A9,'面板-景气指数'!$A$37:$A$244,0),MATCH('面板-总览'!I$2,'面板-景气指数'!$36:$36,0)) -> 0.41475806 | ... N9: =INDEX('面板-景气指数'!$37:$244,MATCH('面板-总览'!$A9,'面板-景气指数'!$A$37:$A$244,0),MATCH('面板-总览'!N$2,'面板-景气指数'!$36:$36,0)) -> 0.62291137 | P9: =N9-K9 -> 0.070019951 | R9: 贵金属 | S9: =INDEX('面板-景气指数'!$37:$244,MATCH('面板-总览'!$R9,'面板-景气指数'!$A$37:$A$244,0),MATCH('面板-总览'!S$2,'面板-景气指数'!$36:$36,0)) -> 0.7255 | T9: =INDEX('面板-景气指数'!$37:$244,MATCH('面板-总览'!$R9,'面板-景气指数'!$A$37:$A$244,0),MATCH('面板-总览'!T$2,'面板-景气指数'!$36:$36,0)) -> 0.711 | U9: =INDEX('面板-景气指数'!$37:$244,MATCH('面板-总览'!$R9,'面板-景气指数'!$A$37:$A$244,0),MATCH('面板-总览'!U$2,'面板-景气指数'!$36:$36,0)) -> 0.6585 | V9: =INDEX('面板-景气指数'!$37:$244,MATCH('面板-总览'!$R9,'面板-景气指数'!$A$37:$A$244,0),MATCH('面板-总览'!V$2,'面板-景气指数'!$36:$36,0)) -> 0.591 | W9: =INDEX('面板-景气指数'!$37:$244,MATCH('面板-总览'!$R9,'面板-景气指数'!$A$37:$A$244,0),MATCH('面板-总览'!W$2,'面板-景气指数'!$36:$36,0)) -> 0.5425 | X9: =INDEX('面板-景气指数'!$37:$244,MATCH('面板-总览'!$R9,'面板-景气指数'!$A$37:$A$244,0),MATCH('面板-总览'!X$2,'面板-景气指数'!$36:$36,0)) -> 0.5715 | Y9: =INDEX('面板-景气指数'!$37:$244,MATCH('面板-总览'!$R9,'面板-景气指数'!$A$37:$A$244,0),MATCH('面板-总览'!Y$2,'面板-景气指数'!$36:$36,0)) -> 0.629 | Z9: =INDEX('面板-景气指数'!$37:$244,MATCH('面板-总览'!$R9,'面板-景气指数'!$A$37:$A$244,0),MATCH('面板-总览'!Z$2,'面板-景气指数'!$36:$36,0)) -> 0.687 | ... AE9: =INDEX('面板-景气指数'!$37:$244,MATCH('面板-总览'!$R9,'面板-景气指数'!$A$37:$A$244,0),MATCH('面板-总览'!AE$2,'面板-景气指数'!$36:$36,0)) -> 0.9325 | AG9: =AE9-AB9 -> 0.111 | AI9: 钨 | AJ9: =INDEX('面板-景气指数'!$37:$244,MATCH('面板-总览'!$AI9,'面板-景气指数'!$A$37:$A$244,0),MATCH('面板-总览'!AJ$2,'面板-景气指数'!$36:$36,0)) -> 0.48 | AK9: =INDEX('面板-景气指数'!$37:$244,MATCH('面板-总览'!$AI9,'面板-景气指数'!$A$37:$A$244,0),MATCH('面板-总览'!AK$2,'面板-景气指数'!$36:$36,0)) -> 0.519 | AL9: =INDEX('面板-景气指数'!$37:$244,MATCH('面板-总览'!$AI9,'面板-景气指数'!$A$37:$A$244,0),MATCH('面板-总览'!AL$2,'面板-景气指数'!$36:$36,0)) -> 0.576 | AM9: =INDEX('面板-景气指数'!$37:$244,MATCH('面板-总览'!$AI9,'面板-景气指数'!$A$37:$A$244,0),MATCH('面板-总览'!AM$2,'面板-景气指数'!$36:$36,0)) -> 0.528 | AN9: =INDEX('面板-景气指数'!$37:$244,MATCH('面板-总览'!$AI9,'面板-景气指数'!$A$37:$A$244,0),MATCH('面板-总览'!AN$2,'面板-景气指数'!$36:$36,0)) -> 0.451 | AO9: =INDEX('面板-景气指数'!$37:$244,MATCH('面板-总览'!$AI9,'面板-景气指数'!$A$37:$A$244,0),MATCH('面板-总览'!AO$2,'面板-景气指数'!$36:$36,0)) -> 0.432 | AP9: =INDEX('面板-景气指数'!$37:$244,MATCH('面板-总览'!$AI9,'面板-景气指数'!$A$37:$A$244,0),MATCH('面板-总览'!AP$2,'面板-景气指数'!$36:$36,0)) -> 0.538 | AQ9: =INDEX('面板-景气指数'!$37:$244,MATCH('面板-总览'!$AI9,'面板-景气指数'!$A$37:$A$244,0),MATCH('面板-总览'!AQ$2,'面板-景气指数'!$36:$36,0)) -> 0.673 | ... AV9: =INDEX('面板-景气指数'!$37:$244,MATCH('面板-总览'!$AI9,'面板-景气指数'!$A$37:$A$244,0),MATCH('面板-总览'!AV$2,'面板-景气指数'!$36:$36,0)) -> 0.625 | AX9: =AV9-AS9 -> -0.115
A10: 电力设备 | B10: =INDEX('面板-景气指数'!$37:$244,MATCH('面板-总览'!$A10,'面板-景气指数'!$A$37:$A$244,0),MATCH('面板-总览'!B$2,'面板-景气指数'!$36:$36,0)) -> 0.45139438 | C10: =INDEX('面板-景气指数'!$37:$244,MATCH('面板-总览'!$A10,'面板-景气指数'!$A$37:$A$244,0),MATCH('面板-总览'!C$2,'面板-景气指数'!$36:$36,0)) -> 0.46906961 | D10: =INDEX('面板-景气指数'!$37:$244,MATCH('面板-总览'!$A10,'面板-景气指数'!$A$37:$A$244,0),MATCH('面板-总览'!D$2,'面板-景气指数'!$36:$36,0)) -> 0.49384103 | E10: =INDEX('面板-景气指数'!$37:$244,MATCH('面板-总览'!$A10,'面板-景气指数'!$A$37:$A$244,0),MATCH('面板-总览'!E$2,'面板-景气指数'!$36:$36,0)) -> 0.50740977 | F10: =INDEX('面板-景气指数'!$37:$244,MATCH('面板-总览'!$A10,'面板-景气指数'!$A$37:$A$244,0),MATCH('面板-总览'!F$2,'面板-景气指数'!$36:$36,0)) -> 0.49636199 | G10: =INDEX('面板-景气指数'!$37:$244,MATCH('面板-总览'!$A10,'面板-景气指数'!$A$37:$A$244,0),MATCH('面板-总览'!G$2,'面板-景气指数'!$36:$36,0)) -> 0.47957166 | H10: =INDEX('面板-景气指数'!$37:$244,MATCH('面板-总览'!$A10,'面板-景气指数'!$A$37:$A$244,0),MATCH('面板-总览'!H$2,'面板-景气指数'!$36:$36,0)) -> 0.48177898 | I10: =INDEX('面板-景气指数'!$37:$244,MATCH('面板-总览'!$A10,'面板-景气指数'!$A$37:$A$244,0),MATCH('面板-总览'!I$2,'面板-景气指数'!$36:$36,0)) -> 0.44575454 | ... N10: =INDEX('面板-景气指数'!$37:$244,MATCH('面板-总览'!$A10,'面板-景气指数'!$A$37:$A$244,0),MATCH('面板-总览'!N$2,'面板-景气指数'!$36:$36,0)) -> 0.45877097 | P10: =N10-K10 -> 0.016641076 | R10: 小金属 | S10: =INDEX('面板-景气指数'!$37:$244,MATCH('面板-总览'!$R10,'面板-景气指数'!$A$37:$A$244,0),MATCH('面板-总览'!S$2,'面板-景气指数'!$36:$36,0)) -> 0.66775 | T10: =INDEX('面板-景气指数'!$37:$244,MATCH('面板-总览'!$R10,'面板-景气指数'!$A$37:$A$244,0),MATCH('面板-总览'!T$2,'面板-景气指数'!$36:$36,0)) -> 0.63425 | U10: =INDEX('面板-景气指数'!$37:$244,MATCH('面板-总览'!$R10,'面板-景气指数'!$A$37:$A$244,0),MATCH('面板-总览'!U$2,'面板-景气指数'!$36:$36,0)) -> 0.5405 | V10: =INDEX('面板-景气指数'!$37:$244,MATCH('面板-总览'!$R10,'面板-景气指数'!$A$37:$A$244,0),MATCH('面板-总览'!V$2,'面板-景气指数'!$36:$36,0)) -> 0.45875 | W10: =INDEX('面板-景气指数'!$37:$244,MATCH('面板-总览'!$R10,'面板-景气指数'!$A$37:$A$244,0),MATCH('面板-总览'!W$2,'面板-景气指数'!$36:$36,0)) -> 0.384 | X10: =INDEX('面板-景气指数'!$37:$244,MATCH('面板-总览'!$R10,'面板-景气指数'!$A$37:$A$244,0),MATCH('面板-总览'!X$2,'面板-景气指数'!$36:$36,0)) -> 0.37425 | Y10: =INDEX('面板-景气指数'!$37:$244,MATCH('面板-总览'!$R10,'面板-景气指数'!$A$37:$A$244,0),MATCH('面板-总览'!Y$2,'面板-景气指数'!$36:$36,0)) -> 0.45175 | Z10: =INDEX('面板-景气指数'!$37:$244,MATCH('面板-总览'!$R10,'面板-景气指数'!$A$37:$A$244,0),MATCH('面板-总览'!Z$2,'面板-景气指数'!$36:$36,0)) -> 0.57175 | ... AE10: =INDEX('面板-景气指数'!$37:$244,MATCH('面板-总览'!$R10,'面板-景气指数'!$A$37:$A$244,0),MATCH('面板-总览'!AE$2,'面板-景气指数'!$36:$36,0)) -> 0.507 | AG10: =AE10-AB10 -> -0.091 | AI10: 钼 | AJ10: =INDEX('面板-景气指数'!$37:$244,MATCH('面板-总览'!$AI10,'面板-景气指数'!$A$37:$A$244,0),MATCH('面板-总览'!AJ$2,'面板-景气指数'!$36:$36,0)) -> 0.778 | AK10: =INDEX('面板-景气指数'!$37:$244,MATCH('面板-总览'!$AI10,'面板-景气指数'!$A$37:$A$244,0),MATCH('面板-总览'!AK$2,'面板-景气指数'!$36:$36,0)) -> 0.576 | AL10: =INDEX('面板-景气指数'!$37:$244,MATCH('面板-总览'!$AI10,'面板-景气指数'!$A$37:$A$244,0),MATCH('面板-总览'!AL$2,'面板-景气指数'!$36:$36,0)) -> 0.221 | AM10: =INDEX('面板-景气指数'!$37:$244,MATCH('面板-总览'!$AI10,'面板-景气指数'!$A$37:$A$244,0),MATCH('面板-总览'!AM$2,'面板-景气指数'!$36:$36,0)) -> 0.096 | AN10: =INDEX('面板-景气指数'!$37:$244,MATCH('面板-总览'!$AI10,'面板-景气指数'!$A$37:$A$244,0),MATCH('面板-总览'!AN$2,'面板-景气指数'!$36:$36,0)) -> 0.038 | AO10: =INDEX('面板-景气指数'!$37:$244,MATCH('面板-总览'!$AI10,'面板-景气指数'!$A$37:$A$244,0),MATCH('面板-总览'!AO$2,'面板-景气指数'!$36:$36,0)) -> 0.028 | AP10: =INDEX('面板-景气指数'!$37:$244,MATCH('面板-总览'!$AI10,'面板-景气指数'!$A$37:$A$244,0),MATCH('面板-总览'!AP$2,'面板-景气指数'!$36:$36,0)) -> 0.125 | AQ10: =INDEX('面板-景气指数'!$37:$244,MATCH('面板-总览'!$AI10,'面板-景气指数'!$A$37:$A$244,0),MATCH('面板-总览'!AQ$2,'面板-景气指数'!$36:$36,0)) -> 0.317 | ... AV10: =INDEX('面板-景气指数'!$37:$244,MATCH('面板-总览'!$AI10,'面板-景气指数'!$A$37:$A$244,0),MATCH('面板-总览'!AV$2,'面板-景气指数'!$36:$36,0)) -> 0.144 | AX10: =AV10-AS10 -> -0.182
A11: 国防军工 | B11: =INDEX('面板-景气指数'!$37:$244,MATCH('面板-总览'!$A11,'面板-景气指数'!$A$37:$A$244,0),MATCH('面板-总览'!B$2,'面板-景气指数'!$36:$36,0)) -> 0.27027071 | C11: =INDEX('面板-景气指数'!$37:$244,MATCH('面板-总览'!$A11,'面板-景气指数'!$A$37:$A$244,0),MATCH('面板-总览'!C$2,'面板-景气指数'!$36:$36,0)) -> 0.27291822 | D11: =INDEX('面板-景气指数'!$37:$244,MATCH('面板-总览'!$A11,'面板-景气指数'!$A$37:$A$244,0),MATCH('面板-总览'!D$2,'面板-景气指数'!$36:$36,0)) -> 0.27936614 | E11: =INDEX('面板-景气指数'!$37:$244,MATCH('面板-总览'!$A11,'面板-景气指数'!$A$37:$A$244,0),MATCH('面板-总览'!E$2,'面板-景气指数'!$36:$36,0)) -> 0.30122389 | F11: =INDEX('面板-景气指数'!$37:$244,MATCH('面板-总览'!$A11,'面板-景气指数'!$A$37:$A$244,0),MATCH('面板-总览'!F$2,'面板-景气指数'!$36:$36,0)) -> 0.32360826 | G11: =INDEX('面板-景气指数'!$37:$244,MATCH('面板-总览'!$A11,'面板-景气指数'!$A$37:$A$244,0),MATCH('面板-总览'!G$2,'面板-景气指数'!$36:$36,0)) -> 0.35693495 | H11: =INDEX('面板-景气指数'!$37:$244,MATCH('面板-总览'!$A11,'面板-景气指数'!$A$37:$A$244,0),MATCH('面板-总览'!H$2,'面板-景气指数'!$36:$36,0)) -> 0.37055023 | I11: =INDEX('面板-景气指数'!$37:$244,MATCH('面板-总览'!$A11,'面板-景气指数'!$A$37:$A$244,0),MATCH('面板-总览'!I$2,'面板-景气指数'!$36:$36,0)) -> 0.42115442 | ... N11: =INDEX('面板-景气指数'!$37:$244,MATCH('面板-总览'!$A11,'面板-景气指数'!$A$37:$A$244,0),MATCH('面板-总览'!N$2,'面板-景气指数'!$36:$36,0)) -> 0.46612586 | P11: =N11-K11 -> 0.015896855 | R11: 能源金属 | S11: =INDEX('面板-景气指数'!$37:$244,MATCH('面板-总览'!$R11,'面板-景气指数'!$A$37:$A$244,0),MATCH('面板-总览'!S$2,'面板-景气指数'!$36:$36,0)) -> 0.185 | T11: =INDEX('面板-景气指数'!$37:$244,MATCH('面板-总览'!$R11,'面板-景气指数'!$A$37:$A$244,0),MATCH('面板-总览'!T$2,'面板-景气指数'!$36:$36,0)) -> 0.14366667 | U11: =INDEX('面板-景气指数'!$37:$244,MATCH('面板-总览'!$R11,'面板-景气指数'!$A$37:$A$244,0),MATCH('面板-总览'!U$2,'面板-景气指数'!$36:$36,0)) -> 0.11266667 | V11: =INDEX('面板-景气指数'!$37:$244,MATCH('面板-总览'!$R11,'面板-景气指数'!$A$37:$A$244,0),MATCH('面板-总览'!V$2,'面板-景气指数'!$36:$36,0)) -> 0.11366667 | W11: =INDEX('面板-景气指数'!$37:$244,MATCH('面板-总览'!$R11,'面板-景气指数'!$A$37:$A$244,0),MATCH('面板-总览'!W$2,'面板-景气指数'!$36:$36,0)) -> 0.13 | X11: =INDEX('面板-景气指数'!$37:$244,MATCH('面板-总览'!$R11,'面板-景气指数'!$A$37:$A$244,0),MATCH('面板-总览'!X$2,'面板-景气指数'!$36:$36,0)) -> 0.14966667 | Y11: =INDEX('面板-景气指数'!$37:$244,MATCH('面板-总览'!$R11,'面板-景气指数'!$A$37:$A$244,0),MATCH('面板-总览'!Y$2,'面板-景气指数'!$36:$36,0)) -> 0.20133333 | Z11: =INDEX('面板-景气指数'!$37:$244,MATCH('面板-总览'!$R11,'面板-景气指数'!$A$37:$A$244,0),MATCH('面板-总览'!Z$2,'面板-景气指数'!$36:$36,0)) -> 0.234 | ... AE11: =INDEX('面板-景气指数'!$37:$244,MATCH('面板-总览'!$R11,'面板-景气指数'!$A$37:$A$244,0),MATCH('面板-总览'!AE$2,'面板-景气指数'!$36:$36,0)) -> 0.24266667 | AG11: =AE11-AB11 -> 0.005 | AI11: 其它小金属 | AJ11: =INDEX('面板-景气指数'!$37:$244,MATCH('面板-总览'!$AI11,'面板-景气指数'!$A$37:$A$244,0),MATCH('面板-总览'!AJ$2,'面板-景气指数'!$36:$36,0)) -> 0.663 | AK11: =INDEX('面板-景气指数'!$37:$244,MATCH('面板-总览'!$AI11,'面板-景气指数'!$A$37:$A$244,0),MATCH('面板-总览'!AK$2,'面板-景气指数'!$36:$36,0)) -> 0.673 | AL11: =INDEX('面板-景气指数'!$37:$244,MATCH('面板-总览'!$AI11,'面板-景气指数'!$A$37:$A$244,0),MATCH('面板-总览'!AL$2,'面板-景气指数'!$36:$36,0)) -> 0.625 | AM11: =INDEX('面板-景气指数'!$37:$244,MATCH('面板-总览'!$AI11,'面板-景气指数'!$A$37:$A$244,0),MATCH('面板-总览'!AM$2,'面板-景气指数'!$36:$36,0)) -> 0.538 | AN11: =INDEX('面板-景气指数'!$37:$244,MATCH('面板-总览'!$AI11,'面板-景气指数'!$A$37:$A$244,0),MATCH('面板-总览'!AN$2,'面板-景气指数'!$36:$36,0)) -> 0.394 | AO11: =INDEX('面板-景气指数'!$37:$244,MATCH('面板-总览'!$AI11,'面板-景气指数'!$A$37:$A$244,0),MATCH('面板-总览'!AO$2,'面板-景气指数'!$36:$36,0)) -> 0.451 | AP11: =INDEX('面板-景气指数'!$37:$244,MATCH('面板-总览'!$AI11,'面板-景气指数'!$A$37:$A$244,0),MATCH('面板-总览'!AP$2,'面板-景气指数'!$36:$36,0)) -> 0.596 | AQ11: =INDEX('面板-景气指数'!$37:$244,MATCH('面板-总览'!$AI11,'面板-景气指数'!$A$37:$A$244,0),MATCH('面板-总览'!AQ$2,'面板-景气指数'!$36:$36,0)) -> 0.701 | ... AV11: =INDEX('面板-景气指数'!$37:$244,MATCH('面板-总览'!$AI11,'面板-景气指数'!$A$37:$A$244,0),MATCH('面板-总览'!AV$2,'面板-景气指数'!$36:$36,0)) -> 0.644 | AX11: =AV11-AS11 -> -0.115
A12: 农林牧渔 | B12: =INDEX('面板-景气指数'!$37:$244,MATCH('面板-总览'!$A12,'面板-景气指数'!$A$37:$A$244,0),MATCH('面板-总览'!B$2,'面板-景气指数'!$36:$36,0)) -> 0.20829772 | C12: =INDEX('面板-景气指数'!$37:$244,MATCH('面板-总览'!$A12,'面板-景气指数'!$A$37:$A$244,0),MATCH('面板-总览'!C$2,'面板-景气指数'!$36:$36,0)) -> 0.15816532 | D12: =INDEX('面板-景气指数'!$37:$244,MATCH('面板-总览'!$A12,'面板-景气指数'!$A$37:$A$244,0),MATCH('面板-总览'!D$2,'面板-景气指数'!$36:$36,0)) -> 0.13632548 | E12: =INDEX('面板-景气指数'!$37:$244,MATCH('面板-总览'!$A12,'面板-景气指数'!$A$37:$A$244,0),MATCH('面板-总览'!E$2,'面板-景气指数'!$36:$36,0)) -> 0.13643751 | F12: =INDEX('面板-景气指数'!$37:$244,MATCH('面板-总览'!$A12,'面板-景气指数'!$A$37:$A$244,0),MATCH('面板-总览'!F$2,'面板-景气指数'!$36:$36,0)) -> 0.13544072 | G12: =INDEX('面板-景气指数'!$37:$244,MATCH('面板-总览'!$A12,'面板-景气指数'!$A$37:$A$244,0),MATCH('面板-总览'!G$2,'面板-景气指数'!$36:$36,0)) -> 0.17570142 | H12: =INDEX('面板-景气指数'!$37:$244,MATCH('面板-总览'!$A12,'面板-景气指数'!$A$37:$A$244,0),MATCH('面板-总览'!H$2,'面板-景气指数'!$36:$36,0)) -> 0.17258462 | I12: =INDEX('面板-景气指数'!$37:$244,MATCH('面板-总览'!$A12,'面板-景气指数'!$A$37:$A$244,0),MATCH('面板-总览'!I$2,'面板-景气指数'!$36:$36,0)) -> 0.19502475 | ... N12: =INDEX('面板-景气指数'!$37:$244,MATCH('面板-总览'!$A12,'面板-景气指数'!$A$37:$A$244,0),MATCH('面板-总览'!N$2,'面板-景气指数'!$36:$36,0)) -> 0.26707846 | P12: =N12-K12 -> 0.0031961488 | R12: 金属新材料 | S12: =INDEX('面板-景气指数'!$37:$244,MATCH('面板-总览'!$R12,'面板-景气指数'!$A$37:$A$244,0),MATCH('面板-总览'!S$2,'面板-景气指数'!$36:$36,0)) -> 0.221 | T12: =INDEX('面板-景气指数'!$37:$244,MATCH('面板-总览'!$R12,'面板-景气指数'!$A$37:$A$244,0),MATCH('面板-总览'!T$2,'面板-景气指数'!$36:$36,0)) -> 0.163 | U12: =INDEX('面板-景气指数'!$37:$244,MATCH('面板-总览'!$R12,'面板-景气指数'!$A$37:$A$244,0),MATCH('面板-总览'!U$2,'面板-景气指数'!$36:$36,0)) -> 0.076 | V12: =INDEX('面板-景气指数'!$37:$244,MATCH('面板-总览'!$R12,'面板-景气指数'!$A$37:$A$244,0),MATCH('面板-总览'!V$2,'面板-景气指数'!$36:$36,0)) -> 0.038 | W12: =INDEX('面板-景气指数'!$37:$244,MATCH('面板-总览'!$R12,'面板-景气指数'!$A$37:$A$244,0),MATCH('面板-总览'!W$2,'面板-景气指数'!$36:$36,0)) -> 0.009 | X12: =INDEX('面板-景气指数'!$37:$244,MATCH('面板-总览'!$R12,'面板-景气指数'!$A$37:$A$244,0),MATCH('面板-总览'!X$2,'面板-景气指数'!$36:$36,0)) -> 0 | Y12: =INDEX('面板-景气指数'!$37:$244,MATCH('面板-总览'!$R12,'面板-景气指数'!$A$37:$A$244,0),MATCH('面板-总览'!Y$2,'面板-景气指数'!$36:$36,0)) -> 0.028 | Z12: =INDEX('面板-景气指数'!$37:$244,MATCH('面板-总览'!$R12,'面板-景气指数'!$A$37:$A$244,0),MATCH('面板-总览'!Z$2,'面板-景气指数'!$36:$36,0)) -> 0.067 | ... AE12: =INDEX('面板-景气指数'!$37:$244,MATCH('面板-总览'!$R12,'面板-景气指数'!$A$37:$A$244,0),MATCH('面板-总览'!AE$2,'面板-景气指数'!$36:$36,0)) -> 0.211 | AG12: =AE12-AB12 -> 0.096 | AI12: 锂 | AJ12: =INDEX('面板-景气指数'!$37:$244,MATCH('面板-总览'!$AI12,'面板-景气指数'!$A$37:$A$244,0),MATCH('面板-总览'!AJ$2,'面板-景气指数'!$36:$36,0)) -> 0.123 | AK12: =INDEX('面板-景气指数'!$37:$244,MATCH('面板-总览'!$AI12,'面板-景气指数'!$A$37:$A$244,0),MATCH('面板-总览'!AK$2,'面板-景气指数'!$36:$36,0)) -> 0.061 | AL12: =INDEX('面板-景气指数'!$37:$244,MATCH('面板-总览'!$AI12,'面板-景气指数'!$A$37:$A$244,0),MATCH('面板-总览'!AL$2,'面板-景气指数'!$36:$36,0)) -> 0.037 | AM12: =INDEX('面板-景气指数'!$37:$244,MATCH('面板-总览'!$AI12,'面板-景气指数'!$A$37:$A$244,0),MATCH('面板-总览'!AM$2,'面板-景气指数'!$36:$36,0)) -> 0.012 | AN12: =INDEX('面板-景气指数'!$37:$244,MATCH('面板-总览'!$AI12,'面板-景气指数'!$A$37:$A$244,0),MATCH('面板-总览'!AN$2,'面板-景气指数'!$36:$36,0)) -> 0 | AO12: =INDEX('面板-景气指数'!$37:$244,MATCH('面板-总览'!$AI12,'面板-景气指数'!$A$37:$A$244,0),MATCH('面板-总览'!AO$2,'面板-景气指数'!$36:$36,0)) -> 0.024 | AP12: =INDEX('面板-景气指数'!$37:$244,MATCH('面板-总览'!$AI12,'面板-景气指数'!$A$37:$A$244,0),MATCH('面板-总览'!AP$2,'面板-景气指数'!$36:$36,0)) -> 0.111 | AQ12: =INDEX('面板-景气指数'!$37:$244,MATCH('面板-总览'!$AI12,'面板-景气指数'!$A$37:$A$244,0),MATCH('面板-总览'!AQ$2,'面板-景气指数'!$36:$36,0)) -> 0.148 | ... AV12: =INDEX('面板-景气指数'!$37:$244,MATCH('面板-总览'!$AI12,'面板-景气指数'!$A$37:$A$244,0),MATCH('面板-总览'!AV$2,'面板-景气指数'!$36:$36,0)) -> 0.098 | AX12: =AV12-AS12 -> 0.012
A13: 食品饮料 | B13: =INDEX('面板-景气指数'!$37:$244,MATCH('面板-总览'!$A13,'面板-景气指数'!$A$37:$A$244,0),MATCH('面板-总览'!B$2,'面板-景气指数'!$36:$36,0)) -> 0.30511594 | C13: =INDEX('面板-景气指数'!$37:$244,MATCH('面板-总览'!$A13,'面板-景气指数'!$A$37:$A$244,0),MATCH('面板-总览'!C$2,'面板-景气指数'!$36:$36,0)) -> 0.34685361 | D13: =INDEX('面板-景气指数'!$37:$244,MATCH('面板-总览'!$A13,'面板-景气指数'!$A$37:$A$244,0),MATCH('面板-总览'!D$2,'面板-景气指数'!$36:$36,0)) -> 0.37611403 | E13: =INDEX('面板-景气指数'!$37:$244,MATCH('面板-总览'!$A13,'面板-景气指数'!$A$37:$A$244,0),MATCH('面板-总览'!E$2,'面板-景气指数'!$36:$36,0)) -> 0.38341736 | F13: =INDEX('面板-景气指数'!$37:$244,MATCH('面板-总览'!$A13,'面板-景气指数'!$A$37:$A$244,0),MATCH('面板-总览'!F$2,'面板-景气指数'!$36:$36,0)) -> 0.37985162 | G13: =INDEX('面板-景气指数'!$37:$244,MATCH('面板-总览'!$A13,'面板-景气指数'!$A$37:$A$244,0),MATCH('面板-总览'!G$2,'面板-景气指数'!$36:$36,0)) -> 0.3108386 | H13: =INDEX('面板-景气指数'!$37:$244,MATCH('面板-总览'!$A13,'面板-景气指数'!$A$37:$A$244,0),MATCH('面板-总览'!H$2,'面板-景气指数'!$36:$36,0)) -> 0.28958418 | I13: =INDEX('面板-景气指数'!$37:$244,MATCH('面板-总览'!$A13,'面板-景气指数'!$A$37:$A$244,0),MATCH('面板-总览'!I$2,'面板-景气指数'!$36:$36,0)) -> 0.28929481 | ... N13: =INDEX('面板-景气指数'!$37:$244,MATCH('面板-总览'!$A13,'面板-景气指数'!$A$37:$A$244,0),MATCH('面板-总览'!N$2,'面板-景气指数'!$36:$36,0)) -> 0.25307411 | P13: =N13-K13 -> -0.032291715 | R13: 化学原料 | S13: =INDEX('面板-景气指数'!$37:$244,MATCH('面板-总览'!$R13,'面板-景气指数'!$A$37:$A$244,0),MATCH('面板-总览'!S$2,'面板-景气指数'!$36:$36,0)) -> 0.42826653 | T13: =INDEX('面板-景气指数'!$37:$244,MATCH('面板-总览'!$R13,'面板-景气指数'!$A$37:$A$244,0),MATCH('面板-总览'!T$2,'面板-景气指数'!$36:$36,0)) -> 0.44121275 | U13: =INDEX('面板-景气指数'!$37:$244,MATCH('面板-总览'!$R13,'面板-景气指数'!$A$37:$A$244,0),MATCH('面板-总览'!U$2,'面板-景气指数'!$36:$36,0)) -> 0.40729762 | V13: =INDEX('面板-景气指数'!$37:$244,MATCH('面板-总览'!$R13,'面板-景气指数'!$A$37:$A$244,0),MATCH('面板-总览'!V$2,'面板-景气指数'!$36:$36,0)) -> 0.32602119 | W13: =INDEX('面板-景气指数'!$37:$244,MATCH('面板-总览'!$R13,'面板-景气指数'!$A$37:$A$244,0),MATCH('面板-总览'!W$2,'面板-景气指数'!$36:$36,0)) -> 0.29206042 | X13: =INDEX('面板-景气指数'!$37:$244,MATCH('面板-总览'!$R13,'面板-景气指数'!$A$37:$A$244,0),MATCH('面板-总览'!X$2,'面板-景气指数'!$36:$36,0)) -> 0.23924694 | Y13: =INDEX('面板-景气指数'!$37:$244,MATCH('面板-总览'!$R13,'面板-景气指数'!$A$37:$A$244,0),MATCH('面板-总览'!Y$2,'面板-景气指数'!$36:$36,0)) -> 0.2758754 | Z13: =INDEX('面板-景气指数'!$37:$244,MATCH('面板-总览'!$R13,'面板-景气指数'!$A$37:$A$244,0),MATCH('面板-总览'!Z$2,'面板-景气指数'!$36:$36,0)) -> 0.37467935 | ... AE13: =INDEX('面板-景气指数'!$37:$244,MATCH('面板-总览'!$R13,'面板-景气指数'!$A$37:$A$244,0),MATCH('面板-总览'!AE$2,'面板-景气指数'!$36:$36,0)) -> 0.18248593 | AG13: =AE13-AB13 -> -0.23814135 | AI13: 钴 | AJ13: =INDEX('面板-景气指数'!$37:$244,MATCH('面板-总览'!$AI13,'面板-景气指数'!$A$37:$A$244,0),MATCH('面板-总览'!AJ$2,'面板-景气指数'!$36:$36,0)) -> 0.269 | AK13: =INDEX('面板-景气指数'!$37:$244,MATCH('面板-总览'!$AI13,'面板-景气指数'!$A$37:$A$244,0),MATCH('面板-总览'!AK$2,'面板-景气指数'!$36:$36,0)) -> 0.217 | AL13: =INDEX('面板-景气指数'!$37:$244,MATCH('面板-总览'!$AI13,'面板-景气指数'!$A$37:$A$244,0),MATCH('面板-总览'!AL$2,'面板-景气指数'!$36:$36,0)) -> 0.205 | AM13: =INDEX('面板-景气指数'!$37:$244,MATCH('面板-总览'!$AI13,'面板-景气指数'!$A$37:$A$244,0),MATCH('面板-总览'!AM$2,'面板-景气指数'!$36:$36,0)) -> 0.243 | AN13: =INDEX('面板-景气指数'!$37:$244,MATCH('面板-总览'!$AI13,'面板-景气指数'!$A$37:$A$244,0),MATCH('面板-总览'!AN$2,'面板-景气指数'!$36:$36,0)) -> 0.333 | AO13: =INDEX('面板-景气指数'!$37:$244,MATCH('面板-总览'!$AI13,'面板-景气指数'!$A$37:$A$244,0),MATCH('面板-总览'!AO$2,'面板-景气指数'!$36:$36,0)) -> 0.397 | AP13: =INDEX('面板-景气指数'!$37:$244,MATCH('面板-总览'!$AI13,'面板-景气指数'!$A$37:$A$244,0),MATCH('面板-总览'!AP$2,'面板-景气指数'!$36:$36,0)) -> 0.474 | AQ13: =INDEX('面板-景气指数'!$37:$244,MATCH('面板-总览'!$AI13,'面板-景气指数'!$A$37:$A$244,0),MATCH('面板-总览'!AQ$2,'面板-景气指数'!$36:$36,0)) -> 0.487 | ... AV13: =INDEX('面板-景气指数'!$37:$244,MATCH('面板-总览'!$AI13,'面板-景气指数'!$A$37:$A$244,0),MATCH('面板-总览'!AV$2,'面板-景气指数'!$36:$36,0)) -> 0.448 | AX13: =AV13-AS13 -> 0.013
A14: 医药生物 | B14: =INDEX('面板-景气指数'!$37:$244,MATCH('面板-总览'!$A14,'面板-景气指数'!$A$37:$A$244,0),MATCH('面板-总览'!B$2,'面板-景气指数'!$36:$36,0)) -> 0.23497622 | C14: =INDEX('面板-景气指数'!$37:$244,MATCH('面板-总览'!$A14,'面板-景气指数'!$A$37:$A$244,0),MATCH('面板-总览'!C$2,'面板-景气指数'!$36:$36,0)) -> 0.26093889 | D14: =INDEX('面板-景气指数'!$37:$244,MATCH('面板-总览'!$A14,'面板-景气指数'!$A$37:$A$244,0),MATCH('面板-总览'!D$2,'面板-景气指数'!$36:$36,0)) -> 0.232717 | E14: =INDEX('面板-景气指数'!$37:$244,MATCH('面板-总览'!$A14,'面板-景气指数'!$A$37:$A$244,0),MATCH('面板-总览'!E$2,'面板-景气指数'!$36:$36,0)) -> 0.24061864 | F14: =INDEX('面板-景气指数'!$37:$244,MATCH('面板-总览'!$A14,'面板-景气指数'!$A$37:$A$244,0),MATCH('面板-总览'!F$2,'面板-景气指数'!$36:$36,0)) -> 0.25423932 | G14: =INDEX('面板-景气指数'!$37:$244,MATCH('面板-总览'!$A14,'面板-景气指数'!$A$37:$A$244,0),MATCH('面板-总览'!G$2,'面板-景气指数'!$36:$36,0)) -> 0.25112513 | H14: =INDEX('面板-景气指数'!$37:$244,MATCH('面板-总览'!$A14,'面板-景气指数'!$A$37:$A$244,0),MATCH('面板-总览'!H$2,'面板-景气指数'!$36:$36,0)) -> 0.28610818 | I14: =INDEX('面板-景气指数'!$37:$244,MATCH('面板-总览'!$A14,'面板-景气指数'!$A$37:$A$244,0),MATCH('面板-总览'!I$2,'面板-景气指数'!$36:$36,0)) -> 0.31377697 | ... N14: =INDEX('面板-景气指数'!$37:$244,MATCH('面板-总览'!$A14,'面板-景气指数'!$A$37:$A$244,0),MATCH('面板-总览'!N$2,'面板-景气指数'!$36:$36,0)) -> 0.22870675 | P14: =N14-K14 -> -0.044111541 | R14: 化学制品 | S14: =INDEX('面板-景气指数'!$37:$244,MATCH('面板-总览'!$R14,'面板-景气指数'!$A$37:$A$244,0),MATCH('面板-总览'!S$2,'面板-景气指数'!$36:$36,0)) -> 0.47729161 | T14: =INDEX('面板-景气指数'!$37:$244,MATCH('面板-总览'!$R14,'面板-景气指数'!$A$37:$A$244,0),MATCH('面板-总览'!T$2,'面板-景气指数'!$36:$36,0)) -> 0.47738169 | U14: =INDEX('面板-景气指数'!$37:$244,MATCH('面板-总览'!$R14,'面板-景气指数'!$A$37:$A$244,0),MATCH('面板-总览'!U$2,'面板-景气指数'!$36:$36,0)) -> 0.4697587 | V14: =INDEX('面板-景气指数'!$37:$244,MATCH('面板-总览'!$R14,'面板-景气指数'!$A$37:$A$244,0),MATCH('面板-总览'!V$2,'面板-景气指数'!$36:$36,0)) -> 0.46186904 | W14: =INDEX('面板-景气指数'!$37:$244,MATCH('面板-总览'!$R14,'面板-景气指数'!$A$37:$A$244,0),MATCH('面板-总览'!W$2,'面板-景气指数'!$36:$36,0)) -> 0.4395678 | X14: =INDEX('面板-景气指数'!$37:$244,MATCH('面板-总览'!$R14,'面板-景气指数'!$A$37:$A$244,0),MATCH('面板-总览'!X$2,'面板-景气指数'!$36:$36,0)) -> 0.42023231 | Y14: =INDEX('面板-景气指数'!$37:$244,MATCH('面板-总览'!$R14,'面板-景气指数'!$A$37:$A$244,0),MATCH('面板-总览'!Y$2,'面板-景气指数'!$36:$36,0)) -> 0.42070919 | Z14: =INDEX('面板-景气指数'!$37:$244,MATCH('面板-总览'!$R14,'面板-景气指数'!$A$37:$A$244,0),MATCH('面板-总览'!Z$2,'面板-景气指数'!$36:$36,0)) -> 0.42260676 | ... AE14: =INDEX('面板-景气指数'!$37:$244,MATCH('面板-总览'!$R14,'面板-景气指数'!$A$37:$A$244,0),MATCH('面板-总览'!AE$2,'面板-景气指数'!$36:$36,0)) -> 0.4259358 | AG14: =AE14-AB14 -> 0.015760315 | AI14: 镍 | AJ14: =INDEX('面板-景气指数'!$37:$244,MATCH('面板-总览'!$AI14,'面板-景气指数'!$A$37:$A$244,0),MATCH('面板-总览'!AJ$2,'面板-景气指数'!$36:$36,0)) -> 0.163 | AK14: =INDEX('面板-景气指数'!$37:$244,MATCH('面板-总览'!$AI14,'面板-景气指数'!$A$37:$A$244,0),MATCH('面板-总览'!AK$2,'面板-景气指数'!$36:$36,0)) -> 0.153 | AL14: =INDEX('面板-景气指数'!$37:$244,MATCH('面板-总览'!$AI14,'面板-景气指数'!$A$37:$A$244,0),MATCH('面板-总览'!AL$2,'面板-景气指数'!$36:$36,0)) -> 0.096 | AM14: =INDEX('面板-景气指数'!$37:$244,MATCH('面板-总览'!$AI14,'面板-景气指数'!$A$37:$A$244,0),MATCH('面板-总览'!AM$2,'面板-景气指数'!$36:$36,0)) -> 0.086 | AN14: =INDEX('面板-景气指数'!$37:$244,MATCH('面板-总览'!$AI14,'面板-景气指数'!$A$37:$A$244,0),MATCH('面板-总览'!AN$2,'面板-景气指数'!$36:$36,0)) -> 0.057 | AO14: =INDEX('面板-景气指数'!$37:$244,MATCH('面板-总览'!$AI14,'面板-景气指数'!$A$37:$A$244,0),MATCH('面板-总览'!AO$2,'面板-景气指数'!$36:$36,0)) -> 0.028 | AP14: =INDEX('面板-景气指数'!$37:$244,MATCH('面板-总览'!$AI14,'面板-景气指数'!$A$37:$A$244,0),MATCH('面板-总览'!AP$2,'面板-景气指数'!$36:$36,0)) -> 0.019 | AQ14: =INDEX('面板-景气指数'!$37:$244,MATCH('面板-总览'!$AI14,'面板-景气指数'!$A$37:$A$244,0),MATCH('面板-总览'!AQ$2,'面板-景气指数'!$36:$36,0)) -> 0.067 | ... AV14: =INDEX('面板-景气指数'!$37:$244,MATCH('面板-总览'!$AI14,'面板-景气指数'!$A$37:$A$244,0),MATCH('面板-总览'!AV$2,'面板-景气指数'!$36:$36,0)) -> 0.182 | AX14: =AV14-AS14 -> -0.01
... A31: 交通运输 | B31: =INDEX('面板-景气指数'!$37:$244,MATCH('面板-总览'!$A31,'面板-景气指数'!$A$37:$A$244,0),MATCH('面板-总览'!B$2,'面板-景气指数'!$36:$36,0)) -> 0.46078434 | C31: =INDEX('面板-景气指数'!$37:$244,MATCH('面板-总览'!$A31,'面板-景气指数'!$A$37:$A$244,0),MATCH('面板-总览'!C$2,'面板-景气指数'!$36:$36,0)) -> 0.51699915 | D31: =INDEX('面板-景气指数'!$37:$244,MATCH('面板-总览'!$A31,'面板-景气指数'!$A$37:$A$244,0),MATCH('面板-总览'!D$2,'面板-景气指数'!$36:$36,0)) -> 0.49904959 | E31: =INDEX('面板-景气指数'!$37:$244,MATCH('面板-总览'!$A31,'面板-景气指数'!$A$37:$A$244,0),MATCH('面板-总览'!E$2,'面板-景气指数'!$36:$36,0)) -> 0.51981812 | F31: =INDEX('面板-景气指数'!$37:$244,MATCH('面板-总览'!$A31,'面板-景气指数'!$A$37:$A$244,0),MATCH('面板-总览'!F$2,'面板-景气指数'!$36:$36,0)) -> 0.54878502 | G31: =INDEX('面板-景气指数'!$37:$244,MATCH('面板-总览'!$A31,'面板-景气指数'!$A$37:$A$244,0),MATCH('面板-总览'!G$2,'面板-景气指数'!$36:$36,0)) -> 0.49427353 | H31: =INDEX('面板-景气指数'!$37:$244,MATCH('面板-总览'!$A31,'面板-景气指数'!$A$37:$A$244,0),MATCH('面板-总览'!H$2,'面板-景气指数'!$36:$36,0)) -> 0.4416033 | I31: =INDEX('面板-景气指数'!$37:$244,MATCH('面板-总览'!$A31,'面板-景气指数'!$A$37:$A$244,0),MATCH('面板-总览'!I$2,'面板-景气指数'!$36:$36,0)) -> 0.38809938 | ... N31: =INDEX('面板-景气指数'!$37:$244,MATCH('面板-总览'!$A31,'面板-景气指数'!$A$37:$A$244,0),MATCH('面板-总览'!N$2,'面板-景气指数'!$36:$36,0)) -> 0.35574371 | P31: =N31-K31 -> 0.00067987717 | R31: 电池 | S31: =INDEX('面板-景气指数'!$37:$244,MATCH('面板-总览'!$R31,'面板-景气指数'!$A$37:$A$244,0),MATCH('面板-总览'!S$2,'面板-景气指数'!$36:$36,0)) -> 0.29041667 | T31: =INDEX('面板-景气指数'!$37:$244,MATCH('面板-总览'!$R31,'面板-景气指数'!$A$37:$A$244,0),MATCH('面板-总览'!T$2,'面板-景气指数'!$36:$36,0)) -> 0.28708333 | U31: =INDEX('面板-景气指数'!$37:$244,MATCH('面板-总览'!$R31,'面板-景气指数'!$A$37:$A$244,0),MATCH('面板-总览'!U$2,'面板-景气指数'!$36:$36,0)) -> 0.32658333 | V31: =INDEX('面板-景气指数'!$37:$244,MATCH('面板-总览'!$R31,'面板-景气指数'!$A$37:$A$244,0),MATCH('面板-总览'!V$2,'面板-景气指数'!$36:$36,0)) -> 0.330125 | W31: =INDEX('面板-景气指数'!$37:$244,MATCH('面板-总览'!$R31,'面板-景气指数'!$A$37:$A$244,0),MATCH('面板-总览'!W$2,'面板-景气指数'!$36:$36,0)) -> 0.34258333 | X31: =INDEX('面板-景气指数'!$37:$244,MATCH('面板-总览'!$R31,'面板-景气指数'!$A$37:$A$244,0),MATCH('面板-总览'!X$2,'面板-景气指数'!$36:$36,0)) -> 0.33129167 | Y31: =INDEX('面板-景气指数'!$37:$244,MATCH('面板-总览'!$R31,'面板-景气指数'!$A$37:$A$244,0),MATCH('面板-总览'!Y$2,'面板-景气指数'!$36:$36,0)) -> 0.317125 | Z31: =INDEX('面板-景气指数'!$37:$244,MATCH('面板-总览'!$R31,'面板-景气指数'!$A$37:$A$244,0),MATCH('面板-总览'!Z$2,'面板-景气指数'!$36:$36,0)) -> 0.293625 | ... AE31: =INDEX('面板-景气指数'!$37:$244,MATCH('面板-总览'!$R31,'面板-景气指数'!$A$37:$A$244,0),MATCH('面板-总览'!AE$2,'面板-景气指数'!$36:$36,0)) -> 0.30541667 | AG31: =AE31-AB31 -> 0.039333333 | AI31: 其他化学纤维 | AJ31: =INDEX('面板-景气指数'!$37:$244,MATCH('面板-总览'!$AI31,'面板-景气指数'!$A$37:$A$244,0),MATCH('面板-总览'!AJ$2,'面板-景气指数'!$36:$36,0)) -> 0.336 | AK31: =INDEX('面板-景气指数'!$37:$244,MATCH('面板-总览'!$AI31,'面板-景气指数'!$A$37:$A$244,0),MATCH('面板-总览'!AK$2,'面板-景气指数'!$36:$36,0)) -> 0.3605 | AL31: =INDEX('面板-景气指数'!$37:$244,MATCH('面板-总览'!$AI31,'面板-景气指数'!$A$37:$A$244,0),MATCH('面板-总览'!AL$2,'面板-景气指数'!$36:$36,0)) -> 0.432 | AM31: =INDEX('面板-景气指数'!$37:$244,MATCH('面板-总览'!$AI31,'面板-景气指数'!$A$37:$A$244,0),MATCH('面板-总览'!AM$2,'面板-景气指数'!$36:$36,0)) -> 0.5185 | AN31: =INDEX('面板-景气指数'!$37:$244,MATCH('面板-总览'!$AI31,'面板-景气指数'!$A$37:$A$244,0),MATCH('面板-总览'!AN$2,'面板-景气指数'!$36:$36,0)) -> 0.533 | AO31: =INDEX('面板-景气指数'!$37:$244,MATCH('面板-总览'!$AI31,'面板-景气指数'!$A$37:$A$244,0),MATCH('面板-总览'!AO$2,'面板-景气指数'!$36:$36,0)) -> 0.336 | AP31: =INDEX('面板-景气指数'!$37:$244,MATCH('面板-总览'!$AI31,'面板-景气指数'!$A$37:$A$244,0),MATCH('面板-总览'!AP$2,'面板-景气指数'!$36:$36,0)) -> 0.2975 | AQ31: =INDEX('面板-景气指数'!$37:$244,MATCH('面板-总览'!$AI31,'面板-景气指数'!$A$37:$A$244,0),MATCH('面板-总览'!AQ$2,'面板-景气指数'!$36:$36,0)) -> 0.2785 | ... AV31: =INDEX('面板-景气指数'!$37:$244,MATCH('面板-总览'!$AI31,'面板-景气指数'!$A$37:$A$244,0),MATCH('面板-总览'!AV$2,'面板-景气指数'!$36:$36,0)) -> 0.216 | AX31: =AV31-AS31 -> -0.1055
R32: 电网设备 | S32: =INDEX('面板-景气指数'!$37:$244,MATCH('面板-总览'!$R32,'面板-景气指数'!$A$37:$A$244,0),MATCH('面板-总览'!S$2,'面板-景气指数'!$36:$36,0)) -> 0.46375 | T32: =INDEX('面板-景气指数'!$37:$244,MATCH('面板-总览'!$R32,'面板-景气指数'!$A$37:$A$244,0),MATCH('面板-总览'!T$2,'面板-景气指数'!$36:$36,0)) -> 0.51875 | U32: =INDEX('面板-景气指数'!$37:$244,MATCH('面板-总览'!$R32,'面板-景气指数'!$A$37:$A$244,0),MATCH('面板-总览'!U$2,'面板-景气指数'!$36:$36,0)) -> 0.574 | V32: =INDEX('面板-景气指数'!$37:$244,MATCH('面板-总览'!$R32,'面板-景气指数'!$A$37:$A$244,0),MATCH('面板-总览'!V$2,'面板-景气指数'!$36:$36,0)) -> 0.6125 | W32: =INDEX('面板-景气指数'!$37:$244,MATCH('面板-总览'!$R32,'面板-景气指数'!$A$37:$A$244,0),MATCH('面板-总览'!W$2,'面板-景气指数'!$36:$36,0)) -> 0.63675 | X32: =INDEX('面板-景气指数'!$37:$244,MATCH('面板-总览'!$R32,'面板-景气指数'!$A$37:$A$244,0),MATCH('面板-总览'!X$2,'面板-景气指数'!$36:$36,0)) -> 0.69425 | Y32: =INDEX('面板-景气指数'!$37:$244,MATCH('面板-总览'!$R32,'面板-景气指数'!$A$37:$A$244,0),MATCH('面板-总览'!Y$2,'面板-景气指数'!$36:$36,0)) -> 0.75675 | Z32: =INDEX('面板-景气指数'!$37:$244,MATCH('面板-总览'!$R32,'面板-景气指数'!$A$37:$A$244,0),MATCH('面板-总览'!Z$2,'面板-景气指数'!$36:$36,0)) -> 0.72575 | ... AE32: =INDEX('面板-景气指数'!$37:$244,MATCH('面板-总览'!$R32,'面板-景气指数'!$A$37:$A$244,0),MATCH('面板-总览'!AE$2,'面板-景气指数'!$36:$36,0)) -> 0.78825 | AG32: =AE32-AB32 -> 0.02425 | AI32: 其他塑料制品 | AJ32: =INDEX('面板-景气指数'!$37:$244,MATCH('面板-总览'!$AI32,'面板-景气指数'!$A$37:$A$244,0),MATCH('面板-总览'!AJ$2,'面板-景气指数'!$36:$36,0)) -> 0.759 | AK32: =INDEX('面板-景气指数'!$37:$244,MATCH('面板-总览'!$AI32,'面板-景气指数'!$A$37:$A$244,0),MATCH('面板-总览'!AK$2,'面板-景气指数'!$36:$36,0)) -> 0.682 | AL32: =INDEX('面板-景气指数'!$37:$244,MATCH('面板-总览'!$AI32,'面板-景气指数'!$A$37:$A$244,0),MATCH('面板-总览'!AL$2,'面板-景气指数'!$36:$36,0)) -> 0.711 | AM32: =INDEX('面板-景气指数'!$37:$244,MATCH('面板-总览'!$AI32,'面板-景气指数'!$A$37:$A$244,0),MATCH('面板-总览'!AM$2,'面板-景气指数'!$36:$36,0)) -> 0.721 | AN32: =INDEX('面板-景气指数'!$37:$244,MATCH('面板-总览'!$AI32,'面板-景气指数'!$A$37:$A$244,0),MATCH('面板-总览'!AN$2,'面板-景气指数'!$36:$36,0)) -> 0.74 | AO32: =INDEX('面板-景气指数'!$37:$244,MATCH('面板-总览'!$AI32,'面板-景气指数'!$A$37:$A$244,0),MATCH('面板-总览'!AO$2,'面板-景气指数'!$36:$36,0)) -> 0.692 | AP32: =INDEX('面板-景气指数'!$37:$244,MATCH('面板-总览'!$AI32,'面板-景气指数'!$A$37:$A$244,0),MATCH('面板-总览'!AP$2,'面板-景气指数'!$36:$36,0)) -> 0.615 | AQ32: =INDEX('面板-景气指数'!$37:$244,MATCH('面板-总览'!$AI32,'面板-景气指数'!$A$37:$A$244,0),MATCH('面板-总览'!AQ$2,'面板-景气指数'!$36:$36,0)) -> 0.509 | ... AV32: =INDEX('面板-景气指数'!$37:$244,MATCH('面板-总览'!$AI32,'面板-景气指数'!$A$37:$A$244,0),MATCH('面板-总览'!AV$2,'面板-景气指数'!$36:$36,0)) -> 0.048 | AX32: =AV32-AS32 -> -0.413
R33: 航海装备 | S33: =INDEX('面板-景气指数'!$37:$244,MATCH('面板-总览'!$R33,'面板-景气指数'!$A$37:$A$244,0),MATCH('面板-总览'!S$2,'面板-景气指数'!$36:$36,0)) -> 0.65575 | T33: =INDEX('面板-景气指数'!$37:$244,MATCH('面板-总览'!$R33,'面板-景气指数'!$A$37:$A$244,0),MATCH('面板-总览'!T$2,'面板-景气指数'!$36:$36,0)) -> 0.62475 | U33: =INDEX('面板-景气指数'!$37:$244,MATCH('面板-总览'!$R33,'面板-景气指数'!$A$37:$A$244,0),MATCH('面板-总览'!U$2,'面板-景气指数'!$36:$36,0)) -> 0.632 | V33: =INDEX('面板-景气指数'!$37:$244,MATCH('面板-总览'!$R33,'面板-景气指数'!$A$37:$A$244,0),MATCH('面板-总览'!V$2,'面板-景气指数'!$36:$36,0)) -> 0.651 | W33: =INDEX('面板-景气指数'!$37:$244,MATCH('面板-总览'!$R33,'面板-景气指数'!$A$37:$A$244,0),MATCH('面板-总览'!W$2,'面板-景气指数'!$36:$36,0)) -> 0.728 | X33: =INDEX('面板-景气指数'!$37:$244,MATCH('面板-总览'!$R33,'面板-景气指数'!$A$37:$A$244,0),MATCH('面板-总览'!X$2,'面板-景气指数'!$36:$36,0)) -> 0.747 | Y33: =INDEX('面板-景气指数'!$37:$244,MATCH('面板-总览'!$R33,'面板-景气指数'!$A$37:$A$244,0),MATCH('面板-总览'!Y$2,'面板-景气指数'!$36:$36,0)) -> 0.7665 | Z33: =INDEX('面板-景气指数'!$37:$244,MATCH('面板-总览'!$R33,'面板-景气指数'!$A$37:$A$244,0),MATCH('面板-总览'!Z$2,'面板-景气指数'!$36:$36,0)) -> 0.7665 | ... AE33: =INDEX('面板-景气指数'!$37:$244,MATCH('面板-总览'!$R33,'面板-景气指数'!$A$37:$A$244,0),MATCH('面板-总览'!AE$2,'面板-景气指数'!$36:$36,0)) -> 0.6775 | AG33: =AE33-AB33 -> -0.0865 | AI33: 改性塑料 | AJ33: =INDEX('面板-景气指数'!$37:$244,MATCH('面板-总览'!$AI33,'面板-景气指数'!$A$37:$A$244,0),MATCH('面板-总览'!AJ$2,'面板-景气指数'!$36:$36,0)) -> 0.365 | AK33: =INDEX('面板-景气指数'!$37:$244,MATCH('面板-总览'!$AI33,'面板-景气指数'!$A$37:$A$244,0),MATCH('面板-总览'!AK$2,'面板-景气指数'!$36:$36,0)) -> 0.408 | AL33: =INDEX('面板-景气指数'!$37:$244,MATCH('面板-总览'!$AI33,'面板-景气指数'!$A$37:$A$244,0),MATCH('面板-总览'!AL$2,'面板-景气指数'!$36:$36,0)) -> 0.4995 | AM33: =INDEX('面板-景气指数'!$37:$244,MATCH('面板-总览'!$AI33,'面板-景气指数'!$A$37:$A$244,0),MATCH('面板-总览'!AM$2,'面板-景气指数'!$36:$36,0)) -> 0.5045 | AN33: =INDEX('面板-景气指数'!$37:$244,MATCH('面板-总览'!$AI33,'面板-景气指数'!$A$37:$A$244,0),MATCH('面板-总览'!AN$2,'面板-景气指数'!$36:$36,0)) -> 0.485 | AO33: =INDEX('面板-景气指数'!$37:$244,MATCH('面板-总览'!$AI33,'面板-景气指数'!$A$37:$A$244,0),MATCH('面板-总览'!AO$2,'面板-景气指数'!$36:$36,0)) -> 0.4945 | AP33: =INDEX('面板-景气指数'!$37:$244,MATCH('面板-总览'!$AI33,'面板-景气指数'!$A$37:$A$244,0),MATCH('面板-总览'!AP$2,'面板-景气指数'!$36:$36,0)) -> 0.4995 | AQ33: =INDEX('面板-景气指数'!$37:$244,MATCH('面板-总览'!$AI33,'面板-景气指数'!$A$37:$A$244,0),MATCH('面板-总览'!AQ$2,'面板-景气指数'!$36:$36,0)) -> 0.538 | ... AV33: =INDEX('面板-景气指数'!$37:$244,MATCH('面板-总览'!$AI33,'面板-景气指数'!$A$37:$A$244,0),MATCH('面板-总览'!AV$2,'面板-景气指数'!$36:$36,0)) -> 0.365 | AX33: =AV33-AS33 -> -0.077
R34: 航空装备 | S34: =INDEX('面板-景气指数'!$37:$244,MATCH('面板-总览'!$R34,'面板-景气指数'!$A$37:$A$244,0),MATCH('面板-总览'!S$2,'面板-景气指数'!$36:$36,0)) -> 0.014 | T34: =INDEX('面板-景气指数'!$37:$244,MATCH('面板-总览'!$R34,'面板-景气指数'!$A$37:$A$244,0),MATCH('面板-总览'!T$2,'面板-景气指数'!$36:$36,0)) -> 0.038 | U34: =INDEX('面板-景气指数'!$37:$244,MATCH('面板-总览'!$R34,'面板-景气指数'!$A$37:$A$244,0),MATCH('面板-总览'!U$2,'面板-景气指数'!$36:$36,0)) -> 0.038 | V34: =INDEX('面板-景气指数'!$37:$244,MATCH('面板-总览'!$R34,'面板-景气指数'!$A$37:$A$244,0),MATCH('面板-总览'!V$2,'面板-景气指数'!$36:$36,0)) -> 0.0185 | W34: =INDEX('面板-景气指数'!$37:$244,MATCH('面板-总览'!$R34,'面板-景气指数'!$A$37:$A$244,0),MATCH('面板-总览'!W$2,'面板-景气指数'!$36:$36,0)) -> 0.0335 | X34: =INDEX('面板-景气指数'!$37:$244,MATCH('面板-总览'!$R34,'面板-景气指数'!$A$37:$A$244,0),MATCH('面板-总览'!X$2,'面板-景气指数'!$36:$36,0)) -> 0.057 | Y34: =INDEX('面板-景气指数'!$37:$244,MATCH('面板-总览'!$R34,'面板-景气指数'!$A$37:$A$244,0),MATCH('面板-总览'!Y$2,'面板-景气指数'!$36:$36,0)) -> 0.0815 | Z34: =INDEX('面板-景气指数'!$37:$244,MATCH('面板-总览'!$R34,'面板-景气指数'!$A$37:$A$244,0),MATCH('面板-总览'!Z$2,'面板-景气指数'!$36:$36,0)) -> 0.081 | ... AE34: =INDEX('面板-景气指数'!$37:$244,MATCH('面板-总览'!$R34,'面板-景气指数'!$A$37:$A$244,0),MATCH('面板-总览'!AE$2,'面板-景气指数'!$36:$36,0)) -> 0.2545 | AG34: =AE34-AB34 -> 0.13 | AI34: 合成树脂 | AJ34: =INDEX('面板-景气指数'!$37:$244,MATCH('面板-总览'!$AI34,'面板-景气指数'!$A$37:$A$244,0),MATCH('面板-总览'!AJ$2,'面板-景气指数'!$36:$36,0)) -> 0.449 | AK34: =INDEX('面板-景气指数'!$37:$244,MATCH('面板-总览'!$AI34,'面板-景气指数'!$A$37:$A$244,0),MATCH('面板-总览'!AK$2,'面板-景气指数'!$36:$36,0)) -> 0.692 | AL34: =INDEX('面板-景气指数'!$37:$244,MATCH('面板-总览'!$AI34,'面板-景气指数'!$A$37:$A$244,0),MATCH('面板-总览'!AL$2,'面板-景气指数'!$36:$36,0)) -> 0.68 | AM34: =INDEX('面板-景气指数'!$37:$244,MATCH('面板-总览'!$AI34,'面板-景气指数'!$A$37:$A$244,0),MATCH('面板-总览'!AM$2,'面板-景气指数'!$36:$36,0)) -> 0.5515 | AN34: =INDEX('面板-景气指数'!$37:$244,MATCH('面板-总览'!$AI34,'面板-景气指数'!$A$37:$A$244,0),MATCH('面板-总览'!AN$2,'面板-景气指数'!$36:$36,0)) -> 0.5235 | AO34: =INDEX('面板-景气指数'!$37:$244,MATCH('面板-总览'!$AI34,'面板-景气指数'!$A$37:$A$244,0),MATCH('面板-总览'!AO$2,'面板-景气指数'!$36:$36,0)) -> 0.676 | AP34: =INDEX('面板-景气指数'!$37:$244,MATCH('面板-总览'!$AI34,'面板-景气指数'!$A$37:$A$244,0),MATCH('面板-总览'!AP$2,'面板-景气指数'!$36:$36,0)) -> 0.6405 | AQ34: =INDEX('面板-景气指数'!$37:$244,MATCH('面板-总览'!$AI34,'面板-景气指数'!$A$37:$A$244,0),MATCH('面板-总览'!AQ$2,'面板-景气指数'!$36:$36,0)) -> 0.756 | ... AV34: =INDEX('面板-景气指数'!$37:$244,MATCH('面板-总览'!$AI34,'面板-景气指数'!$A$37:$A$244,0),MATCH('面板-总览'!AV$2,'面板-景气指数'!$36:$36,0)) -> 0.745 | AX34: =AV34-AS34 -> 0.0025
R35: 军工电子 | S35: =INDEX('面板-景气指数'!$37:$244,MATCH('面板-总览'!$R35,'面板-景气指数'!$A$37:$A$244,0),MATCH('面板-总览'!S$2,'面板-景气指数'!$36:$36,0)) -> 0.211 | T35: =INDEX('面板-景气指数'!$37:$244,MATCH('面板-总览'!$R35,'面板-景气指数'!$A$37:$A$244,0),MATCH('面板-总览'!T$2,'面板-景气指数'!$36:$36,0)) -> 0.221 | U35: =INDEX('面板-景气指数'!$37:$244,MATCH('面板-总览'!$R35,'面板-景气指数'!$A$37:$A$244,0),MATCH('面板-总览'!U$2,'面板-景气指数'!$36:$36,0)) -> 0.24 | V35: =INDEX('面板-景气指数'!$37:$244,MATCH('面板-总览'!$R35,'面板-景气指数'!$A$37:$A$244,0),MATCH('面板-总览'!V$2,'面板-景气指数'!$36:$36,0)) -> 0.355 | W35: =INDEX('面板-景气指数'!$37:$244,MATCH('面板-总览'!$R35,'面板-景气指数'!$A$37:$A$244,0),MATCH('面板-总览'!W$2,'面板-景气指数'!$36:$36,0)) -> 0.307 | X35: =INDEX('面板-景气指数'!$37:$244,MATCH('面板-总览'!$R35,'面板-景气指数'!$A$37:$A$244,0),MATCH('面板-总览'!X$2,'面板-景气指数'!$36:$36,0)) -> 0.384 | Y35: =INDEX('面板-景气指数'!$37:$244,MATCH('面板-总览'!$R35,'面板-景气指数'!$A$37:$A$244,0),MATCH('面板-总览'!Y$2,'面板-景气指数'!$36:$36,0)) -> 0.365 | Z35: =INDEX('面板-景气指数'!$37:$244,MATCH('面板-总览'!$R35,'面板-景气指数'!$A$37:$A$244,0),MATCH('面板-总览'!Z$2,'面板-景气指数'!$36:$36,0)) -> 0.605 | ... AE35: =INDEX('面板-景气指数'!$37:$244,MATCH('面板-总览'!$R35,'面板-景气指数'!$A$37:$A$244,0),MATCH('面板-总览'!AE$2,'面板-景气指数'!$36:$36,0)) -> 0.586 | AG35: =AE35-AB35 -> -0.067 | AI35: 膜材料 | AJ35: =INDEX('面板-景气指数'!$37:$244,MATCH('面板-总览'!$AI35,'面板-景气指数'!$A$37:$A$244,0),MATCH('面板-总览'!AJ$2,'面板-景气指数'!$36:$36,0)) -> 0.5 | AK35: =INDEX('面板-景气指数'!$37:$244,MATCH('面板-总览'!$AI35,'面板-景气指数'!$A$37:$A$244,0),MATCH('面板-总览'!AK$2,'面板-景气指数'!$36:$36,0)) -> 0.528 | AL35: =INDEX('面板-景气指数'!$37:$244,MATCH('面板-总览'!$AI35,'面板-景气指数'!$A$37:$A$244,0),MATCH('面板-总览'!AL$2,'面板-景气指数'!$36:$36,0)) -> 0.442 | AM35: =INDEX('面板-景气指数'!$37:$244,MATCH('面板-总览'!$AI35,'面板-景气指数'!$A$37:$A$244,0),MATCH('面板-总览'!AM$2,'面板-景气指数'!$36:$36,0)) -> 0.548 | AN35: =INDEX('面板-景气指数'!$37:$244,MATCH('面板-总览'!$AI35,'面板-景气指数'!$A$37:$A$244,0),MATCH('面板-总览'!AN$2,'面板-景气指数'!$36:$36,0)) -> 0.557 | AO35: =INDEX('面板-景气指数'!$37:$244,MATCH('面板-总览'!$AI35,'面板-景气指数'!$A$37:$A$244,0),MATCH('面板-总览'!AO$2,'面板-景气指数'!$36:$36,0)) -> 0.509 | AP35: =INDEX('面板-景气指数'!$37:$244,MATCH('面板-总览'!$AI35,'面板-景气指数'!$A$37:$A$244,0),MATCH('面板-总览'!AP$2,'面板-景气指数'!$36:$36,0)) -> 0.48 | AQ35: =INDEX('面板-景气指数'!$37:$244,MATCH('面板-总览'!$AI35,'面板-景气指数'!$A$37:$A$244,0),MATCH('面板-总览'!AQ$2,'面板-景气指数'!$36:$36,0)) -> 0.413 | ... AV35: =INDEX('面板-景气指数'!$37:$244,MATCH('面板-总览'!$AI35,'面板-景气指数'!$A$37:$A$244,0),MATCH('面板-总览'!AV$2,'面板-景气指数'!$36:$36,0)) -> 0.278 | AX35: =AV35-AS35 -> -0.212
R36: 半导体 | S36: =INDEX('面板-景气指数'!$37:$244,MATCH('面板-总览'!$R36,'面板-景气指数'!$A$37:$A$244,0),MATCH('面板-总览'!S$2,'面板-景气指数'!$36:$36,0)) -> 0.26192857 | T36: =INDEX('面板-景气指数'!$37:$244,MATCH('面板-总览'!$R36,'面板-景气指数'!$A$37:$A$244,0),MATCH('面板-总览'!T$2,'面板-景气指数'!$36:$36,0)) -> 0.30335714 | U36: =INDEX('面板-景气指数'!$37:$244,MATCH('面板-总览'!$R36,'面板-景气指数'!$A$37:$A$244,0),MATCH('面板-总览'!U$2,'面板-景气指数'!$36:$36,0)) -> 0.36942857 | V36: =INDEX('面板-景气指数'!$37:$244,MATCH('面板-总览'!$R36,'面板-景气指数'!$A$37:$A$244,0),MATCH('面板-总览'!V$2,'面板-景气指数'!$36:$36,0)) -> 0.40957143 | W36: =INDEX('面板-景气指数'!$37:$244,MATCH('面板-总览'!$R36,'面板-景气指数'!$A$37:$A$244,0),MATCH('面板-总览'!W$2,'面板-景气指数'!$36:$36,0)) -> 0.46835714 | X36: =INDEX('面板-景气指数'!$37:$244,MATCH('面板-总览'!$R36,'面板-景气指数'!$A$37:$A$244,0),MATCH('面板-总览'!X$2,'面板-景气指数'!$36:$36,0)) -> 0.524 | Y36: =INDEX('面板-景气指数'!$37:$244,MATCH('面板-总览'!$R36,'面板-景气指数'!$A$37:$A$244,0),MATCH('面板-总览'!Y$2,'面板-景气指数'!$36:$36,0)) -> 0.53771429 | Z36: =INDEX('面板-景气指数'!$37:$244,MATCH('面板-总览'!$R36,'面板-景气指数'!$A$37:$A$244,0),MATCH('面板-总览'!Z$2,'面板-景气指数'!$36:$36,0)) -> 0.57421429 | ... AE36: =INDEX('面板-景气指数'!$37:$244,MATCH('面板-总览'!$R36,'面板-景气指数'!$A$37:$A$244,0),MATCH('面板-总览'!AE$2,'面板-景气指数'!$36:$36,0)) -> 0.5775 | AG36: =AE36-AB36 -> -0.033571429 | AI36: 其他橡胶制品 | AJ36: =INDEX('面板-景气指数'!$37:$244,MATCH('面板-总览'!$AI36,'面板-景气指数'!$A$37:$A$244,0),MATCH('面板-总览'!AJ$2,'面板-景气指数'!$36:$36,0)) -> 0.653 | AK36: =INDEX('面板-景气指数'!$37:$244,MATCH('面板-总览'!$AI36,'面板-景气指数'!$A$37:$A$244,0),MATCH('面板-总览'!AK$2,'面板-景气指数'!$36:$36,0)) -> 0.682 | AL36: =INDEX('面板-景气指数'!$37:$244,MATCH('面板-总览'!$AI36,'面板-景气指数'!$A$37:$A$244,0),MATCH('面板-总览'!AL$2,'面板-景气指数'!$36:$36,0)) -> 0.673 | AM36: =INDEX('面板-景气指数'!$37:$244,MATCH('面板-总览'!$AI36,'面板-景气指数'!$A$37:$A$244,0),MATCH('面板-总览'!AM$2,'面板-景气指数'!$36:$36,0)) -> 0.538 | AN36: =INDEX('面板-景气指数'!$37:$244,MATCH('面板-总览'!$AI36,'面板-景气指数'!$A$37:$A$244,0),MATCH('面板-总览'!AN$2,'面板-景气指数'!$36:$36,0)) -> 0.576 | AO36: =INDEX('面板-景气指数'!$37:$244,MATCH('面板-总览'!$AI36,'面板-景气指数'!$A$37:$A$244,0),MATCH('面板-总览'!AO$2,'面板-景气指数'!$36:$36,0)) -> 0.663 | AP36: =INDEX('面板-景气指数'!$37:$244,MATCH('面板-总览'!$AI36,'面板-景气指数'!$A$37:$A$244,0),MATCH('面板-总览'!AP$2,'面板-景气指数'!$36:$36,0)) -> 0.74 | AQ36: =INDEX('面板-景气指数'!$37:$244,MATCH('面板-总览'!$AI36,'面板-景气指数'!$A$37:$A$244,0),MATCH('面板-总览'!AQ$2,'面板-景气指数'!$36:$36,0)) -> 0.807 | ... AV36: =INDEX('面板-景气指数'!$37:$244,MATCH('面板-总览'!$AI36,'面板-景气指数'!$A$37:$A$244,0),MATCH('面板-总览'!AV$2,'面板-景气指数'!$36:$36,0)) -> 0.903 | AX36: =AV36-AS36 -> 0.086
